Workbook

Sheet KPIs_v1
B2: # | C2: Ítem | D2: Unidad | E2: 45474 | F2: 45505 | G2: 45536 | H2: 45566 | I2: 45597 | J2: 45627 | K2: Q4-24 | L2: Media Q4 2024 | M2: S1 | N2: S2 | O2: S3 | P2: S4 | Q2: 45658 | R2: S1 feb-25 | S2: Media | U2: Observaciones:
B3: 1 | C3: Propuestas emitidas | D3: # | E3: =8+8 -> 16 | G3: 6 | H3: =8+H5 -> 12 | I3: =9+I5 -> 15 | J3: =7+J5 -> 15 | K3: =+SUM(H3:J3) -> 42 | L3: =+K4/K3 -> 236.30952 | M3: 1 | N3: 3 | O3: 3 | P3: 1 | Q3: =+M3+N3+O3+P3 -> 8 | R3: 3 | S3: =+R4/R3 -> 323.66667
D4: kUS$ | E4: =1062+E6 -> 1735 | G4: =453+300 -> 753 | H4: =1600+H6 -> 1999 | I4: =2455+I6 -> 3967 | J4: =2600+J6 -> 3959 | K4: =+SUM(H4:J4) -> 9925 | M4: 200 | N4: 1400 | O4: 470 | P4: 142 | Q4: =+M4+N4+O4+P4 -> 2212 | R4: 971
B5: 2 | C5: Propuestas adjudicadas | D5: # | E5: 8 | F5: 6 | G5: 3 | H5: 4 | I5: 6 | J5: 8 | K5: =+SUM(H5:J5) -> 18 | L5: =+K6/K5 -> 181.66667 | M5: 4 | N5: 2 | O5: 2 | P5: 0 | Q5: =+M5+N5+O5+P5 -> 8 | R5: 1 | S5: =+R6/R5 -> 1045
D6: kUS$ | E6: 673 | F6: 524 | G6: 300 | H6: 399 | I6: =+Respaldo!I25 -> 1512 | J6: =+Respaldo!I31 -> 1359 | K6: =+SUM(H6:J6) -> 3270 | M6: 690 | N6: 240 | O6: 395 | P6: 0 | Q6: =+M6+N6+O6+P6 -> 1325 | R6: 1045
C7: Plazo Medio Adjudicado | D7: Meses | Q7: =+M7 -> 0
C8: Relación Monto/plazo | D8: US$/mes | Q8: =+M8 -> 0
C9: Saldo de Contratos (Por Ejecutar) | D9: kUS$ | Q9: =+M9 -> 0
B10: 3 | C10: Propuestas iniciadas c/ KOM | D10: # | H10: 4 | I10: 6 | J10: 5 | K10: =+SUM(H10:J10) -> 15 | L10: =+K11/K10 -> 193 | M10: 0 | N10: 1 | Q10: =+N10+M10+O10+P10 -> 1 | R10: 0 | S10: 0
D11: kUS$ | H11: 399 | I11: 1012 | J11: 1484 | K11: =+SUM(H11:J11) -> 2895 | M11: 0 | N11: 345 | Q11: =+N11+M11+O11+P11 -> 345 | R11: 0
D12: #(KOM interno) | H12: 1 | I12: 3 | J12: 4 | K12: =+SUM(H12:J12) -> 8 | Q12: =+M12 -> 0
B13: 4 | C13: POM Mensual | D13: # | H13: 14 | I13: 24 | J13: 23 | K13: =+SUM(H13:J13) -> 61 | L13: =+K14/K13 -> 31.95082 | M13: 22 | N13: 22 | O13: 22 | P13: 22 | Q13: =+P13 -> 22 | R13: 16 | S13: =+R14/R13 -> 35.1875
D14: kUS$ | H14: 516 | I14: 652 | J14: 781 | K14: =+SUM(H14:J14) -> 1949 | M14: 762 | N14: 754 | O14: 718 | P14: 718 | Q14: =+P14 -> 718 | R14: 563
B15: 5 | C15: EDP Emitidos | D15: # | H15: 16 | I15: 17 | J15: 19 | K15: =+SUM(H15:J15) -> 52 | L15: =+K16/K15 -> 34.384615 | M15: 0 | N15: 2 | O15: 8 | P15: 10 | Q15: =M15+N15+O15+P15 -> 20 | R15: 0 | S15: 0
D16: kUS$ | H16: 527 | I16: 429 | J16: =770+62 -> 832 | K16: =+SUM(H16:J16) -> 1788 | M16: 0 | N16: 86 | O16: 261 | P16: 354 | Q16: =M16+N16+O16+P16 -> 701 | R16: 0
B17: 6 | C17: EDP Facturados | D17: # | H17: 23 | I17: 17 | J17: 18 | K17: =+SUM(H17:J17) -> 58 | L17: =+K18/K17 -> 32.37931 | M17: 12 | N17: 1 | O17: 1 | P17: 4 | Q17: =+N17+M17+O17+P17 -> 18 | R17: 0 | S17: 0
D18: kUS$ | H18: 864 | I18: 493 | J18: 521 | K18: =+SUM(H18:J18) -> 1878 | M18: 427 | N18: 82 | O18: 35 | P18: 142 | Q18: =+N18+M18+O18+P18 -> 686 | R18: 0
B19: 7 | C19: EDP Pendientes (En proceso de aprobación) | D19: # | M19: 4 | N19: 2 | O19: 2 | P19: 0 | Q19: =+P19 -> 0 | R19: 10 | S19: =+R20/R19 -> 17.5
D20: kUS$ | M20: 192 | N20: 43 | O20: 43 | P20: 0 | Q20: =+P20 -> 0 | R20: 175
B21: 8 | C21: EDP Rezagados (emitidos no aprobados) | D21: # | I21: 1 | J21: 3 | K21: =+SUM(H21:J21) -> 4 | L21: =+K22/K21 -> 23.5 | M21: 2 | N21: 2 | O21: 1 | P21: 1 | Q21: =+P21 -> 1 | R21: 1 | S21: =+R22/R21 -> 35
D22: kUS$ | I22: 35 | J22: 59 | K22: =+SUM(H22:J22) -> 94 | M22: 70 | N22: 70 | O22: 35 | P22: 35 | Q22: =+P22 -> 35 | R22: 35
C23: Facturación | D23: kUS$ | H23: 864 | I23: 493 | J23: 551 | K23: =+SUM(H23:J23) -> 1908 | L23: =+K23/3 -> 636 | Q23: =+M23 -> 0
C24: Facturas por cobrar | D24: # | Q24: =+M24 -> 0
D25: kUS$ | Q25: =+M25 -> 0
B26: 9 | C26: Facturas Pagadas (Ingreso Operacional) | D26: # | H26: 25 | I26: 15 | J26: 15 | K26: =+SUM(H26:J26) -> 55 | L26: =+K27/K26 -> 38.109091 | M26: 4 | N26: 4 | O26: 8 | P26: 4 | Q26: =+N26+M26+O26+P26 -> 20 | R26: 2 | S26: =+R27/R26 -> 23 | T26: =+T27-Q27 -> 0 | W26: 175.000 adjudicada birchlake | X26: 175
D27: kUS$ | H27: 1004 | I27: 616 | J27: 476 | K27: =+SUM(H27:J27) -> 2096 | M27: 197 | N27: 83 | O27: 269 | P27: 157 | Q27: =+N27+M27+O27+P27 -> 706 | R27: 46 | T27: 706 | W27: Revisión de validación reportes R&R (15 assets) | X27: 220
B28: 10 | C28: Facturas Vencidas | D28: # | J28: 8 | K28: =+SUM(H28:J28) -> 8 | L28: =+K29/K28 -> 35.75 | M28: 5 | N28: 3 | O28: 2 | P28: 5 | Q28: =+P28 -> 5 | R28: 5 | S28: =+R29/R28 -> 50.8 | U28: Enviado | V28: Candelaria Zublin
D29: KUS$ | J29: 286 | K29: =+SUM(H29:J29) -> 286 | M29: 110 | N29: 60 | O29: 26.8 | P29: =227+27 -> 254 | Q29: =+P29 -> 254 | R29: 254 | V29: Cadelaria | W29: 80
B30: 11 | C30: Cumplimiento POM vs EDP | D30: % | H30: =+IFERROR(H16/H14,0) -> 1.0213178 | I30: =+IFERROR(I16/I14,0) -> 0.65797546 | J30: =+IFERROR(J16/J14,0) -> 1.0653009 | K30: =+AVERAGE(H30:J30) -> 0.91486473 | L30: - | M30: - | N30: =+IFERROR(N16/N14,0) -> 0.11405836 | O30: =+IFERROR(O16/O14,0) -> 0.36350975 | P30: =+IFERROR(P16/P14,0) -> 0.49303621 | Q30: =+IFERROR(Q16/Q14,0) -> 0.97632312 | R30: 0 | S30: 0 | W30: 240
B31: 12 | C31: Adherencia POM vs EDP | D31: % | H31: 0.73 | I31: 0.67 | J31: 0.76 | K31: =+AVERAGE(H31:J31) -> 0.72 | L31: - | M31: - | N31: - | O31: - | P31: - | Q31: 0.84 | R31: 0 | S31: 0 | W31: 150

Sheet Respaldo
B3: ID | C3: Proyecto | D3: US$ | E3: Fecha Inicio | F3: Mes | G3: KOM con cliente | H3: KOM Interno Realizado
B4: 1 | C4: BHP – MEL​-Modelo predictivo Pozos de drenaje | D4: 190 | F4: Julio | I4: =+SUM(D4:D11) -> 673
B5: 2 | C5: BHP - Spence​-Análisis de cumplimiento del plan | D5: 75 | F5: Julio
B6: 3 | C6: Mosaic – Cajati​-Actualización análisis de Estabilidad OP​ | D6: 90 | F6: Julio
B7: 4 | C7: CMP – Los Colorados​-“Plan Minero Base Escenario Brownfield MLC​ | D7: 43 | F7: Julio
B8: 5 | C8: CMP – Tofo Norte​-Tofo Norte, modularizado​ | D8: 50 | F8: Julio
B9: 6 | C9: CMP – CNN/LC​-Apoyo LOM 2024 Faenas MLC y CNN​ | D9: 95 | F9: Julio
B10: 7 | C10: Mosaic – Cajati​-Evaluación cumplimiento plan OP | D10: 60 | F10: Julio
B11: 8 | C11: Minsur – San Rafael​-Evaluación de recursos marginales​ | D11: 70 | F11: Julio
B12: 9 | C12: Minsur – Mina Justa​-Proyecto Achupallas | D12: 133 | F12: Agosto | I12: =+SUM(D12:D17) -> 524
B13: 10 | C13: Codelco - DCH​-Analisis opciones de vaciado | D13: 85 | F13: Septiembre
B14: 11 | C14: CMP –Algarrobo​-Algarrobo Finos | D14: 100 | F14: Octubre
B15: 12 | C15: CMP – CNN​-Mejoras operacionales | D15: 100 | F15: Noviembre
B16: 13 | C16: Lundin – Candelaria​-Diagnóstico de gaps de planificación y operaciones | D16: 66 | F16: Diciembre
B17: 14 | C17: Lhg - Autazes​-Taller y evaluación de información | D17: 40 | F17: Enero
B18: 15 | C18: Tantahuatay​ - servicio de capacitación en DBS y SIMPLAN​ | D18: 20 | F18: Septiembre | I18: =+SUM(D18:D20) -> 300
B19: 16 | C19: BHP - Escondida​-Tunel exploratorio​ | D19: 160 | F19: Septiembre
B20: 17 | C20: Lundin – Caserones​-Evaluación opciones de mejora de planificación | D20: 120 | F20: Septiembre
B21: 18 | C21: Estudio Conceptual Sierra Norte (Opción Óxidos) | D21: 250 | E21: 45572 | F21: Octubre | G21: Si | H21: Si | I21: =+SUM(D21:D24) -> 398.5 | J21: Propuesta Iniciadas c/KOM | K21: #
B22: 19 | C22: FEL3 CNN | D22: 100 | E22: 45579 | F22: Octubre | G22: Si | H22: No | K22: kUS$
B23: 20 | C23: Capacitacion DBS Buenaventura | D23: 20 | E23: 45579 | F23: Octubre | G23: Si | H23: No
B24: 21 | C24: Soporte Minero en Litigio OT - Gobierno Mongolia | D24: 28.5 | E24: 45586 | F24: Octubre | G24: Si | H24: No
B25: 22 | C25: Pre-PFS Twin Metals Birch Lake - Maturi | D25: 480 | E25: 45600 | F25: Noviembre | G25: Si | H25: Si | I25: =+SUM(D25:D31) -> 1512
B26: 23 | C26: Analisis de Capacidad Optima Tofo Norte | D26: 45 | E26: 45600 | F26: Noviembre | G26: Si | H26: No
B27: 24 | C27: Fase 2 CTV: Modelamiento Recursos, Geomecanica y LOM actualizado | D27: 355 | E27: 45600 | F27: Noviembre | G27: Si | H27: Si
B28: 25 | C28: Revision Normativa Recursos y Reservas Codelco (NCC-31) | D28: 80 | E28: 45614 | F28: Noviembre | G28: Si | H28: No
B29: 26 | C29: Servicio de Apoyo a la doc. De corto Plazo - RT | D29: 14 | E29: 45614 | F29: Noviembre | G29: Si | H29: No
B30: 27 | C30: RT: Análisis de Estándar cierre topográfico | D30: 38 | E30: 45614 | F30: Noviembre | G30: Si | H30: Si
B31: 28 | C31: Analisis Innovación Tecnologica Distrito Centinela | D31: 500 | E31: 45649 | F31: Noviembre | G31: Si | H31: Si | I31: =+SUM(D32:D38) -> 1359
B32: 29 | C32: Análisis Conceptual - Aura UG | D32: 224 | E32: 45642 | F32: Diciembre | G32: Si | H32: Si
B33: 30 | C33: Resolution: MinePlan Review (Scoping) | D33: 260 | E33: 45635 | F33: Diciembre | G33: Si | H33: Si
B34: 31 | C34: Raura: Analisis Plan LOM 2025 | D34: 50 | E34: 45642 | F34: Diciembre | G34: Si | H34: Si
B35: 32 | C35: Cerro Colorado: Diseño Cierre de Botaderos | D35: 450 | E35: 45649 | F35: Diciembre | G35: Si | H35: No
B36: 33 | C36: INGENIERÍA EXPLORATORIA DEL PROYECTO DMH NORTE | D36: 75 | E36: 45635 | F36: Diciembre | H36: Si
B37: 34 | C37: Los Calatos Pre-FP Study (V3) | D37: 270 | E37: - | F37: Diciembre | H37: Si
B38: 35 | C38: BCG: Evaluación de la planificación de Codelco | D38: 30 | F38: Diciembre | G38: NO | H38: No
C39: Cumplimiento | D39: =+SUM(D21:D38) -> 3269.5 | H39: 0.53
C41: Diciembre | D41: Anglo American | E41: Los Bronces | F41: Estudio de productividad | G41: 100000
C42: Diciembre | D42: BHP | E42: Spence | F42: Análisis de confiabilidad y detección de cuellos de botella del LoA 25 – Proyecto SCUT | G42: 45000
C43: Diciembre | D43: Vale | F43: Servicio IQS para nueve assets | G43: 1600000
...

Sheet KPI´s de negocio 2024
B2: # | C2: Ítem | D2: Unidad | E2: 45474 | F2: 45505 | G2: 45536 | H2: 45566 | I2: 45597 | J2: 45627 | K2: Acumulado | L2: Media kUS$ | N2: Cantidad de Proyectos | O2: 24
B3: 1 | C3: Propuestas emitidas | D3: # | H3: =8+H5 -> 12 | I3: =9+I5 -> 15 | J3: =7+J5 -> 15 | K3: =+SUM(H3:J3) -> 42 | L3: =+K4/K3 -> 236.30952
D4: kUS$ | H4: =1600+H6 -> 1999 | I4: =2455+I6 -> 3467 | J4: =2600+J6 -> 4459 | K4: =+SUM(H4:J4) -> 9925
B5: 2 | C5: Propuestas adjudicadas | D5: # | H5: 4 | I5: 6 | J5: 8 | K5: =+SUM(H5:J5) -> 18 | L5: =+K6/K5 -> 181.66667
D6: kUS$ | H6: 399 | I6: 1012 | J6: 1859 | K6: =+SUM(H6:J6) -> 3270
B7: 3 | C7: Propuestas iniciadas c/ KOM | D7: # | H7: 4 | I7: 6 | J7: 5 | K7: =+SUM(H7:J7) -> 15 | L7: =+K8/K7 -> 193
D8: kUS$ | H8: 399 | I8: 1012 | J8: 1484 | K8: =+SUM(H8:J8) -> 2895
D9: #(KOM interno) | H9: 1 | I9: 3 | J9: 4 | K9: =+SUM(H9:J9) -> 8
B10: 4 | C10: POM Mensual | D10: # | H10: 14 | I10: 24 | J10: 23 | K10: =+SUM(H10:J10) -> 61 | L10: =+K11/K10 -> 31.95082
D11: kUS$ | H11: 516 | I11: 652 | J11: 781 | K11: =+SUM(H11:J11) -> 1949
B12: 5 | C12: EDP Mensual | D12: # | H12: 16 | I12: 17 | J12: 19 | K12: =+SUM(H12:J12) -> 52 | L12: =+K13/K12 -> 34.384615 | N12: =+L12*O2 -> 825.23077 | O12: =+N12*12 -> 9902.7692
D13: kUS$ | H13: 527 | I13: 429 | J13: =770+62 -> 832 | K13: =+SUM(H13:J13) -> 1788 | N13: Considera 25 EDP | O13: Proyecta 10,3 MUS$
B14: 6 | C14: Facturación | D14: kUS$ | H14: 864 | I14: 493 | J14: 551 | K14: =+SUM(H14:J14) -> 1908 | L14: =+K14/3 -> 636
B15: 7 | C15: Ingresos Operacionales | D15: kUS$ | H15: 1004 | I15: 616 | J15: 476 | K15: =+SUM(H15:J15) -> 2096 | L15: =+K15/3 -> 698.66667
B16: 8 | C16: Cumplimiento POM vs EDP | D16: % | H16: =+IFERROR(H13/H11,0) -> 1.0213178 | I16: =+IFERROR(I13/I11,0) -> 0.65797546 | J16: =+IFERROR(J13/J11,0) -> 1.0653009 | K16: =+AVERAGE(H16:J16) -> 0.91486473 | L16: -
B17: 9 | C17: Adherencia POM vs EDP | D17: % | H17: 0.73 | I17: 0.67 | J17: 0.76 | K17: =+AVERAGE(H17:J17) -> 0.72 | L17: -

Sheet KPI´s de negocio REDCO
B2: Resp. | C2: # | D2: Ítem | E2: Unidad | F2: 45474 | G2: 45505 | H2: 45536 | I2: 45566 | J2: 45597 | K2: 45627 | L2: Q4-24 | M2: Media Q4 2024 | N2: S1 | O2: S2 | P2: S3 | Q2: S4 | R2: 45658 | S2: S1 feb-25 | T2: S2 feb-25 | U2: S3 feb-25 | V2: S4 feb-25 | W2: 45689 | X2: S1 mar-25 | Y2: S2 mar-25 | Z2: S3 mar-25 | AA2: S4 mar-25 | AB2: 45717 | AC2: S1 abr-25 | AD2: S2 abr-25 | AE2: S3 abr-25 | AF2: S4 abr-25 | AG2: S5 abril-25 | AH2: 45748 | AI2: S1 may-25 | AJ2: S2 may-25 | AK2: S3 may-25 | AL2: S4 may-25 | AM2: 45778 | AN2: S1 Jun-25 | AO2: S2 Jun-25 | AP2: S3 Jun-25 | AQ2: S4 Jun-25 | AR2: 45809 | AS2: S1 Jul-25 | AT2: S2 Jul-25 | AU2: S3 Jul-25 | AV2: S4 Jul-25 | AW2: S5 Jul-25 | AX2: 45839 | AY2: S1 ago-25 | AZ2: S2 ago-25 | BA2: S3 ago-25 | BB2: S4 ago-25 | BC2: 45870 | BD2: S1 sep-25 | BE2: S2 sep-25 | BF2: S3 sep-25 | BG2: S4 sep-25 | BH2: 45901 | BI2: S1 oct-25 | BJ2: S2 oct-25 | BK2: S3 oct-25 | BL2: S4 oct-25 | BM2: 45931 | BN2: Media oct | BO2: Acum. 2025 | BP2: Media Acum. | BR2: Observaciones:
B3: PA | C3: 1 | D3: Propuestas Emitidas | E3: # | F3: =8+8 -> 16 | H3: 6 | I3: =8+I5 -> 12 | J3: =9+J5 -> 15 | K3: =7+K5 -> 15 | L3: =+SUM(I3:K3) -> 42 | M3: =+L4/L3 -> 236.30952 | N3: 1 | O3: 3 | P3: 3 | Q3: 1 | R3: =+N3+O3+P3+Q3 -> 8 | S3: 3 | T3: 2 | U3: 2 | V3: 3 | W3: =+S3+T3+U3+V3 -> 10 | X3: 5 | Y3: 2 | Z3: 3 | AA3: 1 | AB3: =+X3+Y3+Z3+AA3 -> 11 | AC3: 0 | AD3: 9 | AE3: 2 | AF3: 5 | AG3: 2 | AH3: =+AC3+AD3+AE3+AF3+AG3 -> 18 | AI3: 2 | AJ3: 2 | AK3: 3 | AL3: 1 | AM3: =+AI3+AJ3+AK3+AL3 -> 8 | AN3: 3 | AO3: 9 | AP3: 3 | AQ3: 6 | AR3: =+AN3+AO3+AP3+AQ3 -> 21 | AS3: 4 | AT3: 4 | AU3: 6 | AV3: 3 | AW3: 3 | AX3: =+AS3+AT3+AU3+AV3+AW3 -> 20 | AY3: 4 | AZ3: 2 | BA3: 5 | BB3: 1 | BC3: =+AY3+AZ3+BA3+BB3 -> 12 | BD3: 2 | BE3: 5 | BF3: 2 | BG3: 1 | BH3: =+BD3+BE3+BF3+BG3 -> 10 | BI3: 0 | BJ3: 4 | BK3: 2 | BL3: 2 | BM3: =+BI3+BJ3+BK3+BL3 -> 8 | BN3: =+IFERROR(BM4/BM3,0) -> 416.25 | BO3: =+R3+W3+AB3+AH3+AM3+AR3+AX3+BC3+BH3+BM3 -> 126 | BP3: =+BO4/BO3 -> 280.65873 | BR3: 9
E4: kUS$ | F4: =1062+F6 -> 1735 | H4: =453+300 -> 753 | I4: =1600+I6 -> 1999 | J4: =2455+J6 -> 3967 | K4: =2600+K6 -> 3959 | L4: =+SUM(I4:K4) -> 9925 | N4: 200 | O4: 1400 | P4: 470 | Q4: 142 | R4: =+N4+O4+P4+Q4 -> 2212 | S4: 971 | T4: 100 | U4: =950+150 -> 1100 | V4: 400 | W4: =+S4+T4+U4+V4 -> 2571 | X4: 570 | Y4: 200 | Z4: 1500 | AA4: 3860 | AB4: =+X4+Y4+Z4+AA4 -> 6130 | AC4: 0 | AD4: 1288 | AE4: 500 | AF4: 2225 | AG4: =165+200 -> 365 | AH4: =+AC4+AD4+AE4+AF4+AG4 -> 4378 | AI4: 537 | AJ4: =180+190 -> 370 | AK4: =1500+150+21 -> 1671 | AL4: 448 | AM4: =+AI4+AJ4+AK4+AL4 -> 3026 | AN4: 625 | AO4: 6230 | AP4: 440 | AQ4: 770 | AR4: =+AN4+AO4+AP4+AQ4 -> 8065 | AS4: 345 | AT4: 530 | AU4: 800 | AV4: 360 | AW4: 262 | AX4: =+AS4+AT4+AU4+AV4+AW4 -> 2297 | AY4: 638 | AZ4: 124 | BA4: 975 | BB4: 52 | BC4: =+AY4+AZ4+BA4+BB4 -> 1789 | BD4: =380+84 -> 464 | BE4: 637 | BF4: =590-226 -> 364 | BG4: 100 | BH4: =+BD4+BE4+BF4+BG4 -> 1565 | BI4: 0 | BJ4: 665 | BK4: 2365 | BL4: =125+175 -> 300 | BM4: =+BI4+BJ4+BK4+BL4 -> 3330 | BO4: =+R4+W4+AB4+AH4+AM4+AR4+AX4+BC4+BH4+BM4 -> 35363 | BQ4: =+AVERAGE(R4,W4,AB4,AH4,AM4,AR4,AX4,BC4,BH4,BM4) -> 3536.3 | BR4: 1465 | BS4: =+BR4-BH4 -> -100
B5: PA | C5: 2 | D5: Propuestas Adjudicadas | E5: # | F5: 8 | G5: 6 | H5: 3 | I5: 4 | J5: 6 | K5: 8 | L5: =+SUM(I5:K5) -> 18 | M5: =+L6/L5 -> 181.66667 | N5: 4 | O5: 2 | P5: 2 | Q5: 0 | R5: =+N5+O5+P5+Q5 -> 8 | S5: 2 | T5: 3 | V5: 1 | W5: =+S5+T5+U5+V5 -> 6 | X5: 1 | Y5: 1 | Z5: 4 | AA5: 2 | AB5: =+X5+Y5+Z5+AA5 -> 8 | AC5: 0 | AD5: 2 | AE5: 1 | AF5: 1 | AG5: 3 | AH5: =+AC5+AD5+AE5+AF5+AG5 -> 7 | AI5: 1 | AJ5: 1 | AK5: 1 | AL5: 1 | AM5: =+AI5+AJ5+AK5+AL5 -> 4 | AN5: 0 | AO5: 3 | AP5: 1 | AQ5: 4 | AR5: =+AN5+AO5+AP5+AQ5 -> 8 | AS5: 1 | AT5: 1 | AU5: 3 | AV5: 2 | AW5: 2 | AX5: =+AS5+AT5+AU5+AV5+AW5 -> 9 | AY5: 1 | AZ5: 2 | BA5: 3 | BB5: 2 | BC5: =+AY5+AZ5+BA5+BB5 -> 8 | BD5: 0 | BE5: 3 | BF5: 0 | BG5: 1 | BH5: =+BD5+BE5+BF5+BG5 -> 4 | BI5: 0 | BJ5: 1 | BK5: 0 | BL5: 2 | BM5: =+BI5+BJ5+BK5+BL5 -> 3 | BN5: =+IFERROR(BM6/BM5,0) -> 115 | BO5: =+R5+W5+AB5+AH5+AM5+AR5+AX5+BC5+BH5+BM5 -> 65 | BP5: =+BO6/BO5 -> 126.95385 | BR5: 4
E6: kUS$ | F6: 673 | G6: 524 | H6: 300 | I6: 399 | J6: =+Respaldo!I25 -> 1512 | K6: =+Respaldo!I31 -> 1359 | L6: =+SUM(I6:K6) -> 3270 | N6: 690 | O6: 240 | P6: 126 | Q6: 0 | R6: =+N6+O6+P6+Q6 -> 1056 | S6: =1035+120 -> 1155 | T6: 91 | V6: 0 | W6: =+S6+T6+U6+V6 -> 1246 | X6: 20 | Y6: 65 | Z6: 563 | AA6: 88 | AB6: =+X6+Y6+Z6+AA6 -> 736 | AC6: 0 | AD6: 94 | AE6: 60 | AF6: =1114-650-60-94 -> 310 | AG6: =300+200+50 -> 550 | AH6: =+AC6+AD6+AE6+AF6+AG6 -> 1014 | AI6: 490 | AJ6: 262 | AK6: 21 | AL6: 195 | AM6: =+AI6+AJ6+AK6+AL6 -> 968 | AN6: 0 | AO6: 348 | AP6: 25 | AQ6: =286+37 -> 323 | AR6: =+AN6+AO6+AP6+AQ6 -> 696 | AS6: 80 | AT6: 23 | AU6: 119 | AV6: 113 | AW6: 324 | AX6: =+AS6+AT6+AU6+AV6+AW6 -> 659 | AY6: 135 | AZ6: =140+16 -> 156 | BA6: 485 | BB6: 120 | BC6: =+AY6+AZ6+BA6+BB6 -> 896 | BD6: 0 | BE6: 446 | BF6: 0 | BG6: 190 | BH6: =+BD6+BE6+BF6+BG6 -> 636 | BI6: 0 | BJ6: 140 | BK6: 0 | BL6: 205 | BM6: =+BI6+BJ6+BK6+BL6 -> 345 | BO6: =+R6+W6+AB6+AH6+AM6+AR6+AX6+BC6+BH6+BM6 -> 8252 | BQ6: =+AVERAGE(R6,W6,AB6,AH6,AM6,AR6,AX6,BC6,BH6,BM6) -> 825.2 | BR6: 636 | BS6: =+BR6-BH6 -> 0
D7: Plazo Medio Adjudicado | E7: Meses | R7: =+N7 -> 0 | W7: =+S7+T7 -> 0 | AM7: =+AI7+AJ7+AK7+AL7 -> 0 | AR7: =+AN7+AO7 -> 0 | BC7: =+AY7+AZ7+BA7+BB7 -> 0 | BH7: =+BD7+BE7 -> 0 | BM7: =+BI7+BJ7+BK7+BL7 -> 0
D8: Relación Monto/plazo | E8: US$/mes | R8: =+N8 -> 0 | W8: =+S8+T8 -> 0 | AM8: =+AI8+AJ8+AK8+AL8 -> 0 | AR8: =+AN8+AO8 -> 0 | BC8: =+AY8+AZ8+BA8+BB8 -> 0 | BH8: =+BD8+BE8 -> 0 | BM8: =+BI8+BJ8+BK8+BL8 -> 0
D9: Saldo de Contratos (Por Ejecutar) | E9: kUS$ | R9: =+N9 -> 0 | W9: =+S9+T9 -> 0 | AM9: =+AI9+AJ9+AK9+AL9 -> 0 | AR9: =+AN9+AO9 -> 0 | BC9: =+AY9+AZ9+BA9+BB9 -> 0 | BH9: =+BD9+BE9 -> 0 | BM9: =+BI9+BJ9+BK9+BL9 -> 0
B10: EC | D10: Propuestas iniciadas c/ KOM | E10: # | I10: 4 | J10: 6 | K10: 5 | L10: =+SUM(I10:K10) -> 15 | M10: =+L11/L10 -> 193 | N10: 0 | O10: 1 | R10: =+O10+N10+P10+Q10 -> 1 | S10: 0 | T10: 0 | U10: 0 | V10: 5 | W10: =+S10+T10+U10+V10 -> 5 | X10: 1 | Y10: 0 | Z10: =1+1 -> 2 | AA10: 0 | AB10: =+X10+Y10+Z10+AA10 -> 3 | AC10: 0 | AD10: 0 | AE10: 1 | AF10: 1 | AG10: 0 | AH10: =+AC10+AD10+AE10+AF10+AG10 -> 2 | AI10: 1 | AJ10: 0 | AM10: =+AI10+AJ10+AK10+AL10 -> 1 | AR10: =+AN10+AO10 -> 0 | BC10: =+AY10+AZ10+BA10+BB10 -> 0 | BH10: =+BD10+BE10 -> 0 | BM10: =+BI10+BJ10+BK10+BL10 -> 0 | BN10: =+IFERROR(AM11/AM10,0) -> 490 | BO10: =+R10+W10+AB10+AH10+AM10 -> 12 | BP10: =+BO11/BO10 -> 210.58333
E11: kUS$ | I11: 399 | J11: 1012 | K11: 1484 | L11: =+SUM(I11:K11) -> 2895 | N11: 0 | O11: 345 | R11: =+O11+N11+P11+Q11 -> 345 | S11: 0 | T11: 0 | U11: 0 | V11: 960 | W11: =+S11+T11+U11+V11 -> 960 | X11: 132 | Y11: 0 | Z11: =198+141 -> 339 | AA11: 0 | AB11: =+X11+Y11+Z11+AA11 -> 471 | AC11: 0 | AD11: 0 | AE11: 108 | AF11: 153 | AG11: 0 | AH11: =+AC11+AD11+AE11+AF11+AG11 -> 261 | AI11: 490 | AJ11: 0 | AM11: =+AI11+AJ11+AK11+AL11 -> 490 | AR11: =+AN11+AO11 -> 0 | BC11: =+AY11+AZ11+BA11+BB11 -> 0 | BH11: =+BD11+BE11 -> 0 | BM11: =+BI11+BJ11+BK11+BL11 -> 0 | BO11: =+R11+W11+AB11+AH11+AM11 -> 2527
E12: #(KOM interno) | I12: 1 | J12: 3 | K12: 4 | L12: =+SUM(I12:K12) -> 8 | R12: =+N12 -> 0 | W12: =+S12+T12 -> 0 | AM12: =+AI12+AJ12+AK12+AL12 -> 0 | AR12: =+AN12+AO12 -> 0 | BC12: =+AY12+AZ12+BA12+BB12 -> 0 | BH12: =+BD12+BE12 -> 0 | BM12: =+BI12+BJ12+BK12+BL12 -> 0
B13: EC | C13: 3 | D13: POM Mensual | E13: # | I13: 14 | J13: 24 | K13: 23 | L13: =+SUM(I13:K13) -> 61 | M13: =+L14/L13 -> 31.95082 | N13: 22 | O13: 22 | P13: 22 | Q13: 21 | R13: =+Q13 -> 21 | S13: 16 | T13: 5 | U13: 0 | V13: 0 | W13: =+S13+T13+U13+V13 -> 21 | X13: 19 | Y13: 3 | Z13: 0 | AA13: 0 | AB13: =+X13+Y13+Z13+AA13 -> 22 | AC13: 9 | AD13: 4 | AE13: 0 | AF13: 0 | AG13: 0 | AH13: =AC13+AD13+AE13+AF13+AG13 -> 13 | AI13: 14 | AJ13: 3 | AK13: 0 | AL13: 0 | AM13: =+AI13+AJ13+AK13+AL13 -> 17 | AN13: 12 | AO13: 2 | AP13: 0 | AQ13: 0 | AR13: =+AN13+AO13+AP13+AQ13 -> 14 | AS13: 18 | AT13: 0 | AU13: 0 | AV13: 0 | AW13: 0 | AX13: =+AS13+AT13+AU13+AV13+AW13 -> 18 | AY13: 22 | AZ13: 0 | BA13: 0 | BB13: 0 | BC13: =+AY13+AZ13+BA13+BB13 -> 22 | BD13: 25 | BE13: 1 | BF13: 0 | BG13: -2 | BH13: =+BD13+BE13+BF13+BG13 -> 24 | BI13: 23 | BJ13: -4 | BK13: 4 | BL13: -2 | BM13: =+BI13+BJ13+BK13+BL13 -> 21 | BN13: =+IFERROR(BM14/BM13,0) -> 33.571429 | BO13: =+R13+W13+AB13+AH13+AM13+AR13+AX13+BC13+BH13+BM13 -> 193 | BP13: =+BO14/BO13 -> 41.274611 | BR13: 23 | BS13: =+BR13-BM13 -> 2
E14: kUS$ | I14: 516 | J14: 652 | K14: 781 | L14: =+SUM(I14:K14) -> 1949 | N14: 762 | O14: 754 | P14: 718 | Q14: 718 | R14: =+Q14 -> 718 | S14: 563 | T14: 310 | U14: 0 | V14: 0 | W14: =+S14+T14+U14+V14 -> 873 | X14: 678 | Y14: 133 | Z14: 0 | AA14: 0 | AB14: =+X14+Y14+Z14+AA14 -> 811 | AC14: 466 | AD14: 145 | AE14: 0 | AF14: 0 | AG14: 0 | AH14: =AC14+AD14+AE14+AF14+AG14 -> 611 | AI14: 734 | AJ14: 100 | AK14: 0 | AL14: 0 | AM14: =+AI14+AJ14+AK14+AL14 -> 834 | AN14: 780 | AO14: 130 | AP14: 0 | AQ14: 0 | AR14: =+AN14+AO14+AP14+AQ14 -> 910 | AS14: 787 | AT14: 0 | AU14: 0 | AV14: 0 | AW14: 0 | AX14: =+AS14+AT14+AU14+AV14+AW14 -> 787 | AY14: 922 | AZ14: 0 | BA14: 0 | BB14: 0 | BC14: =+AY14+AZ14+BA14+BB14 -> 922 | BD14: 923 | BE14: 52 | BF14: 0 | BG14: -180 | BH14: =+BD14+BE14+BF14+BG14 -> 795 | BI14: 679 | BJ14: -131 | BK14: 219 | BL14: =-50-12 -> -62 | BM14: =+BI14+BJ14+BK14+BL14 -> 705 | BO14: =+R14+W14+AB14+AH14+AM14+AR14+AX14+BC14+BH14+BM14 -> 7966 | BQ14: =+AVERAGE(R14,W14,AB14,AH14,AM14,AR14,AX14,BC14,BH14,BM14) -> 796.6 | BR14: 767 | BS14: =+BR14-BM14 -> 62
B15: EC | C15: 4 | D15: EDP Emitidos (Mes en curso) | E15: # | I15: 16 | J15: 17 | K15: 19 | L15: =+SUM(I15:K15) -> 52 | M15: =+L16/L15 -> 34.384615 | N15: 0 | O15: 2 | P15: 8 | Q15: 9 | R15: =N15+O15+P15+Q15 -> 19 | S15: 0 | T15: 0 | U15: 0 | V15: 20 | W15: =+S15+T15+U15+V15 -> 20 | X15: 0 | Y15: 0 | Z15: 3 | AA15: =8+1+4+1 -> 14 | AB15: =+X15+Y15+Z15+AA15 -> 17 | AC15: 0 | AD15: 1 | AE15: 1 | AF15: 3 | AG15: 10 | AH15: =+AC15+AD15+AE15+AF15+AG15 -> 15 | AI15: 0 | AJ15: 1 | AK15: 1 | AL15: 14 | AM15: =+AI15+AJ15+AK15+AL15 -> 16 | AN15: 0 | AO15: 1 | AP15: 3 | AQ15: =8+3-1 -> 10 | AR15: =+AN15+AO15+AP15+AQ15 -> 14 | AS15: 0 | AT15: 0 | AU15: 6 | AV15: 4 | AW15: =2+1+1+1 -> 5 | AX15: =+AS15+AT15+AU15+AV15+AW15 -> 15 | AY15: 0 | AZ15: 0 | BA15: 9 | BB15: =7+1 -> 8 | BC15: =+AY15+AZ15+BA15+BB15 -> 17 | BD15: 0 | BE15: 5 | BF15: 2 | BG15: =3+6+3 -> 12 | BH15: =+BD15+BE15+BF15+BG15 -> 19 | BI15: 0 | BJ15: 1 | BK15: 8 | BL15: 7 | BM15: =+BI15+BJ15+BK15+BL15 -> 16 | BN15: =+IFERROR(BM16/BM15,0) -> 39.8 | BO15: =+R15+W15+AB15+AH15+AM15+AR15+AX15+BC15+BH15+BM15 -> 168 | BP15: =+BO16/BO15 -> 46.028571 | BR15: 16 | BS15: =+BR15-BM15 -> 0
E16: kUS$ | I16: 527 | J16: 429 | K16: =770+62 -> 832 | L16: =+SUM(I16:K16) -> 1788 | N16: 0 | O16: 86 | P16: 261 | Q16: =354-34+2 -> 322 | R16: =N16+O16+P16+Q16 -> 669 | S16: 0 | T16: 0 | U16: 0 | V16: 892 | W16: =+S16+T16+U16+V16 -> 892 | X16: 0 | Y16: 0 | Z16: 56 | AA16: =424+59+81+74 -> 638 | AB16: =+X16+Y16+Z16+AA16 -> 694 | AC16: 0 | AD16: 65 | AE16: 39 | AF16: 128 | AG16: =548+5-70+7-18 -> 472 | AH16: =+AC16+AD16+AE16+AF16+AG16 -> 704 | AI16: 0 | AJ16: 39 | AK16: 67 | AL16: =511+690-96-39-416-26 -> 624 | AM16: =+AI16+AJ16+AK16+AL16 -> 730 | AN16: 0 | AO16: 81 | AP16: 171 | AQ16: =540+340+73-27 -> 926 | AR16: =+AN16+AO16+AP16+AQ16 -> 1178 | AS16: 0 | AT16: 0 | AU16: 157 | AV16: =165+100+36 -> 301 | AW16: =39+70+126+35+35-20 -> 285 | AX16: =+AS16+AT16+AU16+AV16+AW16 -> 743 | AY16: 0 | AZ16: 0 | BA16: 306 | BB16: =375+150-46 -> 479 | BC16: =+AY16+AZ16+BA16+BB16 -> 785 | BD16: 0 | BE16: 183 | BF16: 50 | BG16: =71+312+85 -> 468 | BH16: =+BD16+BE16+BF16+BG16 -> 701 | BI16: 0 | BJ16: 3.8 | BK16: 257 | BL16: 376 | BM16: =+BI16+BJ16+BK16+BL16 -> 636.8 | BO16: =+R16+W16+AB16+AH16+AM16+AR16+AX16+BC16+BH16+BM16 -> 7732.8 | BQ16: =+AVERAGE(R16,W16,AB16,AH16,AM16,AR16,AX16,BC16,BH16,BM16) -> 773.28 | BR16: 637 | BS16: =+BR16-BM16 -> 0.2 | BV16: 1000
B17: IM | C17: 5 | D17: EDP Facturados (Facturas emitidas) | E17: # | I17: 23 | J17: 17 | K17: 18 | L17: =+SUM(I17:K17) -> 58 | M17: =+L18/L17 -> 32.37931 | N17: 12 | O17: 1 | P17: 1 | Q17: =4+4 -> 8 | R17: 22 | S17: 0 | T17: 0 | U17: 1 | V17: 8 | W17: 9 | X17: 2 | Y17: =1+2+3 -> 6 | Z17: 6 | AA17: =1+1+1 -> 3 | AB17: =+X17+Y17+Z17+AA17 -> 17 | AC17: 4 | AD17: 2 | AE17: 2 | AF17: 5 | AG17: 4 | AH17: 16 | AI17: 8 | AJ17: 3 | AK17: 2 | AL17: 8 | AM17: =+AI17+AJ17+AK17+AL17 -> 21 | AN17: 6 | AO17: 4 | AP17: 1 | AQ17: 6 | AR17: =+AN17+AO17+AP17+AQ17 -> 17 | AS17: 4 | AT17: 5 | AU17: 3 | AV17: 3 | AW17: =2+1 -> 3 | AX17: =+AS17+AT17+AU17+AV17+AW17 -> 18 | AY17: 7 | AZ17: 2 | BA17: 8 | BB17: =3+3 -> 6 | BC17: =+AY17+AZ17+BA17+BB17 -> 23 | BD17: 3 | BE17: 2 | BF17: 2 | BG17: 8 | BH17: =+BD17+BE17+BF17+BG17 -> 15 | BI17: 1 | BJ17: 4 | BK17: 5 | BL17: 5 | BM17: =+BI17+BJ17+BK17+BL17 -> 15 | BN17: =+IFERROR(BM18/BM17,0) -> 50.733333 | BO17: =+R17+W17+AB17+AH17+AM17+AR17+AX17+BC17+BH17+BM17 -> 173 | BP17: =+BO18/BO17 -> 46.404624 | BR17: 15 | BS17: =+BR17-BM17 -> 0 | BV17: 45658 | BW17: 45689 | BX17: 45717 | BY17: 45748 | BZ17: 45778 | CA17: 45809 | CB17: 45839
E18: kUS$ | I18: 864 | J18: 493 | K18: 521 | L18: =+SUM(I18:K18) -> 1878 | N18: 427 | O18: 82 | P18: 35 | Q18: =142+173 -> 315 | R18: 823 | S18: 0 | T18: 0 | U18: 96 | V18: 298 | W18: 313 | X18: =0+0+0+47 -> 47 | Y18: =84.795+106+248 -> 438.795 | Z18: 239.205 | AA18: =25+11 -> 36 | AB18: 798 | AC18: 182 | AD18: 39 | AE18: 38 | AF18: 122 | AG18: 344 | AH18: 702 | AI18: 201 | AJ18: 134 | AK18: 35 | AL18: =563+38 -> 601 | AM18: 916 | AN18: 111 | AO18: 176 | AP18: 15 | AQ18: =470+47-16-21 -> 480 | AR18: =+AN18+AO18+AP18+AQ18 -> 782 | AS18: 144 | AT18: 345 | AU18: 70 | AV18: 201 | AW18: =35+99 -> 134 | AX18: =+AS18+AT18+AU18+AV18+AW18 -> 894 | AY18: 752 | AZ18: 145 | BA18: 217 | BB18: =155+65 -> 220 | BC18: =+AY18+AZ18+BA18+BB18 -> 1334 | BD18: 55 | BE18: 171 | BF18: 102 | BG18: 377 | BH18: =+BD18+BE18+BF18+BG18 -> 705 | BI18: 34 | BJ18: 116 | BK18: 251 | BL18: 360 | BM18: =+BI18+BJ18+BK18+BL18 -> 761 | BO18: =+R18+W18+AB18+AH18+AM18+AR18+AX18+BC18+BH18+BM18 -> 8028 | BQ18: =+AVERAGE(R18,W18,AB18,AH18,AM18,AR18,AX18,BC18,BH18,BM18) -> 802.8 | BR18: 761 | BS18: =+BR18-BM18 -> 0 | BU18: EDP | BV18: 669.095 | BW18: 891.9687 | BX18: 693.81329 | BY18: 722.43473 | BZ18: 755.657 | CA18: 1204.9966 | CB18: 762.70685 | CC18: 5700.6722
B19: EC | C19: 6 | E19: #
E20: kUS$
B21: EC | C21: 6.1 | D21: Pendientes (En proceso de aprobación) | E21: # | M21: 0 | N21: 4 | O21: 2 | P21: 2 | Q21: 0 | R21: =+Q21 -> 0 | S21: 10 | T21: 7 | U21: 7 | V21: 17 | W21: =+V21 -> 17 | X21: 14 | Y21: 12 | Z21: 6 | AA21: 6 | AB21: =+AA21 -> 6 | AC21: 11 | AD21: 8 | AE21: 9 | AF21: 5 | AG21: 2 | AH21: =+AG21 -> 2 | AI21: 6 | AJ21: 5 | AK21: 5 | AL21: 4 | AM21: =+AL21 -> 4 | AN21: 10 | AO21: 8 | AP21: 6 | AQ21: 3 | AR21: =+AQ21 -> 3 | AS21: 10 | AT21: 6 | AU21: 4 | AV21: 2 | AW21: 2 | AX21: =+AW21 -> 2 | AY21: 5 | AZ21: 3 | BA21: 3 | BB21: 2 | BC21: =+BB21 -> 2 | BD21: 7 | BE21: 7 | BF21: 5 | BG21: 3 | BH21: =+BG21 -> 3 | BI21: 7 | BJ21: 10 | BK21: 8 | BL21: 6 | BM21: =+BL21 -> 6 | BN21: =+IFERROR(BM22/BM21,0) -> 21.333333 | BO21: =+BM21 -> 6 | BP21: =+BO22/BO21 -> 21.333333
E22: kUS$ | N22: 192 | O22: 43 | P22: 43 | Q22: 0 | R22: =+Q22 -> 0 | S22: 175 | T22: 158 | U22: 158 | V22: 831 | W22: =+V22 -> 831 | X22: 653 | Y22: 568 | Z22: 250 | AA22: 250 | AB22: =+AA22 -> 250 | AC22: 478 | AD22: 430 | AE22: 440 | AF22: 285 | AG22: 73 | AH22: =+AG22 -> 73 | AI22: 330 | AJ22: 259 | AK22: 259 | AL22: 183 | AM22: =+AL22 -> 183 | AN22: 1037 | AO22: 953 | AP22: 834 | AQ22: 681 | AR22: =+AQ22 -> 681 | AS22: 801 | AT22: 692 | AU22: 633 | AV22: 568 | AW22: 568 | AX22: =+AW22 -> 568 | AY22: 254 | AZ22: 84 | BA22: 84 | BB22: 50 | BC22: =+BB22 -> 50 | BD22: 351 | BE22: 478 | BF22: 258 | BG22: 53 | BH22: =+BG22 -> 53 | BI22: 334 | BJ22: 419 | BK22: 360 | BL22: 128 | BM22: =+BL22 -> 128 | BO22: =+BM22 -> 128 | BU22: Factura | BV22: 822.535 | BW22: 313.029 | BX22: 798.15916 | BY22: 702.12786 | BZ22: 916.262 | CA22: 802.653 | CB22: 795.33726 | CC22: 751.57259
B23: EC | C23: 6.2 | D23: Rezagados | E23: # | J23: 1 | K23: 3 | L23: =+SUM(I23:K23) -> 4 | M23: =+L24/L23 -> 23.5 | N23: 2 | O23: 2 | P23: 1 | Q23: 1 | R23: =+Q23 -> 1 | S23: 1 | T23: 2 | U23: 1 | V23: =1+6 -> 7 | W23: =+V23 -> 7 | X23: =1+5 -> 6 | Y23: 5 | Z23: 5 | AA23: 5 | AB23: =+AA23 -> 5 | AC23: 10 | AD23: 9 | AE23: 5 | AF23: 5 | AG23: 4 | AH23: =+AG23 -> 4 | AI23: 3 | AJ23: 2 | AK23: 2 | AL23: 2 | AM23: =+AL23 -> 2 | AN23: 6 | AO23: 4 | AP23: 4 | AQ23: 4 | AR23: =+AQ23 -> 4 | AS23: 5 | AT23: 4 | AU23: 4 | AV23: 3 | AW23: 3 | AX23: =+AW23 -> 3 | AY23: 4 | AZ23: 1 | BA23: 1 | BB23: 1 | BC23: =+BB23 -> 1 | BD23: 3 | BE23: 3 | BF23: 3 | BG23: 3 | BH23: =+BG23 -> 3 | BI23: 6 | BJ23: 4 | BK23: 4 | BL23: 4 | BM23: =+BL23 -> 4 | BN23: =+IFERROR(BM24/BM23,0) -> 15.5 | BO23: =+BM23 -> 4 | BP23: =+BO24/BO23 -> 15.5
E24: kUS$ | J24: 35 | K24: 59 | L24: =+SUM(I24:K24) -> 94 | N24: 70 | O24: 70 | P24: 35 | Q24: 35 | R24: =+Q24 -> 35 | S24: 35 | T24: =35+71 -> 106 | U24: 35 | V24: =35+124 -> 159 | W24: =+V24 -> 159 | X24: =35+100 -> 135 | Y24: 101 | Z24: 101 | AA24: 101 | AB24: =+AA24 -> 101 | AC24: 326 | AD24: 276 | AE24: 201 | AF24: 201 | AG24: 88 | AH24: =+AG24 -> 88 | AI24: 67 | AJ24: =29+15 -> 44 | AK24: 44 | AL24: 44 | AM24: =+AL24 -> 44 | AN24: 227 | AO24: =29+113 -> 142 | AP24: 142 | AQ24: =113+29 -> 142 | AR24: =+AQ24 -> 142 | AS24: 548 | AT24: 493 | AU24: 493 | AV24: 76.3 | AW24: 76 | AX24: =+AW24 -> 76 | AY24: 190 | AZ24: 29 | BA24: 29 | BB24: 29 | BC24: =+BB24 -> 29 | BD24: 79 | BE24: 79 | BF24: 79 | BG24: 79 | BH24: =+BG24 -> 79 | BI24: 132 | BJ24: 62 | BK24: 62 | BL24: 62 | BM24: =+BL24 -> 62 | BO24: =+BM24 -> 62 | BU24: Ingreso | BV24: 724.71915 | BW24: 932.41047 | BX24: 785.48233 | BY24: 611.32257 | BZ24: 666.9483 | CA24: 796.9543 | CB24: 894.28984
B25: IM | C25: 7 | D25: Gasto Operacional | E25: kUS$ | R25: 522 | W25: 534 | AB25: 618 | AH25: 555 | AM25: 566 | AR25: 640 | AX25: 630 | BC25: 665 | BD25: 0 | BE25: 0 | BF25: 0 | BG25: 0 | BH25: 648 | BM25: 581 | BN25: =+BM25 -> 581 | BO25: =+R25+W25+AB25+AH25+AM25+AR25+AX25+BC25+BH25+BM25 -> 5959 | BP25: =+BO25/10 -> 595.9 | BQ25: =+AVERAGE(R25,W25,AB25,AH25,AM25,AR25,AX25,BC25,BH25,BM25) -> 595.9
B26: IM | C26: 8 | D26: Facturas Pagadas (Ingreso Operacional) | E26: # | I26: 25 | J26: 15 | K26: 15 | L26: =+SUM(I26:K26) -> 55 | M26: =+L27/L26 -> 38.109091 | N26: 4 | O26: 4 | P26: 8 | Q26: 4 | R26: 22 | S26: 2 | T26: 6 | U26: =5+2 -> 7 | V26: =3+3+1 -> 7 | W26: 20 | X26: 3 | Y26: 5 | Z26: 4 | AA26: =3+2+1 -> 6 | AB26: 16 | AC26: 2 | AD26: =5-1 -> 4 | AE26: 1 | AF26: 4 | AG26: 1 | AH26: =+AC26+AD26+AE26+AF26+AG26 -> 12 | AI26: 2 | AJ26: 3 | AK26: 7 | AL26: 8 | AM26: =+AI26+AJ26+AK26+AL26 -> 20 | AN26: 4 | AO26: 4 | AP26: 5 | AQ26: 5 | AR26: =+AN26+AO26+AP26+AQ26 -> 18 | AS26: 5 | AT26: 5 | AU26: 3 | AV26: 2 | AW26: =2+1 -> 3 | AX26: =+AS26+AT26+AU26+AV26+AW26 -> 18 | AY26: 5 | AZ26: 2 | BA26: 4 | BB26: 7 | BC26: =+AY26+AZ26+BA26+BB26 -> 18 | BD26: 1 | BE26: 3 | BF26: 5 | BG26: =6 -> 6 | BH26: =+BD26+BE26+BF26+BG26 -> 15 | BI26: 0 | BJ26: 0 | BK26: 7 | BL26: 9 | BM26: =+BI26+BJ26+BK26+BL26 -> 16 | BN26: =+IFERROR(BM27/BM26,0) -> 45.5625 | BO26: =+R26+W26+AB26+AH26+AM26+AR26+AX26+BC26+BH26+BM26 -> 175 | BP26: =+BO27/BO26 -> 43.32 | BR26: 16 | BS26: =+BR26-BM26 -> 0
E27: kUS$ | I27: 1004 | J27: 616 | K27: 476 | L27: =+SUM(I27:K27) -> 2096 | N27: 197 | O27: 83 | P27: 269 | Q27: 157 | R27: 724 | S27: 46 | T27: 261 | U27: =181+160 -> 341 | V27: =152+87+22 -> 261 | W27: 932 | X27: =96270/1000 -> 96.27 | Y27: 132 | Z27: 253.73 | AA27: =197+51+29 -> 277 | AB27: =785-5 -> 780 | AC27: 35 | AD27: 346 | AE27: 42 | AF27: 105 | AG27: 83 | AH27: =+AC27+AD27+AE27+AF27+AG27-10 -> 601 | AI27: 123 | AJ27: 121 | AK27: 171 | AL27: 233 | AM27: =667-39 -> 628 | AN27: 345 | AO27: 121 | AP27: 195 | AQ27: 125 | AR27: 797 | AS27: 219 | AT27: 123 | AU27: 241 | AV27: 47 | AW27: =127+137 -> 264 | AX27: =+AS27+AT27+AU27+AV27+AW27-67 -> 827 | AY27: 163 | AZ27: 59 | BA27: 550 | BB27: 213 | BC27: =+AY27+AZ27+BA27+BB27-36 -> 949 | BD27: 112 | BE27: 103 | BF27: 308 | BG27: =33+61-3 -> 91 | BH27: =+BD27+BE27+BF27+BG27 -> 614 | BI27: 0 | BJ27: 0 | BK27: 307 | BL27: 422 | BM27: =+BI27+BJ27+BK27+BL27 -> 729 | BO27: =+R27+W27+AB27+AH27+AM27+AR27+AX27+BC27+BH27+BM27 -> 7581 | BQ27: =+AVERAGE(R27,W27,AB27,AH27,AM27,AR27,AX27,BC27,BH27,BM27) -> 758.1 | BR27: 729 | BS27: =+BR27-BM27 -> 0
B28: IM | C28: 9 | D28: Facturas Vencidas | E28: # | K28: 8 | L28: =+SUM(I28:K28) -> 8 | M28: =+L29/L28 -> 35.75 | N28: 5 | O28: 3 | P28: 2 | Q28: 5 | R28: =+Q28 -> 5 | S28: 5 | T28: 6 | U28: 3 | V28: 3 | W28: =+V28 -> 3 | X28: 3 | Y28: 1 | Z28: 2 | AA28: 2 | AB28: =+AA28 -> 2 | AC28: 2 | AD28: 2 | AE28: 2 | AF28: 2 | AG28: 2 | AH28: =+AG28 -> 2 | AI28: 2 | AJ28: 6 | AK28: 4 | AL28: 3 | AM28: =+AL28 -> 3 | AN28: 3 | AO28: 6 | AP28: 5 | AQ28: 3 | AR28: =+AQ28 -> 3 | AS28: 2 | AT28: 1 | AU28: 1 | AV28: 1 | AW28: 4 | AX28: =+AW28 -> 4 | AY28: 2 | AZ28: 5 | BA28: 4 | BB28: 4 | BC28: =+BB28 -> 4 | BD28: 4 | BE28: 6 | BF28: 6 | BG28: 5 | BH28: =+BG28 -> 5 | BI28: 5 | BJ28: 5 | BK28: 6 | BL28: 5 | BM28: =+BL28 -> 5 | BN28: =+IFERROR(BM29/BM28,0) -> 65.4 | BO28: =+BM28 -> 5 | BP28: =+IFERROR(BO29/BO28,0) -> 65.4
E29: KUS$ | K29: 286 | L29: =+SUM(I29:K29) -> 286 | N29: 110 | O29: 60 | P29: 26.8 | Q29: =227+27 -> 254 | R29: =+Q29 -> 254 | S29: 254 | T29: 213 | U29: 109 | V29: 109 | W29: =+V29 -> 109 | X29: 109 | Y29: 5.2 | Z29: 29 | AA29: 29 | AB29: =+AA29 -> 29 | AC29: 29 | AD29: 29 | AE29: 29 | AF29: 29 | AG29: 29 | AH29: =+AG29 -> 29 | AI29: 29 | AJ29: 198 | AK29: 162 | AL29: 61 | AM29: =+AL29 -> 61 | AN29: 61 | AO29: 225 | AP29: 99 | AQ29: 83 | AR29: =+AQ29 -> 83 | AS29: 10 | AT29: 5 | AU29: 5 | AV29: 5 | AW29: 78 | AX29: =+AW29 -> 78 | AY29: 15 | AZ29: 261 | BA29: 239 | BB29: 239 | BC29: =+BB29 -> 239 | BD29: 218 | BE29: 406 | BF29: 406 | BG29: 367 | BH29: =+BG29 -> 367 | BI29: 367 | BJ29: 367 | BK29: 387 | BL29: 327 | BM29: =+BL29 -> 327 | BO29: =+BM29 -> 327
B30: EC | C30: 10 | D30: Cumplimiento POM vs EDP | E30: % | I30: =+IFERROR(I16/I14,0) -> 1.0213178 | J30: =+IFERROR(J16/J14,0) -> 0.65797546 | K30: =+IFERROR(K16/K14,0) -> 1.0653009 | L30: =+AVERAGE(I30:K30) -> 0.91486473 | M30: =+L30 -> 0.91486473 | N30: - | O30: =+IFERROR(O16/O14,0) -> 0.11405836 | P30: =+IFERROR(P16/P14,0) -> 0.36350975 | Q30: =+IFERROR(Q16/Q14,0) -> 0.44846797 | R30: =+IFERROR(R16/R14,0) -> 0.93175487 | S30: 0 | T30: 0 | U30: 0 | V30: 0 | W30: =+IFERROR(W16/W14,0) -> 1.021764 | X30: 0 | Y30: 0 | Z30: 0 | AA30: 0 | AB30: =+IFERROR(AB16/AB14,0) -> 0.85573366 | AC30: 0 | AD30: 0 | AE30: 0 | AF30: 0 | AG30: 0 | AH30: =+IFERROR(AH16/AH14,0) -> 1.1522095 | AI30: 0 | AJ30: 0 | AK30: 0 | AL30: 0 | AM30: =+IFERROR(AM16/AM14,0) -> 0.87529976 | AN30: 0 | AO30: 0 | AP30: 0 | AQ30: 0 | AR30: =+IFERROR(AR16/AR14,0) -> 1.2945055 | AS30: 0 | AT30: 0 | AU30: 0 | AV30: 0 | AW30: 0 | AX30: =+IFERROR(AX16/AX14,0) -> 0.94409149 | AY30: 0 | AZ30: 0 | BA30: 0 | BB30: 0 | BC30: =+IFERROR(BC16/BC14,0) -> 0.85140998 | BD30: 0 | BE30: 0 | BF30: 0 | BG30: 0 | BH30: =+IFERROR(BH16/BH14,0) -> 0.88176101 | BI30: 0 | BJ30: 0 | BK30: 0 | BL30: 0 | BM30: =+IFERROR(BM16/BM14,0) -> 0.90326241 | BN30: =+BM30 -> 0.90326241 | BO30: =+AVERAGE(R30,W30,AB30,AH30,AM30,AR30,AX30,BC30,BH30,BM30) -> 0.97117922 | BP30: =+BO30 -> 0.97117922
B31: EC | C31: 11 | D31: Adherencia POM vs EDP | E31: % | I31: 0.73 | J31: 0.67 | K31: 0.76 | L31: =+AVERAGE(I31:K31) -> 0.72 | M31: =+L31 -> 0.72 | N31: - | O31: - | P31: - | Q31: - | R31: 0.81 | S31: 0 | T31: 0 | U31: 0 | V31: 0 | W31: 0.83 | X31: 0 | Y31: 0 | Z31: 0 | AA31: 0 | AB31: 0.7 | AC31: 0 | AD31: 0 | AE31: 0 | AF31: 0 | AG31: 0 | AH31: 0.69 | AI31: 0 | AJ31: 0 | AK31: 0 | AL31: 0 | AM31: 0.77 | AN31: 0 | AO31: 0 | AP31: 0 | AQ31: 0 | AR31: 0.92 | AS31: 0 | AT31: 0 | AU31: 0 | AV31: 0 | AW31: 0 | AX31: 0.65 | AY31: 0 | AZ31: 0 | BA31: 0 | BB31: 0 | BC31: 0.54 | BD31: 0 | BE31: 0 | BF31: 0 | BG31: 0 | BH31: 0.59 | BI31: 0 | BJ31: 0 | BK31: 0 | BL31: 0 | BM31: 0.68 | BN31: =+BM31 -> 0.68 | BO31: =+AVERAGE(R31,W31,AB31,AH31,AM31,AR31,AX31,BC31,BH31,BM31) -> 0.718 | BP31: =+BO31 -> 0.718
AC33: 2 | AD33: 6 | AE33: 1 | AF33: 4
AC34: 98 | AD34: 346 | AE34: 42 | AF34: 65 | BO34: =+BO27-BO25 -> 1622
BO35: =+BO34/BO27 -> 0.21395594
AO38: =6677-6537 -> 140

Sheet Modulo 2025
B1: 45566 | C1: 45597 | D1: 45627 | E1: 45658 | F1: 45689 | G1: 45717
A2: Emitido | B2: 527 | C2: 429 | D2: 832 | E2: 667 | F2: 928 | G2: 718 | H2: =+AVERAGE(B2:F2) -> 676.6 | J2: =+H2*12 -> 8119.2
A3: Facturado | B3: 864 | C3: 493 | D3: 521 | E3: 859 | F3: 394 | G3: 788 | H3: =+AVERAGE(B3:F3) -> 626.2 | J3: =+H3*12 -> 7514.4
A4: Ingresado | B4: 1004 | C4: 616 | D4: 476 | E4: 706 | F4: 887 | G4: 403 | H4: =+AVERAGE(B4:F4) -> 737.8 | J4: =+H4*12 -> 8853.6
A6: Remanente | D6: 2900 | E6: 2300 | F6: 3541 | G6: =+F6-G2 -> 2823
B28: Item | C28: Módulo | D28: Liquido USD | E28: Bruto USD | F28: Módulo USD | G28: % | I28: Dotación | J28: Meses
B29: Director | C29: 0.3 | D29: 6500 | E29: =+D29*1.3 -> 8450 | F29: =+C29*E29 -> 2535 | I29: =+ROUNDUP(C29*$F$47,0) -> 8 | J29: 12 | L29: 7.5
B30: Ing Ppal | C30: 0.5 | D30: 4500 | E30: =+D30*1.3 -> 5850 | F30: =+C30*E30 -> 2925 | I30: =+ROUNDUP(C30*$F$47,0) -> 13 | L30: 12.5
B31: Ing Proy | C31: 1.76 | D31: 2500 | E31: =+D31*1.3 -> 3250 | F31: =+C31*E31 -> 5720 | I31: =+ROUNDUP(C31*$F$47,0) -> 44 | L31: 44
B32: Ing Senior | C32: 0.3 | D32: 4000 | E32: =+D32*1.3 -> 5200 | F32: =+C32*E32 -> 1560 | I32: =+ROUNDUP(C32*$F$47,0) -> 8 | L32: 7.5
B33: Gerente | C33: 0.1 | D33: 7500 | E33: =+D33*1.3 -> 9750 | F33: =+C33*E33 -> 975 | I33: =+ROUNDUP(C33*$F$47,0) -> 3 | L33: 2.5
B34: Total | F34: =SUM(F29:F33) -> 13715 | I34: =SUM(I29:I33) -> 76
N35: Sueldos | O35: 380000 | P35: 1
E36: COSTO TOTAL MÓDULO
E37: Item | F37: USD | G37: % | N37: Overhead | O37: 70000 | P37: =+O37/O35 -> 0.18421053 | Q37: =+Q39*P37/P39 -> 3096.9355
E38: Directo | F38: =SUM(F34) -> 13715 | G38: 0.82 | I38: =+F38*$F$47 -> 342875
E39: Overhead | F39: =+F38*P37/P39 -> 3096.9355 | G39: 0.18 | I39: =+F39*$F$47 -> 77423.387 | N39: Ingeniería | O39: =+O35-O37 -> 310000 | P39: =1-P37 -> 0.81578947 | Q39: =+F38 -> 13715
E40: MO | F40: =SUM(F38:F39) -> 16811.935 | G40: 0.7 | I40: =+F40*$F$47 -> 420298.39
E41: Tercero | F41: =+F40*G41/G40 -> 2401.7051 | G41: 0.1 | I41: =+F41*$F$47 -> 60042.627
E42: Operación | F42: =+F40*G42/G40 -> 3122.2166 | G42: 0.13 | I42: =+F42*$F$47 -> 78055.415
E43: Admin | F43: =+F40*G43/G40 -> 1200.8525 | G43: 0.05 | I43: =+F43*$F$47 -> 30021.313
E44: Otros | F44: =+F40*G44/G40 -> 480.34101 | G44: 0.02 | I44: =+F44*$F$47 -> 12008.525
E45: TOTAL | F45: =SUM(F40:F44) -> 24017.051 | G45: =SUM(G40:G44) -> 1
E47: Modulos | F47: 25
E49: Gasto | F49: =+F45*F47 -> 600426.27 | G49: =+F49*J29 -> 7205115.2 | I49: =+SUM(F41:F44)*F47 -> 180127.88 | L49: =+G40*$G$49 -> 5043580.6
L50: =+G41*$G$49 -> 720511.52
E51: Ingreso | F51: =+I51*F47 -> 800000 | G51: =+F51*J29 -> 9600000 | I51: =9600000/(J29*F47) -> 32000 | L51: =+G42*$G$49 -> 936664.98
L52: =+G43*$G$49 -> 360255.76
E53: EBITDA | F53: =+F51-F49 -> 199573.73 | G53: =+F53/F51 -> 0.24946717 | L53: =+G44*$G$49 -> 144102.3

Sheet Compromisos
A1: # | B1: Acción | C1: Responsable | D1: Fecha | E1: Estatus
A2: 1 | B2: Replantear el enfoque de reunión comercial con Country Managers | C2: A.Fraser | D2: 46020 | E2: En proceso
A3: =1+A2 -> 2 | B3: Definir estrategia para abordar Paloma Sulfato (internamente) | C3: A.Fraser | D3: 46021 | E3: Pendiente
A4: =1+A3 -> 3 | B4: Enviar términos y condiciones de propuestas comerciales | C4: A.Fraser | D4: 46013 | E4: Realizado
A5: =1+A4 -> 4 | B5: Actualizar información comercial (adjudicado y cierre contractual) | C5: P.Aguiluz | D5: 46020 | E5: Realizado
A6: =1+A5 -> 5 | B6: Aplicar cuociente monto/meses a propuestas comerciales en seguimiento | C6: P.Aguiluz | D6: 46020 | E6: En proceso
A7: =1+A6 -> 6 | B7: Asignar prioridades a propuestas comerciales enviadas para definir foco | C7: P.Aguiluz | D7: 46020 | E7: Realizado

Sheet KPI´s de negocio 2025
B2: Resp. | C2: # | D2: Ítem | E2: Unidad | F2: 45474 | G2: 45505 | H2: 45536 | I2: 45566 | J2: 45597 | K2: 45627 | L2: Q4-24 | M2: Media Q4 2024 | N2: S1 | O2: S2 | P2: S3 | Q2: S4 | R2: 45658 | S2: S1 feb-25 | T2: S2 feb-25 | U2: S3 feb-25 | V2: S4 feb-25 | W2: 45689 | X2: S1 mar-25 | Y2: S2 mar-25 | Z2: S3 mar-25 | AA2: S4 mar-25 | AB2: 45717 | AC2: S1 abr-25 | AD2: S2 abr-25 | AE2: S3 abr-25 | AF2: S4 abr-25 | AG2: S5 abril-25 | AH2: 45748 | AI2: S1 may-25 | AJ2: S2 may-25 | AK2: S3 may-25 | AL2: S4 may-25 | AM2: 45778 | AN2: S1 Jun-25 | AO2: S2 Jun-25 | AP2: S3 Jun-25 | AQ2: S4 Jun-25 | AR2: 45809 | AS2: S1 Jul-25 | AT2: S2 Jul-25 | AU2: S3 Jul-25 | AV2: S4 Jul-25 | AW2: S5 Jul-25 | AX2: 45839 | AY2: S1 ago-25 | AZ2: S2 ago-25 | BA2: S3 ago-25 | BB2: S4 ago-25 | BC2: 45870 | BD2: S1 sep-25 | BE2: S2 sep-25 | BF2: S3 sep-25 | BG2: S4 sep-25 | BH2: 45901 | BI2: S1 oct-25 | BJ2: S2 oct-25 | BK2: S3 oct-25 | BL2: S4 oct-25 | BM2: S5 oct-25 | BN2: 45931 | BO2: S1 | BP2: S2 | BQ2: S3 | BR2: S4 | BS2: 45962 | BT2: S1 | BU2: S2 | BV2: S3 | BW2: S4 | BX2: S5 | BY2: 45992 | BZ2: Media dic | CA2: Acum. 2025 | CB2: Media Acum. | CC2: =+CA4/CA3 -> 266.19512 | CG2: Item | CH2: kUS$ | CI2: Rezagado
B3: PA | C3: 1 | D3: Propuestas Emitidas | E3: # | F3: =8+8 -> 16 | H3: 6 | I3: =8+I5 -> 12 | J3: =9+J5 -> 15 | K3: =7+K5 -> 15 | L3: =+SUM(I3:K3) -> 42 | M3: =+L4/L3 -> 236.30952 | N3: 1 | O3: 3 | P3: 3 | Q3: 1 | R3: =+N3+O3+P3+Q3 -> 8 | S3: 3 | T3: 2 | U3: 2 | V3: 3 | W3: =+S3+T3+U3+V3 -> 10 | X3: 5 | Y3: 2 | Z3: 3 | AA3: 1 | AB3: =+X3+Y3+Z3+AA3 -> 11 | AC3: 0 | AD3: 9 | AE3: 2 | AF3: 5 | AG3: 2 | AH3: =+AC3+AD3+AE3+AF3+AG3 -> 18 | AI3: 2 | AJ3: 2 | AK3: 3 | AL3: 1 | AM3: =+AI3+AJ3+AK3+AL3 -> 8 | AN3: 3 | AO3: 9 | AP3: 3 | AQ3: 6 | AR3: =+AN3+AO3+AP3+AQ3 -> 21 | AS3: 4 | AT3: 4 | AU3: 6 | AV3: 3 | AW3: 3 | AX3: =+AS3+AT3+AU3+AV3+AW3 -> 20 | AY3: 4 | AZ3: 2 | BA3: 5 | BB3: 1 | BC3: =+AY3+AZ3+BA3+BB3 -> 12 | BD3: 2 | BE3: 5 | BF3: 2 | BG3: 1 | BH3: =+BD3+BE3+BF3+BG3 -> 10 | BI3: 0 | BJ3: 4 | BK3: 2 | BL3: 2 | BM3: 1 | BN3: =+BI3+BJ3+BK3+BL3+BM3 -> 9 | BO3: 3 | BP3: 2 | BQ3: 6 | BR3: 8 | BS3: =+BO3+BP3+BQ3+BR3 -> 19 | BT3: 6 | BU3: 6 | BV3: 5 | BW3: 0 | BX3: 1 | BY3: =+BT3+BU3+BV3+BW3+BX3 -> 18 | BZ3: =+IFERROR(BY4/BY3,0) -> 203.5 | CA3: =+R3+W3+AB3+AH3+AM3+AR3+AX3+BC3+BH3+BN3+BS3+BY3 -> 164 | CB3: =+CA4/CA3 -> 266.19512 | CD3: 9 | CG3: Ingreso Operacional | CH3: =+CA14 -> 9025
E4: kUS$ | F4: =1062+F6 -> 1735 | H4: =453+300 -> 753 | I4: =1600+I6 -> 1999 | J4: =2455+J6 -> 3967 | K4: =2600+K6 -> 3959 | L4: =+SUM(I4:K4) -> 9925 | N4: 200 | O4: 1400 | P4: 470 | Q4: 142 | R4: =+N4+O4+P4+Q4 -> 2212 | S4: 971 | T4: 100 | U4: =950+150 -> 1100 | V4: 400 | W4: =+S4+T4+U4+V4 -> 2571 | X4: 570 | Y4: 200 | Z4: 1500 | AA4: 3860 | AB4: =+X4+Y4+Z4+AA4 -> 6130 | AC4: 0 | AD4: 1288 | AE4: 500 | AF4: 2225 | AG4: =165+200 -> 365 | AH4: =+AC4+AD4+AE4+AF4+AG4 -> 4378 | AI4: 537 | AJ4: =180+190 -> 370 | AK4: =1500+150+21 -> 1671 | AL4: 448 | AM4: =+AI4+AJ4+AK4+AL4 -> 3026 | AN4: 625 | AO4: 6230 | AP4: 440 | AQ4: 770 | AR4: =+AN4+AO4+AP4+AQ4 -> 8065 | AS4: 345 | AT4: 530 | AU4: 800 | AV4: 360 | AW4: 262 | AX4: =+AS4+AT4+AU4+AV4+AW4 -> 2297 | AY4: 638 | AZ4: 124 | BA4: 975 | BB4: 52 | BC4: =+AY4+AZ4+BA4+BB4 -> 1789 | BD4: =380+84 -> 464 | BE4: 637 | BF4: =590-226 -> 364 | BG4: 100 | BH4: =+BD4+BE4+BF4+BG4 -> 1565 | BI4: 0 | BJ4: 665 | BK4: 2365 | BL4: =125+175 -> 300 | BM4: 185 | BN4: =+BI4+BJ4+BK4+BL4+BM4 -> 3515 | BO4: 1295 | BP4: =180+48 -> 228 | BQ4: 1077 | BR4: 1845 | BS4: =+BO4+BP4+BQ4+BR4 -> 4445 | BT4: 1410 | BU4: 1065 | BV4: 688 | BW4: 0 | BX4: 500 | BY4: =+BT4+BU4+BV4+BW4+BX4 -> 3663 | CA4: =+R4+W4+AB4+AH4+AM4+AR4+AX4+BC4+BH4+BN4+BS4+BY4 -> 43656 | CC4: =+AVERAGE(R4,W4,AB4,AH4,AM4,AR4,AX4,BC4,BH4,BN4,BS4) -> 3635.7273 | CD4: 1465 | CE4: =+CD4-BH4 -> -100 | CG4: Facturas por cobrar | CH4: =+CA25 -> 1462 | CI4: =+BY27 -> 822
B5: PA | C5: 2 | D5: Propuestas Adjudicadas | E5: # | F5: 8 | G5: 6 | H5: 3 | I5: 4 | J5: 6 | K5: 8 | L5: =+SUM(I5:K5) -> 18 | M5: =+L6/L5 -> 181.66667 | N5: 4 | O5: 2 | P5: 2 | Q5: 0 | R5: =+N5+O5+P5+Q5 -> 8 | S5: 2 | T5: 3 | V5: 1 | W5: =+S5+T5+U5+V5 -> 6 | X5: 1 | Y5: 1 | Z5: 4 | AA5: 2 | AB5: =+X5+Y5+Z5+AA5 -> 8 | AC5: 0 | AD5: 2 | AE5: 1 | AF5: 1 | AG5: 3 | AH5: =+AC5+AD5+AE5+AF5+AG5 -> 7 | AI5: 1 | AJ5: 1 | AK5: 1 | AL5: 1 | AM5: =+AI5+AJ5+AK5+AL5 -> 4 | AN5: 0 | AO5: 3 | AP5: 1 | AQ5: 4 | AR5: =+AN5+AO5+AP5+AQ5 -> 8 | AS5: 1 | AT5: 1 | AU5: 3 | AV5: 2 | AW5: 2 | AX5: =+AS5+AT5+AU5+AV5+AW5 -> 9 | AY5: 1 | AZ5: 2 | BA5: 3 | BB5: 2 | BC5: =+AY5+AZ5+BA5+BB5 -> 8 | BD5: 0 | BE5: 3 | BF5: 0 | BG5: 1 | BH5: =+BD5+BE5+BF5+BG5 -> 4 | BI5: 0 | BJ5: 1 | BK5: 0 | BL5: 2 | BM5: 3 | BN5: =+BI5+BJ5+BK5+BL5+BM5 -> 6 | BO5: 0 | BP5: 0 | BQ5: 2 | BR5: 1 | BS5: =+BO5+BP5+BQ5+BR5 -> 3 | BT5: 1 | BU5: 2 | BV5: 2 | BW5: 1 | BX5: 1 | BY5: =+BT5+BU5+BV5+BW5+BX5 -> 7 | BZ5: =+IFERROR(BY6/BY5,0) -> 186.57143 | CA5: =+R5+W5+AB5+AH5+AM5+AR5+AX5+BC5+BH5+BN5+BS5+BY5 -> 78 | CB5: =+CA6/CA5 -> 131.74359 | CD5: 4 | CG5: EDP por facturar | CH5: =+CA19 -> 245 | CI5: =+BY23 -> 159
E6: kUS$ | F6: 673 | G6: 524 | H6: 300 | I6: 399 | J6: =+Respaldo!I25 -> 1512 | K6: =+Respaldo!I31 -> 1359 | L6: =+SUM(I6:K6) -> 3270 | N6: 690 | O6: 240 | P6: 126 | Q6: 0 | R6: =+N6+O6+P6+Q6 -> 1056 | S6: =1035+120 -> 1155 | T6: 91 | V6: 0 | W6: =+S6+T6+U6+V6 -> 1246 | X6: 20 | Y6: 65 | Z6: 563 | AA6: 88 | AB6: =+X6+Y6+Z6+AA6 -> 736 | AC6: 0 | AD6: 94 | AE6: 60 | AF6: =1114-650-60-94 -> 310 | AG6: =300+200+50 -> 550 | AH6: =+AC6+AD6+AE6+AF6+AG6 -> 1014 | AI6: 490 | AJ6: 262 | AK6: 21 | AL6: 195 | AM6: =+AI6+AJ6+AK6+AL6 -> 968 | AN6: 0 | AO6: 348 | AP6: 25 | AQ6: =286+37 -> 323 | AR6: =+AN6+AO6+AP6+AQ6 -> 696 | AS6: 80 | AT6: 23 | AU6: 119 | AV6: 113 | AW6: 324 | AX6: =+AS6+AT6+AU6+AV6+AW6 -> 659 | AY6: 135 | AZ6: =140+16 -> 156 | BA6: 485 | BB6: 120 | BC6: =+AY6+AZ6+BA6+BB6 -> 896 | BD6: 0 | BE6: 446 | BF6: 0 | BG6: 190 | BH6: =+BD6+BE6+BF6+BG6 -> 636 | BI6: 0 | BJ6: 140 | BK6: 0 | BL6: 205 | BM6: 118 | BN6: =+BI6+BJ6+BK6+BL6+BM6 -> 463 | BO6: 0 | BP6: 0 | BQ6: 249 | BR6: 351 | BS6: =+BO6+BP6+BQ6+BR6 -> 600 | BT6: 445 | BU6: 251 | BV6: 295 | BW6: 285 | BX6: 30 | BY6: =+BT6+BU6+BV6+BW6+BX6 -> 1306 | CA6: =+R6+W6+AB6+AH6+AM6+AR6+AX6+BC6+BH6+BN6+BS6+BY6 -> 10276 | CC6: =+AVERAGE(R6,W6,AB6,AH6,AM6,AR6,AX6,BC6,BH6,BN6,BS6) -> 815.45455 | CD6: 991 | CE6: =+CD6-BY6 -> -315 | CG6: Total | CH6: =SUM(CH3:CH5) -> 10732 | CI6: =SUM(CI3:CI5) -> 981
B7: EC | C7: 3 | D7: POM | E7: # | I7: 14 | J7: 24 | K7: 23 | L7: =+SUM(I7:K7) -> 61 | M7: =+L8/L7 -> 31.95082 | N7: 22 | O7: 22 | P7: 22 | Q7: 21 | R7: =+Q7 -> 21 | S7: 16 | T7: 5 | U7: 0 | V7: 0 | W7: =+S7+T7+U7+V7 -> 21 | X7: 19 | Y7: 3 | Z7: 0 | AA7: 0 | AB7: =+X7+Y7+Z7+AA7 -> 22 | AC7: 9 | AD7: 4 | AE7: 0 | AF7: 0 | AG7: 0 | AH7: =AC7+AD7+AE7+AF7+AG7 -> 13 | AI7: 14 | AJ7: 3 | AK7: 0 | AL7: 0 | AM7: =+AI7+AJ7+AK7+AL7 -> 17 | AN7: 12 | AO7: 2 | AP7: 0 | AQ7: 0 | AR7: =+AN7+AO7+AP7+AQ7 -> 14 | AS7: 18 | AT7: 0 | AU7: 0 | AV7: 0 | AW7: 0 | AX7: =+AS7+AT7+AU7+AV7+AW7 -> 18 | AY7: 22 | AZ7: 0 | BA7: 0 | BB7: 0 | BC7: =+AY7+AZ7+BA7+BB7 -> 22 | BD7: 25 | BE7: 1 | BF7: 0 | BG7: -2 | BH7: =+BD7+BE7+BF7+BG7 -> 24 | BI7: 23 | BJ7: -4 | BK7: 4 | BL7: -2 | BM7: 0 | BN7: =+BI7+BJ7+BK7+BL7+BM7 -> 21 | BO7: 18 | BP7: 0 | BQ7: 0 | BR7: 0 | BS7: =+BO7+BP7+BQ7+BR7 -> 18 | BT7: 13 | BU7: 0 | BV7: -2 | BW7: 0 | BX7: 0 | BY7: =+BT7+BU7+BV7+BW7+BX7 -> 11 | BZ7: =+IFERROR(BY8/BY7,0) -> 38.454545 | CA7: =+R7+W7+AB7+AH7+AM7+AR7+AX7+BC7+BH7+BN7+BS7+BY7 -> 222 | CB7: =+CA8/CA7 -> 40.707207 | CD7: 11 | CE7: =+CD7-BY7 -> 0
E8: kUS$ | I8: 516 | J8: 652 | K8: 781 | L8: =+SUM(I8:K8) -> 1949 | N8: 762 | O8: 754 | P8: 718 | Q8: 718 | R8: =+Q8 -> 718 | S8: 563 | T8: 310 | U8: 0 | V8: 0 | W8: =+S8+T8+U8+V8 -> 873 | X8: 678 | Y8: 133 | Z8: 0 | AA8: 0 | AB8: =+X8+Y8+Z8+AA8 -> 811 | AC8: 466 | AD8: 145 | AE8: 0 | AF8: 0 | AG8: 0 | AH8: =AC8+AD8+AE8+AF8+AG8 -> 611 | AI8: 734 | AJ8: 100 | AK8: 0 | AL8: 0 | AM8: =+AI8+AJ8+AK8+AL8 -> 834 | AN8: 780 | AO8: 130 | AP8: 0 | AQ8: 0 | AR8: =+AN8+AO8+AP8+AQ8 -> 910 | AS8: 787 | AT8: 0 | AU8: 0 | AV8: 0 | AW8: 0 | AX8: =+AS8+AT8+AU8+AV8+AW8 -> 787 | AY8: 922 | AZ8: 0 | BA8: 0 | BB8: 0 | BC8: =+AY8+AZ8+BA8+BB8 -> 922 | BD8: 923 | BE8: 52 | BF8: 0 | BG8: -180 | BH8: =+BD8+BE8+BF8+BG8 -> 795 | BI8: 679 | BJ8: -131 | BK8: 219 | BL8: =-50-12 -> -62 | BM8: 0 | BN8: =+BI8+BJ8+BK8+BL8+BM8 -> 705 | BO8: 648 | BP8: 0 | BQ8: 0 | BR8: 0 | BS8: =+BO8+BP8+BQ8+BR8 -> 648 | BT8: 480 | BU8: 0 | BV8: -57 | BW8: 0 | BX8: 0 | BY8: =+BT8+BU8+BV8+BW8+BX8 -> 423 | CA8: =+R8+W8+AB8+AH8+AM8+AR8+AX8+BC8+BH8+BN8+BS8+BY8 -> 9037 | CC8: =+AVERAGE(R8,W8,AB8,AH8,AM8,AR8,AX8,BC8,BH8,BN8,BS8) -> 783.09091 | CD8: 423 | CE8: =+CD8-BY8 -> 0
B9: EC | C9: 4 | D9: EDP Emitidos (Estados de pago) | E9: # | I9: 16 | J9: 17 | K9: 19 | L9: =+SUM(I9:K9) -> 52 | M9: =+L10/L9 -> 34.384615 | N9: 0 | O9: 2 | P9: 8 | Q9: 9 | R9: =N9+O9+P9+Q9 -> 19 | S9: 0 | T9: 0 | U9: 0 | V9: 20 | W9: =+S9+T9+U9+V9 -> 20 | X9: 0 | Y9: 0 | Z9: 3 | AA9: =8+1+4+1 -> 14 | AB9: =+X9+Y9+Z9+AA9 -> 17 | AC9: 0 | AD9: 1 | AE9: 1 | AF9: 3 | AG9: 10 | AH9: =+AC9+AD9+AE9+AF9+AG9 -> 15 | AI9: 0 | AJ9: 1 | AK9: 1 | AL9: 14 | AM9: =+AI9+AJ9+AK9+AL9 -> 16 | AN9: 0 | AO9: 1 | AP9: 3 | AQ9: =8+3-1 -> 10 | AR9: =+AN9+AO9+AP9+AQ9 -> 14 | AS9: 0 | AT9: 0 | AU9: 6 | AV9: 4 | AW9: =2+1+1+1 -> 5 | AX9: =+AS9+AT9+AU9+AV9+AW9 -> 15 | AY9: 0 | AZ9: 0 | BA9: 9 | BB9: =7+1 -> 8 | BC9: =+AY9+AZ9+BA9+BB9 -> 17 | BD9: 0 | BE9: 5 | BF9: 2 | BG9: =3+6+3-1 -> 11 | BH9: =+BD9+BE9+BF9+BG9 -> 18 | BI9: 0 | BJ9: 1 | BK9: 8 | BL9: 7 | BM9: =4+1 -> 5 | BN9: =+BI9+BJ9+BK9+BL9+BM9 -> 21 | BO9: 0 | BP9: 5 | BQ9: 3 | BR9: 11 | BS9: =+BO9+BP9+BQ9+BR9 -> 19 | BT9: 0 | BU9: 0 | BV9: 5 | BW9: 4 | BX9: 4 | BY9: =+BT9+BU9+BV9+BW9+BX9 -> 13 | BZ9: =+IFERROR(BY10/BY9,0) -> 47 | CA9: =+R9+W9+AB9+AH9+AM9+AR9+AX9+BC9+BH9+BN9+BS9+BY9 -> 204 | CB9: =+CA10/CA9 -> 45.849956 | CD9: 13 | CE9: =+CD9-BY9 -> 0
E10: kUS$ | I10: 527 | J10: 429 | K10: =770+62 -> 832 | L10: =+SUM(I10:K10) -> 1788 | N10: 0 | O10: 86 | P10: 261 | Q10: =354-34+2 -> 322 | R10: =N10+O10+P10+Q10 -> 669 | S10: 0 | T10: 0 | U10: 0 | V10: 892 | W10: =+S10+T10+U10+V10 -> 892 | X10: 0 | Y10: 0 | Z10: 56 | AA10: =424+59+81+74 -> 638 | AB10: =+X10+Y10+Z10+AA10 -> 694 | AC10: 0 | AD10: 65 | AE10: 39 | AF10: 128 | AG10: =548+5-70+7-18 -> 472 | AH10: =+AC10+AD10+AE10+AF10+AG10 -> 704 | AI10: 0 | AJ10: 39 | AK10: 67 | AL10: =511+690-96-39-416-26 -> 624 | AM10: =+AI10+AJ10+AK10+AL10 -> 730 | AN10: 0 | AO10: 81 | AP10: 171 | AQ10: =540+340+73-27 -> 926 | AR10: =+AN10+AO10+AP10+AQ10 -> 1178 | AS10: 0 | AT10: 0 | AU10: 157 | AV10: =165+100+36 -> 301 | AW10: =39+70+126+35+35-20 -> 285 | AX10: =+AS10+AT10+AU10+AV10+AW10 -> 743 | AY10: 0 | AZ10: 0 | BA10: 306 | BB10: =375+150-46 -> 479 | BC10: =+AY10+AZ10+BA10+BB10 -> 785 | BD10: 0 | BE10: 183 | BF10: 50 | BG10: =71+312+85-22.409 -> 445.591 | BH10: =+BD10+BE10+BF10+BG10 -> 678.591 | BI10: 0 | BJ10: 3.8 | BK10: 257 | BL10: 376 | BM10: =185+41 -> 226 | BN10: =+BI10+BJ10+BK10+BL10+BM10 -> 862.8 | BO10: 0 | BP10: 319 | BQ10: 102 | BR10: 385 | BS10: =+BO10+BP10+BQ10+BR10 -> 806 | BT10: 0 | BU10: 0 | BV10: 291 | BW10: 257 | BX10: 63 | BY10: =+BT10+BU10+BV10+BW10+BX10 -> 611 | CA10: =+R10+W10+AB10+AH10+AM10+AR10+AX10+BC10+BH10+BN10+BS10+BY10 -> 9353.391 | CC10: =+AVERAGE(R10,W10,AB10,AH10,AM10,AR10,AX10,BC10,BH10,BN10,BS10,BY10) -> 779.44925 | CD10: 611 | CE10: =+CD10-BY10 -> 0
B11: IM | C11: 5 | D11: EDP Facturados (Facturación) | E11: # | I11: 23 | J11: 17 | K11: 18 | L11: =+SUM(I11:K11) -> 58 | M11: =+L12/L11 -> 32.37931 | N11: 12 | O11: 1 | P11: 1 | Q11: =4+4 -> 8 | R11: 22 | S11: 0 | T11: 0 | U11: 1 | V11: 8 | W11: 9 | X11: 2 | Y11: =1+2+3 -> 6 | Z11: 6 | AA11: =1+1+1 -> 3 | AB11: =+X11+Y11+Z11+AA11 -> 17 | AC11: 4 | AD11: 2 | AE11: 2 | AF11: 5 | AG11: 4 | AH11: 16 | AI11: 8 | AJ11: 3 | AK11: 2 | AL11: 8 | AM11: =+AI11+AJ11+AK11+AL11 -> 21 | AN11: 6 | AO11: 4 | AP11: 1 | AQ11: 6 | AR11: =+AN11+AO11+AP11+AQ11 -> 17 | AS11: 4 | AT11: 5 | AU11: 3 | AV11: 3 | AW11: =2+1 -> 3 | AX11: =+AS11+AT11+AU11+AV11+AW11 -> 18 | AY11: 7 | AZ11: 2 | BA11: 8 | BB11: =3+3 -> 6 | BC11: =+AY11+AZ11+BA11+BB11 -> 23 | BD11: 3 | BE11: 2 | BF11: 2 | BG11: =8+1 -> 9 | BH11: =+BD11+BE11+BF11+BG11 -> 16 | BI11: 1 | BJ11: 4 | BK11: 5 | BL11: 5 | BM11: 8 | BN11: =+BI11+BJ11+BK11+BL11+BM11 -> 23 | BO11: 2 | BP11: 4 | BQ11: 6 | BR11: 4 | BS11: =+BO11+BP11+BQ11+BR11 -> 16 | BT11: 2 | BU11: 3 | BV11: 8 | BW11: 5 | BX11: 3 | BY11: =+BT11+BU11+BV11+BW11+BX11 -> 21 | BZ11: =+IFERROR(BY12/BY11,0) -> 42.190476 | CA11: =+R11+W11+AB11+AH11+AM11+AR11+AX11+BC11+BH11+BN11+BS11+BY11 -> 219 | CB11: =+CA12/CA11 -> 44.726027 | CD11: 21 | CE11: =+CD11-BY11 -> 0
E12: kUS$ | I12: 864 | J12: 493 | K12: 521 | L12: =+SUM(I12:K12) -> 1878 | N12: 427 | O12: 82 | P12: 35 | Q12: =142+173 -> 315 | R12: 823 | S12: 0 | T12: 0 | U12: 96 | V12: 298 | W12: 313 | X12: =0+0+0+47 -> 47 | Y12: =84.795+106+248 -> 438.795 | Z12: 239.205 | AA12: =25+11 -> 36 | AB12: 798 | AC12: 182 | AD12: 39 | AE12: 38 | AF12: 122 | AG12: 344 | AH12: 702 | AI12: 201 | AJ12: 134 | AK12: 35 | AL12: =563+38 -> 601 | AM12: 916 | AN12: 111 | AO12: 176 | AP12: 15 | AQ12: =470+47-16-21 -> 480 | AR12: =+AN12+AO12+AP12+AQ12 -> 782 | AS12: 144 | AT12: 345 | AU12: 70 | AV12: 201 | AW12: =35+99 -> 134 | AX12: =+AS12+AT12+AU12+AV12+AW12 -> 894 | AY12: 752 | AZ12: 145 | BA12: 217 | BB12: =155+65 -> 220 | BC12: =+AY12+AZ12+BA12+BB12 -> 1334 | BD12: 55 | BE12: 171 | BF12: 102 | BG12: =377+22 -> 399 | BH12: =+BD12+BE12+BF12+BG12 -> 727 | BI12: 34 | BJ12: 116 | BK12: 251 | BL12: 360 | BM12: 194 | BN12: 884 | BO12: 62 | BP12: 271 | BQ12: 138 | BR12: 317 | BS12: 736 | BT12: 16 | BU12: 169 | BV12: 427 | BW12: 191 | BX12: 83 | BY12: =+BT12+BU12+BV12+BW12+BX12 -> 886 | CA12: =+R12+W12+AB12+AH12+AM12+AR12+AX12+BC12+BH12+BN12+BS12+BY12 -> 9795 | CC12: =+AVERAGE(R12,W12,AB12,AH12,AM12,AR12,AX12,BC12,BH12,BN12,BS12) -> 809.90909 | CD12: 886 | CE12: =+CD12-BY12 -> 0
B13: IM | C13: 6 | D13: EDP Pagados (Ingreso Operacional) | E13: # | I13: 25 | J13: 15 | K13: 15 | L13: =+SUM(I13:K13) -> 55 | M13: =+L14/L13 -> 38.109091 | N13: 4 | O13: 4 | P13: 8 | Q13: 4 | R13: 22 | S13: 2 | T13: 6 | U13: =5+2 -> 7 | V13: =3+3+1 -> 7 | W13: 20 | X13: 3 | Y13: 5 | Z13: 4 | AA13: =3+2+1 -> 6 | AB13: 16 | AC13: 2 | AD13: =5-1 -> 4 | AE13: 1 | AF13: 4 | AG13: 1 | AH13: =+AC13+AD13+AE13+AF13+AG13 -> 12 | AI13: 2 | AJ13: 3 | AK13: 7 | AL13: 8 | AM13: =+AI13+AJ13+AK13+AL13 -> 20 | AN13: 4 | AO13: 4 | AP13: 5 | AQ13: 5 | AR13: =+AN13+AO13+AP13+AQ13 -> 18 | AS13: 5 | AT13: 5 | AU13: 3 | AV13: 2 | AW13: =2+1 -> 3 | AX13: =+AS13+AT13+AU13+AV13+AW13 -> 18 | AY13: 5 | AZ13: 2 | BA13: 4 | BB13: 7 | BC13: =+AY13+AZ13+BA13+BB13 -> 18 | BD13: 1 | BE13: 3 | BF13: 5 | BG13: =6 -> 6 | BH13: =+BD13+BE13+BF13+BG13 -> 15 | BI13: 0 | BJ13: 0 | BK13: 7 | BL13: 9 | BM13: =1+2 -> 3 | BN13: =+BI13+BJ13+BK13+BL13+BM13 -> 19 | BO13: 3 | BP13: 4 | BQ13: 12 | BR13: 2 | BS13: =+BO13+BP13+BQ13+BR13 -> 21 | BT13: 4 | BU13: 3 | BV13: 6 | BW13: 2 | BX13: 2 | BY13: =+BT13+BU13+BV13+BW13+BX13 -> 17 | BZ13: =+IFERROR(BY14/BY13,0) -> 47.882353 | CA13: =+R13+W13+AB13+AH13+AM13+AR13+AX13+BC13+BH13+BN13+BS13+BY13 -> 216 | CB13: =+CA14/CA13 -> 41.782407 | CD13: 17 | CE13: =+CD13-BY13 -> 0
E14: kUS$ | I14: 1004 | J14: 616 | K14: 476 | L14: =+SUM(I14:K14) -> 2096 | N14: 197 | O14: 83 | P14: 269 | Q14: 157 | R14: 724 | S14: 46 | T14: 261 | U14: =181+160 -> 341 | V14: =152+87+22 -> 261 | W14: 932 | X14: =96270/1000 -> 96.27 | Y14: 132 | Z14: 253.73 | AA14: =197+51+29 -> 277 | AB14: =785-5 -> 780 | AC14: 35 | AD14: 346 | AE14: 42 | AF14: 105 | AG14: 83 | AH14: =+AC14+AD14+AE14+AF14+AG14-10 -> 601 | AI14: 123 | AJ14: 121 | AK14: 171 | AL14: 233 | AM14: =667-39 -> 628 | AN14: 345 | AO14: 121 | AP14: 195 | AQ14: 125 | AR14: 797 | AS14: 219 | AT14: 123 | AU14: 241 | AV14: 47 | AW14: =127+137 -> 264 | AX14: =+AS14+AT14+AU14+AV14+AW14-67 -> 827 | AY14: 163 | AZ14: 59 | BA14: 550 | BB14: 213 | BC14: =+AY14+AZ14+BA14+BB14-36 -> 949 | BD14: 112 | BE14: 103 | BF14: 308 | BG14: =33+61-3 -> 91 | BH14: =+BD14+BE14+BF14+BG14 -> 614 | BI14: 0 | BJ14: 0 | BK14: 307 | BL14: 422 | BM14: =5+52 -> 57 | BN14: =+BI14+BJ14+BK14+BL14+BM14 -> 786 | BO14: 53 | BP14: 117 | BQ14: 354 | BR14: 49 | BS14: =+BO14+BP14+BQ14+BR14 -> 573 | BT14: 63 | BU14: 271 | BV14: 224 | BW14: 178 | BX14: 78 | BY14: =+BT14+BU14+BV14+BW14+BX14 -> 814 | CA14: =+R14+W14+AB14+AH14+AM14+AR14+AX14+BC14+BH14+BN14+BS14+BY14 -> 9025 | CC14: =+AVERAGE(R14,W14,AB14,AH14,AM14,AR14,AX14,BC14,BH14,BN14,BS14) -> 746.45455 | CD14: 814 | CE14: =+CD14-BY14 -> 0
B15: IM | C15: 7 | D15: Gasto Operacional | E15: kUS$ | R15: 477 | W15: 500 | AB15: 536 | AH15: 518 | AM15: 534 | AR15: 614 | AX15: 526 | BC15: 585 | BD15: 0 | BE15: 0 | BF15: 0 | BG15: 0 | BH15: 605 | BN15: 621 | BS15: 623 | BY15: 651 | BZ15: =+BY15 -> 651 | CA15: =+R15+W15+AB15+AH15+AM15+AR15+AX15+BC15+BH15+BN15+BS15+BY15 -> 6790 | CB15: =+CA15/12 -> 565.83333 | CC15: =+AVERAGE(R15,W15,AB15,AH15,AM15,AR15,AX15,BC15,BH15,BN15,BS15) -> 558.09091
B16: EC | C16: 8 | D16: Cumplimiento POM vs EDP | E16: % | I16: =+IFERROR(I10/I8,0) -> 1.0213178 | J16: =+IFERROR(J10/J8,0) -> 0.65797546 | K16: =+IFERROR(K10/K8,0) -> 1.0653009 | L16: =+AVERAGE(I16:K16) -> 0.91486473 | M16: =+L16 -> 0.91486473 | N16: - | O16: =+IFERROR(O10/O8,0) -> 0.11405836 | P16: =+IFERROR(P10/P8,0) -> 0.36350975 | Q16: =+IFERROR(Q10/Q8,0) -> 0.44846797 | R16: =+IFERROR(R10/R8,0) -> 0.93175487 | S16: 0 | T16: 0 | U16: 0 | V16: 0 | W16: =+IFERROR(W10/W8,0) -> 1.021764 | X16: 0 | Y16: 0 | Z16: 0 | AA16: 0 | AB16: =+IFERROR(AB10/AB8,0) -> 0.85573366 | AC16: 0 | AD16: 0 | AE16: 0 | AF16: 0 | AG16: 0 | AH16: =+IFERROR(AH10/AH8,0) -> 1.1522095 | AI16: 0 | AJ16: 0 | AK16: 0 | AL16: 0 | AM16: =+IFERROR(AM10/AM8,0) -> 0.87529976 | AN16: 0 | AO16: 0 | AP16: 0 | AQ16: 0 | AR16: =+IFERROR(AR10/AR8,0) -> 1.2945055 | AS16: 0 | AT16: 0 | AU16: 0 | AV16: 0 | AW16: 0 | AX16: =+IFERROR(AX10/AX8,0) -> 0.94409149 | AY16: 0 | AZ16: 0 | BA16: 0 | BB16: 0 | BC16: =+IFERROR(BC10/BC8,0) -> 0.85140998 | BD16: 0 | BE16: 0 | BF16: 0 | BG16: 0 | BH16: =+IFERROR(BH10/BH8,0) -> 0.85357358 | BI16: 0 | BJ16: 0 | BK16: 0 | BL16: 0 | BM16: 0 | BN16: =+IFERROR(BN10/BN8,0) -> 1.2238298 | BO16: 0 | BP16: 0 | BQ16: 0 | BR16: 0 | BS16: =+IFERROR(BS10/BS8,0) -> 1.2438272 | BT16: =+IFERROR(BT10/BT8,0) -> 0 | BU16: 0 | BV16: 0 | BW16: 0 | BX16: 0 | BY16: =+IFERROR(BY10/BY8,0) -> 1.4444444 | BZ16: =+BY16 -> 1.4444444 | CA16: =+AVERAGE(R16,W16,AB16,AH16,AM16,AR16,AX16,BC16,BH16,BN16,BS16,BY16) -> 1.0577036 | CB16: =+CA16 -> 1.0577036
B17: EC | C17: 9 | D17: Adherencia POM vs EDP | E17: % | I17: 0.73 | J17: 0.67 | K17: 0.76 | L17: =+AVERAGE(I17:K17) -> 0.72 | M17: =+L17 -> 0.72 | N17: - | O17: - | P17: - | Q17: - | R17: 0.81 | S17: 0 | T17: 0 | U17: 0 | V17: 0 | W17: 0.83 | X17: 0 | Y17: 0 | Z17: 0 | AA17: 0 | AB17: 0.7 | AC17: 0 | AD17: 0 | AE17: 0 | AF17: 0 | AG17: 0 | AH17: 0.69 | AI17: 0 | AJ17: 0 | AK17: 0 | AL17: 0 | AM17: 0.77 | AN17: 0 | AO17: 0 | AP17: 0 | AQ17: 0 | AR17: 0.92 | AS17: 0 | AT17: 0 | AU17: 0 | AV17: 0 | AW17: 0 | AX17: 0.65 | AY17: 0 | AZ17: 0 | BA17: 0 | BB17: 0 | BC17: 0.54 | BD17: 0 | BE17: 0 | BF17: 0 | BG17: 0 | BH17: 0.62 | BI17: 0 | BJ17: 0 | BK17: 0 | BL17: 0 | BM17: 0 | BN17: 0.87 | BO17: 0 | BP17: 0 | BQ17: 0 | BR17: 0 | BS17: 0.81 | BT17: 0 | BU17: 0 | BV17: 0 | BW17: 0 | BX17: 0 | BY17: 0.79 | BZ17: =+BY17 -> 0.79 | CA17: =+AVERAGE(R17,W17,AB17,AH17,AM17,AR17,AX17,BC17,BH17,BN17,BS17,BY17) -> 0.75 | CB17: =+CA17 -> 0.75
B18: EC | C18: 10 | D18: Backlog EDP (por facturar) | E18: # | R18: =+R20+R22 -> 1 | W18: =+W20+W22 -> 24 | AB18: =+AB20+AB22 -> 11 | AH18: =+AH20+AH22 -> 6 | AM18: =+AM20+AM22 -> 6 | AR18: =+AR20+AR22 -> 7 | AX18: =+AX20+AX22 -> 5 | BC18: =+BC20+BC22 -> 3 | BH18: =+BH20+BH22 -> 6 | BN18: =+BN20+BN22 -> 16 | BO18: =+BO20+BO22 -> 15 | BP18: =+BP20+BP22 -> 13 | BQ18: =+BQ20+BQ22 -> 9 | BR18: =+BR20+BR22 -> 7 | BS18: =+BS20+BS22 -> 7 | BT18: =+BT20+BT22 -> 18 | BU18: =+BU20+BU22 -> 15 | ... BY18: =+BY20+BY22 -> 9 | BZ18: =+IFERROR(BY19/BY18,0) -> 27.222222 | CA18: =+BY18 -> 9 | CB18: =+IFERROR(CA19/CA18,0) -> 27.222222
