Workbook

Sheet Formato reporte EDP_2024
B10: Nombre fantasía | C10: Cliente | D10: Nombre Proyecto | E10: Director | F10: Ing Principal | G10: Real | H10: Otros | J10: EDP Real | K10: EDP POM | L10: EDP Curva S | M10: Dif. USD | N10: Var. % | O10: Saldo Actual | P10: Saldo Proy | Q10: Comentarios | R10: Tipo 1 | S10: Tipo 2 | T10: Estatus
B11: Gran total | C11: Gran total | D11: Gran total | E11: Todos | F11: Todos | G11: =+SUM(G12:G13) -> 985703.15 | H11: =+SUM(H12:H13) -> 0 | I11: =+SUM(G11:H11) -> 985703.15 | J11: =+SUM(J12:J13) -> 985703.15 | K11: =+SUM(K12:K13) -> 550910.74 | L11: =+SUM(L12:L13) -> 1054085.7 | M11: =+J11-L11 -> -68382.556 | N11: =+IFERROR(((J11-L11)/L11),0) -> -0.064873811 | O11: =+SUM(O12:O13) -> 267749.45 | P11: =+O11-L11 -> -786336.25 | R11: Todos | S11: Todos | T11: Todos | U11: =+I11=J11 -> TRUE
B12: En Proceso | C12: En Proceso | D12: En Proceso | E12: En Proceso | F12: En Proceso | G12: =+IF($B12="En Proceso",1*SUMIF($T21:$T10018,$B12,$G21:$G10018),0) -> 945703.15 | H12: =+IF($B12="En Proceso",1*SUMIF($T21:$T10018,$B12,$H21:$H10018),0) -> 0 | I12: =+SUM(G12:H12) -> 945703.15 | J12: =+G12+H12 -> 945703.15 | K12: =+IF(B12="En proceso",SUMIF(T17:T1018,B12,K$17:K$1048576),0) -> 550910.74 | L12: =+IF(B12="En proceso",SUMIF(T17:T1018,B12,L$17:L$1048576),0) -> 1054085.7 | M12: =+J12-L12 -> -108382.56 | N12: =+IFERROR(((J12-L12)/L12),0) -> -0.10282139 | O12: =+IF($B12="En Proceso",1*SUMIF(T21:T10018,$B12,O21:O10018),0) -> 261703.47 | P12: =+O12-L12 -> -792382.23 | R12: En Proceso | S12: En Proceso | T12: En Proceso | U12: =+I12=J12 -> TRUE | X12: SI($B12="En Proceso";SUMAR.SI($P:$P;$B12;$I:$I);0)
B13: Terminado | C13: Terminado | D13: Terminado | E13: Terminado | F13: Terminado | G13: =+IF($B13="Terminado",1*SUMIF($T21:$T10018,$B13,$G21:$G10018),0) -> 40000 | H13: =+IF($B13="Terminado",1*SUMIF($T21:$T10018,$B13,$H21:$H10018),0) -> 0 | I13: =+SUM(G13:H13) -> 40000 | J13: =+G13+H13 -> 40000 | K13: =+IF(B13="Terminado",SUMIF(T20:T1018,B13,K$20:K$1048576),0) -> 0 | L13: =+IF(B13="Terminado",SUMIF(T20:T1018,B13,L$20:L$1048576),0) -> 0 | M13: =+J13-L13 -> 40000 | N13: =+IFERROR(((J13-L13)/L13),0) -> 0 | O13: =+IF($B13="Terminado",1*SUMIF(T21:T10018,$B13,O21:O10018),0) -> 6045.98 | P13: =+O13-L13 -> 6045.98 | R13: Terminado | S13: Terminado | T13: Terminado | U13: =+I13=J13 -> TRUE
B14: Ejecución | C14: Ejecución | D14: Ejecución | E14: Ejecución | F14: Ejecución | G14: =+IF($B14="Ejecución",1*SUMIF($S21:$S10018,$B14,$G21:$G10018),0) -> 887997.15 | H14: =+IF($B14="Ejecución",1*SUMIF($S21:$S10018,$B14,$H21:$H10018),0) -> 0 | I14: =+SUM(G14:H14) -> 887997.15 | J14: =+G14+H14 -> 887997.15 | K14: =+IF(B14="Ejecución",SUMIF(S20:S1020,B14,K$20:K$1048576),0) -> 550910.74 | L14: =+IF(B14="Ejecución",SUMIF(S20:S1020,B14,L$20:L$1048576),0) -> 1006721.6 | M14: =+J14-L14 -> -118724.47 | N14: =+IFERROR(((J14-L14)/L14),0) -> -0.11793178 | O14: =+IF($B14="Ejecución",1*SUMIF(S21:S10018,$B14,O21:O10018),0) -> 258208.39 | P14: =+O14-L14 -> -748513.23 | R14: Ejecución | S14: Ejecución | T14: Ejecución | U14: =+I14=J14 -> TRUE
B15: Terminal | C15: Terminal | D15: Terminal | E15: Terminal | F15: Terminal | G15: =+IF($B15="Terminal",1*SUMIF($S21:$S10018,$B15,$G21:$G10018),0) -> 57706 | H15: =+IF($B15="Terminal",1*SUMIF($S21:$S10018,$B15,$H21:$H10018),0) -> 0 | I15: =+SUM(G15:H15) -> 57706 | J15: =+G15+H15 -> 57706 | K15: =+IF(B15="Terminal",SUMIF(S20:S1021,B15,K$20:K$1048576),0) -> 0 | L15: =+IF(B15="Terminal",SUMIF(S20:S1021,B15,L$20:L$1048576),0) -> 47364.082 | M15: =+J15-L15 -> 10341.918 | N15: =+IFERROR(((J15-L15)/L15),0) -> 0.21834939 | O15: =+IF($B15="Terminal",1*SUMIF(S21:S10018,$B15,O21:O10018),0) -> 3495.0816 | P15: =+O15-L15 -> -43869 | R15: Terminal | S15: Terminal | T15: Terminal | U15: =+I15=J15 -> TRUE
B16: Rezagado | C16: Rezagado | D16: Rezagado | E16: Rezagado | F16: Rezagado | G16: =+IF($B16="Rezagado",1*SUMIF($S21:$S10018,$B16,$G21:$G10018),0) -> 40000 | H16: =+IF($B16="Rezagado",1*SUMIF($S21:$S10018,$B16,$H21:$H10018),0) -> 0 | I16: =+SUM(G16:H16) -> 40000 | J16: =+G16+H16 -> 40000 | K16: =+IF(B16="Rezagado",SUMIF(S20:S1022,B16,K$20:K$1048576),0) -> 0 | L16: =+IF(B16="Rezagado",SUMIF(S20:S1022,B16,L$20:L$1048576),0) -> 0 | M16: =+J16-L16 -> 40000 | N16: =+IFERROR(((J16-L16)/L16),0) -> 0 | O16: =+IF($B16="Rezagado",1*SUMIF(S21:S10018,$B16,O21:O10018),0) -> 6045.98 | P16: =+O16-L16 -> 6045.98 | R16: Rezagado | S16: Rezagado | T16: Rezagado | U16: =+I16=J16 -> TRUE
C20: =+C10 -> Cliente | D20: =+D10 -> Nombre Proyecto | E20: =+E10 -> Director | F20: =+F10 -> Ing Principal | G20: =+G10 -> Real | H20: =+H10 -> Otros | I20: =+I10 -> 0 | J20: =+J10 -> EDP Real | ... Q20: =+Q10 -> Comentarios | R20: Tipo 1 | S20: Tipo 2 | T20: Estatus
B21: Mosaic_Cajati | C21: =+_xlfn.XLOOKUP(B21,'[1]Proyectos (NO FILTRAR)'!$F:$F,'[1]Proyectos (NO FILTRAR)'!$I:$I) -> Mosaic | D21: Modelo geomecanico de esfuerzos + FS P1 y PFS P2 - Mina Cajati | E21: =+_xlfn.XLOOKUP(B21,'POM 2024'!B:B,'POM 2024'!F:F,"!",0,1) -> Alex Figueroa | F21: =+_xlfn.XLOOKUP(B21,'POM 2024'!B:B,'POM 2024'!H:H,"!",0,1) -> Pablo Quiero | G21: =+J21 -> 15442 | H21: 0 | I21: =+SUM(G21:H21) -> 15442 | J21: =VLOOKUP(B21,'POM 2024'!$B$2:$BI$64,48,FALSE) -> 15442 | K21: =+_xlfn.XLOOKUP($B21,'POM 2024'!B:B,'POM 2024'!AV:AV,"!",0,1) -> 22988.54 | L21: =+_xlfn.XLOOKUP($B21,'POM 2024'!B:B,'POM 2024'!AU:AU,"!",0,1) -> 22988.54 | M21: =+J21-L21 -> -7546.54 | N21: =+IFERROR(((J21-K21)/K21),0) -> -0.328274 | O21: =IF(_xlfn.XLOOKUP($B21,'POM 2024'!B:B,'POM 2024'!L:L,"!",0,1)<0,0,_xlfn.XLOOKUP($B21,'POM 2024'!B:B,'POM 2024'!L:L,"!",0,1)) -> 7546.54 | P21: =+O21-L21 -> -15442 | R21: Técnico | S21: Ejecución | T21: En Proceso | U21: =+I21=J21 -> TRUE
B22: CMP_Los Colorados Adelantamiento Planta | C22: =+_xlfn.XLOOKUP(B22,'[1]Proyectos (NO FILTRAR)'!$F:$F,'[1]Proyectos (NO FILTRAR)'!$I:$I) -> CMP | D22: Adelantamiento Planta Los Colorados | E22: =+_xlfn.XLOOKUP(B22,'POM 2024'!B:B,'POM 2024'!F:F,"!",0,1) -> Alex Figueroa | F22: =+_xlfn.XLOOKUP(B22,'POM 2024'!B:B,'POM 2024'!H:H,"!",0,1) -> Felipe Matamoros | G22: =+J22 -> 0 | H22: 0 | I22: =+SUM(G22:H22) -> 0 | J22: =VLOOKUP(B22,'POM 2024'!$B$2:$BI$64,48,FALSE) -> 0 | K22: =+_xlfn.XLOOKUP($B22,'POM 2024'!B:B,'POM 2024'!AV:AV,"!",0,1) -> 0 | L22: =+_xlfn.XLOOKUP($B22,'POM 2024'!B:B,'POM 2024'!AU:AU,"!",0,1) -> 0 | M22: =+J22-L22 -> 0 | N22: =+IFERROR(((J22-K22)/K22),0) -> 0 | O22: =IF(_xlfn.XLOOKUP($B22,'POM 2024'!B:B,'POM 2024'!L:L,"!",0,1)<0,0,_xlfn.XLOOKUP($B22,'POM 2024'!B:B,'POM 2024'!L:L,"!",0,1)) -> 0 | P22: =+O22-L22 -> 0 | R22: Técnico | S22: Ejecución | T22: En Proceso | U22: =+I22=J22 -> TRUE
B23: CSH_LOM Mina Guarello | C23: Siderúrgica Huachipato | D23: Plan de largo plazo Mina Guarello | E23: =+_xlfn.XLOOKUP(B23,'POM 2024'!B:B,'POM 2024'!F:F,"!",0,1) -> Matias Fuentes | F23: =+_xlfn.XLOOKUP(B23,'POM 2024'!B:B,'POM 2024'!H:H,"!",0,1) -> TBD | G23: =+J23 -> 19065 | H23: 0 | I23: =+SUM(G23:H23) -> 19065 | J23: =VLOOKUP(B23,'POM 2024'!$B$2:$BI$64,48,FALSE) -> 19065 | K23: =+_xlfn.XLOOKUP($B23,'POM 2024'!B:B,'POM 2024'!AV:AV,"!",0,1) -> 0 | L23: =+_xlfn.XLOOKUP($B23,'POM 2024'!B:B,'POM 2024'!AU:AU,"!",0,1) -> 0 | M23: =+J23-L23 -> 19065 | N23: =+IFERROR(((J23-K23)/K23),0) -> 0 | O23: =IF(_xlfn.XLOOKUP($B23,'POM 2024'!B:B,'POM 2024'!L:L,"!",0,1)<0,0,_xlfn.XLOOKUP($B23,'POM 2024'!B:B,'POM 2024'!L:L,"!",0,1)) -> 0 | P23: =+O23-L23 -> 0 | R23: Administrativo | S23: Ejecución | T23: En Proceso | U23: =+I23=J23 -> TRUE
B24: PFS Los Calatos | C24: Minera Hampton | D24: PFS Los Calatos Project | E24: =+_xlfn.XLOOKUP(B24,'POM 2024'!B:B,'POM 2024'!F:F,"!",0,1) -> Alex Figueroa | F24: =+_xlfn.XLOOKUP(B24,'POM 2024'!B:B,'POM 2024'!H:H,"!",0,1) -> Jorman Barrera | G24: =+J24 -> 85235 | H24: 0 | I24: =+SUM(G24:H24) -> 85235 | J24: =VLOOKUP(B24,'POM 2024'!$B$2:$BI$64,48,FALSE) -> 85235 | K24: =+_xlfn.XLOOKUP($B24,'POM 2024'!B:B,'POM 2024'!AV:AV,"!",0,1) -> 90000 | L24: =+_xlfn.XLOOKUP($B24,'POM 2024'!B:B,'POM 2024'!AU:AU,"!",0,1) -> 110447.1 | M24: =+J24-L24 -> -25212.1 | N24: =+IFERROR(((J24-K24)/K24),0) -> -0.052944444 | O24: =IF(_xlfn.XLOOKUP($B24,'POM 2024'!B:B,'POM 2024'!L:L,"!",0,1)<0,0,_xlfn.XLOOKUP($B24,'POM 2024'!B:B,'POM 2024'!L:L,"!",0,1)) -> 0 | P24: =+O24-L24 -> -110447.1 | R24: Técnico | S24: Ejecución | T24: En Proceso | U24: =+I24=J24 -> TRUE
B25: IvanhoeElectric_Santa-Cruz_PrePFS | C25: =+_xlfn.XLOOKUP(B25,'[1]Proyectos (NO FILTRAR)'!$F:$F,'[1]Proyectos (NO FILTRAR)'!$I:$I) -> Ivanhoe Electric | D25: Pre PFS Santa Cruz Project | E25: =+_xlfn.XLOOKUP(B25,'POM 2024'!B:B,'POM 2024'!F:F,"!",0,1) -> Matias Fuentes | F25: =+_xlfn.XLOOKUP(B25,'POM 2024'!B:B,'POM 2024'!H:H,"!",0,1) -> Carlos Morante | G25: =+J25 -> 0 | H25: 0 | I25: =+SUM(G25:H25) -> 0 | J25: =VLOOKUP(B25,'POM 2024'!$B$2:$BI$64,48,FALSE) -> 0 | K25: =+_xlfn.XLOOKUP($B25,'POM 2024'!B:B,'POM 2024'!AV:AV,"!",0,1) -> 0 | L25: =+_xlfn.XLOOKUP($B25,'POM 2024'!B:B,'POM 2024'!AU:AU,"!",0,1) -> 0 | M25: =+J25-L25 -> 0 | N25: =+IFERROR(((J25-K25)/K25),0) -> 0 | O25: =IF(_xlfn.XLOOKUP($B25,'POM 2024'!B:B,'POM 2024'!L:L,"!",0,1)<0,0,_xlfn.XLOOKUP($B25,'POM 2024'!B:B,'POM 2024'!L:L,"!",0,1)) -> 0 | P25: =+O25-L25 -> 0 | R25: Técnico | S25: Ejecución | T25: En Proceso | U25: =+I25=J25 -> TRUE
B26: LasBambas_Ferrobamba_OP_UG | C26: =+_xlfn.XLOOKUP(B26,'[1]Proyectos (NO FILTRAR)'!$F:$F,'[1]Proyectos (NO FILTRAR)'!$I:$I) -> MMG Las Bambas | D26: Ferrobamba UG Scoping Study | E26: =+_xlfn.XLOOKUP(B26,'POM 2024'!B:B,'POM 2024'!F:F,"!",0,1) -> Matias Fuentes | F26: =+_xlfn.XLOOKUP(B26,'POM 2024'!B:B,'POM 2024'!H:H,"!",0,1) -> Pablo Quiero | G26: =+J26 -> 45952 | H26: 0 | I26: =+SUM(G26:H26) -> 45952 | J26: =VLOOKUP(B26,'POM 2024'!$B$2:$BI$64,48,FALSE) -> 45952 | K26: =+_xlfn.XLOOKUP($B26,'POM 2024'!B:B,'POM 2024'!AV:AV,"!",0,1) -> 0 | L26: =+_xlfn.XLOOKUP($B26,'POM 2024'!B:B,'POM 2024'!AU:AU,"!",0,1) -> 45951.005 | M26: =+J26-L26 -> 0.9952 | N26: =+IFERROR(((J26-K26)/K26),0) -> 0 | O26: =IF(_xlfn.XLOOKUP($B26,'POM 2024'!B:B,'POM 2024'!L:L,"!",0,1)<0,0,_xlfn.XLOOKUP($B26,'POM 2024'!B:B,'POM 2024'!L:L,"!",0,1)) -> 0 | P26: =+O26-L26 -> -45951.005 | R26: Técnico | S26: Ejecución | T26: En Proceso | U26: =+I26=J26 -> TRUE
B27: CMP_Romeral Estabilización + UG PFS | C27: =+_xlfn.XLOOKUP(B27,'[1]Proyectos (NO FILTRAR)'!$F:$F,'[1]Proyectos (NO FILTRAR)'!$I:$I) -> CMP | D27: LOM Estabilizado, gestion de plan mensual, PFS UG y link con largo plazo del Valle; Mina Romeral | E27: =+_xlfn.XLOOKUP(B27,'POM 2024'!B:B,'POM 2024'!F:F,"!",0,1) -> Alex Figueroa | F27: =+_xlfn.XLOOKUP(B27,'POM 2024'!B:B,'POM 2024'!H:H,"!",0,1) -> Felipe Matamoros | G27: =+J27 -> 0 | H27: 0 | I27: =+SUM(G27:H27) -> 0 | J27: =VLOOKUP(B27,'POM 2024'!$B$2:$BI$64,48,FALSE) -> 0 | K27: =+_xlfn.XLOOKUP($B27,'POM 2024'!B:B,'POM 2024'!AV:AV,"!",0,1) -> 0 | L27: =+_xlfn.XLOOKUP($B27,'POM 2024'!B:B,'POM 2024'!AU:AU,"!",0,1) -> 88555.4 | M27: =+J27-L27 -> -88555.4 | N27: =+IFERROR(((J27-K27)/K27),0) -> 0 | O27: =IF(_xlfn.XLOOKUP($B27,'POM 2024'!B:B,'POM 2024'!L:L,"!",0,1)<0,0,_xlfn.XLOOKUP($B27,'POM 2024'!B:B,'POM 2024'!L:L,"!",0,1)) -> 0 | P27: =+O27-L27 -> -88555.4 | R27: Técnico | S27: Ejecución | T27: En Proceso | U27: =+I27=J27 -> TRUE
B28: Lundin_Candelaria_EstudiosCugep | C28: =+_xlfn.XLOOKUP(B28,'[1]Proyectos (NO FILTRAR)'!$F:$F,'[1]Proyectos (NO FILTRAR)'!$I:$I) -> Lundin | D28: Ingeniería de valor para Robustecer el Proyecto CUGEP | E28: =+_xlfn.XLOOKUP(B28,'POM 2024'!B:B,'POM 2024'!F:F,"!",0,1) -> Mauricio Melendez | F28: =+_xlfn.XLOOKUP(B28,'POM 2024'!B:B,'POM 2024'!H:H,"!",0,1) -> Freddy Diaz | G28: =+J28 -> 71980 | H28: 0 | I28: =+SUM(G28:H28) -> 71980 | J28: =VLOOKUP(B28,'POM 2024'!$B$2:$BI$64,48,FALSE) -> 71980 | K28: =+_xlfn.XLOOKUP($B28,'POM 2024'!B:B,'POM 2024'!AV:AV,"!",0,1) -> 50337.7 | L28: =+_xlfn.XLOOKUP($B28,'POM 2024'!B:B,'POM 2024'!AU:AU,"!",0,1) -> 173030 | M28: =+J28-L28 -> -101050 | N28: =+IFERROR(((J28-K28)/K28),0) -> 0.42994217 | O28: =IF(_xlfn.XLOOKUP($B28,'POM 2024'!B:B,'POM 2024'!L:L,"!",0,1)<0,0,_xlfn.XLOOKUP($B28,'POM 2024'!B:B,'POM 2024'!L:L,"!",0,1)) -> 6695 | P28: =+O28-L28 -> -166335 | S28: Ejecución | T28: En Proceso | U28: =+I28=J28 -> TRUE
B29: AMSA_Asesoria Centinela | C29: =+_xlfn.XLOOKUP(B29,'[1]Proyectos (NO FILTRAR)'!$F:$F,'[1]Proyectos (NO FILTRAR)'!$I:$I) -> AMSA | D29: Asesoría Plan 2024 y quinquenio 2024-2028 | E29: =+_xlfn.XLOOKUP(B29,'POM 2024'!B:B,'POM 2024'!F:F,"!",0,1) -> Cristian Quezada | F29: =+_xlfn.XLOOKUP(B29,'POM 2024'!B:B,'POM 2024'!H:H,"!",0,1) -> Nicolás Ayarza | G29: =+J29 -> 8760 | H29: 0 | I29: =+SUM(G29:H29) -> 8760 | J29: =VLOOKUP(B29,'POM 2024'!$B$2:$BI$64,48,FALSE) -> 8760 | K29: =+_xlfn.XLOOKUP($B29,'POM 2024'!B:B,'POM 2024'!AV:AV,"!",0,1) -> 8509.5 | L29: =+_xlfn.XLOOKUP($B29,'POM 2024'!B:B,'POM 2024'!AU:AU,"!",0,1) -> 8509.5 | M29: =+J29-L29 -> 250.5 | N29: =+IFERROR(((J29-K29)/K29),0) -> 0.029437687 | O29: =IF(_xlfn.XLOOKUP($B29,'POM 2024'!B:B,'POM 2024'!L:L,"!",0,1)<0,0,_xlfn.XLOOKUP($B29,'POM 2024'!B:B,'POM 2024'!L:L,"!",0,1)) -> 0 | P29: =+O29-L29 -> -8509.5 | S29: Ejecución | T29: En Proceso | U29: =+I29=J29 -> TRUE
B30: AMSA_Estandares Minimos | C30: =+_xlfn.XLOOKUP(B30,'[1]Proyectos (NO FILTRAR)'!$F:$F,'[1]Proyectos (NO FILTRAR)'!$I:$I) -> AMSA | D30: Desarrollo de Manuales de Minimos Estandares | E30: =+_xlfn.XLOOKUP(B30,'POM 2024'!B:B,'POM 2024'!F:F,"!",0,1) -> Alex Figueroa | F30: =+_xlfn.XLOOKUP(B30,'POM 2024'!B:B,'POM 2024'!H:H,"!",0,1) -> Cristian Alarcón | G30: =+J30 -> 15305 | H30: 0 | I30: =+SUM(G30:H30) -> 15305 | J30: =VLOOKUP(B30,'POM 2024'!$B$2:$BI$64,48,FALSE) -> 15305 | K30: =+_xlfn.XLOOKUP($B30,'POM 2024'!B:B,'POM 2024'!AV:AV,"!",0,1) -> 0 | L30: =+_xlfn.XLOOKUP($B30,'POM 2024'!B:B,'POM 2024'!AU:AU,"!",0,1) -> 35286.5 | M30: =+J30-L30 -> -19981.5 | N30: =+IFERROR(((J30-K30)/K30),0) -> 0 | O30: =IF(_xlfn.XLOOKUP($B30,'POM 2024'!B:B,'POM 2024'!L:L,"!",0,1)<0,0,_xlfn.XLOOKUP($B30,'POM 2024'!B:B,'POM 2024'!L:L,"!",0,1)) -> 3008 | P30: =+O30-L30 -> -32278.5 | S30: Ejecución | T30: En Proceso | U30: =+I30=J30 -> TRUE
B31: Glencore_Coroccohuayco_OptimizacionLOM | C31: =+_xlfn.XLOOKUP(B31,'[1]Proyectos (NO FILTRAR)'!$F:$F,'[1]Proyectos (NO FILTRAR)'!$I:$I) -> Glencore | D31: Estudios mineros complementarios para la PFS | E31: =+_xlfn.XLOOKUP(B31,'POM 2024'!B:B,'POM 2024'!F:F,"!",0,1) -> Cristian Quezada | F31: =+_xlfn.XLOOKUP(B31,'POM 2024'!B:B,'POM 2024'!H:H,"!",0,1) -> Kevin Rios | G31: =+J31 -> 42188.15 | H31: 0 | I31: =+SUM(G31:H31) -> 42188.15 | J31: =VLOOKUP(B31,'POM 2024'!$B$2:$BI$64,48,FALSE) -> 42188.15 | K31: =+_xlfn.XLOOKUP($B31,'POM 2024'!B:B,'POM 2024'!AV:AV,"!",0,1) -> 38000 | L31: =+_xlfn.XLOOKUP($B31,'POM 2024'!B:B,'POM 2024'!AU:AU,"!",0,1) -> 42188.15 | M31: =+J31-L31 -> 0 | N31: =+IFERROR(((J31-K31)/K31),0) -> 0.11021447 | O31: =IF(_xlfn.XLOOKUP($B31,'POM 2024'!B:B,'POM 2024'!L:L,"!",0,1)<0,0,_xlfn.XLOOKUP($B31,'POM 2024'!B:B,'POM 2024'!L:L,"!",0,1)) -> 0 | P31: =+O31-L31 -> -42188.15 | S31: Ejecución | T31: En Proceso | U31: =+I31=J31 -> TRUE
B32: Coripuno_Metodos de Minado | C32: =+_xlfn.XLOOKUP(B32,'[1]Proyectos (NO FILTRAR)'!$F:$F,'[1]Proyectos (NO FILTRAR)'!$I:$I) -> Coripuno | D32: Alternativas método de minado proyecto Torremani | E32: =+_xlfn.XLOOKUP(B32,'POM 2024'!B:B,'POM 2024'!F:F,"!",0,1) -> Claudio Hernández | F32: =+_xlfn.XLOOKUP(B32,'POM 2024'!B:B,'POM 2024'!H:H,"!",0,1) -> Pablo Quiero | G32: =+J32 -> 105000 | H32: 0 | I32: =+SUM(G32:H32) -> 105000 | J32: =VLOOKUP(B32,'POM 2024'!$B$2:$BI$64,48,FALSE) -> 105000 | K32: =+_xlfn.XLOOKUP($B32,'POM 2024'!B:B,'POM 2024'!AV:AV,"!",0,1) -> 20185 | L32: =+_xlfn.XLOOKUP($B32,'POM 2024'!B:B,'POM 2024'!AU:AU,"!",0,1) -> 105060 | M32: =+J32-L32 -> -60 | N32: =+IFERROR(((J32-K32)/K32),0) -> 4.2018826 | O32: =IF(_xlfn.XLOOKUP($B32,'POM 2024'!B:B,'POM 2024'!L:L,"!",0,1)<0,0,_xlfn.XLOOKUP($B32,'POM 2024'!B:B,'POM 2024'!L:L,"!",0,1)) -> 0 | P32: =+O32-L32 -> -105060 | S32: Ejecución | T32: En Proceso | U32: =+I32=J32 -> TRUE
B33: Minsur_Mejoramiento datos geotecnicos SR | C33: =+_xlfn.XLOOKUP(B33,'[1]Proyectos (NO FILTRAR)'!$F:$F,'[1]Proyectos (NO FILTRAR)'!$I:$I) -> Minsur | D33: Apoyo Planificacion Geomecanica | E33: =+_xlfn.XLOOKUP(B33,'POM 2024'!B:B,'POM 2024'!F:F,"!",0,1) -> Claudio Hernández | F33: =+_xlfn.XLOOKUP(B33,'POM 2024'!B:B,'POM 2024'!H:H,"!",0,1) -> TBD | G33: =+J33 -> 24551 | H33: 0 | I33: =+SUM(G33:H33) -> 24551 | J33: =VLOOKUP(B33,'POM 2024'!$B$2:$BI$64,48,FALSE) -> 24551 | K33: =+_xlfn.XLOOKUP($B33,'POM 2024'!B:B,'POM 2024'!AV:AV,"!",0,1) -> 0 | L33: =+_xlfn.XLOOKUP($B33,'POM 2024'!B:B,'POM 2024'!AU:AU,"!",0,1) -> 0 | M33: =+J33-L33 -> 24551 | N33: =+IFERROR(((J33-K33)/K33),0) -> 0 | O33: =IF(_xlfn.XLOOKUP($B33,'POM 2024'!B:B,'POM 2024'!L:L,"!",0,1)<0,0,_xlfn.XLOOKUP($B33,'POM 2024'!B:B,'POM 2024'!L:L,"!",0,1)) -> 0 | P33: =+O33-L33 -> 0 | S33: Ejecución | T33: En Proceso | U33: =+I33=J33 -> TRUE
B34: BHP_Tunel Exploratorio | C34: =+_xlfn.XLOOKUP(B34,'[1]Proyectos (NO FILTRAR)'!$F:$F,'[1]Proyectos (NO FILTRAR)'!$I:$I) -> BHP | D34: Estudio FEL1 de evaluación de opciones de acceso exploratrio para el cuerpo Escondida East Deep, de BHP Minerals America. | E34: =+_xlfn.XLOOKUP(B34,'POM 2024'!B:B,'POM 2024'!F:F,"!",0,1) -> Mauricio Melendez | F34: =+_xlfn.XLOOKUP(B34,'POM 2024'!B:B,'POM 2024'!H:H,"!",0,1) -> Freddy Diaz | G34: =+J34 -> 0 | H34: 0 | I34: =+SUM(G34:H34) -> 0 | J34: =VLOOKUP(B34,'POM 2024'!$B$2:$BI$64,48,FALSE) -> 0 | K34: =+_xlfn.XLOOKUP($B34,'POM 2024'!B:B,'POM 2024'!AV:AV,"!",0,1) -> 0 | L34: =+_xlfn.XLOOKUP($B34,'POM 2024'!B:B,'POM 2024'!AU:AU,"!",0,1) -> 0 | M34: =+J34-L34 -> 0 | N34: =+IFERROR(((J34-K34)/K34),0) -> 0 | O34: =IF(_xlfn.XLOOKUP($B34,'POM 2024'!B:B,'POM 2024'!L:L,"!",0,1)<0,0,_xlfn.XLOOKUP($B34,'POM 2024'!B:B,'POM 2024'!L:L,"!",0,1)) -> 0 | P34: =+O34-L34 -> 0 | S34: Ejecución | T34: En Proceso | U34: =+I34=J34 -> TRUE
B35: J&F_Urucrum_RecuperacionPilares | C35: J&F | D35: Recuperación de Pilares Mina Urucrum | E35: Alex Figueroa | F35: Freddy Diaz | G35: =+J35 -> 0 | H35: 0 | I35: =+SUM(G35:H35) -> 0 | J35: =VLOOKUP(B35,'POM 2024'!$B$2:$BI$64,48,FALSE) -> 0 | K35: =+_xlfn.XLOOKUP($B35,'POM 2024'!B:B,'POM 2024'!AV:AV,"!",0,1) -> 0 | L35: =+_xlfn.XLOOKUP($B35,'POM 2024'!B:B,'POM 2024'!AU:AU,"!",0,1) -> 56177.69 | M35: =+J35-L35 -> -56177.69 | N35: =+IFERROR(((J35-K35)/K35),0) -> 0 | O35: =IF(_xlfn.XLOOKUP($B35,'POM 2024'!B:B,'POM 2024'!L:L,"!",0,1)<0,0,_xlfn.XLOOKUP($B35,'POM 2024'!B:B,'POM 2024'!L:L,"!",0,1)) -> 31049 | P35: =+O35-L35 -> -25128.69 | S35: Ejecución | T35: En Proceso | U35: =+I35=J35 -> TRUE
B36: Eurochem_Himmelfarb Deposit | C36: =+_xlfn.XLOOKUP(B36,'[1]Proyectos (NO FILTRAR)'!$F:$F,'[1]Proyectos (NO FILTRAR)'!$I:$I) -> Eurochem | D36: Auditoría técnica y optimización de soluciones para el "Estudio exploratorio sobre la extracción y el tratamiento de recursos minerales de fosforita potencialmente recuperables en el yacimiento de Himmelfarb". | E36: =+_xlfn.XLOOKUP(B36,'POM 2024'!B:B,'POM 2024'!F:F,"!",0,1) -> Ricardo Miranda | F36: =+_xlfn.XLOOKUP(B36,'POM 2024'!B:B,'POM 2024'!H:H,"!",0,1) -> Gerson Alfaro | G36: =+J36 -> 76050 | H36: 0 | I36: =+SUM(G36:H36) -> 76050 | J36: =VLOOKUP(B36,'POM 2024'!$B$2:$BI$64,48,FALSE) -> 76050 | K36: =+_xlfn.XLOOKUP($B36,'POM 2024'!B:B,'POM 2024'!AV:AV,"!",0,1) -> 91260 | L36: =+_xlfn.XLOOKUP($B36,'POM 2024'!B:B,'POM 2024'!AU:AU,"!",0,1) -> 105398.64 | M36: =+J36-L36 -> -29348.64 | N36: =+IFERROR(((J36-K36)/K36),0) -> -0.16666667 | O36: =IF(_xlfn.XLOOKUP($B36,'POM 2024'!B:B,'POM 2024'!L:L,"!",0,1)<0,0,_xlfn.XLOOKUP($B36,'POM 2024'!B:B,'POM 2024'!L:L,"!",0,1)) -> 0 | P36: =+O36-L36 -> -105398.64 | S36: Ejecución | T36: En Proceso | U36: =+I36=J36 -> TRUE
B37: Seligdar_Kyuchus | C37: =+_xlfn.XLOOKUP(B37,'[1]Proyectos (NO FILTRAR)'!$F:$F,'[1]Proyectos (NO FILTRAR)'!$I:$I) -> Seligdar | D37: Estudio de Prefactibilidad Explotación Proyecto Minero, Rusia. | E37: =+_xlfn.XLOOKUP(B37,'POM 2024'!B:B,'POM 2024'!F:F,"!",0,1) -> Ricardo Miranda | F37: =+_xlfn.XLOOKUP(B37,'POM 2024'!B:B,'POM 2024'!H:H,"!",0,1) -> Gerson Alfaro | G37: =+J37 -> 0 | H37: 0 | I37: =+SUM(G37:H37) -> 0 | J37: =VLOOKUP(B37,'POM 2024'!$B$2:$BI$64,48,FALSE) -> 0 | K37: =+_xlfn.XLOOKUP($B37,'POM 2024'!B:B,'POM 2024'!AV:AV,"!",0,1) -> 0 | L37: =+_xlfn.XLOOKUP($B37,'POM 2024'!B:B,'POM 2024'!AU:AU,"!",0,1) -> 0 | M37: =+J37-L37 -> 0 | N37: =+IFERROR(((J37-K37)/K37),0) -> 0 | O37: =IF(_xlfn.XLOOKUP($B37,'POM 2024'!B:B,'POM 2024'!L:L,"!",0,1)<0,0,_xlfn.XLOOKUP($B37,'POM 2024'!B:B,'POM 2024'!L:L,"!",0,1)) -> 0 | P37: =+O37-L37 -> 0 | R37: Administrativo | S37: Ejecución | T37: En Proceso | U37: =+I37=J37 -> TRUE
B38: MCI_Mine Plan Review Los Bronces | C38: Mitsubichi | D38: Revisión y evaluación de oportunidades para el plan minero de largo plazo de Los Bronces (LB) | E38: Cristian Quezada | F38: TBD | G38: =+J38 -> 0 | H38: 0 | I38: =+SUM(G38:H38) -> 0 | J38: =VLOOKUP(B38,'POM 2024'!$B$2:$BI$64,48,FALSE) -> 0 | K38: =+_xlfn.XLOOKUP($B38,'POM 2024'!B:B,'POM 2024'!AV:AV,"!",0,1) -> 0 | L38: =+_xlfn.XLOOKUP($B38,'POM 2024'!B:B,'POM 2024'!AU:AU,"!",0,1) -> 69250 | M38: =+J38-L38 -> -69250 | N38: =+IFERROR(((J38-K38)/K38),0) -> 0 | O38: =IF(_xlfn.XLOOKUP($B38,'POM 2024'!B:B,'POM 2024'!L:L,"!",0,1)<0,0,_xlfn.XLOOKUP($B38,'POM 2024'!B:B,'POM 2024'!L:L,"!",0,1)) -> 23720 | P38: =+O38-L38 -> -45530 | Q38: Se generará el seungo EDP cuando el avance fisico alcance el 50% | S38: Ejecución | T38: En Proceso | U38: =+I38=J38 -> TRUE
B39: MEIA Coripuno | C39: Coripuno | D39: Coripuno MEIA | E39: Matias Fuentes | F39: Jhonny Pacheco | G39: =+J39 -> 23980 | H39: 0 | I39: =+SUM(G39:H39) -> 23980 | J39: =VLOOKUP(B39,'POM 2024'!$B$2:$BI$64,48,FALSE) -> 23980 | K39: =+_xlfn.XLOOKUP($B39,'POM 2024'!B:B,'POM 2024'!AV:AV,"!",0,1) -> 23980 | L39: =+_xlfn.XLOOKUP($B39,'POM 2024'!B:B,'POM 2024'!AU:AU,"!",0,1) -> 47960 | M39: =+J39-L39 -> -23980 | N39: =+IFERROR(((J39-K39)/K39),0) -> 0 | O39: =IF(_xlfn.XLOOKUP($B39,'POM 2024'!B:B,'POM 2024'!L:L,"!",0,1)<0,0,_xlfn.XLOOKUP($B39,'POM 2024'!B:B,'POM 2024'!L:L,"!",0,1)) -> 2398 | P39: =+O39-L39 -> -45562 | S39: Ejecución | T39: En Proceso | U39: =+I39=J39 -> TRUE
B40: EMX_Metallurgical expert for review | C40: EMX | D40: Metallurgical expert for review | E40: Matias Fuentes | F40: Fernando Rodriguez | G40: =+J40 -> 0 | H40: 0 | I40: =+SUM(G40:H40) -> 0 | J40: =VLOOKUP(B40,'POM 2024'!$B$2:$BI$64,48,FALSE) -> 0 | K40: =+_xlfn.XLOOKUP($B40,'POM 2024'!B:B,'POM 2024'!AV:AV,"!",0,1) -> 0 | L40: =+_xlfn.XLOOKUP($B40,'POM 2024'!B:B,'POM 2024'!AU:AU,"!",0,1) -> 0 | M40: =+J40-L40 -> 0 | N40: =+IFERROR(((J40-K40)/K40),0) -> 0 | O40: =IF(_xlfn.XLOOKUP($B40,'POM 2024'!B:B,'POM 2024'!L:L,"!",0,1)<0,0,_xlfn.XLOOKUP($B40,'POM 2024'!B:B,'POM 2024'!L:L,"!",0,1)) -> 0 | P40: =+O40-L40 -> 0 | S40: Ejecución | T40: En Proceso | U40: =+I40=J40 -> TRUE
B41: EMX_Due Diligence de Chapi | C41: =+_xlfn.XLOOKUP(B41,'[1]Proyectos (NO FILTRAR)'!$F:$F,'[1]Proyectos (NO FILTRAR)'!$I:$I) -> EMX Royalty | D41: Revisión para oportunidades de negocio Proyecto Chapi | E41: Fernando Rodriguez | F41: - | G41: =+J41 -> 26649 | H41: 0 | I41: =+SUM(G41:H41) -> 26649 | J41: =VLOOKUP(B41,'POM 2024'!$B$2:$BI$130,48,FALSE) -> 26649 | K41: =+_xlfn.XLOOKUP($B41,'POM 2024'!B:B,'POM 2024'!AV:AV,"!",0,1) -> 0 | L41: =+_xlfn.XLOOKUP($B41,'POM 2024'!B:B,'POM 2024'!AU:AU,"!",0,1) -> 0 | M41: =+J41-L41 -> 26649 | N41: =+IFERROR(((J41-K41)/K41),0) -> 0 | O41: =IF(_xlfn.XLOOKUP($B41,'POM 2024'!B:B,'POM 2024'!L:L,"!",0,1)<0,0,_xlfn.XLOOKUP($B41,'POM 2024'!B:B,'POM 2024'!L:L,"!",0,1)) -> 0 | S41: Ejecución | T41: En Proceso | U41: =+I41=J41 -> TRUE
B42: IvanhoeElectric_Mine Planning Support | C42: =+_xlfn.XLOOKUP(B42,'[1]Proyectos (NO FILTRAR)'!$F:$F,'[1]Proyectos (NO FILTRAR)'!$I:$I) -> Ivanhoe Electric | D42: Mine Planning Support | E42: Matias Fuentes | F42: Carlos Morante | G42: =+J42 -> 38146 | H42: 0 | I42: =+SUM(G42:H42) -> 38146 | J42: =VLOOKUP(B42,'POM 2024'!$B$2:$BI$130,48,FALSE) -> 38146 | K42: =+_xlfn.XLOOKUP($B42,'POM 2024'!B:B,'POM 2024'!AV:AV,"!",0,1) -> 0 | L42: =+_xlfn.XLOOKUP($B42,'POM 2024'!B:B,'POM 2024'!AU:AU,"!",0,1) -> 0 | M42: =+J42-L42 -> 38146 | N42: =+IFERROR(((J42-K42)/K42),0) -> 0 | O42: =IF(_xlfn.XLOOKUP($B42,'POM 2024'!B:B,'POM 2024'!L:L,"!",0,1)<0,0,_xlfn.XLOOKUP($B42,'POM 2024'!B:B,'POM 2024'!L:L,"!",0,1)) -> 41413 | S42: Ejecución | T42: En Proceso | U42: =+I42=J42 -> TRUE
B43: J&F_Autazes Due Diligence | C43: =+_xlfn.XLOOKUP(B43,'[1]Proyectos (NO FILTRAR)'!$F:$F,'[1]Proyectos (NO FILTRAR)'!$I:$I) -> J&F | D43: Revisión para evaluar posibles oportunidades de negocio de LHG Mining | E43: =+_xlfn.XLOOKUP(B43,'POM 2024'!B:B,'POM 2024'!F:F,"!",0,1) -> - | F43: =+_xlfn.XLOOKUP(B43,'POM 2024'!B:B,'POM 2024'!H:H,"!",0,1) -> Kevin Rios | G43: =+J43 -> 72664 | H43: 0 | I43: =+SUM(G43:H43) -> 72664 | J43: =VLOOKUP(B43,'POM 2024'!$B$2:$BI$129,48,FALSE) -> 72664 | K43: =+_xlfn.XLOOKUP($B43,'POM 2024'!B:B,'POM 2024'!AV:AV,"!",0,1) -> 0 | L43: =+_xlfn.XLOOKUP($B43,'POM 2024'!B:B,'POM 2024'!AU:AU,"!",0,1) -> 70000 | M43: =+J43-L43 -> 2664 | N43: =+IFERROR(((J43-K43)/K43),0) -> 0 | O43: =IF(_xlfn.XLOOKUP($B43,'POM 2024'!B:B,'POM 2024'!L:L,"!",0,1)<0,0,_xlfn.XLOOKUP($B43,'POM 2024'!B:B,'POM 2024'!L:L,"!",0,1)) -> 1791 | S43: Ejecución | T43: En Proceso | U43: =+I43=J43 -> TRUE
B44: SierraMetals_Update MEIA Yauricocha | C44: =+_xlfn.XLOOKUP(B44,'[1]Proyectos (NO FILTRAR)'!$F:$F,'[1]Proyectos (NO FILTRAR)'!$I:$I) -> Sierra metals | D44: MEIA- Actualización de los dieños de labores y envolvente | E44: =+_xlfn.XLOOKUP(B44,'POM 2024'!B:B,'POM 2024'!F:F,"!",0,1) -> - | F44: =+_xlfn.XLOOKUP(B44,'POM 2024'!B:B,'POM 2024'!H:H,"!",0,1) -> - | G44: =+J44 -> 20941 | H44: 0 | I44: =+SUM(G44:H44) -> 20941 | J44: =VLOOKUP(B44,'POM 2024'!$B$2:$BI$129,48,FALSE) -> 20941 | K44: =+_xlfn.XLOOKUP($B44,'POM 2024'!B:B,'POM 2024'!AV:AV,"!",0,1) -> 0 | L44: =+_xlfn.XLOOKUP($B44,'POM 2024'!B:B,'POM 2024'!AU:AU,"!",0,1) -> 25919.1 | M44: =+J44-L44 -> -4978.1 | N44: =+IFERROR(((J44-K44)/K44),0) -> 0 | O44: =IF(_xlfn.XLOOKUP($B44,'POM 2024'!B:B,'POM 2024'!L:L,"!",0,1)<0,0,_xlfn.XLOOKUP($B44,'POM 2024'!B:B,'POM 2024'!L:L,"!",0,1)) -> 5647 | Q44: Kevin Rios | S44: Ejecución | T44: En Proceso | U44: =+I44=J44 -> TRUE
B45: CMP_LOM CNN 2024 | C45: =+_xlfn.XLOOKUP(B45,'[1]Proyectos (NO FILTRAR)'!$F:$F,'[1]Proyectos (NO FILTRAR)'!$I:$I) -> CMP | D45: LOM CNN 2024 | E45: =+_xlfn.XLOOKUP(B45,'POM 2024'!B:B,'POM 2024'!F:F,"!",0,1) -> Cristian Quezada | F45: =+_xlfn.XLOOKUP(B45,'POM 2024'!B:B,'POM 2024'!H:H,"!",0,1) -> TBD | G45: =+J45 -> 34041 | H45: 0 | I45: =+SUM(G45:H45) -> 34041 | J45: =VLOOKUP(B45,'POM 2024'!$B$2:$BI$73,48,FALSE) -> 34041 | K45: =+_xlfn.XLOOKUP($B45,'POM 2024'!B:B,'POM 2024'!AV:AV,"!",0,1) -> 36850 | L45: =+_xlfn.XLOOKUP($B45,'POM 2024'!B:B,'POM 2024'!AU:AU,"!",0,1) -> 0 | M45: =+J45-L45 -> 34041 | N45: =+IFERROR(((J45-K45)/K45),0) -> -0.076227951 | O45: =IF(_xlfn.XLOOKUP($B45,'POM 2024'!B:B,'POM 2024'!L:L,"!",0,1)<0,0,_xlfn.XLOOKUP($B45,'POM 2024'!B:B,'POM 2024'!L:L,"!",0,1)) -> 2164 | P45: =+O45-L45 -> 2164 | S45: Ejecución | T45: En Proceso | U45: =+I45=J45 -> TRUE
B46: CMP_LOM MLC 2024 | C46: =+_xlfn.XLOOKUP(B46,'[1]Proyectos (NO FILTRAR)'!$F:$F,'[1]Proyectos (NO FILTRAR)'!$I:$I) -> CMP | D46: LOM MLC 2024 | E46: =+_xlfn.XLOOKUP(B46,'POM 2024'!B:B,'POM 2024'!F:F,"!",0,1) -> Cristian Quezada | F46: =+_xlfn.XLOOKUP(B46,'POM 2024'!B:B,'POM 2024'!H:H,"!",0,1) -> TBD | G46: =+J46 -> 26563 | H46: 0 | I46: =+SUM(G46:H46) -> 26563 | J46: =VLOOKUP(B46,'POM 2024'!$B$2:$BI$73,48,FALSE) -> 26563 | K46: =+_xlfn.XLOOKUP($B46,'POM 2024'!B:B,'POM 2024'!AV:AV,"!",0,1) -> 28800 | L46: =+_xlfn.XLOOKUP($B46,'POM 2024'!B:B,'POM 2024'!AU:AU,"!",0,1) -> 0 | M46: =+J46-L46 -> 26563 | N46: =+IFERROR(((J46-K46)/K46),0) -> -0.077673611 | O46: =IF(_xlfn.XLOOKUP($B46,'POM 2024'!B:B,'POM 2024'!L:L,"!",0,1)<0,0,_xlfn.XLOOKUP($B46,'POM 2024'!B:B,'POM 2024'!L:L,"!",0,1)) -> 1836 | P46: =+O46-L46 -> 1836 | S46: Ejecución | T46: En Proceso | U46: =+I46=J46 -> TRUE
B47: CMP_Puesta en marcha SLS Romeral | C47: =+_xlfn.XLOOKUP(B47,'[1]Proyectos (NO FILTRAR)'!$F:$F,'[1]Proyectos (NO FILTRAR)'!$I:$I) -> CMP | D47: Puesta en marcha SLS Romeral | E47: =+_xlfn.XLOOKUP(B47,'POM 2024'!B:B,'POM 2024'!F:F,"!",0,1) -> Ricardo Miranda | F47: =+_xlfn.XLOOKUP(B47,'POM 2024'!B:B,'POM 2024'!H:H,"!",0,1) -> Pablo Quiero | G47: =+J47 -> 135485 | H47: 0 | I47: =+SUM(G47:H47) -> 135485 | J47: =VLOOKUP(B47,'POM 2024'!$B$2:$BI$73,48,FALSE) -> 135485 | K47: =+_xlfn.XLOOKUP($B47,'POM 2024'!B:B,'POM 2024'!AV:AV,"!",0,1) -> 140000 | L47: =+_xlfn.XLOOKUP($B47,'POM 2024'!B:B,'POM 2024'!AU:AU,"!",0,1) -> 0 | M47: =+J47-L47 -> 135485 | N47: =+IFERROR(((J47-K47)/K47),0) -> -0.03225 | O47: =IF(_xlfn.XLOOKUP($B47,'POM 2024'!B:B,'POM 2024'!L:L,"!",0,1)<0,0,_xlfn.XLOOKUP($B47,'POM 2024'!B:B,'POM 2024'!L:L,"!",0,1)) -> 130940.85 | P47: =+O47-L47 -> 130940.85 | S47: Ejecución | T47: En Proceso | U47: =+I47=J47 -> TRUE
G48: =+SUM(G21:G47) -> 887997.15 | H48: =+SUM(H21:H47) -> 0 | I48: =+SUM(I21:I47) -> 887997.15 | J48: =+SUM(J21:J47) -> 887997.15 | K48: =+SUM(K21:K47) -> 550910.74 | L48: =+SUM(L21:L47) -> 1006721.6 | M48: =+SUM(M21:M47) -> -118724.47 | N48: =+IFERROR(((J48-K48)/K48),0) -> 0.61187119 | O48: =+SUM(O21:O47) -> 258208.39 | P48: =+SUM(P21:P40) -> -836385.98
C52: =+C20 -> Cliente | D52: =+D20 -> Nombre Proyecto | E52: =+E20 -> Director | F52: =+F20 -> Ing Principal | G52: =+G20 -> Real | H52: =+H20 -> Otros | I52: =+I20 -> 0 | J52: =+J20 -> EDP Real | ... Q52: =+Q20 -> Comentarios | R52: Tipo 1 | S52: Tipo 2 | T52: Estatus
B53: CMP - FEL 2A | C53: CMP | D53: FEL2A Valle Elqui Norte | E53: =+_xlfn.XLOOKUP(B53,'POM 2024'!B:B,'POM 2024'!F:F,"!",0,1) -> Alex Figueroa | F53: =+_xlfn.XLOOKUP(B53,'POM 2024'!B:B,'POM 2024'!H:H,"!",0,1) -> Felipe Lira | G53: =+J53 -> 0 | H53: 0 | I53: =+SUM(G53:H53) -> 0 | J53: =VLOOKUP(B53,'POM 2024'!$B$2:$BI$64,48,FALSE) -> 0 | K53: =+_xlfn.XLOOKUP($B53,'POM 2024'!B:B,'POM 2024'!AP:AP,"!",0,1) -> 0 | L53: =+_xlfn.XLOOKUP($B53,'POM 2024'!B:B,'POM 2024'!AU:AU,"!",0,1) -> 0 | M53: =+J53-L53 -> 0 | N53: =+IFERROR(((J53-K53)/K53),0) -> 0 | O53: =IF(_xlfn.XLOOKUP($B53,'POM 2024'!B:B,'POM 2024'!L:L,"!",0,1)<0,0,_xlfn.XLOOKUP($B53,'POM 2024'!B:B,'POM 2024'!L:L,"!",0,1)) -> 0 | P53: =+O53-L53 -> 0 | R53: Técnico | S53: Terminal | T53: En Proceso | U53: =+I53=J53 -> TRUE
B54: CMP - FEL 2A | C54: CMP | D54: FEL2A Valle Elqui Norte - Update de modelos | E54: =+_xlfn.XLOOKUP(B54,'POM 2024'!B:B,'POM 2024'!F:F,"!",0,1) -> Alex Figueroa | F54: =+_xlfn.XLOOKUP(B54,'POM 2024'!B:B,'POM 2024'!H:H,"!",0,1) -> Felipe Lira | G54: =+J54 -> 0 | H54: 0 | I54: =+SUM(G54:H54) -> 0 | J54: ='POM 2024'!AT22 -> 0 | K54: =+_xlfn.XLOOKUP($B54,'POM 2024'!B:B,'POM 2024'!AP:AP,"!",0,1) -> 0 | L54: 0 | M54: =+J54-L54 -> 0 | N54: =+IFERROR(((J54-K54)/K54),0) -> 0 | O54: =IF(_xlfn.XLOOKUP($B54,'POM 2024'!B:B,'POM 2024'!L:L,"!",0,-1)<0,0,_xlfn.XLOOKUP($B54,'POM 2024'!B:B,'POM 2024'!L:L,"!",0,-1)) -> 0 | P54: =+O54-L54 -> 0 | R54: Técnico | S54: Terminal | T54: En Proceso | U54: =+I54=J54 -> TRUE
B55: Codelco_Capacitacion Deswik DET | C55: Codelco | D55: Capacitación y construcción de modelos de preparación minera usando software DESWIK | E55: =+_xlfn.XLOOKUP(B55,'POM 2024'!B:B,'POM 2024'!F:F,"!",0,1) -> Mauricio Melendez | F55: =+_xlfn.XLOOKUP(B55,'POM 2024'!B:B,'POM 2024'!H:H,"!",0,1) -> Felipe Lira | G55: =+J55 -> 13837 | H55: 0 | I55: =+SUM(G55:H55) -> 13837 | J55: =VLOOKUP(B55,'POM 2024'!$B$2:$BI$64,48,FALSE) -> 13837 | K55: =+_xlfn.XLOOKUP($B55,'POM 2024'!B:B,'POM 2024'!AP:AP,"!",0,1) -> 0 | L55: =+_xlfn.XLOOKUP($B55,'POM 2024'!B:B,'POM 2024'!AU:AU,"!",0,1) -> 0 | M55: =+J55-L55 -> 13837 | N55: =+IFERROR(((J55-K55)/K55),0) -> 0 | O55: =IF(_xlfn.XLOOKUP($B55,'POM 2024'!B:B,'POM 2024'!L:L,"!",0,1)<0,0,_xlfn.XLOOKUP($B55,'POM 2024'!B:B,'POM 2024'!L:L,"!",0,1)) -> 0 | P55: =+O55-L55 -> 0 | R55: Técnico | S55: Terminal | T55: En Proceso | U55: =+I55=J55 -> TRUE
...

Sheet Curva S
A1: Código | B1: Proyectos | C1: 45139 | D1: 45170 | E1: 45200 | F1: 45231 | G1: 45261 | H1: 45292 | I1: 45323 | J1: 45352 | K1: 45383 | L1: 45413 | M1: 45444 | N1: 45474 | O1: 45505 | P1: 45536 | Q1: 45566 | R1: 45597 | S1: 45627
B2: Actualización LoM Raura | C2: 0 | D2: 1 | E2: 1 | F2: 1 | G2: 1 | H2: 1
B3: Candelaria (Estandar y Planificacion) | C3: 0.56 | D3: 0.56 | E3: 0.56 | F3: 0.56 | G3: 0.56 | H3: 0.56
B4: CMP - FEL 2A | C4: 0.94 | D4: 0.9560571 | E4: 1 | F4: 1 | G4: 1 | H4: 1 | I4: 1 | J4: 1 | K4: 1 | L4: 1 | M4: 1 | N4: 1 | O4: 1 | P4: 1 | Q4: 1 | R4: 1 | S4: 1
B5: Adrianita -Raúl | C5: 1 | D5: 1 | E5: 1 | F5: 1 | G5: 1 | H5: 1
B6: Codelco_Falla Oeste | C6: 0.16 | D6: 0.66 | E6: 0.88 | F6: 1 | G6: 1 | H6: 1
B7: Codelco_Panel Central | C7: 0.22 | D7: 0.63 | E7: 0.85 | F7: 1 | G7: 1 | H7: 1
B8: Diagnóstico Operacional Candelaria | C8: 0.95 | D8: 1 | E8: 1 | F8: 1 | G8: 1 | H8: 1
B9: Sierra Metals_Plan de Minado MEIA | C9: 0 | D9: 0.49 | E9: 0.78 | F9: 1 | G9: 1 | H9: 1 | I9: 1
B10: Mosaic_Cajati | C10: 0.34 | D10: 0.45313995 | E10: 0.24 | F10: 0.52 | G10: 0.8 | H10: 0.6 | I10: 0.76 | J10: 0.9 | K10: 1 | L10: 1 | M10: 1 | N10: 1 | O10: 1 | P10: 1 | Q10: 1 | R10: 1 | S10: 1
B11: Mosaic_Taquari Vassouras | C11: 0 | D11: 0.06 | E11: 0.41 | F11: 0.62 | G11: 0.88 | H11: 1 | I11: 1 | J11: 1 | K11: 1
B12: NEXA_FEL2 Aripuana | C12: 0 | D12: 0.09 | E12: 0.43 | F12: 0.44 | G12: 1 | H12: 1 | I12: 1 | J12: 1 | K12: 1 | L12: 1 | M12: 1 | N12: 1 | O12: 1 | P12: 1 | Q12: 1 | R12: 1 | S12: 1
B13: Romeral | C13: 0.89 | D13: 1 | E13: 1 | F13: 1 | G13: 1 | H13: 1
B14: Minsur_Forecast_Budget24 | C14: 0 | D14: 0.69 | E14: 1 | F14: 1 | G14: 1 | H14: 1
B15: San Rafael: Gestión del Corto Plazo | C15: 0.09 | D15: 0.24 | E15: 0.85 | F15: 1 | G15: 1 | H15: 1
B16: Lomas Bayas - LoA24 | C16: 1 | D16: 1 | E16: 1 | F16: 1 | G16: 1 | H16: 1
B17: Pilares Mineros - Candelaria | C17: 1 | D17: 1 | E17: 1 | F17: 1 | G17: 1 | H17: 1
B18: LOM CNN 2023 | C18: 1 | D18: 1 | E18: 1 | F18: 1 | G18: 1 | H18: 1
B19: LOM MLC 2023 | C19: 1 | D19: 1 | E19: 1 | F19: 1 | G19: 1 | H19: 1
B20: Algarrobo | C20: 1 | D20: 1 | E20: 1 | F20: 0.4 | G20: 1 | H20: 1
B21: CMP - FEL 2A | C21: 0 | D21: 0.12 | E21: 0.3 | F21: 1 | G21: 1 | H21: 1 | I21: 1 | J21: 1 | K21: 1 | L21: 1 | M21: 1 | N21: 1 | O21: 1 | P21: 1 | Q21: 1 | R21: 1 | S21: 1 | T21: Update de Modelos
B22: RDP | C22: 1 | D22: 1 | E22: 1 | F22: 1 | G22: 1 | H22: 1
B23: San Rafael Gestión Operativa | C23: 1 | D23: 1 | E23: 1 | F23: 1 | G23: 1 | H23: 1
B24: NorGold | C24: 1 | D24: 1 | E24: 1 | F24: 1 | G24: 1 | H24: 1
B25: Marcobre - Minajusta | C25: 1 | D25: 1 | E25: 1 | F25: 1 | G25: 1 | H25: 1
B26: PFS Los Calatos | F26: 0.1 | G26: 0.19 | H26: 0.22 | I26: 0.23 | J26: 0.34 | K26: 0.49 | L26: 0.54 | M26: 0.7 | N26: 0.82 | O26: =94% -> 0.94 | P26: 1 | Q26: 1 | R26: 1 | S26: 1
B27: CSH_LOM Mina Guarello
B28: AMSA_Planificacion | F28: 0.15 | G28: 0.92 | H28: 1
B29: MEIA Coripuno | E29: 0.24 | F29: 0.89 | G29: 1 | N29: 1
B30: Codelco_Capacitacion Deswik DET | F30: 0.43 | G30: 0.87 | H30: 1 | I30: 0.89 | K30: 0.94 | L30: 1
B31: Codelco_Drenaje QT | H31: 0.6 | I31: 0.84 | J31: 1
B32: MiskiMayo_LOM | H32: 0.5 | I32: 0.65 | J32: 0.87 | K32: 0.85 | L32: 1
B33: CMP_CNN Update plan LOM | H33: 1 | I33: 1 | J33: 1
B34: CMP_Los Colorados Adelantamiento Planta | H34: 0.43 | I34: 1 | J34: 1 | K34: 1 | L34: 1
B35: LasBambas_Ferrobamba_OP_UG | H35: 0.5 | I35: 0.63 | J35: 0.79 | K35: 0.54 | L35: 0.82 | M35: 0.91 | N35: 1
B36: CMP_Romeral Estabilización + UG PFS | H36: 0.08 | I36: 0.31 | J36: 0.53 | K36: 0.67 | L36: 0.56 | M36: 0.9 | N36: 1
B37: Codelco_Cluster Toki | H37: 1 | I37: 1 | J37: 1
B38: IvanhoeElectric_Santa-Cruz_PrePFS | H38: 0.34 | I38: 0.61 | J38: 0.87 | K38: 0.93 | L38: 1 | M38: 1
B39: Boston_Inmaculada Hochschild | J39: 1
B40: Minsur_Update LOM San Rafael | I40: 1
...

Sheet Formato Backlog_Sept25
F1: =SUM(F22:F25) -> 366737 | G1: =SUM(G22:G25) -> 297004 | H1: =+G1/F1 -> 0.80985556 | I1: =SUM(I22:I25) -> 69733 | J1: =+I1/F1 -> 0.19014444
A3: Código | B3: Proyecto | C3: País | D3: Año Inicio | E3: Director | F3: Contrato US$ | G3: Emitido US$ | H3: Avance Financiero% | I3: Saldo US$ | J3: Saldo % | K3: Saldo Acum% | L3: Saldo Acum
A4: BR-EQG-UG-FEL03-172-A | B4: EQUINOX_Actualización Ing. Básica UG | C4: Brasil | D4: 2025 | E4: Alex Figueroa | F4: 330237.61 | G4: 12415 | H4: =+G4/F4 -> 0.037594143 | I4: =+F4-G4 -> 317822.61 | J4: =+I4/F4 -> 0.96240586 | K4: =+L4/$L$24 -> 0.14236106 | L4: =+I4 -> 317822.61
A5: BR-ERC-UG-FEL00-152-A | B5: EroCopper_Scoping Proyecto Furnas | C5: Brasil | D5: 2025 | E5: Alex Figueroa | F5: 484000 | G5: 223644 | H5: =+G5/F5 -> 0.46207438 | I5: =+F5-G5 -> 260356 | J5: =+I5/F5 -> 0.53792562 | K5: =+L5/$L$24 -> 0.25898133 | L5: =+L4+I5 -> 578178.61
A6: PE-MMG-UG-FEL2A-143-A | B6: LasBambas_Ferrobamba PFS | C6: Perú | D6: 2025 | E6: JF San Martin | F6: 920000 | G6: 665060.59 | H6: =+G6/F6 -> 0.72289195 | I6: =+F6-G6 -> 254939.41 | J6: =+I6/F6 -> 0.27710805 | K6: =+L6/$L$24 -> 0.37317536 | L6: =+L5+I6 -> 833118.02
A7: OT-RES-CS-OTR00-178-A | B7: Resolution_General Review | C7: Otros | D7: 2025 | E7: Carolina Arcos | F7: 185615 | G7: 0 | H7: =+G7/F7 -> 0 | I7: =+F7-G7 -> 185615 | J7: =+I7/F7 -> 1 | K7: =+L7/$L$24 -> 0.45631717 | L7: =+L6+I7 -> 1018733
A8: PE-ALP-GM-FEL00-156-A | B8: Alpayana_Estudio de Sismicidad | C8: Perú | D8: 2025 | E8: Claudio Hernández | F8: 197494 | G8: 43788 | H8: =+G8/F8 -> 0.22171813 | I8: =+F8-G8 -> 153706 | J8: =+I8/F8 -> 0.77828187 | K8: =+L8/$L$24 -> 0.52516611 | L8: =+L7+I8 -> 1172439
A9: CH-AMS-OP-FEL00-171-A | B9: AMSA_RIINO BC - Centinela | C9: Chile | D9: 2025 | E9: Felipe Rojas | F9: 141656.26 | G9: 0 | H9: =+G9/F9 -> 0 | I9: =+F9-G9 -> 141656.26 | J9: =+I9/F9 -> 1 | K9: =+L9/$L$24 -> 0.58861766 | L9: =+L8+I9 -> 1314095.3
A10: CH-CRF-CS-FEL00-169-A | B10: CORFO_Valorización Boquerón Chañar | C10: Chile | D10: 2025 | E10: Carolina Arcos | F10: 123838.96 | G10: 0 | H10: =+G10/F10 -> 0 | I10: =+F10-G10 -> 123838.96 | J10: =+I10/F10 -> 1 | K10: =+L10/$L$24 -> 0.64408837 | L10: =+L9+I10 -> 1437934.2
A11: PE-SPM-UG-FEL03-160-A | B11: SPM_FS Labores Subterraneas 2da MEIA | C11: Perú | D11: 2025 | E11: Sin Director | F11: 99244 | G11: 0 | H11: =+G11/F11 -> 0 | I11: =+F11-G11 -> 99244 | J11: =+I11/F11 -> 1 | K11: =+L11/$L$24 -> 0.68854235 | L11: =+L10+I11 -> 1537178.2
A12: BR-MOS-UG-OTR00-098-A | B12: Mosaic_Taquari Vassouras Fase II | C12: Brasil | D12: 2024 | E12: Claudio Hernández | F12: 330410 | G12: 242146.09 | H12: =+G12/F12 -> 0.7328655 | I12: =+F12-G12 -> 88263.91 | J12: =+I12/F12 -> 0.2671345 | K12: =+L12/$L$24 -> 0.72807807 | L12: =+L11+I12 -> 1625442.1
A13: PE-NEX-GM-FEL00-167-A | B13: NEXA_Estudio Geomecánico AT y EP | C13: Perú | D13: 2025 | E13: Claudio Hernández | F13: 80283 | G13: 0 | H13: =+G13/F13 -> 0 | I13: =+F13-G13 -> 80283 | J13: =+I13/F13 -> 1 | K13: =+L13/$L$24 -> 0.76403892 | L13: =+L12+I13 -> 1705725.1
A14: CH-AMS-CS-OTR00-165-A | B14: AMSA_Mejoras Planificación Centinela | C14: Chile | D14: 2025 | E14: Felipe Rojas | F14: 80125 | G14: 0 | H14: =+G14/F14 -> 0 | I14: =+F14-G14 -> 80125 | J14: =+I14/F14 -> 1 | K14: =+L14/$L$24 -> 0.79992901 | L14: =+L13+I14 -> 1785850.1
A15: CH-CCO-CS-OTR00-159-A | B15: Capstone Copper_Production at Risk | C15: Chile | D15: 2025 | E15: Gonzalo Díaz | F15: 148240 | G15: 88297 | H15: =+G15/F15 -> 0.59563546 | I15: =+F15-G15 -> 59943 | J15: =+I15/F15 -> 0.40436454 | K15: =+L15/$L$24 -> 0.82677905 | L15: =+L14+I15 -> 1845793.1
A16: CH-AAM-CS-OTR00-179-A | B16: Anglo_Production at Risk Mina Rio | C16: Chile | D16: 2025 | E16: Gonzalo Díaz | F16: 84870 | G16: 26973 | H16: =+G16/F16 -> 0.31781548 | I16: =+F16-G16 -> 57897 | J16: =+I16/F16 -> 0.68218452 | K16: =+L16/$L$24 -> 0.85271263 | L16: =+L15+I16 -> 1903690.1
... A24: PE-MSR-UG-FEL00-142-A | B24: Minsur_San Rafael Estudio V MEIA | C24: Perú | D24: 2025 | E24: JF San Martin | F24: 231021 | G24: 222625 | H24: =+G24/F24 -> 0.96365698 | I24: =+F24-G24 -> 8396 | J24: =+I24/F24 -> 0.036343016 | K24: =+L24/$L$24 -> 1 | L24: =+L23+I24 -> 2232510.8
A29: Etiquetas de fila | B29: Suma de Saldo US$ | C29: %
A30: Brasil | B30: 747122.17 | C30: =+B30/$B$34 -> 0.33465557
A31: Perú | B31: 626284.41 | C31: =+B31/$B$34 -> 0.28052917
A32: Chile | B32: 621089.22 | C32: =+B32/$B$34 -> 0.27820211
A33: Otros | B33: 238015 | C33: =+B33/$B$34 -> 0.10661315
A34: Total general | B34: 2232510.8 | C34: =+B34/$B$34 -> 1
A37: Etiquetas de fila | B37: Suma de Saldo US$ | C37: Cuenta de Saldo US$2
A38: Alex Figueroa | B38: 627237.26 | C38: 3
A39: Claudio Hernández | B39: 351968.91 | C39: 4
A40: Carolina Arcos | B40: 341074.96 | C40: 3
A41: Felipe Rojas | B41: 324917.26 | C41: 4
A42: JF San Martin | B42: 263335.41 | C42: 2
A43: Sin Director | B43: 206137 | C43: 3
A44: Gonzalo Díaz | B44: 117840 | C44: 2
A45: Total general | B45: 2232510.8 | C45: 21
A51: Etiquetas de fila | B51: Suma de Saldo US$ | C51: Cuenta de Saldo US$2
A52: Alex Figueroa | B52: 627237.26 | C52: 3 | D52: =+B52/$B$59 -> 0.28095598
A53: Claudio Hernández | B53: 351968.91 | C53: 4 | D53: =+B53/$B$59 -> 0.15765608
A54: Carolina Arcos | B54: 341074.96 | C54: 3 | D54: =+B54/$B$59 -> 0.1527764
A55: Felipe Rojas | B55: 324917.26 | C55: 4 | D55: =+B55/$B$59 -> 0.14553894
A56: JF San Martin | B56: 263335.41 | C56: 2 | D56: =+B56/$B$59 -> 0.11795482
A57: Sin Director | B57: 206137 | C57: 3 | D57: =+B57/$B$59 -> 0.092334156
A58: Gonzalo Díaz | B58: 117840 | C58: 2 | D58: =+B58/$B$59 -> 0.052783619
B59: =SUM(B52:B58) -> 2232510.8 | C59: =SUM(C52:C58) -> 21
...

Sheet POM 2024
AE1: =+COUNTIF(AE3:AE88,">0") -> 15 | AF1: =+COUNTIF(AF3:AF73,">0") -> 17 | AG1: =+COUNTIF(AG3:AG73,">0") -> 17 | AH1: =+COUNTIF(AH3:AH88,">0") -> 15 | AI1: =+COUNTIF(AI3:AI73,">0") -> 17 | AJ1: =+COUNTIF(AJ3:AJ73,">0") -> 15 | AK1: =+COUNTIF(AK3:AK88,">0") -> 11 | AL1: =+COUNTIF(AL3:AL73,">0") -> 17 | AM1: =+COUNTIF(AM3:AM73,">0") -> 17 | AN1: =+COUNTIF(AN3:AN88,">0") -> 14 | AO1: =+COUNTIF(AO3:AO73,">0") -> 16 | AP1: =+COUNTIF(AP3:AP73,">0") -> 0 | AQ1: =+COUNTIF(AQ3:AQ88,">0") -> 12 | AR1: =+COUNTIF(AR3:AR73,">0") -> 18 | AS1: =+COUNTIF(AS3:AS73,">0") -> 13 | AT1: =+COUNTIF(AT3:AT88,">0") -> 12 | AU1: =+COUNTIF(AU3:AU73,">0") -> 20 | AV1: =+COUNTIF(AV3:AV73,">0") -> 11 | AW1: =+COUNTIF(AW3:AW88,">0") -> 28 | AX1: =+COUNTIF(AX3:AX48,">0") -> 3 | AY1: =+COUNTIF(AY3:AY48,">0") -> 0 | AZ1: =+COUNTIF(AZ3:AZ88,">0") -> 17 | BA1: =+COUNTIF(BA3:BA48,">0") -> 3 | BB1: =+COUNTIF(BB3:BB48,">0") -> 0 | BC1: =+COUNTIF(BC3:BC88,">0") -> 18 | BD1: =+COUNTIF(BD3:BD48,">0") -> 1 | BE1: =+COUNTIF(BE3:BE94,">0") -> 16 | BF1: =+COUNTIF(BF3:BF94,">0") -> 24 | BG1: =+COUNTIF(BG3:BG94,">0") -> 18 | BH1: =+COUNTIF(BH3:BH96,">0") -> 23 | BI1: =+COUNTIF(BI3:BI94,">0") -> 19
A2: Código | B2: Proyecto | C2: País | D2: Estado Comercial | E2: Estado Operativo | F2: Director | G2: Consultor | H2: Ingeniero Principal | I2: Monto Contrato (USD) | J2: Emitido Acumulado Actual [USD] | K2: Avance Financiero Actual % | L2: Saldo actual [USD] | M2: Saldo actual % | N2: Acumulado Proyectado (USD) | O2: Avance Proyectado % | P2: Saldo Proyectado (USD) | Q2: Emitido Acumulado 2023 | R2: Saldo 2024 (USD) | S2: SEPT POM | T2: SEPT R | U2: OCT RESAGADO | V2: OCT F | W2: OCT R | X2: NOV F | Y2: NOV R | Z2: DIC F | AA2: DIC P | AB2: DIC R | AC2: ENE F | AD2: ENE P | AE2: ENE R | AF2: FEB F | AG2: FEB P | AH2: FEB R | AI2: MAR F | AJ2: MAR P | AK2: MAR R | AL2: ABR F | AM2: ABR P | AN2: ABR R | AO2: MAY F | AP2: MAY P | AQ2: MAY R | AR2: JUN F | AS2: JUN P | AT2: JUN R | AU2: JUL F | AV2: JUL P | AW2: JUL R | AX2: AGO F | AY2: AGO P | AZ2: AGO R | BA2: SEP F | BB2: SEP P | BC2: SEP R | BD2: OCT P | BE2: OCT R | BF2: NOV P | BG2: NOV R | BH2: DIC P | BI2: DIC R | BK2: Oct | BL2: Nov | BM2: Dic
A3: =+_xlfn.XLOOKUP(B3,'[1]Proyectos (NO FILTRAR)'!$F:$F,'[1]Proyectos (NO FILTRAR)'!$B:$B,0,0,1) -> PE-MSR-UG-FEL03-008-A | B3: Actualización LoM Raura | C3: =+_xlfn.XLOOKUP(A3,'[1]Proyectos (NO FILTRAR)'!$B:$B,'[1]Proyectos (NO FILTRAR)'!$G:$G,"error",0,1) -> Perú | D3: Adjudicado | E3: Terminado | G3: Matias Fuentes | H3: Jorman Barrera | I3: 165237 | J3: =+Q3+AE3+AH3+AK3+AN3+AQ3+AT3+AW3+AZ3+BC3+BE3+BG3+BI3 -> 165237 | K3: =+IFERROR(J3/I3,0) -> 1 | L3: =+I3-J3 -> 0 | M3: =+IFERROR(L3/I3,0) -> 0 | O3: =IFERROR(N3/I3,0) -> 0 | P3: =+I3-N3 -> 165237 | Q3: 165237 | R3: =+I3-Q3 -> 0 | S3: 165237 | T3: 165237 | U3: 0 | V3: 0 | W3: 0 | X3: 0 | Z3: 0 | AA3: 0 | AC3: 0 | AF3: 0 | AI3: 0 | AL3: 0 | AO3: 0 | AR3: 0 | AU3: 0 | AX3: =+IF((_xlfn.XLOOKUP($B3,'Curva S'!$B$2:$B$100,'Curva S'!$O$2:$O$100,0,0,1)*$I3-$J3)<0,0,(_xlfn.XLOOKUP($B3,'Curva S'!$B$2:$B$100,'Curva S'!$O$2:$O$100,0,0,1)*$I3-$J3)) -> 0 | BA3: =+IF((_xlfn.XLOOKUP($B3,'Curva S'!$B$2:$B$100,'Curva S'!$P$2:$P$100,0,0,1)*$I3-$J3)<0,0,(_xlfn.XLOOKUP($B3,'Curva S'!$B$2:$B$100,'Curva S'!$P$2:$P$100,0,0,1)*$I3-$J3)) -> 0 | BK3: =+IF(AND(BD3>0,BE3=""),0,IF(BE3="","",IF(BE3>=BD3,1,BE3/BD3))) | BL3: =+IF(AND(BF3>0,BG3=""),0,IF(BG3="","",IF(BG3>=BF3,1,BG3/BF3))) | BM3: =+IF(AND(BH3>0,BI3=""),0,IF(BI3="","",IF(BI3>=BH3,1,BI3/BH3)))
A4: =+_xlfn.XLOOKUP(B4,'[1]Proyectos (NO FILTRAR)'!$F:$F,'[1]Proyectos (NO FILTRAR)'!$B:$B,0,0,1) -> CH-LUN-CS-OTR00-004-A | B4: Candelaria (Estandar y Planificacion) | C4: =+_xlfn.XLOOKUP(A4,'[1]Proyectos (NO FILTRAR)'!$B:$B,'[1]Proyectos (NO FILTRAR)'!$G:$G,"error",0,1) -> Chile | D4: Adjudicado | E4: Terminado | G4: Ricardo Miranda | H4: Felipe Matamoros | I4: 139847.12 | J4: =+Q4+AE4+AH4+AK4+AN4+AQ4+AT4+AW4+AZ4+BC4+BE4+BG4+BI4 -> 139847.12 | K4: =+IFERROR(J4/I4,0) -> 1 | L4: =+I4-J4 -> 0 | M4: =+IFERROR(L4/I4,0) -> 0 | O4: =IFERROR(N4/I4,0) -> 0 | P4: =+I4-N4 -> 139847.12 | Q4: 139847.12 | R4: =+I4-Q4 -> 0 | S4: 0 | T4: 0 | U4: 0 | V4: 0 | W4: 0 | X4: 0 | Z4: 0 | AA4: 0 | AC4: 0 | AF4: 0 | AI4: 0 | AL4: 0 | AO4: 0 | AR4: 0 | AU4: 0 | AX4: =+IF((_xlfn.XLOOKUP($B4,'Curva S'!$B$2:$B$100,'Curva S'!$O$2:$O$100,0,0,1)*$I4-$J4)<0,0,(_xlfn.XLOOKUP($B4,'Curva S'!$B$2:$B$100,'Curva S'!$O$2:$O$100,0,0,1)*$I4-$J4)) -> 0 | BA4: 0 | BK4: =+IF(AND(BD4>0,BE4=""),0,IF(BE4="","",IF(BE4>=BD4,1,BE4/BD4))) | BL4: =+IF(AND(BF4>0,BG4=""),0,IF(BG4="","",IF(BG4>=BF4,1,BG4/BF4))) | BM4: =+IF(AND(BH4>0,BI4=""),0,IF(BI4="","",IF(BI4>=BH4,1,BI4/BH4)))
A5: =+_xlfn.XLOOKUP(B5,'[1]Proyectos (NO FILTRAR)'!$F:$F,'[1]Proyectos (NO FILTRAR)'!$B:$B,0,0,1) -> CH-CMP-OU-FEL2A-033-A | B5: CMP - FEL 2A | C5: =+_xlfn.XLOOKUP(A5,'[1]Proyectos (NO FILTRAR)'!$B:$B,'[1]Proyectos (NO FILTRAR)'!$G:$G,"error",0,1) -> Chile | D5: Adjudicado | E5: En Proceso | F5: Alex Figueroa | G5: Felipe Rojas | H5: Felipe Lira | I5: 610108.79 | J5: =+Q5+AE5+AH5+AK5+AN5+AQ5+AT5+AW5+AZ5+BC5+BE5+BG5+BI5 -> 610108.79 | K5: =+IFERROR(J5/I5,0) -> 1 | L5: =+I5-J5 -> 0 | M5: =+IFERROR(L5/I5,0) -> 0 | O5: =IFERROR(N5/I5,0) -> 0 | P5: =+I5-N5 -> 610108.79 | Q5: 558961.99 | R5: =+I5-Q5 -> 51146.8 | S5: 37300 | T5: 21340 | U5: 15960 | V5: 25588.89 | W5: 9211.06 | X5: 28678.52 | Y5: =31481-Y22 -> 1672.39 | Z5: 27006.13 | AA5: 27006.13 | AB5: 7306 | AC5: 19700.13 | AD5: 19700.13 | AE5: 16995 | AF5: 2705.13 | AG5: 2705 | AH5: 2022.8 | AI5: 15886.33 | AJ5: 0 | AL5: 15886.33 | AM5: 10691 | AN5: 1896 | AO5: 13990.33 | AQ5: =10289-1314 -> 8975 | AR5: 25170.52 | AS5: 21258 | AT5: 21258 | AU5: 0 | AX5: =+IF((_xlfn.XLOOKUP($B5,'Curva S'!$B$2:$B$100,'Curva S'!$O$2:$O$100,0,0,1)*$I5-$J5)<0,0,(_xlfn.XLOOKUP($B5,'Curva S'!$B$2:$B$100,'Curva S'!$O$2:$O$100,0,0,1)*$I5-$J5)) -> 0 | BA5: 0 | BK5: =+IF(AND(BD5>0,BE5=""),0,IF(BE5="","",IF(BE5>=BD5,1,BE5/BD5))) | BL5: =+IF(AND(BF5>0,BG5=""),0,IF(BG5="","",IF(BG5>=BF5,1,BG5/BF5))) | BM5: =+IF(AND(BH5>0,BI5=""),0,IF(BI5="","",IF(BI5>=BH5,1,BI5/BH5)))
A6: =+_xlfn.XLOOKUP(B6,'[1]Proyectos (NO FILTRAR)'!$F:$F,'[1]Proyectos (NO FILTRAR)'!$B:$B,0,0,1) -> CH-CMP-OU-FEL00-001-A | B6: Adrianita -Raúl | C6: =+_xlfn.XLOOKUP(A6,'[1]Proyectos (NO FILTRAR)'!$B:$B,'[1]Proyectos (NO FILTRAR)'!$G:$G,"error",0,1) -> Chile | D6: Adjudicado | E6: Terminado | G6: Ricardo Miranda | H6: Ricardo Miranda | I6: 261767.16 | J6: =+Q6+AE6+AH6+AK6+AN6+AQ6+AT6+AW6+AZ6+BC6+BE6+BG6+BI6 -> 261767.16 | K6: =+IFERROR(J6/I6,0) -> 1 | L6: =+I6-J6 -> 0 | M6: =+IFERROR(L6/I6,0) -> 0 | O6: =IFERROR(N6/I6,0) -> 0 | P6: =+I6-N6 -> 261767.16 | Q6: 261767.16 | R6: =+I6-Q6 -> 0 | S6: 1136.0975 | T6: 274 | U6: 51143 | V6: 0 | W6: 51143 | X6: 0 | Z6: 0 | AA6: 0 | AC6: 0 | AF6: 0 | AI6: 0 | AL6: 0 | AO6: 0 | AR6: 0 | AU6: 0 | AX6: =+IF((_xlfn.XLOOKUP($B6,'Curva S'!$B$2:$B$100,'Curva S'!$O$2:$O$100,0,0,1)*$I6-$J6)<0,0,(_xlfn.XLOOKUP($B6,'Curva S'!$B$2:$B$100,'Curva S'!$O$2:$O$100,0,0,1)*$I6-$J6)) -> 0 | BA6: 0 | BK6: =+IF(AND(BD6>0,BE6=""),0,IF(BE6="","",IF(BE6>=BD6,1,BE6/BD6))) | BL6: =+IF(AND(BF6>0,BG6=""),0,IF(BG6="","",IF(BG6>=BF6,1,BG6/BF6))) | BM6: =+IF(AND(BH6>0,BI6=""),0,IF(BI6="","",IF(BI6>=BH6,1,BI6/BH6)))
A7: =+_xlfn.XLOOKUP(B7,'[1]Proyectos (NO FILTRAR)'!$F:$F,'[1]Proyectos (NO FILTRAR)'!$B:$B,0,0,1) -> CH-COD-UG-FEL01-031-A | B7: Codelco_Falla Oeste | C7: =+_xlfn.XLOOKUP(A7,'[1]Proyectos (NO FILTRAR)'!$B:$B,'[1]Proyectos (NO FILTRAR)'!$G:$G,"error",0,1) -> Chile | D7: Adjudicado | E7: Terminado | G7: Mauricio Melendez | H7: Freddy Diaz | I7: 93503 | J7: =+Q7+AE7+AH7+AK7+AN7+AQ7+AT7+AW7+AZ7+BC7+BE7+BG7+BI7 -> 93503 | K7: =+IFERROR(J7/I7,0) -> 1 | L7: =+I7-J7 -> 0 | M7: =+IFERROR(L7/I7,0) -> 0 | O7: =IFERROR(N7/I7,0) -> 0 | P7: =+I7-N7 -> 93503 | Q7: 93503 | R7: =+I7-Q7 -> 0 | S7: 61711.98 | T7: 67556 | U7: 0 | V7: 20570.66 | W7: 19139 | X7: 6808 | Y7: 6808 | Z7: 0 | AA7: 0 | AC7: 0 | AF7: 0 | AI7: 0 | AL7: 0 | AO7: 0 | AR7: 0 | AU7: 0 | AX7: =+IF((_xlfn.XLOOKUP($B7,'Curva S'!$B$2:$B$100,'Curva S'!$O$2:$O$100,0,0,1)*$I7-$J7)<0,0,(_xlfn.XLOOKUP($B7,'Curva S'!$B$2:$B$100,'Curva S'!$O$2:$O$100,0,0,1)*$I7-$J7)) -> 0 | BA7: 0 | BK7: =+IF(AND(BD7>0,BE7=""),0,IF(BE7="","",IF(BE7>=BD7,1,BE7/BD7))) | BL7: =+IF(AND(BF7>0,BG7=""),0,IF(BG7="","",IF(BG7>=BF7,1,BG7/BF7))) | BM7: =+IF(AND(BH7>0,BI7=""),0,IF(BI7="","",IF(BI7>=BH7,1,BI7/BH7)))
A8: =+_xlfn.XLOOKUP(B8,'[1]Proyectos (NO FILTRAR)'!$F:$F,'[1]Proyectos (NO FILTRAR)'!$B:$B,0,0,1) -> CH-COD-UG-FEL01-032-A | B8: Codelco_Panel Central | C8: =+_xlfn.XLOOKUP(A8,'[1]Proyectos (NO FILTRAR)'!$B:$B,'[1]Proyectos (NO FILTRAR)'!$G:$G,"error",0,1) -> Chile | D8: Adjudicado | E8: Terminado | G8: Mauricio Melendez | H8: Freddy Diaz | I8: 88171 | J8: =+Q8+AE8+AH8+AK8+AN8+AQ8+AT8+AW8+AZ8+BC8+BE8+BG8+BI8 -> 88171 | K8: =+IFERROR(J8/I8,0) -> 1 | L8: =+I8-J8 -> 0 | M8: =+IFERROR(L8/I8,0) -> 0 | O8: =IFERROR(N8/I8,0) -> 0 | P8: =+I8-N8 -> 88171 | Q8: 88171 | R8: =+I8-Q8 -> 0 | S8: 55585.53 | T8: 62838 | U8: 0 | V8: 19410.82 | W8: 17202 | X8: 8191 | Y8: 8131 | Z8: 0 | AA8: 0 | AC8: 0 | AF8: 0 | AI8: 0 | AL8: 0 | AO8: 0 | AR8: 0 | AU8: 0 | AX8: =+IF((_xlfn.XLOOKUP($B8,'Curva S'!$B$2:$B$100,'Curva S'!$O$2:$O$100,0,0,1)*$I8-$J8)<0,0,(_xlfn.XLOOKUP($B8,'Curva S'!$B$2:$B$100,'Curva S'!$O$2:$O$100,0,0,1)*$I8-$J8)) -> 0 | BA8: 0 | BK8: =+IF(AND(BD8>0,BE8=""),0,IF(BE8="","",IF(BE8>=BD8,1,BE8/BD8))) | BL8: =+IF(AND(BF8>0,BG8=""),0,IF(BG8="","",IF(BG8>=BF8,1,BG8/BF8))) | BM8: =+IF(AND(BH8>0,BI8=""),0,IF(BI8="","",IF(BI8>=BH8,1,BI8/BH8)))
A9: =+_xlfn.XLOOKUP(B9,'[1]Proyectos (NO FILTRAR)'!$F:$F,'[1]Proyectos (NO FILTRAR)'!$B:$B,0,0,1) -> CH-LUN-CS-OTR00-007-A | B9: Diagnóstico Operacional Candelaria | C9: =+_xlfn.XLOOKUP(A9,'[1]Proyectos (NO FILTRAR)'!$B:$B,'[1]Proyectos (NO FILTRAR)'!$G:$G,"error",0,1) -> Chile | D9: Adjudicado | E9: Terminado | G9: Ricardo Miranda | H9: Emilio Sánchez | I9: 178540.96 | J9: =+Q9+AE9+AH9+AK9+AN9+AQ9+AT9+AW9+AZ9+BC9+BE9+BG9+BI9 -> 178540.96 | K9: =+IFERROR(J9/I9,0) -> 1 | L9: =+I9-J9 -> 0 | M9: =+IFERROR(L9/I9,0) -> 0 | O9: =IFERROR(N9/I9,0) -> 0 | P9: =+I9-N9 -> 178540.96 | Q9: 178540.96 | R9: =+I9-Q9 -> 0 | S9: 21776.04 | T9: 29101 | U9: 0 | V9: 0 | W9: 0 | X9: 0 | Z9: 0 | AA9: 0 | AC9: 0 | AF9: 0 | AI9: 0 | AL9: 0 | AO9: 0 | AR9: 0 | AU9: 0 | AX9: =+IF((_xlfn.XLOOKUP($B9,'Curva S'!$B$2:$B$100,'Curva S'!$O$2:$O$100,0,0,1)*$I9-$J9)<0,0,(_xlfn.XLOOKUP($B9,'Curva S'!$B$2:$B$100,'Curva S'!$O$2:$O$100,0,0,1)*$I9-$J9)) -> 0 | BA9: 0 | BK9: =+IF(AND(BD9>0,BE9=""),0,IF(BE9="","",IF(BE9>=BD9,1,BE9/BD9))) | BL9: =+IF(AND(BF9>0,BG9=""),0,IF(BG9="","",IF(BG9>=BF9,1,BG9/BF9))) | BM9: =+IF(AND(BH9>0,BI9=""),0,IF(BI9="","",IF(BI9>=BH9,1,BI9/BH9)))
A10: =+_xlfn.XLOOKUP(B10,'[1]Proyectos (NO FILTRAR)'!$F:$F,'[1]Proyectos (NO FILTRAR)'!$B:$B,0,0,1) -> PE-SME-UG-FEL2A-046-A | B10: Sierra Metals_Plan de Minado MEIA | C10: =+_xlfn.XLOOKUP(A10,'[1]Proyectos (NO FILTRAR)'!$B:$B,'[1]Proyectos (NO FILTRAR)'!$G:$G,"error",0,1) -> Perú | D10: Adjudicado | E10: Terminado | G10: Matias Fuentes | H10: Carlos Catalán | I10: 56629 | J10: =+Q10+AE10+AH10+AK10+AN10+AQ10+AT10+AW10+AZ10+BC10+BE10+BG10+BI10 -> 56629 | K10: =+IFERROR(J10/I10,0) -> 1 | L10: =+I10-J10 -> 0 | M10: =+IFERROR(L10/I10,0) -> 0 | O10: =IFERROR(N10/I10,0) -> 0 | P10: =+I10-N10 -> 56629 | Q10: 36682 | R10: =+I10-Q10 -> 19947 | S10: 27748.7 | T10: 0 | U10: 11178.7 | V10: 16422.7 | W10: 0 | X10: 18705 | Y10: 36682 | Z10: 0 | AA10: 0 | AC10: 0 | AD10: 0 | AF10: 19948 | AG10: 19948 | AH10: 14729 | AI10: 0 | AL10: 0 | AO10: 0 | AR10: 0 | AU10: 0 | AX10: =+IF((_xlfn.XLOOKUP($B10,'Curva S'!$B$2:$B$100,'Curva S'!$O$2:$O$100,0,0,1)*$I10-$J10)<0,0,(_xlfn.XLOOKUP($B10,'Curva S'!$B$2:$B$100,'Curva S'!$O$2:$O$100,0,0,1)*$I10-$J10)) -> 0 | AZ10: 5218 | BA10: 0 | BK10: =+IF(AND(BD10>0,BE10=""),0,IF(BE10="","",IF(BE10>=BD10,1,BE10/BD10))) | BL10: =+IF(AND(BF10>0,BG10=""),0,IF(BG10="","",IF(BG10>=BF10,1,BG10/BF10))) | BM10: =+IF(AND(BH10>0,BI10=""),0,IF(BI10="","",IF(BI10>=BH10,1,BI10/BH10)))
A11: =+_xlfn.XLOOKUP(B11,'[1]Proyectos (NO FILTRAR)'!$F:$F,'[1]Proyectos (NO FILTRAR)'!$B:$B,0,0,1) -> BR-MOS-OU-FEL03-026-A | B11: Mosaic_Cajati | C11: =+_xlfn.XLOOKUP(A11,'[1]Proyectos (NO FILTRAR)'!$B:$B,'[1]Proyectos (NO FILTRAR)'!$G:$G,"error",0,1) -> Brasil | D11: Adjudicado | E11: Terminado | F11: Alex Figueroa | G11: Alex Figueroa | H11: Pablo Quiero | I11: =647241+78000 -> 725241 | J11: =+Q11+AE11+AH11+AK11+AN11+AQ11+AT11+AW11+AZ11+BC11+BE11+BG11+BI11 -> 717694.46 | K11: =+IFERROR(J11/I11,0) -> 0.98959444 | L11: =+I11-J11 -> 7546.54 | M11: =+IFERROR(L11/I11,0) -> 0.010405562 | O11: =IFERROR(N11/I11,0) -> 0 | P11: =+I11-N11 -> 725241 | Q11: 368694.46 | R11: =+I11-Q11 -> 356546.54 | S11: 132966.72 | T11: 29306 | U11: 103660.72 | W11: 23474 | X11: 175963.6 | Y11: 103264 | Z11: 188102.03 | AA11: 188102.03 | AB11: =36629+12172 -> 48801 | AC11: 111795.92 | AD11: 20000 | AE11: 31463 | AF11: 176976.29 | AG11: 40000 | AH11: 72122 | AI11: 78758.44 | AJ11: 127854.49 | AK11: =186908+11425 -> 198333 | AL11: 35947.54 | AM11: 25111.86 | AN11: 31640 | AO11: 22988.54 | AR11: 22988.54 | AS11: 0 | AU11: 22988.54 | AV11: 22988.54 | AW11: 15442 | AX11: =+IF((_xlfn.XLOOKUP($B11,'Curva S'!$B$2:$B$100,'Curva S'!$O$2:$O$100,0,0,1)*$I11-$J11)<0,0,(_xlfn.XLOOKUP($B11,'Curva S'!$B$2:$B$100,'Curva S'!$O$2:$O$100,0,0,1)*$I11-$J11)) -> 7546.54 | BA11: 7546.54 | BK11: =+IF(AND(BD11>0,BE11=""),0,IF(BE11="","",IF(BE11>=BD11,1,BE11/BD11))) | BL11: =+IF(AND(BF11>0,BG11=""),0,IF(BG11="","",IF(BG11>=BF11,1,BG11/BF11))) | BM11: =+IF(AND(BH11>0,BI11=""),0,IF(BI11="","",IF(BI11>=BH11,1,BI11/BH11)))
A12: =+_xlfn.XLOOKUP(B12,'[1]Proyectos (NO FILTRAR)'!$F:$F,'[1]Proyectos (NO FILTRAR)'!$B:$B,0,0,1) -> BR-MOS-UG-FEL01-028-A | B12: Mosaic_Taquari Vassouras | C12: =+_xlfn.XLOOKUP(A12,'[1]Proyectos (NO FILTRAR)'!$B:$B,'[1]Proyectos (NO FILTRAR)'!$G:$G,"error",0,1) -> Brasil | D12: Adjudicado | E12: En Proceso | F12: Mauricio Melendez | G12: Alex Figueroa | H12: Kevin Rios | I12: 284632.92 | J12: =+Q12+AE12+AH12+AK12+AN12+AQ12+AT12+AW12+AZ12+BC12+BE12+BG12+BI12 -> 284632.92 | K12: =+IFERROR(J12/I12,0) -> 1 | L12: =+I12-J12 -> 0 | M12: =+IFERROR(L12/I12,0) -> 0 | O12: =IFERROR(N12/I12,0) -> 0 | P12: =+I12-N12 -> 284632.92 | Q12: 232261.92 | R12: =+I12-Q12 -> 52371 | S12: 16907.22 | T12: 34067 | U12: 0 | V12: 81465.67 | W12: 39226 | X12: 129266.28 | Y12: 92850.92 | Z12: 101765.91 | AA12: 93670.895 | AB12: 66118 | AC12: 52371.08 | AD12: 52371.08 | AE12: 41400 | AF12: 10971.08 | AG12: 10971 | AH12: =6798 -> 6798 | AI12: 0 | AJ12: 4173.08 | AL12: 4173.08 | AM12: 4173 | AN12: 4173 | AO12: 0 | AR12: 0 | AU12: 0 | AX12: =+IF((_xlfn.XLOOKUP($B12,'Curva S'!$B$2:$B$100,'Curva S'!$O$2:$O$100,0,0,1)*$I12-$J12)<0,0,(_xlfn.XLOOKUP($B12,'Curva S'!$B$2:$B$100,'Curva S'!$O$2:$O$100,0,0,1)*$I12-$J12)) -> 0 | BA12: 0 | BK12: =+IF(AND(BD12>0,BE12=""),0,IF(BE12="","",IF(BE12>=BD12,1,BE12/BD12))) | BL12: =+IF(AND(BF12>0,BG12=""),0,IF(BG12="","",IF(BG12>=BF12,1,BG12/BF12))) | BM12: =+IF(AND(BH12>0,BI12=""),0,IF(BI12="","",IF(BI12>=BH12,1,BI12/BH12)))
A13: =+_xlfn.XLOOKUP(B13,'[1]Proyectos (NO FILTRAR)'!$F:$F,'[1]Proyectos (NO FILTRAR)'!$B:$B,0,0,1) -> BR-NEX-UG-FEL2A-027-A | B13: NEXA_FEL2 Aripuana | C13: =+_xlfn.XLOOKUP(A13,'[1]Proyectos (NO FILTRAR)'!$B:$B,'[1]Proyectos (NO FILTRAR)'!$G:$G,"error",0,1) -> Brasil | D13: Adjudicado | E13: Terminado | F13: Matias Fuentes | G13: Matias Fuentes | H13: Andres Budini | I13: 207726.08 | J13: =+Q13+AE13+AH13+AK13+AN13+AQ13+AT13+AW13+AZ13+BC13+BE13+BG13+BI13 -> 204231 | K13: =+IFERROR(J13/I13,0) -> 0.98317457 | L13: =+I13-J13 -> 3495.0816 | M13: =+IFERROR(L13/I13,0) -> 0.016825435 | O13: =IFERROR(N13/I13,0) -> 0 | P13: =+I13-N13 -> 207726.08 | Q13: 128437 | R13: =+I13-Q13 -> 79289.082 | S13: 24763.59 | T13: 11644 | U13: 13119.59 | V13: 93551.34 | W13: 16248 | X13: 71041.96 | Y13: 29518 | Z13: 112739 | AA13: 112739 | AB13: 71027 | AC13: 68900 | AD13: 71918 | AE13: 31925 | AF13: 43247 | AG13: 36975 | AI13: 43247 | AJ13: 46417 | AL13: 43247 | AM13: 43247 | AO13: 43247 | AR13: 0 | AU13: 47364.082 | AW13: 43869 | AX13: =+IF((_xlfn.XLOOKUP($B13,'Curva S'!$B$2:$B$100,'Curva S'!$O$2:$O$100,0,0,1)*$I13-$J13)<0,0,(_xlfn.XLOOKUP($B13,'Curva S'!$B$2:$B$100,'Curva S'!$O$2:$O$100,0,0,1)*$I13-$J13)) -> 3495.0816 | BA13: 3495.0816 | BK13: =+IF(AND(BD13>0,BE13=""),0,IF(BE13="","",IF(BE13>=BD13,1,BE13/BD13))) | BL13: =+IF(AND(BF13>0,BG13=""),0,IF(BG13="","",IF(BG13>=BF13,1,BG13/BF13))) | BM13: =+IF(AND(BH13>0,BI13=""),0,IF(BI13="","",IF(BI13>=BH13,1,BI13/BH13)))
A14: =+_xlfn.XLOOKUP(B14,'[1]Proyectos (NO FILTRAR)'!$F:$F,'[1]Proyectos (NO FILTRAR)'!$B:$B,0,0,1) -> CH-CMP-OP-OTR00-018-A | B14: Romeral | C14: =+_xlfn.XLOOKUP(A14,'[1]Proyectos (NO FILTRAR)'!$B:$B,'[1]Proyectos (NO FILTRAR)'!$G:$G,"error",0,1) -> Chile | D14: Adjudicado | E14: Terminado | G14: Ricardo Miranda | H14: Felipe Matamoros | I14: 645045.4 | J14: =+Q14+AE14+AH14+AK14+AN14+AQ14+AT14+AW14+AZ14+BC14+BE14+BG14+BI14 -> 645045.4 | K14: =+IFERROR(J14/I14,0) -> 1 | L14: =+I14-J14 -> 0 | M14: =+IFERROR(L14/I14,0) -> 0 | O14: =IFERROR(N14/I14,0) -> 0 | P14: =+I14-N14 -> 645045.4 | Q14: 635530.4 | R14: =+I14-Q14 -> 9515 | S14: 61272.138 | T14: 38387 | U14: 22885.138 | V14: 0 | W14: 21231 | X14: 1654.1375 | Y14: 90409 | Z14: 0 | AA14: 0 | AC14: 0 | AD14: 0 | AE14: 9515 | AF14: 0 | AI14: 0 | AL14: 0 | AO14: 0 | AR14: 0 | AU14: 0 | AX14: =+IF((_xlfn.XLOOKUP($B14,'Curva S'!$B$2:$B$100,'Curva S'!$O$2:$O$100,0,0,1)*$I14-$J14)<0,0,(_xlfn.XLOOKUP($B14,'Curva S'!$B$2:$B$100,'Curva S'!$O$2:$O$100,0,0,1)*$I14-$J14)) -> 0 | BA14: 0 | BK14: =+IF(AND(BD14>0,BE14=""),0,IF(BE14="","",IF(BE14>=BD14,1,BE14/BD14))) | BL14: =+IF(AND(BF14>0,BG14=""),0,IF(BG14="","",IF(BG14>=BF14,1,BG14/BF14))) | BM14: =+IF(AND(BH14>0,BI14=""),0,IF(BI14="","",IF(BI14>=BH14,1,BI14/BH14)))
