Workbook
Name NombresProfesionales: '[1]Listado Profesionales'!$B$5:$B$1048576
Name NombresProfesionales: 'Listado Profesionales'!$B$5:$B$1048576
Name SegmentaciónDeDatos_Nombre: #N/A

Sheet Resumen
A1: Nombre | B1: Proyecto | C1: Horas | F1: Nombre >168 h | G1: Proyectos ordenados
A2: Profesional | B2: Algarrobo Finos | C2: 0
A3: Orden | B3: Algarrobo Finos | C3: 0
A4: Profesional | B4: AMSA_Contrato Marco | C4: 0
A5: Orden | B5: AMSA_Contrato Marco | C5: 0
A6: Profesional | B6: AMSA_Trade Off Tecnologico NGD | C6: 0
A7: Felipe Rojas | B7: AMSA_Trade Off Tecnologico NGD

Sheet Listado Proyectos
A1: Algarrobo
A2: AMSA_Asesoria Centinela
A3: AMSA_Contrato Marco
A4: AMSA_Contrato Marco
A5: AMSA_Estandares Minimos
A6: AMSA_Trade Off Tecnologico NGD
A7: AngloAmerican_Análisis Productividad MLB
A8: AngloAmerican_Productividad Transporte LB
A9: AngloAmerican_Tecnología HDD
A10: Apoyo tecnico-comercial
A11: AuraMinerals_Expansión Mina Paiol OP-UG
A12: BHP_Análisis LoA 2025 - SCUT
... A159: South32_HoV and optimized cut-off grade

Sheet Listado Profesionales
A2: Fecha de referencia POM | B2: 46143
A4: País | B4: Nombre TEAMS | C4: Rut/DNI | D4: Nombre | E4: Apellido Paterno | F4: Apellido Materno | G4: ÁREA | H4: Cargo | I4: Fecha Inicio Contrato | J4: Fecha Fin Contrato
A5: Chile | B5: Alex Figueroa | C5: 16.385.625-5 | D5: ALEX PATRICIO | E5: FIGUEROA | F5: SAAVEDRA | G5: Ingenieria | H5: Director de Ingenieria | I5: 44389
A6: Chile | B6: Alex Pacheco | C6: 15.432.941-2 | D6: ALEX RODRIGO | E6: PACHECO | F6: CISTERNAS | G6: Ingenieria | H6: Ingeniero Principal Senior | I6: 41487
A7: Chile | B7: Alex Remolcoy | C7: 19.874.043-8 | D7: ALEX DAMIAN | E7: REMOLCOY | F7: GUENTEO | G7: Ingenieria | H7: Ingeniero Estructural | I7: 45881
A8: Chile | B8: Álvaro De la Quintana | C8: 15.370.268-3 | D8: ALVARO OMAR | E8: DE LA QUINTANA | F8: QUEZADA | G8: Ingenieria | H8: Ingeniero Senior | I8: 46104 | J8: 46295
A9: Perú | B9: Arnold Tadeo | C9: 75075850 | D9: ARNOLD ISAIAS | E9: TADEO | F9: FABIAN | G9: INGENIERIA | H9: Ingeniero de Proyectos | I9: 45293 | J9: 46204
A10: Chile | B10: Benjamín Baeza | C10: 20.705.613-8 | D10: BENJAMIN RICARDO | E10: BAEZA | F10: RIOS | G10: Ingenieria | H10: Ingeniero de Proyectos | I10: 45672
A11: Perú | B11: Carlos Catalán | C11: 72204192 | D11: CARLOS EDUARDO | E11: CATALAN | F11: CORDOVA | G11: INGENIERIA | H11: Ingeniero de Proyectos | I11: 43497
A12: Chile | B12: Carol Shand | C12: 16.322.341-4 | D12: CAROL | E12: SHAND | F12: MORALES | G12: Geotecnia | H12: Director de Proyecto | I12: 46069
A13: Chile | B13: Claudio Hernandez | C13: 12.718.085-7 | D13: CLAUDIO ALEJANDRO | E13: HERNANDEZ | F13: VILLARROEL | G13: Geotecnia | H13: Director de Ingenieria | I13: 45201
A14: Chile | B14: Cristian Alarcón | C14: 19.135.730-2 | D14: CRISTIAN ADOLFO | E14: ALARCON | F14: MARTINEZ | G14: Ingenieria | H14: Ingeniero de Proyectos | I14: 44562
A15: Chile | B15: Cristóbal Ventura | C15: 19.838.938-2 | D15: CRISTOBAL IGNACIO | E15: VENTURA | F15: MENESES | G15: Ingenieria | H15: Ingenieria | I15: 45414
A16: Chile | B16: Daniela Oyarzo | C16: 18.756.364-K | D16: DANIELA SIU YING | E16: OYARZO | F16: ESCOBAR | G16: Ingenieria | H16: Ingeniero de Proyectos | I16: 44824
A17: Perú | B17: Dennis Mamani | C17: 70818334 | D17: DENNIS | E17: MAMANI | F17: SIMEON | G17: Ingenieria | H17: Junior de Proyectos | I17: 46175
A18: Chile | B18: Diego Muñoz | C18: 19.958.057-4 | D18: DIEGO ANDRÉS | E18: MUÑOZ | F18: ÁLVAREZ | G18: Ingenieria | H18: Ingenieria | I18: 45031
A19: Chile | B19: Eduardo Cepeda | C19: 18.988.438-9 | D19: EDUARDO | E19: CEPEDA | F19: GONZÁLEZ | G19: Geotecnia | H19: Ingeniero de Proyectos | I19: 45749
A20: Chile | B20: Eduardo Cuevas | C20: 17.882.713-8 | D20: EDUARDO ESTEBAN | E20: CUEVAS | F20: CARRASCO | G20: Servicios Técnicos | H20: Ingenieria | I20: 44949
A21: Chile | B21: Eduardo Morales | C21: 14.123.628-8 | D21: EDUARDO IGNACIO | E21: MORALES | F21: PALMA | G21: Ingenieria | H21: Ingenieria | I21: 45630
A22: Perú | B22: Edward Torres | C22: 72881217 | D22: EDWARD CRISTIAN | E22: TORRES | F22: CALLUPE | G22: INGENIERIA | H22: Ingeniero de Proyectos | I22: 44756 | J22: 46356
A23: Chile | B23: Enzo Ruiz | C23: 19.852.351-8 | D23: ENZO FRANCO | E23: RUIZ | F23: ROMO | G23: Ingenieria | H23: Ingeniero de Proyectos | I23: 45870
A24: Chile | B24: Erick Sanhueza | C24: 19.558.460-5 | D24: ERICK NICOLAS | E24: SANHUEZA | F24: CORREA | G24: Ingenieria | H24: Ingeniero de Proyectos | I24: 45607
A25: Chile | B25: Felipe Matamoros | C25: 17.859.307-2 | D25: FELIPE NICOLAS | E25: MATAMOROS | F25: CARUMAN | G25: Ingenieria | H25: DIRECTOR METALURGIA | I25: 46027
A26: Chile | B26: Francisco Cabañas | C26: 23.696.637-2 | D26: FRANCISCO JAVIER | E26: CABAÑAS | F26: GONZALEZ | G26: Geotecnia | H26: Ingeniero Senior | I26: 46113
A27: Chile | B27: Gersson Rivera | C27: 18.685.971-5 | D27: GERSSON ALBERTO | E27: RIVERA | F27: ABELLO | G27: Ingenieria | H27: Modelador Numérico | I27: 45973 | J27: 46154
A28: Perú | B28: Gino Espinoza | C28: 73023479 | D28: GINO SEGUNDO | E28: ESPINOZA | F28: GUZMAN | G28: INGENIERIA | H28: Ingeniero de Proyectos | I28: 44445 | J28: 46295
A29: Chile | B29: Gonzalo Parada | C29: 17.617.420-K | D29: GONZALO IGNACIO | E29: PARADA | F29: FUENTES | G29: Ingenieria | H29: Ingeniero Principal Metalurgia | I29: 46038
A30: Chile | B30: Ignacia Alvarez | C30: 20.096.296-6 | D30: IGNACIA PAZ | E30: ÁLVAREZ | F30: BAHAMONDES | G30: Ingenieria | H30: Ingeniero de Proyectos Metalúrgico | I30: 45912
A31: Chile | B31: Ignacio Navarrete | C31: 18.300.718-1 | D31: IGNACIO ALFONSO | E31: NAVARRETE | F31: CATALDO | G31: Ingenieria | H31: Ingeniero Principal Senior | I31: 45943
A32: Chile | B32: Isidora Figueroa | C32: 20.298.041-4 | D32: ISIDORA BELÉN | E32: FIGUEROA | F32: FERNÁNDEZ | G32: Ingenieria | H32: Ingeniero de Proyectos | I32: 45031
A33: Chile | B33: Javier Morales | C33: 16.019.653-K | D33: JAVIER EDUARDO | E33: MORALES | F33: CARDENAS | G33: Ingenieria | H33: Ingeniero Senior | I33: 46055
A34: Chile | B34: Javier Salazar | C34: 19.615.623-2 | D34: JAVIER IGNACIO | E34: SALAZAR | F34: NUÑEZ | G34: Geotecnia | H34: Ingeniero de Proyectos | I34: 45495
A35: Perú | B35: Jhonatan Huaynate | C35: 72259733 | D35: JHONATAN RICHARD | E35: HUAYNATE | F35: MEZA | G35: INGENIERIA | H35: Ingeniero Junior de Proyectos | I35: 45536 | J35: 46295
A36: Perú | B36: Jorman Barrera | C36: 70518094 | D36: JORMAN IVAN | E36: BARRERA | F36: VERGARA | G36: INGENIERIA | H36: Jefe de Ingenieria | I36: 43101
A37: Perú | B37: Joseph Livia | C37: 71130178 | D37: JOSEPH ANGEL | E37: LIVIA | F37: ESTRADA | G37: INGENIERIA | H37: Ingeniero de Proyectos | I37: 45689 | J37: 46265
A38: Chile | B38: Juan Francisco San Martin | C38: 10.253.765-3 | D38: JUAN FRANCISCO | E38: SAN MARTIN | F38: REYES | G38: Ingenieria | H38: Gerente de Ingenieria | I38: 46023
A39: Chile | B39: Juan Luis Pizarro | C39: 8.638.456-6 | D39: JUAN LUIS | E39: PIZARRO | F39: ROJAS | G39: Ingenieria | H39: Ingeniero de Proyectos Metalúrgico | I39: 45901
A40: Chile | B40: Julio Beniscelli | C40: 5.270.452-9 | D40: JULIO PATRICIO | E40: BENISCELLI | F40: TRONCOSO | G40: Ingenieria | H40: Gerente de Ingenieria | I40: 46113
A41: Perú | B41: Kevin Rios | C41: 72621966 | D41: KEVIN PERCY | E41: RIOS | F41: MORI | G41: INGENIERIA | H41: Ingeniero de Proyectos | I41: 44562
A42: Perú | B42: Luis Chumpitaz | C42: 74636982 | D42: LUIS ALBERTO | E42: CHUMPITAZ | F42: BARBOZA | G42: INGENIERIA | H42: Ingeniero Geomecánico | I42: 45659 | J42: 46265
...

Sheet Calendario
C1: Fecha inicio | D1: =IF(WEEKDAY(D2,3)<5,D2-WEEKDAY(D2,3),D2-WEEKDAY(D2,3)+7) -> 46174 | H1: Fecha | I1: Día de semana | J1: Horas Chile | K1: Feriado Chile | L1: Feriado Perú | M1: Horas Perú
C2: Mes (día 1° del mes) | D2: 46174 | E2: Fecha inicio | F2: =DATE(YEAR(D2),MONTH(D2),1) -> 46174 | H2: =D2 -> 46174 | I2: =WEEKDAY(H2,2) -> 1 | J2: =IF(AND(MONTH(H2)=MONTH(H$2),K2=0),IF(I2<=4,9,IF(I2=5,6,0)),0) -> 9 | M2: =IF(AND(MONTH(H2)=MONTH(H$2),L2=0),IF(I2<=4,9,IF(I2=5,6,0)),0) -> 9
E3: Fecha Fin | F3: =DATE(YEAR(D2),1+MONTH(D2),1)-1 -> 46203 | H3: =H2+1 -> 46175 | I3: =WEEKDAY(H3,2) -> 2 | J3: =IF(AND(MONTH(H3)=MONTH(H$2),K3=0),IF(I3<=4,9,IF(I3=5,6,0)),0) -> 9 | M3: =IF(AND(MONTH(H3)=MONTH(H$2),L3=0),IF(I3<=4,9,IF(I3=5,6,0)),0) -> 9
C4: Mes anterior | D4: =DATE(YEAR(D2),MONTH(D2)-1,16) -> 46158 | H4: =H3+1 -> 46176 | I4: =WEEKDAY(H4,2) -> 3 | J4: =IF(AND(MONTH(H4)=MONTH(H$2),K4=0),IF(I4<=4,9,IF(I4=5,6,0)),0) -> 9 | M4: =IF(AND(MONTH(H4)=MONTH(H$2),L4=0),IF(I4<=4,9,IF(I4=5,6,0)),0) -> 9
H5: =H4+1 -> 46177 | I5: =WEEKDAY(H5,2) -> 4 | J5: =IF(AND(MONTH(H5)=MONTH(H$2),K5=0),IF(I5<=4,9,IF(I5=5,6,0)),0) -> 9 | M5: =IF(AND(MONTH(H5)=MONTH(H$2),L5=0),IF(I5<=4,9,IF(I5=5,6,0)),0) -> 9
H6: =H5+1 -> 46178 | I6: =WEEKDAY(H6,2) -> 5 | J6: =IF(AND(MONTH(H6)=MONTH(H$2),K6=0),IF(I6<=4,9,IF(I6=5,6,0)),0) -> 6 | M6: =IF(AND(MONTH(H6)=MONTH(H$2),L6=0),IF(I6<=4,9,IF(I6=5,6,0)),0) -> 6
E7: Fecha inicio calendario quincena | F7: =IF(WEEKDAY(D4,3)<5,D4-WEEKDAY(D4,3),D4-WEEKDAY(D4,3)+7) -> 46160 | H7: =H6+1 -> 46179 | I7: =WEEKDAY(H7,2) -> 6 | J7: =IF(AND(MONTH(H7)=MONTH(H$2),K7=0),IF(I7<=4,9,IF(I7=5,6,0)),0) -> 0 | M7: =IF(AND(MONTH(H7)=MONTH(H$2),L7=0),IF(I7<=4,9,IF(I7=5,6,0)),0) -> 0
H8: =H7+1 -> 46180 | I8: =WEEKDAY(H8,2) -> 7 | J8: =IF(AND(MONTH(H8)=MONTH(H$2),K8=0),IF(I8<=4,9,IF(I8=5,6,0)),0) -> 0 | L8: 1 | M8: =IF(AND(MONTH(H8)=MONTH(H$2),L8=0),IF(I8<=4,9,IF(I8=5,6,0)),0) -> 0
H9: =H8+1 -> 46181 | I9: =WEEKDAY(H9,2) -> 1 | J9: =IF(AND(MONTH(H9)=MONTH(H$2),K9=0),IF(I9<=4,9,IF(I9=5,6,0)),0) -> 9 | M9: =IF(AND(MONTH(H9)=MONTH(H$2),L9=0),IF(I9<=4,9,IF(I9=5,6,0)),0) -> 9
F10: Totales horas | H10: =H9+1 -> 46182 | I10: =WEEKDAY(H10,2) -> 2 | J10: =IF(AND(MONTH(H10)=MONTH(H$2),K10=0),IF(I10<=4,9,IF(I10=5,6,0)),0) -> 9 | M10: =IF(AND(MONTH(H10)=MONTH(H$2),L10=0),IF(I10<=4,9,IF(I10=5,6,0)),0) -> 9
E11: Mensual | F11: =SUM(J2:J32) -> 177 | H11: =H10+1 -> 46183 | I11: =WEEKDAY(H11,2) -> 3 | J11: =IF(AND(MONTH(H11)=MONTH(H$2),K11=0),IF(I11<=4,9,IF(I11=5,6,0)),0) -> 9 | M11: =IF(AND(MONTH(H11)=MONTH(H$2),L11=0),IF(I11<=4,9,IF(I11=5,6,0)),0) -> 9
H12: =H11+1 -> 46184 | I12: =WEEKDAY(H12,2) -> 4 | J12: =IF(AND(MONTH(H12)=MONTH(H$2),K12=0),IF(I12<=4,9,IF(I12=5,6,0)),0) -> 9 | M12: =IF(AND(MONTH(H12)=MONTH(H$2),L12=0),IF(I12<=4,9,IF(I12=5,6,0)),0) -> 9
H13: =H12+1 -> 46185 | I13: =WEEKDAY(H13,2) -> 5 | J13: =IF(AND(MONTH(H13)=MONTH(H$2),K13=0),IF(I13<=4,9,IF(I13=5,6,0)),0) -> 6 | M13: =IF(AND(MONTH(H13)=MONTH(H$2),L13=0),IF(I13<=4,9,IF(I13=5,6,0)),0) -> 6
H14: =H13+1 -> 46186 | I14: =WEEKDAY(H14,2) -> 6 | J14: =IF(AND(MONTH(H14)=MONTH(H$2),K14=0),IF(I14<=4,9,IF(I14=5,6,0)),0) -> 0 | M14: =IF(AND(MONTH(H14)=MONTH(H$2),L14=0),IF(I14<=4,9,IF(I14=5,6,0)),0) -> 0
H15: =H14+1 -> 46187 | I15: =WEEKDAY(H15,2) -> 7 | J15: =IF(AND(MONTH(H15)=MONTH(H$2),K15=0),IF(I15<=4,9,IF(I15=5,6,0)),0) -> 0 | M15: =IF(AND(MONTH(H15)=MONTH(H$2),L15=0),IF(I15<=4,9,IF(I15=5,6,0)),0) -> 0
H16: =H15+1 -> 46188 | I16: =WEEKDAY(H16,2) -> 1 | J16: =IF(AND(MONTH(H16)=MONTH(H$2),K16=0),IF(I16<=4,9,IF(I16=5,6,0)),0) -> 9 | M16: =IF(AND(MONTH(H16)=MONTH(H$2),L16=0),IF(I16<=4,9,IF(I16=5,6,0)),0) -> 9
H17: =H16+1 -> 46189 | I17: =WEEKDAY(H17,2) -> 2 | J17: =IF(AND(MONTH(H17)=MONTH(H$2),K17=0),IF(I17<=4,9,IF(I17=5,6,0)),0) -> 9 | M17: =IF(AND(MONTH(H17)=MONTH(H$2),L17=0),IF(I17<=4,9,IF(I17=5,6,0)),0) -> 9
H18: =H17+1 -> 46190 | I18: =WEEKDAY(H18,2) -> 3 | J18: =IF(AND(MONTH(H18)=MONTH(H$2),K18=0),IF(I18<=4,9,IF(I18=5,6,0)),0) -> 9 | M18: =IF(AND(MONTH(H18)=MONTH(H$2),L18=0),IF(I18<=4,9,IF(I18=5,6,0)),0) -> 9
H19: =H18+1 -> 46191 | I19: =WEEKDAY(H19,2) -> 4 | J19: =IF(AND(MONTH(H19)=MONTH(H$2),K19=0),IF(I19<=4,9,IF(I19=5,6,0)),0) -> 9 | M19: =IF(AND(MONTH(H19)=MONTH(H$2),L19=0),IF(I19<=4,9,IF(I19=5,6,0)),0) -> 9
H20: =H19+1 -> 46192 | I20: =WEEKDAY(H20,2) -> 5 | J20: =IF(AND(MONTH(H20)=MONTH(H$2),K20=0),IF(I20<=4,9,IF(I20=5,6,0)),0) -> 6 | M20: =IF(AND(MONTH(H20)=MONTH(H$2),L20=0),IF(I20<=4,9,IF(I20=5,6,0)),0) -> 6
H21: =H20+1 -> 46193 | I21: =WEEKDAY(H21,2) -> 6 | J21: =IF(AND(MONTH(H21)=MONTH(H$2),K21=0),IF(I21<=4,9,IF(I21=5,6,0)),0) -> 0 | M21: =IF(AND(MONTH(H21)=MONTH(H$2),L21=0),IF(I21<=4,9,IF(I21=5,6,0)),0) -> 0
H22: =H21+1 -> 46194 | I22: =WEEKDAY(H22,2) -> 7 | J22: =IF(AND(MONTH(H22)=MONTH(H$2),K22=0),IF(I22<=4,9,IF(I22=5,6,0)),0) -> 0 | K22: 1 | M22: =IF(AND(MONTH(H22)=MONTH(H$2),L22=0),IF(I22<=4,9,IF(I22=5,6,0)),0) -> 0
H23: =H22+1 -> 46195 | I23: =WEEKDAY(H23,2) -> 1 | J23: =IF(AND(MONTH(H23)=MONTH(H$2),K23=0),IF(I23<=4,9,IF(I23=5,6,0)),0) -> 9 | M23: =IF(AND(MONTH(H23)=MONTH(H$2),L23=0),IF(I23<=4,9,IF(I23=5,6,0)),0) -> 9
H24: =H23+1 -> 46196 | I24: =WEEKDAY(H24,2) -> 2 | J24: =IF(AND(MONTH(H24)=MONTH(H$2),K24=0),IF(I24<=4,9,IF(I24=5,6,0)),0) -> 9 | M24: =IF(AND(MONTH(H24)=MONTH(H$2),L24=0),IF(I24<=4,9,IF(I24=5,6,0)),0) -> 9
H25: =H24+1 -> 46197 | I25: =WEEKDAY(H25,2) -> 3 | J25: =IF(AND(MONTH(H25)=MONTH(H$2),K25=0),IF(I25<=4,9,IF(I25=5,6,0)),0) -> 9 | M25: =IF(AND(MONTH(H25)=MONTH(H$2),L25=0),IF(I25<=4,9,IF(I25=5,6,0)),0) -> 9
H26: =H25+1 -> 46198 | I26: =WEEKDAY(H26,2) -> 4 | J26: =IF(AND(MONTH(H26)=MONTH(H$2),K26=0),IF(I26<=4,9,IF(I26=5,6,0)),0) -> 9 | M26: =IF(AND(MONTH(H26)=MONTH(H$2),L26=0),IF(I26<=4,9,IF(I26=5,6,0)),0) -> 9
H27: =H26+1 -> 46199 | I27: =WEEKDAY(H27,2) -> 5 | J27: =IF(AND(MONTH(H27)=MONTH(H$2),K27=0),IF(I27<=4,9,IF(I27=5,6,0)),0) -> 6 | M27: =IF(AND(MONTH(H27)=MONTH(H$2),L27=0),IF(I27<=4,9,IF(I27=5,6,0)),0) -> 6
H28: =H27+1 -> 46200 | I28: =WEEKDAY(H28,2) -> 6 | J28: =IF(AND(MONTH(H28)=MONTH(H$2),K28=0),IF(I28<=4,9,IF(I28=5,6,0)),0) -> 0 | M28: =IF(AND(MONTH(H28)=MONTH(H$2),L28=0),IF(I28<=4,9,IF(I28=5,6,0)),0) -> 0
H29: =H28+1 -> 46201 | I29: =WEEKDAY(H29,2) -> 7 | J29: =IF(AND(MONTH(H29)=MONTH(H$2),K29=0),IF(I29<=4,9,IF(I29=5,6,0)),0) -> 0 | M29: =IF(AND(MONTH(H29)=MONTH(H$2),L29=0),IF(I29<=4,9,IF(I29=5,6,0)),0) -> 0
H30: =H29+1 -> 46202 | I30: =WEEKDAY(H30,2) -> 1 | J30: =IF(AND(MONTH(H30)=MONTH(H$2),K30=0),IF(I30<=4,9,IF(I30=5,6,0)),0) -> 0 | K30: 1 | L30: 1 | M30: =IF(AND(MONTH(H30)=MONTH(H$2),L30=0),IF(I30<=4,9,IF(I30=5,6,0)),0) -> 0
H31: =H30+1 -> 46203 | I31: =WEEKDAY(H31,2) -> 2 | J31: =IF(AND(MONTH(H31)=MONTH(H$2),K31=0),IF(I31<=4,9,IF(I31=5,6,0)),0) -> 9 | M31: =IF(AND(MONTH(H31)=MONTH(H$2),L31=0),IF(I31<=4,9,IF(I31=5,6,0)),0) -> 9
H32: =H31+1 -> 46204 | I32: =WEEKDAY(H32,2) -> 3 | J32: =IF(AND(MONTH(H32)=MONTH(H$2),K32=0),IF(I32<=4,9,IF(I32=5,6,0)),0) -> 0 | M32: =IF(AND(MONTH(H32)=MONTH(H$2),L32=0),IF(I32<=4,9,IF(I32=5,6,0)),0) -> 0
C116: No vigente
C122: No vigente

Sheet AuraMinerals_Proyecto Paiol PFS
C2: Planificación de Actividades
C3: =Calendario!$D$2 -> 46174
C4: ="Proyecto: "&D9 -> Proyecto: AuraMinerals_Proyecto Paiol PFS UG
C5: =_xlfn.CONCAT("Director:"," ",D10) -> Director: Alex Figueroa
A7: 1 | B7: Carga Laboral | C7: *No modificar
H8: =_xlfn.XLOOKUP(H48,Calendario!$H$2:$H$32,Calendario!$J$2:$J$32,0,0) -> 9 | I8: =_xlfn.XLOOKUP(I48,Calendario!$H$2:$H$32,Calendario!$J$2:$J$32,0,0) -> 9 | J8: =_xlfn.XLOOKUP(J48,Calendario!$H$2:$H$32,Calendario!$J$2:$J$32,0,0) -> 9 | K8: =_xlfn.XLOOKUP(K48,Calendario!$H$2:$H$32,Calendario!$J$2:$J$32,0,0) -> 9 | L8: =_xlfn.XLOOKUP(L48,Calendario!$H$2:$H$32,Calendario!$J$2:$J$32,0,0) -> 6 | M8: =_xlfn.XLOOKUP(M48,Calendario!$H$2:$H$32,Calendario!$J$2:$J$32,0,0) -> 0 | N8: =_xlfn.XLOOKUP(N48,Calendario!$H$2:$H$32,Calendario!$J$2:$J$32,0,0) -> 0 | O8: =_xlfn.XLOOKUP(O48,Calendario!$H$2:$H$32,Calendario!$J$2:$J$32,0,0) -> 9 | ... AN8: =_xlfn.XLOOKUP(AN48,Calendario!$H$2:$H$32,Calendario!$J$2:$J$32,0,0) -> 0
C9: Nombre | D9: AuraMinerals_Proyecto Paiol PFS UG | H9: L | I9: M | J9: M | K9: J | L9: V | M9: S | N9: D | O9: L | P9: M | Q9: M | R9: J | S9: V | T9: S | U9: D | V9: L | W9: M | X9: M | Y9: J | Z9: V | AA9: S | AB9: D | AC9: L | AD9: M | AE9: M | AF9: J | AG9: V | AH9: S | AI9: D | AJ9: L | AK9: M | AL9: M | AM9: J | AN9: V
C10: Director | D10: Alex Figueroa | G10: Horas Laborales (max) | H10: 9 | I10: 9 | J10: 9 | K10: 9 | L10: 6 | O10: 9 | P10: 9 | Q10: 9 | R10: 9 | S10: 6 | V10: 9 | W10: 9 | X10: 9 | Y10: 9 | Z10: 6 | AC10: 9 | AD10: 9 | AE10: 9 | AF10: 9 | AG10: 6 | AJ10: 9 | AK10: 9 | AL10: 9 | AM10: 9 | AN10: 6
C11: Ingenieros | D11: =COUNTIF(G16:G35,">"&0) -> 0 | G11: Hora Colación | H11: 1 | I11: 1 | J11: 1 | K11: 1 | L11: 0 | O11: 1 | P11: 1 | Q11: 1 | R11: 1 | S11: 0 | V11: 1 | W11: 1 | X11: 1 | Y11: 1 | Z11: 0 | AC11: 1 | AD11: 1 | AE11: 1 | AF11: 1 | AG11: 0 | AJ11: 1 | AK11: 1 | AL11: 1 | AM11: 1 | AN11: 0
C12: Horas Totales | D12: =SUM(G16:G36) -> 0 | G12: Totales | H12: =SUM(H10:H11) -> 10 | I12: =SUM(I10:I11) -> 10 | J12: =SUM(J10:J11) -> 10 | K12: =SUM(K10:K11) -> 10 | L12: =SUM(L10:L11) -> 6 | O12: =SUM(O10:O11) -> 10 | P12: =SUM(P10:P11) -> 10 | Q12: =SUM(Q10:Q11) -> 10 | R12: =SUM(R10:R11) -> 10 | S12: =SUM(S10:S11) -> 6 | V12: =SUM(V10:V11) -> 10 | W12: =SUM(W10:W11) -> 10 | X12: =SUM(X10:X11) -> 10 | Y12: =SUM(Y10:Y11) -> 10 | Z12: =SUM(Z10:Z11) -> 6 | AC12: =SUM(AC10:AC11) -> 10 | AD12: =SUM(AD10:AD11) -> 10 | AE12: =SUM(AE10:AE11) -> 10 | AF12: =SUM(AF10:AF11) -> 10 | AG12: =SUM(AG10:AG11) -> 6 | AJ12: =SUM(AJ10:AJ11) -> 10 | AK12: =SUM(AK10:AK11) -> 10 | AL12: =SUM(AL10:AL11) -> 10 | AM12: =SUM(AM10:AM11) -> 10 | AN12: =SUM(AN10:AN11) -> 6
C13: Entregables | D13: 0
G14: *No modificar | H14: L | I14: M | J14: M | K14: J | L14: V | M14: S | N14: D | O14: L | P14: M | Q14: M | R14: J | S14: V | T14: S | U14: D | V14: L | W14: M | X14: M | Y14: J | Z14: V | AA14: S | AB14: D | AC14: L | AD14: M | AE14: M | AF14: J | AG14: V | AH14: S | AI14: D | AJ14: L | AK14: M | AL14: M | AM14: J | AN14: V
C15: Estado de Pago proyectado | F15: Profesional | G15: Horas Totales del Mes | H15: =H48 -> 46174 | I15: =H15+1 -> 46175 | J15: =I15+1 -> 46176 | K15: =J15+1 -> 46177 | L15: =K15+1 -> 46178 | M15: =L15+1 -> 46179 | N15: =M15+1 -> 46180 | O15: =N15+1 -> 46181 | P15: =O15+1 -> 46182 | ... AN15: =AM15+1 -> 46206
F16: Eduardo Cepeda | G16: =SUM(H16:XFD16) -> 0 | H16: =SUMIFS(H$49:H$1048576,$D$49:$D$1048576,$F16) -> 0 | I16: =SUMIFS(I$49:I$1048576,$D$49:$D$1048576,$F16) -> 0 | J16: =SUMIFS(J$49:J$1048576,$D$49:$D$1048576,$F16) -> 0 | K16: =SUMIFS(K$49:K$1048576,$D$49:$D$1048576,$F16) -> 0 | L16: =SUMIFS(L$49:L$1048576,$D$49:$D$1048576,$F16) -> 0 | O16: =SUMIFS(O$49:O$1048576,$D$49:$D$1048576,$F16) -> 0 | P16: =SUMIFS(P$49:P$1048576,$D$49:$D$1048576,$F16) -> 0 | Q16: =SUMIFS(Q$49:Q$1048576,$D$49:$D$1048576,$F16) -> 0 | R16: =SUMIFS(R$49:R$1048576,$D$49:$D$1048576,$F16) -> 0 | S16: =SUMIFS(S$49:S$1048576,$D$49:$D$1048576,$F16) -> 0 | V16: =SUMIFS(V$49:V$1048576,$D$49:$D$1048576,$F16) -> 0 | W16: =SUMIFS(W$49:W$1048576,$D$49:$D$1048576,$F16) -> 0 | X16: =SUMIFS(X$49:X$1048576,$D$49:$D$1048576,$F16) -> 0 | Y16: =SUMIFS(Y$49:Y$1048576,$D$49:$D$1048576,$F16) -> 0 | Z16: =SUMIFS(Z$49:Z$1048576,$D$49:$D$1048576,$F16) -> 0 | AC16: =SUMIFS(AC$49:AC$1048576,$D$49:$D$1048576,$F16) -> 0 | AD16: =SUMIFS(AD$49:AD$1048576,$D$49:$D$1048576,$F16) -> 0 | AE16: =SUMIFS(AE$49:AE$1048576,$D$49:$D$1048576,$F16) -> 0 | AF16: =SUMIFS(AF$49:AF$1048576,$D$49:$D$1048576,$F16) -> 0 | AG16: =SUMIFS(AG$49:AG$1048576,$D$49:$D$1048576,$F16) -> 0 | AJ16: =SUMIFS(AJ$49:AJ$1048576,$D$49:$D$1048576,$F16) -> 0 | AK16: =SUMIFS(AK$49:AK$1048576,$D$49:$D$1048576,$F16) -> 0 | AL16: =SUMIFS(AL$49:AL$1048576,$D$49:$D$1048576,$F16) -> 0 | AM16: =SUMIFS(AM$49:AM$1048576,$D$49:$D$1048576,$F16) -> 0 | AN16: =SUMIFS(AN$49:AN$1048576,$D$49:$D$1048576,$F16) -> 0
B17: Profesional / Empresa (externo) | C17: Entregable comprometido | D17: Monto a pagar | F17: María Huamán | G17: =SUM(H17:XFD17) -> 0 | H17: =SUMIFS(H$49:H$1048576,$D$49:$D$1048576,$F17) -> 0 | I17: =SUMIFS(I$49:I$1048576,$D$49:$D$1048576,$F17) -> 0 | J17: =SUMIFS(J$49:J$1048576,$D$49:$D$1048576,$F17) -> 0 | K17: =SUMIFS(K$49:K$1048576,$D$49:$D$1048576,$F17) -> 0 | L17: =SUMIFS(L$49:L$1048576,$D$49:$D$1048576,$F17) -> 0 | O17: =SUMIFS(O$49:O$1048576,$D$49:$D$1048576,$F17) -> 0 | P17: =SUMIFS(P$49:P$1048576,$D$49:$D$1048576,$F17) -> 0 | Q17: =SUMIFS(Q$49:Q$1048576,$D$49:$D$1048576,$F17) -> 0 | R17: =SUMIFS(R$49:R$1048576,$D$49:$D$1048576,$F17) -> 0 | S17: =SUMIFS(S$49:S$1048576,$D$49:$D$1048576,$F17) -> 0 | V17: =SUMIFS(V$49:V$1048576,$D$49:$D$1048576,$F17) -> 0 | W17: =SUMIFS(W$49:W$1048576,$D$49:$D$1048576,$F17) -> 0 | X17: =SUMIFS(X$49:X$1048576,$D$49:$D$1048576,$F17) -> 0 | Y17: =SUMIFS(Y$49:Y$1048576,$D$49:$D$1048576,$F17) -> 0 | Z17: =SUMIFS(Z$49:Z$1048576,$D$49:$D$1048576,$F17) -> 0 | AC17: =SUMIFS(AC$49:AC$1048576,$D$49:$D$1048576,$F17) -> 0 | AD17: =SUMIFS(AD$49:AD$1048576,$D$49:$D$1048576,$F17) -> 0 | AE17: =SUMIFS(AE$49:AE$1048576,$D$49:$D$1048576,$F17) -> 0 | AF17: =SUMIFS(AF$49:AF$1048576,$D$49:$D$1048576,$F17) -> 0 | AG17: =SUMIFS(AG$49:AG$1048576,$D$49:$D$1048576,$F17) -> 0 | AJ17: =SUMIFS(AJ$49:AJ$1048576,$D$49:$D$1048576,$F17) -> 0 | AK17: =SUMIFS(AK$49:AK$1048576,$D$49:$D$1048576,$F17) -> 0 | AL17: =SUMIFS(AL$49:AL$1048576,$D$49:$D$1048576,$F17) -> 0 | AM17: =SUMIFS(AM$49:AM$1048576,$D$49:$D$1048576,$F17) -> 0 | AN17: =SUMIFS(AN$49:AN$1048576,$D$49:$D$1048576,$F17) -> 0
F18: Eduardo Morales | G18: =SUM(H18:XFD18) -> 0 | H18: =SUMIFS(H$49:H$1048576,$D$49:$D$1048576,$F18) -> 0 | I18: =SUMIFS(I$49:I$1048576,$D$49:$D$1048576,$F18) -> 0 | J18: =SUMIFS(J$49:J$1048576,$D$49:$D$1048576,$F18) -> 0 | K18: =SUMIFS(K$49:K$1048576,$D$49:$D$1048576,$F18) -> 0 | L18: =SUMIFS(L$49:L$1048576,$D$49:$D$1048576,$F18) -> 0 | O18: =SUMIFS(O$49:O$1048576,$D$49:$D$1048576,$F18) -> 0 | P18: =SUMIFS(P$49:P$1048576,$D$49:$D$1048576,$F18) -> 0 | Q18: =SUMIFS(Q$49:Q$1048576,$D$49:$D$1048576,$F18) -> 0 | R18: =SUMIFS(R$49:R$1048576,$D$49:$D$1048576,$F18) -> 0 | S18: =SUMIFS(S$49:S$1048576,$D$49:$D$1048576,$F18) -> 0 | V18: =SUMIFS(V$49:V$1048576,$D$49:$D$1048576,$F18) -> 0 | W18: =SUMIFS(W$49:W$1048576,$D$49:$D$1048576,$F18) -> 0 | X18: =SUMIFS(X$49:X$1048576,$D$49:$D$1048576,$F18) -> 0 | Y18: =SUMIFS(Y$49:Y$1048576,$D$49:$D$1048576,$F18) -> 0 | Z18: =SUMIFS(Z$49:Z$1048576,$D$49:$D$1048576,$F18) -> 0 | AC18: =SUMIFS(AC$49:AC$1048576,$D$49:$D$1048576,$F18) -> 0 | AD18: =SUMIFS(AD$49:AD$1048576,$D$49:$D$1048576,$F18) -> 0 | AE18: =SUMIFS(AE$49:AE$1048576,$D$49:$D$1048576,$F18) -> 0 | AF18: =SUMIFS(AF$49:AF$1048576,$D$49:$D$1048576,$F18) -> 0 | AG18: =SUMIFS(AG$49:AG$1048576,$D$49:$D$1048576,$F18) -> 0 | AJ18: =SUMIFS(AJ$49:AJ$1048576,$D$49:$D$1048576,$F18) -> 0 | AK18: =SUMIFS(AK$49:AK$1048576,$D$49:$D$1048576,$F18) -> 0 | AL18: =SUMIFS(AL$49:AL$1048576,$D$49:$D$1048576,$F18) -> 0 | AM18: =SUMIFS(AM$49:AM$1048576,$D$49:$D$1048576,$F18) -> 0 | AN18: =SUMIFS(AN$49:AN$1048576,$D$49:$D$1048576,$F18) -> 0
F19: Benjamín Baeza | G19: =SUM(H19:XFD19) -> 0 | H19: =SUMIFS(H$49:H$1048576,$D$49:$D$1048576,$F19) -> 0 | I19: =SUMIFS(I$49:I$1048576,$D$49:$D$1048576,$F19) -> 0 | J19: =SUMIFS(J$49:J$1048576,$D$49:$D$1048576,$F19) -> 0 | K19: =SUMIFS(K$49:K$1048576,$D$49:$D$1048576,$F19) -> 0 | L19: =SUMIFS(L$49:L$1048576,$D$49:$D$1048576,$F19) -> 0 | O19: =SUMIFS(O$49:O$1048576,$D$49:$D$1048576,$F19) -> 0 | P19: =SUMIFS(P$49:P$1048576,$D$49:$D$1048576,$F19) -> 0 | Q19: =SUMIFS(Q$49:Q$1048576,$D$49:$D$1048576,$F19) -> 0 | R19: =SUMIFS(R$49:R$1048576,$D$49:$D$1048576,$F19) -> 0 | S19: =SUMIFS(S$49:S$1048576,$D$49:$D$1048576,$F19) -> 0 | V19: =SUMIFS(V$49:V$1048576,$D$49:$D$1048576,$F19) -> 0 | W19: =SUMIFS(W$49:W$1048576,$D$49:$D$1048576,$F19) -> 0 | X19: =SUMIFS(X$49:X$1048576,$D$49:$D$1048576,$F19) -> 0 | Y19: =SUMIFS(Y$49:Y$1048576,$D$49:$D$1048576,$F19) -> 0 | Z19: =SUMIFS(Z$49:Z$1048576,$D$49:$D$1048576,$F19) -> 0 | AC19: =SUMIFS(AC$49:AC$1048576,$D$49:$D$1048576,$F19) -> 0 | AD19: =SUMIFS(AD$49:AD$1048576,$D$49:$D$1048576,$F19) -> 0 | AE19: =SUMIFS(AE$49:AE$1048576,$D$49:$D$1048576,$F19) -> 0 | AF19: =SUMIFS(AF$49:AF$1048576,$D$49:$D$1048576,$F19) -> 0 | AG19: =SUMIFS(AG$49:AG$1048576,$D$49:$D$1048576,$F19) -> 0 | AJ19: =SUMIFS(AJ$49:AJ$1048576,$D$49:$D$1048576,$F19) -> 0 | AK19: =SUMIFS(AK$49:AK$1048576,$D$49:$D$1048576,$F19) -> 0 | AL19: =SUMIFS(AL$49:AL$1048576,$D$49:$D$1048576,$F19) -> 0 | AM19: =SUMIFS(AM$49:AM$1048576,$D$49:$D$1048576,$F19) -> 0 | AN19: =SUMIFS(AN$49:AN$1048576,$D$49:$D$1048576,$F19) -> 0
F20: Enzo Ruiz | G20: =SUM(H20:XFD20) -> 0 | H20: =SUMIFS(H$49:H$1048576,$D$49:$D$1048576,$F20) -> 0 | I20: =SUMIFS(I$49:I$1048576,$D$49:$D$1048576,$F20) -> 0 | J20: =SUMIFS(J$49:J$1048576,$D$49:$D$1048576,$F20) -> 0 | K20: =SUMIFS(K$49:K$1048576,$D$49:$D$1048576,$F20) -> 0 | L20: =SUMIFS(L$49:L$1048576,$D$49:$D$1048576,$F20) -> 0 | O20: =SUMIFS(O$49:O$1048576,$D$49:$D$1048576,$F20) -> 0 | P20: =SUMIFS(P$49:P$1048576,$D$49:$D$1048576,$F20) -> 0 | Q20: =SUMIFS(Q$49:Q$1048576,$D$49:$D$1048576,$F20) -> 0 | R20: =SUMIFS(R$49:R$1048576,$D$49:$D$1048576,$F20) -> 0 | S20: =SUMIFS(S$49:S$1048576,$D$49:$D$1048576,$F20) -> 0 | V20: =SUMIFS(V$49:V$1048576,$D$49:$D$1048576,$F20) -> 0 | W20: =SUMIFS(W$49:W$1048576,$D$49:$D$1048576,$F20) -> 0 | X20: =SUMIFS(X$49:X$1048576,$D$49:$D$1048576,$F20) -> 0 | Y20: =SUMIFS(Y$49:Y$1048576,$D$49:$D$1048576,$F20) -> 0 | Z20: =SUMIFS(Z$49:Z$1048576,$D$49:$D$1048576,$F20) -> 0 | AC20: =SUMIFS(AC$49:AC$1048576,$D$49:$D$1048576,$F20) -> 0 | AD20: =SUMIFS(AD$49:AD$1048576,$D$49:$D$1048576,$F20) -> 0 | AE20: =SUMIFS(AE$49:AE$1048576,$D$49:$D$1048576,$F20) -> 0 | AF20: =SUMIFS(AF$49:AF$1048576,$D$49:$D$1048576,$F20) -> 0 | AG20: =SUMIFS(AG$49:AG$1048576,$D$49:$D$1048576,$F20) -> 0 | AJ20: =SUMIFS(AJ$49:AJ$1048576,$D$49:$D$1048576,$F20) -> 0 | AK20: =SUMIFS(AK$49:AK$1048576,$D$49:$D$1048576,$F20) -> 0 | AL20: =SUMIFS(AL$49:AL$1048576,$D$49:$D$1048576,$F20) -> 0 | AM20: =SUMIFS(AM$49:AM$1048576,$D$49:$D$1048576,$F20) -> 0 | AN20: =SUMIFS(AN$49:AN$1048576,$D$49:$D$1048576,$F20) -> 0
F21: Arnold Tadeo | G21: =SUM(H21:XFD21) -> 0 | H21: =SUMIFS(H$49:H$1048576,$D$49:$D$1048576,$F21) -> 0 | I21: =SUMIFS(I$49:I$1048576,$D$49:$D$1048576,$F21) -> 0 | J21: =SUMIFS(J$49:J$1048576,$D$49:$D$1048576,$F21) -> 0 | K21: =SUMIFS(K$49:K$1048576,$D$49:$D$1048576,$F21) -> 0 | L21: =SUMIFS(L$49:L$1048576,$D$49:$D$1048576,$F21) -> 0 | O21: =SUMIFS(O$49:O$1048576,$D$49:$D$1048576,$F21) -> 0 | P21: =SUMIFS(P$49:P$1048576,$D$49:$D$1048576,$F21) -> 0 | Q21: =SUMIFS(Q$49:Q$1048576,$D$49:$D$1048576,$F21) -> 0 | R21: =SUMIFS(R$49:R$1048576,$D$49:$D$1048576,$F21) -> 0 | S21: =SUMIFS(S$49:S$1048576,$D$49:$D$1048576,$F21) -> 0 | V21: =SUMIFS(V$49:V$1048576,$D$49:$D$1048576,$F21) -> 0 | W21: =SUMIFS(W$49:W$1048576,$D$49:$D$1048576,$F21) -> 0 | X21: =SUMIFS(X$49:X$1048576,$D$49:$D$1048576,$F21) -> 0 | Y21: =SUMIFS(Y$49:Y$1048576,$D$49:$D$1048576,$F21) -> 0 | Z21: =SUMIFS(Z$49:Z$1048576,$D$49:$D$1048576,$F21) -> 0 | AC21: =SUMIFS(AC$49:AC$1048576,$D$49:$D$1048576,$F21) -> 0 | AD21: =SUMIFS(AD$49:AD$1048576,$D$49:$D$1048576,$F21) -> 0 | AE21: =SUMIFS(AE$49:AE$1048576,$D$49:$D$1048576,$F21) -> 0 | AF21: =SUMIFS(AF$49:AF$1048576,$D$49:$D$1048576,$F21) -> 0 | AG21: =SUMIFS(AG$49:AG$1048576,$D$49:$D$1048576,$F21) -> 0 | AJ21: =SUMIFS(AJ$49:AJ$1048576,$D$49:$D$1048576,$F21) -> 0 | AK21: =SUMIFS(AK$49:AK$1048576,$D$49:$D$1048576,$F21) -> 0 | AL21: =SUMIFS(AL$49:AL$1048576,$D$49:$D$1048576,$F21) -> 0 | AM21: =SUMIFS(AM$49:AM$1048576,$D$49:$D$1048576,$F21) -> 0 | AN21: =SUMIFS(AN$49:AN$1048576,$D$49:$D$1048576,$F21) -> 0
F22: Pablo Quiero | G22: =SUM(H22:XFD22) -> 0 | H22: =SUMIFS(H$49:H$1048576,$D$49:$D$1048576,$F22) -> 0 | I22: =SUMIFS(I$49:I$1048576,$D$49:$D$1048576,$F22) -> 0 | J22: =SUMIFS(J$49:J$1048576,$D$49:$D$1048576,$F22) -> 0 | K22: =SUMIFS(K$49:K$1048576,$D$49:$D$1048576,$F22) -> 0 | L22: =SUMIFS(L$49:L$1048576,$D$49:$D$1048576,$F22) -> 0 | O22: =SUMIFS(O$49:O$1048576,$D$49:$D$1048576,$F22) -> 0 | P22: =SUMIFS(P$49:P$1048576,$D$49:$D$1048576,$F22) -> 0 | Q22: =SUMIFS(Q$49:Q$1048576,$D$49:$D$1048576,$F22) -> 0 | R22: =SUMIFS(R$49:R$1048576,$D$49:$D$1048576,$F22) -> 0 | S22: =SUMIFS(S$49:S$1048576,$D$49:$D$1048576,$F22) -> 0 | V22: =SUMIFS(V$49:V$1048576,$D$49:$D$1048576,$F22) -> 0 | W22: =SUMIFS(W$49:W$1048576,$D$49:$D$1048576,$F22) -> 0 | X22: =SUMIFS(X$49:X$1048576,$D$49:$D$1048576,$F22) -> 0 | Y22: =SUMIFS(Y$49:Y$1048576,$D$49:$D$1048576,$F22) -> 0 | Z22: =SUMIFS(Z$49:Z$1048576,$D$49:$D$1048576,$F22) -> 0 | AC22: =SUMIFS(AC$49:AC$1048576,$D$49:$D$1048576,$F22) -> 0 | AD22: =SUMIFS(AD$49:AD$1048576,$D$49:$D$1048576,$F22) -> 0 | AE22: =SUMIFS(AE$49:AE$1048576,$D$49:$D$1048576,$F22) -> 0 | AF22: =SUMIFS(AF$49:AF$1048576,$D$49:$D$1048576,$F22) -> 0 | AG22: =SUMIFS(AG$49:AG$1048576,$D$49:$D$1048576,$F22) -> 0 | AJ22: =SUMIFS(AJ$49:AJ$1048576,$D$49:$D$1048576,$F22) -> 0 | AK22: =SUMIFS(AK$49:AK$1048576,$D$49:$D$1048576,$F22) -> 0 | AL22: =SUMIFS(AL$49:AL$1048576,$D$49:$D$1048576,$F22) -> 0 | AM22: =SUMIFS(AM$49:AM$1048576,$D$49:$D$1048576,$F22) -> 0 | AN22: =SUMIFS(AN$49:AN$1048576,$D$49:$D$1048576,$F22) -> 0
G23: =SUM(H23:XFD23) -> 0 | H23: =SUMIFS(H$49:H$1048576,$D$49:$D$1048576,$F23) -> 0 | I23: =SUMIFS(I$49:I$1048576,$D$49:$D$1048576,$F23) -> 0 | J23: =SUMIFS(J$49:J$1048576,$D$49:$D$1048576,$F23) -> 0 | K23: =SUMIFS(K$49:K$1048576,$D$49:$D$1048576,$F23) -> 0 | L23: =SUMIFS(L$49:L$1048576,$D$49:$D$1048576,$F23) -> 0 | O23: =SUMIFS(O$49:O$1048576,$D$49:$D$1048576,$F23) -> 0 | P23: =SUMIFS(P$49:P$1048576,$D$49:$D$1048576,$F23) -> 0 | Q23: =SUMIFS(Q$49:Q$1048576,$D$49:$D$1048576,$F23) -> 0 | R23: =SUMIFS(R$49:R$1048576,$D$49:$D$1048576,$F23) -> 0 | S23: =SUMIFS(S$49:S$1048576,$D$49:$D$1048576,$F23) -> 0 | V23: =SUMIFS(V$49:V$1048576,$D$49:$D$1048576,$F23) -> 0 | W23: =SUMIFS(W$49:W$1048576,$D$49:$D$1048576,$F23) -> 0 | X23: =SUMIFS(X$49:X$1048576,$D$49:$D$1048576,$F23) -> 0 | Y23: =SUMIFS(Y$49:Y$1048576,$D$49:$D$1048576,$F23) -> 0 | Z23: =SUMIFS(Z$49:Z$1048576,$D$49:$D$1048576,$F23) -> 0 | AC23: =SUMIFS(AC$49:AC$1048576,$D$49:$D$1048576,$F23) -> 0 | AD23: =SUMIFS(AD$49:AD$1048576,$D$49:$D$1048576,$F23) -> 0 | AE23: =SUMIFS(AE$49:AE$1048576,$D$49:$D$1048576,$F23) -> 0 | AF23: =SUMIFS(AF$49:AF$1048576,$D$49:$D$1048576,$F23) -> 0 | AG23: =SUMIFS(AG$49:AG$1048576,$D$49:$D$1048576,$F23) -> 0 | AJ23: =SUMIFS(AJ$49:AJ$1048576,$D$49:$D$1048576,$F23) -> 0 | AK23: =SUMIFS(AK$49:AK$1048576,$D$49:$D$1048576,$F23) -> 0 | AL23: =SUMIFS(AL$49:AL$1048576,$D$49:$D$1048576,$F23) -> 0 | AM23: =SUMIFS(AM$49:AM$1048576,$D$49:$D$1048576,$F23) -> 0 | AN23: =SUMIFS(AN$49:AN$1048576,$D$49:$D$1048576,$F23) -> 0
C24: Total | D24: =SUM(D18:D23) -> 0 | G24: =SUM(H24:XFD24) -> 0 | H24: =SUMIFS(H$49:H$1048576,$D$49:$D$1048576,$F24) -> 0 | I24: =SUMIFS(I$49:I$1048576,$D$49:$D$1048576,$F24) -> 0 | J24: =SUMIFS(J$49:J$1048576,$D$49:$D$1048576,$F24) -> 0 | K24: =SUMIFS(K$49:K$1048576,$D$49:$D$1048576,$F24) -> 0 | L24: =SUMIFS(L$49:L$1048576,$D$49:$D$1048576,$F24) -> 0 | O24: =SUMIFS(O$49:O$1048576,$D$49:$D$1048576,$F24) -> 0 | P24: =SUMIFS(P$49:P$1048576,$D$49:$D$1048576,$F24) -> 0 | Q24: =SUMIFS(Q$49:Q$1048576,$D$49:$D$1048576,$F24) -> 0 | R24: =SUMIFS(R$49:R$1048576,$D$49:$D$1048576,$F24) -> 0 | S24: =SUMIFS(S$49:S$1048576,$D$49:$D$1048576,$F24) -> 0 | V24: =SUMIFS(V$49:V$1048576,$D$49:$D$1048576,$F24) -> 0 | W24: =SUMIFS(W$49:W$1048576,$D$49:$D$1048576,$F24) -> 0 | X24: =SUMIFS(X$49:X$1048576,$D$49:$D$1048576,$F24) -> 0 | Y24: =SUMIFS(Y$49:Y$1048576,$D$49:$D$1048576,$F24) -> 0 | Z24: =SUMIFS(Z$49:Z$1048576,$D$49:$D$1048576,$F24) -> 0 | AC24: =SUMIFS(AC$49:AC$1048576,$D$49:$D$1048576,$F24) -> 0 | AD24: =SUMIFS(AD$49:AD$1048576,$D$49:$D$1048576,$F24) -> 0 | AE24: =SUMIFS(AE$49:AE$1048576,$D$49:$D$1048576,$F24) -> 0 | AF24: =SUMIFS(AF$49:AF$1048576,$D$49:$D$1048576,$F24) -> 0 | AG24: =SUMIFS(AG$49:AG$1048576,$D$49:$D$1048576,$F24) -> 0 | AJ24: =SUMIFS(AJ$49:AJ$1048576,$D$49:$D$1048576,$F24) -> 0 | AK24: =SUMIFS(AK$49:AK$1048576,$D$49:$D$1048576,$F24) -> 0 | AL24: =SUMIFS(AL$49:AL$1048576,$D$49:$D$1048576,$F24) -> 0 | AM24: =SUMIFS(AM$49:AM$1048576,$D$49:$D$1048576,$F24) -> 0 | AN24: =SUMIFS(AN$49:AN$1048576,$D$49:$D$1048576,$F24) -> 0
G25: =SUM(H25:XFD25) -> 0 | H25: =SUMIFS(H$49:H$1048576,$D$49:$D$1048576,$F25) -> 0 | I25: =SUMIFS(I$49:I$1048576,$D$49:$D$1048576,$F25) -> 0 | J25: =SUMIFS(J$49:J$1048576,$D$49:$D$1048576,$F25) -> 0 | K25: =SUMIFS(K$49:K$1048576,$D$49:$D$1048576,$F25) -> 0 | L25: =SUMIFS(L$49:L$1048576,$D$49:$D$1048576,$F25) -> 0 | O25: =SUMIFS(O$49:O$1048576,$D$49:$D$1048576,$F25) -> 0 | P25: =SUMIFS(P$49:P$1048576,$D$49:$D$1048576,$F25) -> 0 | Q25: =SUMIFS(Q$49:Q$1048576,$D$49:$D$1048576,$F25) -> 0 | R25: =SUMIFS(R$49:R$1048576,$D$49:$D$1048576,$F25) -> 0 | S25: =SUMIFS(S$49:S$1048576,$D$49:$D$1048576,$F25) -> 0 | V25: =SUMIFS(V$49:V$1048576,$D$49:$D$1048576,$F25) -> 0 | W25: =SUMIFS(W$49:W$1048576,$D$49:$D$1048576,$F25) -> 0 | X25: =SUMIFS(X$49:X$1048576,$D$49:$D$1048576,$F25) -> 0 | Y25: =SUMIFS(Y$49:Y$1048576,$D$49:$D$1048576,$F25) -> 0 | Z25: =SUMIFS(Z$49:Z$1048576,$D$49:$D$1048576,$F25) -> 0 | AC25: =SUMIFS(AC$49:AC$1048576,$D$49:$D$1048576,$F25) -> 0 | AD25: =SUMIFS(AD$49:AD$1048576,$D$49:$D$1048576,$F25) -> 0 | AE25: =SUMIFS(AE$49:AE$1048576,$D$49:$D$1048576,$F25) -> 0 | AF25: =SUMIFS(AF$49:AF$1048576,$D$49:$D$1048576,$F25) -> 0 | AG25: =SUMIFS(AG$49:AG$1048576,$D$49:$D$1048576,$F25) -> 0 | AJ25: =SUMIFS(AJ$49:AJ$1048576,$D$49:$D$1048576,$F25) -> 0 | AK25: =SUMIFS(AK$49:AK$1048576,$D$49:$D$1048576,$F25) -> 0 | AL25: =SUMIFS(AL$49:AL$1048576,$D$49:$D$1048576,$F25) -> 0 | AM25: =SUMIFS(AM$49:AM$1048576,$D$49:$D$1048576,$F25) -> 0 | AN25: =SUMIFS(AN$49:AN$1048576,$D$49:$D$1048576,$F25) -> 0
G26: =SUM(H26:XFD26) -> 0 | H26: =SUMIFS(H$49:H$1048576,$D$49:$D$1048576,$F26) -> 0 | I26: =SUMIFS(I$49:I$1048576,$D$49:$D$1048576,$F26) -> 0 | J26: =SUMIFS(J$49:J$1048576,$D$49:$D$1048576,$F26) -> 0 | K26: =SUMIFS(K$49:K$1048576,$D$49:$D$1048576,$F26) -> 0 | L26: =SUMIFS(L$49:L$1048576,$D$49:$D$1048576,$F26) -> 0 | O26: =SUMIFS(O$49:O$1048576,$D$49:$D$1048576,$F26) -> 0 | P26: =SUMIFS(P$49:P$1048576,$D$49:$D$1048576,$F26) -> 0 | Q26: =SUMIFS(Q$49:Q$1048576,$D$49:$D$1048576,$F26) -> 0 | R26: =SUMIFS(R$49:R$1048576,$D$49:$D$1048576,$F26) -> 0 | S26: =SUMIFS(S$49:S$1048576,$D$49:$D$1048576,$F26) -> 0 | V26: =SUMIFS(V$49:V$1048576,$D$49:$D$1048576,$F26) -> 0 | W26: =SUMIFS(W$49:W$1048576,$D$49:$D$1048576,$F26) -> 0 | X26: =SUMIFS(X$49:X$1048576,$D$49:$D$1048576,$F26) -> 0 | Y26: =SUMIFS(Y$49:Y$1048576,$D$49:$D$1048576,$F26) -> 0 | Z26: =SUMIFS(Z$49:Z$1048576,$D$49:$D$1048576,$F26) -> 0 | AC26: =SUMIFS(AC$49:AC$1048576,$D$49:$D$1048576,$F26) -> 0 | AD26: =SUMIFS(AD$49:AD$1048576,$D$49:$D$1048576,$F26) -> 0 | AE26: =SUMIFS(AE$49:AE$1048576,$D$49:$D$1048576,$F26) -> 0 | AF26: =SUMIFS(AF$49:AF$1048576,$D$49:$D$1048576,$F26) -> 0 | AG26: =SUMIFS(AG$49:AG$1048576,$D$49:$D$1048576,$F26) -> 0 | AJ26: =SUMIFS(AJ$49:AJ$1048576,$D$49:$D$1048576,$F26) -> 0 | AK26: =SUMIFS(AK$49:AK$1048576,$D$49:$D$1048576,$F26) -> 0 | AL26: =SUMIFS(AL$49:AL$1048576,$D$49:$D$1048576,$F26) -> 0 | AM26: =SUMIFS(AM$49:AM$1048576,$D$49:$D$1048576,$F26) -> 0 | AN26: =SUMIFS(AN$49:AN$1048576,$D$49:$D$1048576,$F26) -> 0
G27: =SUM(H27:XFD27) -> 0 | H27: =SUMIFS(H$49:H$1048576,$D$49:$D$1048576,$F27) -> 0 | I27: =SUMIFS(I$49:I$1048576,$D$49:$D$1048576,$F27) -> 0 | J27: =SUMIFS(J$49:J$1048576,$D$49:$D$1048576,$F27) -> 0 | K27: =SUMIFS(K$49:K$1048576,$D$49:$D$1048576,$F27) -> 0 | L27: =SUMIFS(L$49:L$1048576,$D$49:$D$1048576,$F27) -> 0 | O27: =SUMIFS(O$49:O$1048576,$D$49:$D$1048576,$F27) -> 0 | P27: =SUMIFS(P$49:P$1048576,$D$49:$D$1048576,$F27) -> 0 | Q27: =SUMIFS(Q$49:Q$1048576,$D$49:$D$1048576,$F27) -> 0 | R27: =SUMIFS(R$49:R$1048576,$D$49:$D$1048576,$F27) -> 0 | S27: =SUMIFS(S$49:S$1048576,$D$49:$D$1048576,$F27) -> 0 | V27: =SUMIFS(V$49:V$1048576,$D$49:$D$1048576,$F27) -> 0 | W27: =SUMIFS(W$49:W$1048576,$D$49:$D$1048576,$F27) -> 0 | X27: =SUMIFS(X$49:X$1048576,$D$49:$D$1048576,$F27) -> 0 | Y27: =SUMIFS(Y$49:Y$1048576,$D$49:$D$1048576,$F27) -> 0 | Z27: =SUMIFS(Z$49:Z$1048576,$D$49:$D$1048576,$F27) -> 0 | AC27: =SUMIFS(AC$49:AC$1048576,$D$49:$D$1048576,$F27) -> 0 | AD27: =SUMIFS(AD$49:AD$1048576,$D$49:$D$1048576,$F27) -> 0 | AE27: =SUMIFS(AE$49:AE$1048576,$D$49:$D$1048576,$F27) -> 0 | AF27: =SUMIFS(AF$49:AF$1048576,$D$49:$D$1048576,$F27) -> 0 | AG27: =SUMIFS(AG$49:AG$1048576,$D$49:$D$1048576,$F27) -> 0 | AJ27: =SUMIFS(AJ$49:AJ$1048576,$D$49:$D$1048576,$F27) -> 0 | AK27: =SUMIFS(AK$49:AK$1048576,$D$49:$D$1048576,$F27) -> 0 | AL27: =SUMIFS(AL$49:AL$1048576,$D$49:$D$1048576,$F27) -> 0 | AM27: =SUMIFS(AM$49:AM$1048576,$D$49:$D$1048576,$F27) -> 0 | AN27: =SUMIFS(AN$49:AN$1048576,$D$49:$D$1048576,$F27) -> 0
G28: =SUM(H28:XFD28) -> 0 | H28: =SUMIFS(H$49:H$1048576,$D$49:$D$1048576,$F28) -> 0 | I28: =SUMIFS(I$49:I$1048576,$D$49:$D$1048576,$F28) -> 0 | J28: =SUMIFS(J$49:J$1048576,$D$49:$D$1048576,$F28) -> 0 | K28: =SUMIFS(K$49:K$1048576,$D$49:$D$1048576,$F28) -> 0 | L28: =SUMIFS(L$49:L$1048576,$D$49:$D$1048576,$F28) -> 0 | O28: =SUMIFS(O$49:O$1048576,$D$49:$D$1048576,$F28) -> 0 | P28: =SUMIFS(P$49:P$1048576,$D$49:$D$1048576,$F28) -> 0 | Q28: =SUMIFS(Q$49:Q$1048576,$D$49:$D$1048576,$F28) -> 0 | R28: =SUMIFS(R$49:R$1048576,$D$49:$D$1048576,$F28) -> 0 | S28: =SUMIFS(S$49:S$1048576,$D$49:$D$1048576,$F28) -> 0 | V28: =SUMIFS(V$49:V$1048576,$D$49:$D$1048576,$F28) -> 0 | W28: =SUMIFS(W$49:W$1048576,$D$49:$D$1048576,$F28) -> 0 | X28: =SUMIFS(X$49:X$1048576,$D$49:$D$1048576,$F28) -> 0 | Y28: =SUMIFS(Y$49:Y$1048576,$D$49:$D$1048576,$F28) -> 0 | Z28: =SUMIFS(Z$49:Z$1048576,$D$49:$D$1048576,$F28) -> 0 | AC28: =SUMIFS(AC$49:AC$1048576,$D$49:$D$1048576,$F28) -> 0 | AD28: =SUMIFS(AD$49:AD$1048576,$D$49:$D$1048576,$F28) -> 0 | AE28: =SUMIFS(AE$49:AE$1048576,$D$49:$D$1048576,$F28) -> 0 | AF28: =SUMIFS(AF$49:AF$1048576,$D$49:$D$1048576,$F28) -> 0 | AG28: =SUMIFS(AG$49:AG$1048576,$D$49:$D$1048576,$F28) -> 0 | AJ28: =SUMIFS(AJ$49:AJ$1048576,$D$49:$D$1048576,$F28) -> 0 | AK28: =SUMIFS(AK$49:AK$1048576,$D$49:$D$1048576,$F28) -> 0 | AL28: =SUMIFS(AL$49:AL$1048576,$D$49:$D$1048576,$F28) -> 0 | AM28: =SUMIFS(AM$49:AM$1048576,$D$49:$D$1048576,$F28) -> 0 | AN28: =SUMIFS(AN$49:AN$1048576,$D$49:$D$1048576,$F28) -> 0
G29: =SUM(H29:XFD29) -> 0 | H29: =SUMIFS(H$49:H$1048576,$D$49:$D$1048576,$F29) -> 0 | I29: =SUMIFS(I$49:I$1048576,$D$49:$D$1048576,$F29) -> 0 | J29: =SUMIFS(J$49:J$1048576,$D$49:$D$1048576,$F29) -> 0 | K29: =SUMIFS(K$49:K$1048576,$D$49:$D$1048576,$F29) -> 0 | L29: =SUMIFS(L$49:L$1048576,$D$49:$D$1048576,$F29) -> 0 | O29: =SUMIFS(O$49:O$1048576,$D$49:$D$1048576,$F29) -> 0 | P29: =SUMIFS(P$49:P$1048576,$D$49:$D$1048576,$F29) -> 0 | Q29: =SUMIFS(Q$49:Q$1048576,$D$49:$D$1048576,$F29) -> 0 | R29: =SUMIFS(R$49:R$1048576,$D$49:$D$1048576,$F29) -> 0 | S29: =SUMIFS(S$49:S$1048576,$D$49:$D$1048576,$F29) -> 0 | V29: =SUMIFS(V$49:V$1048576,$D$49:$D$1048576,$F29) -> 0 | W29: =SUMIFS(W$49:W$1048576,$D$49:$D$1048576,$F29) -> 0 | X29: =SUMIFS(X$49:X$1048576,$D$49:$D$1048576,$F29) -> 0 | Y29: =SUMIFS(Y$49:Y$1048576,$D$49:$D$1048576,$F29) -> 0 | Z29: =SUMIFS(Z$49:Z$1048576,$D$49:$D$1048576,$F29) -> 0 | AC29: =SUMIFS(AC$49:AC$1048576,$D$49:$D$1048576,$F29) -> 0 | AD29: =SUMIFS(AD$49:AD$1048576,$D$49:$D$1048576,$F29) -> 0 | AE29: =SUMIFS(AE$49:AE$1048576,$D$49:$D$1048576,$F29) -> 0 | AF29: =SUMIFS(AF$49:AF$1048576,$D$49:$D$1048576,$F29) -> 0 | AG29: =SUMIFS(AG$49:AG$1048576,$D$49:$D$1048576,$F29) -> 0 | AJ29: =SUMIFS(AJ$49:AJ$1048576,$D$49:$D$1048576,$F29) -> 0 | AK29: =SUMIFS(AK$49:AK$1048576,$D$49:$D$1048576,$F29) -> 0 | AL29: =SUMIFS(AL$49:AL$1048576,$D$49:$D$1048576,$F29) -> 0 | AM29: =SUMIFS(AM$49:AM$1048576,$D$49:$D$1048576,$F29) -> 0 | AN29: =SUMIFS(AN$49:AN$1048576,$D$49:$D$1048576,$F29) -> 0
G30: =SUM(H30:XFD30) -> 0 | H30: =SUMIFS(H$49:H$1048576,$D$49:$D$1048576,$F30) -> 0 | I30: =SUMIFS(I$49:I$1048576,$D$49:$D$1048576,$F30) -> 0 | J30: =SUMIFS(J$49:J$1048576,$D$49:$D$1048576,$F30) -> 0 | K30: =SUMIFS(K$49:K$1048576,$D$49:$D$1048576,$F30) -> 0 | L30: =SUMIFS(L$49:L$1048576,$D$49:$D$1048576,$F30) -> 0 | O30: =SUMIFS(O$49:O$1048576,$D$49:$D$1048576,$F30) -> 0 | P30: =SUMIFS(P$49:P$1048576,$D$49:$D$1048576,$F30) -> 0 | Q30: =SUMIFS(Q$49:Q$1048576,$D$49:$D$1048576,$F30) -> 0 | R30: =SUMIFS(R$49:R$1048576,$D$49:$D$1048576,$F30) -> 0 | S30: =SUMIFS(S$49:S$1048576,$D$49:$D$1048576,$F30) -> 0 | V30: =SUMIFS(V$49:V$1048576,$D$49:$D$1048576,$F30) -> 0 | W30: =SUMIFS(W$49:W$1048576,$D$49:$D$1048576,$F30) -> 0 | X30: =SUMIFS(X$49:X$1048576,$D$49:$D$1048576,$F30) -> 0 | Y30: =SUMIFS(Y$49:Y$1048576,$D$49:$D$1048576,$F30) -> 0 | Z30: =SUMIFS(Z$49:Z$1048576,$D$49:$D$1048576,$F30) -> 0 | AC30: =SUMIFS(AC$49:AC$1048576,$D$49:$D$1048576,$F30) -> 0 | AD30: =SUMIFS(AD$49:AD$1048576,$D$49:$D$1048576,$F30) -> 0 | AE30: =SUMIFS(AE$49:AE$1048576,$D$49:$D$1048576,$F30) -> 0 | AF30: =SUMIFS(AF$49:AF$1048576,$D$49:$D$1048576,$F30) -> 0 | AG30: =SUMIFS(AG$49:AG$1048576,$D$49:$D$1048576,$F30) -> 0 | AJ30: =SUMIFS(AJ$49:AJ$1048576,$D$49:$D$1048576,$F30) -> 0 | AK30: =SUMIFS(AK$49:AK$1048576,$D$49:$D$1048576,$F30) -> 0 | AL30: =SUMIFS(AL$49:AL$1048576,$D$49:$D$1048576,$F30) -> 0 | AM30: =SUMIFS(AM$49:AM$1048576,$D$49:$D$1048576,$F30) -> 0 | AN30: =SUMIFS(AN$49:AN$1048576,$D$49:$D$1048576,$F30) -> 0
G31: =SUM(H31:XFD31) -> 0 | H31: =SUMIFS(H$49:H$1048576,$D$49:$D$1048576,$F31) -> 0 | I31: =SUMIFS(I$49:I$1048576,$D$49:$D$1048576,$F31) -> 0 | J31: =SUMIFS(J$49:J$1048576,$D$49:$D$1048576,$F31) -> 0 | K31: =SUMIFS(K$49:K$1048576,$D$49:$D$1048576,$F31) -> 0 | L31: =SUMIFS(L$49:L$1048576,$D$49:$D$1048576,$F31) -> 0 | O31: =SUMIFS(O$49:O$1048576,$D$49:$D$1048576,$F31) -> 0 | P31: =SUMIFS(P$49:P$1048576,$D$49:$D$1048576,$F31) -> 0 | Q31: =SUMIFS(Q$49:Q$1048576,$D$49:$D$1048576,$F31) -> 0 | R31: =SUMIFS(R$49:R$1048576,$D$49:$D$1048576,$F31) -> 0 | S31: =SUMIFS(S$49:S$1048576,$D$49:$D$1048576,$F31) -> 0 | V31: =SUMIFS(V$49:V$1048576,$D$49:$D$1048576,$F31) -> 0 | W31: =SUMIFS(W$49:W$1048576,$D$49:$D$1048576,$F31) -> 0 | X31: =SUMIFS(X$49:X$1048576,$D$49:$D$1048576,$F31) -> 0 | Y31: =SUMIFS(Y$49:Y$1048576,$D$49:$D$1048576,$F31) -> 0 | Z31: =SUMIFS(Z$49:Z$1048576,$D$49:$D$1048576,$F31) -> 0 | AC31: =SUMIFS(AC$49:AC$1048576,$D$49:$D$1048576,$F31) -> 0 | AD31: =SUMIFS(AD$49:AD$1048576,$D$49:$D$1048576,$F31) -> 0 | AE31: =SUMIFS(AE$49:AE$1048576,$D$49:$D$1048576,$F31) -> 0 | AF31: =SUMIFS(AF$49:AF$1048576,$D$49:$D$1048576,$F31) -> 0 | AG31: =SUMIFS(AG$49:AG$1048576,$D$49:$D$1048576,$F31) -> 0 | AJ31: =SUMIFS(AJ$49:AJ$1048576,$D$49:$D$1048576,$F31) -> 0 | AK31: =SUMIFS(AK$49:AK$1048576,$D$49:$D$1048576,$F31) -> 0 | AL31: =SUMIFS(AL$49:AL$1048576,$D$49:$D$1048576,$F31) -> 0 | AM31: =SUMIFS(AM$49:AM$1048576,$D$49:$D$1048576,$F31) -> 0 | AN31: =SUMIFS(AN$49:AN$1048576,$D$49:$D$1048576,$F31) -> 0
G32: =SUM(H32:XFD32) -> 0 | H32: =SUMIFS(H$49:H$1048576,$D$49:$D$1048576,$F32) -> 0 | I32: =SUMIFS(I$49:I$1048576,$D$49:$D$1048576,$F32) -> 0 | J32: =SUMIFS(J$49:J$1048576,$D$49:$D$1048576,$F32) -> 0 | K32: =SUMIFS(K$49:K$1048576,$D$49:$D$1048576,$F32) -> 0 | L32: =SUMIFS(L$49:L$1048576,$D$49:$D$1048576,$F32) -> 0 | O32: =SUMIFS(O$49:O$1048576,$D$49:$D$1048576,$F32) -> 0 | P32: =SUMIFS(P$49:P$1048576,$D$49:$D$1048576,$F32) -> 0 | Q32: =SUMIFS(Q$49:Q$1048576,$D$49:$D$1048576,$F32) -> 0 | R32: =SUMIFS(R$49:R$1048576,$D$49:$D$1048576,$F32) -> 0 | S32: =SUMIFS(S$49:S$1048576,$D$49:$D$1048576,$F32) -> 0 | V32: =SUMIFS(V$49:V$1048576,$D$49:$D$1048576,$F32) -> 0 | W32: =SUMIFS(W$49:W$1048576,$D$49:$D$1048576,$F32) -> 0 | X32: =SUMIFS(X$49:X$1048576,$D$49:$D$1048576,$F32) -> 0 | Y32: =SUMIFS(Y$49:Y$1048576,$D$49:$D$1048576,$F32) -> 0 | Z32: =SUMIFS(Z$49:Z$1048576,$D$49:$D$1048576,$F32) -> 0 | AC32: =SUMIFS(AC$49:AC$1048576,$D$49:$D$1048576,$F32) -> 0 | AD32: =SUMIFS(AD$49:AD$1048576,$D$49:$D$1048576,$F32) -> 0 | AE32: =SUMIFS(AE$49:AE$1048576,$D$49:$D$1048576,$F32) -> 0 | AF32: =SUMIFS(AF$49:AF$1048576,$D$49:$D$1048576,$F32) -> 0 | AG32: =SUMIFS(AG$49:AG$1048576,$D$49:$D$1048576,$F32) -> 0 | AJ32: =SUMIFS(AJ$49:AJ$1048576,$D$49:$D$1048576,$F32) -> 0 | AK32: =SUMIFS(AK$49:AK$1048576,$D$49:$D$1048576,$F32) -> 0 | AL32: =SUMIFS(AL$49:AL$1048576,$D$49:$D$1048576,$F32) -> 0 | AM32: =SUMIFS(AM$49:AM$1048576,$D$49:$D$1048576,$F32) -> 0 | AN32: =SUMIFS(AN$49:AN$1048576,$D$49:$D$1048576,$F32) -> 0
G33: =SUM(H33:XFD33) -> 0 | H33: =SUMIFS(H$49:H$1048576,$D$49:$D$1048576,$F33) -> 0 | I33: =SUMIFS(I$49:I$1048576,$D$49:$D$1048576,$F33) -> 0 | J33: =SUMIFS(J$49:J$1048576,$D$49:$D$1048576,$F33) -> 0 | K33: =SUMIFS(K$49:K$1048576,$D$49:$D$1048576,$F33) -> 0 | L33: =SUMIFS(L$49:L$1048576,$D$49:$D$1048576,$F33) -> 0 | O33: =SUMIFS(O$49:O$1048576,$D$49:$D$1048576,$F33) -> 0 | P33: =SUMIFS(P$49:P$1048576,$D$49:$D$1048576,$F33) -> 0 | Q33: =SUMIFS(Q$49:Q$1048576,$D$49:$D$1048576,$F33) -> 0 | R33: =SUMIFS(R$49:R$1048576,$D$49:$D$1048576,$F33) -> 0 | S33: =SUMIFS(S$49:S$1048576,$D$49:$D$1048576,$F33) -> 0 | V33: =SUMIFS(V$49:V$1048576,$D$49:$D$1048576,$F33) -> 0 | W33: =SUMIFS(W$49:W$1048576,$D$49:$D$1048576,$F33) -> 0 | X33: =SUMIFS(X$49:X$1048576,$D$49:$D$1048576,$F33) -> 0 | Y33: =SUMIFS(Y$49:Y$1048576,$D$49:$D$1048576,$F33) -> 0 | Z33: =SUMIFS(Z$49:Z$1048576,$D$49:$D$1048576,$F33) -> 0 | AC33: =SUMIFS(AC$49:AC$1048576,$D$49:$D$1048576,$F33) -> 0 | AD33: =SUMIFS(AD$49:AD$1048576,$D$49:$D$1048576,$F33) -> 0 | AE33: =SUMIFS(AE$49:AE$1048576,$D$49:$D$1048576,$F33) -> 0 | AF33: =SUMIFS(AF$49:AF$1048576,$D$49:$D$1048576,$F33) -> 0 | AG33: =SUMIFS(AG$49:AG$1048576,$D$49:$D$1048576,$F33) -> 0 | AJ33: =SUMIFS(AJ$49:AJ$1048576,$D$49:$D$1048576,$F33) -> 0 | AK33: =SUMIFS(AK$49:AK$1048576,$D$49:$D$1048576,$F33) -> 0 | AL33: =SUMIFS(AL$49:AL$1048576,$D$49:$D$1048576,$F33) -> 0 | AM33: =SUMIFS(AM$49:AM$1048576,$D$49:$D$1048576,$F33) -> 0 | AN33: =SUMIFS(AN$49:AN$1048576,$D$49:$D$1048576,$F33) -> 0
G34: =SUM(H34:XFD34) -> 0 | H34: =SUMIFS(H$49:H$1048576,$D$49:$D$1048576,$F34) -> 0 | I34: =SUMIFS(I$49:I$1048576,$D$49:$D$1048576,$F34) -> 0 | J34: =SUMIFS(J$49:J$1048576,$D$49:$D$1048576,$F34) -> 0 | K34: =SUMIFS(K$49:K$1048576,$D$49:$D$1048576,$F34) -> 0 | L34: =SUMIFS(L$49:L$1048576,$D$49:$D$1048576,$F34) -> 0 | O34: =SUMIFS(O$49:O$1048576,$D$49:$D$1048576,$F34) -> 0 | P34: =SUMIFS(P$49:P$1048576,$D$49:$D$1048576,$F34) -> 0 | Q34: =SUMIFS(Q$49:Q$1048576,$D$49:$D$1048576,$F34) -> 0 | R34: =SUMIFS(R$49:R$1048576,$D$49:$D$1048576,$F34) -> 0 | S34: =SUMIFS(S$49:S$1048576,$D$49:$D$1048576,$F34) -> 0 | V34: =SUMIFS(V$49:V$1048576,$D$49:$D$1048576,$F34) -> 0 | W34: =SUMIFS(W$49:W$1048576,$D$49:$D$1048576,$F34) -> 0 | X34: =SUMIFS(X$49:X$1048576,$D$49:$D$1048576,$F34) -> 0 | Y34: =SUMIFS(Y$49:Y$1048576,$D$49:$D$1048576,$F34) -> 0 | Z34: =SUMIFS(Z$49:Z$1048576,$D$49:$D$1048576,$F34) -> 0 | AC34: =SUMIFS(AC$49:AC$1048576,$D$49:$D$1048576,$F34) -> 0 | AD34: =SUMIFS(AD$49:AD$1048576,$D$49:$D$1048576,$F34) -> 0 | AE34: =SUMIFS(AE$49:AE$1048576,$D$49:$D$1048576,$F34) -> 0 | AF34: =SUMIFS(AF$49:AF$1048576,$D$49:$D$1048576,$F34) -> 0 | AG34: =SUMIFS(AG$49:AG$1048576,$D$49:$D$1048576,$F34) -> 0 | AJ34: =SUMIFS(AJ$49:AJ$1048576,$D$49:$D$1048576,$F34) -> 0 | AK34: =SUMIFS(AK$49:AK$1048576,$D$49:$D$1048576,$F34) -> 0 | AL34: =SUMIFS(AL$49:AL$1048576,$D$49:$D$1048576,$F34) -> 0 | AM34: =SUMIFS(AM$49:AM$1048576,$D$49:$D$1048576,$F34) -> 0 | AN34: =SUMIFS(AN$49:AN$1048576,$D$49:$D$1048576,$F34) -> 0
G35: =SUM(H35:XFD35) -> 0 | H35: =SUMIFS(H$49:H$1048576,$D$49:$D$1048576,$F35) -> 0 | I35: =SUMIFS(I$49:I$1048576,$D$49:$D$1048576,$F35) -> 0 | J35: =SUMIFS(J$49:J$1048576,$D$49:$D$1048576,$F35) -> 0 | K35: =SUMIFS(K$49:K$1048576,$D$49:$D$1048576,$F35) -> 0 | L35: =SUMIFS(L$49:L$1048576,$D$49:$D$1048576,$F35) -> 0 | O35: =SUMIFS(O$49:O$1048576,$D$49:$D$1048576,$F35) -> 0 | P35: =SUMIFS(P$49:P$1048576,$D$49:$D$1048576,$F35) -> 0 | Q35: =SUMIFS(Q$49:Q$1048576,$D$49:$D$1048576,$F35) -> 0 | R35: =SUMIFS(R$49:R$1048576,$D$49:$D$1048576,$F35) -> 0 | S35: =SUMIFS(S$49:S$1048576,$D$49:$D$1048576,$F35) -> 0 | V35: =SUMIFS(V$49:V$1048576,$D$49:$D$1048576,$F35) -> 0 | W35: =SUMIFS(W$49:W$1048576,$D$49:$D$1048576,$F35) -> 0 | X35: =SUMIFS(X$49:X$1048576,$D$49:$D$1048576,$F35) -> 0 | Y35: =SUMIFS(Y$49:Y$1048576,$D$49:$D$1048576,$F35) -> 0 | Z35: =SUMIFS(Z$49:Z$1048576,$D$49:$D$1048576,$F35) -> 0 | AC35: =SUMIFS(AC$49:AC$1048576,$D$49:$D$1048576,$F35) -> 0 | AD35: =SUMIFS(AD$49:AD$1048576,$D$49:$D$1048576,$F35) -> 0 | AE35: =SUMIFS(AE$49:AE$1048576,$D$49:$D$1048576,$F35) -> 0 | AF35: =SUMIFS(AF$49:AF$1048576,$D$49:$D$1048576,$F35) -> 0 | AG35: =SUMIFS(AG$49:AG$1048576,$D$49:$D$1048576,$F35) -> 0 | AJ35: =SUMIFS(AJ$49:AJ$1048576,$D$49:$D$1048576,$F35) -> 0 | AK35: =SUMIFS(AK$49:AK$1048576,$D$49:$D$1048576,$F35) -> 0 | AL35: =SUMIFS(AL$49:AL$1048576,$D$49:$D$1048576,$F35) -> 0 | AM35: =SUMIFS(AM$49:AM$1048576,$D$49:$D$1048576,$F35) -> 0 | AN35: =SUMIFS(AN$49:AN$1048576,$D$49:$D$1048576,$F35) -> 0
G36: =SUM(H36:XFD36) -> 0 | H36: =SUMIFS(H$75:H$1048576,$D$75:$D$1048576,$F36) -> 0 | I36: =SUMIFS(I$75:I$1048576,$D$75:$D$1048576,$F36) -> 0 | J36: =SUMIFS(J$75:J$1048576,$D$75:$D$1048576,$F36) -> 0 | K36: =SUMIFS(K$75:K$1048576,$D$75:$D$1048576,$F36) -> 0 | L36: =SUMIFS(L$75:L$1048576,$D$75:$D$1048576,$F36) -> 0 | O36: =SUMIFS(O$75:O$1048576,$D$75:$D$1048576,$F36) -> 0 | P36: =SUMIFS(P$75:P$1048576,$D$75:$D$1048576,$F36) -> 0 | Q36: =SUMIFS(Q$75:Q$1048576,$D$75:$D$1048576,$F36) -> 0 | R36: =SUMIFS(R$75:R$1048576,$D$75:$D$1048576,$F36) -> 0 | S36: =SUMIFS(S$75:S$1048576,$D$75:$D$1048576,$F36) -> 0 | V36: =SUMIFS(V$75:V$1048576,$D$75:$D$1048576,$F36) -> 0 | W36: =SUMIFS(W$75:W$1048576,$D$75:$D$1048576,$F36) -> 0 | X36: =SUMIFS(X$75:X$1048576,$D$75:$D$1048576,$F36) -> 0 | Y36: =SUMIFS(Y$75:Y$1048576,$D$75:$D$1048576,$F36) -> 0 | Z36: =SUMIFS(Z$75:Z$1048576,$D$75:$D$1048576,$F36) -> 0 | AC36: =SUMIFS(AC$75:AC$1048576,$D$75:$D$1048576,$F36) -> 0 | AD36: =SUMIFS(AD$75:AD$1048576,$D$75:$D$1048576,$F36) -> 0 | AE36: =SUMIFS(AE$75:AE$1048576,$D$75:$D$1048576,$F36) -> 0 | AF36: =SUMIFS(AF$75:AF$1048576,$D$75:$D$1048576,$F36) -> 0 | AG36: =SUMIFS(AG$75:AG$1048576,$D$75:$D$1048576,$F36) -> 0 | AJ36: =SUMIFS(AJ$75:AJ$1048576,$D$75:$D$1048576,$F36) -> 0 | AK36: =SUMIFS(AK$75:AK$1048576,$D$75:$D$1048576,$F36) -> 0 | AL36: =SUMIFS(AL$75:AL$1048576,$D$75:$D$1048576,$F36) -> 0 | AM36: =SUMIFS(AM$75:AM$1048576,$D$75:$D$1048576,$F36) -> 0 | AN36: =SUMIFS(AN$75:AN$1048576,$D$75:$D$1048576,$F36) -> 0
G37: =SUM(H37:XFD37) -> 0 | H37: =SUMIFS(H$75:H$1048576,$D$75:$D$1048576,$F37) -> 0 | I37: =SUMIFS(I$75:I$1048576,$D$75:$D$1048576,$F37) -> 0 | J37: =SUMIFS(J$75:J$1048576,$D$75:$D$1048576,$F37) -> 0 | K37: =SUMIFS(K$75:K$1048576,$D$75:$D$1048576,$F37) -> 0 | L37: =SUMIFS(L$75:L$1048576,$D$75:$D$1048576,$F37) -> 0 | O37: =SUMIFS(O$75:O$1048576,$D$75:$D$1048576,$F37) -> 0 | P37: =SUMIFS(P$75:P$1048576,$D$75:$D$1048576,$F37) -> 0 | Q37: =SUMIFS(Q$75:Q$1048576,$D$75:$D$1048576,$F37) -> 0 | R37: =SUMIFS(R$75:R$1048576,$D$75:$D$1048576,$F37) -> 0 | S37: =SUMIFS(S$75:S$1048576,$D$75:$D$1048576,$F37) -> 0 | V37: =SUMIFS(V$75:V$1048576,$D$75:$D$1048576,$F37) -> 0 | W37: =SUMIFS(W$75:W$1048576,$D$75:$D$1048576,$F37) -> 0 | X37: =SUMIFS(X$75:X$1048576,$D$75:$D$1048576,$F37) -> 0 | Y37: =SUMIFS(Y$75:Y$1048576,$D$75:$D$1048576,$F37) -> 0 | Z37: =SUMIFS(Z$75:Z$1048576,$D$75:$D$1048576,$F37) -> 0 | AC37: =SUMIFS(AC$75:AC$1048576,$D$75:$D$1048576,$F37) -> 0 | AD37: =SUMIFS(AD$75:AD$1048576,$D$75:$D$1048576,$F37) -> 0 | AE37: =SUMIFS(AE$75:AE$1048576,$D$75:$D$1048576,$F37) -> 0 | AF37: =SUMIFS(AF$75:AF$1048576,$D$75:$D$1048576,$F37) -> 0 | AG37: =SUMIFS(AG$75:AG$1048576,$D$75:$D$1048576,$F37) -> 0 | AJ37: =SUMIFS(AJ$75:AJ$1048576,$D$75:$D$1048576,$F37) -> 0 | AK37: =SUMIFS(AK$75:AK$1048576,$D$75:$D$1048576,$F37) -> 0 | AL37: =SUMIFS(AL$75:AL$1048576,$D$75:$D$1048576,$F37) -> 0 | AM37: =SUMIFS(AM$75:AM$1048576,$D$75:$D$1048576,$F37) -> 0 | AN37: =SUMIFS(AN$75:AN$1048576,$D$75:$D$1048576,$F37) -> 0
G38: =SUM(H38:XFD38) -> 0 | H38: =SUMIFS(H$75:H$1048576,$D$75:$D$1048576,$F38) -> 0 | I38: =SUMIFS(I$75:I$1048576,$D$75:$D$1048576,$F38) -> 0 | J38: =SUMIFS(J$75:J$1048576,$D$75:$D$1048576,$F38) -> 0 | K38: =SUMIFS(K$75:K$1048576,$D$75:$D$1048576,$F38) -> 0 | L38: =SUMIFS(L$75:L$1048576,$D$75:$D$1048576,$F38) -> 0 | O38: =SUMIFS(O$75:O$1048576,$D$75:$D$1048576,$F38) -> 0 | P38: =SUMIFS(P$75:P$1048576,$D$75:$D$1048576,$F38) -> 0 | Q38: =SUMIFS(Q$75:Q$1048576,$D$75:$D$1048576,$F38) -> 0 | R38: =SUMIFS(R$75:R$1048576,$D$75:$D$1048576,$F38) -> 0 | S38: =SUMIFS(S$75:S$1048576,$D$75:$D$1048576,$F38) -> 0 | V38: =SUMIFS(V$75:V$1048576,$D$75:$D$1048576,$F38) -> 0 | W38: =SUMIFS(W$75:W$1048576,$D$75:$D$1048576,$F38) -> 0 | X38: =SUMIFS(X$75:X$1048576,$D$75:$D$1048576,$F38) -> 0 | Y38: =SUMIFS(Y$75:Y$1048576,$D$75:$D$1048576,$F38) -> 0 | Z38: =SUMIFS(Z$75:Z$1048576,$D$75:$D$1048576,$F38) -> 0 | AC38: =SUMIFS(AC$75:AC$1048576,$D$75:$D$1048576,$F38) -> 0 | AD38: =SUMIFS(AD$75:AD$1048576,$D$75:$D$1048576,$F38) -> 0 | AE38: =SUMIFS(AE$75:AE$1048576,$D$75:$D$1048576,$F38) -> 0 | AF38: =SUMIFS(AF$75:AF$1048576,$D$75:$D$1048576,$F38) -> 0 | AG38: =SUMIFS(AG$75:AG$1048576,$D$75:$D$1048576,$F38) -> 0 | AJ38: =SUMIFS(AJ$75:AJ$1048576,$D$75:$D$1048576,$F38) -> 0 | AK38: =SUMIFS(AK$75:AK$1048576,$D$75:$D$1048576,$F38) -> 0 | AL38: =SUMIFS(AL$75:AL$1048576,$D$75:$D$1048576,$F38) -> 0 | AM38: =SUMIFS(AM$75:AM$1048576,$D$75:$D$1048576,$F38) -> 0 | AN38: =SUMIFS(AN$75:AN$1048576,$D$75:$D$1048576,$F38) -> 0
G39: =SUM(H39:XFD39) -> 0 | H39: =SUMIFS(H$75:H$1048576,$D$75:$D$1048576,$F39) -> 0 | I39: =SUMIFS(I$75:I$1048576,$D$75:$D$1048576,$F39) -> 0 | J39: =SUMIFS(J$75:J$1048576,$D$75:$D$1048576,$F39) -> 0 | K39: =SUMIFS(K$75:K$1048576,$D$75:$D$1048576,$F39) -> 0 | L39: =SUMIFS(L$75:L$1048576,$D$75:$D$1048576,$F39) -> 0 | O39: =SUMIFS(O$75:O$1048576,$D$75:$D$1048576,$F39) -> 0 | P39: =SUMIFS(P$75:P$1048576,$D$75:$D$1048576,$F39) -> 0 | Q39: =SUMIFS(Q$75:Q$1048576,$D$75:$D$1048576,$F39) -> 0 | R39: =SUMIFS(R$75:R$1048576,$D$75:$D$1048576,$F39) -> 0 | S39: =SUMIFS(S$75:S$1048576,$D$75:$D$1048576,$F39) -> 0 | V39: =SUMIFS(V$75:V$1048576,$D$75:$D$1048576,$F39) -> 0 | W39: =SUMIFS(W$75:W$1048576,$D$75:$D$1048576,$F39) -> 0 | X39: =SUMIFS(X$75:X$1048576,$D$75:$D$1048576,$F39) -> 0 | Y39: =SUMIFS(Y$75:Y$1048576,$D$75:$D$1048576,$F39) -> 0 | Z39: =SUMIFS(Z$75:Z$1048576,$D$75:$D$1048576,$F39) -> 0 | AC39: =SUMIFS(AC$75:AC$1048576,$D$75:$D$1048576,$F39) -> 0 | AD39: =SUMIFS(AD$75:AD$1048576,$D$75:$D$1048576,$F39) -> 0 | AE39: =SUMIFS(AE$75:AE$1048576,$D$75:$D$1048576,$F39) -> 0 | AF39: =SUMIFS(AF$75:AF$1048576,$D$75:$D$1048576,$F39) -> 0 | AG39: =SUMIFS(AG$75:AG$1048576,$D$75:$D$1048576,$F39) -> 0 | AJ39: =SUMIFS(AJ$75:AJ$1048576,$D$75:$D$1048576,$F39) -> 0 | AK39: =SUMIFS(AK$75:AK$1048576,$D$75:$D$1048576,$F39) -> 0 | AL39: =SUMIFS(AL$75:AL$1048576,$D$75:$D$1048576,$F39) -> 0 | AM39: =SUMIFS(AM$75:AM$1048576,$D$75:$D$1048576,$F39) -> 0 | AN39: =SUMIFS(AN$75:AN$1048576,$D$75:$D$1048576,$F39) -> 0
G40: =SUM(H40:XFD40) -> 0 | H40: =SUMIFS(H$75:H$1048576,$D$75:$D$1048576,$F40) -> 0 | I40: =SUMIFS(I$75:I$1048576,$D$75:$D$1048576,$F40) -> 0 | J40: =SUMIFS(J$75:J$1048576,$D$75:$D$1048576,$F40) -> 0 | K40: =SUMIFS(K$75:K$1048576,$D$75:$D$1048576,$F40) -> 0 | L40: =SUMIFS(L$75:L$1048576,$D$75:$D$1048576,$F40) -> 0 | O40: =SUMIFS(O$75:O$1048576,$D$75:$D$1048576,$F40) -> 0 | P40: =SUMIFS(P$75:P$1048576,$D$75:$D$1048576,$F40) -> 0 | Q40: =SUMIFS(Q$75:Q$1048576,$D$75:$D$1048576,$F40) -> 0 | R40: =SUMIFS(R$75:R$1048576,$D$75:$D$1048576,$F40) -> 0 | S40: =SUMIFS(S$75:S$1048576,$D$75:$D$1048576,$F40) -> 0 | V40: =SUMIFS(V$75:V$1048576,$D$75:$D$1048576,$F40) -> 0 | W40: =SUMIFS(W$75:W$1048576,$D$75:$D$1048576,$F40) -> 0 | X40: =SUMIFS(X$75:X$1048576,$D$75:$D$1048576,$F40) -> 0 | Y40: =SUMIFS(Y$75:Y$1048576,$D$75:$D$1048576,$F40) -> 0 | Z40: =SUMIFS(Z$75:Z$1048576,$D$75:$D$1048576,$F40) -> 0 | AC40: =SUMIFS(AC$75:AC$1048576,$D$75:$D$1048576,$F40) -> 0 | AD40: =SUMIFS(AD$75:AD$1048576,$D$75:$D$1048576,$F40) -> 0 | AE40: =SUMIFS(AE$75:AE$1048576,$D$75:$D$1048576,$F40) -> 0 | AF40: =SUMIFS(AF$75:AF$1048576,$D$75:$D$1048576,$F40) -> 0 | AG40: =SUMIFS(AG$75:AG$1048576,$D$75:$D$1048576,$F40) -> 0 | AJ40: =SUMIFS(AJ$75:AJ$1048576,$D$75:$D$1048576,$F40) -> 0 | AK40: =SUMIFS(AK$75:AK$1048576,$D$75:$D$1048576,$F40) -> 0 | AL40: =SUMIFS(AL$75:AL$1048576,$D$75:$D$1048576,$F40) -> 0 | AM40: =SUMIFS(AM$75:AM$1048576,$D$75:$D$1048576,$F40) -> 0 | AN40: =SUMIFS(AN$75:AN$1048576,$D$75:$D$1048576,$F40) -> 0
A42: 2 | B42: Actividades Mensuales
H46: L | I46: M | J46: M | K46: J | L46: V | M46: S | N46: D | O46: L | P46: M | Q46: M | R46: J | S46: V | T46: S | U46: D | V46: L | W46: M | X46: M | Y46: J | Z46: V | AA46: S | AB46: D | AC46: L | AD46: M | AE46: M | AF46: J | AG46: V | AH46: S | AI46: D | AJ46: L | AK46: M | AL46: M | AM46: J | AN46: V
...

Sheet GPT cache
RYB132792: {"hash":"b5b206b700d57213a5feb4820321b9b08946c141ff23d608b1ae412b84b40a8c","version":1,"value":"[[\"Memo técnico - bases de planificación\"],[\"Memo técnico - bases de planificación\"],[\"Memo técnico - bases de planificación\"],[\"Memo técnico - bases de planificación\"],[\"Memo técnico - bases de planificación\"],[\"Memo técnico - bases de planificación\"],[\"Memo técnico - bases de planificación\"],[\"Modelo de planificación\"],[\"Modelo de planificación\"],[\"Modelo de planificación\"],[\"Modelo de planificación\"],[\"Modelo de planificación\"],[\"Informe Optimización, Diseño Minero y Reservas Mineras\"],[\"Informe Optimización, Diseño Minero y Reservas Mineras\"],[\"Informe Optimización, Diseño Minero y Reservas Mineras\"],[\"Informe Optimización, Diseño Minero y Reservas Mineras\"],[\"Informe Optimización, Diseño Minero y Reservas Mineras\"],[\"Informe Optimización, Diseño Minero y Reservas Mineras\"],[\"Informe Optimización, Diseño Minero y Reservas Mineras\"],[\"Informe Optimización, Diseño Minero y Reservas Mineras\"],[\"Informe Optimización, Diseño Minero y Reservas Mineras\"],[\"Informe Optimización, Diseño Minero y Reservas Mineras\"],[\"\"],[\"\"],[\"\"],[\"\"],[\"\"],[\"\"],[\"\"],[\"\"],[\"\"],[\"\"],[\"\"],[\"\"],[\"\"],[\"\"],[\"\"],[\"\"],[\"\"],[\"\"],[\"\"],[\"\"],[\"\"],[\"\"],[\"\"],[\"\"],[\"\"],[\"\"],[\"\"],[\"\"],[\"\"],[\"\"],[\"\"],[\"\"],[\"\"],[\"\"],[\"\"],[\"\"],[\"\"],[\"\"],[\"\"],[\"\"],[\"\"],[\"\"],[\"\"],[\"\"],[\"\"],[\"\"],[\"\"],[\"\"],[\"\"],[\"\"],[\"\"],[\"\"],[\"\"],[\"\"],[\"\"],[\"\"],[\"\"],[\"\"],[\"\"],[\"\"],[\"\"],[\"\"],[\"\"],[\"\"],[\"\"],[\"\"],[\"\"],[\"\"],[\"\"],[\"\"],[\"\"],[\"\"],[\"\"],[\"\"],[\"\"],[\"\"],[\"\"],[\"\"],[\"\"],[\"\"],[\"\"],[\"\"],[\"\"],[\"\"],[\"\"],[\"\"],[\"\"],[\"\"],[\"\"],[\"\"],[\"\"],[\"\"],[\"\"],[\"\"],[\"\"],[\"\"],[\"\"],[\"\"],[\"\"],[\"\"],[\"\"],[\"\"],[\"\"],[\"\"],[\"\"],[\"\"],[\"\"],[\"\"],[\"\"],[\"\"],[\"\"],[\"\"],[\"\"],[\"\"],[\"\"],[\"\"],[\"\"],[\"\"],[\"\"],[\"\"],[\"\"],[\"\"],[\"\"],[\"\"],[\"\"],[\"\"],[\"\"],[\"\"],[\"\"],[\"\"],[\"\"],[\"\"],[\"\"],[\"\"],[\"\"],[\"\"],[\"\"],[\"\"],[\"\"],[\"\"],[\"\"],[\"\"],[\"\"],[\"\"],[\"\"],[\"\"],[\"\"],[\"\"],[\"\"],[\"\"],[\"\"],[\"\"],[\"\"],[\"\"],[\"\"],[\"\"],[\"\"],[\"\"],[\"\"],[\"\"],[\"\"],[\"\"],[\"\"],[\"\"],[\"\"],[\"\"],[\"\"],[\"\"],[\"\"],[\"\"],[\"\"],[\"\"],[\"\"],[\"\"],[\"\"],[\"\"],[\"\"],[\"\"],[\"\"]]"}

Sheet EroCopper_Scoping Furnas
C2: Planificación de Actividades
C3: =Calendario!$D$2 -> 46174
C4: ="Proyecto: "&D9 -> Proyecto: EroCopper_Scoping Proyecto Furnas
C5: =_xlfn.CONCAT("Director:"," ",D10) -> Director: Alex Figueroa
A7: 1 | B7: Carga Laboral | C7: *No modificar
H8: =IF(OR(H$48<Calendario!$F$2,H$48>Calendario!$F$3),0,H10) -> 9 | I8: =IF(OR(I$48<Calendario!$F$2,I$48>Calendario!$F$3),0,I10) -> 9 | J8: =IF(OR(J$48<Calendario!$F$2,J$48>Calendario!$F$3),0,J10) -> 9 | K8: =IF(OR(K$48<Calendario!$F$2,K$48>Calendario!$F$3),0,K10) -> 9 | L8: =IF(OR(L$48<Calendario!$F$2,L$48>Calendario!$F$3),0,L10) -> 6 | M8: =IF(OR(M$48<Calendario!$F$2,M$48>Calendario!$F$3),0,M10) -> 0 | N8: =IF(OR(N$48<Calendario!$F$2,N$48>Calendario!$F$3),0,N10) -> 0 | O8: =IF(OR(O$48<Calendario!$F$2,O$48>Calendario!$F$3),0,O10) -> 9 | ... AN8: =IF(OR(AN$48<Calendario!$F$2,AN$48>Calendario!$F$3),0,AN10) -> 0
C9: Nombre | D9: EroCopper_Scoping Proyecto Furnas | H9: L | I9: M | J9: M | K9: J | L9: V | M9: S | N9: D | O9: L | P9: M | Q9: M | R9: J | S9: V | T9: S | U9: D | V9: L | W9: M | X9: M | Y9: J | Z9: V | AA9: S | AB9: D | AC9: L | AD9: M | AE9: M | AF9: J | AG9: V | AH9: S | AI9: D | AJ9: L | AK9: M | AL9: M | AM9: J | AN9: V
