Workbook

Sheet Comparativo por País
A1: Dotación por País y Categoría Estandarizada — Comparativo 2025 vs 2026
A2: Categorías estandarizadas según taxonomía 2026. Ver hoja "Mapeo de Cargos" para el detalle de la reclasificación de 2025.
A4: Categoría | B4: Brasil | D4: Chile | F4: Perú | H4: Rusia | J4: USA | L4: Total | N4: Variación
B5: 2025 | C5: 2026 | D5: 2025 | E5: 2026 | F5: 2025 | G5: 2026 | H5: 2025 | I5: 2026 | J5: 2025 | K5: 2026 | L5: 2025 | M5: 2026 | N5: Δ (n) | O5: Δ (%)
A6: Administración | B6: =SUMIFS('Datos Estandarizados'!$F$2:$F$195,'Datos Estandarizados'!$A$2:$A$195,2025,'Datos Estandarizados'!$B$2:$B$195,$A6,'Datos Estandarizados'!$E$2:$E$195,"Brasil") -> 0 | C6: =SUMIFS('Datos Estandarizados'!$F$2:$F$195,'Datos Estandarizados'!$A$2:$A$195,2026,'Datos Estandarizados'!$B$2:$B$195,$A6,'Datos Estandarizados'!$E$2:$E$195,"Brasil") -> 2 | D6: =SUMIFS('Datos Estandarizados'!$F$2:$F$195,'Datos Estandarizados'!$A$2:$A$195,2025,'Datos Estandarizados'!$B$2:$B$195,$A6,'Datos Estandarizados'!$E$2:$E$195,"Chile") -> 4 | E6: =SUMIFS('Datos Estandarizados'!$F$2:$F$195,'Datos Estandarizados'!$A$2:$A$195,2026,'Datos Estandarizados'!$B$2:$B$195,$A6,'Datos Estandarizados'!$E$2:$E$195,"Chile") -> 5 | F6: =SUMIFS('Datos Estandarizados'!$F$2:$F$195,'Datos Estandarizados'!$A$2:$A$195,2025,'Datos Estandarizados'!$B$2:$B$195,$A6,'Datos Estandarizados'!$E$2:$E$195,"Perú") -> 0 | G6: =SUMIFS('Datos Estandarizados'!$F$2:$F$195,'Datos Estandarizados'!$A$2:$A$195,2026,'Datos Estandarizados'!$B$2:$B$195,$A6,'Datos Estandarizados'!$E$2:$E$195,"Perú") -> 1 | H6: =SUMIFS('Datos Estandarizados'!$F$2:$F$195,'Datos Estandarizados'!$A$2:$A$195,2025,'Datos Estandarizados'!$B$2:$B$195,$A6,'Datos Estandarizados'!$E$2:$E$195,"Rusia") -> 0 | I6: =SUMIFS('Datos Estandarizados'!$F$2:$F$195,'Datos Estandarizados'!$A$2:$A$195,2026,'Datos Estandarizados'!$B$2:$B$195,$A6,'Datos Estandarizados'!$E$2:$E$195,"Rusia") -> 0 | J6: =SUMIFS('Datos Estandarizados'!$F$2:$F$195,'Datos Estandarizados'!$A$2:$A$195,2025,'Datos Estandarizados'!$B$2:$B$195,$A6,'Datos Estandarizados'!$E$2:$E$195,"USA") -> 0 | K6: =SUMIFS('Datos Estandarizados'!$F$2:$F$195,'Datos Estandarizados'!$A$2:$A$195,2026,'Datos Estandarizados'!$B$2:$B$195,$A6,'Datos Estandarizados'!$E$2:$E$195,"USA") -> 1 | L6: =SUMIFS('Datos Estandarizados'!$F$2:$F$195,'Datos Estandarizados'!$A$2:$A$195,2025,'Datos Estandarizados'!$B$2:$B$195,$A6) -> 4 | M6: =SUMIFS('Datos Estandarizados'!$F$2:$F$195,'Datos Estandarizados'!$A$2:$A$195,2026,'Datos Estandarizados'!$B$2:$B$195,$A6) -> 9 | N6: =M6-L6 -> 5 | O6: =IF(L6=0,"n/a",(M6-L6)/L6) -> 1.25
A7: Comercial | B7: =SUMIFS('Datos Estandarizados'!$F$2:$F$195,'Datos Estandarizados'!$A$2:$A$195,2025,'Datos Estandarizados'!$B$2:$B$195,$A7,'Datos Estandarizados'!$E$2:$E$195,"Brasil") -> 3 | C7: =SUMIFS('Datos Estandarizados'!$F$2:$F$195,'Datos Estandarizados'!$A$2:$A$195,2026,'Datos Estandarizados'!$B$2:$B$195,$A7,'Datos Estandarizados'!$E$2:$E$195,"Brasil") -> 1 | D7: =SUMIFS('Datos Estandarizados'!$F$2:$F$195,'Datos Estandarizados'!$A$2:$A$195,2025,'Datos Estandarizados'!$B$2:$B$195,$A7,'Datos Estandarizados'!$E$2:$E$195,"Chile") -> 4 | E7: =SUMIFS('Datos Estandarizados'!$F$2:$F$195,'Datos Estandarizados'!$A$2:$A$195,2026,'Datos Estandarizados'!$B$2:$B$195,$A7,'Datos Estandarizados'!$E$2:$E$195,"Chile") -> 6 | F7: =SUMIFS('Datos Estandarizados'!$F$2:$F$195,'Datos Estandarizados'!$A$2:$A$195,2025,'Datos Estandarizados'!$B$2:$B$195,$A7,'Datos Estandarizados'!$E$2:$E$195,"Perú") -> 2 | G7: =SUMIFS('Datos Estandarizados'!$F$2:$F$195,'Datos Estandarizados'!$A$2:$A$195,2026,'Datos Estandarizados'!$B$2:$B$195,$A7,'Datos Estandarizados'!$E$2:$E$195,"Perú") -> 2 | H7: =SUMIFS('Datos Estandarizados'!$F$2:$F$195,'Datos Estandarizados'!$A$2:$A$195,2025,'Datos Estandarizados'!$B$2:$B$195,$A7,'Datos Estandarizados'!$E$2:$E$195,"Rusia") -> 0 | I7: =SUMIFS('Datos Estandarizados'!$F$2:$F$195,'Datos Estandarizados'!$A$2:$A$195,2026,'Datos Estandarizados'!$B$2:$B$195,$A7,'Datos Estandarizados'!$E$2:$E$195,"Rusia") -> 1 | J7: =SUMIFS('Datos Estandarizados'!$F$2:$F$195,'Datos Estandarizados'!$A$2:$A$195,2025,'Datos Estandarizados'!$B$2:$B$195,$A7,'Datos Estandarizados'!$E$2:$E$195,"USA") -> 1 | K7: =SUMIFS('Datos Estandarizados'!$F$2:$F$195,'Datos Estandarizados'!$A$2:$A$195,2026,'Datos Estandarizados'!$B$2:$B$195,$A7,'Datos Estandarizados'!$E$2:$E$195,"USA") -> 0 | L7: =SUMIFS('Datos Estandarizados'!$F$2:$F$195,'Datos Estandarizados'!$A$2:$A$195,2025,'Datos Estandarizados'!$B$2:$B$195,$A7) -> 10 | M7: =SUMIFS('Datos Estandarizados'!$F$2:$F$195,'Datos Estandarizados'!$A$2:$A$195,2026,'Datos Estandarizados'!$B$2:$B$195,$A7) -> 10 | N7: =M7-L7 -> 0 | O7: =IF(L7=0,"n/a",(M7-L7)/L7) -> 0
A8: Geomecánica | B8: =SUMIFS('Datos Estandarizados'!$F$2:$F$195,'Datos Estandarizados'!$A$2:$A$195,2025,'Datos Estandarizados'!$B$2:$B$195,$A8,'Datos Estandarizados'!$E$2:$E$195,"Brasil") -> 0 | C8: =SUMIFS('Datos Estandarizados'!$F$2:$F$195,'Datos Estandarizados'!$A$2:$A$195,2026,'Datos Estandarizados'!$B$2:$B$195,$A8,'Datos Estandarizados'!$E$2:$E$195,"Brasil") -> 0 | D8: =SUMIFS('Datos Estandarizados'!$F$2:$F$195,'Datos Estandarizados'!$A$2:$A$195,2025,'Datos Estandarizados'!$B$2:$B$195,$A8,'Datos Estandarizados'!$E$2:$E$195,"Chile") -> 0 | E8: =SUMIFS('Datos Estandarizados'!$F$2:$F$195,'Datos Estandarizados'!$A$2:$A$195,2026,'Datos Estandarizados'!$B$2:$B$195,$A8,'Datos Estandarizados'!$E$2:$E$195,"Chile") -> 8 | F8: =SUMIFS('Datos Estandarizados'!$F$2:$F$195,'Datos Estandarizados'!$A$2:$A$195,2025,'Datos Estandarizados'!$B$2:$B$195,$A8,'Datos Estandarizados'!$E$2:$E$195,"Perú") -> 0 | G8: =SUMIFS('Datos Estandarizados'!$F$2:$F$195,'Datos Estandarizados'!$A$2:$A$195,2026,'Datos Estandarizados'!$B$2:$B$195,$A8,'Datos Estandarizados'!$E$2:$E$195,"Perú") -> 9 | H8: =SUMIFS('Datos Estandarizados'!$F$2:$F$195,'Datos Estandarizados'!$A$2:$A$195,2025,'Datos Estandarizados'!$B$2:$B$195,$A8,'Datos Estandarizados'!$E$2:$E$195,"Rusia") -> 0 | I8: =SUMIFS('Datos Estandarizados'!$F$2:$F$195,'Datos Estandarizados'!$A$2:$A$195,2026,'Datos Estandarizados'!$B$2:$B$195,$A8,'Datos Estandarizados'!$E$2:$E$195,"Rusia") -> 0 | J8: =SUMIFS('Datos Estandarizados'!$F$2:$F$195,'Datos Estandarizados'!$A$2:$A$195,2025,'Datos Estandarizados'!$B$2:$B$195,$A8,'Datos Estandarizados'!$E$2:$E$195,"USA") -> 0 | K8: =SUMIFS('Datos Estandarizados'!$F$2:$F$195,'Datos Estandarizados'!$A$2:$A$195,2026,'Datos Estandarizados'!$B$2:$B$195,$A8,'Datos Estandarizados'!$E$2:$E$195,"USA") -> 0 | L8: =SUMIFS('Datos Estandarizados'!$F$2:$F$195,'Datos Estandarizados'!$A$2:$A$195,2025,'Datos Estandarizados'!$B$2:$B$195,$A8) -> 0 | M8: =SUMIFS('Datos Estandarizados'!$F$2:$F$195,'Datos Estandarizados'!$A$2:$A$195,2026,'Datos Estandarizados'!$B$2:$B$195,$A8) -> 17 | N8: =M8-L8 -> 17 | O8: =IF(L8=0,"n/a",(M8-L8)/L8) -> n/a
A9: Gestión | B9: =SUMIFS('Datos Estandarizados'!$F$2:$F$195,'Datos Estandarizados'!$A$2:$A$195,2025,'Datos Estandarizados'!$B$2:$B$195,$A9,'Datos Estandarizados'!$E$2:$E$195,"Brasil") -> 0 | C9: =SUMIFS('Datos Estandarizados'!$F$2:$F$195,'Datos Estandarizados'!$A$2:$A$195,2026,'Datos Estandarizados'!$B$2:$B$195,$A9,'Datos Estandarizados'!$E$2:$E$195,"Brasil") -> 0 | D9: =SUMIFS('Datos Estandarizados'!$F$2:$F$195,'Datos Estandarizados'!$A$2:$A$195,2025,'Datos Estandarizados'!$B$2:$B$195,$A9,'Datos Estandarizados'!$E$2:$E$195,"Chile") -> 5 | E9: =SUMIFS('Datos Estandarizados'!$F$2:$F$195,'Datos Estandarizados'!$A$2:$A$195,2026,'Datos Estandarizados'!$B$2:$B$195,$A9,'Datos Estandarizados'!$E$2:$E$195,"Chile") -> 3 | F9: =SUMIFS('Datos Estandarizados'!$F$2:$F$195,'Datos Estandarizados'!$A$2:$A$195,2025,'Datos Estandarizados'!$B$2:$B$195,$A9,'Datos Estandarizados'!$E$2:$E$195,"Perú") -> 1 | G9: =SUMIFS('Datos Estandarizados'!$F$2:$F$195,'Datos Estandarizados'!$A$2:$A$195,2026,'Datos Estandarizados'!$B$2:$B$195,$A9,'Datos Estandarizados'!$E$2:$E$195,"Perú") -> 1 | H9: =SUMIFS('Datos Estandarizados'!$F$2:$F$195,'Datos Estandarizados'!$A$2:$A$195,2025,'Datos Estandarizados'!$B$2:$B$195,$A9,'Datos Estandarizados'!$E$2:$E$195,"Rusia") -> 0 | I9: =SUMIFS('Datos Estandarizados'!$F$2:$F$195,'Datos Estandarizados'!$A$2:$A$195,2026,'Datos Estandarizados'!$B$2:$B$195,$A9,'Datos Estandarizados'!$E$2:$E$195,"Rusia") -> 0 | J9: =SUMIFS('Datos Estandarizados'!$F$2:$F$195,'Datos Estandarizados'!$A$2:$A$195,2025,'Datos Estandarizados'!$B$2:$B$195,$A9,'Datos Estandarizados'!$E$2:$E$195,"USA") -> 0 | K9: =SUMIFS('Datos Estandarizados'!$F$2:$F$195,'Datos Estandarizados'!$A$2:$A$195,2026,'Datos Estandarizados'!$B$2:$B$195,$A9,'Datos Estandarizados'!$E$2:$E$195,"USA") -> 0 | L9: =SUMIFS('Datos Estandarizados'!$F$2:$F$195,'Datos Estandarizados'!$A$2:$A$195,2025,'Datos Estandarizados'!$B$2:$B$195,$A9) -> 6 | M9: =SUMIFS('Datos Estandarizados'!$F$2:$F$195,'Datos Estandarizados'!$A$2:$A$195,2026,'Datos Estandarizados'!$B$2:$B$195,$A9) -> 4 | N9: =M9-L9 -> -2 | O9: =IF(L9=0,"n/a",(M9-L9)/L9) -> -0.33333333
A10: Ingeniería | B10: =SUMIFS('Datos Estandarizados'!$F$2:$F$195,'Datos Estandarizados'!$A$2:$A$195,2025,'Datos Estandarizados'!$B$2:$B$195,$A10,'Datos Estandarizados'!$E$2:$E$195,"Brasil") -> 1 | C10: =SUMIFS('Datos Estandarizados'!$F$2:$F$195,'Datos Estandarizados'!$A$2:$A$195,2026,'Datos Estandarizados'!$B$2:$B$195,$A10,'Datos Estandarizados'!$E$2:$E$195,"Brasil") -> 0 | D10: =SUMIFS('Datos Estandarizados'!$F$2:$F$195,'Datos Estandarizados'!$A$2:$A$195,2025,'Datos Estandarizados'!$B$2:$B$195,$A10,'Datos Estandarizados'!$E$2:$E$195,"Chile") -> 42 | E10: =SUMIFS('Datos Estandarizados'!$F$2:$F$195,'Datos Estandarizados'!$A$2:$A$195,2026,'Datos Estandarizados'!$B$2:$B$195,$A10,'Datos Estandarizados'!$E$2:$E$195,"Chile") -> 54 | F10: =SUMIFS('Datos Estandarizados'!$F$2:$F$195,'Datos Estandarizados'!$A$2:$A$195,2025,'Datos Estandarizados'!$B$2:$B$195,$A10,'Datos Estandarizados'!$E$2:$E$195,"Perú") -> 18 | G10: =SUMIFS('Datos Estandarizados'!$F$2:$F$195,'Datos Estandarizados'!$A$2:$A$195,2026,'Datos Estandarizados'!$B$2:$B$195,$A10,'Datos Estandarizados'!$E$2:$E$195,"Perú") -> 17 | H10: =SUMIFS('Datos Estandarizados'!$F$2:$F$195,'Datos Estandarizados'!$A$2:$A$195,2025,'Datos Estandarizados'!$B$2:$B$195,$A10,'Datos Estandarizados'!$E$2:$E$195,"Rusia") -> 0 | I10: =SUMIFS('Datos Estandarizados'!$F$2:$F$195,'Datos Estandarizados'!$A$2:$A$195,2026,'Datos Estandarizados'!$B$2:$B$195,$A10,'Datos Estandarizados'!$E$2:$E$195,"Rusia") -> 0 | J10: =SUMIFS('Datos Estandarizados'!$F$2:$F$195,'Datos Estandarizados'!$A$2:$A$195,2025,'Datos Estandarizados'!$B$2:$B$195,$A10,'Datos Estandarizados'!$E$2:$E$195,"USA") -> 0 | K10: =SUMIFS('Datos Estandarizados'!$F$2:$F$195,'Datos Estandarizados'!$A$2:$A$195,2026,'Datos Estandarizados'!$B$2:$B$195,$A10,'Datos Estandarizados'!$E$2:$E$195,"USA") -> 2 | L10: =SUMIFS('Datos Estandarizados'!$F$2:$F$195,'Datos Estandarizados'!$A$2:$A$195,2025,'Datos Estandarizados'!$B$2:$B$195,$A10) -> 61 | M10: =SUMIFS('Datos Estandarizados'!$F$2:$F$195,'Datos Estandarizados'!$A$2:$A$195,2026,'Datos Estandarizados'!$B$2:$B$195,$A10) -> 73 | N10: =M10-L10 -> 12 | O10: =IF(L10=0,"n/a",(M10-L10)/L10) -> 0.19672131
A11: Total general | B11: =SUM(B6:B10) -> 4 | C11: =SUM(C6:C10) -> 3 | D11: =SUM(D6:D10) -> 55 | E11: =SUM(E6:E10) -> 76 | F11: =SUM(F6:F10) -> 21 | G11: =SUM(G6:G10) -> 30 | H11: =SUM(H6:H10) -> 0 | I11: =SUM(I6:I10) -> 1 | ... M11: =SUM(M6:M10) -> 113 | N11: =M11-L11 -> 32 | O11: =IF(L11=0,"n/a",(M11-L11)/L11) -> 0.39506173

Sheet Mapeo de Cargos
A1: Mapeo de Cargos Originales a Categorías Estandarizadas
A3: Año | B3: Cargo Original | C3: Categoría Estandarizada | D3: Evidencia / Nota
A4: 2026 | B4: Administración | C4: Administración | D4: Categoría ya estandarizada (usada tal cual en 2026).
A5: 2026 | B5: Comercial | C5: Comercial | D5: Categoría ya estandarizada (usada tal cual en 2026).
A6: 2026 | B6: Geomecánica | C6: Geomecánica | D6: Categoría nueva en 2026, sin equivalente explícito en 2025 (especialidad separada del área de Ingeniería).
A7: 2026 | B7: Gestión | C7: Gestión | D7: Categoría ya estandarizada (usada tal cual en 2026).
A8: 2026 | B8: Ingeniería | C8: Ingeniería | D8: Categoría ya estandarizada (usada tal cual en 2026).
A9: 2025 | B9: Aseo y Ornato | C9: Administración | D9: Semántico: función de servicios generales/soporte.
A10: 2025 | B10: Consultor Administración | C10: Administración | D10: Semántico: rol de consultoría administrativa.
A11: 2025 | B11: Contabilidad y Administración | C11: Administración | D11: Confirmado: Isabel Marchant -> Administración en 2026 (1/1 coincidencia).
A12: 2025 | B12: Country Manager | C12: Comercial | D12: Confirmado: Eduardo Lama -> Comercial en 2026 (1/1 coincidencia).
A13: 2025 | B13: Country Manager Brasil | C13: Comercial | D13: Sin coincidencia directa; se aplica mismo criterio que "Country Manager".
A14: 2025 | B14: Country Manager Rusia | C14: Comercial | D14: Confirmado: Olesya Dashavskaya -> Comercial en 2026 (1/1 coincidencia).
A15: 2025 | B15: Country Manager USA | C15: Comercial | D15: Nota: Patricio Vergara aparece como Ingeniería en 2026 (posible cambio de función); se mantiene Comercial por consistencia con el resto de "Country Manager".
... A29: 2025 | B29: Subgerente Comercial | C29: Comercial | D29: Confirmado: Pedro Aguiluz -> Comercial en 2026 (1/1 coincidencia).
A31: Nota metodológica: se usaron las 5 categorías ya presentes en "Dotación 2026" (Administración, Comercial, Geomecánica, Gestión, Ingeniería) como estándar. Los cargos granulares de 2025 se reclasificaron a estas 5 categorías cruzando nombres de personas presentes en ambos años (evidencia empírica) y, cuando no hubo coincidencia, aplicando criterio semántico del cargo. "Geomecánica" es una especialidad nueva en 2026 sin etiqueta propia en 2025 (estaba dentro de los cargos "Ingeniero *"), por lo que 2025 no tendrá headcount en esa categoría.

Sheet Datos Estandarizados
A1: Año | B1: Categoría Estandarizada | C1: Cargo Original | D1: Nombre | E1: País | F1: Headcount
A2: 2025 | B2: Administración | C2: Aseo y Ornato | D2: Aseo y Ornato | E2: Chile | F2: 1
A3: 2025 | B3: Administración | C3: Consultor Administración | D3: Alberto Reinao | E3: Chile | F3: 1
A4: 2025 | B4: Administración | C4: Contabilidad y Administración | D4: Isabel Marchant | E4: Chile | F4: 1
A5: 2025 | B5: Comercial | C5: Country Manager | D5: Eduardo Lama | E5: Perú | F5: 1
A6: 2025 | B6: Comercial | C6: Country Manager Brasil | D6: Isabela Camisassa | E6: Brasil | F6: 1
A7: 2025 | B7: Comercial | C7: Country Manager Rusia | D7: Olesya Dashavskaya | E7: Chile | F7: 1
A8: 2025 | B8: Comercial | C8: Country Manager USA | D8: Patricio Vergara | E8: USA | F8: 1
A9: 2025 | B9: Comercial | C9: Desarrollo de Negocios | D9: Maria Celia Fonseca | E9: Brasil | F9: 1
A10: 2025 | B10: Ingeniería | C10: Director de Proyecto | D10: Alex Figueroa | E10: Chile | F10: 1
A11: 2025 | B11: Ingeniería | C11: Director de Proyecto | D11: Carolina Arcos | E11: Chile | F11: 1
A12: 2025 | B12: Ingeniería | C12: Director de Proyecto | D12: Claudio Hernandez | E12: Chile | F12: 1
A13: 2025 | B13: Ingeniería | C13: Director de Proyecto | D13: Felipe Rojas | E13: Chile | F13: 1
... A195: 2026 | B195: Ingeniería | C195: Ingeniería | D195: Walter Lupinta | E195: Perú | F195: 1

Sheet Dotación 2026
A1: Etiquetas de fila | B1: Brasil | C1: Chile | D1: Perú | E1: Rusia | F1: USA
A2: Administración | B2: 2 | C2: 5 | D2: 1 | F2: 1
A3: Alejandra Montalván Aratia | D3: 1
A4: Cinthia Moreno | C4: 1
A5: Gladys Myriam Muñoz | C5: 1
A6: Isabel Marchant | C6: 1
A7: Karina Barrera (servicio contable) | F7: 1
A8: Magaly Esquivel | C8: 1
A9: María Célia P. Fonseca | B9: 1
A10: Nicélio José dos Santos | B10: 1
A11: Sandra Salazar (Reemplazo Gladys) | C11: 1
A12: Comercial | B12: 1 | C12: 6 | D12: 2 | E12: 1
A13: Alan Fraser | C13: 1
A14: Álvaro Soto Galaz | C14: 1
A15: Antonio Schettino | B15: 1
A16: Eduardo Lama | D16: 1
A17: Francisco Hizo | D17: 1
A18: Matías Gallardo Zapata | C18: 1
A19: Olesya Dashavskaya | E19: 1
A20: Pedro Aguiluz | C20: 1
A21: Practicante 1 | C21: 1
A22: Vicente Alberto Jiménez | C22: 1
A23: Geomecánica | C23: 8 | D23: 9
A24: Claudio Hernández | C24: 1
A25: Director de Proyecto | C25: 1
A26: Eduardo Cepeda | C26: 1
A27: Eduardo Morales | C27: 1
A28: Edward Torres | D28: 1
A29: Eugenio Santander | C29: 1
A30: Gersson Rivera | C30: 1
A31: Javier Salazar | C31: 1
A32: Joseph Livia | D32: 1
A33: Luis Flores | D33: 1
A34: Luiz Chumpitaz | D34: 1
A35: Maria Huaman | D35: 1
A36: Martin Robles | D36: 1
A37: Miguel Cuadros | D37: 1
A38: Nicolás Díaz | D38: 1
A39: Nicolas Diaz Ramos | D39: 1
A40: Victor Pacheco | C40: 1
...

Sheet Datación 2025
A1: Etiquetas de fila | B1: Brasil | C1: Chile | D1: Perú | E1: USA
A2: Aseo y Ornato | C2: 1
A3: Consultor Administración
A4: Alberto Reinao | C4: 1
A5: Contabilidad y Administración
A6: Isabel Marchant | C6: 1
A7: Country Manager
A8: Eduardo Lama | D8: 1
A9: Country Manager Brasil
A10: Isabela Camisassa | B10: 1
A11: Country Manager Rusia
A12: Olesya Dashavskaya | C12: 1
A13: Country Manager USA
A14: Patricio Vergara | E14: 1
A15: Desarrollo de Negocios
A16: Maria Celia Fonseca | B16: 1
A17: Director de Proyecto
A18: Alex Figueroa | C18: 1
A19: Carolina Arcos | C19: 1
A20: Claudio Hernandez | C20: 1
A21: Felipe Rojas | C21: 1
A22: Gonzalo Díaz | C22: 1
A23: Ricardo Miranda | C23: 1
A24: Ronald Leal | B24: 1
A25: Gerente Comercial
A26: Rodrigo Valdes | C26: 1
A27: Gerente General
A28: Enrique Rubio | C28: 1
A29: Gerentes
A30: Christian Caviedes | C30: 1
A31: Matias Fuentes | C31: 1
A32: Ingeniero de Proyecto
A33: Arnold Tadeo | D33: 1
A34: Cristian Alarcon | C34: 1
A35: Cristobal Ventura | C35: 1
A36: Daniela Oyarzo | C36: 1
A37: Darwin Varas | C37: 1
A38: Diego Muñoz | C38: 1
A39: Edward Torres | D39: 1
A40: Erick Sanhueza | C40: 1
...
