Workbook

Sheet Flujo Redco 2025 v1
B1: INGENIERÍA REDCO LTDA.
B3: 2025
B6: FLUJO EFECTIVO OPERACIONAL DE ENERO A DICIEMBRE 2025 | C6: REAL | D6: REAL | E6: ESTIMACION
B8: RESUMEN | C8: 45658 | D8: 45689 | E8: 45717
B9: SALDO CTA. CTE. INICIAL | C9: =SUM(C43+C44) -> 48703652 | D9: =SUM(D43+D44) -> 154486282 | E9: =SUM(E43+E44) -> 282096553
B10: INGRESOS OPERACIONALES | C10: =+C81 -> 382405283 | D10: =+D81 -> 615898051 | E10: =+E81 -> 251774915
B11: INGRESO NO OPERACIONAL (IVA DEBITO) | C11: =+C85 -> 73201311 | D11: =+D85 -> 97684687 | E11: =+E85 -> 47837233
B12: Rescate Fondos Mutuos
B13: Otros Ingresos No Operacioanles (dev.proveedor)
B14: Crédito Bco.Chile - Pmo. Redco Perú
B15: OTROS INGRESOS NO OPERACIONALES | C15: =+C99 -> 119395962 | D15: =+D99 -> 9692163 | E15: =+E99 -> -7470050
B16: TOTAL INGRESOS | C16: =SUM(C9:C15) -> 623706208 | D16: =SUM(D9:D15) -> 877761183 | E16: =SUM(E9:E15) -> 574238651
B18: SUELDOS OPERACIONALES | C18: =SUM(C167) -> 278812947 | D18: =SUM(D167) -> 205478739 | E18: =SUM(E167) -> 206804053
B19: HONORARIOS OPERACIONALES | C19: =SUM(C199) -> 28678785 | D19: =SUM(D199) -> 95836510 | E19: =SUM(E199) -> 18385968
B20: GASTOS OPERACIONALES | C20: =SUM(C261) -> 43582698 | D20: =SUM(D261) -> 32950339 | E20: =SUM(E261) -> 71518398
B21: ACTIVO FIJO- EQUIPOS COMPUTACIONALES | C21: =SUM(C266) -> 0 | D21: =SUM(D266) -> 9258153 | E21: =SUM(E266) -> 1400000
B22: TOTAL COSTOS OPERACIONALES | C22: =SUM(C18:C21) -> 3.5107443e+08 | D22: =SUM(D18:D21) -> 343523741 | E22: =SUM(E18:E21) -> 298108419
B23: SUELDOS ADMINISTRATIVOS | C23: =SUM(C280) -> 9731942 | D23: =SUM(D280) -> 35844455 | E23: =SUM(E280) -> 34501236
B24: GASTOS DE ADMINISTRACION | C24: =SUM(C306) -> 3572717 | D24: =SUM(D306) -> 15591695 | E24: =SUM(E306) -> 7866800
B25: TOTAL COSTO ADMINISTRATIVO | C25: =SUM(C23:C24) -> 13304659 | D25: =SUM(D23:D24) -> 51436150 | E25: =SUM(E23:E24) -> 42368036
B26: IMPUESTOS PPM-IVA-IMPTO.ADICIONAL | C26: =SUM(C314) -> 32600739 | D26: =SUM(D314) -> 58964333 | E26: =SUM(E314) -> 14300000
B27: CREDITOS BCO.CHILE | C27: =SUM(C320) -> 25722767 | D27: =SUM(D320) -> 25698938 | E27: =SUM(E320) -> 25750000
B28: GTOS. EXTRAORDINARIOS DIRECTOR REDCO | C28: =SUM(C327) -> 172475 | D28: =SUM(D327) -> 1220320 | E28: =SUM(E327) -> 1221063
B29: CTA.CTE. EERR | C29: =SUM(C337) -> 46257039 | D29: =SUM(D337) -> 114821148 | E29: =SUM(E337) -> 57713026
B30: TOTAL OTROS FLUJOS | C30: =SUM(C26:C29) -> 104753020 | D30: =SUM(D26:D29) -> 200704739 | E30: =SUM(E26:E29) -> 98984089
B32: TOTAL COSTOS Y FLUJOS ANUAL | C32: =SUM(C30,C25,C22) -> 4.6913211e+08 | D32: =SUM(D30,D25,D22) -> 595664630 | E32: =SUM(E30,E25,E22) -> 439460544
C33: =SUM(C339-C32) -> 0 | D33: =SUM(D339-D32) -> 0 | E33: =SUM(E339-E32) -> 0
B34: SALDO NETO FLUJO | C34: =SUM(C16-C32) -> 1.545741e+08 | D34: =SUM(D16-D32) -> 282096553 | E34: =SUM(E16-E32) -> 134778107
C35: =SUM(C34-C341) -> 0 | D35: =SUM(D34-D341) -> 0 | E35: =SUM(E34-E341) -> 0
C41: REAL | D41: REAL | E41: ESTIMACION
C42: 45658 | D42: 45689 | E42: 45717
B43: SDO.CTA.CTE. BCO. CHILE CLP 01-01-25 | C43: 48372971 | D43: =+C343 -> 59978095 | E43: =+D343 -> 201419874
B44: SDO.CTA.CTE. BCO. CHILE DOLARES 01-01-25 | C44: 330681 | D44: 94508187 | E44: =+D344 -> 80676679
B47: INGRESOS INGENIERÍA CHILE | C47: 45658 | D47: 45689 | E47: 45717
B48: CLIENTE | C48: MONTO $ | D48: MONTO $ | E48: MONTO $
B49: CPM Plan LOM Estabilizado. PFS UG y LINK LP del Valle; El Romeral | C49: 83858385
B50: CMP S.A. Estudio Implem. Mina UG-SLS en ROM y Consoli.LOM 2024 en CNN y MLC | C50: 82670896 | D50: =+'Facturas e Ingresos 2025'!E20+'Facturas e Ingresos 2025'!E28 -> 150942195 | E50: 44047733
B51: CMP S.A. Consolidación LOM 2024 en CNN y MLC | C51: 80377561
B52: CMP S.A. Analisis de Factibilidad Minera mejoras OP CNN y Desarr caso Exp | C52: 41976916 | D52: =+'Facturas e Ingresos 2025'!E31 -> 9265729
B53: CODELCO Servicio Opti. Sondajes para DRT mediante DRX- FACT. REDTEC | D53: =+'Facturas e Ingresos 2025'!I17 -> 43972803
...

Sheet Bono Anual 2024
K20: 151765177
K21: -3130000
K22: -2408000
K23: =SUM(K20:K22) -> 146227177

Sheet Resumen Flujo consolidado 
B2: CONTROL GESTION GLOBAL FLUJO CAJA
C3: 2025
C4: MUS$
B5: Flujos de efectivo procedentes de (utilizados en) actividades de operación
B6: Ingresos operacionales | C6: =+'Flujo Consolidado por mes'!L12 -> #REF! | E6: SALDOS CTAS.CTES. 21-03-2025
B7: Clases de pagos: | E7: EMPRESA | F7: US$ | G7: FFMM US$
B8: Pago Remuneraciones | C8: =-'Flujo Consolidado por mes'!L15 -> -2995748.8 | E8: REDCO CHILE | F8: 422165 | G8: 220817
B9: Pago servicios Externos | C9: =-'Flujo Consolidado por mes'!L16 -> -1085852.5 | E9: REDCO PERU | F9: 134500
B10: Pago viajes,ropa coorp., ases.gestión, int.bg | C10: =-'Flujo Consolidado por mes'!L17 -> -507164.32 | E10: REDCO BRASIL | F10: 158418
B11: Pagos Remuneraciones-otros R+ | C11: =-'Flujo Redco Chile'!#REF! -> #REF! | E11: REDCO USA | F11: 468406
B12: Pagos Remuneraciones-honorarios administración | E12: SUMA | F12: =SUM(F8:F11) -> 1183489
B13: Otras entradas de efectivo | C13: 0
B14: Flujos de efectivo netos procedentes de (utilizados en) actividades de operación | C14: =SUM(C5:C13) -> #REF! | D14: =SUM(C14/C6) -> #REF!
B16: Flujos de efectivo procedentes de (utilizados en) actividades de administración
B17: Gastos Administraticos | C17: =-'Flujo Consolidado por mes'!L23 -> -703088.83
B18: Compra activo fijo | C18: =-'Flujo Consolidado por mes'!L25 -> -134744.68
B19: Flujos de efectivo procedentes de (utilizados en) actividades de administración | C19: =SUM(C17:C18) -> -837833.51 | D19: =SUM(C19/C6)*-1 -> #REF!
B21: Flujos de efectivo netos procedentes de (utilizados en) actividades no operacionales | C21: =SUM(C14+C19) -> #REF! | D21: =SUM(C21/C6) -> #REF!
B23: Flujos de efectivo (utilizados en) procedentes de actividades de financiación
B24: Ingreso por devolución boleta garantía | C24: =+'Flujo Consolidado por mes'!L31 -> 21714.461
B25: Aporte FFMM | C25: =-'Flujo Redco Chile'!F48 -> 0
B26: Pagos de créditos | C26: =-'Flujo Redco Chile'!F45-'Flujo Redco Chile'!F46-'Flujo Redco Chile'!F47 -> -31866.891
B27: Ingresos recuperación gastos | C27: =+'Flujo Consolidado por mes'!L33 -> 695515.28
B28: Flujos de efectivo netos(utilizados en) procedentes de actividades de financiación | C28: =SUM(C24:C27) -> 685362.85
B30: Flujos de efectivo (utilizados en) procedentes de actividades empresas relacionadas RELACIONADAS
B31: Otras entradas facturación por cuenta Redtec | C31: =+'Flujo Redco Chile'!F32 -> 146563.3
B32: Ingresos cuenta corriente EERR (Redco Perú) | C32: =+'Flujo Redco Chile'!F35-'Flujo Redco Chile'!F55 -> 0
B33: Pago facturación Redtec | C33: =-'Flujo Redco Chile'!F53 -> -140964.71
B34: Egreso por cta. BVI | C34: =+'Flujo Redco Chile'!F36-'Flujo Redco Chile'!F52 -> -14882.192
B35: Ingresos cuenta corriente EERR (Redco USA) | C35: =-'Flujo Redco Chile'!F54+'Flujo Redco Chile'!F37 -> 0
B36: Flujos de efectivo (utilizados en) procedentes de actividades EERR | C36: =SUM(C31:C35) -> -9283.5998
B38: Ingresos por IVA (débito-crédito) | C38: =+'Flujo Consolidado por mes'!L30 -> 930965.53
B39: Egresos pago Imptos retenidos/Débito | C39: =-'Flujo Consolidado por mes'!L37 -> -826022.35
B40: Flujo positivo IVA Débito Fiscal | C40: =SUM(C38:C39) -> 104943.18
B42: Aumento neto de efectivo y equivalentes al efectivo | C42: =SUM(C14+C19+C28+C36+C40) -> #REF!
B43: Efectivo y equivalentes al efectivo al principio del período | C43: =+'Flujo Consolidado por mes'!L47 -> 253992.16
B44: Efectivo y equivalentes al efectivo al final del período 31-03-2025 | C44: =SUM(C42:C43) -> #REF!
C45: =SUM(C44-'Flujo Consolidado por mes'!L48) -> #REF!

Sheet Tabla Análisis (2)
A2: País | B2: (Todas)
A4: Suma de Monto | C4: Meses (Fecha)
A5: Categoría | B5: Detalle | C5: ene | D5: feb | E5: mar | F5: abr | G5: may | H5: jun | I5: jul | J5: ago | K5: sept | L5: oct | M5: nov | N5: dic | O5: Total general
A6: Operacional | C6: 55815.879 | D6: 41890.363 | E6: 48925.263 | F6: 65992.216 | G6: 58191.892 | H6: 75589.438 | I6: 52328.506 | J6: 104511.27 | K6: 79579.002 | L6: 104137.1 | M6: 41028.986 | N6: 77538.835 | O6: 805528.74
A7: Administración | C7: 12027.719 | D7: 22080.862 | E7: 21292.178 | F7: 30224.079 | G7: 13707.694 | H7: 24521.868 | I7: 25233.887 | J7: 32104.548 | K7: 21154.016 | L7: 19672.344 | M7: 18556.384 | N7: 20054.299 | O7: 260629.88
A8: REDTEC | C8: 9720 | D8: 2711 | E8: 9675 | F8: 17383 | G8: 11056 | H8: 8453 | I8: 7808 | J8: 6464 | K8: 9114 | L8: 13294 | M8: 13325 | N8: 21627 | O8: 130630
A9: REDCROSS | C9: 0 | D9: 13948.498 | E9: 13948.498 | F9: 13948.498 | G9: 13948.498 | H9: 13948.498 | I9: 13948.498 | J9: 13948.498 | K9: 13948.498 | L9: 0 | M9: 0 | N9: 0 | O9: 111587.98
A10: Total general | C10: 77563.598 | D10: 80630.722 | E10: 93840.939 | F10: 127547.79 | G10: 96904.084 | H10: 122512.8 | I10: 99318.892 | J10: 157028.31 | K10: 123795.52 | L10: 137103.44 | M10: 72910.37 | N10: 119220.13 | O10: 1308376.6
P13: =+N13-M13 -> 0
P15: =+N15-M15 -> 0
P16: =+N16-M16 -> 0
P17: =+N17-M17 -> 0
P19: =+N19-M19 -> 0
P22: =+N22-M22 -> 0
P23: =+N23-M23 -> 0
P24: =+N24-M24 -> 0
P29: =+N29-M29 -> 0
P30: =+N30-M30 -> 0
P31: =+N31-M31 -> 0
P33: =+N33-M33 -> 0
... P91: =+N91-M91 -> 0

Sheet Ppto vs Real_Nov
B1: TC | C1: 920
B3: Item 1 | C3: Descripción | D3: 45658 | E3: 45689 | F3: 45717 | G3: 45748 | H3: 45778 | I3: 45809 | J3: 45839 | K3: 45870 | L3: 45901 | M3: 45931 | N3: 45962 | O3: 45992 | P3: Total (KUS$)
B4: Resumen gastos | C4: Total gastos | D4: 688.03016 | E4: 472.25504 | F4: 437.9579 | G4: 351.0094 | H4: 522.76343 | I4: 394.83649 | J4: 526.62049 | K4: 538.31008 | L4: 383.77724 | M4: 519.01289 | N4: 452.20354 | O4: 681.06638 | P4: 5967.843 | Q4: 5967.843
B5: Chile | C5: Sub total 1 | D5: 476.29051 | E5: 313.31492 | F5: 275.86855 | G5: 231.52127 | H5: 317.17005 | I5: 288.14494 | J5: 292.12749 | K5: 299.21779 | L5: 267.60024 | M5: 356.05444 | N5: 318.27454 | O5: 334.87696 | P5: 3770.4617 | Q5: 0.63179639
B6: Peru | C6: Sub total 2 | D6: 167.14016 | E6: 109.66978 | F6: 119.90377 | G6: 98.13241 | H6: 125.25863 | I6: 82.824806 | J6: 139.674 | K6: 152.09422 | L6: 73.594 | M6: 88.14845 | N6: 112.788 | O6: 159.18262 | P6: 1428.4109 | Q6: 0.23935128
B7: Brasil | C7: Sub total 3 | D7: 44.59949 | E7: 49.27034 | F7: 12.37958 | G7: 21.355715 | H7: 46.92575 | I7: 15.35474 | J7: 23.351 | K7: 25.03507 | L7: 27.683 | M7: 42.455 | N7: 13.641 | O7: 36.3368 | P7: 358.38748 | Q7: 0.060053102
B8: EEUU | C8: Sub total 4 | D8: 0 | E8: 0 | F8: 29.806 | G8: 0 | H8: 33.409 | I8: 8.512 | J8: 71.468 | K8: 61.963 | L8: 14.9 | M8: 32.355 | N8: 7.5 | O8: 150.67 | P8: 410.583 | Q8: 0.068799229
B11: Item 2 | C11: Descripción | D11: ene-25 | E11: feb-25 | F11: mar-25 | G11: abr-25 | H11: may-25 | I11: jun-25 | J11: jul-25 | K11: ago-25 | L11: sept-25 | M11: oct-25 | N11: nov-25 | O11: dic-25 | P11: Total (KUS$)
B12: Sueldo | C12: REDCO | D12: 231.52655 | E12: 238.52655 | F12: 245.02655 | G12: 245.02655 | H12: 278.82421 | I12: 259.58655 | J12: 316.80787 | K12: 264.00655 | L12: 264.00655 | M12: 264.00655 | N12: 290.40721 | O12: 316.80787 | P12: 3214.5596
B13: Sueldo | C13: REDCROSS | D13: 22.138493 | E13: 22.138493 | F13: 22.138493 | G13: 22.138493 | H13: 22.138493 | I13: 22.138493 | J13: 22.138493 | K13: 22.138493 | L13: 22.138493 | M13: 22.138493 | N13: 22.138493 | O13: 22.138493 | P13: 265.66192
B14: Sueldo | C14: R+ | D14: 68.529744 | E14: 75.029744 | F14: 75.029744 | G14: 88.679744 | H14: 88.679744 | I14: 88.679744 | J14: 88.679744 | K14: 88.679744 | L14: 88.679744 | M14: 88.679744 | N14: 88.679744 | O14: 88.679744 | P14: 1016.7069
B15: Sueldo | C15: REDTEC | D15: 8.964027 | E15: 8.964027 | F15: 8.964027 | G15: 8.964027 | H15: 9.8604297 | I15: 8.964027 | J15: 10.756832 | K15: 8.964027 | L15: 8.964027 | M15: 8.964027 | N15: 9.8604297 | O15: 10.756832 | P15: 112.94674
B16: Sueldo | C16: Bonos | D16: 200 | E16: 0 | F16: 0 | G16: 0 | H16: 0 | I16: 0 | J16: 0 | K16: 0 | L16: 0 | M16: 0 | N16: 0 | O16: 0 | P16: 200
B17: Externo | C17: Servicios | D17: 52.9 | E17: 52.9 | F17: 52.9 | G17: 52.9 | H17: 52.9 | I17: 52.9 | J17: 52.9 | K17: 52.9 | L17: 52.9 | M17: 52.9 | N17: 52.9 | O17: 52.9 | P17: 634.8
B18: Operacional | C18: Cumplimiento Legal | D18: 0.2173913 | E18: 0.2173913 | F18: 0.2173913 | G18: 0.2173913 | H18: 0.2173913 | I18: 0.2173913 | J18: 0.2173913 | K18: 0.2173913 | L18: 0.2173913 | M18: 0.2173913 | N18: 0.2173913 | O18: 0.2173913 | P18: 2.6086957
B19: Operacional | C19: Servicios personal | D19: 5.4347826 | E19: 0.2173913 | F19: 0 | G19: 0 | H19: 0.2173913 | I19: 0 | J19: 0 | K19: 0.2173913 | L19: 0 | M19: 0 | N19: 5.6521739 | O19: 0 | P19: 11.73913
B20: Operacional | C20: Reclutamiento | D20: 5 | E20: 0 | F20: 0 | G20: 0 | H20: 0 | I20: 0 | J20: 0 | K20: 0 | L20: 0 | M20: 0 | N20: 0 | O20: 0 | P20: 5
B21: Operacional | C21: Capacitación | D21: 0 | E21: 15 | F21: 15 | G21: 0 | H21: 0 | I21: 15 | J21: 0 | K21: 0 | L21: 0 | M21: 15 | N21: 0 | O21: 0 | P21: 60
B22: Operacional | C22: Recompensas | D22: 0 | E22: 0 | F22: 5 | G22: 0 | H22: 0 | I22: 5 | J22: 0 | K22: 0 | L22: 5 | M22: 0 | N22: 0 | O22: 5 | P22: 20
B23: Operacional | C23: Bienestar | D23: 4 | E23: 0.28804348 | F23: 0.50543478 | G23: 0.72282609 | H23: 0.28804348 | I23: 0.28804348 | J23: 0.72282609 | K23: 10.61413 | L23: 0.28804348 | M23: 0.72282609 | N23: 0.28804348 | O23: 3.0054348 | P23: 21.733696
... B60: Operacional | C60: Eventos | D60: 5.8 | E60: 5.8 | F60: 5.8 | G60: 5.8 | H60: 5.8 | I60: 5.8 | J60: 5.8 | K60: 5.8 | L60: 5.8 | M60: 5.8 | N60: 5.8 | O60: 5.8 | P60: 69.6
B62: Resumen gastos | C62: Total gastos | D62: 45658 | E62: 45689 | F62: 45717 | G62: 45748 | H62: 45778 | I62: 45809 | J62: 45839 | K62: 45870 | L62: 45901 | M62: 45931 | N62: 45962 | O62: 45992 | P62: Total (kUS$) | Q62: Distribución
B63: Resumen gastos | C63: Total gastos | D63: 695.28316 | E63: 507.61468 | F63: 519.11468 | G63: 514.39511 | H63: 547.45874 | I63: 547.10729 | J63: 590.31705 | K63: 542.07076 | L63: 536.52729 | M63: 550.87511 | N63: 564.47652 | O63: 593.83879 | P63: 6709.0792 | Q63: 1
B64: Chile | C64: Sub total 1 | D64: 439.27739 | E64: 320.70912 | F64: 327.97478 | G64: 324.99298 | H64: 345.88245 | I64: 345.66041 | J64: 372.96019 | K64: 342.47835 | L64: 338.976 | M64: 348.04091 | N64: 356.63423 | O64: 375.18521 | P64: 4238.772 | Q64: 0.63179639
B65: Peru | C65: Sub total 2 | D65: 166.41691 | E65: 121.49822 | F65: 124.25076 | G65: 123.12113 | H65: 131.03495 | I65: 130.95083 | J65: 141.29314 | K65: 129.74533 | L65: 128.41849 | M65: 131.85266 | N65: 135.10818 | O65: 142.13607 | P65: 1605.8267 | Q65: 0.23935128
B66: Brasil | C66: Sub total 3 | D66: 41.75391 | E66: 30.483836 | F66: 31.174446 | G66: 30.891022 | H66: 32.876595 | I66: 32.855489 | J66: 35.45037 | K66: 32.553031 | L66: 32.220128 | M66: 33.081759 | N66: 33.898566 | O66: 35.661861 | P66: 402.90101 | Q66: 0.060053102
B67: EEUU | C67: Sub total 4 | D67: 47.834945 | E67: 34.923498 | F67: 35.71469 | G67: 35.389987 | H67: 37.664739 | I67: 37.640559 | J67: 40.613358 | K67: 37.294051 | L67: 36.912664 | M67: 37.899783 | N67: 38.835549 | O67: 40.855651 | P67: 461.57947 | Q67: 0.068799229
B69: Resumen gastos | C69: Total gastos | D69: 45658 | E69: 45689 | F69: 45717 | G69: 45748 | H69: 45778 | I69: 45809 | J69: 45839 | K69: 45870 | L69: 45901 | M69: 45931 | N69: 45962 | O69: 45992 | P69: Total (kUS$) | Q69: Distribución
B70: Resumen gastos | C70: Total gastos | D70: 695.28316 | E70: 507.61468 | F70: 519.11468 | G70: 514.39511 | H70: 547.45874 | I70: 547.10729 | J70: 590.31705 | K70: 542.07076 | L70: 536.52729 | M70: 550.87511 | N70: 564.47652 | O70: 593.83879 | P70: 6709.0792 | Q70: 1
B71: Sueldos | C71: Sub total 1 | D71: 531.15882 | E71: 344.65882 | F71: 351.15882 | G71: 364.80882 | H71: 399.50288 | I71: 379.36882 | J71: 438.38294 | K71: 383.78882 | L71: 383.78882 | M71: 383.78882 | N71: 411.08588 | O71: 438.38294 | P71: 4809.8752 | Q71: 0.71692032
B72: Impuestos | C72: Sub total 2 | D72: 0 | E72: 0 | F72: 0 | G72: 0 | H72: 0 | I72: 0 | J72: 0 | K72: 0 | L72: 0 | M72: 0 | N72: 0 | O72: 0 | P72: 0 | Q72: 0
B73: Oficina | C73: Sub total 3 | D73: 52.11 | E73: 51.61 | F73: 51.61 | G73: 51.61 | H73: 51.61 | I73: 51.61 | J73: 52.11 | K73: 51.61 | L73: 51.61 | M73: 51.61 | N73: 51.61 | O73: 51.61 | P73: 620.32 | Q73: 0.092459782
B74: RRHH | C74: Sub total 4 | D74: 19.891304 | E74: 19.222826 | F74: 24.222826 | G74: 5.8532609 | H74: 4.2228261 | I74: 24.005435 | J74: 7.701087 | K74: 14.548913 | L74: 9.0054348 | M74: 23.353261 | N74: 9.6576087 | O74: 11.722826 | P74: 173.40761 | Q74: 0.025846708
B75: Externo | C75: Sub total 5 | D75: 52.9 | E75: 52.9 | F75: 52.9 | G75: 52.9 | H75: 52.9 | I75: 52.9 | J75: 52.9 | K75: 52.9 | L75: 52.9 | M75: 52.9 | N75: 52.9 | O75: 52.9 | P75: 634.8 | Q75: 0.094618052
B76: Viajes | C76: Sub total 6 | D76: 12 | E76: 12 | F76: 12 | G76: 12 | H76: 12 | I76: 12 | J76: 12 | K76: 12 | L76: 12 | M76: 12 | N76: 12 | O76: 12 | P76: 144 | Q76: 0.021463452
B77: Otros | C77: Sub total 7 | D77: 19.423033 | E77: 19.423033 | F77: 19.423033 | G77: 19.423033 | H77: 19.423033 | I77: 19.423033 | J77: 19.423033 | K77: 19.423033 | L77: 19.423033 | M77: 19.423033 | N77: 19.423033 | O77: 19.423033 | P77: 233.07639 | Q77: 0.034740444
B78: Comercial | C78: Sub total 8 | D78: 7.8 | E78: 7.8 | F78: 7.8 | G78: 7.8 | H78: 7.8 | I78: 7.8 | J78: 7.8 | K78: 7.8 | L78: 7.8 | M78: 7.8 | N78: 7.8 | O78: 7.8 | P78: 93.6 | Q78: 0.013951244
B83: Resumen gastos | C83: Total (kUS$)
B84: Resumen gastos | C84: 6709.0792
B85: Sueldos | C85: 4809.8752
...

Sheet Tabla datos unidades_Dic
L1: 6853202.5 | M1: =+L10-L1 -> 73593.425 | N1: =+M1/L10 -> 0.010624454 | Q1: =+P6*0.2 -> 319418.44
J2: =+J17/1000 -> 641.80299 | K2: =+K17/1000 -> 678.99571 | L2: =+L17/1000 -> 666.97613 | M2: =+M17/1000 -> 729.50446 | N2: =+N17/1000 -> 586.01155 | O2: =+O17/1000 -> 976.72234
B3: País | C3: Concepto | D3: 45658 | E3: 45689 | F3: 45717 | G3: 45748 | H3: 45778 | I3: 45809 | J3: 45839 | K3: 45870 | L3: 45901 | M3: 45931 | N3: 45962 | O3: 45992 | P3: Total | R3: País | S3: Concepto | T3: 45658
B4: Chile | C4: INGRESOS OP | D4: =+'Flujo Redco Chile'!C12 -> 362362.73 | E4: =+'Flujo Redco Chile'!D12 -> 547310.62 | F4: =+'Flujo Redco Chile'!E12 -> 389727.46 | G4: =+'Flujo Redco Chile'!F12 -> 237434.48 | H4: =+'Flujo Redco Chile'!G12 -> 272631.08 | I4: =+'Flujo Redco Chile'!H12 -> 277419.07 | J4: =+'Flujo Redco Chile'!I12 -> 475570.75 | K4: =+'Flujo Redco Chile'!J12 -> 151482.74 | ... O4: =+'Flujo Redco Chile'!N12 -> 173207.55 | P4: =SUM(D4:O4) -> 3592126.9 | Q4: =+P4/$P$9 -> 0.39255574 | R4: Chile | S4: SALDO INICIAL | T4: =+'Flujo Redco Chile'!C8 -> 52257.137
B5: Perú | C5: INGRESOS OP | D5: =+'Flujo Redco Perú'!C13 -> 123848 | E5: =+'Flujo Redco Perú'!D13 -> 62454 | F5: =+'Flujo Redco Perú'!E13 -> 105377 | G5: =+'Flujo Redco Perú'!F13 -> 110077 | H5: =+'Flujo Redco Perú'!G13 -> 142610 | I5: =+'Flujo Redco Perú'!H13 -> 229588 | J5: =+'Flujo Redco Perú'!I13 -> 251702 | K5: =+'Flujo Redco Perú'!J13 -> 641573 | ... O5: =+'Flujo Redco Perú'!N13 -> 269432 | P5: =SUM(D5:O5) -> 2417353 | Q5: =+P5/$P$9 -> 0.26417379 | R5: Perú | S5: SALDO INICIAL | T5: =+'Flujo Redco Perú'!C9 -> 136767.69
B6: Brasil | C6: INGRESOS OP | D6: =+'Flujo Redco Brasil'!C14 -> 80502 | E6: =+'Flujo Redco Brasil'!D14 -> 59683 | F6: =+'Flujo Redco Brasil'!E14 -> 96322 | G6: =+'Flujo Redco Brasil'!F14 -> 97209.7 | H6: =+'Flujo Redco Brasil'!G14 -> 37074 | I6: =+'Flujo Redco Brasil'!H14 -> 66563 | J6: =+'Flujo Redco Brasil'!I14 -> 47717 | K6: =+'Flujo Redco Brasil'!J14 -> 119652 | ... O6: =+'Flujo Redco Brasil'!N14 -> 224116.51 | P6: =SUM(D6:O6) -> 1597092.2 | Q6: =+P6/$P$9 -> 0.17453384 | R6: Brasil | S6: SALDO INICIAL | T6: =+'Flujo Redco Brasil'!C9 -> 9622.33
B7: USA | C7: INGRESOS OP | D7: =+'Flujo Redco USA'!C13 -> 150453 | E7: =+'Flujo Redco USA'!D13 -> 243465.21 | F7: =+'Flujo Redco USA'!E13 -> 141526 | G7: =+'Flujo Redco USA'!F13 -> 169200 | H7: =+'Flujo Redco USA'!G13 -> 195090 | I7: =+'Flujo Redco USA'!H13 -> 61796 | J7: =+'Flujo Redco USA'!I13 -> 0 | K7: =+'Flujo Redco USA'!J13 -> 20000 | ... O7: =+'Flujo Redco USA'!N13 -> 178785 | P7: =SUM(D7:O7) -> 1205315.2 | Q7: =+P7/$P$9 -> 0.13171957 | R7: USA | S7: SALDO INICIAL | T7: =+'Flujo Redco USA'!C9 -> 55345
B8: Otros | C8: INGRESOS OP | D8: =+'Flujo Redco BVI'!C13 -> 0 | E8: =+'Flujo Redco BVI'!D13 -> 21682 | F8: =+'Flujo Redco BVI'!E13 -> 45478 | G8: =+'Flujo Redco BVI'!F13 -> 0 | H8: =+'Flujo Redco BVI'!G13 -> 0 | I8: =+'Flujo Redco BVI'!H13 -> 172045 | J8: =+'Flujo Redco BVI'!I13 -> 0 | K8: =+'Flujo Redco BVI'!J13 -> 99524 | ... O8: =+'Flujo Redco BVI'!N13 -> 0 | P8: =SUM(D8:O8) -> 338729 | Q8: =+P8/$P$9 -> 0.037017069 | R8: BVI | S8: SALDO INICIAL | T8: =+'Flujo Redco BVI'!S13 -> 0
B9: TOTAL | C9: INGRESOS OP | D9: =SUM(D4:D8) -> 717165.73 | E9: =SUM(E4:E8) -> 934594.83 | F9: =SUM(F4:F8) -> 778430.46 | G9: =SUM(G4:G8) -> 613921.18 | H9: =SUM(H4:H8) -> 647405.08 | I9: =SUM(I4:I8) -> 807411.07 | J9: =SUM(J4:J8) -> 774989.75 | K9: =SUM(K4:K8) -> 1032231.7 | ... P9: =SUM(P4:P8) -> 9150616.3 | R9: CAJA FINAL | S9: CAJA FINAL | T9: =SUM(T4:T8) -> 253992.16
C10: INGRESOS OP ACUM | D10: =+SUM($D$9:D9) -> 717165.73 | E10: =+SUM($D$9:E9) -> 1651760.6 | F10: =+SUM($D$9:F9) -> 2430191 | G10: =+SUM($D$9:G9) -> 3044112.2 | H10: =+SUM($D$9:H9) -> 3691517.3 | I10: =+SUM($D$9:I9) -> 4498928.4 | J10: =+SUM($D$9:J9) -> 5273918.1 | K10: =+SUM($D$9:K9) -> 6306149.8 | ... O10: =+SUM($D$9:O9) -> 9150616.3
B11: País | C11: Concepto | D11: 45658 | E11: 45689 | F11: 45717 | G11: 45748 | H11: 45778 | I11: 45809 | J11: 45839 | K11: 45870 | L11: 45901 | M11: 45931 | N11: 45962 | O11: 45992 | P11: Total
B12: Chile | C12: COSTOS OP | D12: =+'Flujo Redco Chile'!C18+'Flujo Redco Chile'!C23+'Flujo Redco Chile'!C25 -> 397276.65 | E12: =+'Flujo Redco Chile'!D18+'Flujo Redco Chile'!D23+'Flujo Redco Chile'!D25 -> 422126.64 | F12: =+'Flujo Redco Chile'!E18+'Flujo Redco Chile'!E23+'Flujo Redco Chile'!E25 -> 439899.18 | G12: =+'Flujo Redco Chile'!F18+'Flujo Redco Chile'!F23+'Flujo Redco Chile'!F25 -> 341507.35 | H12: =+'Flujo Redco Chile'!G18+'Flujo Redco Chile'!G23+'Flujo Redco Chile'!G25 -> 340134.8 | I12: =+'Flujo Redco Chile'!H18+'Flujo Redco Chile'!H23+'Flujo Redco Chile'!H25 -> 380566.17 | J12: =+'Flujo Redco Chile'!I18+'Flujo Redco Chile'!I23+'Flujo Redco Chile'!I25 -> 395727.19 | K12: =+'Flujo Redco Chile'!J18+'Flujo Redco Chile'!J23+'Flujo Redco Chile'!J25 -> 425248.91 | ... O12: =+'Flujo Redco Chile'!N18+'Flujo Redco Chile'!N23+'Flujo Redco Chile'!N25 -> 495505.54 | P12: =SUM(D12:O12) -> 4999267.5
B13: Perú | C13: COSTOS OP | D13: =+'Flujo Redco Perú'!C19+'Flujo Redco Perú'!C26+'Flujo Redco Perú'!C28 -> 89462.85 | E13: =+'Flujo Redco Perú'!D19+'Flujo Redco Perú'!D26+'Flujo Redco Perú'!D28 -> 81597 | F13: =+'Flujo Redco Perú'!E19+'Flujo Redco Perú'!E26+'Flujo Redco Perú'!E28 -> 92755 | G13: =+'Flujo Redco Perú'!F19+'Flujo Redco Perú'!F26+'Flujo Redco Perú'!F28 -> 137672.3 | H13: =+'Flujo Redco Perú'!G19+'Flujo Redco Perú'!G26+'Flujo Redco Perú'!G28 -> 128924 | I13: =+'Flujo Redco Perú'!H19+'Flujo Redco Perú'!H26+'Flujo Redco Perú'!H28 -> 167995 | J13: =+'Flujo Redco Perú'!I19+'Flujo Redco Perú'!I26+'Flujo Redco Perú'!I28 -> 199355 | K13: =+'Flujo Redco Perú'!J19+'Flujo Redco Perú'!J26+'Flujo Redco Perú'!J28 -> 225572 | ... O13: =+'Flujo Redco Perú'!N19+'Flujo Redco Perú'!N26+'Flujo Redco Perú'!N28 -> 234121 | P13: =SUM(D13:O13) -> 1731862.8
B14: Brasil | C14: COSTOS OP | D14: =+'Flujo Redco Brasil'!C20+'Flujo Redco Brasil'!C25+'Flujo Redco Brasil'!C27 -> 21023 | E14: =+'Flujo Redco Brasil'!D20+'Flujo Redco Brasil'!D25+'Flujo Redco Brasil'!D27 -> 27812 | F14: =+'Flujo Redco Brasil'!E20+'Flujo Redco Brasil'!E25+'Flujo Redco Brasil'!E27 -> 26425 | G14: =+'Flujo Redco Brasil'!F20+'Flujo Redco Brasil'!F25+'Flujo Redco Brasil'!F27 -> 52004.4 | H14: =+'Flujo Redco Brasil'!G20+'Flujo Redco Brasil'!G25+'Flujo Redco Brasil'!G27 -> 33329 | I14: =+'Flujo Redco Brasil'!H20+'Flujo Redco Brasil'!H25+'Flujo Redco Brasil'!H27 -> 76286 | J14: =+'Flujo Redco Brasil'!I20+'Flujo Redco Brasil'!I25+'Flujo Redco Brasil'!I27 -> 31019 | K14: =+'Flujo Redco Brasil'!J20+'Flujo Redco Brasil'!J25+'Flujo Redco Brasil'!J27 -> 21475 | ... O14: =+'Flujo Redco Brasil'!N20+'Flujo Redco Brasil'!N25+'Flujo Redco Brasil'!N27 -> 23001 | P14: =SUM(D14:O14) -> 451717.4
B15: USA | C15: COSTOS OP | D15: =+'Flujo Redco USA'!C19+'Flujo Redco USA'!C27+'Flujo Redco USA'!C29 -> 15 | E15: =+'Flujo Redco USA'!D19+'Flujo Redco USA'!D27+'Flujo Redco USA'!D29 -> 2025 | F15: =+'Flujo Redco USA'!E19+'Flujo Redco USA'!E27+'Flujo Redco USA'!E29 -> 58728 | G15: =+'Flujo Redco USA'!F19+'Flujo Redco USA'!F27+'Flujo Redco USA'!F29 -> 9898 | H15: =+'Flujo Redco USA'!G19+'Flujo Redco USA'!G27+'Flujo Redco USA'!G29 -> 47666 | I15: =+'Flujo Redco USA'!H19+'Flujo Redco USA'!H27+'Flujo Redco USA'!H29 -> 4178 | J15: =+'Flujo Redco USA'!I19+'Flujo Redco USA'!I27+'Flujo Redco USA'!I29 -> 10017 | K15: =+'Flujo Redco USA'!J19+'Flujo Redco USA'!J27+'Flujo Redco USA'!J29 -> 1015 | ... O15: =+'Flujo Redco USA'!N19+'Flujo Redco USA'!N27+'Flujo Redco USA'!N29 -> 218410 | P15: =SUM(D15:O15) -> 442363
B16: Otros | C16: COSTOS OP | D16: =+'Flujo Redco BVI'!C19+'Flujo Redco BVI'!C27+'Flujo Redco BVI'!C29 -> 14044 | E16: =+'Flujo Redco BVI'!D19+'Flujo Redco BVI'!D27+'Flujo Redco BVI'!D29 -> 0 | F16: =+'Flujo Redco BVI'!E19+'Flujo Redco BVI'!E27+'Flujo Redco BVI'!E29 -> 0 | G16: =+'Flujo Redco BVI'!F19+'Flujo Redco BVI'!F27+'Flujo Redco BVI'!F29 -> 14380 | H16: =+'Flujo Redco BVI'!G19+'Flujo Redco BVI'!G27+'Flujo Redco BVI'!G29 -> 16000 | I16: =+'Flujo Redco BVI'!H19+'Flujo Redco BVI'!H27+'Flujo Redco BVI'!H29 -> 15094 | J16: =+'Flujo Redco BVI'!I19+'Flujo Redco BVI'!I27+'Flujo Redco BVI'!I29 -> 5684.8 | K16: =+'Flujo Redco BVI'!J19+'Flujo Redco BVI'!J27+'Flujo Redco BVI'!J29 -> 5684.8 | ... O16: =+'Flujo Redco BVI'!N19+'Flujo Redco BVI'!N27+'Flujo Redco BVI'!N29 -> 5684.8 | P16: =SUM(D16:O16) -> 93626.8
B17: TOTAL | C17: COSTOS OP | D17: =SUM(D12:D16) -> 521821.5 | E17: =SUM(E12:E16) -> 533560.64 | F17: =SUM(F12:F16) -> 617807.18 | G17: =SUM(G12:G16) -> 555462.05 | H17: =SUM(H12:H16) -> 566053.8 | I17: =SUM(I12:I16) -> 644119.17 | J17: =SUM(J12:J16) -> 641802.99 | K17: =SUM(K12:K16) -> 678995.71 | ... O17: =SUM(O12:O16) -> 976722.34 | P17: =SUM(D17:O17) -> 7718837.5
C18: COSTOS OP ACUM | D18: =+SUM($D$17:D17) -> 521821.5 | E18: =+SUM($D$17:E17) -> 1055382.1 | F18: =+SUM($D$17:F17) -> 1673189.3 | G18: =+SUM($D$17:G17) -> 2228651.4 | H18: =+SUM($D$17:H17) -> 2794705.2 | I18: =+SUM($D$17:I17) -> 3438824.3 | J18: =+SUM($D$17:J17) -> 4080627.3 | K18: =+SUM($D$17:K17) -> 4759623 | ... O18: =+SUM($D$17:O17) -> 7718837.5
B19: País | C19: Concepto | D19: 45658 | E19: 45689 | F19: 45717 | G19: 45748 | H19: 45778 | I19: 45809 | J19: 45839 | K19: 45870 | L19: 45901 | M19: 45931 | N19: 45962 | O19: 45992 | P19: Total
B20: Chile | C20: RESULTADO OP. | D20: =+D4-D12 -> -34913.914 | E20: =+E4-E12 -> 125183.98 | F20: =+F4-F12 -> -50171.722 | G20: =+G4-G12 -> -104072.86 | H20: =+H4-H12 -> -67503.719 | I20: =+I4-I12 -> -103147.1 | J20: =+J4-J12 -> 79843.563 | K20: =+K4-K12 -> -273766.17 | ... O20: =+O4-O12 -> -322297.98 | P20: =SUM(D20:O20) -> -1407140.6
B21: Perú | C21: RESULTADO OP. | D21: =+D5-D13 -> 34385.15 | E21: =+E5-E13 -> -19143 | F21: =+F5-F13 -> 12622 | G21: =+G5-G13 -> -27595.3 | H21: =+H5-H13 -> 13686 | I21: =+I5-I13 -> 61593 | J21: =+J5-J13 -> 52347 | K21: =+K5-K13 -> 416001 | ... O21: =+O5-O13 -> 35311 | P21: =SUM(D21:O21) -> 685490.21
B22: Brasil | C22: RESULTADO OP. | D22: =+D6-D14 -> 59479 | E22: =+E6-E14 -> 31871 | F22: =+F6-F14 -> 69897 | G22: =+G6-G14 -> 45205.3 | H22: =+H6-H14 -> 3745 | I22: =+I6-I14 -> -9723 | J22: =+J6-J14 -> 16698 | K22: =+K6-K14 -> 98177 | ... O22: =+O6-O14 -> 201115.51 | P22: =SUM(D22:O22) -> 1145374.8
B23: USA | C23: RESULTADO OP. | D23: =+D7-D15 -> 150438 | E23: =+E7-E15 -> 241440.21 | F23: =+F7-F15 -> 82798 | G23: =+G7-G15 -> 159302 | H23: =+H7-H15 -> 147424 | I23: =+I7-I15 -> 57618 | J23: =+J7-J15 -> -10017 | K23: =+K7-K15 -> 18985 | ... O23: =+O7-O15 -> -39625 | P23: =SUM(D23:O23) -> 762952.21
B24: Otros | C24: RESULTADO OP. | D24: =+D8-D16 -> -14044 | E24: =+E8-E16 -> 21682 | F24: =+F8-F16 -> 45478 | G24: =+G8-G16 -> -14380 | H24: =+H8-H16 -> -16000 | I24: =+I8-I16 -> 156951 | J24: =+J8-J16 -> -5684.8 | K24: =+K8-K16 -> 93839.2 | ... O24: =+O8-O16 -> -5684.8 | P24: =SUM(D24:O24) -> 245102.2
B25: TOTAL | C25: RESULTADO OP. | D25: =SUM(D20:D24) -> 195344.24 | E25: =SUM(E20:E24) -> 401034.19 | F25: =SUM(F20:F24) -> 160623.28 | G25: =SUM(G20:G24) -> 58459.138 | H25: =SUM(H20:H24) -> 81351.281 | I25: =SUM(I20:I24) -> 163291.9 | J25: =SUM(J20:J24) -> 133186.76 | K25: =SUM(K20:K24) -> 353236.03 | ... P25: =SUM(P20:P24) -> 1431778.8
D26: =+SUM($D$25:D25) -> 195344.24 | E26: =+SUM($D$25:E25) -> 596378.43 | F26: =+SUM($D$25:F25) -> 757001.71 | G26: =+SUM($D$25:G25) -> 815460.84 | H26: =+SUM($D$25:H25) -> 896812.13 | I26: =+SUM($D$25:I25) -> 1060104 | J26: =+SUM($D$25:J25) -> 1193290.8 | K26: =+SUM($D$25:K25) -> 1546526.8 | ... O26: =+SUM($D$25:O25) -> 1431778.8
B27: País | C27: Concepto | D27: 45658 | E27: 45689 | F27: 45717 | G27: 45748 | H27: 45778 | I27: 45809 | J27: 45839 | K27: 45870 | L27: 45901 | M27: 45931 | N27: 45962 | O27: 45992 | P27: Total
B28: Chile | C28: INGRESO IVA DEBITO | D28: =+'Flujo Redco Chile'!C31 -> 69432.94 | E28: =+'Flujo Redco Chile'!D31 -> 104811.9 | F28: =+'Flujo Redco Chile'!E31 -> 75208.024 | G28: =+'Flujo Redco Chile'!F31 -> 47094.724 | H28: =+'Flujo Redco Chile'!G31 -> 62773.513 | I28: =+'Flujo Redco Chile'!H31+'Flujo Redco Chile'!H34 -> 53789.215 | J28: =+'Flujo Redco Chile'!I31 -> 103658.78 | K28: =+'Flujo Redco Chile'!J31 -> 35825.605 | L28: =+'Flujo Redco Chile'!K31 -> 57280.832 | M28: =+'Flujo Redco Chile'!L31 -> 32498.942 | N28: =+'Flujo Redco Chile'!M31 -> 37753.16 | O28: =+'Flujo Redco Chile'!N31 -> 32909.433 | P28: =SUM(D28:O28) -> 713037.07
B29: Perú | C29: INGRESO IVA DEBITO | D29: =+'Flujo Redco Perú'!C35 -> 11907 | E29: =+'Flujo Redco Perú'!D35 -> 16500 | F29: =+'Flujo Redco Perú'!E35 -> 20068 | G29: =+'Flujo Redco Perú'!F35 -> 28529 | H29: =+'Flujo Redco Perú'!G35 -> 31304 | I29: =+'Flujo Redco Perú'!H35 -> 36127 | J29: =+'Flujo Redco Perú'!I35 -> 34183 | K29: =+'Flujo Redco Perú'!J35 -> 126435 | ... O29: =+'Flujo Redco Perú'!N35 -> 75885 | P29: =SUM(D29:O29) -> 544185
B30: Chile | C30: OTROS INGRESOS | D30: =+'Flujo Redco Chile'!C38+'Flujo Redco Chile'!C39+'Flujo Redco Chile'!E42+'Flujo Redco Chile'!C34 -> 703.28541 | E30: =+'Flujo Redco Chile'!D38+'Flujo Redco Chile'!D39+'Flujo Redco Chile'!D34 -> 10399.317 | F30: =+'Flujo Redco Chile'!E38+'Flujo Redco Chile'!E39+'Flujo Redco Chile'!E34 -> 5265.8026 | G30: =+'Flujo Redco Chile'!F38+'Flujo Redco Chile'!F39+'Flujo Redco Chile'!F34 -> 21747.626 | H30: =+'Flujo Redco Chile'!G38+'Flujo Redco Chile'!G39+'Flujo Redco Chile'!G34 -> 55661.029 | I30: =+'Flujo Redco Chile'!H38+'Flujo Redco Chile'!H39+'Flujo Redco Chile'!H34 -> 0 | J30: =+'Flujo Redco Chile'!I38+'Flujo Redco Chile'!I39+'Flujo Redco Chile'!I34 -> 68680.616 | K30: =+'Flujo Redco Chile'!J38+'Flujo Redco Chile'!J39+'Flujo Redco Chile'!J34 -> 37073.082 | L30: =+'Flujo Redco Chile'!K38+'Flujo Redco Chile'!K39+'Flujo Redco Chile'!K34 -> 4069.9474 | ... O30: =+'Flujo Redco Chile'!N38+'Flujo Redco Chile'!N39+'Flujo Redco Chile'!N34 -> 119.83584 | P30: =SUM(D30:O30) -> 227205.51
B31: Brasil | C31: OTROS INGRESOS | D31: =+'Flujo Redco Brasil'!C34 -> 6388 | E31: =+'Flujo Redco Brasil'!D34 -> 363 | F31: =+'Flujo Redco Brasil'!E34 -> 0 | G31: =+'Flujo Redco Brasil'!F34 -> 0 | H31: =+'Flujo Redco Brasil'!G34 -> 1526 | I31: =+'Flujo Redco Brasil'!H34 -> 0 | J31: =+'Flujo Redco Brasil'!I34 -> 0 | K31: =+'Flujo Redco Brasil'!J34 -> 0 | ... O31: =+'Flujo Redco Brasil'!N34 -> 0 | P31: =SUM(D31:O31) -> 11702
B32: Chile | C32: INGRESO CTA.CTE. EERR | D32: =+'Flujo Redco Chile'!C35+'Flujo Redco Chile'!C36+'Flujo Redco Chile'!C37 -> 134087.98 | E32: =+'Flujo Redco Chile'!D35+'Flujo Redco Chile'!D36+'Flujo Redco Chile'!D37 -> 0 | F32: =+'Flujo Redco Chile'!E35+'Flujo Redco Chile'!E36+'Flujo Redco Chile'!E37 -> 19816.29 | G32: =+'Flujo Redco Chile'!F35+'Flujo Redco Chile'!F36+'Flujo Redco Chile'!F37 -> 48275.16 | H32: =+'Flujo Redco Chile'!G35+'Flujo Redco Chile'!G36+'Flujo Redco Chile'!G37 -> 32259.954 | I32: =+'Flujo Redco Chile'!H35+'Flujo Redco Chile'!H36+'Flujo Redco Chile'!H37 -> 0 | J32: =+'Flujo Redco Chile'!I35+'Flujo Redco Chile'!I36+'Flujo Redco Chile'!I37 -> 46679.406 | K32: =+'Flujo Redco Chile'!J35+'Flujo Redco Chile'!J36+'Flujo Redco Chile'!J37 -> 459872.82 | ... M32: =+'Flujo Redco Chile'!L35+'Flujo Redco Chile'!L36+'Flujo Redco Chile'!L37 -> 154199.14 | N32: =+'Flujo Redco Chile'!M35+'Flujo Redco Chile'!M36+'Flujo Redco Chile'!M37+'Flujo Redco Chile'!M33 -> 147113.87 | O32: =+'Flujo Redco Chile'!N35+'Flujo Redco Chile'!N36+'Flujo Redco Chile'!N37+'Flujo Redco Chile'!N33 -> 395829.61 | P32: =SUM(D32:O32) -> 1438134.2
B33: Chile | C33: CTA.CTE. EERR (REDTEC) | D33: =+'Flujo Redco Chile'!C32 -> 57052.603 | E33: =+'Flujo Redco Chile'!D32 -> 113524.2 | F33: =+'Flujo Redco Chile'!E32 -> 0 | G33: =+'Flujo Redco Chile'!F32 -> 146563.3 | H33: =+'Flujo Redco Chile'!G32 -> 9291.9936 | I33: =+'Flujo Redco Chile'!H32 -> 0 | J33: =+'Flujo Redco Chile'!I32 -> 0 | K33: =+'Flujo Redco Chile'!J32 -> 0 | ... O33: =+'Flujo Redco Chile'!N32 -> 0 | P33: =SUM(D33:O33) -> 353646.46
B34: Perú | C34: CTA.CTE. EERR (REDTEC) | D34: =+'Flujo Redco Perú'!C36 -> 0 | E34: =+'Flujo Redco Perú'!D36 -> 0 | F34: =+'Flujo Redco Perú'!E36 -> 51893 | G34: =+'Flujo Redco Perú'!F36 -> 0 | H34: =+'Flujo Redco Perú'!G36 -> 0 | I34: =+'Flujo Redco Perú'!H36 -> 0 | J34: =+'Flujo Redco Perú'!I36 -> 0 | K34: =+'Flujo Redco Perú'!J36 -> 0 | ... O34: =+'Flujo Redco Perú'!N36 -> 0 | P34: =SUM(D34:O34) -> 51893
B35: Chile | C35: RESCATE FFMM BANCHILE | D35: =+'Flujo Redco Chile'!C40 -> 0 | E35: =+'Flujo Redco Chile'!D40 -> 0 | F35: =+'Flujo Redco Chile'!E40 -> 0 | G35: =+'Flujo Redco Chile'!F40 -> 0 | H35: =+'Flujo Redco Chile'!G40 -> 0 | I35: =+'Flujo Redco Chile'!H40 -> 89784.033 | J35: =+'Flujo Redco Chile'!I40 -> 0 | K35: =+'Flujo Redco Chile'!J40 -> 0 | ... O35: =+'Flujo Redco Chile'!N40 -> 0 | P35: =SUM(D35:O35) -> 171414.93
B36: Otros | C36: INGRESO CTA.CTE. EERR | D36: =+'Flujo Redco BVI'!C36 -> 0 | E36: =+'Flujo Redco BVI'!D36 -> 0 | F36: =+'Flujo Redco BVI'!E36 -> 0 | G36: =+'Flujo Redco BVI'!F36 -> 0 | H36: =+'Flujo Redco BVI'!G36 -> 415568 | I36: =+'Flujo Redco BVI'!H36 -> 0 | J36: =+'Flujo Redco BVI'!I36 -> 0 | K36: =+'Flujo Redco BVI'!J36 -> 0 | ... O36: =+'Flujo Redco BVI'!N36 -> 349514 | P36: =SUM(D36:O36) -> 1154049
B37: TOTAL | C37: SUMA OTROS INGRESOS | D37: =SUM(D28:D36) -> 279571.81 | E37: =SUM(E28:E36) -> 245598.41 | F37: =SUM(F28:F36) -> 172251.12 | G37: =SUM(G28:G36) -> 292209.81 | H37: =SUM(H28:H36) -> 608384.49 | I37: =SUM(I28:I36) -> 179700.25 | J37: =SUM(J28:J36) -> 253201.81 | K37: =SUM(K28:K36) -> 659206.51 | ... P37: =SUM(P28:P36) -> 4665267.2
B39: Chile | C39: EGRESO IVA DEBITO | D39: =+'Flujo Redco Chile'!C44*-1 -> -34979.334 | E39: =+'Flujo Redco Chile'!D44*-1 -> -63266.452 | F39: =+'Flujo Redco Chile'!E44*-1 -> -11946.348 | G39: =+'Flujo Redco Chile'!F44*-1 -> -31666.326 | H39: =+'Flujo Redco Chile'!G44*-1 -> -65886.451 | I39: =+'Flujo Redco Chile'!H44*-1 -> -41468.266 | J39: =+'Flujo Redco Chile'!I44*-1 -> -8884.088 | K39: =+'Flujo Redco Chile'!J44*-1 -> -86387.474 | ... O39: =+'Flujo Redco Chile'!N44*-1 -> -24253.626 | P39: =SUM(D39:O39) -> -489115.1
B40: Chile | C40: EGRESO CREDITOS | D40: =(+'Flujo Redco Chile'!C45+'Flujo Redco Chile'!C46+'Flujo Redco Chile'!C47)*-1 -> -27599.535 | E40: =(+'Flujo Redco Chile'!D45+'Flujo Redco Chile'!D46+'Flujo Redco Chile'!D47)*-1 -> -38631.281 | F40: =(+'Flujo Redco Chile'!E45+'Flujo Redco Chile'!E46+'Flujo Redco Chile'!E47)*-1 -> -30686.726 | G40: =(+'Flujo Redco Chile'!F45+'Flujo Redco Chile'!F46+'Flujo Redco Chile'!F47)*-1 -> -31866.891 | H40: =(+'Flujo Redco Chile'!G45+'Flujo Redco Chile'!G46+'Flujo Redco Chile'!G47)*-1 -> -32660.93 | I40: =(+'Flujo Redco Chile'!H45+'Flujo Redco Chile'!H46+'Flujo Redco Chile'!H47)*-1 -> -27706.253 | J40: =(+'Flujo Redco Chile'!I45+'Flujo Redco Chile'!I46+'Flujo Redco Chile'!I47)*-1 -> -31882.783 | K40: =(+'Flujo Redco Chile'!J45+'Flujo Redco Chile'!J46+'Flujo Redco Chile'!J47)*-1 -> -30717.742 | ... O40: =(+'Flujo Redco Chile'!N45+'Flujo Redco Chile'!N46+'Flujo Redco Chile'!N47)*-1 -> -30784.118 | P40: =SUM(D40:O40) -> -373754.78
B41: Chile | C41: CTA.CTE. EERR | D41: =(+'Flujo Redco Chile'!C52+'Flujo Redco Chile'!C54+'Flujo Redco Chile'!C55+'Flujo Redco Chile'!C56+'Flujo Redco Chile'!C57)*-1 -> -21128.81 | E41: =(+'Flujo Redco Chile'!D52+'Flujo Redco Chile'!D54+'Flujo Redco Chile'!D55+'Flujo Redco Chile'!D56+'Flujo Redco Chile'!D57)*-1 -> -5335.2929 | F41: =(+'Flujo Redco Chile'!E52+'Flujo Redco Chile'!E54+'Flujo Redco Chile'!E55+'Flujo Redco Chile'!E56+'Flujo Redco Chile'!E57)*-1 -> -20323.139 | G41: =(+'Flujo Redco Chile'!F52+'Flujo Redco Chile'!F54+'Flujo Redco Chile'!F55+'Flujo Redco Chile'!F56+'Flujo Redco Chile'!F57)*-1 -> -68310.75 | H41: =(+'Flujo Redco Chile'!G52+'Flujo Redco Chile'!G54+'Flujo Redco Chile'!G55+'Flujo Redco Chile'!G56+'Flujo Redco Chile'!G57)*-1 -> -25408.954 | I41: =(+'Flujo Redco Chile'!H52+'Flujo Redco Chile'!H54+'Flujo Redco Chile'!H55+'Flujo Redco Chile'!H56+'Flujo Redco Chile'!H57)*-1 -> -19313.305 | J41: =(+'Flujo Redco Chile'!I52+'Flujo Redco Chile'!I54+'Flujo Redco Chile'!I55+'Flujo Redco Chile'!I56+'Flujo Redco Chile'!I57)*-1 -> -66329.145 | K41: =(+'Flujo Redco Chile'!J52+'Flujo Redco Chile'!J54+'Flujo Redco Chile'!J55+'Flujo Redco Chile'!J56+'Flujo Redco Chile'!J57)*-1 -> -7645.6223 | ... O41: =(+'Flujo Redco Chile'!N52+'Flujo Redco Chile'!N54+'Flujo Redco Chile'!N55+'Flujo Redco Chile'!N56+'Flujo Redco Chile'!N57)*-1 -> -47905.397 | P41: =SUM(D41:O41) -> -289705.24
...

Sheet Tabla datos unidades_Sept
L1: 6853202.5 | M1: =+L10-L1 -> 73593.425 | N1: =+M1/L10 -> 0.010624454
J2: =+J17/1000 -> 641.80299 | K2: =+K17/1000 -> 678.99571 | L2: =+L17/1000 -> 666.97613 | M2: =+M17/1000 -> 639.22703 | N2: =+N17/1000 -> 617.98793 | O2: =+O17/1000 -> 842.67783
B3: País | C3: Concepto | D3: 45658 | E3: 45689 | F3: 45717 | G3: 45748 | H3: 45778 | I3: 45809 | J3: 45839 | K3: 45870 | L3: 45901 | M3: 45931 | N3: 45962 | O3: 45992 | P3: Total | R3: País | S3: Concepto | T3: 45658
B4: Chile | C4: INGRESOS OP | D4: =+'Flujo Redco Chile'!C12 -> 362362.73 | E4: =+'Flujo Redco Chile'!D12 -> 547310.62 | F4: =+'Flujo Redco Chile'!E12 -> 389727.46 | G4: =+'Flujo Redco Chile'!F12 -> 237434.48 | H4: =+'Flujo Redco Chile'!G12 -> 272631.08 | I4: =+'Flujo Redco Chile'!H12 -> 277419.07 | J4: =+'Flujo Redco Chile'!I12 -> 475570.75 | K4: =+'Flujo Redco Chile'!J12 -> 151482.74 | ... O4: =+'Flujo Redco Chile'!N12 -> 173207.55 | P4: =SUM(D4:O4) -> 3592126.9 | R4: Chile | S4: SALDO INICIAL | T4: =+'Flujo Redco Chile'!C8 -> 52257.137
B5: Perú | C5: INGRESOS OP | D5: =+'Flujo Redco Perú'!C13 -> 123848 | E5: =+'Flujo Redco Perú'!D13 -> 62454 | F5: =+'Flujo Redco Perú'!E13 -> 105377 | G5: =+'Flujo Redco Perú'!F13 -> 110077 | H5: =+'Flujo Redco Perú'!G13 -> 142610 | I5: =+'Flujo Redco Perú'!H13 -> 229588 | J5: =+'Flujo Redco Perú'!I13 -> 251702 | K5: =+'Flujo Redco Perú'!J13 -> 641573 | ... O5: =+'Flujo Redco Perú'!N13 -> 269432 | P5: =SUM(D5:O5) -> 2417353 | R5: Perú | S5: SALDO INICIAL | T5: =+'Flujo Redco Perú'!C9 -> 136767.69
B6: Brasil | C6: INGRESOS OP | D6: =+'Flujo Redco Brasil'!C14 -> 80502 | E6: =+'Flujo Redco Brasil'!D14 -> 59683 | F6: =+'Flujo Redco Brasil'!E14 -> 96322 | G6: =+'Flujo Redco Brasil'!F14 -> 97209.7 | H6: =+'Flujo Redco Brasil'!G14 -> 37074 | I6: =+'Flujo Redco Brasil'!H14 -> 66563 | J6: =+'Flujo Redco Brasil'!I14 -> 47717 | K6: =+'Flujo Redco Brasil'!J14 -> 119652 | ... O6: =+'Flujo Redco Brasil'!N14 -> 224116.51 | P6: =SUM(D6:O6) -> 1597092.2 | R6: Brasil | S6: SALDO INICIAL | T6: =+'Flujo Redco Brasil'!C9 -> 9622.33
B7: USA | C7: INGRESOS OP | D7: =+'Flujo Redco USA'!C13 -> 150453 | E7: =+'Flujo Redco USA'!D13 -> 243465.21 | F7: =+'Flujo Redco USA'!E13 -> 141526 | G7: =+'Flujo Redco USA'!F13 -> 169200 | H7: =+'Flujo Redco USA'!G13 -> 195090 | I7: =+'Flujo Redco USA'!H13 -> 61796 | J7: =+'Flujo Redco USA'!I13 -> 0 | K7: =+'Flujo Redco USA'!J13 -> 20000 | ... O7: =+'Flujo Redco USA'!N13 -> 178785 | P7: =SUM(D7:O7) -> 1205315.2 | R7: USA | S7: SALDO INICIAL | T7: =+'Flujo Redco USA'!C9 -> 55345
B8: Otros | C8: INGRESOS OP | D8: =+'Flujo Redco BVI'!C13 -> 0 | E8: =+'Flujo Redco BVI'!D13 -> 21682 | F8: =+'Flujo Redco BVI'!E13 -> 45478 | G8: =+'Flujo Redco BVI'!F13 -> 0 | H8: =+'Flujo Redco BVI'!G13 -> 0 | I8: =+'Flujo Redco BVI'!H13 -> 172045 | J8: =+'Flujo Redco BVI'!I13 -> 0 | K8: =+'Flujo Redco BVI'!J13 -> 99524 | ... O8: =+'Flujo Redco BVI'!N13 -> 0 | P8: =SUM(D8:O8) -> 338729 | Q8: 415000 | R8: BVI | S8: SALDO INICIAL | T8: =+'Flujo Redco BVI'!S13 -> 0
B9: TOTAL | C9: INGRESOS OP | D9: =SUM(D4:D8) -> 717165.73 | E9: =SUM(E4:E8) -> 934594.83 | F9: =SUM(F4:F8) -> 778430.46 | G9: =SUM(G4:G8) -> 613921.18 | H9: =SUM(H4:H8) -> 647405.08 | I9: =SUM(I4:I8) -> 807411.07 | J9: =SUM(J4:J8) -> 774989.75 | K9: =SUM(K4:K8) -> 1032231.7 | ... P9: =SUM(P4:P8) -> 9150616.3 | R9: CAJA FINAL | S9: CAJA FINAL | T9: =SUM(T4:T8) -> 253992.16
C10: INGRESOS OP ACUM | D10: =+SUM($D$9:D9) -> 717165.73 | E10: =+SUM($D$9:E9) -> 1651760.6 | F10: =+SUM($D$9:F9) -> 2430191 | G10: =+SUM($D$9:G9) -> 3044112.2 | H10: =+SUM($D$9:H9) -> 3691517.3 | I10: =+SUM($D$9:I9) -> 4498928.4 | J10: =+SUM($D$9:J9) -> 5273918.1 | K10: =+SUM($D$9:K9) -> 6306149.8 | ... O10: =+SUM($D$9:O9) -> 9150616.3
B11: País | C11: Concepto | D11: 45658 | E11: 45689 | F11: 45717 | G11: 45748 | H11: 45778 | I11: 45809 | J11: 45839 | K11: 45870 | L11: 45901 | M11: 45931 | N11: 45962 | O11: 45992 | P11: Total
B12: Chile | C12: COSTOS OP | D12: =+'Flujo Redco Chile'!C18+'Flujo Redco Chile'!C23+'Flujo Redco Chile'!C25 -> 397276.65 | E12: =+'Flujo Redco Chile'!D18+'Flujo Redco Chile'!D23+'Flujo Redco Chile'!D25 -> 422126.64 | F12: =+'Flujo Redco Chile'!E18+'Flujo Redco Chile'!E23+'Flujo Redco Chile'!E25 -> 439899.18 | G12: =+'Flujo Redco Chile'!F18+'Flujo Redco Chile'!F23+'Flujo Redco Chile'!F25 -> 341507.35 | H12: =+'Flujo Redco Chile'!G18+'Flujo Redco Chile'!G23+'Flujo Redco Chile'!G25 -> 340134.8 | I12: =+'Flujo Redco Chile'!H18+'Flujo Redco Chile'!H23+'Flujo Redco Chile'!H25 -> 380566.17 | J12: =+'Flujo Redco Chile'!I18+'Flujo Redco Chile'!I23+'Flujo Redco Chile'!I25 -> 395727.19 | K12: =+'Flujo Redco Chile'!J18+'Flujo Redco Chile'!J23+'Flujo Redco Chile'!J25 -> 425248.91 | L12: =+'Flujo Redco Chile'!K18+'Flujo Redco Chile'!K23+'Flujo Redco Chile'!K25 -> 455871.33 | M12: 425000 | N12: 425000 | O12: 425000 | P12: =SUM(D12:O12) -> 4873358.2
B13: Perú | C13: COSTOS OP | D13: =+'Flujo Redco Perú'!C19+'Flujo Redco Perú'!C26+'Flujo Redco Perú'!C28 -> 89462.85 | E13: =+'Flujo Redco Perú'!D19+'Flujo Redco Perú'!D26+'Flujo Redco Perú'!D28 -> 81597 | F13: =+'Flujo Redco Perú'!E19+'Flujo Redco Perú'!E26+'Flujo Redco Perú'!E28 -> 92755 | G13: =+'Flujo Redco Perú'!F19+'Flujo Redco Perú'!F26+'Flujo Redco Perú'!F28 -> 137672.3 | H13: =+'Flujo Redco Perú'!G19+'Flujo Redco Perú'!G26+'Flujo Redco Perú'!G28 -> 128924 | I13: =+'Flujo Redco Perú'!H19+'Flujo Redco Perú'!H26+'Flujo Redco Perú'!H28 -> 167995 | J13: =+'Flujo Redco Perú'!I19+'Flujo Redco Perú'!I26+'Flujo Redco Perú'!I28 -> 199355 | K13: =+'Flujo Redco Perú'!J19+'Flujo Redco Perú'!J26+'Flujo Redco Perú'!J28 -> 225572 | L13: =+'Flujo Redco Perú'!K19+'Flujo Redco Perú'!K26+'Flujo Redco Perú'!K28 -> 127097 | M13: 106082.23 | N13: 138332.13 | O13: 170582.03 | P13: =SUM(D13:O13) -> 1665426.5
B14: Brasil | C14: COSTOS OP | D14: =+'Flujo Redco Brasil'!C20+'Flujo Redco Brasil'!C25+'Flujo Redco Brasil'!C27 -> 21023 | E14: =+'Flujo Redco Brasil'!D20+'Flujo Redco Brasil'!D25+'Flujo Redco Brasil'!D27 -> 27812 | F14: =+'Flujo Redco Brasil'!E20+'Flujo Redco Brasil'!E25+'Flujo Redco Brasil'!E27 -> 26425 | G14: =+'Flujo Redco Brasil'!F20+'Flujo Redco Brasil'!F25+'Flujo Redco Brasil'!F27 -> 52004.4 | H14: =+'Flujo Redco Brasil'!G20+'Flujo Redco Brasil'!G25+'Flujo Redco Brasil'!G27 -> 33329 | I14: =+'Flujo Redco Brasil'!H20+'Flujo Redco Brasil'!H25+'Flujo Redco Brasil'!H27 -> 76286 | J14: =+'Flujo Redco Brasil'!I20+'Flujo Redco Brasil'!I25+'Flujo Redco Brasil'!I27 -> 31019 | K14: =+'Flujo Redco Brasil'!J20+'Flujo Redco Brasil'!J25+'Flujo Redco Brasil'!J27 -> 21475 | ... O14: =+'Flujo Redco Brasil'!N20+'Flujo Redco Brasil'!N25+'Flujo Redco Brasil'!N27 -> 23001 | P14: =SUM(D14:O14) -> 451717.4
B15: USA | C15: COSTOS OP | D15: =+'Flujo Redco USA'!C19+'Flujo Redco USA'!C27+'Flujo Redco USA'!C29 -> 15 | E15: =+'Flujo Redco USA'!D19+'Flujo Redco USA'!D27+'Flujo Redco USA'!D29 -> 2025 | F15: =+'Flujo Redco USA'!E19+'Flujo Redco USA'!E27+'Flujo Redco USA'!E29 -> 58728 | G15: =+'Flujo Redco USA'!F19+'Flujo Redco USA'!F27+'Flujo Redco USA'!F29 -> 9898 | H15: =+'Flujo Redco USA'!G19+'Flujo Redco USA'!G27+'Flujo Redco USA'!G29 -> 47666 | I15: =+'Flujo Redco USA'!H19+'Flujo Redco USA'!H27+'Flujo Redco USA'!H29 -> 4178 | J15: =+'Flujo Redco USA'!I19+'Flujo Redco USA'!I27+'Flujo Redco USA'!I29 -> 10017 | K15: =+'Flujo Redco USA'!J19+'Flujo Redco USA'!J27+'Flujo Redco USA'!J29 -> 1015 | ... O15: =+'Flujo Redco USA'!N19+'Flujo Redco USA'!N27+'Flujo Redco USA'!N29 -> 218410 | P15: =SUM(D15:O15) -> 442363
B16: Otros | C16: COSTOS OP | D16: =+'Flujo Redco BVI'!C19+'Flujo Redco BVI'!C27+'Flujo Redco BVI'!C29 -> 14044 | E16: =+'Flujo Redco BVI'!D19+'Flujo Redco BVI'!D27+'Flujo Redco BVI'!D29 -> 0 | F16: =+'Flujo Redco BVI'!E19+'Flujo Redco BVI'!E27+'Flujo Redco BVI'!E29 -> 0 | G16: =+'Flujo Redco BVI'!F19+'Flujo Redco BVI'!F27+'Flujo Redco BVI'!F29 -> 14380 | H16: =+'Flujo Redco BVI'!G19+'Flujo Redco BVI'!G27+'Flujo Redco BVI'!G29 -> 16000 | I16: =+'Flujo Redco BVI'!H19+'Flujo Redco BVI'!H27+'Flujo Redco BVI'!H29 -> 15094 | J16: =+'Flujo Redco BVI'!I19+'Flujo Redco BVI'!I27+'Flujo Redco BVI'!I29 -> 5684.8 | K16: =+'Flujo Redco BVI'!J19+'Flujo Redco BVI'!J27+'Flujo Redco BVI'!J29 -> 5684.8 | ... O16: =+'Flujo Redco BVI'!N19+'Flujo Redco BVI'!N27+'Flujo Redco BVI'!N29 -> 5684.8 | P16: =SUM(D16:O16) -> 93626.8
B17: TOTAL | C17: COSTOS OP | D17: =SUM(D12:D16) -> 521821.5 | E17: =SUM(E12:E16) -> 533560.64 | F17: =SUM(F12:F16) -> 617807.18 | G17: =SUM(G12:G16) -> 555462.05 | H17: =SUM(H12:H16) -> 566053.8 | I17: =SUM(I12:I16) -> 644119.17 | J17: =SUM(J12:J16) -> 641802.99 | K17: =SUM(K12:K16) -> 678995.71 | ... O17: =SUM(O12:O16) -> 842677.83 | P17: =SUM(D17:O17) -> 7526491.9
C18: COSTOS OP ACUM | D18: =+SUM($D$17:D17) -> 521821.5 | E18: =+SUM($D$17:E17) -> 1055382.1 | F18: =+SUM($D$17:F17) -> 1673189.3 | G18: =+SUM($D$17:G17) -> 2228651.4 | H18: =+SUM($D$17:H17) -> 2794705.2 | I18: =+SUM($D$17:I17) -> 3438824.3 | J18: =+SUM($D$17:J17) -> 4080627.3 | K18: =+SUM($D$17:K17) -> 4759623 | ... O18: =+SUM($D$17:O17) -> 7526491.9
B19: País | C19: Concepto | D19: 45658 | E19: 45689 | F19: 45717 | G19: 45748 | H19: 45778 | I19: 45809 | J19: 45839 | K19: 45870 | L19: 45901 | M19: 45931 | N19: 45962 | O19: 45992 | P19: Total
B20: Chile | C20: RESULTADO OP. | D20: =+D4-D12 -> -34913.914 | E20: =+E4-E12 -> 125183.98 | F20: =+F4-F12 -> -50171.722 | G20: =+G4-G12 -> -104072.86 | H20: =+H4-H12 -> -67503.719 | I20: =+I4-I12 -> -103147.1 | J20: =+J4-J12 -> 79843.563 | K20: =+K4-K12 -> -273766.17 | ... O20: =+O4-O12 -> -251792.45 | P20: =SUM(D20:O20) -> -1281231.3
B21: Perú | C21: RESULTADO OP. | D21: =+D5-D13 -> 34385.15 | E21: =+E5-E13 -> -19143 | F21: =+F5-F13 -> 12622 | G21: =+G5-G13 -> -27595.3 | H21: =+H5-H13 -> 13686 | I21: =+I5-I13 -> 61593 | J21: =+J5-J13 -> 52347 | K21: =+K5-K13 -> 416001 | ... O21: =+O5-O13 -> 98849.97 | P21: =SUM(D21:O21) -> 751926.46
B22: Brasil | C22: RESULTADO OP. | D22: =+D6-D14 -> 59479 | E22: =+E6-E14 -> 31871 | F22: =+F6-F14 -> 69897 | G22: =+G6-G14 -> 45205.3 | H22: =+H6-H14 -> 3745 | I22: =+I6-I14 -> -9723 | J22: =+J6-J14 -> 16698 | K22: =+K6-K14 -> 98177 | ... O22: =+O6-O14 -> 201115.51 | P22: =SUM(D22:O22) -> 1145374.8
B23: USA | C23: RESULTADO OP. | D23: =+D7-D15 -> 150438 | E23: =+E7-E15 -> 241440.21 | F23: =+F7-F15 -> 82798 | G23: =+G7-G15 -> 159302 | H23: =+H7-H15 -> 147424 | I23: =+I7-I15 -> 57618 | J23: =+J7-J15 -> -10017 | K23: =+K7-K15 -> 18985 | ... O23: =+O7-O15 -> -39625 | P23: =SUM(D23:O23) -> 762952.21
B24: Otros | C24: RESULTADO OP. | D24: =+D8-D16 -> -14044 | E24: =+E8-E16 -> 21682 | F24: =+F8-F16 -> 45478 | G24: =+G8-G16 -> -14380 | H24: =+H8-H16 -> -16000 | I24: =+I8-I16 -> 156951 | J24: =+J8-J16 -> -5684.8 | K24: =+K8-K16 -> 93839.2 | ... O24: =+O8-O16 -> -5684.8 | P24: =SUM(D24:O24) -> 245102.2
B25: TOTAL | C25: RESULTADO OP. | D25: =SUM(D20:D24) -> 195344.24 | E25: =SUM(E20:E24) -> 401034.19 | F25: =SUM(F20:F24) -> 160623.28 | G25: =SUM(G20:G24) -> 58459.138 | H25: =SUM(H20:H24) -> 81351.281 | I25: =SUM(I20:I24) -> 163291.9 | J25: =SUM(J20:J24) -> 133186.76 | K25: =SUM(K20:K24) -> 353236.03 | ... P25: =SUM(P20:P24) -> 1624124.4
D26: =+SUM($D$25:D25) -> 195344.24 | E26: =+SUM($D$25:E25) -> 596378.43 | F26: =+SUM($D$25:F25) -> 757001.71 | G26: =+SUM($D$25:G25) -> 815460.84 | H26: =+SUM($D$25:H25) -> 896812.13 | I26: =+SUM($D$25:I25) -> 1060104 | J26: =+SUM($D$25:J25) -> 1193290.8 | K26: =+SUM($D$25:K25) -> 1546526.8 | L26: =+SUM($D$25:L25) -> 1500196.7 | M26: =+L26/L10 -> 0.21657874
B27: País | C27: Concepto | D27: 45658 | E27: 45689 | F27: 45717 | G27: 45748 | H27: 45778 | I27: 45809 | J27: 45839 | K27: 45870 | L27: 45901 | M27: 45931 | N27: 45962 | O27: 45992 | P27: Total
B28: Chile | C28: INGRESO IVA DEBITO | D28: =+'Flujo Redco Chile'!C31 -> 69432.94 | E28: =+'Flujo Redco Chile'!D31 -> 104811.9 | F28: =+'Flujo Redco Chile'!E31 -> 75208.024 | G28: =+'Flujo Redco Chile'!F31 -> 47094.724 | H28: =+'Flujo Redco Chile'!G31 -> 62773.513 | I28: =+'Flujo Redco Chile'!H31+'Flujo Redco Chile'!H34 -> 53789.215 | J28: =+'Flujo Redco Chile'!I31 -> 103658.78 | K28: =+'Flujo Redco Chile'!J31 -> 35825.605 | L28: =+'Flujo Redco Chile'!K31 -> 57280.832 | M28: =+'Flujo Redco Chile'!L31 -> 32498.942 | N28: =+'Flujo Redco Chile'!M31 -> 37753.16 | O28: =+'Flujo Redco Chile'!N31 -> 32909.433 | P28: =SUM(D28:O28) -> 713037.07
B29: Perú | C29: INGRESO IVA DEBITO | D29: =+'Flujo Redco Perú'!C35 -> 11907 | E29: =+'Flujo Redco Perú'!D35 -> 16500 | F29: =+'Flujo Redco Perú'!E35 -> 20068 | G29: =+'Flujo Redco Perú'!F35 -> 28529 | H29: =+'Flujo Redco Perú'!G35 -> 31304 | I29: =+'Flujo Redco Perú'!H35 -> 36127 | J29: =+'Flujo Redco Perú'!I35 -> 34183 | K29: =+'Flujo Redco Perú'!J35 -> 126435 | ... O29: =+'Flujo Redco Perú'!N35 -> 75885 | P29: =SUM(D29:O29) -> 544185
B30: Chile | C30: OTROS INGRESOS | D30: =+'Flujo Redco Chile'!C38+'Flujo Redco Chile'!C39+'Flujo Redco Chile'!E42+'Flujo Redco Chile'!C34 -> 703.28541 | E30: =+'Flujo Redco Chile'!D38+'Flujo Redco Chile'!D39+'Flujo Redco Chile'!D34 -> 10399.317 | F30: =+'Flujo Redco Chile'!E38+'Flujo Redco Chile'!E39+'Flujo Redco Chile'!E34 -> 5265.8026 | G30: =+'Flujo Redco Chile'!F38+'Flujo Redco Chile'!F39+'Flujo Redco Chile'!F34 -> 21747.626 | H30: =+'Flujo Redco Chile'!G38+'Flujo Redco Chile'!G39+'Flujo Redco Chile'!G34 -> 55661.029 | I30: =+'Flujo Redco Chile'!H38+'Flujo Redco Chile'!H39+'Flujo Redco Chile'!H34+'Flujo Redco Chile'!H40 -> 89784.033 | J30: =+'Flujo Redco Chile'!I38+'Flujo Redco Chile'!I39+'Flujo Redco Chile'!I34 -> 68680.616 | K30: =+'Flujo Redco Chile'!J38+'Flujo Redco Chile'!J39+'Flujo Redco Chile'!J34 -> 37073.082 | L30: =+'Flujo Redco Chile'!K38+'Flujo Redco Chile'!K39+'Flujo Redco Chile'!K34 -> 4069.9474 | M30: =+'Flujo Redco Chile'!L38+'Flujo Redco Chile'!L39 -> 13.927039 | N30: =+'Flujo Redco Chile'!M38+'Flujo Redco Chile'!M39 -> 415.80687 | O30: =+'Flujo Redco Chile'!N38+'Flujo Redco Chile'!N39 -> 119.83584 | P30: =SUM(D30:O30) -> 293934.31
B31: Brasil | C31: OTROS INGRESOS | D31: =+'Flujo Redco Brasil'!C34 -> 6388 | E31: =+'Flujo Redco Brasil'!D34 -> 363 | F31: =+'Flujo Redco Brasil'!E34 -> 0 | G31: =+'Flujo Redco Brasil'!F34 -> 0 | H31: =+'Flujo Redco Brasil'!G34 -> 1526 | I31: =+'Flujo Redco Brasil'!H34 -> 0 | J31: =+'Flujo Redco Brasil'!I34 -> 0 | K31: =+'Flujo Redco Brasil'!J34 -> 0 | ... O31: =+'Flujo Redco Brasil'!N34 -> 0 | P31: =SUM(D31:O31) -> 11702
B32: Chile | C32: INGRESO CTA.CTE. EERR | D32: =+'Flujo Redco Chile'!C35+'Flujo Redco Chile'!C36+'Flujo Redco Chile'!C37 -> 134087.98 | E32: =+'Flujo Redco Chile'!D35+'Flujo Redco Chile'!D36+'Flujo Redco Chile'!D37 -> 0 | F32: =+'Flujo Redco Chile'!E35+'Flujo Redco Chile'!E36+'Flujo Redco Chile'!E37 -> 19816.29 | G32: =+'Flujo Redco Chile'!F35+'Flujo Redco Chile'!F36+'Flujo Redco Chile'!F37 -> 48275.16 | H32: =+'Flujo Redco Chile'!G35+'Flujo Redco Chile'!G36+'Flujo Redco Chile'!G37 -> 32259.954 | I32: =+'Flujo Redco Chile'!H35+'Flujo Redco Chile'!H36+'Flujo Redco Chile'!H37 -> 0 | J32: =+'Flujo Redco Chile'!I35+'Flujo Redco Chile'!I36+'Flujo Redco Chile'!I37 -> 46679.406 | K32: =+'Flujo Redco Chile'!J35+'Flujo Redco Chile'!J36+'Flujo Redco Chile'!J37 -> 459872.82 | ... O32: =+'Flujo Redco Chile'!N35+'Flujo Redco Chile'!N36+'Flujo Redco Chile'!N37 -> 390966.74 | P32: =SUM(D32:O32) -> 1406447.3
B33: Chile | C33: CTA.CTE. EERR (REDTEC) | D33: =+'Flujo Redco Chile'!C32 -> 57052.603 | E33: =+'Flujo Redco Chile'!D32 -> 113524.2 | F33: =+'Flujo Redco Chile'!E32 -> 0 | G33: =+'Flujo Redco Chile'!F32 -> 146563.3 | H33: =+'Flujo Redco Chile'!G32 -> 9291.9936 | I33: =+'Flujo Redco Chile'!H32 -> 0 | J33: =+'Flujo Redco Chile'!I32 -> 0 | K33: =+'Flujo Redco Chile'!J32 -> 0 | ... O33: =+'Flujo Redco Chile'!N32 -> 0 | P33: =SUM(D33:O33) -> 353646.46
B34: Perú | C34: CTA.CTE. EERR (REDTEC) | D34: =+'Flujo Redco Perú'!C36 -> 0 | E34: =+'Flujo Redco Perú'!D36 -> 0 | F34: =+'Flujo Redco Perú'!E36 -> 51893 | G34: =+'Flujo Redco Perú'!F36 -> 0 | H34: =+'Flujo Redco Perú'!G36 -> 0 | I34: =+'Flujo Redco Perú'!H36 -> 0 | J34: =+'Flujo Redco Perú'!I36 -> 0 | K34: =+'Flujo Redco Perú'!J36 -> 0 | ... O34: =+'Flujo Redco Perú'!N36 -> 0 | P34: =SUM(D34:O34) -> 51893
B35: Chile | C35: RESCATE FFMM BANCHILE | P35: =SUM(D35:O35) -> 0
B36: Otros | C36: INGRESO CTA.CTE. EERR | D36: =+'Flujo Redco BVI'!C36 -> 0 | E36: =+'Flujo Redco BVI'!D36 -> 0 | F36: =+'Flujo Redco BVI'!E36 -> 0 | G36: =+'Flujo Redco BVI'!F36 -> 0 | H36: =+'Flujo Redco BVI'!G36 -> 415568 | I36: =+'Flujo Redco BVI'!H36 -> 0 | J36: =+'Flujo Redco BVI'!I36 -> 0 | K36: =+'Flujo Redco BVI'!J36 -> 0 | ... O36: =+'Flujo Redco BVI'!N36 -> 349514 | P36: =SUM(D36:O36) -> 1154049
B37: TOTAL | C37: SUMA OTROS INGRESOS | D37: =SUM(D28:D36) -> 279571.81 | E37: =SUM(E28:E36) -> 245598.41 | F37: =SUM(F28:F36) -> 172251.12 | G37: =SUM(G28:G36) -> 292209.81 | H37: =SUM(H28:H36) -> 608384.49 | I37: =SUM(I28:I36) -> 179700.25 | J37: =SUM(J28:J36) -> 253201.81 | K37: =SUM(K28:K36) -> 659206.51 | ... P37: =SUM(P28:P36) -> 4528894.2
B39: Chile | C39: EGRESO IVA DEBITO | D39: =+'Flujo Redco Chile'!C44*-1 -> -34979.334 | E39: =+'Flujo Redco Chile'!D44*-1 -> -63266.452 | F39: =+'Flujo Redco Chile'!E44*-1 -> -11946.348 | G39: =+'Flujo Redco Chile'!F44*-1 -> -31666.326 | H39: =+'Flujo Redco Chile'!G44*-1 -> -65886.451 | I39: =+'Flujo Redco Chile'!H44*-1 -> -41468.266 | J39: =+'Flujo Redco Chile'!I44*-1 -> -8884.088 | K39: =+'Flujo Redco Chile'!J44*-1 -> -86387.474 | ... O39: =+'Flujo Redco Chile'!N44*-1 -> -24253.626 | P39: =SUM(D39:O39) -> -489115.1
B40: Chile | C40: EGRESO CREDITOS | D40: =(+'Flujo Redco Chile'!C45+'Flujo Redco Chile'!C46+'Flujo Redco Chile'!C47)*-1 -> -27599.535 | E40: =(+'Flujo Redco Chile'!D45+'Flujo Redco Chile'!D46+'Flujo Redco Chile'!D47)*-1 -> -38631.281 | F40: =(+'Flujo Redco Chile'!E45+'Flujo Redco Chile'!E46+'Flujo Redco Chile'!E47)*-1 -> -30686.726 | G40: =(+'Flujo Redco Chile'!F45+'Flujo Redco Chile'!F46+'Flujo Redco Chile'!F47)*-1 -> -31866.891 | H40: =(+'Flujo Redco Chile'!G45+'Flujo Redco Chile'!G46+'Flujo Redco Chile'!G47)*-1 -> -32660.93 | I40: =(+'Flujo Redco Chile'!H45+'Flujo Redco Chile'!H46+'Flujo Redco Chile'!H47)*-1 -> -27706.253 | J40: =(+'Flujo Redco Chile'!I45+'Flujo Redco Chile'!I46+'Flujo Redco Chile'!I47)*-1 -> -31882.783 | K40: =(+'Flujo Redco Chile'!J45+'Flujo Redco Chile'!J46+'Flujo Redco Chile'!J47)*-1 -> -30717.742 | ... O40: =(+'Flujo Redco Chile'!N45+'Flujo Redco Chile'!N46+'Flujo Redco Chile'!N47)*-1 -> -30784.118 | P40: =SUM(D40:O40) -> -373754.78
B41: Chile | C41: CTA.CTE. EERR | D41: =(+'Flujo Redco Chile'!C52+'Flujo Redco Chile'!C54+'Flujo Redco Chile'!C55+'Flujo Redco Chile'!C56+'Flujo Redco Chile'!C57)*-1 -> -21128.81 | E41: =(+'Flujo Redco Chile'!D52+'Flujo Redco Chile'!D54+'Flujo Redco Chile'!D55+'Flujo Redco Chile'!D56+'Flujo Redco Chile'!D57)*-1 -> -5335.2929 | F41: =(+'Flujo Redco Chile'!E52+'Flujo Redco Chile'!E54+'Flujo Redco Chile'!E55+'Flujo Redco Chile'!E56+'Flujo Redco Chile'!E57)*-1 -> -20323.139 | G41: =(+'Flujo Redco Chile'!F52+'Flujo Redco Chile'!F54+'Flujo Redco Chile'!F55+'Flujo Redco Chile'!F56+'Flujo Redco Chile'!F57)*-1 -> -68310.75 | H41: =(+'Flujo Redco Chile'!G52+'Flujo Redco Chile'!G54+'Flujo Redco Chile'!G55+'Flujo Redco Chile'!G56+'Flujo Redco Chile'!G57)*-1 -> -25408.954 | I41: =(+'Flujo Redco Chile'!H52+'Flujo Redco Chile'!H54+'Flujo Redco Chile'!H55+'Flujo Redco Chile'!H56+'Flujo Redco Chile'!H57)*-1 -> -19313.305 | J41: =(+'Flujo Redco Chile'!I52+'Flujo Redco Chile'!I54+'Flujo Redco Chile'!I55+'Flujo Redco Chile'!I56+'Flujo Redco Chile'!I57)*-1 -> -66329.145 | K41: =(+'Flujo Redco Chile'!J52+'Flujo Redco Chile'!J54+'Flujo Redco Chile'!J55+'Flujo Redco Chile'!J56+'Flujo Redco Chile'!J57)*-1 -> -7645.6223 | ... O41: =(+'Flujo Redco Chile'!N52+'Flujo Redco Chile'!N54+'Flujo Redco Chile'!N55+'Flujo Redco Chile'!N56+'Flujo Redco Chile'!N57)*-1 -> -47905.397 | P41: =SUM(D41:O41) -> -289705.24
...

Sheet Tabla datos unidades
L1: 6853202.5 | M1: =+L10-L1 -> 73593.425 | N1: =+M1/L10 -> 0.010624454
J2: =+J17/1000 -> 641.80299 | K2: =+K17/1000 -> 678.99571 | L2: =+L17/1000 -> 666.97613 | M2: =+M17/1000 -> 729.50446 | N2: =+N17/1000 -> 586.01155 | O2: =+O17/1000 -> 976.72234 | V2: enro a septiembre 2025
B3: País | C3: Concepto | D3: 45658 | E3: 45689 | F3: 45717 | G3: 45748 | H3: 45778 | I3: 45809 | J3: 45839 | K3: 45870 | L3: 45901 | M3: 45931 | N3: 45962 | O3: 45992 | P3: Total | R3: País | S3: Concepto | T3: 45658 | V3: PAIS | W3: CONCEPTO | X3: MUS$
B4: Chile | C4: INGRESOS OP | D4: =+'Flujo Redco Chile'!C12 -> 362362.73 | E4: =+'Flujo Redco Chile'!D12 -> 547310.62 | F4: =+'Flujo Redco Chile'!E12 -> 389727.46 | G4: =+'Flujo Redco Chile'!F12 -> 237434.48 | H4: =+'Flujo Redco Chile'!G12 -> 272631.08 | I4: =+'Flujo Redco Chile'!H12 -> 277419.07 | J4: =+'Flujo Redco Chile'!I12 -> 475570.75 | K4: =+'Flujo Redco Chile'!J12 -> 151482.74 | ... O4: =+'Flujo Redco Chile'!N12 -> 173207.55 | P4: =SUM(D4:O4) -> 3592126.9 | R4: Chile | S4: SALDO INICIAL | T4: =+'Flujo Redco Chile'!C8 -> 52257.137 | V4: Chile | W4: INGRESO NETO | X4: =SUM(D4:L4) -> 3011864
B5: Perú | C5: INGRESOS OP | D5: =+'Flujo Redco Perú'!C13 -> 123848 | E5: =+'Flujo Redco Perú'!D13 -> 62454 | F5: =+'Flujo Redco Perú'!E13 -> 105377 | G5: =+'Flujo Redco Perú'!F13 -> 110077 | H5: =+'Flujo Redco Perú'!G13 -> 142610 | I5: =+'Flujo Redco Perú'!H13 -> 229588 | J5: =+'Flujo Redco Perú'!I13 -> 251702 | K5: =+'Flujo Redco Perú'!J13 -> 641573 | ... O5: =+'Flujo Redco Perú'!N13 -> 269432 | P5: =SUM(D5:O5) -> 2417353 | R5: Perú | S5: SALDO INICIAL | T5: =+'Flujo Redco Perú'!C9 -> 136767.69 | V5: Perú | W5: INGRESO NETO | X5: =SUM(D5:L5) -> 1786362
