Workbook
Name RutaCarpeta: #REF!

Sheet Resumen Forecast 25´
A1: Ítem | B1: 45658 | C1: 45689 | D1: 45717 | E1: 45748 | F1: 45778 | G1: 45809 | H1: 45839 | I1: 45870 | J1: 45901 | K1: 45931 | L1: 45962 | M1: 45992 | O1: Ítem | P1: Total | Q1: Promedio
A2: Propuestas | B2: 2212 | C2: 2571 | D2: 6130 | E2: 4378 | F2: 3026 | G2: =+G3/0.43 -> 1618.6047 | H2: =+H3/0.43 -> 1531.6279 | I2: =+I3/0.43 -> 2046.5116 | J2: =+J3/0.43 -> 1472.093 | K2: =+K3/0.43 -> 1006.9767 | L2: =+L3/0.43 -> 1393.0233 | M2: =+M3/0.43 -> 3037.2093 | O2: Propuestas | P2: =+SUM(B2:M2) -> 30423.047 | Q2: =+AVERAGE(B2:M2) -> 2535.2539
A3: Ventas | B3: 1056 | C3: 1246 | D3: 736 | E3: 1013 | F3: 968 | G3: 696 | H3: 658.6 | I3: 880 | J3: 633 | K3: 433 | L3: 599 | M3: 1306 | O3: Ventas | P3: =+SUM(B3:M3) -> 10224.6 | Q3: =+AVERAGE(B3:M3) -> 852.05 | V3: Factor EDP | W3: 1.2279086
A4: EDP | B4: =+O34 -> 669.095 | C4: =+P34 -> 891.9687 | D4: =+Q34 -> 693.81329 | E4: =+R34 -> 704.04973 | F4: =+S34 -> 730.257 | G4: =+T34 -> 1177.5466 | H4: =+U34 -> 742.58685 | I4: =+V34 -> 784.663 | ... M4: =+Z34 -> 611.272 | O4: EDP | P4: =+SUM(B4:M4) -> 9344.8999 | Q4: =+AVERAGE(B4:M4) -> 778.74166 | S4: 10596.552 | T4: =+S4-SUM(B4:H4) -> 4987.2348 | V4: Factor Factura | W4: 0.98376235
A5: Facturación | B5: =+O37 -> 822.535 | C5: =+P37 -> 313.029 | D5: =+Q37 -> 798.15916 | E5: =+R37 -> 702.12786 | F5: =+S37 -> 916.262 | G5: =+T37 -> 782.343 | H5: =+U37 -> 894.86126 | I5: =+V37 -> 1334.0146 | ... M5: =+Z37 -> 886.41968 | O5: Facturación | P5: =+SUM(B5:M5) -> 9796.9289 | Q5: =+AVERAGE(B5:M5) -> 816.41074 | S5: 10440.257 | T5: =+T4/5 -> 997.44697
A6: Ingresos | B6: =+O28 -> 717.16573 | C6: =+P28 -> 934.59483 | D6: =+Q28 -> 778.43046 | E6: =+R28 -> 613.92118 | F6: =+S28 -> 647.40508 | G6: =+T28 -> 807.41107 | H6: =+U28 -> 774.98975 | I6: =+V28 -> 1032.2317 | ... M6: =+Z28 -> 845.54106 | O6: Ingresos | P6: =+SUM(B6:M6) -> 9150.6163 | Q6: =+AVERAGE(B6:M6) -> 762.55136 | T6: 845 | U6: =+T5/T6 -> 1.1804106
A7: Gasto | B7: =+O31 -> 502.98161 | C7: =+P31 -> 509.774 | D7: =+Q31 -> 535.88132 | E7: =+R31 -> 549.83671 | F7: =+S31 -> 550.67196 | G7: =+T31 -> 638.75126 | H7: =+U31 -> 597.91154 | I7: =+V31 -> 664.68484 | ... M7: =+Z31 -> 959.54297 | O7: Gasto | P7: =+SUM(B7:M7) -> 7434.7245 | Q7: =+AVERAGE(B7:M7) -> 619.56037 | S7: =+SUM(B5:H5) -> 5229.3173 | T7: =+S5-S7 -> 5210.9399 | U7: =+T7/5 -> 1042.188
A8: Beneficio | B8: =+B6-B7 -> 214.18413 | C8: =+C6-C7 -> 424.82083 | D8: =+D6-D7 -> 242.54914 | E8: =+E6-E7 -> 64.084471 | F8: =+F6-F7 -> 96.733125 | G8: =+G6-G7 -> 168.65981 | H8: =+H6-H7 -> 177.07821 | I8: =+I6-I7 -> 367.5469 | ... M8: =+M6-M7 -> -114.00191 | O8: Beneficio | P8: =+SUM(B8:M8) -> 1715.8919 | Q8: =+AVERAGE(B8:M8) -> 142.99099 | T8: =+SUM(I5:M5) -> 4567.6116 | U8: 845
A9: Margen % | B9: =+B8/B6 -> 0.2986536 | C9: =+C8/C6 -> 0.45455081 | D9: =+D8/D6 -> 0.31158742 | E9: =+E8/E6 -> 0.1043855 | F9: =+F8/F6 -> 0.14941669 | G9: =+G8/G6 -> 0.20888964 | H9: =+H8/H6 -> 0.22849103 | I9: =+I8/I6 -> 0.35607014 | ... M9: =+M8/M6 -> -0.13482717 | O9: Margen % | P9: =+P8/P6 -> 0.18751653 | Q9: =+AVERAGE(B9:M9) -> 0.17046786 | T9: =+T7/T8 -> 1.1408457 | U9: =+U7/U8 -> 1.2333585
B10: =+SUM($B$8:B8) -> 214.18413 | C10: =+SUM($B$8:C8) -> 639.00496 | D10: =+SUM($B$8:D8) -> 881.5541 | E10: =+SUM($B$8:E8) -> 945.63857 | F10: =+SUM($B$8:F8) -> 1042.3717 | G10: =+SUM($B$8:G8) -> 1211.0315 | H10: =+SUM($B$8:H8) -> 1388.1097 | I10: =+SUM($B$8:I8) -> 1755.6566 | ... M10: =+SUM($B$8:M8) -> 1715.8919
S11: =+S5*'Resumen Budget 25´'!S4 -> 10596.552
V15: =+P6*Resumen!G36 -> 9169.226 | W15: =+V15-SUM(B5:K5) -> 994.48769 | Y15: =+P5*Resumen!G35 -> 9943.5928 | Z15: =+Y15-SUM(B4:K4) -> 2013.2078
W16: =+W15/2 -> 497.24384 | Z16: =+Z15/2 -> 1006.6039
W17: =+'Resumen Budget 25´'!K5 -> 845 | Z17: 845
W18: =+W16/W17 -> 0.58845425 | Z18: =+Z16/Z17 -> 1.1912472
N27: Ingreso | O27: 717165.73 | P27: 934594.83 | Q27: 778430.46 | R27: 613921.18 | S27: 647405.08 | T27: 807411.07 | U27: 774989.75 | V27: 1032231.7 | W27: 620646.05 | X27: 793777.46 | Y27: 584501.93 | Z27: 845541.06 | AA27: =+SUM(O27:Z27) -> 9150616.3
O28: =+O27/1000 -> 717.16573 | P28: =+P27/1000 -> 934.59483 | Q28: =+Q27/1000 -> 778.43046 | R28: =+R27/1000 -> 613.92118 | S28: =+S27/1000 -> 647.40508 | T28: =+T27/1000 -> 807.41107 | U28: =+U27/1000 -> 774.98975 | V28: =+V27/1000 -> 1032.2317 | ... Z28: =+Z27/1000 -> 845.54106
N30: Gasto | O30: 502981.61 | P30: 509774 | Q30: 535881.32 | R30: 549836.71 | S30: 550671.96 | T30: 638751.26 | U30: 597911.54 | V30: 664684.84 | W30: 642343.95 | X30: 659040.33 | Y30: 623303.99 | Z30: 959542.97 | AA30: =+SUM(O30:Z30) -> 7434724.5
O31: =+O30/1000 -> 502.98161 | P31: =+P30/1000 -> 509.774 | Q31: =+Q30/1000 -> 535.88132 | R31: =+R30/1000 -> 549.83671 | S31: =+S30/1000 -> 550.67196 | T31: =+T30/1000 -> 638.75126 | U31: =+U30/1000 -> 597.91154 | V31: =+V30/1000 -> 664.68484 | ... Z31: =+Z30/1000 -> 959.54297
A33: Item | B33: Acum | N33: EDP | O33: 669095 | P33: 891968.7 | Q33: 693813.29 | R33: 704049.73 | S33: 730257 | T33: 1177546.6 | U33: 742586.85 | V33: 784663 | W33: 676238.04 | X33: 860166.81 | Y33: 803242.9 | Z33: 611272 | AA33: =+SUM(O33:Z33) -> 9344899.9
A34: Propuestas | B34: =+SUM($B2:F2) -> 18317 | O34: =+O33/1000 -> 669.095 | P34: =+P33/1000 -> 891.9687 | Q34: =+Q33/1000 -> 693.81329 | R34: =+R33/1000 -> 704.04973 | S34: =+S33/1000 -> 730.257 | T34: =+T33/1000 -> 1177.5466 | U34: =+U33/1000 -> 742.58685 | V34: =+V33/1000 -> 784.663 | ... Z34: =+Z33/1000 -> 611.272
A35: Ventas | B35: =+SUM($B3:F3) -> 5019
A36: EDP | B36: =+SUM($B4:F4) -> 3689.1837 | N36: Facturación | O36: 822535 | P36: 313029 | Q36: 798159.16 | R36: 702127.86 | S36: 916262 | T36: 782343 | U36: 894861.26 | V36: 1334014.6 | W36: 726924.49 | X36: 884482 | Y36: 735770.82 | Z36: 886419.68 | AA36: =+SUM(O36:Z36) -> 9796928.9
A37: Facturación | B37: =+SUM($B5:F5) -> 3552.113 | O37: =+O36/1000 -> 822.535 | P37: =+P36/1000 -> 313.029 | Q37: =+Q36/1000 -> 798.15916 | R37: =+R36/1000 -> 702.12786 | S37: =+S36/1000 -> 916.262 | T37: =+T36/1000 -> 782.343 | U37: =+U36/1000 -> 894.86126 | V37: =+V36/1000 -> 1334.0146 | ... Z37: =+Z36/1000 -> 886.41968
A38: Ingresos | B38: =+SUM($B6:F6) -> 3691.5173
A39: Gasto | B39: =+SUM($B7:F7) -> 2649.1456
A40: Beneficio | B40: =+SUM($B8:F8) -> 1042.3717
A41: Margen % | B41: =+B40/B38 -> 0.28236945

Sheet Resumen Budget 25´
A1: Ítem | B1: 45658 | C1: 45689 | D1: 45717 | E1: 45748 | F1: 45778 | G1: 45809 | H1: 45839 | I1: 45870 | J1: 45901 | K1: 45931 | L1: 45962 | M1: 45992 | O1: Ítem | P1: Total | Q1: Promedio
A2: Propuestas | B2: =+B3/0.43 -> 2162.7907 | C2: =+C3/0.43 -> 2344.186 | D2: =+D3/0.43 -> 3697.6744 | E2: =+E3/0.43 -> 3269.7674 | F2: =+F3/0.43 -> 1703.1395 | G2: =+G3/0.43 -> 1703.1395 | H2: =+H3/0.43 -> 1703.1395 | I2: =+I3/0.43 -> 1703.1395 | ... M2: =+M3/0.43 -> 1247.907 | O2: Propuestas | P2: =+SUM(B2:M2) -> 25116.279 | Q2: =+AVERAGE(B2:M2) -> 2093.0233
A3: Ventas | B3: 930 | C3: 1008 | D3: 1590 | E3: 1406 | F3: 732.35 | G3: 732.35 | H3: 732.35 | I3: 732.35 | J3: 800 | K3: 800 | L3: 800 | M3: 536.6 | O3: Ventas | P3: =+SUM(B3:M3) -> 10800 | Q3: =+AVERAGE(B3:M3) -> 900
A4: EDP | B4: =+'[1]Resumen 2025'!C11 -> 753.937 | C4: =+'[1]Resumen 2025'!D11 -> 843.38067 | D4: =+'[1]Resumen 2025'!E11 -> 899.04433 | E4: =+'[1]Resumen 2025'!F11 -> 1040.236 | F4: =+'[1]Resumen 2025'!G11 -> 859.26633 | G4: =+'[1]Resumen 2025'!H11 -> 724.37967 | H4: =+'[1]Resumen 2025'!I11 -> 845 | I4: =+'[1]Resumen 2025'!J11 -> 845 | ... M4: =+'[1]Resumen 2025'!N11 -> 656.522 | O4: POM | P4: =+SUM(B4:M4) -> 10001.766 | Q4: =+AVERAGE(B4:M4) -> 833.4805 | S4: =+P4/P5 -> 1.0149704
A5: Facturación | B5: =+'[1]Resumen 2025'!C12 -> 509 | C5: =+'[1]Resumen 2025'!D12 -> 753.937 | D5: =+'[1]Resumen 2025'!E12 -> 843.38067 | E5: =+'[1]Resumen 2025'!F12 -> 899.04433 | F5: =+'[1]Resumen 2025'!G12 -> 1040.236 | G5: =+'[1]Resumen 2025'!H12 -> 859.26633 | H5: =+'[1]Resumen 2025'!I12 -> 724.37967 | I5: =+'[1]Resumen 2025'!J12 -> 845 | ... M5: =+'[1]Resumen 2025'!N12 -> 845 | O5: Facturación | P5: =+SUM(B5:M5) -> 9854.244 | Q5: =+AVERAGE(B5:M5) -> 821.187
A6: Ingresos | B6: =+'[1]Resumen 2025'!C13 -> 825 | C6: =+'[1]Resumen 2025'!D13 -> 509 | D6: =+'[1]Resumen 2025'!E13 -> 753.937 | E6: =+'[1]Resumen 2025'!F13 -> 843.38067 | F6: =+'[1]Resumen 2025'!G13 -> 899.04433 | G6: =+'[1]Resumen 2025'!H13 -> 1040.236 | H6: =+'[1]Resumen 2025'!I13 -> 859.26633 | I6: =+'[1]Resumen 2025'!J13 -> 724.37967 | ... M6: =+'[1]Resumen 2025'!N13 -> 845 | O6: Ingresos | P6: =+SUM(B6:M6) -> 9834.244 | Q6: =+AVERAGE(B6:M6) -> 819.52033
A7: Gasto | B7: =+'[1]Resumen 2025'!C15 -> 695.28316 | C7: =+'[1]Resumen 2025'!D15 -> 507.61468 | D7: =+'[1]Resumen 2025'!E15 -> 519.11468 | E7: =+'[1]Resumen 2025'!F15 -> 514.39511 | F7: =+'[1]Resumen 2025'!G15 -> 547.45874 | G7: =+'[1]Resumen 2025'!H15 -> 547.10729 | H7: =+'[1]Resumen 2025'!I15 -> 590.31705 | I7: =+'[1]Resumen 2025'!J15 -> 542.07076 | ... M7: =+'[1]Resumen 2025'!N15 -> 593.83879 | O7: Gasto | P7: =+SUM(B7:M7) -> 6709.0792 | Q7: =+AVERAGE(B7:M7) -> 559.08993
A8: Beneficio | B8: =+B6-B7 -> 129.71684 | C8: =+C6-C7 -> 1.3853225 | D8: =+D6-D7 -> 234.82232 | E8: =+E6-E7 -> 328.98555 | F8: =+F6-F7 -> 351.5856 | G8: =+G6-G7 -> 493.12871 | H8: =+H6-H7 -> 268.94928 | I8: =+I6-I7 -> 182.3089 | ... M8: =+M6-M7 -> 251.16121 | O8: Beneficio | P8: =+SUM(B8:M8) -> 3125.1648 | Q8: =+AVERAGE(B8:M8) -> 260.4304
A9: Margen % | B9: =+B8/B6 -> 0.15723254 | C9: =+C8/C6 -> 0.0027216553 | D9: =+D8/D6 -> 0.31146147 | E9: =+E8/E6 -> 0.39007955 | F9: =+F8/F6 -> 0.39106592 | G9: =+G8/G6 -> 0.47405465 | H9: =+H8/H6 -> 0.31299874 | I9: =+I8/I6 -> 0.2516759 | ... M9: =+M8/M6 -> 0.2972322 | O9: Margen % | P9: =+P8/P6 -> 0.31778394 | Q9: =+AVERAGE(B9:M9) -> 0.30280303
B10: =+SUM($B$8:B8) -> 129.71684 | C10: =+SUM($B$8:C8) -> 131.10217 | D10: =+SUM($B$8:D8) -> 365.92449 | E10: =+SUM($B$8:E8) -> 694.91004 | F10: =+SUM($B$8:F8) -> 1046.4956 | G10: =+SUM($B$8:G8) -> 1539.6244 | H10: =+SUM($B$8:H8) -> 1808.5736 | I10: =+SUM($B$8:I8) -> 1990.8825 | ... M10: =+SUM($B$8:M8) -> 3125.1648
A33: Propuestas | B33: =+SUM($B2:F2) -> 13177.558
A34: Ventas | B34: =+SUM($B3:F3) -> 5666.35
A35: EDP | B35: =+SUM($B4:F4) -> 4395.8643
A36: Facturación | B36: =+SUM($B5:F5) -> 4045.598
A37: Ingresos | B37: =+SUM($B6:F6) -> 3830.362
A38: Gasto | B38: =+SUM($B7:F7) -> 2783.8664
A39: Beneficio | B39: =+SUM($B8:F8) -> 1046.4956
A40: Margen % | B40: =+B39/B37 -> 0.27321064

Sheet Resumen
A1: RESUMEN GESTIÓN
A3: Item | B3: 45687 | C3: 45716 | D3: 45745 | E3: 45774 | F3: 45803 | G3: 45832 | H3: 45862 | I3: 45893 | J3: 45924 | K3: 45954 | L3: 45985 | M3: 46015 | N3: Total Acum | O3: Promedio | P3: Var.% mes
A4: Venta Budget | B4: =+'Resumen Budget 25´'!B3 -> 930 | C4: =+'Resumen Budget 25´'!C3 -> 1008 | D4: =+'Resumen Budget 25´'!D3 -> 1590 | E4: =+'Resumen Budget 25´'!E3 -> 1406 | F4: =+'Resumen Budget 25´'!F3 -> 732.35 | G4: =+'Resumen Budget 25´'!G3 -> 732.35 | H4: =+'Resumen Budget 25´'!H3 -> 732.35 | I4: =+'Resumen Budget 25´'!I3 -> 732.35 | ... M4: =+'Resumen Budget 25´'!M3 -> 536.6 | N4: =+SUM(B4:M4) -> 10800 | O4: =+AVERAGE(B4:M4) -> 900 | P4: =+K5-K4 -> -367
A5: Venta Real | B5: =+'Resumen Forecast 25´'!B3 -> 1056 | C5: =+'Resumen Forecast 25´'!C3 -> 1246 | D5: =+'Resumen Forecast 25´'!D3 -> 736 | E5: =+'Resumen Forecast 25´'!E3 -> 1013 | F5: =+'Resumen Forecast 25´'!F3 -> 968 | G5: =+'Resumen Forecast 25´'!G3 -> 696 | H5: =+'Resumen Forecast 25´'!H3 -> 658.6 | I5: =+'Resumen Forecast 25´'!I3 -> 880 | ... M5: =+'Resumen Forecast 25´'!M3 -> 1306 | N5: =+SUM(B5:M5) -> 10224.6 | O5: =+AVERAGE(B5:M5) -> 852.05 | P5: =+P4/K4 -> -0.45875
A6: EDP Budget | B6: 753.937 | C6: 843.38067 | D6: 899.04433 | E6: 1040.236 | F6: 859.26633 | G6: 724.37967 | H6: 845 | I6: =+'Resumen Budget 25´'!I4 -> 845 | J6: =+'Resumen Budget 25´'!J4 -> 845 | K6: =+'Resumen Budget 25´'!K4 -> 845 | L6: =+'Resumen Budget 25´'!L4 -> 845 | M6: =+'Resumen Budget 25´'!M4 -> 656.522 | N6: =+SUM(B6:M6) -> 10001.766 | O6: =+AVERAGE(B6:M6) -> 833.4805 | P6: =+K7-K6 -> 15.166813
A7: EDP Real | B7: =+'Resumen Forecast 25´'!B4 -> 669.095 | C7: =+'Resumen Forecast 25´'!C4 -> 891.9687 | D7: =+'Resumen Forecast 25´'!D4 -> 693.81329 | E7: =+'Resumen Forecast 25´'!E4 -> 704.04973 | F7: =+'Resumen Forecast 25´'!F4 -> 730.257 | G7: =+'Resumen Forecast 25´'!G4 -> 1177.5466 | H7: =+'Resumen Forecast 25´'!H4 -> 742.58685 | I7: =+'Resumen Forecast 25´'!I4 -> 784.663 | ... M7: =+'Resumen Forecast 25´'!M4 -> 611.272 | N7: =+SUM(B7:M7) -> 9344.8999 | O7: =+AVERAGE(B7:M7) -> 778.74166 | P7: =+P6/K6 -> 0.017948891
A8: Facturación Budget | B8: 509 | C8: 753.937 | D8: 843.38067 | E8: 899.04433 | F8: 1040.236 | G8: 859.26633 | H8: 724.37967 | I8: =+'Resumen Budget 25´'!I5 -> 845 | J8: =+'Resumen Budget 25´'!J5 -> 845 | K8: =+'Resumen Budget 25´'!K5 -> 845 | L8: =+'Resumen Budget 25´'!L5 -> 845 | M8: =+'Resumen Budget 25´'!M5 -> 845 | N8: =+SUM(B8:M8) -> 9854.244 | O8: =+AVERAGE(B8:M8) -> 821.187 | P8: =+K9-K8 -> 39.482
A9: Facturación Real | B9: =+'Resumen Forecast 25´'!B5 -> 822.535 | C9: =+'Resumen Forecast 25´'!C5 -> 313.029 | D9: =+'Resumen Forecast 25´'!D5 -> 798.15916 | E9: =+'Resumen Forecast 25´'!E5 -> 702.12786 | F9: =+'Resumen Forecast 25´'!F5 -> 916.262 | G9: =+'Resumen Forecast 25´'!G5 -> 782.343 | H9: =+'Resumen Forecast 25´'!H5 -> 894.86126 | I9: =+'Resumen Forecast 25´'!I5 -> 1334.0146 | ... M9: =+'Resumen Forecast 25´'!M5 -> 886.41968 | N9: =+SUM(B9:M9) -> 9796.9289 | O9: =+AVERAGE(B9:M9) -> 816.41074 | P9: =+P8/K8 -> 0.04672426
A10: Ingresos Budget | B10: 825 | C10: 509 | D10: 753.937 | E10: 843.38067 | F10: 899.04433 | G10: 1040.236 | H10: 859 | I10: =+'Resumen Budget 25´'!I6 -> 724.37967 | J10: =+'Resumen Budget 25´'!J6 -> 845 | K10: =+'Resumen Budget 25´'!K6 -> 845 | L10: =+'Resumen Budget 25´'!L6 -> 845 | M10: =+'Resumen Budget 25´'!M6 -> 845 | N10: =+SUM(B10:M10) -> 9833.9777 | O10: =+AVERAGE(B10:M10) -> 819.49814 | P10: =+K11-K10 -> -51.22254
A11: Ingresos Real | B11: =+'Resumen Forecast 25´'!B6 -> 717.16573 | C11: =+'Resumen Forecast 25´'!C6 -> 934.59483 | D11: =+'Resumen Forecast 25´'!D6 -> 778.43046 | E11: =+'Resumen Forecast 25´'!E6 -> 613.92118 | F11: =+'Resumen Forecast 25´'!F6 -> 647.40508 | G11: =+'Resumen Forecast 25´'!G6 -> 807.41107 | H11: =+'Resumen Forecast 25´'!H6 -> 774.98975 | I11: =+'Resumen Forecast 25´'!I6 -> 1032.2317 | ... M11: =+'Resumen Forecast 25´'!M6 -> 845.54106 | N11: =+SUM(B11:M11) -> 9150.6163 | O11: =+AVERAGE(B11:M11) -> 762.55136 | P11: =+P10/K10 -> -0.06061839
A12: Gastos Budget | B12: 695.28316 | C12: 507.61468 | D12: 519.11468 | E12: 514.39511 | F12: 547.45874 | G12: 547.10729 | H12: 590.31705 | I12: =+'Resumen Budget 25´'!I7 -> 542.07076 | J12: =+'Resumen Budget 25´'!J7 -> 536.52729 | K12: =+'Resumen Budget 25´'!K7 -> 550.87511 | L12: =+'Resumen Budget 25´'!L7 -> 564.47652 | M12: =+'Resumen Budget 25´'!M7 -> 593.83879 | N12: =+SUM(B12:M12) -> 6709.0792 | O12: =+AVERAGE(B12:M12) -> 559.08993 | P12: =+K13-K12 -> 108.16522
A13: Gastos Real | B13: =+'Resumen Forecast 25´'!B7 -> 502.98161 | C13: =+'Resumen Forecast 25´'!C7 -> 509.774 | D13: =+'Resumen Forecast 25´'!D7 -> 535.88132 | E13: =+'Resumen Forecast 25´'!E7 -> 549.83671 | F13: =+'Resumen Forecast 25´'!F7 -> 550.67196 | G13: =+'Resumen Forecast 25´'!G7 -> 638.75126 | H13: =+'Resumen Forecast 25´'!H7 -> 597.91154 | I13: =+'Resumen Forecast 25´'!I7 -> 664.68484 | ... M13: =+'Resumen Forecast 25´'!M7 -> 959.54297 | N13: =+SUM(B13:M13) -> 7434.7245 | O13: =+AVERAGE(B13:M13) -> 619.56037 | P13: =+P12/K12 -> 0.19635162
A14: Margen Operativo Budget | B14: =+B10-B12 -> 129.71684 | C14: =+C10-C12 -> 1.3853225 | D14: =+D10-D12 -> 234.82232 | E14: =+E10-E12 -> 328.98555 | F14: =+F10-F12 -> 351.5856 | G14: =+G10-G12 -> 493.12871 | H14: =+H10-H12 -> 268.68295 | I14: =+I10-I12 -> 182.3089 | ... M14: =+M10-M12 -> 251.16121 | N14: =+SUM(B14:M14) -> 3124.8985 | O14: =+AVERAGE(B14:M14) -> 260.40821 | P14: =+K15-K14 -> -159.38776
A15: Margen Operativo Real | B15: =+B11-B13 -> 214.18413 | C15: =+C11-C13 -> 424.82083 | D15: =+D11-D13 -> 242.54914 | E15: =+E11-E13 -> 64.084471 | F15: =+F11-F13 -> 96.733125 | G15: =+G11-G13 -> 168.65981 | H15: =+H11-H13 -> 177.07821 | I15: =+I11-I13 -> 367.5469 | ... M15: =+M11-M13 -> -114.00191 | N15: =+SUM(B15:M15) -> 1715.8919 | O15: =+AVERAGE(B15:M15) -> 142.99099 | P15: =+P14/K14 -> -0.54190504
A16: % Margen Op. Budget | B16: =+B14/B10 -> 0.15723254 | C16: =+C14/C10 -> 0.0027216553 | D16: =+D14/D10 -> 0.31146147 | E16: =+E14/E10 -> 0.39007955 | F16: =+F14/F10 -> 0.39106592 | G16: =+G14/G10 -> 0.47405465 | H16: =+H14/H10 -> 0.31278573 | I16: =+I14/I10 -> 0.2516759 | ... N16: =+N14/N10 -> 0.31776547 | O16: =+AVERAGE(B16:M16) -> 0.30278528
A17: % Margen Op. Real | B17: =+B15/B11 -> 0.2986536 | C17: =+C15/C11 -> 0.45455081 | D17: =+D15/D11 -> 0.31158742 | E17: =+E15/E11 -> 0.1043855 | F17: =+F15/F11 -> 0.14941669 | G17: =+G15/G11 -> 0.20888964 | H17: =+H15/H11 -> 0.22849103 | I17: =+I15/I11 -> 0.35607014 | ... N17: =+N15/N11 -> 0.18751653 | O17: =+AVERAGE(B17:M17) -> 0.17046786
A19: Caja Real REDCO | N19: =+F19 -> 0
A21: TABLA COMPARATIVA A DICIEMBRE 2025
B22: Budget | C22: Real Acum | D22: Dif. | E22: Var.% | G22: CumpMimiento A NOV | I22: CumpMimiento aM 2025
A23: Ventas | B23: =+N4 -> 10800 | C23: =+N5 -> 10224.6 | D23: =+C23-B23 -> -575.4 | E23: =+D23/B23 -> -0.053277778 | G23: =+C23/B23 -> 0.94672222 | I23: =+C23/B34 -> 0.94672222
A24: EDP | B24: =+N6 -> 10001.766 | C24: =+N7 -> 9344.8999 | D24: =+C24-B24 -> -656.86609 | E24: =+D24/B24 -> -0.065675011 | G24: =+C24/B24 -> 0.93432499 | I24: =+C24/B35 -> 0.93432499
A25: Facturación | B25: =+N8 -> 9854.244 | C25: =+N9 -> 9796.9289 | D25: =+C25-B25 -> -57.315149 | E25: =+D25/B25 -> -0.0058162908 | G25: =+C25/B25 -> 0.99418371 | I25: =+C25/B36 -> 0.99418371
A26: Ingresos | B26: =+N10 -> 9833.9777 | C26: =+N11 -> 9150.6163 | D26: =+C26-B26 -> -683.36132 | E26: =+D26/B26 -> -0.069489818 | G26: =+C26/B26 -> 0.93051018 | I26: =+C26/B37 -> 0.93048498
A27: Gastos | B27: =+N12 -> 6709.0792 | C27: =+N13 -> 7434.7245 | D27: =+C27-B27 -> 725.64531 | E27: =+D27/B27 -> 0.1081587 | G27: =+C27/B27 -> 1.1081587 | I27: =+C27/B38 -> 1.1081587
A28: Margen Operativo | B28: =+B26-B27 -> 3124.8985 | C28: =+C26-C27 -> 1715.8919 | D28: =+C28-B28 -> -1409.0066 | E28: =+D28/B28 -> -0.45089677 | G28: =+C28/B28 -> 0.54910323 | I28: =+C28/B39 -> 0.54905644
A29: % Margen OP. | B29: =+B28/B26 -> 0.31776547 | C29: =+C28/C26 -> 0.18751653 | D29: =+C29-B29 -> -0.13024893 | E29: =+D29/B29 -> -0.40989014
A32: TABMA COMPARATIVA AÑO 2025
B33: Budget 25 | C33: Forecast 25 | D33: Dif. | E33: Var.%
A34: Ventas | B34: 10800 | C34: =+'Resumen Forecast 25´'!P3 -> 10224.6 | D34: =+C34-B34 -> -575.4 | E34: =+D34/B34 -> -0.053277778
A35: EDP | B35: 10001.766 | C35: =+'Resumen Forecast 25´'!P4 -> 9344.8999 | D35: =+C35-B35 -> -656.86609 | E35: =+D35/B35 -> -0.065675011 | G35: =+B35/B36 -> 1.0149704
A36: Facturación | B36: 9854.244 | C36: =+'Resumen Forecast 25´'!P5 -> 9796.9289 | D36: =+C36-B36 -> -57.315149 | E36: =+D36/B36 -> -0.0058162908 | G36: =+B36/B37 -> 1.0020337 | O36: =+B36*O37 -> 9169.226 | P36: =+O36-N9 -> -627.70281 | Q36: =+P36/8 -> -78.462851
A37: Ingresos | B37: 9834.244 | C37: =+'Resumen Forecast 25´'!P6 -> 9150.6163 | D37: =+C37-B37 -> -683.62765 | E37: =+D37/B37 -> -0.069515019 | O37: =+C37/B37 -> 0.93048498
A38: Gastos | B38: 6709.0792 | C38: =+'Resumen Forecast 25´'!P7 -> 7434.7245 | D38: =+C38-B38 -> 725.64531 | E38: =+D38/B38 -> 0.1081587
A39: Margen Operativo | B39: =+B37-B38 -> 3125.1648 | C39: =+C37-C38 -> 1715.8919 | D39: =+C39-B39 -> -1409.273 | E39: =+D39/B39 -> -0.45094356
A40: % Margen OP. | B40: =+B39/B37 -> 0.31778394 | C40: =+C39/C37 -> 0.18751653 | D40: =+C40-B40 -> -0.13026741 | E40: =+D40/B40 -> -0.40992445
B42: =+B35/B36 -> 1.0149704 | C42: =+C36*B42 -> 9943.5928
A43: RESUMEN GESTIÓN
A45: Item | B45: 45687 | C45: 45716 | D45: 45746 | E45: 45777 | F45: 45808 | G45: 45838 | H45: 45869 | I45: 45900 | J45: 45930 | K45: 45961 | L45: 45991 | M45: 46022
A46: Venta Budget | B46: =+SUM($B$4:B4) -> 930 | C46: =+SUM($B$4:C4) -> 1938 | D46: =+SUM($B$4:D4) -> 3528 | E46: =+SUM($B$4:E4) -> 4934 | F46: =+SUM($B$4:F4) -> 5666.35 | G46: =+SUM($B$4:G4) -> 6398.7 | H46: =+SUM($B$4:H4) -> 7131.05 | I46: =+SUM($B$4:I4) -> 7863.4 | ... M46: =+SUM($B$4:M4) -> 10800
A47: Venta Real | B47: =+SUM($B$5:B5) -> 1056 | C47: =+SUM($B$5:C5) -> 2302 | D47: =+SUM($B$5:D5) -> 3038 | E47: =+SUM($B$5:E5) -> 4051 | F47: =+SUM($B$5:F5) -> 5019 | G47: =+SUM($B$5:G5) -> 5715 | H47: =+SUM($B$5:H5) -> 6373.6 | I47: =+SUM($B$5:I5) -> 7253.6 | ... M47: =+SUM($B$5:M5) -> 10224.6
...

Sheet Dashboard
L2: Modelo de Flujo REDCO
L3: 2025
L4: Dashboard de Decisiones y Resultados
DL8: Casos | DN8: Actual | DO8: Asignado | DP8: No Asignado
C9: Proyectos Contemplados | N9: Personal Proyectado | AA9: Personal Proyectado Chile | AO9: Personal Proyectado Perú | BC9: Personal Proyectado Brasil | BQ9: Personal Proyectado USA | CE9: Personal Proyectado Otros | CS9: Ferias | DL9: Considerar (Si=1; No=0) | DN9: 1 | DO9: 1 | DP9: 1
B10: Año venta | C10: Nombre Proyecto | D10: Nombre Compañía | E10: País Origen | F10: =+'Gantt Proyectos'!L96 -> Monto Contrato | G10: Nivel de Ingeniería | H10: Status General | I10: % Ingreso En base a Pbb Comercial | J10: Activo (1)/ Inactivo (0) | N10: Gerencia General (incluye RRHH) | O10: Gerencia Comercial | P10: Gerentes Ingeniera | Q10: Director de Proyecto | R10: Ingeniero Principal | S10: Ingeniero Senior | T10: Ingeniero de Proyecto | U10: Ingeniero Junior | V10: Ingeniero P&C | W10: Gerencia Contabilidad y Administracion | X10: Total | AA10: Gerencia General (incluye RRHH) | AB10: Gerencia Comercial | AC10: Gerencia Ingeniera | AD10: Gerentes Ingeniera | AE10: Director de Proyecto | AF10: Ingeniero Principal | AG10: Ingeniero Senior | AH10: Ingeniero de Proyecto | AI10: Ingeniero Junior | AJ10: Ingeniero P&C | AK10: Gerencia Contabilidad y Administracion | AL10: Total | AO10: Gerencia General (incluye RRHH) | AP10: Gerencia Comercial | AQ10: Gerencia Ingeniera | AR10: Gerentes Ingeniera | AS10: Director de Proyecto | AT10: Ingeniero Principal | AU10: Ingeniero Senior | AV10: Ingeniero de Proyecto | AW10: Ingeniero Junior | AX10: Ingeniero P&C | AY10: Gerencia Contabilidad y Administracion | AZ10: Total | BC10: Gerencia General (incluye RRHH) | BD10: Gerencia Comercial | BE10: Gerencia Ingeniera | BF10: Gerentes Ingeniera | BG10: Director de Proyecto | BH10: Ingeniero Principal | BI10: Ingeniero Senior | BJ10: Ingeniero de Proyecto | BK10: Ingeniero Junior | BL10: Ingeniero P&C | BM10: Gerencia Contabilidad y Administracion | BN10: Total | BQ10: Gerencia General (incluye RRHH) | BR10: Gerencia Comercial | BS10: Gerencia Ingeniera | BT10: Gerentes Ingeniera | BU10: Director de Proyecto | BV10: Ingeniero Principal | BW10: Ingeniero Senior | BX10: Ingeniero de Proyecto | BY10: Ingeniero Junior | BZ10: Ingeniero P&C | CA10: Gerencia Contabilidad y Administracion | CB10: Total | CE10: Gerencia General (incluye RRHH) | CF10: Gerencia Comercial | CG10: Gerencia Ingeniera | CH10: Gerentes Ingeniera | CI10: Director de Proyecto | CJ10: Ingeniero Principal | CK10: Ingeniero Senior | CL10: Ingeniero de Proyecto | CM10: Ingeniero Junior | CN10: Ingeniero P&C | CO10: Gerencia Contabilidad y Administracion | CP10: Total | CS10: Item | CT10: Feria | CU10: Monto | CV10: Mes | CW10: Aplica (1), No Aplica (2) | DI10: 1. Resultados Flujo de Caja (Proyección desde Mayo)
C11: =+'Gantt Proyectos'!D97 -> CMP: Estrategia Minera para MLC Brownfield | D11: =+'Gantt Proyectos'!E97 -> CMP | E11: =+'Gantt Proyectos'!F97 -> Chile | F11: =+'Gantt Proyectos'!L97 -> 36143 | G11: =+'Gantt Proyectos'!AC97 -> Estudio Conceptual / LOM | H11: =+'Gantt Proyectos'!AD97 -> Actual | I11: 1 | J11: 1 | L11: Actual --> | M11: 45748 | N11: =+'Listas y Parametros'!Q78 -> 6 | O11: =+'Listas y Parametros'!Q79 -> 4 | P11: =+'Listas y Parametros'!Q81 -> 2 | Q11: =+'Listas y Parametros'!Q82 -> 7 | R11: =+'Listas y Parametros'!Q83 -> 8 | S11: =+'Listas y Parametros'!Q84 -> 12 | T11: =+'Listas y Parametros'!Q85 -> 21 | U11: =+'Listas y Parametros'!Q86 -> 13 | V11: =+'Listas y Parametros'!Q87 -> 3 | W11: =+'Listas y Parametros'!Q88 -> 5 | X11: =+SUM(N11:W11) -> 81 | Z11: 45748 | AA11: {=TRANSPOSE('Listas y Parametros'!L78:L88)} -> 2 | AB11: 3 | AC11: 46 | AD11: 2 | AE11: 6 | AF11: 6 | AG11: 9 | AH11: 13 | AI11: 8 | AJ11: 2 | AK11: 4 | AL11: =+SUM(AA11:AB11,AD11:AK11) -> 55 | AN11: 45748 | AO11: {=+TRANSPOSE('Listas y Parametros'!M78:M88)} -> 1 | AP11: 1 | AQ11: 19 | AR11: 0 | AS11: 0 | AT11: 2 | AU11: 3 | AV11: 8 | AW11: 5 | AX11: 1 | AY11: 0 | AZ11: =+SUM(AO11:AP11,AR11:AY11) -> 21 | BB11: 45748 | BC11: {=+TRANSPOSE('Listas y Parametros'!N78:N88)} -> 2 | BD11: 0 | BE11: 1 | BF11: 0 | BG11: 1 | BH11: 0 | BI11: 0 | BJ11: 0 | BK11: 0 | BL11: 0 | BM11: 1 | BN11: =+SUM(BC11:BD11,BF11:BM11) -> 4 | BP11: 45748 | BQ11: {=+TRANSPOSE('Listas y Parametros'!O78:O88)} -> 1 | BR11: 0 | BS11: 0 | BT11: 0 | BU11: 0 | BV11: 0 | BW11: 0 | BX11: 0 | BY11: 0 | BZ11: 0 | CA11: 0 | CB11: =+SUM(BQ11:BR11,BT11:CA11) -> 1 | CD11: 45748 | CE11: {=+TRANSPOSE('Listas y Parametros'!P78:P88)} -> 0 | CF11: 0 | CG11: 0 | CH11: 0 | CI11: 0 | CJ11: 0 | CK11: 0 | CL11: 0 | CM11: 0 | CN11: 0 | CO11: 0 | CP11: =+SUM(CE11:CF11,CH11:CO11) -> 0 | CS11: Chile | CT11: =+'Listas y Parametros'!C219 -> The Electric Mine | CU11: =+'Listas y Parametros'!D219 -> 2000 | CV11: =+'Listas y Parametros'!E219 -> 45777 | CW11: 1 | DI11: Ingreso | DJ11: Total | DK11: Acumulado | DL11: 45687 | DM11: 45716 | DN11: 45746 | DO11: 45777 | DP11: 45807 | DQ11: 45838 | DR11: 45868 | DS11: 45899 | DT11: 45930 | DU11: 45960 | DV11: 45991 | DW11: 46021
C12: =+'Gantt Proyectos'!D98 -> Spence: Analisis proyecto SCUT | D12: =+'Gantt Proyectos'!E98 -> BHP | E12: =+'Gantt Proyectos'!F98 -> Chile | F12: =+'Gantt Proyectos'!L98 -> 47590 | G12: =+'Gantt Proyectos'!AC98 -> Confiabilidad Planes | H12: =+'Gantt Proyectos'!AD98 -> Actual | I12: 1 | J12: 1 | M12: 45778 | N12: =+AA12+AO12+BC12+BQ12+CE12 -> 6 | O12: =+AB12+AP12+BD12+BR12+CF12 -> 4 | P12: =+AD12+AR12+BF12+BT12+CH12 -> 2 | Q12: =+AE12+AS12+BG12+BU12+CI12 -> 7 | R12: =+AF12+AT12+BH12+BV12+CJ12 -> 8 | S12: =+AG12+AU12+BI12+BW12+CK12 -> 12 | T12: =+AH12+AV12+BJ12+BX12+CL12 -> 21 | U12: =+AI12+AW12+BK12+BY12+CM12 -> 13 | V12: =+AJ12+AX12+BL12+BZ12+CN12 -> 3 | W12: =+AK12+AY12+BM12+CA12+CO12 -> 5 | X12: =+SUM(N12:W12) -> 81 | Z12: 45778 | AA12: 2 | AB12: 3 | AC12: 46 | AD12: 2 | AE12: 6 | AF12: 6 | AG12: 9 | AH12: 13 | AI12: 8 | AJ12: 2 | AK12: 4 | AL12: =+SUM(AA12:AB12,AD12:AK12) -> 55 | AN12: 45778 | AO12: 1 | AP12: 1 | AQ12: 19 | AR12: 0 | AS12: 0 | AT12: 2 | AU12: 3 | AV12: 8 | AW12: 5 | AX12: 1 | AY12: 0 | AZ12: =+SUM(AO12:AP12,AR12:AY12) -> 21 | BB12: 45778 | BC12: 2 | BD12: 0 | BE12: 1 | BF12: 0 | BG12: 1 | BH12: 0 | BI12: 0 | BJ12: 0 | BK12: 0 | BL12: 0 | BM12: 1 | BN12: =+SUM(BC12:BD12,BF12:BM12) -> 4 | BP12: 45778 | BQ12: 1 | BR12: 0 | BS12: 0 | BT12: 0 | BU12: 0 | BV12: 0 | BW12: 0 | BX12: 0 | BY12: 0 | BZ12: 0 | CA12: 0 | CB12: =+SUM(BQ12:BR12,BT12:CA12) -> 1 | CD12: 45778 | CE12: 0 | CF12: 0 | CG12: 0 | CH12: 0 | CI12: 0 | CJ12: 0 | CK12: 0 | CL12: 0 | CM12: 0 | CN12: 0 | CO12: 0 | CP12: =+SUM(CE12:CF12,CH12:CO12) -> 0 | CT12: =+'Listas y Parametros'!C220 -> Gecamin-Mineplanning | CU12: =+'Listas y Parametros'!D220 -> 9000 | CV12: =+'Listas y Parametros'!E220 -> 45777 | CW12: 1 | DI12: Chile | DJ12: =+SUM(DL12:DW12) -> 3351934.6 | DK12: =+SUM(DL12:DS12) -> 2874423.8 | DL12: 362362.73 | DM12: 547310.62 | DN12: 394993.26 | DO12: 247866.97 | DP12: 312930.59 | DQ12: 277419.07 | DR12: 542984.75 | DS12: 188555.82 | DT12: =+'Flujo Caja'!M14 -> 168877.69 | DU12: =+'Flujo Caja'!N14 -> 168877.69 | DV12: =+'Flujo Caja'!O14 -> 69877.689 | DW12: =+'Flujo Caja'!P14 -> 69877.689
C13: =+'Gantt Proyectos'!D99 -> Resolution: MinePlan Review (Scoping) | D13: =+'Gantt Proyectos'!E99 -> BHP | E13: =+'Gantt Proyectos'!F99 -> Chile | F13: =+'Gantt Proyectos'!L99 -> 254012 | G13: =+'Gantt Proyectos'!AC99 -> Scoping | H13: =+'Gantt Proyectos'!AD99 -> Actual | I13: 1 | J13: 1 | M13: 45809 | N13: =+AA13+AO13+BC13+BQ13+CE13 -> 6 | O13: =+AB13+AP13+BD13+BR13+CF13 -> 4 | P13: =+AD13+AR13+BF13+BT13+CH13 -> 2 | Q13: =+AE13+AS13+BG13+BU13+CI13 -> 7 | R13: =+AF13+AT13+BH13+BV13+CJ13 -> 8 | S13: =+AG13+AU13+BI13+BW13+CK13 -> 12 | T13: =+AH13+AV13+BJ13+BX13+CL13 -> 21 | U13: =+AI13+AW13+BK13+BY13+CM13 -> 13 | V13: =+AJ13+AX13+BL13+BZ13+CN13 -> 3 | W13: =+AK13+AY13+BM13+CA13+CO13 -> 5 | X13: =+SUM(N13:W13) -> 81 | Z13: 45809 | AA13: 2 | AB13: 3 | AC13: 46 | AD13: 2 | AE13: 6 | AF13: 6 | AG13: 9 | AH13: 13 | AI13: 8 | AJ13: 2 | AK13: 4 | AL13: =+SUM(AA13:AB13,AD13:AK13) -> 55 | AN13: 45809 | AO13: 1 | AP13: 1 | AQ13: 19 | AR13: 0 | AS13: 0 | AT13: 2 | AU13: 3 | AV13: 8 | AW13: 5 | AX13: 1 | AY13: 0 | AZ13: =+SUM(AO13:AP13,AR13:AY13) -> 21 | BB13: 45809 | BC13: 2 | BD13: 0 | BE13: 1 | BF13: 0 | BG13: 1 | BH13: 0 | BI13: 0 | BJ13: 0 | BK13: 0 | BL13: 0 | BM13: 1 | BN13: =+SUM(BC13:BD13,BF13:BM13) -> 4 | BP13: 45809 | BQ13: 1 | BR13: 0 | BS13: 0 | BT13: 0 | BU13: 0 | BV13: 0 | BW13: 0 | BX13: 0 | BY13: 0 | BZ13: 0 | CA13: 0 | CB13: =+SUM(BQ13:BR13,BT13:CA13) -> 1 | CD13: 45809 | CE13: 0 | CF13: 0 | CG13: 0 | CH13: 0 | CI13: 0 | CJ13: 0 | CK13: 0 | CL13: 0 | CM13: 0 | CN13: 0 | CO13: 0 | CP13: =+SUM(CE13:CF13,CH13:CO13) -> 0 | CT13: =+'Listas y Parametros'!C221 -> Congreso - IIMCH | CU13: =+'Listas y Parametros'!D222 -> 13000 | CV13: =+'Listas y Parametros'!E221 -> 45960 | CW13: 1 | DI13: Perú | DJ13: =+SUM(DL13:DW13) -> 3049795.6 | DK13: =+SUM(DL13:DS13) -> 1667229 | DL13: 123848 | DM13: 62454 | DN13: 105377 | DO13: 110077 | DP13: 142610 | DQ13: 229588 | DR13: 251702 | DS13: 641573 | DT13: =+'Flujo Caja'!M17 -> 393534.51 | DU13: =+'Flujo Caja'!N17 -> 420617.85 | DV13: =+'Flujo Caja'!O17 -> 285332.13 | DW13: =+'Flujo Caja'!P17 -> 283082.13
C14: =+'Gantt Proyectos'!D100 -> Twin Metals: Analisis integrado con Northmet | D14: =+'Gantt Proyectos'!E100 -> Twin Metals | E14: =+'Gantt Proyectos'!F100 -> Chile | F14: =+'Gantt Proyectos'!L100 -> 132000 | G14: =+'Gantt Proyectos'!AC100 -> Estudio Conceptual / LOM | H14: =+'Gantt Proyectos'!AD100 -> Actual | I14: 1 | J14: 1 | M14: 45839 | N14: =+AA14+AO14+BC14+BQ14+CE14 -> 6 | O14: =+AB14+AP14+BD14+BR14+CF14 -> 4 | P14: =+AD14+AR14+BF14+BT14+CH14 -> 2 | Q14: =+AE14+AS14+BG14+BU14+CI14 -> 7 | R14: =+AF14+AT14+BH14+BV14+CJ14 -> 8 | S14: =+AG14+AU14+BI14+BW14+CK14 -> 12 | T14: =+AH14+AV14+BJ14+BX14+CL14 -> 21 | U14: =+AI14+AW14+BK14+BY14+CM14 -> 13 | V14: =+AJ14+AX14+BL14+BZ14+CN14 -> 3 | W14: =+AK14+AY14+BM14+CA14+CO14 -> 5 | X14: =+SUM(N14:W14) -> 81 | Z14: 45839 | AA14: 2 | AB14: 3 | AC14: 46 | AD14: 2 | AE14: 6 | AF14: 6 | AG14: 9 | AH14: 13 | AI14: 8 | AJ14: 2 | AK14: 4 | AL14: =+SUM(AA14:AB14,AD14:AK14) -> 55 | AN14: 45839 | AO14: 1 | AP14: 1 | AQ14: 19 | AR14: 0 | AS14: 0 | AT14: 2 | AU14: 3 | AV14: 8 | AW14: 5 | AX14: 1 | AY14: 0 | AZ14: =+SUM(AO14:AP14,AR14:AY14) -> 21 | BB14: 45839 | BC14: 2 | BD14: 0 | BE14: 1 | BF14: 0 | BG14: 1 | BH14: 0 | BI14: 0 | BJ14: 0 | BK14: 0 | BL14: 0 | BM14: 1 | BN14: =+SUM(BC14:BD14,BF14:BM14) -> 4 | BP14: 45839 | BQ14: 1 | BR14: 0 | BS14: 0 | BT14: 0 | BU14: 0 | BV14: 0 | BW14: 0 | BX14: 0 | BY14: 0 | BZ14: 0 | CA14: 0 | CB14: =+SUM(BQ14:BR14,BT14:CA14) -> 1 | CD14: 45839 | CE14: 0 | CF14: 0 | CG14: 0 | CH14: 0 | CI14: 0 | CJ14: 0 | CK14: 0 | CL14: 0 | CM14: 0 | CN14: 0 | CO14: 0 | CP14: =+SUM(CE14:CF14,CH14:CO14) -> 0 | CT14: =+'Listas y Parametros'!C222 -> Mines and money UK | CU14: =+'Listas y Parametros'!D223 -> 10000 | CV14: =+'Listas y Parametros'!E222 -> 45960 | CW14: 1 | DI14: Brasil | DJ14: =+SUM(DL14:DW14) -> 1790095.8 | DK14: =+SUM(DL14:DS14) -> 604565 | DL14: 80502 | DM14: 59683 | DN14: 96322 | DO14: 97147 | DP14: 37074 | DQ14: 66468 | DR14: 47717 | DS14: 119652 | DT14: =+'Flujo Caja'!M20 -> 358235.47 | DU14: =+'Flujo Caja'!N20 -> 316934.22 | DV14: =+'Flujo Caja'!O20 -> 301513.89 | DW14: =+'Flujo Caja'!P20 -> 208847.22
C15: =+'Gantt Proyectos'!D101 -> FEL3 CNN | D15: =+'Gantt Proyectos'!E101 -> CMP | E15: =+'Gantt Proyectos'!F101 -> Chile | F15: =+'Gantt Proyectos'!L101 -> 121038.49 | G15: =+'Gantt Proyectos'!AC101 -> PFS | H15: =+'Gantt Proyectos'!AD101 -> Actual | I15: 1 | J15: 1 | M15: 45870 | N15: =+AA15+AO15+BC15+BQ15+CE15 -> 6 | O15: =+AB15+AP15+BD15+BR15+CF15 -> 4 | P15: =+AD15+AR15+BF15+BT15+CH15 -> 2 | Q15: =+AE15+AS15+BG15+BU15+CI15 -> 7 | R15: =+AF15+AT15+BH15+BV15+CJ15 -> 8 | S15: =+AG15+AU15+BI15+BW15+CK15 -> 12 | T15: =+AH15+AV15+BJ15+BX15+CL15 -> 21 | U15: =+AI15+AW15+BK15+BY15+CM15 -> 13 | V15: =+AJ15+AX15+BL15+BZ15+CN15 -> 3 | W15: =+AK15+AY15+BM15+CA15+CO15 -> 5 | X15: =+SUM(N15:W15) -> 81 | Z15: 45870 | AA15: 2 | AB15: 3 | AC15: 46 | AD15: 2 | AE15: 6 | AF15: 6 | AG15: 9 | AH15: 13 | AI15: 8 | AJ15: 2 | AK15: 4 | AL15: =+SUM(AA15:AB15,AD15:AK15) -> 55 | AN15: 45870 | AO15: 1 | AP15: 1 | AQ15: 19 | AR15: 0 | AS15: 0 | AT15: 2 | AU15: 3 | AV15: 8 | AW15: 5 | AX15: 1 | AY15: 0 | AZ15: =+SUM(AO15:AP15,AR15:AY15) -> 21 | BB15: 45870 | BC15: 2 | BD15: 0 | BE15: 1 | BF15: 0 | BG15: 1 | BH15: 0 | BI15: 0 | BJ15: 0 | BK15: 0 | BL15: 0 | BM15: 1 | BN15: =+SUM(BC15:BD15,BF15:BM15) -> 4 | BP15: 45870 | BQ15: 1 | BR15: 0 | BS15: 0 | BT15: 0 | BU15: 0 | BV15: 0 | BW15: 0 | BX15: 0 | BY15: 0 | BZ15: 0 | CA15: 0 | CB15: =+SUM(BQ15:BR15,BT15:CA15) -> 1 | CD15: 45870 | CE15: 0 | CF15: 0 | CG15: 0 | CH15: 0 | CI15: 0 | CJ15: 0 | CK15: 0 | CL15: 0 | CM15: 0 | CN15: 0 | CO15: 0 | CP15: =+SUM(CE15:CF15,CH15:CO15) -> 0 | CT15: =+'Listas y Parametros'!C223 -> Argentina Mining | CU15: =+'Listas y Parametros'!D224 -> 15000 | CV15: =+'Listas y Parametros'!E223 -> 45868 | CW15: 1 | DI15: USA | DJ15: =+SUM(DL15:DW15) -> 998673.07 | DK15: =+SUM(DL15:DS15) -> 981530.21 | DL15: 150453 | DM15: 243465.21 | DN15: 141526 | DO15: 169200 | DP15: 195090 | DQ15: 61796 | DR15: 0 | DS15: 20000 | DT15: =+'Flujo Caja'!M23 -> 4285.7143 | DU15: =+'Flujo Caja'!N23 -> 4285.7143 | DV15: =+'Flujo Caja'!O23 -> 4285.7143 | DW15: =+'Flujo Caja'!P23 -> 4285.7143
C16: =+'Gantt Proyectos'!D102 -> Estudio de Factibilidad Mina Romeral UG - Acceso Mina SLS | D16: =+'Gantt Proyectos'!E102 -> CMP | E16: =+'Gantt Proyectos'!F102 -> Chile | F16: =+'Gantt Proyectos'!L102 -> 900007.88 | G16: =+'Gantt Proyectos'!AC102 -> FS e Ing. Basica | H16: =+'Gantt Proyectos'!AD102 -> Actual | I16: 1 | J16: 1 | M16: 45901 | N16: =+AA16+AO16+BC16+BQ16+CE16 -> 6 | O16: =+AB16+AP16+BD16+BR16+CF16 -> 4 | P16: =+AD16+AR16+BF16+BT16+CH16 -> 2 | Q16: =+AE16+AS16+BG16+BU16+CI16 -> 7 | R16: =+AF16+AT16+BH16+BV16+CJ16 -> 8 | S16: =+AG16+AU16+BI16+BW16+CK16 -> 12 | T16: =+AH16+AV16+BJ16+BX16+CL16 -> 21 | U16: =+AI16+AW16+BK16+BY16+CM16 -> 13 | V16: =+AJ16+AX16+BL16+BZ16+CN16 -> 3 | W16: =+AK16+AY16+BM16+CA16+CO16 -> 5 | X16: =+SUM(N16:W16) -> 81 | Z16: 45901 | AA16: 2 | AB16: 3 | AC16: 46 | AD16: 2 | AE16: 6 | AF16: 6 | AG16: 9 | AH16: 13 | AI16: 8 | AJ16: 2 | AK16: 4 | AL16: =+SUM(AA16:AB16,AD16:AK16) -> 55 | AN16: 45901 | AO16: 1 | AP16: 1 | AQ16: 19 | AR16: 0 | AS16: 0 | AT16: 2 | AU16: 3 | AV16: 8 | AW16: 5 | AX16: 1 | AY16: 0 | AZ16: =+SUM(AO16:AP16,AR16:AY16) -> 21 | BB16: 45901 | BC16: 2 | BD16: 0 | BE16: 1 | BF16: 0 | BG16: 1 | BH16: 0 | BI16: 0 | BJ16: 0 | BK16: 0 | BL16: 0 | BM16: 1 | BN16: =+SUM(BC16:BD16,BF16:BM16) -> 4 | BP16: 45901 | BQ16: 1 | BR16: 0 | BS16: 0 | BT16: 0 | BU16: 0 | BV16: 0 | BW16: 0 | BX16: 0 | BY16: 0 | BZ16: 0 | CA16: 0 | CB16: =+SUM(BQ16:BR16,BT16:CA16) -> 1 | CD16: 45901 | CE16: 0 | CF16: 0 | CG16: 0 | CH16: 0 | CI16: 0 | CJ16: 0 | CK16: 0 | CL16: 0 | CM16: 0 | CN16: 0 | CO16: 0 | CP16: =+SUM(CE16:CF16,CH16:CO16) -> 0 | CS16: Perú | CT16: =+'Listas y Parametros'!C224 -> PERUMIN 36 | CU16: =+'Listas y Parametros'!D224 -> 15000 | CV16: =+'Listas y Parametros'!E224 -> 45777 | CW16: 1 | DI16: Otros | DJ16: =+SUM(DL16:DW16) -> 338205 | DK16: =+SUM(DL16:DS16) -> 338205 | DL16: 0 | DM16: 21682 | DN16: 45478 | DO16: 0 | DP16: 0 | DQ16: 172045 | DR16: 0 | DS16: 99000 | DT16: =+'Flujo Caja'!M26 -> 0 | DU16: =+'Flujo Caja'!N26 -> 0 | DV16: =+'Flujo Caja'!O26 -> 0 | DW16: =+'Flujo Caja'!P26 -> 0
C17: =+'Gantt Proyectos'!D103 -> Cobre Panamá: Evaluación estratégica del activo | D17: =+'Gantt Proyectos'!E103 -> Debevoise&Plimpton | E17: =+'Gantt Proyectos'!F103 -> Chile | F17: =+'Gantt Proyectos'!L103 -> 272200.6 | G17: =+'Gantt Proyectos'!AC103 -> Estudio Conceptual / LOM | H17: =+'Gantt Proyectos'!AD103 -> Actual | I17: 1 | J17: 1 | M17: 45931 | N17: =+AA17+AO17+BC17+BQ17+CE17 -> 6 | O17: =+AB17+AP17+BD17+BR17+CF17 -> 4 | P17: =+AD17+AR17+BF17+BT17+CH17 -> 2 | Q17: =+AE17+AS17+BG17+BU17+CI17 -> 7 | R17: =+AF17+AT17+BH17+BV17+CJ17 -> 8 | S17: =+AG17+AU17+BI17+BW17+CK17 -> 12 | T17: =+AH17+AV17+BJ17+BX17+CL17 -> 21 | U17: =+AI17+AW17+BK17+BY17+CM17 -> 13 | V17: =+AJ17+AX17+BL17+BZ17+CN17 -> 3 | W17: =+AK17+AY17+BM17+CA17+CO17 -> 5 | X17: =+SUM(N17:W17) -> 81 | Z17: 45931 | AA17: 2 | AB17: 3 | AC17: 46 | AD17: 2 | AE17: 6 | AF17: 6 | AG17: 9 | AH17: 13 | AI17: 8 | AJ17: 2 | AK17: 4 | AL17: =+SUM(AA17:AB17,AD17:AK17) -> 55 | AN17: 45931 | AO17: 1 | AP17: 1 | AQ17: 19 | AR17: 0 | AS17: 0 | AT17: 2 | AU17: 3 | AV17: 8 | AW17: 5 | AX17: 1 | AY17: 0 | AZ17: =+SUM(AO17:AP17,AR17:AY17) -> 21 | BB17: 45931 | BC17: 2 | BD17: 0 | BE17: 1 | BF17: 0 | BG17: 1 | BH17: 0 | BI17: 0 | BJ17: 0 | BK17: 0 | BL17: 0 | BM17: 1 | BN17: =+SUM(BC17:BD17,BF17:BM17) -> 4 | BP17: 45931 | BQ17: 1 | BR17: 0 | BS17: 0 | BT17: 0 | BU17: 0 | BV17: 0 | BW17: 0 | BX17: 0 | BY17: 0 | BZ17: 0 | CA17: 0 | CB17: =+SUM(BQ17:BR17,BT17:CA17) -> 1 | CD17: 45931 | CE17: 0 | CF17: 0 | CG17: 0 | CH17: 0 | CI17: 0 | CJ17: 0 | CK17: 0 | CL17: 0 | CM17: 0 | CN17: 0 | CO17: 0 | CP17: =+SUM(CE17:CF17,CH17:CO17) -> 0 | CT17: =+'Listas y Parametros'!C225 -> 0 | CU17: =+'Listas y Parametros'!D225 -> 0 | CV17: =+'Listas y Parametros'!E225 -> 0 | CW17: 1 | DI17: Total | DJ17: =+SUM(DL17:DW17) -> 9528704.1 | DK17: =+SUM(DK12:DK16) -> 6465953 | DL17: =+SUM(DL12:DL16) -> 717165.73 | DM17: =+SUM(DM12:DM16) -> 934594.83 | DN17: =+SUM(DN12:DN16) -> 783696.26 | DO17: =+SUM(DO12:DO16) -> 624290.97 | DP17: =+SUM(DP12:DP16) -> 687704.59 | DQ17: =+SUM(DQ12:DQ16) -> 807316.07 | DR17: =+SUM(DR12:DR16) -> 842403.75 | ... DW17: =+SUM(DW12:DW16) -> 566092.76
C18: =+'Gantt Proyectos'!D104 -> Ferrobamba Scoping Study: Escenarios de sensibilidad | D18: =+'Gantt Proyectos'!E104 -> Las Bambas | E18: =+'Gantt Proyectos'!F104 -> Perú | F18: =+'Gantt Proyectos'!L104 -> 87520 | G18: =+'Gantt Proyectos'!AC104 -> Estudio Conceptual / LOM | H18: =+'Gantt Proyectos'!AD104 -> Actual | I18: 1 | J18: 1 | M18: 45962 | N18: =+AA18+AO18+BC18+BQ18+CE18 -> 6 | O18: =+AB18+AP18+BD18+BR18+CF18 -> 4 | P18: =+AD18+AR18+BF18+BT18+CH18 -> 2 | Q18: =+AE18+AS18+BG18+BU18+CI18 -> 7 | R18: =+AF18+AT18+BH18+BV18+CJ18 -> 8 | S18: =+AG18+AU18+BI18+BW18+CK18 -> 12 | T18: =+AH18+AV18+BJ18+BX18+CL18 -> 21 | U18: =+AI18+AW18+BK18+BY18+CM18 -> 13 | V18: =+AJ18+AX18+BL18+BZ18+CN18 -> 3 | W18: =+AK18+AY18+BM18+CA18+CO18 -> 5 | X18: =+SUM(N18:W18) -> 81 | Z18: 45962 | AA18: 2 | AB18: 3 | AC18: 46 | AD18: 2 | AE18: 6 | AF18: 6 | AG18: 9 | AH18: 13 | AI18: 8 | AJ18: 2 | AK18: 4 | AL18: =+SUM(AA18:AB18,AD18:AK18) -> 55 | AN18: 45962 | AO18: 1 | AP18: 1 | AQ18: 19 | AR18: 0 | AS18: 0 | AT18: 2 | AU18: 3 | AV18: 8 | AW18: 5 | AX18: 1 | AY18: 0 | AZ18: =+SUM(AO18:AP18,AR18:AY18) -> 21 | BB18: 45962 | BC18: 2 | BD18: 0 | BE18: 1 | BF18: 0 | BG18: 1 | BH18: 0 | BI18: 0 | BJ18: 0 | BK18: 0 | BL18: 0 | BM18: 1 | BN18: =+SUM(BC18:BD18,BF18:BM18) -> 4 | BP18: 45962 | BQ18: 1 | BR18: 0 | BS18: 0 | BT18: 0 | BU18: 0 | BV18: 0 | BW18: 0 | BX18: 0 | BY18: 0 | BZ18: 0 | CA18: 0 | CB18: =+SUM(BQ18:BR18,BT18:CA18) -> 1 | CD18: 45962 | CE18: 0 | CF18: 0 | CG18: 0 | CH18: 0 | CI18: 0 | CJ18: 0 | CK18: 0 | CL18: 0 | CM18: 0 | CN18: 0 | CO18: 0 | CP18: =+SUM(CE18:CF18,CH18:CO18) -> 0 | CT18: =+'Listas y Parametros'!C226 -> 0 | CU18: =+'Listas y Parametros'!D226 -> 0 | CV18: =+'Listas y Parametros'!E226 -> 0 | CW18: 1
C19: =+'Gantt Proyectos'!D105 -> Pre-PFS Twin Metals Birch Lake - Maturi | D19: =+'Gantt Proyectos'!E105 -> Twin Metals | E19: =+'Gantt Proyectos'!F105 -> USA | F19: =+'Gantt Proyectos'!L105 -> 481541 | G19: =+'Gantt Proyectos'!AC105 -> PFS | H19: =+'Gantt Proyectos'!AD105 -> Actual | I19: 1 | J19: 1 | M19: 45992 | N19: =+AA19+AO19+BC19+BQ19+CE19 -> 6 | O19: =+AB19+AP19+BD19+BR19+CF19 -> 4 | P19: =+AD19+AR19+BF19+BT19+CH19 -> 2 | Q19: =+AE19+AS19+BG19+BU19+CI19 -> 7 | R19: =+AF19+AT19+BH19+BV19+CJ19 -> 8 | S19: =+AG19+AU19+BI19+BW19+CK19 -> 12 | T19: =+AH19+AV19+BJ19+BX19+CL19 -> 21 | U19: =+AI19+AW19+BK19+BY19+CM19 -> 13 | V19: =+AJ19+AX19+BL19+BZ19+CN19 -> 3 | W19: =+AK19+AY19+BM19+CA19+CO19 -> 5 | X19: =+SUM(N19:W19) -> 81 | Z19: 45992 | AA19: 2 | AB19: 3 | AC19: 46 | AD19: 2 | AE19: 6 | AF19: 6 | AG19: 9 | AH19: 13 | AI19: 8 | AJ19: 2 | AK19: 4 | AL19: =+SUM(AA19:AB19,AD19:AK19) -> 55 | AN19: 45992 | AO19: 1 | AP19: 1 | AQ19: 19 | AR19: 0 | AS19: 0 | AT19: 2 | AU19: 3 | AV19: 8 | AW19: 5 | AX19: 1 | AY19: 0 | AZ19: =+SUM(AO19:AP19,AR19:AY19) -> 21 | BB19: 45992 | BC19: 2 | BD19: 0 | BE19: 1 | BF19: 0 | BG19: 1 | BH19: 0 | BI19: 0 | BJ19: 0 | BK19: 0 | BL19: 0 | BM19: 1 | BN19: =+SUM(BC19:BD19,BF19:BM19) -> 4 | BP19: 45992 | BQ19: 1 | BR19: 0 | BS19: 0 | BT19: 0 | BU19: 0 | BV19: 0 | BW19: 0 | BX19: 0 | BY19: 0 | BZ19: 0 | CA19: 0 | CB19: =+SUM(BQ19:BR19,BT19:CA19) -> 1 | CD19: 45992 | CE19: 0 | CF19: 0 | CG19: 0 | CH19: 0 | CI19: 0 | CJ19: 0 | CK19: 0 | CL19: 0 | CM19: 0 | CN19: 0 | CO19: 0 | CP19: =+SUM(CE19:CF19,CH19:CO19) -> 0 | CT19: =+'Listas y Parametros'!C227 -> 0 | CU19: =+'Listas y Parametros'!D227 -> 0 | CV19: =+'Listas y Parametros'!E227 -> 0 | CW19: 1 | DI19: Costo | DJ19: Total | DK19: Acumulado | DL19: 45687 | DM19: 45716 | DN19: 45746 | DO19: 45777 | DP19: 45807 | DQ19: 45838 | DR19: 45868 | DS19: 45899 | DT19: 45930 | DU19: 45960 | DV19: 45991 | DW19: 46021
C20: =+'Gantt Proyectos'!D106 -> Análisis Conceptual - Aura UG | D20: =+'Gantt Proyectos'!E106 -> Aura Minerals | E20: =+'Gantt Proyectos'!F106 -> Brasil | F20: =+'Gantt Proyectos'!L106 -> 310000 | G20: =+'Gantt Proyectos'!AC106 -> Scoping | H20: =+'Gantt Proyectos'!AD106 -> Actual | I20: 1 | J20: 1 | CS20: Brasil | CT20: =+'Listas y Parametros'!C228 -> Exposibram 2025 | CU20: =+'Listas y Parametros'!D228 -> 20000 | CV20: =+'Listas y Parametros'!E228 -> 45868 | CW20: 1 | DI20: Chile | DJ20: =+SUM(DL20:DW20) -> 4602714.4 | DK20: =+SUM(DL20:DS20) -> 3161800.2 | DL20: 397276.65 | DM20: 422126.64 | DN20: 439899.18 | DO20: 341507.35 | DP20: 340134.8 | DQ20: 399879.47 | DR20: 395727.19 | DS20: 425248.91 | DT20: =+'Flujo Caja'!M15 -> 378739.92 | DU20: =+'Flujo Caja'!N15 -> 359012.64 | DV20: =+'Flujo Caja'!O15 -> 345012.64 | DW20: =+'Flujo Caja'!P15 -> 358149.01
C21: =+'Gantt Proyectos'!D107 -> Los Calatos - Extensión (v3) | D21: =+'Gantt Proyectos'!E107 -> CD Capital | E21: =+'Gantt Proyectos'!F107 -> Perú | F21: =+'Gantt Proyectos'!L107 -> 295769 | G21: =+'Gantt Proyectos'!AC107 -> PFS | H21: =+'Gantt Proyectos'!AD107 -> Actual | I21: 1 | J21: 1 | CT21: =+'Listas y Parametros'!C229 -> Congresso de Mineração Subterrânea | CU21: =+'Listas y Parametros'!D229 -> 5000 | CV21: =+'Listas y Parametros'!E229 -> 45868 | CW21: 1 | DI21: Perú | DJ21: =+SUM(DL21:DW21) -> 1293266.4 | DK21: =+SUM(DL21:DS21) -> 1085106.1 | DL21: 89462.85 | DM21: 81597 | DN21: 92755 | DO21: 137672.3 | DP21: 128924 | DQ21: 153584 | DR21: 189124 | DS21: 211987 | DT21: =+'Flujo Caja'!M18 -> 52040.069 | DU21: =+'Flujo Caja'!N18 -> 52040.069 | DV21: =+'Flujo Caja'!O18 -> 52040.069 | DW21: =+'Flujo Caja'!P18 -> 52040.069
C22: =+'Gantt Proyectos'!D108 -> Analisis Innovación Tecnologica Distrito Centinela | D22: =+'Gantt Proyectos'!E108 -> AMSA | E22: =+'Gantt Proyectos'!F108 -> Chile | F22: =+'Gantt Proyectos'!L108 -> 134445.67 | G22: =+'Gantt Proyectos'!AC108 -> Scoping | H22: =+'Gantt Proyectos'!AD108 -> Actual | I22: 1 | J22: 1 | CT22: =+'Listas y Parametros'!C230 -> 0 | CU22: =+'Listas y Parametros'!D230 -> 0 | CV22: =+'Listas y Parametros'!E230 -> 0 | CW22: 1 | DI22: Brasil | DJ22: =+SUM(DL22:DW22) -> 566395.52 | DK22: =+SUM(DL22:DS22) -> 289373.4 | DL22: 21023 | DM22: 27812 | DN22: 26425 | DO22: 52004.4 | DP22: 33329 | DQ22: 76286 | DR22: 31019 | DS22: 21475 | DT22: =+'Flujo Caja'!M21 -> 85164.621 | DU22: =+'Flujo Caja'!N21 -> 71437.348 | DV22: =+'Flujo Caja'!O21 -> 64573.712 | DW22: =+'Flujo Caja'!P21 -> 55846.439
C23: =+'Gantt Proyectos'!D109 -> Cerro Colorado: Diseño Cierre de Botaderos | D23: =+'Gantt Proyectos'!E109 -> BHP | E23: =+'Gantt Proyectos'!F109 -> Chile | F23: =+'Gantt Proyectos'!L109 -> 904853 | G23: =+'Gantt Proyectos'!AC109 -> FS e Ing. Basica | H23: =+'Gantt Proyectos'!AD109 -> Actual | I23: 1 | J23: 1 | CT23: =+'Listas y Parametros'!C231 -> 0 | CU23: =+'Listas y Parametros'!D231 -> 0 | CV23: =+'Listas y Parametros'!E231 -> 0 | CW23: 1 | DI23: USA | DJ23: =+SUM(DL23:DW23) -> 300763.42 | DK23: =+SUM(DL23:DS23) -> 133542 | DL23: 15 | DM23: 2025 | DN23: 58728 | DO23: 9898 | DP23: 47666 | DQ23: 4178 | DR23: 10017 | DS23: 1015 | DT23: =+'Flujo Caja'!M24 -> 40555.356 | DU23: =+'Flujo Caja'!N24 -> 40555.356 | DV23: =+'Flujo Caja'!O24 -> 40555.356 | DW23: =+'Flujo Caja'!P24 -> 45555.356
C24: =+'Gantt Proyectos'!D110 -> Analisis de Productividad Los Bronces | D24: =+'Gantt Proyectos'!E110 -> AngloAmerican | E24: =+'Gantt Proyectos'!F110 -> Chile | F24: =+'Gantt Proyectos'!L110 -> 62417 | G24: =+'Gantt Proyectos'!AC110 -> Confiabilidad Planes | H24: =+'Gantt Proyectos'!AD110 -> Actual | I24: 1 | J24: 1 | CS24: USA | CT24: =+'Listas y Parametros'!C232 -> MINExpo | CU24: =+'Listas y Parametros'!D232 -> 19500 | CV24: =+'Listas y Parametros'!E232 -> 45838 | CW24: 1 | DI24: Otros | DJ24: =+SUM(DL24:DW24) -> 61478.4 | DK24: =+SUM(DL24:DS24) -> 61478.4 | DL24: 14044 | DM24: 0 | DN24: 0 | DO24: 14380 | DP24: 16000 | DQ24: 5684.8 | DR24: 5684.8 | DS24: 5684.8 | DT24: =+'Flujo Caja'!M27 -> 0 | DU24: =+'Flujo Caja'!N27 -> 0 | DV24: =+'Flujo Caja'!O27 -> 0 | DW24: =+'Flujo Caja'!P27 -> 0
C25: =+'Gantt Proyectos'!D111 -> Ingenieria implementacion HDD Los Bronces | D25: =+'Gantt Proyectos'!E111 -> AngloAmerican | E25: =+'Gantt Proyectos'!F111 -> Chile | F25: =+'Gantt Proyectos'!L111 -> 183430 | G25: =+'Gantt Proyectos'!AC111 -> Estudio Conceptual / LOM | H25: =+'Gantt Proyectos'!AD111 -> Actual | I25: 1 | J25: 1 | CT25: =+'Listas y Parametros'!C233 -> 0 | CU25: =+'Listas y Parametros'!D233 -> 0 | CV25: =+'Listas y Parametros'!E233 -> 0 | CW25: 1 | DI25: Total | DJ25: =+ABS(SUM(DL25:DW25)) -> 6824618.2 | DK25: =+SUM(DK20:DK24) -> 4731300.1 | DL25: =SUM(DL20:DL24) -> 521821.5 | DM25: =SUM(DM20:DM24) -> 533560.64 | DN25: =SUM(DN20:DN24) -> 617807.18 | DO25: =SUM(DO20:DO24) -> 555462.05 | DP25: =SUM(DP20:DP24) -> 566053.8 | DQ25: =SUM(DQ20:DQ24) -> 639612.27 | DR25: =SUM(DR20:DR24) -> 631571.99 | DS25: =SUM(DS20:DS24) -> 665410.71 | ... DW25: =SUM(DW20:DW24) -> 511590.87
C26: =+'Gantt Proyectos'!D112 -> V MEIA San Rafael | D26: =+'Gantt Proyectos'!E112 -> Minsur | E26: =+'Gantt Proyectos'!F112 -> Perú | F26: =+'Gantt Proyectos'!L112 -> 248031 | G26: =+'Gantt Proyectos'!AC112 -> Permisos / MEIA | H26: =+'Gantt Proyectos'!AD112 -> Actual | I26: 1 | J26: 1 | CT26: =+'Listas y Parametros'!C234 -> 0 | CU26: =+'Listas y Parametros'!D234 -> 0 | CV26: =+'Listas y Parametros'!E234 -> 0 | CW26: 1 | DL26: =-DL25 -> -521821.5 | DM26: =-DM25 -> -533560.64 | DN26: =-DN25 -> -617807.18 | DO26: =-DO25 -> -555462.05 | DP26: =-DP25 -> -566053.8 | DQ26: =-DQ25 -> -639612.27 | DR26: =-DR25 -> -631571.99 | DS26: =-DS25 -> -665410.71 | ... DW26: =-DW25 -> -511590.87
C27: =+'Gantt Proyectos'!D113 -> Fase 2 CTV: Modelamiento Recursos, Geomecanica y LOM actualizado | D27: =+'Gantt Proyectos'!E113 -> Mosaic | E27: =+'Gantt Proyectos'!F113 -> Brasil | F27: =+'Gantt Proyectos'!L113 -> 330410 | G27: =+'Gantt Proyectos'!AC113 -> Scoping | H27: =+'Gantt Proyectos'!AD113 -> Actual | I27: 1 | J27: 1 | CT27: =+'Listas y Parametros'!C235 -> 0 | CU27: =+'Listas y Parametros'!D235 -> 0 | CV27: =+'Listas y Parametros'!E235 -> 0 | CW27: 1 | DI27: Margen | DJ27: Total | DK27: Acumulado | DL27: 45687 | DM27: 45716 | DN27: 45746 | DO27: 45777 | DP27: 45807 | DQ27: 45838 | DR27: 45868 | DS27: 45899 | DT27: 45930 | DU27: 45960 | DV27: 45991 | DW27: 46021
C28: =+'Gantt Proyectos'!D114 -> Estrategia de Valor para Mina Cobriza | D28: =+'Gantt Proyectos'!E114 -> OCP | E28: =+'Gantt Proyectos'!F114 -> Perú | F28: =+'Gantt Proyectos'!L114 -> 184000 | G28: =+'Gantt Proyectos'!AC114 -> Estudio Conceptual / LOM | H28: =+'Gantt Proyectos'!AD114 -> Actual | I28: 1 | J28: 1 | CS28: Otros | CT28: =+'Listas y Parametros'!C236 -> 0 | CU28: =+'Listas y Parametros'!D236 -> 0 | CV28: =+'Listas y Parametros'!E236 -> 0 | CW28: 1 | DI28: Chile | DJ28: =+SUM(DL28:DW28) -> -1250779.8 | DK28: =+SUM(DL28:DS28) -> -287376.37 | DL28: =+DL12-DL20 -> -34913.914 | DM28: =+DM12-DM20 -> 125183.98 | DN28: =+DN12-DN20 -> -44905.92 | DO28: =+DO12-DO20 -> -93640.381 | DP28: =+DP12-DP20 -> -27204.209 | DQ28: =+DQ12-DQ20 -> -122460.4 | DR28: =+DR12-DR20 -> 147257.56 | DS28: =+DS12-DS20 -> -236693.09 | DT28: =+'Flujo Caja'!M16 -> -209862.23 | DU28: =+'Flujo Caja'!N16 -> -190134.95 | DV28: =+'Flujo Caja'!O16 -> -275134.95 | DW28: =+'Flujo Caja'!P16 -> -288271.32
C29: =+'Gantt Proyectos'!D115 -> PFS Ferrobamba UG (MEIA) | D29: =+'Gantt Proyectos'!E115 -> Las Bambas | E29: =+'Gantt Proyectos'!F115 -> Perú | F29: =+'Gantt Proyectos'!L115 -> 600000 | G29: =+'Gantt Proyectos'!AC115 -> Permisos / MEIA | H29: =+'Gantt Proyectos'!AD115 -> Actual | I29: 1 | J29: 1 | CT29: =+'Listas y Parametros'!C237 -> 0 | CU29: =+'Listas y Parametros'!D237 -> 0 | CV29: =+'Listas y Parametros'!E237 -> 0 | CW29: 1 | DI29: Perú | DJ29: =+SUM(DL29:DW29) -> 1756529.2 | DK29: =+SUM(DL29:DS29) -> 582122.85 | DL29: =+DL13-DL21 -> 34385.15 | DM29: =+DM13-DM21 -> -19143 | DN29: =+DN13-DN21 -> 12622 | DO29: =+DO13-DO21 -> -27595.3 | DP29: =+DP13-DP21 -> 13686 | DQ29: =+DQ13-DQ21 -> 76004 | DR29: =+DR13-DR21 -> 62578 | DS29: =+DS13-DS21 -> 429586 | DT29: =+'Flujo Caja'!M19 -> 341494.45 | DU29: =+'Flujo Caja'!N19 -> 368577.78 | DV29: =+'Flujo Caja'!O19 -> 233292.06 | DW29: =+'Flujo Caja'!P19 -> 231042.06
C30: =+'Gantt Proyectos'!D116 -> BHP: Análisis de accesibilidad para MEL UG | D30: =+'Gantt Proyectos'!E116 -> MEL | E30: =+'Gantt Proyectos'!F116 -> Chile | F30: =+'Gantt Proyectos'!L116 -> 198920 | G30: =+'Gantt Proyectos'!AC116 -> Scoping | H30: =+'Gantt Proyectos'!AD116 -> Actual | I30: 1 | J30: 1 | CT30: =+'Listas y Parametros'!C238 -> 0 | CU30: =+'Listas y Parametros'!D238 -> 0 | CV30: =+'Listas y Parametros'!E238 -> 0 | CW30: 1 | DI30: Brasil | DJ30: =+SUM(DL30:DW30) -> 1223700.3 | DK30: =+SUM(DL30:DS30) -> 315191.6 | DL30: =+DL14-DL22 -> 59479 | DM30: =+DM14-DM22 -> 31871 | DN30: =+DN14-DN22 -> 69897 | DO30: =+DO14-DO22 -> 45142.6 | DP30: =+DP14-DP22 -> 3745 | DQ30: =+DQ14-DQ22 -> -9818 | DR30: =+DR14-DR22 -> 16698 | DS30: =+DS14-DS22 -> 98177 | DT30: =+'Flujo Caja'!M22 -> 273070.85 | DU30: =+'Flujo Caja'!N22 -> 245496.87 | DV30: =+'Flujo Caja'!O22 -> 236940.18 | DW30: =+'Flujo Caja'!P22 -> 153000.78
C31: =+'Gantt Proyectos'!D117 -> Resolution: Análisis de Proyecto Túnel 68L | D31: =+'Gantt Proyectos'!E117 -> BHP | E31: =+'Gantt Proyectos'!F117 -> Chile | F31: =+'Gantt Proyectos'!L117 -> 47808 | G31: =+'Gantt Proyectos'!AC117 -> Consultoria y Due Dilligence | H31: =+'Gantt Proyectos'!AD117 -> Actual | I31: 1 | J31: 1 | CT31: =+'Listas y Parametros'!C239 -> 0 | CU31: =+'Listas y Parametros'!D239 -> 0 | CV31: =+'Listas y Parametros'!E239 -> 0 | CW31: 1 | DI31: USA | DJ31: =+SUM(DL31:DW31) -> 697909.64 | DK31: =+SUM(DL31:DS31) -> 847988.21 | DL31: =+DL15-DL23 -> 150438 | DM31: =+DM15-DM23 -> 241440.21 | DN31: =+DN15-DN23 -> 82798 | DO31: =+DO15-DO23 -> 159302 | DP31: =+DP15-DP23 -> 147424 | DQ31: =+DQ15-DQ23 -> 57618 | DR31: =+DR15-DR23 -> -10017 | DS31: =+DS15-DS23 -> 18985 | DT31: =+'Flujo Caja'!M25 -> -36269.642 | DU31: =+'Flujo Caja'!N25 -> -36269.642 | DV31: =+'Flujo Caja'!O25 -> -36269.642 | DW31: =+'Flujo Caja'!P25 -> -41269.642
C32: =+'Gantt Proyectos'!D118 -> Cajati: Actualización Ingeniería P1 | D32: =+'Gantt Proyectos'!E118 -> Mosaic | E32: =+'Gantt Proyectos'!F118 -> Brasil | F32: =+'Gantt Proyectos'!L118 -> 147935 | G32: =+'Gantt Proyectos'!AC118 -> FS e Ing. Basica | H32: =+'Gantt Proyectos'!AD118 -> Actual | I32: 1 | J32: 1 | DI32: Otros | DJ32: =+SUM(DL32:DW32) -> 276726.6 | DK32: =+SUM(DL32:DS32) -> 276726.6 | DL32: =+DL16-DL24 -> -14044 | DM32: =+DM16-DM24 -> 21682 | DN32: =+DN16-DN24 -> 45478 | DO32: =+DO16-DO24 -> -14380 | DP32: =+DP16-DP24 -> -16000 | DQ32: =+DQ16-DQ24 -> 166360.2 | DR32: =+DR16-DR24 -> -5684.8 | DS32: =+DS16-DS24 -> 93315.2 | DT32: =+'Flujo Caja'!M28 -> 0 | DU32: =+'Flujo Caja'!N28 -> 0 | DV32: =+'Flujo Caja'!O28 -> 0 | DW32: =+'Flujo Caja'!P28 -> 0
C33: =+'Gantt Proyectos'!D119 -> LOM Integrado San Rafael: 2025 | D33: =+'Gantt Proyectos'!E119 -> Minsur | E33: =+'Gantt Proyectos'!F119 -> Perú | F33: =+'Gantt Proyectos'!L119 -> 60000 | G33: =+'Gantt Proyectos'!AC119 -> Estudio Conceptual / LOM | H33: =+'Gantt Proyectos'!AD119 -> Actual | I33: 1 | J33: 1 | DI33: Total | DJ33: =+SUM(DL33:DW33) -> 2704085.9 | DK33: =+SUM(DK28:DK32) -> 1734652.9 | DL33: =+SUM(DL28:DL32) -> 195344.24 | DM33: =+SUM(DM28:DM32) -> 401034.19 | DN33: =+SUM(DN28:DN32) -> 165889.08 | DO33: =+SUM(DO28:DO32) -> 68828.919 | DP33: =+SUM(DP28:DP32) -> 121650.79 | DQ33: =+SUM(DQ28:DQ32) -> 167703.8 | DR33: =+SUM(DR28:DR32) -> 210831.76 | ... DW33: =+SUM(DW28:DW32) -> 54501.888
C34: =+'Gantt Proyectos'!D120 -> Soporte Minero en Litigio OT - Gobierno Mongolia (Fase 2) | D34: =+'Gantt Proyectos'!E120 -> ThreeCrowns | E34: =+'Gantt Proyectos'!F120 -> USA | F34: =+'Gantt Proyectos'!L120 -> 350000 | G34: =+'Gantt Proyectos'!AC120 -> Consultoria y Due Dilligence | H34: =+'Gantt Proyectos'!AD120 -> Actual | I34: 1 | J34: 1 | DI34: % | DJ34: =+DJ33/DJ17 -> 0.28378318 | DK34: =+DK33/DK17 -> 0.2682749 | DL34: =+DL33/DL17 -> 0.27238367 | DM34: =+DM33/DM17 -> 0.42909952 | DN34: =+DN33/DN17 -> 0.21167522 | DO34: =+DO33/DO17 -> 0.11025135 | DP34: =+DP33/DP17 -> 0.17689396 | DQ34: =+DQ33/DQ17 -> 0.20773004 | ... DW34: =+DW33/DW17 -> 0.09627731
C35: =+'Gantt Proyectos'!D121 -> Aura: Ingeniería Túnel de Exploraciones | D35: =+'Gantt Proyectos'!E121 -> Aura Minerals | E35: =+'Gantt Proyectos'!F121 -> Brasil | F35: =+'Gantt Proyectos'!L121 -> 108000 | G35: =+'Gantt Proyectos'!AC121 -> Scoping | H35: =+'Gantt Proyectos'!AD121 -> Actual | I35: 1 | J35: 1
C36: =+'Gantt Proyectos'!D122 -> Los Calatos - DFS | D36: =+'Gantt Proyectos'!E122 -> CD Capital | E36: =+'Gantt Proyectos'!F122 -> Perú | F36: =+'Gantt Proyectos'!L122 -> 1100000 | G36: =+'Gantt Proyectos'!AC122 -> FS e Ing. Basica | H36: =+'Gantt Proyectos'!AD122 -> Asignado | I36: 1 | J36: 1 | DI36: Margen Acum | DJ36: Total | DK36: Acumulado | DL36: 45687 | DM36: 45716 | DN36: 45746 | DO36: 45777 | DP36: 45807 | DQ36: 45838 | DR36: 45868 | DS36: 45899 | DT36: 45930 | DU36: 45960 | DV36: 45991 | DW36: 46021
C37: =+'Gantt Proyectos'!D123 -> Ferrobamba PFS | D37: =+'Gantt Proyectos'!E123 -> Las Bambas | E37: =+'Gantt Proyectos'!F123 -> Perú | F37: =+'Gantt Proyectos'!L123 -> 600000 | G37: =+'Gantt Proyectos'!AC123 -> PFS | H37: =+'Gantt Proyectos'!AD123 -> No Asignado | I37: 0.7 | J37: 1 | DI37: Chile | DJ37: =+DW37 -> -1250779.8 | DK37: =+DP37 -> -75480.442 | DL37: =+DL28 -> -34913.914 | DM37: =+DL37+DM28 -> 90270.068 | DN37: =+DM37+DN28 -> 45364.148 | DO37: =+DN37+DO28 -> -48276.233 | DP37: =+DO37+DP28 -> -75480.442 | DQ37: =+DP37+DQ28 -> -197940.84 | DR37: =+DQ37+DR28 -> -50683.281 | DS37: =+DR37+DS28 -> -287376.37 | DT37: =+DS37+DT28 -> -497238.59 | ... DW37: =+DV37+DW28 -> -1250779.8
C38: =+'Gantt Proyectos'!D124 -> Caserones: Implementacion NSR en Corto Plazo | D38: =+'Gantt Proyectos'!E124 -> Lundin | E38: =+'Gantt Proyectos'!F124 -> Chile | F38: =+'Gantt Proyectos'!L124 -> 0 | G38: =+'Gantt Proyectos'!AC124 -> Consultoria y Due Dilligence | H38: =+'Gantt Proyectos'!AD124 -> No Asignado | I38: 0 | J38: 0 | DI38: Perú | DJ38: =+DW38 -> 1756529.2 | DK38: =+DP38 -> 13954.85 | DL38: =+DL29 -> 34385.15 | DM38: =+DL38+DM29 -> 15242.15 | DN38: =+DM38+DN29 -> 27864.15 | DO38: =+DN38+DO29 -> 268.85 | DP38: =+DO38+DP29 -> 13954.85 | DQ38: =+DP38+DQ29 -> 89958.85 | DR38: =+DQ38+DR29 -> 152536.85 | DS38: =+DR38+DS29 -> 582122.85 | DT38: =+DS38+DT29 -> 923617.3 | ... DW38: =+DV38+DW29 -> 1756529.2
C39: =+'Gantt Proyectos'!D125 -> Caserones: Análisis Estratégico | D39: =+'Gantt Proyectos'!E125 -> Lundin | E39: =+'Gantt Proyectos'!F125 -> Chile | F39: =+'Gantt Proyectos'!L125 -> 300000 | G39: =+'Gantt Proyectos'!AC125 -> Estudio Conceptual / LOM | H39: =+'Gantt Proyectos'!AD125 -> Actual | I39: 1 | J39: 1 | DI39: Brasil | DJ39: =+DW39 -> 1223700.3 | DK39: =+DP39 -> 210134.6 | DL39: =+DL30 -> 59479 | DM39: =+DL39+DM30 -> 91350 | DN39: =+DM39+DN30 -> 161247 | DO39: =+DN39+DO30 -> 206389.6 | DP39: =+DO39+DP30 -> 210134.6 | DQ39: =+DP39+DQ30 -> 200316.6 | DR39: =+DQ39+DR30 -> 217014.6 | DS39: =+DR39+DS30 -> 315191.6 | DT39: =+DS39+DT30 -> 588262.45 | ... DW39: =+DV39+DW30 -> 1223700.3
C40: =+'Gantt Proyectos'!D126 -> QuinnEmanuel: OT Allegation | D40: =+'Gantt Proyectos'!E126 -> QuinnEmanuel | E40: =+'Gantt Proyectos'!F126 -> USA | F40: =+'Gantt Proyectos'!L126 -> 300000 | G40: =+'Gantt Proyectos'!AC126 -> Consultoria y Due Dilligence | H40: =+'Gantt Proyectos'!AD126 -> No Asignado | I40: 0.1 | J40: 1 | DI40: USA | DJ40: =+DW40 -> 697909.64 | DK40: =+DP40 -> 781402.21 | DL40: =+DL31 -> 150438 | DM40: =+DL40+DM31 -> 391878.21 | DN40: =+DM40+DN31 -> 474676.21 | DO40: =+DN40+DO31 -> 633978.21 | DP40: =+DO40+DP31 -> 781402.21 | DQ40: =+DP40+DQ31 -> 839020.21 | DR40: =+DQ40+DR31 -> 829003.21 | DS40: =+DR40+DS31 -> 847988.21 | DT40: =+DS40+DT31 -> 811718.57 | ... DW40: =+DV40+DW31 -> 697909.64
C41: =+'Gantt Proyectos'!D127 -> DET: Ingeniería Perfil Sector Teniente 9 | D41: =+'Gantt Proyectos'!E127 -> Codelco | E41: =+'Gantt Proyectos'!F127 -> Chile | F41: =+'Gantt Proyectos'!L127 -> 300000 | G41: =+'Gantt Proyectos'!AC127 -> Scoping | H41: =+'Gantt Proyectos'!AD127 -> No Asignado | I41: 0.2 | J41: 1 | DI41: Otros | DJ41: =+DW41 -> 276726.6 | DK41: =+DP41 -> 22736 | DL41: =+DL32 -> -14044 | DM41: =+DL41+DM32 -> 7638 | DN41: =+DM41+DN32 -> 53116 | DO41: =+DN41+DO32 -> 38736 | DP41: =+DO41+DP32 -> 22736 | DQ41: =+DP41+DQ32 -> 189096.2 | DR41: =+DQ41+DR32 -> 183411.4 | DS41: =+DR41+DS32 -> 276726.6 | DT41: =+DS41+DT32 -> 276726.6 | ... DW41: =+DV41+DW32 -> 276726.6
C42: =+'Gantt Proyectos'!D128 -> Ingeniería Basica Sistema Manejo Materiales Candelaria | D42: =+'Gantt Proyectos'!E128 -> Lundin | E42: =+'Gantt Proyectos'!F128 -> Chile | F42: =+'Gantt Proyectos'!L128 -> 1300000 | G42: =+'Gantt Proyectos'!AC128 -> FS e Ing. Basica | H42: =+'Gantt Proyectos'!AD128 -> No Asignado | I42: 0 | J42: 0 | DI42: Total | DJ42: =+DW42 -> 2704085.9 | DK42: =+SUM(DK37:DK41) -> 952747.22 | DL42: =+SUM(DL37:DL41) -> 195344.24 | DM42: =+SUM(DM37:DM41) -> 596378.43 | DN42: =+SUM(DN37:DN41) -> 762267.51 | DO42: =+SUM(DO37:DO41) -> 831096.43 | DP42: =+SUM(DP37:DP41) -> 952747.22 | DQ42: =+SUM(DQ37:DQ41) -> 1120451 | DR42: =+SUM(DR37:DR41) -> 1331282.8 | ... DW42: =+SUM(DW37:DW41) -> 2704085.9
C43: =+'Gantt Proyectos'!D129 -> PEA Proyecto Furnas | D43: =+'Gantt Proyectos'!E129 -> Ero Copper | E43: =+'Gantt Proyectos'!F129 -> Brasil | F43: =+'Gantt Proyectos'!L129 -> 490000 | G43: =+'Gantt Proyectos'!AC129 -> PEA | H43: =+'Gantt Proyectos'!AD129 -> Actual | I43: 1 | J43: 1
C44: =+'Gantt Proyectos'!D130 -> Cerro Blanco: FS Minería + Ing Detalle componentes | D44: =+'Gantt Proyectos'!E130 -> Aura Minerals | E44: =+'Gantt Proyectos'!F130 -> Brasil | F44: =+'Gantt Proyectos'!L130 -> 2400000 | G44: =+'Gantt Proyectos'!AC130 -> FS e Ing. Basica | H44: =+'Gantt Proyectos'!AD130 -> No Asignado | I44: 0.2 | J44: 1
...

Sheet Calculos ->

Sheet Hoja2
A3: Cuenta de # | B3: Etiquetas de columna
A4: Etiquetas de fila | B4: Brasil | C4: Chile | D4: Perú | E4: USA | F4: Total general
A5: Aseo y Ornato | C5: 1 | F5: 1
