Workbook

Sheet CRM
A1: ID | B1: País | C1: Descripcion Oportunidad | D1: Empresa | E1: Mina | F1: Tipo de Estudio | G1: Gestor Comercial | H1: Monto (USD) | I1: Modulos | J1: Duracion (meses) | K1: USD/mes | L1: Tipo Cliente | M1: Tipo de Minería | N1: Forma de Venta | O1: Etapa | P1: Fecha de Envío | Q1: Semana de Adjudicación | R1: Motivo de No Adjudicación | S1: Comentarios | T1: Contacto Clave | U1: Ultima Acción Comprometida | V1: Status
A2: 1 | B2: Perú | C2: Diagnostico operaciónal y construcción de planes alternativos (Blue Sky y potencial) | D2: OCP | E2: Cobriza | F2: Planificación estratégica | G2: PA | H2: 180000 | J2: 3 | K2: =IFERROR(H2/J2,0) -> 60000 | L2: Regular | M2: UG | N2: Solicitud Directa | O2: ODS | P2: 45653 | Q2: Enero
A3: 2 | B3: Chile | C3: . | H3: 0 | O3: Presentación Ad-Hoc
A4: 3 | B4: Perú | C4: PFS Ferrobamba Deep | D4: Las Bambas | E4: Ferrobamba | F4: Ing. de minas | G4: MF | H4: 1035000 | J4: 13 | K4: =IFERROR(H4/J4,0) -> 79615.385 | L4: Premium | M4: UG | N4: Reventa | O4: ODS | Q4: Febrero | T4: Maximiliano Adrove | U4: En espera de resultados de REDCO, que se presentara el 31 de marzo para ver continuidad
A5: 4 | B5: Chile | C5: Evaluación caso de negocio explotación SLS | D5: CMP | E5: Algarrobo | F5: Planificación estratégica | G5: FR | H5: 170000 | J5: 3 | K5: =IFERROR(H5/J5,0) -> 56666.667 | L5: Premium | M5: UG | N5: Solicitud Directa | O5: Seguimiento
A6: 5 | B6: EEUU | C6: Soporte caso de litigio Rio Tinto vs Gobierno Mongolia | D6: McCarthy Abogados | E6: Oyu Tolgoi | F6: Consultoría minera | G6: PV | H6: 566000 | J6: 3 | K6: =IFERROR(H6/J6,0) -> 188666.67 | L6: Target | M6: UG | N6: Solicitud Directa | O6: Seguimiento | S6: Deberiamos recibir respuesta de abril a mayo
A7: 6 | B7: Brasil | C7: Servicio IQS para nueve assets | D7: Vale | F7: Mecánica de rocas | G7: AS | H7: 450000 | J7: 12 | K7: =IFERROR(H7/J7,0) -> 37500 | L7: Target | M7: OP/UG | N7: Busqueda Activa | O7: No Adjudicada
A8: 7 | B8: Chile | C8: Estudio integral de LOM Mina Guarelo | D8: CAP | E8: Guarelo | F8: Planificación estratégica | G8: MF | H8: 60000 | J8: 2 | K8: =IFERROR(H8/J8,0) -> 30000 | L8: Regular | M8: OP | N8: Reventa | O8: Seguimiento | T8: Fernando Galez / Jaime Sepulveda | U8: PA Contactara a Jaime Sepulveda a cargo de Guarelo para ver status de la mina y oportunidades de negocio
A9: 8 | B9: EEUU | C9: Technical Expert Support of the plaintiff’s allegation to Alio Gold Inc | D9: McCarthy Abogados | E9: Alio Gold | F9: Consultoría minera | G9: PV | H9: 340000 | J9: 3 | K9: =IFERROR(H9/J9,0) -> 113333.33 | L9: Regular | M9: OP | N9: Reventa | O9: No Adjudicada
A10: 9 | B10: Perú | C10: Preparación IV MEIA San German | D10: Minsur | E10: San Rafael | F10: Ing. de minas | G10: MF | H10: 240000 | J10: 3 | K10: =IFERROR(H10/J10,0) -> 80000 | L10: Premium | M10: UG | N10: Solicitud Directa | O10: Cierre y Negociacón | P10: 45992 | Q10: Enero | S10: Se envio SOW para validar propuesta | U10: Matias contactara Alex para cierre del estudio, sin embargo por conflico con jefe directo estamos menos agresivo
A11: 10 | B11: Perú | C11: Revisión de validación reportes R&R (15 assets) | D11: Volcan | F11: Consultoría minera | G11: EL | H11: 220000 | J11: 3 | K11: =IFERROR(H11/J11,0) -> 73333.333 | L11: Regular | M11: OP/UG | N11: Licitación | O11: No Adjudicada | P11: 45681 | T11: Freddy Gomez | U11: Feedback de evaluación de parte tecnica, jueves 23
A12: 11 | B12: Chile | C12: Ing. Pre factibilidad perforación HHD | D12: Anglo American | E12: Los Bronces | F12: Ing. de minas | G12: RM | H12: 180000 | J12: 5 | K12: =IFERROR(H12/J12,0) -> 36000 | L12: Target | M12: OP | N12: Busqueda Activa | O12: ODS | P12: 46015 | Q12: Enero
A13: 12 | B13: Chile | C13: LOM estrategico | D13: First Quantum | E13: Cobre Panama | F13: Planificación estratégica | G13: PA | H13: 200000 | J13: 3 | K13: =IFERROR(H13/J13,0) -> 66666.667 | L13: Regular | M13: OP | N13: Solicitud Directa | O13: ODS | P13: 46016 | Q13: Enero
A14: 13 | B14: Chile | C14: Estudio de productividad | D14: Anglo American | E14: Los Bronces | F14: Consultoría minera | G14: FR | H14: 56000 | J14: 2 | K14: =IFERROR(H14/J14,0) -> 28000 | L14: Target | M14: OP | N14: Solicitud Directa | O14: Cierre y Negociacón | P14: 45646 | Q14: Febrero
A15: 14 | B15: Chile | C15: Análisis de confiabilidad y detección de cuellos de botella del LoA 25 – Proyecto SCUT | D15: BHP | E15: Spence | F15: Simulación de sistemas mineros | G15: PA | H15: 35000 | J15: 1 | K15: =IFERROR(H15/J15,0) -> 35000 | L15: Target | M15: OP | N15: Reventa | O15: ODS | P15: 45667 | Q15: Enero
A16: 15 | B16: Brasil | C16: Estudio Conceptual | D16: Vale | E16: Gongo Soco | F16: Mecánica de rocas | G16: AS | H16: 150000 | J16: 3 | K16: =IFERROR(H16/J16,0) -> 50000 | L16: Target | M16: OP | N16: Busqueda Activa | O16: Iniciativa | U16: Retomar contacto con cliente para conseguir una solicitud de propuesta
A17: 16 | B17: Chile | C17: Sistema Integrado de Gestión de Riesgos Geotécnicos | D17: Capstone Copper | E17: Todas | F17: Mecánica de rocas | G17: ER | H17: 900000 | J17: 12 | K17: =IFERROR(H17/J17,0) -> 75000 | L17: Premium | M17: OP | N17: Busqueda Activa | O17: Construcción Propuesta
A18: 17 | B18: Chile | C18: Ing Basica MHD UG | D18: Lundin | E18: Candelaria | F18: Ing. de minas | G18: RM | H18: 1380000 | J18: 5 | K18: =IFERROR(H18/J18,0) -> 276000 | L18: Premium | M18: UG | N18: Licitación | O18: Seguimiento | P18: 45674
A19: 18 | B19: Brasil | C19: PLANO AMBIENTAL DE FECHAMENTO CGM | D19: Alcoa | F19: Ing. de minas | G19: AS | H19: 207000 | J19: 6 | K19: =IFERROR(H19/J19,0) -> 34500 | L19: Regular | M19: OP | N19: Licitación | O19: No Adjudicada | P19: 45665
A20: 19 | B20: Chile | C20: Planificación Corto Plazo para Captura de Valor OP | D20: AMSA | E20: Centinela | F20: Planificación estratégica | G20: ER | H20: 150000 | J20: 3 | K20: =IFERROR(H20/J20,0) -> 50000 | L20: Premium | M20: OP | N20: Busqueda Activa | O20: Iniciativa | S20: A la espera de incorporación de cliente clave
A21: 20 | B21: EEUU | C21: Pre-Prefactibilidad Birch Lake + Tunnel acceso a Maturi | D21: Twin Metals Minnesota | E21: Birch Lake - Maturi | F21: Planificación estratégica | G21: PV | H21: 300000 | J21: 3 | K21: =IFERROR(H21/J21,0) -> 100000 | L21: Premium | M21: UG | N21: Busqueda Activa | O21: Iniciativa
A22: 21 | B22: EEUU | C22: Prefactibilidad para el conjunto Birch Lake - Maturi | D22: Twin Metals Minnesota | E22: Birch Lake - Maturi | F22: Ing. de minas | G22: PV | H22: 800000 | J22: 5 | K22: =IFERROR(H22/J22,0) -> 160000 | L22: Premium | M22: UG | N22: Busqueda Activa | O22: Iniciativa
A23: 22 | B23: EEUU | C23: Technical support for royalty acquisition | D23: EMX Royalty | F23: Consultoría minera | G23: PV | H23: 300000 | J23: 3 | K23: =IFERROR(H23/J23,0) -> 100000 | L23: Regular | M23: OP/UG | N23: Solicitud Directa | O23: Iniciativa
A24: 23 | B24: EEUU | C24: FS Santa Cruz Project UG - Revision Técnica | D24: Ivanhoe Electric | E24: Santa Cruz | F24: Planificación estratégica | G24: PV | H24: 100000 | J24: 3 | K24: =IFERROR(H24/J24,0) -> 33333.333 | L24: Target | M24: UG | N24: Busqueda Activa | O24: Iniciativa
A25: 24 | B25: EEUU | C25: Caso Base Resolution: diseño , planes, evalaucion | D25: BHP | E25: Resolution | F25: Planificación estratégica | G25: PV | H25: 200000 | J25: 3 | K25: =IFERROR(H25/J25,0) -> 66666.667 | L25: Target | M25: UG | N25: Busqueda Activa | O25: Iniciativa
A26: 25 | B26: EEUU | C26: Estudios - Diseños - Planes | D26: BHP | E26: Resolution | F26: Planificación estratégica | G26: PV | H26: 300000 | J26: 3 | K26: =IFERROR(H26/J26,0) -> 100000 | L26: Target | M26: UG | N26: Busqueda Activa | O26: Iniciativa
A27: 26 | B27: EEUU | C27: Estudios - Diseños - Planes | D27: BHP | E27: Antamina | F27: Planificación estratégica | G27: PV | H27: 150000 | J27: 3 | K27: =IFERROR(H27/J27,0) -> 50000 | L27: Target | M27: OP | N27: Busqueda Activa | O27: Iniciativa
A28: 27 | B28: EEUU | C28: Estudios - Diseños - Planes | D28: BHP | E28: CU South Australia | F28: Planificación estratégica | G28: PV | H28: 200000 | J28: 3 | K28: =IFERROR(H28/J28,0) -> 66666.667 | L28: Target | M28: OP/UG | N28: Busqueda Activa | O28: Iniciativa
A29: 28 | B29: EEUU | C29: SIMPREP | D29: Freeport-McMoRan Inc. | E29: PTFI | F29: Simulación de sistemas mineros | G29: PV | H29: 150000 | J29: 3 | K29: =IFERROR(H29/J29,0) -> 50000 | L29: Target | M29: UG | N29: Busqueda Activa | O29: Iniciativa
A30: 29 | B30: EEUU | C30: Planificación - Diseño | D30: Freeport-McMoRan Inc. | E30: PTFI | F30: Planificación estratégica | G30: PV | H30: 200000 | J30: 3 | K30: =IFERROR(H30/J30,0) -> 66666.667 | L30: Target | M30: UG | N30: Busqueda Activa | O30: Iniciativa
A31: 30 | B31: EEUU | C31: Planificación - Diseño | D31: Newmont Mining | F31: Planificación estratégica | G31: PV | H31: 200000 | J31: 3 | K31: =IFERROR(H31/J31,0) -> 66666.667 | L31: Target | M31: OP | N31: Busqueda Activa | O31: Iniciativa
A32: 31 | B32: EEUU | C32: Planificación - Diseño | D32: Anglo Gold Ashanti | F32: Planificación estratégica | G32: PV | H32: 200000 | J32: 3 | K32: =IFERROR(H32/J32,0) -> 66666.667 | L32: Target | M32: UG | N32: Busqueda Activa | O32: Iniciativa
A33: 32 | B33: EEUU | C33: Planificación - Diseño | D33: Vale | F33: Planificación estratégica | G33: PV | H33: 150000 | J33: 3 | K33: =IFERROR(H33/J33,0) -> 50000 | L33: Leads | M33: OP/UG | N33: Busqueda Activa | O33: Iniciativa
A34: 33 | B34: EEUU | C34: Planificación - Diseño | D34: South 32 | F34: Planificación estratégica | G34: PV | H34: 100000 | J34: 3 | K34: =IFERROR(H34/J34,0) -> 33333.333 | L34: Leads | M34: UG | N34: Busqueda Activa | O34: Iniciativa
A35: 34 | B35: EEUU | C35: Planificación - Diseño | D35: Barrick | F35: Planificación estratégica | G35: PV | H35: 100000 | J35: 3 | K35: =IFERROR(H35/J35,0) -> 33333.333 | L35: Leads | M35: OP | N35: Busqueda Activa | O35: Iniciativa
A36: 35 | B36: EEUU | C36: Planificación - Diseño | D36: Lundin | E36: Eagle | F36: Planificación estratégica | G36: PV | H36: 100000 | J36: 3 | K36: =IFERROR(H36/J36,0) -> 33333.333 | L36: Leads | M36: UG | N36: Busqueda Activa | O36: Iniciativa
A37: 36 | B37: EEUU | C37: Planificación - Diseño | D37: Kinross | F37: Planificación estratégica | G37: PV | H37: 200000 | J37: 3 | K37: =IFERROR(H37/J37,0) -> 66666.667 | L37: Leads | M37: OP | N37: Busqueda Activa | O37: Iniciativa
A38: 37 | B38: Brasil | C38: Cajati P1: ingeniería de enlace operacional | D38: Mosaic | E38: Cajati | F38: Ing. de minas | G38: AS | H38: 140000 | J38: 7 | K38: =IFERROR(H38/J38,0) -> 20000 | L38: Premium | M38: UG | N38: Busqueda Activa | O38: Cierre y Negociacón | P38: 45727 | Q38: 45731
A39: 38 | B39: Brasil | C39: Mosaic CTV 5Y Plan + Fase II | D39: Mosaic | E39: Cajati | F39: Planificación estratégica | G39: AS | H39: 358000 | J39: 5 | K39: =IFERROR(H39/J39,0) -> 71600 | L39: Premium | M39: UG | N39: Busqueda Activa | O39: Iniciativa
A40: 39 | B40: Brasil | C40: Ing PFS mina UG | D40: Aura Minerals | E40: Mina Paiol | F40: Planificación estratégica | G40: AS | H40: 288000 | J40: 3 | K40: =IFERROR(H40/J40,0) -> 96000 | L40: Target | M40: UG | N40: Reventa | O40: Construcción Propuesta
...

Sheet Hoja1
A1: ID | B1: País | C1: Descripcion Oportunidad | D1: Empresa | E1: Mina | F1: Tipo de Estudio | G1: Gestor Comercial | H1: Monto (USD) | I1: Duracion (meses) | J1: USD/mes
A2: 1 | B2: Chile | C2: Ing Basica MHD UG | D2: Lundin | E2: Candelaria | F2: Ing. de minas | G2: RM | H2: 1380000 | I2: 5 | J2: 276000
A3: 2 | B3: Chile | C3: Auditoría de las bases de datos geomecánicas y actualización de modelo geomecánico | D3: Lundin | E3: Candelaria | F3: Mecánica de rocas | G3: CH | H3: 390000 | I3: 3 | J3: 130000
A4: 3 | B4: Chile | C4: Análisis de Diseños de Ingeniería Túneles para suministro hidrico | D4: Worley | E4: Cerro Colorado | F4: Ing. de minas | G4: RM | H4: 381000 | I4: 3 | J4: 127000
A5: 4 | B5: Chile | C5: Estudios de Precisión Diseño Correas y Estudio de Flujo de Mineral | D5: Wood | E5: DCH | F5: Ing. de minas | G5: RM | H5: 638000 | I5: 4.5 | J5: 141777.78

Sheet Ventas
A3: Suma de Monto (USD) | B3: Etiquetas de columna
A4: Etiquetas de fila | B4: Cierre y Negociacón | C4: Construcción Propuesta | D4: Contacto Inicial (Enganche) | E4: Iniciativa | F4: No Adjudicada | G4: ODS | H4: Seguimiento | I4: Total general
A5: Brasil | B5: 140000 | C5: 1348000 | D5: 120000 | E5: 1867000 | F5: 657000 | H5: 1272000 | I5: 5404000
A6: Chile | B6: 221000 | C6: 1826000 | D6: 1150000 | E6: 2340000 | F6: 460000 | G6: 670000 | H6: 3249000 | I6: 9916000
A7: EEUU | E7: 3750000 | G7: 116000 | H7: 906000 | I7: 4772000
A8: Perú | B8: 260000 | C8: 160000 | D8: 800000 | E8: 830000 | F8: 558000 | G8: 1285000 | H8: 375700 | I8: 4268700
A9: Total general | B9: 621000 | C9: 3334000 | D9: 2070000 | E9: 8787000 | F9: 1675000 | G9: 2071000 | H9: 5802700 | I9: 24360700
A13: País | B13: Iniciativa | C13: Contacto Inicial (Enganche) | D13: Construcción Propuesta | E13: Seguimiento | F13: Cierre y Negociacón | G13: ODS | H13: Total general
A14: Brasil | B14: =GETPIVOTDATA("Monto (USD)",$A$3,"País","Brasil","Etapa","Iniciativa ")/1000000 -> 1.867 | C14: =GETPIVOTDATA("Monto (USD)",$A$3,"País","Brasil","Etapa","Contacto Inicial (Enganche)")/1000000 -> 0.12 | D14: =GETPIVOTDATA("Monto (USD)",$A$3,"País","Brasil","Etapa","Construcción Propuesta")/1000000 -> 1.348 | E14: =GETPIVOTDATA("Monto (USD)",$A$3,"País","Brasil","Etapa","Seguimiento")/1000000 -> 1.272 | F14: =GETPIVOTDATA("Monto (USD)",$A$3,"País","Brasil","Etapa","Cierre y Negociacón")/1000000 -> 0.14 | G14: =GETPIVOTDATA("Monto (USD)",$A$3,"País","Brasil","Etapa","ODS")/1000000 -> 0 | H14: =+SUM(B14:F14) -> 4.747
A15: Chile | B15: =GETPIVOTDATA("Monto (USD)",$A$3,"País","Chile","Etapa","Iniciativa ")/1000000 -> 2.34 | C15: =GETPIVOTDATA("Monto (USD)",$A$3,"País","Chile","Etapa","Contacto Inicial (Enganche)")/1000000 -> 1.15 | D15: =GETPIVOTDATA("Monto (USD)",$A$3,"País","Chile","Etapa","Construcción Propuesta")/1000000 -> 1.826 | E15: =GETPIVOTDATA("Monto (USD)",$A$3,"País","Chile","Etapa","Seguimiento")/1000000 -> 3.249 | F15: =GETPIVOTDATA("Monto (USD)",$A$3,"País","Chile","Etapa","Cierre y Negociacón")/1000000 -> 0.221 | G15: =GETPIVOTDATA("Monto (USD)",$A$3,"País","Chile","Etapa","ODS")/1000000 -> 0.67 | H15: =+SUM(B15:F15) -> 8.786
A16: EEUU | B16: =GETPIVOTDATA("Monto (USD)",$A$3,"País","EEUU","Etapa","Iniciativa ")/1000000 -> 3.75 | C16: =GETPIVOTDATA("Monto (USD)",$A$3,"País","EEUU","Etapa","Contacto Inicial (Enganche)")/1000000 -> 0 | D16: =GETPIVOTDATA("Monto (USD)",$A$3,"País","EEUU","Etapa","Construcción Propuesta")/1000000 -> 0 | E16: =GETPIVOTDATA("Monto (USD)",$A$3,"País","EEUU","Etapa","Seguimiento")/1000000 -> 0.906 | F16: =GETPIVOTDATA("Monto (USD)",$A$3,"País","EEUU","Etapa","Cierre y Negociacón")/1000000 -> 0 | G16: =GETPIVOTDATA("Monto (USD)",$A$3,"País","EEUU","Etapa","ODS")/1000000 -> 0.116 | H16: =+SUM(B16:F16) -> 4.656
A17: Perú | B17: =GETPIVOTDATA("Monto (USD)",$A$3,"País","Perú","Etapa","Iniciativa ")/1000000 -> 0.83 | C17: =GETPIVOTDATA("Monto (USD)",$A$3,"País","Perú","Etapa","Contacto Inicial (Enganche)")/1000000 -> 0.8 | D17: =GETPIVOTDATA("Monto (USD)",$A$3,"País","Perú","Etapa","Construcción Propuesta")/1000000 -> 0.16 | E17: =GETPIVOTDATA("Monto (USD)",$A$3,"País","Perú","Etapa","Seguimiento")/1000000 -> 0.3757 | F17: =GETPIVOTDATA("Monto (USD)",$A$3,"País","Perú","Etapa","Cierre y Negociacón")/1000000 -> 0.26 | G17: =GETPIVOTDATA("Monto (USD)",$A$3,"País","Perú","Etapa","ODS")/1000000 -> 1.285 | H17: =+SUM(B17:F17) -> 2.4257
A18: Total general | B18: =+SUM(B14:B17) -> 8.787 | C18: =+SUM(C14:C17) -> 2.07 | D18: =+SUM(D14:D17) -> 3.334 | E18: =+SUM(E14:E17) -> 5.8027 | F18: =+SUM(F14:F17) -> 0.621 | G18: =+SUM(G14:G17) -> 2.071 | H18: =+SUM(B18:F18) -> 20.6147
K23: 10000000
K24: 13000000
K25: 7000000
K26: =SUM(K22:K25) -> 30000000

Sheet Do vs At
M1: 0.25 | P1: 0.2 | Q1: 0.15 | R1: 0.2 | S1: 0.1 | T1: 0.1 | AA1: 0.2 | AB1: 0.35 | AC1: 0.15 | AD1: 0.15 | AE1: 0.15
E2: Atractividad | M2: Factor Atractividad | U2: Ejecutabilidad | AA2: Factor Ejecutabilidad | AI2: linea horizontal | AJ2: x | AK2: y | AX2: Variable | AY2: Porcentaje | AZ2: ATRACTIVIDAD | BG2: Variable | BH2: Porcentaje | BI2: ATRACTIVIDAD
B3: Id | C3: Cliente | D3: Nombre estudio | E3: Monto de venta | F3: Facturado | G3: Costo | H3: ROI | I3: Cercania con cliente | J3: Exposición al mercado frente a riesgos | K3: Riesgo | L3: Escalabilidad | M3: Monto de venta | N3: Facturado | O3: Costo | P3: ROI | Q3: Cercania con cliente | R3: Exposición al mercado frente a riesgos | S3: Riesgo | T3: Escalabilidad | U3: Tiempo de ejecución (meses) | V3: % de Conocimiento en REDCO | W3: % de experiencia en ejecució similar | X3: Cercania con el Core | Y3: Volumen de HHs y gestión | Z3: N° Personas | AA3: Tiempo de ejecución (meses) | AB3: % de Conocimiento en REDCO | AC3: % de experiencia en ejecució similar | AD3: Cercania con el Core | AE3: Volumen de HHs y gestión | AI3: 1 | AJ3: 1 | AK3: 3 | AZ3: 1 | BA3: 2 | BB3: 3 | BC3: 4 | BD3: 5 | BI3: 1 | BJ3: 2 | BK3: 3 | BL3: 4 | BM3: 5
B4: 1 | C4: =+_xlfn.XLOOKUP(D4,'[1]#¡REF'!C:C,'[1]#¡REF'!E:E,"!",0,1) -> ! | D4: Algarrobo Finos | E4: 847330 | F4: =+_xlfn.XLOOKUP(D4,#REF!,#REF!,"!",0,1)+223557 -> #REF! | G4: =+_xlfn.XLOOKUP(D4,#REF!,#REF!,"!",0,1) -> #REF! | H4: =+IFERROR((F4-G4)/F4,0) -> 0 | M4: 4 | P4: 5 | Q4: 5 | R4: 3 | S4: 4 | T4: 1 | U4: 16 | Y4: 3066 | Z4: 12 | AA4: 1 | AD4: 2 | AE4: 4 | AI4: 2 | AJ4: 5 | AK4: 3 | AX4: Monto de Vena | AY4: 0.25 | AZ4: < 120 KUS$ | BA4: 120 - 250 KUS$ | BB4: 250-500 KUS$ | BC4: 500-1000 KUS$ | BD4: >1M$ | BG4: Tiempo de ejecución | BH4: 0.2 | BI4: >2 años | BJ4: 12-24 meses | BK4: 8-12 meses | BL4: 4-8 meses | BM4: < 4 meses
B5: 2 | C5: =+_xlfn.XLOOKUP(D5,#REF!,#REF!,"!",0,1) -> #REF! | D5: AMSA_Asesoria Centinela | E5: =+_xlfn.XLOOKUP(D5,#REF!,#REF!,"!",0,1) -> #REF! | F5: =+_xlfn.XLOOKUP(D5,#REF!,#REF!,"!",0,1) -> #REF! | G5: =+_xlfn.XLOOKUP(D5,#REF!,#REF!,"!",0,1) -> #REF! | H5: =+IFERROR((F5-G5)/F5,0) -> 0 | M5: 2 | P5: 5 | Q5: 4 | R5: 4 | S5: 5 | T5: 3 | U5: 6 | Y5: 1112 | Z5: 8 | AA5: 4 | AD5: 4 | AE5: 5 | AX5: ROI | AY5: 0.2 | AZ5: <20% | BA5: 20%-25% | BB5: 25%-35% | BC5: 35%-45% | BD5: >45% | BG5: % de conocimiento en REDCO | BH5: 0.35 | BI5: <20% | BJ5: 20%-25% | BK5: 25%-35% | BL5: 35%-45% | BM5: >45%
B6: 3 | C6: =+_xlfn.XLOOKUP(D6,#REF!,#REF!,"!",0,1) -> #REF! | D6: Banco Santander_Yauricocha y Bolivar | E6: =+_xlfn.XLOOKUP(D6,#REF!,#REF!,"!",0,1) -> #REF! | F6: =+_xlfn.XLOOKUP(D6,#REF!,#REF!,"!",0,1) -> #REF! | G6: =+E6*45% -> #REF! | H6: =+IFERROR((F6-G6)/F6,0) -> 0 | M6: 1 | P6: 5 | Q6: 4 | R6: 3 | S6: 3 | T6: 2 | U6: 2 | Y6: 3.75 | Z6: 1 | AA6: 5 | AD6: 3 | AE6: 5 | AI6: linea vertical | AJ6: x | AK6: y | AX6: Cercania con cliente | AY6: 0.15 | AZ6: Sin historia | BA6: Referido de un cliente actual | BB6: Actual, pero solo ejecutado 1 proy. | BC6: actul y con 1 a 3 años historia | BD6: actual con más de 3 años de historia | BG6: % de experiencia en ejecución similar | BH6: 0.15 | BI6: <20% | BJ6: 20%-25% | BK6: 25%-35% | BL6: 35%-45% | BM6: >45%
B7: 4 | C7: =+_xlfn.XLOOKUP(D7,#REF!,#REF!,"!",0,1) -> #REF! | D7: Capstone Copper_Estimacion confiabilidad de planes | E7: =+_xlfn.XLOOKUP(D7,#REF!,#REF!,"!",0,1) -> #REF! | F7: =+_xlfn.XLOOKUP(D7,#REF!,#REF!,"!",0,1) -> #REF! | G7: =26074*1.35*1.35*1.4 -> 66527.811 | H7: =+IFERROR((F7-G7)/F7,0) -> 0 | M7: 2 | P7: 5 | Q7: 2 | R7: 4 | S7: 3 | T7: 4 | U7: =+(4*E7)/F7 -> #REF! | Y7: 0 | Z7: 6 | AA7: 4 | AD7: 4 | AE7: 5 | AI7: 1 | AJ7: 3 | AK7: 1 | AX7: Exposición al mercado frente a riesgo | AY7: 0.2 | AZ7: Exposición muy alta, juicio y responsabilidad penal | BA7: Exposición alta, se despliega a la industria | BB7: exposicion media, se pierde la relación con la empresa | BC7: Exposición baja, solo se pierde el proyecto | BD7: Sin exposición | BG7: cercania con el core | BH7: 0.15 | BI7: No es core de REDCO | BJ7: <30% es del core de REDCO | BK7: 30%-60% del core de REDCO | BL7: 60%-80% del core de REDCO | BM7: Full core de REDCO
B8: 5 | C8: =+_xlfn.XLOOKUP(D8,#REF!,#REF!,"!",0,1) -> #REF! | D8: CMP - FEL 2A | E8: =+_xlfn.XLOOKUP(D8,#REF!,#REF!,"!",0,1) -> #REF! | F8: =+_xlfn.XLOOKUP(D8,#REF!,#REF!,"!",0,1) -> #REF! | G8: =+_xlfn.XLOOKUP(D8,#REF!,#REF!,"!",0,1) -> #REF! | H8: =+IFERROR((F8-G8)/F8,0) -> 0 | M8: 4 | P8: 5 | Q8: 5 | R8: 3 | S8: 4 | T8: 3 | U8: 20 | Y8: 12596 | Z8: 27 | AA8: 2 | AD8: 4 | AE8: 3 | AI8: 2 | AJ8: 3 | AK8: 5 | AX8: Riesgo | AY8: 0.1 | AZ8: >40% valor de venta | BA8: 40%-30% del valor de venta | BB8: 30%-20% del valor de venta | BC8: 20%-10% del valor de venta | BD8: <10% del valor de venta | BG8: Volumen de HHs y gestión | BH8: 0.15 | BI8: >30.000 HHs | BJ8: 30.000-20.000 HHs | BK8: 20.000-10.000 | BL8: 10.000-3.000 | BM8: <3.000
B9: 6 | C9: =+_xlfn.XLOOKUP(D9,#REF!,#REF!,"!",0,1) -> #REF! | D9: Codelco_Falla Oeste | E9: =+_xlfn.XLOOKUP(D9,#REF!,#REF!,"!",0,1) -> #REF! | F9: =+_xlfn.XLOOKUP(D9,#REF!,#REF!,"!",0,1) -> #REF! | G9: =+_xlfn.XLOOKUP(D9,#REF!,#REF!,"!",0,1) -> #REF! | H9: =+IFERROR((F9-G9)/F9,0) -> 0 | M9: 1 | P9: 5 | Q9: 4 | R9: 3 | S9: 5 | T9: 3 | U9: 4 | Y9: 2352 | Z9: 10 | AA9: 4 | AD9: 4 | AE9: 5 | AX9: Escalabilidad | AY9: 0.15 | AZ9: No es escalable | BA9: Se puede escalar 30% de la solución | BB9: Se puede escalar entre un 30%-60% de la solución | BC9: 60%-80% es escalable | BD9: Todo es escalable
B10: 7 | C10: =+_xlfn.XLOOKUP(D10,#REF!,#REF!,"!",0,1) -> #REF! | D10: CSH_LOM Mina Guarello | E10: =+_xlfn.XLOOKUP(D10,#REF!,#REF!,"!",0,1) -> #REF! | F10: =+_xlfn.XLOOKUP(D10,#REF!,#REF!,"!",0,1) -> #REF! | G10: =+_xlfn.XLOOKUP(D10,#REF!,#REF!,"!",0,1) -> #REF! | H10: =+IFERROR((F10-G10)/F10,0) -> 0 | M10: 1 | P10: 2 | Q10: 1 | R10: 4 | S10: 5 | T10: 2 | U10: 8 | Y10: 822 | Z10: 5 | AA10: 3 | AD10: 4 | AE10: 5
B11: 8 | C11: =+_xlfn.XLOOKUP(D11,#REF!,#REF!,"!",0,1) -> #REF! | D11: Glencore_Coroccohuayco_OptimizacionLOM | E11: =+_xlfn.XLOOKUP(D11,#REF!,#REF!,"!",0,1) -> #REF! | F11: =+_xlfn.XLOOKUP(D11,#REF!,#REF!,"!",0,1) -> #REF! | G11: =+_xlfn.XLOOKUP(D11,#REF!,#REF!,"!",0,1) -> #REF! | H11: =+IFERROR((F11-G11)/F11,0) -> 0 | M11: 2 | P11: 5 | Q11: 3 | R11: 3 | S11: 4 | T11: 2 | U11: 5 | Y11: 2310.75 | Z11: 12 | AA11: 4 | AD11: 5 | AE11: 5
B12: 9 | C12: =+_xlfn.XLOOKUP(D12,#REF!,#REF!,"!",0,1) -> #REF! | D12: IvanhoeElectric_Santa-Cruz_PrePFS | E12: =+_xlfn.XLOOKUP(D12,#REF!,#REF!,"!",0,1) -> #REF! | F12: =+_xlfn.XLOOKUP(D12,#REF!,#REF!,"!",0,1) -> #REF! | G12: =+_xlfn.XLOOKUP(D12,#REF!,#REF!,"!",0,1) -> #REF! | H12: =+IFERROR((F12-G12)/F12,0) -> 0 | M12: 4 | P12: 4 | Q12: 2 | R12: 2 | S12: 3 | T12: 3 | U12: 7 | Y12: 7244 | Z12: 18 | AA12: 4 | AD12: 5 | AE12: 4
B13: 10 | C13: =+_xlfn.XLOOKUP(D13,#REF!,#REF!,"!",0,1) -> #REF! | D13: McCarthy_Litigio Rio Tinto | E13: =+_xlfn.XLOOKUP(D13,#REF!,#REF!,"!",0,1) -> #REF! | F13: =+_xlfn.XLOOKUP(D13,#REF!,#REF!,"!",0,1) -> #REF! | G13: =5118*1.35*1.35*1.4 -> 13058.577 | H13: =+IFERROR((F13-G13)/F13,0) -> 0 | M13: 4 | P13: 5 | Q13: 1 | R13: 3 | S13: 2 | T13: 2 | U13: =+(6*E13)/F13 -> #REF! | Y13: 149 | Z13: 4 | AA13: 4 | AD13: 2 | AE13: 5
B14: 11 | C14: =+_xlfn.XLOOKUP(D14,#REF!,#REF!,"!",0,1) -> #REF! | D14: Minsur_Apoyo Planificacion San Rafael | E14: =+_xlfn.XLOOKUP(D14,#REF!,#REF!,"!",0,1) -> #REF! | F14: =+_xlfn.XLOOKUP(D14,#REF!,#REF!,"!",0,1) -> #REF! | G14: =4299*1.35*1.35*1.4 -> 10968.899 | H14: =+IFERROR((F14-G14)/F14,0) -> 0 | M14: 1 | P14: 5 | Q14: 5 | R14: 4 | S14: 5 | T14: 3 | U14: =+(5*E14)/F14 -> #REF! | Y14: 270 | Z14: 3 | AA14: 4 | AD14: 4 | AE14: 5
B15: 12 | C15: =+_xlfn.XLOOKUP(D15,#REF!,#REF!,"!",0,1) -> #REF! | D15: NEXA_FEL2 Aripuana | E15: =+_xlfn.XLOOKUP(D15,#REF!,#REF!,"!",0,1) -> #REF! | F15: =+_xlfn.XLOOKUP(D15,#REF!,#REF!,"!",0,1) -> #REF! | G15: =+_xlfn.XLOOKUP(D15,#REF!,#REF!,"!",0,1) -> #REF! | H15: =+IFERROR((F15-G15)/F15,0) -> 0 | M15: 2 | P15: 0 | Q15: 1 | R15: 3 | S15: 3 | T15: 1 | U15: 12 | Y15: 6266.75 | Z15: 17 | AA15: 2 | AD15: 2 | AE15: 4
B16: 13 | C16: =+_xlfn.XLOOKUP(D16,#REF!,#REF!,"!",0,1) -> #REF! | D16: PFS Los Calatos | E16: =+_xlfn.XLOOKUP(D16,#REF!,#REF!,"!",0,1) -> #REF! | F16: =+_xlfn.XLOOKUP(D16,#REF!,#REF!,"!",0,1) -> #REF! | G16: =+_xlfn.XLOOKUP(D16,#REF!,#REF!,"!",0,1) -> #REF! | H16: =+IFERROR((F16-G16)/F16,0) -> 0 | M16: 4 | P16: 1 | Q16: 2 | R16: 3 | S16: 4 | T16: 3 | U16: =+(12*E16)/F16 -> #REF! | Y16: 8698 | Z16: 36 | AA16: 2 | AD16: 4 | AE16: 4
B17: 14 | C17: Seligdar | D17: Seligdar_Kyuchus | E17: 2400000 | F17: 598000 | G17: =+_xlfn.XLOOKUP(D17,#REF!,#REF!,"!",0,1) -> #REF! | H17: =+IFERROR((F17-G17)/F17,0) -> 0 | M17: 5 | P17: 5 | Q17: 1 | R17: 2 | S17: 1 | T17: 3 | U17: 8 | Y17: 3264 | Z17: 11 | AA17: 4 | AD17: 3 | AE17: 4
D18: VALE
B19: 15 | C19: =+_xlfn.XLOOKUP(D19,#REF!,#REF!,"!",0,1) -> #REF! | D19: Spence_Confiabilidad Plan 2YB 2025 | E19: =+_xlfn.XLOOKUP(D19,#REF!,#REF!,"!",0,1) -> #REF! | F19: =+_xlfn.XLOOKUP(D19,#REF!,#REF!,"!",0,1) -> #REF! | G19: =+E19*45% -> #REF! | H19: =+IFERROR((F19-G19)/F19,0) -> 0 | M19: 1 | P19: 5 | Q19: 4 | R19: 3 | S19: 5 | T19: 3 | U19: 1 | Y19: 0 | Z19: 7 | AA19: 5 | AC19: 4 | AD19: 3 | AE19: 5
M23: ATRACTIVIDAD | AA23: EJECUTABILIDAD
B24: Id | C24: Cliente | D24: Nombre estudio | M24: Monto de venta | N24: Facturado | O24: Costo | P24: ROI | Q24: Cercania con cliente | R24: Exposición al mercado frente a riesgos | S24: Riesgo | T24: Escalabilidad | AA24: Tiempo de ejecución (meses) | AB24: % de Conocimiento en REDCO | AC24: % de experiencia en ejecució similar | AD24: Cercania con el Core | AE24: Volumen de HHs y gestión
B25: 1 | C25: =+_xlfn.XLOOKUP(D26,#REF!,#REF!,"!",0,1) -> #REF! | D25: Algarrobo Finos | M25: =+M4*M$1 -> 1 | N25: =+N4*N$1 -> 0 | O25: =+O4*O$1 -> 0 | P25: =+P4*P$1 -> 1 | Q25: =+Q4*Q$1 -> 0.75 | R25: =+R4*R$1 -> 0.6 | S25: =+S4*S$1 -> 0.4 | T25: =+T4*T$1 -> 0.1 | AA25: =+AA4*AA$1 -> 0.2 | AB25: =+AB4*AB$1 -> 0 | AC25: =+AC4*AC$1 -> 0 | AD25: =+AD4*AD$1 -> 0.3 | AE25: =+AE4*AE$1 -> 0.6 | AF25: =+AF4*AF$1 -> 0
B26: 2 | C26: =+_xlfn.XLOOKUP(D27,#REF!,#REF!,"!",0,1) -> #REF! | D26: AMSA_Asesoria Centinela | J26: 120 | M26: =+M5*M$1 -> 0.5 | N26: =+N5*N$1 -> 0 | O26: =+O5*O$1 -> 0 | P26: =+P5*P$1 -> 1 | Q26: =+Q5*Q$1 -> 0.6 | R26: =+R5*R$1 -> 0.8 | S26: =+S5*S$1 -> 0.5 | T26: =+T5*T$1 -> 0.3 | AA26: =+AA5*AA$1 -> 0.8 | AB26: =+AB5*AB$1 -> 0 | AC26: =+AC5*AC$1 -> 0 | AD26: =+AD5*AD$1 -> 0.6 | AE26: =+AE5*AE$1 -> 0.75 | AF26: =+AF5*AF$1 -> 0
B27: 3 | C27: =+_xlfn.XLOOKUP(D28,#REF!,#REF!,"!",0,1) -> #REF! | D27: Banco Santander_Yauricocha y Bolivar | J27: =+J26*1000 -> 120000 | M27: =+M6*M$1 -> 0.25 | N27: =+N6*N$1 -> 0 | O27: =+O6*O$1 -> 0 | P27: =+P6*P$1 -> 1 | Q27: =+Q6*Q$1 -> 0.6 | R27: =+R6*R$1 -> 0.6 | S27: =+S6*S$1 -> 0.3 | T27: =+T6*T$1 -> 0.2 | AA27: =+AA6*AA$1 -> 1 | AB27: =+AB6*AB$1 -> 0 | AC27: =+AC6*AC$1 -> 0 | AD27: =+AD6*AD$1 -> 0.45 | AE27: =+AE6*AE$1 -> 0.75 | AF27: =+AF6*AF$1 -> 0
B28: 4 | C28: =+_xlfn.XLOOKUP(D29,#REF!,#REF!,"!",0,1) -> #REF! | D28: Capstone Copper_Estimacion confiabilidad de planes | J28: =250*1000 -> 250000 | M28: =+M7*M$1 -> 0.5 | N28: =+N7*N$1 -> 0 | O28: =+O7*O$1 -> 0 | P28: =+P7*P$1 -> 1 | Q28: =+Q7*Q$1 -> 0.3 | R28: =+R7*R$1 -> 0.8 | S28: =+S7*S$1 -> 0.3 | T28: =+T7*T$1 -> 0.4 | AA28: =+AA7*AA$1 -> 0.8 | AB28: =+AB7*AB$1 -> 0 | AC28: =+AC7*AC$1 -> 0 | AD28: =+AD7*AD$1 -> 0.6 | AE28: =+AE7*AE$1 -> 0.75 | AF28: =+AF7*AF$1 -> 0
B29: 5 | C29: =+_xlfn.XLOOKUP(D30,#REF!,#REF!,"!",0,1) -> #REF! | D29: CMP - FEL 2A | J29: =500*1000 -> 500000 | M29: =+M8*M$1 -> 1 | N29: =+N8*N$1 -> 0 | O29: =+O8*O$1 -> 0 | P29: =+P8*P$1 -> 1 | Q29: =+Q8*Q$1 -> 0.75 | R29: =+R8*R$1 -> 0.6 | S29: =+S8*S$1 -> 0.4 | T29: =+T8*T$1 -> 0.3 | AA29: =+AA8*AA$1 -> 0.4 | AB29: =+AB8*AB$1 -> 0 | AC29: =+AC8*AC$1 -> 0 | AD29: =+AD8*AD$1 -> 0.6 | AE29: =+AE8*AE$1 -> 0.45 | AF29: =+AF8*AF$1 -> 0
B30: 6 | C30: =+_xlfn.XLOOKUP(D31,#REF!,#REF!,"!",0,1) -> #REF! | D30: Codelco_Falla Oeste | J30: =1000*1000 -> 1000000 | M30: =+M9*M$1 -> 0.25 | N30: =+N9*N$1 -> 0 | O30: =+O9*O$1 -> 0 | P30: =+P9*P$1 -> 1 | Q30: =+Q9*Q$1 -> 0.6 | R30: =+R9*R$1 -> 0.6 | S30: =+S9*S$1 -> 0.5 | T30: =+T9*T$1 -> 0.3 | AA30: =+AA9*AA$1 -> 0.8 | AB30: =+AB9*AB$1 -> 0 | AC30: =+AC9*AC$1 -> 0 | AD30: =+AD9*AD$1 -> 0.6 | AE30: =+AE9*AE$1 -> 0.75 | AF30: =+AF9*AF$1 -> 0
B31: 7 | C31: =+_xlfn.XLOOKUP(D32,#REF!,#REF!,"!",0,1) -> #REF! | D31: CSH_LOM Mina Guarello | M31: =+M10*M$1 -> 0.25 | N31: =+N10*N$1 -> 0 | O31: =+O10*O$1 -> 0 | P31: =+P10*P$1 -> 0.4 | Q31: =+Q10*Q$1 -> 0.15 | R31: =+R10*R$1 -> 0.8 | S31: =+S10*S$1 -> 0.5 | T31: =+T10*T$1 -> 0.2 | AA31: =+AA10*AA$1 -> 0.6 | AB31: =+AB10*AB$1 -> 0 | AC31: =+AC10*AC$1 -> 0 | AD31: =+AD10*AD$1 -> 0.6 | AE31: =+AE10*AE$1 -> 0.75 | AF31: =+AF10*AF$1 -> 0
B32: 8 | C32: =+_xlfn.XLOOKUP(D33,#REF!,#REF!,"!",0,1) -> #REF! | D32: Glencore_Coroccohuayco_OptimizacionLOM | M32: =+M11*M$1 -> 0.5 | N32: =+N11*N$1 -> 0 | O32: =+O11*O$1 -> 0 | P32: =+P11*P$1 -> 1 | Q32: =+Q11*Q$1 -> 0.45 | R32: =+R11*R$1 -> 0.6 | S32: =+S11*S$1 -> 0.4 | T32: =+T11*T$1 -> 0.2 | AA32: =+AA11*AA$1 -> 0.8 | AB32: =+AB11*AB$1 -> 0 | AC32: =+AC11*AC$1 -> 0 | AD32: =+AD11*AD$1 -> 0.75 | AE32: =+AE11*AE$1 -> 0.75 | AF32: =+AF11*AF$1 -> 0
B33: 9 | C33: =+_xlfn.XLOOKUP(D34,#REF!,#REF!,"!",0,1) -> #REF! | D33: IvanhoeElectric_Santa-Cruz_PrePFS | M33: =+M12*M$1 -> 1 | N33: =+N12*N$1 -> 0 | O33: =+O12*O$1 -> 0 | P33: =+P12*P$1 -> 0.8 | Q33: =+Q12*Q$1 -> 0.3 | R33: =+R12*R$1 -> 0.4 | S33: =+S12*S$1 -> 0.3 | T33: =+T12*T$1 -> 0.3 | AA33: =+AA12*AA$1 -> 0.8 | AB33: =+AB12*AB$1 -> 0 | AC33: =+AC12*AC$1 -> 0 | AD33: =+AD12*AD$1 -> 0.75 | AE33: =+AE12*AE$1 -> 0.6 | AF33: =+AF12*AF$1 -> 0
B34: 10 | C34: =+_xlfn.XLOOKUP(D35,#REF!,#REF!,"!",0,1) -> #REF! | D34: McCarthy_Litigio Rio Tinto | M34: =+M13*M$1 -> 1 | N34: =+N13*N$1 -> 0 | O34: =+O13*O$1 -> 0 | P34: =+P13*P$1 -> 1 | Q34: =+Q13*Q$1 -> 0.15 | R34: =+R13*R$1 -> 0.6 | S34: =+S13*S$1 -> 0.2 | T34: =+T13*T$1 -> 0.2 | AA34: =+AA13*AA$1 -> 0.8 | AB34: =+AB13*AB$1 -> 0 | AC34: =+AC13*AC$1 -> 0 | AD34: =+AD13*AD$1 -> 0.3 | AE34: =+AE13*AE$1 -> 0.75 | AF34: =+AF13*AF$1 -> 0
B35: 11 | C35: =+_xlfn.XLOOKUP(D36,#REF!,#REF!,"!",0,1) -> #REF! | D35: Minsur_Apoyo Planificacion San Rafael | M35: =+M14*M$1 -> 0.25 | N35: =+N14*N$1 -> 0 | O35: =+O14*O$1 -> 0 | P35: =+P14*P$1 -> 1 | Q35: =+Q14*Q$1 -> 0.75 | R35: =+R14*R$1 -> 0.8 | S35: =+S14*S$1 -> 0.5 | T35: =+T14*T$1 -> 0.3 | AA35: =+AA14*AA$1 -> 0.8 | AB35: =+AB14*AB$1 -> 0 | AC35: =+AC14*AC$1 -> 0 | AD35: =+AD14*AD$1 -> 0.6 | AE35: =+AE14*AE$1 -> 0.75 | AF35: =+AF14*AF$1 -> 0
B36: 12 | C36: =+_xlfn.XLOOKUP(D37,#REF!,#REF!,"!",0,1) -> #REF! | D36: NEXA_FEL2 Aripuana | M36: =+M15*M$1 -> 0.5 | N36: =+N15*N$1 -> 0 | O36: =+O15*O$1 -> 0 | P36: =+P15*P$1 -> 0 | Q36: =+Q15*Q$1 -> 0.15 | R36: =+R15*R$1 -> 0.6 | S36: =+S15*S$1 -> 0.3 | T36: =+T15*T$1 -> 0.1 | AA36: =+AA15*AA$1 -> 0.4 | AB36: =+AB15*AB$1 -> 0 | AC36: =+AC15*AC$1 -> 0 | AD36: =+AD15*AD$1 -> 0.3 | AE36: =+AE15*AE$1 -> 0.6 | AF36: =+AF15*AF$1 -> 0
B37: 13 | C37: =+_xlfn.XLOOKUP(D38,#REF!,#REF!,"!",0,1) -> #REF! | D37: PFS Los Calatos | M37: =+M16*M$1 -> 1 | N37: =+N16*N$1 -> 0 | O37: =+O16*O$1 -> 0 | P37: =+P16*P$1 -> 0.2 | Q37: =+Q16*Q$1 -> 0.3 | R37: =+R16*R$1 -> 0.6 | S37: =+S16*S$1 -> 0.4 | T37: =+T16*T$1 -> 0.3 | AA37: =+AA16*AA$1 -> 0.4 | AB37: =+AB16*AB$1 -> 0 | AC37: =+AC16*AC$1 -> 0 | AD37: =+AD16*AD$1 -> 0.6 | AE37: =+AE16*AE$1 -> 0.6 | AF37: =+AF16*AF$1 -> 0
B38: 14 | C38: Seligdar | D38: Seligdar_Kyuchus | M38: =+M17*M$1 -> 1.25 | N38: =+N17*N$1 -> 0 | O38: =+O17*O$1 -> 0 | P38: =+P17*P$1 -> 1 | Q38: =+Q17*Q$1 -> 0.15 | R38: =+R17*R$1 -> 0.4 | S38: =+S17*S$1 -> 0.1 | T38: =+T17*T$1 -> 0.3 | AA38: =+AA17*AA$1 -> 0.8 | AB38: =+AB17*AB$1 -> 0 | AC38: =+AC17*AC$1 -> 0 | AD38: =+AD17*AD$1 -> 0.45 | AE38: =+AE17*AE$1 -> 0.6 | AF38: =+AF17*AF$1 -> 0
D39: VALE | M39: =+M18*M$1 -> 0 | N39: =+N18*N$1 -> 0 | O39: =+O18*O$1 -> 0 | P39: =+P18*P$1 -> 0 | Q39: =+Q18*Q$1 -> 0 | S39: =+S18*S$1 -> 0 | T39: =+T18*T$1 -> 0 | AA39: =+AA18*AA$1 -> 0 | AB39: =+AB18*AB$1 -> 0 | AC39: =+AC18*AC$1 -> 0 | AD39: =+AD18*AD$1 -> 0 | AE39: =+AE18*AE$1 -> 0 | AF39: =+AF19*AF$1 -> 0
B40: 15 | C40: =+_xlfn.XLOOKUP(D45,#REF!,#REF!,"!",0,1) -> #REF! | D40: Spence_Confiabilidad Plan 2YB 2025 | M40: =+M19*M$1 -> 0.25 | N40: =+N19*N$1 -> 0 | O40: =+O19*O$1 -> 0 | P40: =+P19*P$1 -> 1 | Q40: =+Q19*Q$1 -> 0.6 | R40: =+R19*R$1 -> 0.6 | S40: =+S19*S$1 -> 0.5 | T40: =+T19*T$1 -> 0.3 | AA40: =+AA19*AA$1 -> 1 | AB40: =+AB19*AB$1 -> 0 | AC40: =+AC19*AC$1 -> 0.6 | AD40: =+AD19*AD$1 -> 0.45 | AE40: =+AE19*AE$1 -> 0.75
B46: Id | C46: Cliente | D46: Nombre estudio | M46: Ejecutabilidad | P46: Atractividad
B47: 1 | C47: =+_xlfn.XLOOKUP(D48,#REF!,#REF!,"!",0,1) -> #REF! | D47: Algarrobo Finos | M47: =+SUM(AA25:AE25) -> 1.1 | P47: =+SUM(M25:T25) -> 3.85
B48: 2 | C48: =+_xlfn.XLOOKUP(D49,#REF!,#REF!,"!",0,1) -> #REF! | D48: AMSA_Asesoria Centinela | M48: =+SUM(AA26:AE26) -> 2.15 | P48: =+SUM(M26:T26) -> 3.7
...

Sheet Perú
A1: ID | B1: Tipo Ciente | C1: Empresa | D1: Mina | E1: Descripcion Oportunidad | F1: Monto (USD)
A2: 1 | B2: Premium | C2: Minsur S.A. | D2: San Rafael | E2: Apoyo transversal a la planificación: Forecast, Budget, LOM | F2: 200 | G2: =+F2*1000 -> 200000
A3: 2 | B3: Premium | C3: Minsur S.A. | D3: San Rafael | E3: Proyectización e integración de zonas potenciales | F3: 120 | G3: =+F3*1000 -> 120000
A4: 3 | B4: Premium | C4: Minsur S.A. | D4: San Rafael | E4: Estandarización de procesos de control, cumplimiento y reconciliación | F4: 150 | G4: =+F4*1000 -> 150000
A5: 4 | B5: Premium | C5: Compañía Minera Raura S.A. | D5: Raura | E5: Oportunidades Budget 2025 | F5: 70 | G5: =+F5*1000 -> 70000
A6: 5 | B6: Premium | C6: Compañía Minera Raura S.A. | D6: Raura | E6: Apoyo transversal a la planificación: Forecast, Budget, LOM | F6: 200 | G6: =+F6*1000 -> 200000
A7: 6 | B7: Premium | C7: Minsur S.A. | E7: Compilación R&R | F7: 200 | G7: =+F7*1000 -> 200000
A8: 7 | B8: Regular | C8: Hochschild Mining (Peru) S.A. | D8: Inmaculada | E8: Estudio geomecánico y trade off de métodos de explotación | F8: 50 | G8: =+F8*1000 -> 50000
A9: 8 | B9: Target | C9: Compañía de Minas Buenaventura | D9: - | E9: Análisis de confiabilidad de planes | F9: 150 | G9: =+F9*1000 -> 150000
A10: 9 | B10: Target | C10: Gold Fields | D10: Cerro Corona | E10: Implementación de un sistema de mapeo estructural automatizado | F10: 100 | G10: =+F10*1000 -> 100000
A11: 10 | B11: Regular | C11: Hochschild Mining (Peru) S.A. | D11: Inmaculada | E11: Asesoría Técnica para la Identificación de Oportunidades de Mejora para Incremento de Producción Mina | F11: 150 | G11: =+F11*1000 -> 150000
A12: 11 | B12: Regular | C12: Coripuno | D12: Torremani | E12: Actualización de métodos de minado Torremani (Etapa II) | F12: 100 | G12: =+F12*1000 -> 100000
A13: 12 | B13: Target | C13: Glencore | D13: Coroccohuayco | E13: Estudios Mineros para la PFS | F13: 150 | G13: =+F13*1000 -> 150000
A14: 13 | B14: Target | C14: Hudbay Perú S.A.C | D14: Constancia | E14: Estudio de Factibilidad del WRF y Tajo Constancia para la 4ta MEIA | F14: 150 | G14: =+F14*1000 -> 150000
A15: 14 | B15: Target | C15: Las Bambas | D15: Ferrobamba | E15: Ferrobamba UG (PFS) | F15: 1200 | G15: =+F15*1000 -> 1200000
A16: 15 | B16: Target | C16: Sierra metals | D16: Yauricocha | E16: Desarrollo de Reservas | F16: 150 | G16: =+F16*1000 -> 150000
A17: 16 | B17: Target | C17: Sierra metals | D17: Bolivar | E17: Desarrollo de Reservas | F17: 150 | G17: =+F17*1000 -> 150000
A18: 17 | B18: Target | C18: Volcan Compañía Minera S.A.A. | D18: Todas | E18: Estudio de Validación de R&R | F18: 80 | G18: =+F18*1000 -> 80000
A19: 18 | B19: Target | C19: Volcan Compañía Minera S.A.A. | D19: Romina | E19: Servicio de apoyo para presentación a la autoridad de ROMINA actualizado | F19: 80 | G19: =+F19*1000 -> 80000
... A21: 20 | B21: Target | C21: Volcan Compañía Minera S.A.A. | D21: Chungar | E21: Estudio Conceptual/PFS Proyecto Esperanza | F21: 150 | G21: =+F21*1000 -> 150000
A22: 21 | B22: Target | C22: Miski Mayo | E22: Apoyo transversal a la planificación: Forecast, Budget, LOM | F22: 150 | G22: =+F22*1000 -> 150000
A27: 22 | B27: Leads | C27: Tantahuatay
A28: 23 | B28: Leads | C28: Compañía Minera Condestable S.A
A29: 24 | B29: Leads | C29: Pan American Dolores
A30: 25 | B30: Leads | C30: Hochschild Mining plc
A31: 26 | B31: Leads | C31: Alpayana
A32: 27 | B32: Leads | C32: Pan American Silver Corp.
A33: 28 | B33: Leads | C33: Vulco Perú S.A.
A34: 29 | B34: Leads | C34: Minera Yanacocha S.R.L.
A35: 30 | B35: Leads | C35: Southern Peru Copper
A36: 31 | B36: Leads | C36: Anglo American Quellaveco S.A.
A37: 32 | B37: Leads | C37: Barrick Latam
A38: 33 | B38: Leads | C38: Compañía Minera Zafranal S.A.C.
... A50: 45 | B50: Leads | C50: Minera Boroo Misquichilca

Sheet Chile
A1: ID | B1: Tipo Ciente | C1: Empresa | D1: Mina | E1: Descripcion Oportunidad | F1: Monto (USD) | G1: Fecha de contacto | H1: Fecha de Inicio | I1: Duración | J1: Gestor Comercial | K1: Contacto clave | L1: Comentarios
A3: 14 | B3: Premium | C3: CMP
A4: 15 | B4: Premium | C4: CMP | D4: CNN | E4: Estudio FEL 2B | F4: 100
A5: 16 | B5: Premium | C5: CMP | D5: CNN | E5: Apoyo permisos | F5: 30
A6: 17 | B6: Premium | C6: CMP | D6: CNN | E6: Estudio FEL 3 | F6: 150
A7: 18 | B7: Premium | C7: CMP | D7: Romeral | E7: FEL 1 o FEL 2A formal | F7: 50
A8: 19 | B8: Premium | C8: CMP | D8: Algarrobo | E8: Estudio conceptual UG - SLS + túnel + opc. OP | F8: 150
A9: 20 | B9: Premium | C9: CMP | D9: Algarrobo | E9: Asistencia técnica Implementación Proyecto (ingeniería, permisos sectoriales) | F9: 50
A10: 21 | B10: Premium | C10: CMP | D10: Algarrobo | E10: FEL 2A UG - SLS | F10: 80
A11: 22 | B11: Premium | C11: CMP | D11: MLC | E11: Estudio FEL 2 B | F11: 150
A12: 23 | B12: Premium | C12: CMP | D12: Corporativo | E12: Implementación del estándar de planificación | F12: 150
A13: 24 | B13: Premium | C13: AMSA | D13: Centinela | E13: Planificación - Diseño | F13: 350
A14: 25 | B14: Premium | C14: AMSA
A15: 26 | B15: Premium | C15: AMSA
A16: 27 | B16: Premium | C16: AMSA | D16: Pelambres | E16: Planificación - Diseño | F16: 350
A20: 6 | B20: Premium | C20: Codelco | D20: DCH | E20: Analisis oportunidades de recuperación de reservas colapsadas | F20: 100 | G20: 45658 | H20: 45717 | I20: 2 | J20: MM | K20: Rodrigo Quiroz
A21: 7 | B21: Premium | C21: Codelco | D21: DRT | E21: Metodologia para establecer escenarios productivos de corto plazo (Incoporar SIMPLAN en proceso de planificación o Simprep OP) | F21: 120 | G21: =+G20 -> 45658 | H21: =+H20 -> 45717 | I21: 3 | J21: MM | K21: Sebastian Pizarro
A22: 8 | B22: Premium | C22: Codelco | D22: DET | E22: Implementación de SIMPREP | F22: 100 | G22: =+G21 -> 45658 | H22: =+H21 -> 45717 | I22: 4 | J22: MM | K22: Patricio Miranda | L22: Enrique tomo contacto con gerente Felipe Hidalgo
A23: 9 | B23: Premium | C23: Codelco | D23: DRT | E23: Actualización de estandares y procedimientos de planificación, balances, muestreo, etc (replicar estudios realizados para otras operaciones) | F23: 120 | G23: =+G22 -> 45658 | H23: =+H22 -> 45717 | I23: 3 | J23: MM | K23: Sebastian Pizarro
A24: 10 | B24: Premium | C24: Codelco | D24: GRM | E24: Revisiones independientes | F24: 150 | G24: 45717 | H24: 45839 | I24: 3 | J24: MM | K24: Ximena Policroni Galvez | L24: A la espera de licitación en la cual nos tienen contemplados
A25: 11 | B25: Premium | C25: Codelco | D25: GRM | E25: Profundicación de actualización de NCC31 (con apoyo consultor) | F25: 100 | G25: 45689 | H25: =+H23 -> 45717 | I25: 3 | J25: MM | K25: Fernando Marambio | L25: A la espera de cerrar el estudio actual para avanzar con la etapa 2 (profundización)
A26: 12 | B26: Target | C26: Codelco | D26: DCH | E26: Estudios de oportunidad en planes OP (alargar vida del rajo, recuepeación de stocks y los botaderos, zonas de contacto entre ambos rajos) | F26: 200 | G26: 45658 | H26: 45748 | I26: 3 | J26: CC | K26: Juan Cristobal Videla
A27: 13 | B27: Target | C27: Codelco | D27: DET | E27: Analisis de oportunidades del plan minero, generar coberturas debido a atrasos en proyectos | F27: 150 | G27: 45658 | H27: 45748 | I27: 3 | J27: CC | K27: Felipe Hidalgo
A28: 14 | B28: Target | C28: Codelco | D28: DCH | E28: Implementación de SIMPREP | F28: 100 | G28: =+G27 -> 45658 | H28: =+H27 -> 45748 | I28: 4 | J28: MM | K28: Rodrigo Quiroz | L28: Evaluar la mejor estrategia de implementar esto (tanto para DCH y DET)
A29: 15 | B29: Target | C29: Codelco | D29: Distrito Norte | E29: Evaluación de oportunidades de optimización integrada Distrito Norte | F29: 200 | G29: 45658 | J29: CC | K29: Juan San Martin
B30: Target | C30: Codelco | D30: DMH | E30: XXXXXX | G30: =+G29 -> 45658 | J30: CC, MM | K30: Jose Miguel Castro
A34: 29
A35: 30
A36: 31
A37: 32
A38: 33
A39: 34 | B39: Target | C39: Glencore | D39: Lomas Bayas | E39: Planificación - Diseño | F39: 300
A40: 35 | B40: Target | C40: MCI | D40: Los Bronces | E40: Los Bronces Mine Plan Review | F40: 300
A41: 36 | B41: Target | C41: Collahuasi | E41: Planificación - Diseño | F41: 300
A42: 37 | B42: Target | C42: BHP | D42: Escondida | E42: Planificación - Diseño | F42: 500
A43: 38 | B43: Target | C43: BHP | D43: Spence | E43: Planificación - Diseño | F43: 500
A44: 39 | B44: Target | C44: MARA | E44: Planificación - Diseño | F44: 150
A45: 40 | B45: Target | C45: Anglo American | D45: Los Bronces | E45: Planificación - Diseño | F45: 300
A46: 41 | B46: Regular
A47: 42 | B47: Regular | C47: CEMIN | E47: Planificación - Diseño | F47: 90
...

Sheet Brasil
A1: ID | B1: Tipo Ciente | C1: Empresa | D1: Mina | E1: Descripcion Oportunidad | F1: Monto (USD)
A2: 1 | B2: Premium | C2: Mosaic | D2: Cajati | E2: Cajati P2 | F2: 400 | G2: =+F2*1000 -> 400000
A3: 2 | B3: Premium | C3: Mosaic | D3: Cajati | E3: Mosaic CTV 5Y Plan + Fase II | F3: 350 | G3: =+F3*1000 -> 350000
A4: 3 | B4: Premium | C4: Aura Minerals | E4: Fase 1 | F4: 230 | G4: =+F4*1000 -> 230000
A5: 4 | B5: Premium | C5: Aura Minerals | E5: Fase 2 | F5: 220 | G5: =+F5*1000 -> 220000
A6: 5 | B6: Premium | C6: Lhg | D6: Mina Urucum | E6: Remoción Pilares y Secuecia Operativa | F6: 150 | G6: =+F6*1000 -> 150000
A7: 6 | B7: Target | C7: Vale | E7: Proyectos Subeterraneaos | F7: 220 | G7: =+F7*1000 -> 220000
A8: 7 | B8: Target | C8: Vale | E8: IQS | F8: 450 | G8: =+F8*1000 -> 450000
A9: 8 | B9: Target | C9: EuroChen | E9: Planificación - Diseño | F9: 130 | G9: =+F9*1000 -> 130000
A10: 9 | B10: Target | C10: Alcoa | E10: Planificación - Diseño | F10: 150 | G10: =+F10*1000 -> 150000
A11: 10 | B11: Target | C11: AngloGold Ashanti | E11: Planificación - Diseño | F11: 150 | G11: =+F11*1000 -> 150000 | I11: gerente sumintro y planeamienot mina
A12: 11 | B12: Target | C12: Samarco | E12: Geotecnica y planeamiento | F12: 150 | G12: =+F12*1000 -> 150000 | I12: gerente de geotecnica
A13: 12 | B13: Target | C13: Anglo American | E13: Planificación - Diseño | F13: 300 | G13: =+F13*1000 -> 300000
A14: 13 | B14: Regular | C14: Nexa | D14: Aripuna | E14: Planificación - Diseño | F14: 150 | G14: =+F14*1000 -> 150000
A15: 14 | B15: Leads | C15: Hochschild Mining plc Mara Rosa
A16: 15 | B16: Leads | C16: CBMM
A17: 16 | B17: Leads | C17: CSN
A18: 17 | B18: Leads | C18: Eurochem
A19: 18 | B19: Leads | C19: Erro Copper
A20: 19 | B20: Leads | C20: Gerdau
A21: 20 | B21: Leads | C21: BHP/OZ
A22: 21 | B22: Leads | C22: Vale
A23: 22 | B23: Leads | C23: Arcelor-Mittal
A24: 23 | B24: Leads | C24: Atlantic Nickel
A25: 24 | B25: Leads | C25: Rio Tinto
A26: 25 | B26: Leads | C26: Equinox Gold
... A78: 77 | B78: Leads | C78: Kinrross

Sheet EEUU
A1: ID | B1: Tipo Ciente | C1: Empresa | D1: Mina | E1: Descripcion Oportunidad | F1: Monto 2025 USD | G1: Contrato | H1: Propuesta | I1: Cant Pptas Nuevas
A2: 1 | B2: Premium | C2: Twin Metals Minnesota | D2: Birch Lake - Maturi | E2: Pre-Prefactibilidad Birch Lake + Tunnel acceso a Maturi | F2: 300 | G2: Vigente | H2: NA
A3: 2 | B3: Premium | C3: Twin Metals Minnesota | E3: Prefactibilidad para el conjunto Birch Lake - Maturi | F3: 800 | G3: Nuevo | H3: Nueva | I3: 2
A4: 3 | B4: Regular | C4: EMX Royalty | E4: Technical support for royalty acquisition | F4: 300 | G4: Nuevo | H4: Nueva | I4: 3
A5: 4 | B5: Target | C5: Ivanhoe Electric | D5: Santa Cruz | E5: FS Santa Cruz Project UG - Revision Técnica | F5: 100 | G5: Nuevo | H5: Nueva | I5: 1
A6: 5 | B6: Target | C6: Highland Copper | D6: Copperwood | E6: FS + Detail Engineering | F6: 600 | G6: Nuevo | H6: Vigente
A7: 6 | B7: Target | C7: BHP | D7: Resolution | E7: Caso Base Resolution: diseño , planes, evalaucion | F7: 200 | G7: Vigente | H7: Vigente
A8: 7 | B8: Target | C8: BHP | D8: Resolution | E8: Estudios - Diseños - Planes | F8: 300 | G8: Nuevo | H8: Nueva | I8: 2
A9: 8 | B9: Target | C9: BHP | D9: Antamina | E9: Estudios - Diseños - Planes | F9: 150 | G9: Nuevo | H9: Nueva | I9: 1
A10: 9 | B10: Target | C10: BHP | D10: CU South Australia | E10: Estudios - Diseños - Planes | F10: 200 | G10: Nuevo | H10: Nueva | I10: 2
A11: 10 | B11: Target | C11: Freeport-McMoRan Inc. | D11: PTFI | E11: SIMPREP | F11: 150 | G11: Nuevo | H11: Nueva | I11: 1
A12: 11 | B12: Target | C12: Freeport-McMoRan Inc. | D12: PTFI | E12: Planificación - Diseño | F12: 200 | G12: Nuevo | H12: Nueva | I12: 1
A13: 12 | B13: Target | C13: Newmont Mining | E13: Planificación - Diseño | F13: 200 | G13: Nuevo | H13: Nueva | I13: 2
A14: 13 | B14: Target | C14: Anglo Gold Ashanti | E14: Planificación - Diseño | F14: 200 | G14: Nuevo | H14: Nueva | I14: 2
A15: 14 | B15: Leads | C15: Vale | E15: Planificación - Diseño | F15: 150 | G15: Nuevo | H15: Nueva | I15: 2
A16: 15 | B16: Leads | C16: South 32 | E16: Planificación - Diseño | F16: 100 | G16: Nuevo | H16: Nueva | I16: 1
A17: 16 | B17: Leads | C17: Barrick | E17: Planificación - Diseño | F17: 100 | G17: Nuevo | H17: Nueva | I17: 1
A18: 17 | B18: Leads | C18: Lundin | D18: Eagle | E18: Planificación - Diseño | F18: 100 | G18: Nuevo | H18: Nueva | I18: 1
A19: 18 | B19: Leads | C19: Kinross | E19: Planificación - Diseño | F19: 200 | G19: Nuevo | H19: Nueva | I19: 2
A20: 19 | B20: Leads | C20: Cleveland-Cliffs
A21: 20 | B21: Leads | C21: Pan American Silver Corp.
A22: 21 | B22: Leads | C22: Endeavour Silver Corp.
A23: 22 | B23: Leads | C23: Calibre Mining Corp.
A24: 23 | B24: Leads | C24: FMC Corporation
A25: 24 | B25: Leads | C25: Peabody Energy
A26: 25 | B26: Leads | C26: Southern Copper
A27: 26 | B27: Leads | C27: Midas Gold Corp.
A28: 27 | B28: Leads | C28: Hecla Mining Company
A29: 28 | B29: Leads | C29: Royal Gold
A30: 29 | B30: Leads | C30: Albemarle
A31: 30 | B31: Leads | C31: Mosaic
... A37: 36 | B37: Leads | C37: Hecla mining

Sheet CRM (v1)
B1: Información Iniciativas | N1: Evaluación de Riesgo | T1: Status de las Iniciativas | AK1: Comentarios Seguimiento
A2: País | B2: ID | C2: Tipo | D2: Descripcion Oportunidad | E2: Empresa | F2: Mina | G2: Gestor Comercial | H2: Monto (USD) | I2: Duracion (meses) | J2: Tipo Cliente | K2: Tipo de Mineria | L2: Tipo de Contrato | N2: USD/mes | O2: Riesgo | R2: Valor Final | T2: Contacto Inicial / Enganche | U2: Café/Llamada | V2: Presentación REDCO | W2: Presentación Ad-hoc | X2: Solicitud Propuesta | Y2: Construcción PPT | Z2: Construcción Word | AA2: Presentación Presencial | AB2: Propuesta Enviada | AC2: Seguimiento | AD2: Cierre y Negociación | AE2: ODS | AH2: Estado | AI2: Motivo | AK2: Semana 1 | AL2: Semana 2 | AM2: Semana 3 | AN2: Abril | AO2: Mayo | AP2: Junio | AQ2: Julio | AR2: Agosto | AS2: Septiembre | AT2: Octubre | AU2: Noviembre | AV2: Diciembre
A3: Chile | B3: 1 | C3: Estudios de ing. de minas | D3: Ing de factibilidad: Diseño de botaderos | E3: BPH | F3: Cerro Colorado | G3: PA | H3: 450000 | I3: 6 | J3: Target | K3: OP | L3: Licitación | N3: =+H3/I3 -> 75000 | T3: FALSE | U3: FALSE | V3: TRUE | W3: TRUE | X3: TRUE | Y3: TRUE | Z3: TRUE | AA3: TRUE | AB3: TRUE | AC3: TRUE | AD3: FALSE | AH3: Seguimiento | AI3: N/A | AK3: Coordinar reunión con cliente
A4: Chile | B4: 2 | C4: Estudios de ing. de minas | D4: Ing. Pre factibilidad perforación DHH | E4: Anglo American | F4: Los Bronces | G4: RM | H4: 180000 | I4: 3 | J4: Target | K4: OP | L4: Solicitud Directa | N4: =+H4/I4 -> 60000 | T4: TRUE | U4: TRUE | V4: TRUE | W4: TRUE | X4: TRUE | Y4: TRUE | Z4: FALSE | AA4: TRUE | AB4: TRUE | AC4: TRUE | AD4: FALSE | AH4: Seguimiento | AI4: N/A
A5: Perú | B5: 3 | C5: Estudios de ing. de minas | D5: PFS Ferrobamba Deep | E5: Las Bambas | F5: Ferrobamba | G5: EL | H5: 1100000 | I5: 12 | J5: Target | K5: UG | L5: Licitación | N5: =+H5/I5 -> 91666.667 | T5: FALSE | U5: FALSE | V5: FALSE | W5: FALSE | X5: TRUE | Y5: TRUE | Z5: TRUE | AA5: TRUE | AB5: TRUE | AC5: TRUE | AD5: TRUE | AH5: Seguimiento | AI5: N/A
A6: Chile | B6: 4 | C6: Planificación estratégica | D6: Evaluación caso de negocio explotación SLS | E6: CMP | F6: Algarrobo | G6: FR | H6: 170000 | I6: 3 | J6: Premium | K6: UG | L6: Licitación | N6: =+H6/I6 -> 56666.667 | T6: FALSE | U6: TRUE | V6: FALSE | W6: TRUE | X6: TRUE | Y6: TRUE | Z6: TRUE | AA6: TRUE | AB6: TRUE | AC6: TRUE | AD6: FALSE | AH6: No Adjudicada | AI6: Anulación de licitación
A7: EEUU | B7: 5 | C7: Consultoría minera | D7: Soporte caso de litigio Rio Tinto vs Gobierno Mongolia | E7: Rio Tinto | F7: Oyu Tolgoi | G7: PV | H7: 566000 | I7: 4 | J7: Target | K7: UG | L7: Solicitud Directa | N7: =+H7/I7 -> 141500 | T7: TRUE | U7: TRUE | V7: FALSE | W7: TRUE | X7: TRUE | Y7: TRUE | Z7: FALSE | AA7: TRUE | AB7: TRUE | AC7: TRUE | AD7: TRUE | AH7: Seguimiento | AI7: N/A
T8: FALSE | U8: FALSE | V8: TRUE | W8: FALSE | X8: FALSE | Y8: FALSE | Z8: FALSE | AA8: FALSE | AB8: FALSE | AC8: FALSE | AD8: FALSE
T9: FALSE | U9: FALSE | V9: TRUE | W9: FALSE | X9: FALSE | Y9: FALSE | Z9: FALSE | AA9: TRUE | AB9: FALSE | AC9: FALSE | AD9: FALSE
T10: FALSE | U10: FALSE | V10: FALSE | W10: FALSE | X10: FALSE | Y10: FALSE | Z10: FALSE | AA10: FALSE | AB10: FALSE | AC10: FALSE | AD10: FALSE
T11: FALSE | U11: FALSE | V11: FALSE | W11: FALSE | X11: FALSE | Y11: FALSE | Z11: FALSE | AA11: FALSE | AB11: FALSE | AC11: FALSE | AD11: FALSE
T12: FALSE | U12: FALSE | V12: FALSE | W12: FALSE | X12: FALSE | Y12: FALSE | Z12: FALSE | AA12: FALSE | AB12: FALSE | AC12: FALSE | AD12: FALSE
T13: FALSE | U13: FALSE | V13: FALSE | W13: FALSE | X13: FALSE | Y13: FALSE | Z13: FALSE | AA13: FALSE | AB13: FALSE | AC13: FALSE | AD13: FALSE
T14: FALSE | U14: FALSE | V14: FALSE | W14: FALSE | X14: FALSE | Y14: FALSE | Z14: FALSE | AA14: FALSE | AB14: FALSE | AC14: FALSE | AD14: FALSE
T15: FALSE | U15: FALSE | V15: FALSE | W15: FALSE | X15: FALSE | Y15: FALSE | Z15: FALSE | AA15: FALSE | AB15: FALSE | AC15: FALSE | AD15: FALSE
T16: FALSE | U16: FALSE | V16: FALSE | W16: FALSE | X16: FALSE | Y16: FALSE | Z16: FALSE | AA16: FALSE | AB16: FALSE | AC16: FALSE | AD16: FALSE
T17: FALSE | U17: FALSE | V17: FALSE | W17: FALSE | X17: FALSE | Y17: FALSE | Z17: FALSE | AA17: FALSE | AB17: FALSE | AC17: FALSE | AD17: FALSE
T18: FALSE | U18: FALSE | V18: FALSE | W18: FALSE | X18: FALSE | Y18: FALSE | Z18: FALSE | AA18: FALSE | AB18: FALSE | AC18: FALSE | AD18: FALSE

Sheet Resumen cantidades
A3: Cuenta de Monto (USD) | B3: Etiquetas de columna
A4: Etiquetas de fila | B4: Cierre y Negociacón | C4: Construcción Propuesta | D4: Contacto Inicial (Enganche) | E4: Iniciativa | F4: No Adjudicada | G4: ODS | H4: Presentación Ad-Hoc | I4: Seguimiento | J4: Total general
A5: Brasil | B5: 1 | C5: 4 | D5: 1 | E5: 10 | F5: 2 | I5: 4 | J5: 22
A6: Chile | B6: 4 | C6: 4 | D6: 6 | E6: 21 | F6: 2 | G6: 6 | H6: 1 | I6: 8 | J6: 52
A7: EEUU | E7: 17 | G7: 1 | I7: 2 | J7: 20
A8: Perú | B8: 2 | C8: 1 | D8: 6 | E8: 7 | F8: 3 | G8: 3 | I8: 4 | J8: 26
A9: Total general | B9: 7 | C9: 9 | D9: 13 | E9: 55 | F9: 7 | G9: 10 | H9: 1 | I9: 18 | J9: 120
B13: País | C13: Iniciativa | D13: Contacto Inicial (Enganche) | E13: Construcción Propuesta | F13: Seguimiento | G13: Cierre y Negociación | H13: ODS | I13: Total General
B14: Cantidad | C14: =+GETPIVOTDATA("Monto (USD)",$A$3,"Etapa","Iniciativa ") -> 55 | D14: =+GETPIVOTDATA("Monto (USD)",$A$3,"Etapa","Contacto Inicial (Enganche)") -> 13 | E14: =+GETPIVOTDATA("Monto (USD)",$A$3,"Etapa","Construcción Propuesta") -> 9 | F14: =+GETPIVOTDATA("Monto (USD)",$A$3,"Etapa","Seguimiento") -> 18 | G14: =+GETPIVOTDATA("Monto (USD)",$A$3,"Etapa","Cierre y Negociacón") -> 7 | H14: =+GETPIVOTDATA("Monto (USD)",$A$3,"Etapa","ODS") -> 10 | I14: =+SUM(C14:G14) -> 102
B15: Dif | C15: -2 | D15: 1 | E15: -2 | F15: -5 | H15: 3 | I15: 1

Sheet Gestión
B1: Etapa | C1: (Varios elementos)
B3: Etiquetas de fila | C3: Suma de Monto (USD)
B4: Premium | C4: 1756000 | S4: Marzo | U4: Abril
B5: Regular | C5: 380000 | M5: País | N5: Ventas Enero | O5: Ventas Febrero | P5: Proyección Marzo | Q5: Proyección Abril | R5: Proyección (vendido) | S5: Proyección (posibles)
B6: Target | C6: 556000 | M6: Brasil | N6: 0 | O6: 0 | P6: =+SUM(R6:S6) -> 474400 | Q6: 630000 | R6: 380000 | S6: 94400
B7: Total general | C7: 2692000 | M7: Chile | N7: 450000 | O7: 211000 | P7: =+SUM(R7:S7) -> 310000 | Q7: 1560000 | R7: 30000 | S7: 280000
J8: 9,5 seguimiento y construcción | M8: EEUU | N8: 116000 | O8: 0 | P8: =+SUM(R8:S8) -> 0 | Q8: 0 | R8: 0 | S8: 0
M9: Perú | N9: 490000 | O9: 1035000 | P9: =+SUM(R9:S9) -> 108000 | Q9: 0 | R9: 20000 | S9: 88000
M10: Total | N10: =+SUM(N6:N9) -> 1056000 | O10: =+SUM(O6:O9) -> 1246000 | P10: =+SUM(P6:P9) -> 892400 | Q10: =+SUM(Q6:Q9) -> 2190000 | R10: =+SUM(R6:R9) -> 430000 | S10: =+SUM(S6:S9) -> 462400
M12: Propuestas
L14: Ítem | M14: Unidad | N14: 45658 | O14: 45689 | R14: S1 Mar-25 | S14: Media Acu
L15: Propuestas emitidas | M15: # | N15: 8 | O15: 10 | R15: 5 | S15: 0.35
M16: MUS$ | N16: 2.2 | O16: 2.6 | R16: 0.57
L17: Propuestas adjudicadas | M17: # | N17: 8 | O17: 7 | R17: 0 | S17: 0.18
F18: Etiquetas de fila | G18: Suma de Monto (USD) | H18: % | M18: kUS$ | N18: 1.1 | O18: 1.3 | R18: 0.4
F19: Las Bambas | G19: 1125000 | H19: =+G19/$G$29 -> 0.41178624
F20: Mosaic | G20: 380000 | H20: =+G20/$G$29 -> 0.13909224
F21: Minsur | G21: 240000 | H21: =+G21/$G$29 -> 0.087847731 | N21: Chile | O21: =0.66/2.4 -> 0.275
F22: Anglo American | G22: 236000 | H22: =+G22/$G$29 -> 0.086383602 | N22: Peru | O22: =1.5/2.4 -> 0.625
F23: First Quantum | G23: 200000 | H23: =+G23/$G$29 -> 0.073206442
F24: OCP | G24: 180000 | H24: =+G24/$G$29 -> 0.065885798
F25: Lundin | G25: 120000 | H25: =+G25/$G$29 -> 0.043923865
F26: BHP | G26: 120000 | H26: =+G26/$G$29 -> 0.043923865
F27: Twin Metals Minnesota | G27: 116000 | H27: =+G27/$G$29 -> 0.042459736
F28: CMP | G28: 15000 | H28: =+G28/$G$29 -> 0.0054904832
F29: Total general | G29: 2732000 | H29: =+G29/$G$29 -> 1
L45: Etiquetas de fila | M45: Suma de Monto (USD)
L46: Consultoría minera | M46: 56000 | N46: =+M46/$M$50 -> 0.020497804
L47: Ing. de minas | M47: 2071000 | N47: =+M47/$M$50 -> 0.75805271
L48: Planificación estratégica | M48: 395000 | N48: =+M48/$M$50 -> 0.14458272
L49: Simulación de sistemas mineros | M49: 210000 | N49: =+M49/$M$50 -> 0.076866764
M50: =+SUM(M46:M49) -> 2732000
L55: Premium | M55: 921000 | N55: =+M55/$M$58 -> 0.33711567
L56: Regular | M56: 380000 | N56: =+M56/$M$58 -> 0.13909224
L57: Target | M57: 1431000 | N57: =+M57/$M$58 -> 0.52379209
M58: =+SUM(M55:M57) -> 2732000

Sheet Posbiles
A1: ID | B1: País | C1: Descripcion Oportunidad | D1: Empresa | E1: Mina | F1: Gestor Comercial | G1: Monto (USD) | H1: Tasa de ajuste | I1: Monto (USD) | L1: Duracion (meses) | M1: USD/mes | N1: Tipo Cliente | O1: Forma de Venta
A2: 1 | B2: Perú | C2: Planificación de largo plazo (LOM) integrada con iniciativas + Potenciales | D2: Minsur | E2: San Rafael | F2: MF | G2: 110000 | H2: 0.8 | I2: =+H2*G2 -> 88000 | L2: 3 | M2: 53333.333 | N2: Premium | O2: Reventa
A3: 2 | B3: Brasil | C3: Evaluación estocástica de escenarios con herramienta SIMPLAN | D3: CBMM | F3: AS | G3: 118000 | H3: 0.8 | I3: =+H3*G3 -> 94400 | L3: 3 | M3: 39333.333 | N3: Target | O3: Busqueda Activa
A4: 3 | B4: Chile | C4: Tunel exploración | D4: BHP | E4: Escondida | F4: PV | G4: 200000 | H4: 0.8 | I4: =+H4*G4 -> 160000 | L4: 3 | M4: 66666.667 | N4: Target | O4: Busqueda Activa
A5: 4 | B5: Chile | C5: Opportunity Assessment para optimizar el proyecto Cerro Colorado (LOM estrategico) | D5: BHP | E5: Cerro Colorado | F5: ER | G5: 240000 | H5: 0.5 | I5: =+H5*G5 -> 120000 | L5: 5 | M5: 48000 | N5: Target | O5: Reventa
A7: Marzo | G7: =+SUM(G2:G5) -> 668000 | H7: Tasa de ajuste | I7: =+SUM(I2:I5) -> 462400
A8: 4 | B8: Chile | C8: Evaluación caso de negocio explotación SLS | D8: CMP | E8: Algarrobo | F8: FR | G8: 170000 | H8: 0.8 | I8: =+H8*G8 -> 136000 | L8: 3 | M8: 56666.667 | N8: Premium | O8: Solicitud Directa
A9: 17 | B9: Chile | C9: Ing Basica MHD UG | D9: Lundin | E9: Candelaria | F9: RM | G9: 1380000 | H9: 0.5 | I9: =+H9*G9 -> 690000 | L9: 5 | M9: 276000 | N9: Premium | O9: Licitación
A10: 66 | B10: Chile | C10: Planificación LOM Blue Sky | D10: Lundin | E10: Caserones | F10: ER | G10: 200000 | H10: 0.5 | I10: =+H10*G10 -> 100000 | L10: 3 | M10: 66666.667 | N10: Target | O10: Reventa
A11: 83 | B11: Chile | C11: Auditoría de las bases de datos geomecánicas y actualización de modelo geomecánico | D11: Lundin | E11: Candelaria | F11: CH | G11: 390000 | H11: 0.8 | I11: =+H11*G11 -> 312000 | L11: 3 | M11: 130000 | N11: Premium
A12: 87 | B12: Chile | C12: Soporte Romeral, construcción túnel exploratorio | D12: CMP | E12: Romeral | F12: FR | G12: 646000 | H12: 0.5 | I12: =+H12*G12 -> 323000 | L12: 18 | M12: 35888.889 | N12: Premium
A13: 39 | B13: Brasil | C13: Ing PFS mina UG | D13: Aura Minerals | E13: Mina Paiol | F13: AS | G13: 288000 | H13: 0.8 | I13: =+H13*G13 -> 230400 | L13: 3 | M13: 96000 | N13: Target | O13: Reventa
A14: 60 | B14: Brasil | C14: Ingenieria para construcción tunel de exploración | D14: Aura Minerals | E14: Mina Paiol | F14: AF | G14: 72000 | H14: 0.8 | I14: =+H14*G14 -> 57600 | L14: 3 | M14: 24000 | N14: Target | O14: Reventa
A15: 112 | B15: Brasil | C15: Acompañamiento LOM y capacitación Simplan para Cajati | D15: Mosaic | E15: Cajati | F15: AS | G15: 84000 | H15: 0.8 | I15: =+H15*G15 -> 67200 | L15: 3 | M15: 28000 | N15: Premium | O15: Reventa
A16: 116 | B16: Brasil | C16: PEA Projecto Furnas | D16: Ero Copper | E16: Furnas | F16: AS | G16: 550000 | H16: 0.5 | I16: =+H16*G16 -> 275000 | L16: 6 | M16: 91666.667 | N16: Target | O16: Busqueda Activa
A17: Abril | G17: =+SUM(G8:G16) -> 3780000 | I17: =+SUM(I8:I16) -> 2191200

Sheet Tabla Budget
C2: Proyección EDP | R2: Proyección Venta
C3: Tipo | D3: 45658 | E3: 45689 | F3: 45717 | G3: 45748 | H3: 45778 | I3: 45809 | J3: 45839 | K3: 45870 | L3: 45901 | M3: 45931 | N3: 45962 | O3: 45992 | P3: Total | R3: Tipo | S3: 45658 | T3: 45689 | U3: 45717 | V3: 45748 | W3: 45778 | X3: 45809 | Y3: 45839 | Z3: 45870 | AA3: 45901 | AB3: 45931 | AC3: 45962 | AD3: 45992 | AE3: Total
C4: Remanente | D4: 753937 | E4: 565714 | F4: 326816 | G4: 326816 | H4: 191513 | I4: 191513 | J4: 161442 | K4: 19435 | L4: 19435 | M4: 19435 | N4: 19435 | O4: 19435 | P4: =+SUM(D4:O4) -> 2614926 | R4: Remanente | S4: 0 | T4: 0 | U4: 0 | V4: 0 | W4: 0 | X4: 0 | Y4: 0 | Z4: 0 | AA4: 0 | AB4: 0 | AC4: 0 | AD4: 0 | AE4: =+SUM(S4:AD4) -> 0
C5: Vendido | E5: =+J21 -> 277666.67 | F5: =+K21 -> 327666.67 | G5: =+L21 -> 252666.67 | H5: =+M21 -> 36000 | I5: =+N21 -> 36000 | J5: =+O21 -> 0 | K5: =+P21 -> 0 | L5: =+Q21 -> 0 | ... O5: =+T21 -> 0 | P5: =+SUM(D5:O5) -> 930000 | R5: Vendido | S5: 930000 | T5: 0 | U5: 0 | V5: 0 | W5: 0 | X5: 0 | Y5: 0 | Z5: 0 | AA5: 0 | AB5: 0 | AC5: 0 | AD5: 0 | AE5: =+SUM(S5:AD5) -> 930000
C6: Proyección | D6: =+J43 -> 0 | E6: =+K43 -> 0 | F6: =+L43 -> 244561.67 | G6: =+M43 -> 460753.33 | H6: =+N43 -> 631753.33 | I6: =+O43 -> 496866.67 | J6: =+P43 -> 427960 | K6: =+Q43 -> 342626.67 | ... O6: =+U43 -> 134875 | P6: =+SUM(D6:O6) -> 3527440 | R6: Proyección | T6: 1008000 | U6: 1590000 | V6: 1406000 | W6: 0 | X6: 0 | Y6: 0 | Z6: 0 | AA6: 0 | AB6: 0 | AC6: 0 | AD6: 0 | AE6: =+SUM(S6:AD6) -> 4004000
