Workbook
Name _Hlk138162579: 'Base de Datos 2024'!#REF!

Sheet Reportabilidad
B2: Recuentos | E2: Recuentos Chile | H2: Recuentos Rusia | L2: Pipeline REDCO 2024 | O2: Venta REDCO (>10%) | R2: Ingresos REDCO 2024 | U2: Ingresos REDCO (>10%) 2024 | X2: Flujo de ingresos | Y2: Venta Total Posible (>10%) | Z2: Ingresos Totales Posibles (>10%) | AA2: Proyección Venta | AB2: Proyección Ingreso | AC2: Target | AF2: Ingresos 2025 | AG2: =+SUMIFS('Base de Datos 2024'!#REF!,'Base de Datos 2024'!#REF!,"Propuesta",'Base de Datos 2024'!E:E,"Adjudicada",'Base de Datos 2024'!#REF!,"=1",'Base de Datos 2024'!#REF!,"2024") -> #REF! | AI2: Tasa Adjudicación | AL2: Venta | AP2: Ingresos | AV2: 45292 | AW2: 45323 | AX2: 45352 | AY2: 45383 | AZ2: 45413 | BA2: 45444 | BB2: 45474 | BC2: 45505 | BD2: 45536 | BE2: 45566 | BF2: 45597 | BG2: 45627
B3: N° Iniciativas | C3: =COUNTIFS('Base de Datos 2024'!#REF!,"Iniciativa",'Base de Datos 2024'!#REF!,"2024",'Base de Datos 2024'!#REF!,">0,1") -> #REF! | E3: N° Iniciativas | F3: =+COUNTIFS('Base de Datos 2024'!#REF!,"Iniciativa",'Base de Datos 2024'!F:F,"Chile",'Base de Datos 2024'!#REF!,"2024") -> #REF! | H3: N° Iniciativas | I3: =+COUNTIFS('Base de Datos 2024'!#REF!,"Iniciativa",'Base de Datos 2024'!F:F,"Rusia",'Base de Datos 2024'!#REF!,"2024") -> #REF! | L3: Iniciativas | M3: =+SUMIFS('Base de Datos 2024'!K:K,'Base de Datos 2024'!#REF!,"Iniciativa",'Base de Datos 2024'!#REF!,"2024",'Base de Datos 2024'!#REF!,">0,01")/1000000 -> #REF! | O3: Iniciativas | P3: =+SUMIFS('Base de Datos 2024'!K:K,'Base de Datos 2024'!#REF!,"Iniciativa",'Base de Datos 2024'!#REF!,">0,1",'Base de Datos 2024'!#REF!,"2024")/1000000 -> #REF! | R3: Iniciativas | S3: =+SUMIFS('Base de Datos 2024'!#REF!,'Base de Datos 2024'!#REF!,"Iniciativa",'Base de Datos 2024'!#REF!,"2024")/1000000 -> #REF! | U3: Total | V3: =+SUMIFS('Base de Datos 2024'!#REF!,'Base de Datos 2024'!#REF!,"Propuesta",'Base de Datos 2024'!#REF!,">0,1",'Base de Datos 2024'!#REF!,"2024")/1000000 -> #REF! | X3: Iniciativas | Y3: =+P3 -> #REF! | Z3: =+V8 -> #REF! | AA3: =+Y3*$AJ$4 -> #REF! | AB3: =+Z3*$AJ$4 -> #REF! | AU3: Adjudicada | AV3: =+SUMIFS('Base de Datos 2024'!#REF!,'Base de Datos 2024'!#REF!,"Propuesta",'Base de Datos 2024'!$E:$E,"Adjudicada",'Base de Datos 2024'!#REF!,"2024") -> #REF! | AW3: =+SUMIFS('Base de Datos 2024'!#REF!,'Base de Datos 2024'!#REF!,"Propuesta",'Base de Datos 2024'!$E:$E,"Adjudicada",'Base de Datos 2024'!#REF!,"2024") -> #REF! | AX3: =+SUMIFS('Base de Datos 2024'!#REF!,'Base de Datos 2024'!#REF!,"Propuesta",'Base de Datos 2024'!$E:$E,"Adjudicada",'Base de Datos 2024'!#REF!,"2024") -> #REF! | AY3: =+SUMIFS('Base de Datos 2024'!#REF!,'Base de Datos 2024'!#REF!,"Propuesta",'Base de Datos 2024'!$E:$E,"Adjudicada",'Base de Datos 2024'!#REF!,"2024") -> #REF! | AZ3: =+SUMIFS('Base de Datos 2024'!#REF!,'Base de Datos 2024'!#REF!,"Propuesta",'Base de Datos 2024'!$E:$E,"Adjudicada",'Base de Datos 2024'!#REF!,"2024") -> #REF! | BA3: =+SUMIFS('Base de Datos 2024'!#REF!,'Base de Datos 2024'!#REF!,"Propuesta",'Base de Datos 2024'!$E:$E,"Adjudicada",'Base de Datos 2024'!#REF!,"2024") -> #REF! | BB3: =+SUMIFS('Base de Datos 2024'!#REF!,'Base de Datos 2024'!#REF!,"Propuesta",'Base de Datos 2024'!$E:$E,"Adjudicada",'Base de Datos 2024'!#REF!,"2024") -> #REF! | BC3: =+SUMIFS('Base de Datos 2024'!#REF!,'Base de Datos 2024'!#REF!,"Propuesta",'Base de Datos 2024'!$E:$E,"Adjudicada",'Base de Datos 2024'!#REF!,"2024") -> #REF! | ... BG3: =+SUMIFS('Base de Datos 2024'!#REF!,'Base de Datos 2024'!#REF!,"Propuesta",'Base de Datos 2024'!$E:$E,"Adjudicada",'Base de Datos 2024'!#REF!,"2024") -> #REF!
B4: N° Propuestas | C4: =+COUNTIFS('Base de Datos 2024'!#REF!,"Propuesta",'Base de Datos 2024'!#REF!,"2024",'Base de Datos 2024'!#REF!,">0,1")-C8 -> #REF! | E4: N° Propuestas | F4: =+COUNTIFS('Base de Datos 2024'!#REF!,"Propuesta",'Base de Datos 2024'!F:F,"Chile",'Base de Datos 2024'!#REF!,"2024") -> #REF! | H4: N° Propuestas | I4: =+COUNTIFS('Base de Datos 2024'!#REF!,"Propuesta",'Base de Datos 2024'!F:F,"Rusia",'Base de Datos 2024'!#REF!,"2024") -> #REF! | L4: Propuestas | M4: =+(SUMIFS('Base de Datos 2024'!K:K,'Base de Datos 2024'!#REF!,"Propuesta",'Base de Datos 2024'!#REF!,"2024"))/1000000-(M8+M9) -> #REF! | O4: Propuestas | P4: =+SUMIFS('Base de Datos 2024'!K:K,'Base de Datos 2024'!#REF!,"Propuesta",'Base de Datos 2024'!#REF!,">0,1",'Base de Datos 2024'!#REF!,"2024")/1000000-P10 -> #REF! | R4: Propuestas | S4: =+SUMIFS('Base de Datos 2024'!#REF!,'Base de Datos 2024'!#REF!,"Propuesta",'Base de Datos 2024'!#REF!,"2024")/1000000-S10 -> #REF! | U4: En Construcción | V4: =+SUMIFS('Base de Datos 2024'!#REF!,'Base de Datos 2024'!#REF!,"Propuesta",'Base de Datos 2024'!E:E,"En Construcción",'Base de Datos 2024'!#REF!,">0,1",'Base de Datos 2024'!#REF!,"2024")/1000000 -> #REF! | X4: Propuestas | Y4: =+P4 -> #REF! | Z4: =+V3 -> #REF! | AA4: =+(P7+P8)*$AJ$4+P9 -> #REF! | AB4: =(V4+V5)*$AJ$4+V6 -> #REF! | AI4: Tasa de Efectividad | AJ4: =+AJ5/(AJ6+AJ5) -> #REF! | AL4: Adjudicado | AM4: =+M8 -> #REF! | AN4: =+AM4/AM6 -> #REF! | AP4: Adjudicado | AQ4: =+V6 -> #REF! | AR4: =+AQ4/AQ6 -> #REF! | AU4: Por Adjudicar | AV4: =+SUMIFS('Base de Datos 2024'!#REF!,'Base de Datos 2024'!#REF!,">0,1",'Base de Datos 2024'!#REF!,"2024",'Base de Datos 2024'!$E:$E,"Hallazgo Inicial",'Base de Datos 2024'!$E:$E,"En Construccion (Word)",'Base de Datos 2024'!$E:$E,"En Construccion (PPT+Excel)") -> #REF! | AW4: =+SUMIFS('Base de Datos 2024'!#REF!,'Base de Datos 2024'!#REF!,">0,1",'Base de Datos 2024'!#REF!,"2024",'Base de Datos 2024'!$E:$E,"Hallazgo Inicial",'Base de Datos 2024'!$E:$E,"En Construccion (Word)",'Base de Datos 2024'!$E:$E,"En Construccion (PPT+Excel)") -> #REF! | AX4: =+SUMIFS('Base de Datos 2024'!#REF!,'Base de Datos 2024'!#REF!,">0,1",'Base de Datos 2024'!#REF!,"2024",'Base de Datos 2024'!$E:$E,"Hallazgo Inicial",'Base de Datos 2024'!$E:$E,"En Construccion (Word)",'Base de Datos 2024'!$E:$E,"En Construccion (PPT+Excel)") -> #REF! | AY4: =+SUMIFS('Base de Datos 2024'!#REF!,'Base de Datos 2024'!#REF!,">0,1",'Base de Datos 2024'!#REF!,"2024",'Base de Datos 2024'!$E:$E,"Hallazgo Inicial",'Base de Datos 2024'!$E:$E,"En Construccion (Word)",'Base de Datos 2024'!$E:$E,"En Construccion (PPT+Excel)") -> #REF! | AZ4: =+SUMIFS('Base de Datos 2024'!#REF!,'Base de Datos 2024'!#REF!,">0,1",'Base de Datos 2024'!#REF!,"2024",'Base de Datos 2024'!$E:$E,"Hallazgo Inicial",'Base de Datos 2024'!$E:$E,"En Construccion (Word)",'Base de Datos 2024'!$E:$E,"En Construccion (PPT+Excel)") -> #REF! | BA4: =+SUMIFS('Base de Datos 2024'!#REF!,'Base de Datos 2024'!#REF!,">0,1",'Base de Datos 2024'!#REF!,"2024",'Base de Datos 2024'!$E:$E,"Hallazgo Inicial",'Base de Datos 2024'!$E:$E,"En Construccion (Word)",'Base de Datos 2024'!$E:$E,"En Construccion (PPT+Excel)") -> #REF! | BB4: =+SUMIFS('Base de Datos 2024'!#REF!,'Base de Datos 2024'!#REF!,">0,1",'Base de Datos 2024'!#REF!,"2024",'Base de Datos 2024'!$E:$E,"Hallazgo Inicial",'Base de Datos 2024'!$E:$E,"En Construccion (Word)",'Base de Datos 2024'!$E:$E,"En Construccion (PPT+Excel)") -> #REF! | BC4: =+SUMIFS('Base de Datos 2024'!#REF!,'Base de Datos 2024'!#REF!,">0,1",'Base de Datos 2024'!#REF!,"2024",'Base de Datos 2024'!$E:$E,"Hallazgo Inicial",'Base de Datos 2024'!$E:$E,"En Construccion (Word)",'Base de Datos 2024'!$E:$E,"En Construccion (PPT+Excel)") -> #REF! | ... BG4: =+SUMIFS('Base de Datos 2024'!#REF!,'Base de Datos 2024'!#REF!,">0,1",'Base de Datos 2024'!#REF!,"2024",'Base de Datos 2024'!$E:$E,"Hallazgo Inicial",'Base de Datos 2024'!$E:$E,"En Construccion (Word)",'Base de Datos 2024'!$E:$E,"En Construccion (PPT+Excel)") -> #REF!
B5: Total | C5: =+C4+C3 -> #REF! | E5: N° En Construcción | F5: =+COUNTIFS('Base de Datos 2024'!E:E,"En Construcción",'Base de Datos 2024'!#REF!,"Propuesta",'Base de Datos 2024'!F:F,"Chile",'Base de Datos 2024'!#REF!,"2024") -> #REF! | H5: N° En Construcción | I5: =+COUNTIFS('Base de Datos 2024'!E:E,"En Construcción",'Base de Datos 2024'!#REF!,"Propuesta",'Base de Datos 2024'!F:F,"Rusia",'Base de Datos 2024'!#REF!,"2024") -> #REF! | L5: Total | M5: =+M4+M3 -> #REF! | O5: Total | P5: =+P4+P3 -> #REF! | R5: Total | S5: =+S4+S3 -> #REF! | U5: Enviada / Seguimiento | V5: =+SUMIFS('Base de Datos 2024'!#REF!,'Base de Datos 2024'!#REF!,"Propuesta",'Base de Datos 2024'!E:E,"Enviada / Seguimiento",'Base de Datos 2024'!#REF!,">0,1",'Base de Datos 2024'!#REF!,"2024")/1000000 -> #REF! | X5: Total | Y5: =+P5 -> #REF! | Z5: =+V9 -> #REF! | AA5: =+AA4+AA3 -> #REF! | AB5: =+AB4+AB3 -> #REF! | AF5: =+AG2 -> #REF! | AI5: Propuestas Adjudicadas | AJ5: =+C8 -> #REF! | AL5: Por adjudicar | AM5: =+SUMIFS('Base de Datos 2024'!K:K,'Base de Datos 2024'!#REF!,">0,5",'Base de Datos 2024'!#REF!,"2024")/1000000 -> #REF! | AN5: =+AM5/AM6 -> #REF! | AP5: Por adjudicar | AQ5: =+SUMIFS('Base de Datos 2024'!#REF!,'Base de Datos 2024'!#REF!,">0,5",'Base de Datos 2024'!#REF!,"2024")/1000000 -> #REF! | AR5: =+AQ5/AQ6 -> #REF! | AU5: Total | AV5: =+AV4+AV3 -> #REF! | AW5: =+AW4+AW3 -> #REF! | AX5: =+AX4+AX3 -> #REF! | AY5: =+AY4+AY3 -> #REF! | AZ5: =+AZ4+AZ3 -> #REF! | BA5: =+BA4+BA3 -> #REF! | BB5: =+BB4+BB3 -> #REF! | BC5: =+BC4+BC3 -> #REF! | ... BG5: =+BG4+BG3 -> #REF!
B6: N° En Construcción | C6: =+COUNTIFS('Base de Datos 2024'!E:E,"En Construcción",'Base de Datos 2024'!#REF!,"Propuesta",'Base de Datos 2024'!#REF!,"2024",'Base de Datos 2024'!#REF!,">0,1") -> #REF! | L6: En Construcción | M6: =+SUMIFS('Base de Datos 2024'!K:K,'Base de Datos 2024'!#REF!,"Propuesta",'Base de Datos 2024'!E:E,"En Construcción",'Base de Datos 2024'!#REF!,"2024")/1000000 -> #REF! | O6: % del Target | P6: =+P5/15 -> #REF! | U6: Adjudicada | V6: =+SUMIFS('Base de Datos 2024'!#REF!,'Base de Datos 2024'!#REF!,"Propuesta",'Base de Datos 2024'!E:E,"Adjudicada",'Base de Datos 2024'!#REF!,">0,1",'Base de Datos 2024'!#REF!,"2024")/1000000 -> #REF! | AI6: Propuetas No Adjudicadas | AJ6: =+C9 -> #REF! | AL6: Meta | AM6: =15000000/1000000 -> 15 | AP6: Meta | AQ6: 10
B7: N° Enviada / Seguimiento | C7: =+COUNTIFS('Base de Datos 2024'!E:E,"Enviada / Seguimiento",'Base de Datos 2024'!#REF!,"Propuesta",'Base de Datos 2024'!#REF!,"2024",'Base de Datos 2024'!#REF!,">0,1") -> #REF! | E7: N° Enviada / Seguimiento | F7: =+COUNTIFS('Base de Datos 2024'!E:E,"Enviada / Seguimiento",'Base de Datos 2024'!#REF!,"Propuesta",'Base de Datos 2024'!F:F,"Chile",'Base de Datos 2024'!#REF!,"2024") -> #REF! | H7: N° Enviada / Seguimiento | I7: =+COUNTIFS('Base de Datos 2024'!E:E,"Enviada / Seguimiento",'Base de Datos 2024'!#REF!,"Propuesta",'Base de Datos 2024'!F:F,"Rusia",'Base de Datos 2024'!#REF!,"2024") -> #REF! | L7: Enviada / Seguimiento | M7: =+SUMIFS('Base de Datos 2024'!K:K,'Base de Datos 2024'!#REF!,"Propuesta",'Base de Datos 2024'!E:E,"Enviada / Seguimiento",'Base de Datos 2024'!#REF!,"2024")/1000000 -> #REF! | O7: En Construcción | P7: =+SUMIFS('Base de Datos 2024'!K:K,'Base de Datos 2024'!#REF!,"Propuesta",'Base de Datos 2024'!E:E,"En Construcción",'Base de Datos 2024'!#REF!,">0,1",'Base de Datos 2024'!#REF!,"2024")/1000000 -> #REF! | R7: En Construcción | S7: =+SUMIFS('Base de Datos 2024'!#REF!,'Base de Datos 2024'!#REF!,"Propuesta",'Base de Datos 2024'!E:E,"En Construcción",'Base de Datos 2024'!#REF!,"2024")/1000000 -> #REF!
B8: N° Adjudicada | C8: =+COUNTIFS('Base de Datos 2024'!E:E,"Adjudicada",'Base de Datos 2024'!#REF!,"Propuesta",'Base de Datos 2024'!#REF!,"2024",'Base de Datos 2024'!#REF!,">0,1") -> #REF! | E8: N° Adjudicada | F8: =+COUNTIFS('Base de Datos 2024'!E:E,"Adjudicada",'Base de Datos 2024'!#REF!,"Propuesta",'Base de Datos 2024'!F:F,"Chile",'Base de Datos 2024'!#REF!,"2024") -> #REF! | H8: N° Adjudicada | I8: =+COUNTIFS('Base de Datos 2024'!E:E,"Adjudicada",'Base de Datos 2024'!#REF!,"Propuesta",'Base de Datos 2024'!F:F,"Rusia",'Base de Datos 2024'!#REF!,"2024") -> #REF! | L8: Adjudicada | M8: =+SUMIFS('Base de Datos 2024'!K:K,'Base de Datos 2024'!#REF!,"Propuesta",'Base de Datos 2024'!E:E,"Adjudicada",'Base de Datos 2024'!#REF!,"2024")/1000000 -> #REF! | O8: Enviada / Seguimiento | P8: =+SUMIFS('Base de Datos 2024'!K:K,'Base de Datos 2024'!#REF!,"Propuesta",'Base de Datos 2024'!E:E,"Enviada / Seguimiento",'Base de Datos 2024'!#REF!,">0,1",'Base de Datos 2024'!#REF!,"2024")/1000000 -> #REF! | R8: Enviada / Seguimiento | S8: =+SUMIFS('Base de Datos 2024'!#REF!,'Base de Datos 2024'!#REF!,"Propuesta",'Base de Datos 2024'!E:E,"Enviada / Seguimiento",'Base de Datos 2024'!#REF!,"2024")/1000000 -> #REF! | U8: Iniciativas | V8: =+SUMIFS('Base de Datos 2024'!#REF!,'Base de Datos 2024'!#REF!,"Iniciativa",'Base de Datos 2024'!#REF!,">0,1",'Base de Datos 2024'!#REF!,"2024")/1000000 -> #REF!
B9: N° No Adjudicada | C9: =+COUNTIFS('Base de Datos 2024'!E:E,"No Adjudicada",'Base de Datos 2024'!#REF!,"Propuesta",'Base de Datos 2024'!#REF!,"2024") -> #REF! | E9: N° No Adjudicada | F9: =+COUNTIFS('Base de Datos 2024'!E:E,"No Adjudicada",'Base de Datos 2024'!#REF!,"Propuesta",'Base de Datos 2024'!F:F,"Chile",'Base de Datos 2024'!#REF!,"2024") -> #REF! | H9: N° No Adjudicada | I9: =+COUNTIFS('Base de Datos 2024'!E:E,"No Adjudicada",'Base de Datos 2024'!#REF!,"Propuesta",'Base de Datos 2024'!F:F,"Rusia",'Base de Datos 2024'!#REF!,"2024") -> #REF! | L9: No Adjudicada | M9: =+SUMIFS('Base de Datos 2024'!K:K,'Base de Datos 2024'!#REF!,"Propuesta",'Base de Datos 2024'!E:E,"No Adjudicada",'Base de Datos 2024'!#REF!,"2024")/1000000 -> #REF! | O9: Adjudicada | P9: =+SUMIFS('Base de Datos 2024'!K:K,'Base de Datos 2024'!#REF!,"Propuesta",'Base de Datos 2024'!E:E,"Adjudicada",'Base de Datos 2024'!#REF!,">0,1",'Base de Datos 2024'!#REF!,"2024")/1000000 -> #REF! | R9: Adjudicada | S9: =+SUMIFS('Base de Datos 2024'!#REF!,'Base de Datos 2024'!#REF!,"Propuesta",'Base de Datos 2024'!E:E,"Adjudicada",'Base de Datos 2024'!#REF!,"2024")/1000000 -> #REF! | U9: Total | V9: =+V3 -> #REF!
C10: =+C4-(SUM(C6:C9)) -> #REF! | F10: =+F4-(SUM(F5:F9)) -> #REF! | I10: =+I4-(SUM(I5:I9)) -> #REF! | O10: No Adjudicada | P10: =+SUMIFS('Base de Datos 2024'!K:K,'Base de Datos 2024'!#REF!,"Propuesta",'Base de Datos 2024'!E:E,"No Adjudicada",'Base de Datos 2024'!#REF!,">0,1",'Base de Datos 2024'!#REF!,"2024")/1000000 -> #REF! | R10: No Adjudicada | S10: =+SUMIFS('Base de Datos 2024'!#REF!,'Base de Datos 2024'!#REF!,"Propuesta",'Base de Datos 2024'!E:E,"No Adjudicada",'Base de Datos 2024'!#REF!,"2024")/1000000 -> #REF! | U10: No Adjudicada | V10: =+SUMIFS('Base de Datos 2024'!#REF!,'Base de Datos 2024'!#REF!,"Propuesta",'Base de Datos 2024'!E:E,"No Adjudicada",'Base de Datos 2024'!#REF!,">0,1",'Base de Datos 2024'!#REF!,"2024")/1000000 -> #REF!
B11: Recuentos Perú | E11: Recuentos EEUU | H11: Recuentos Brasil
B12: N° Iniciativas | C12: =+COUNTIFS('Base de Datos 2024'!#REF!,"Iniciativa",'Base de Datos 2024'!F:F,"Perú",'Base de Datos 2024'!#REF!,"2024") -> #REF! | E12: N° Iniciativas | F12: =+COUNTIFS('Base de Datos 2024'!#REF!,"Iniciativa",'Base de Datos 2024'!F:F,"EEUU",'Base de Datos 2024'!#REF!,"2024") -> #REF! | H12: N° Iniciativas | I12: =+COUNTIFS('Base de Datos 2024'!#REF!,"Iniciativa",'Base de Datos 2024'!F:F,"Brasil",'Base de Datos 2024'!#REF!,"2024") -> #REF! | N12: Venta REDCO (>10%) por País | R12: Ingresos REDCO (>10%) por País 2024
B13: N° Propuestas | C13: =+COUNTIFS('Base de Datos 2024'!#REF!,"Propuesta",'Base de Datos 2024'!F:F,"Perú",'Base de Datos 2024'!#REF!,"2024") -> #REF! | E13: N° Propuestas | F13: =+COUNTIFS('Base de Datos 2024'!#REF!,"Propuesta",'Base de Datos 2024'!F:F,"EEUU",'Base de Datos 2024'!#REF!,"2024") -> #REF! | H13: N° Propuestas | I13: =+COUNTIFS('Base de Datos 2024'!#REF!,"Propuesta",'Base de Datos 2024'!F:F,"Brasil",'Base de Datos 2024'!#REF!,"2024") -> #REF! | N13: Chile | O13: Iniciativas | P13: =+SUMIFS('Base de Datos 2024'!K:K,'Base de Datos 2024'!#REF!,"Iniciativa",'Base de Datos 2024'!#REF!,">0,1",'Base de Datos 2024'!F:F,"Chile",'Base de Datos 2024'!#REF!,"2024")/1000000 -> #REF! | R13: Chile | S13: Iniciativas | T13: =+SUMIFS('Base de Datos 2024'!#REF!,'Base de Datos 2024'!#REF!,"Iniciativa",'Base de Datos 2024'!#REF!,">0,1",'Base de Datos 2024'!F:F,"Chile",'Base de Datos 2024'!#REF!,"2024")/1000000 -> #REF!
B14: N° En Construcción | C14: =+COUNTIFS('Base de Datos 2024'!E:E,"En Construcción",'Base de Datos 2024'!#REF!,"Propuesta",'Base de Datos 2024'!F:F,"Perú",'Base de Datos 2024'!#REF!,"2024") -> #REF! | E14: N° En Construcción | F14: =+COUNTIFS('Base de Datos 2024'!E:E,"En Construcción",'Base de Datos 2024'!#REF!,"Propuesta",'Base de Datos 2024'!F:F,"EEUU",'Base de Datos 2024'!#REF!,"2024") -> #REF! | H14: N° En Construcción | I14: =+COUNTIFS('Base de Datos 2024'!E:E,"En Construcción",'Base de Datos 2024'!#REF!,"Propuesta",'Base de Datos 2024'!F:F,"Brasil",'Base de Datos 2024'!#REF!,"2024") -> #REF! | O14: Propuestas | P14: =+SUMIFS('Base de Datos 2024'!K:K,'Base de Datos 2024'!#REF!,"Propuesta",'Base de Datos 2024'!#REF!,">0,1",'Base de Datos 2024'!F:F,"Chile",'Base de Datos 2024'!#REF!,"2024")/1000000 -> #REF! | S14: Propuestas | T14: =+SUMIFS('Base de Datos 2024'!#REF!,'Base de Datos 2024'!#REF!,"Propuesta",'Base de Datos 2024'!#REF!,">0,1",'Base de Datos 2024'!F:F,"Chile",'Base de Datos 2024'!#REF!,"2024")/1000000 -> #REF!
N15: EEUU | O15: Iniciativas | P15: =+SUMIFS('Base de Datos 2024'!K:K,'Base de Datos 2024'!#REF!,"Iniciativa",'Base de Datos 2024'!#REF!,">0,1",'Base de Datos 2024'!F:F,"EEUU",'Base de Datos 2024'!#REF!,"2024")/1000000 -> #REF! | R15: EEUU | S15: Iniciativas | T15: =+SUMIFS('Base de Datos 2024'!#REF!,'Base de Datos 2024'!#REF!,"Iniciativa",'Base de Datos 2024'!#REF!,">0,1",'Base de Datos 2024'!F:F,"EEUU",'Base de Datos 2024'!#REF!,"2024")/1000000 -> #REF!
B16: N° Enviada / Seguimiento | C16: =+COUNTIFS('Base de Datos 2024'!E:E,"Enviada / Seguimiento",'Base de Datos 2024'!#REF!,"Propuesta",'Base de Datos 2024'!F:F,"Perú",'Base de Datos 2024'!#REF!,"2024") -> #REF! | E16: N° Enviada / Seguimiento | F16: =+COUNTIFS('Base de Datos 2024'!E:E,"Enviada / Seguimiento",'Base de Datos 2024'!#REF!,"Propuesta",'Base de Datos 2024'!F:F,"EEUU",'Base de Datos 2024'!#REF!,"2024") -> #REF! | H16: N° Enviada / Seguimiento | I16: =+COUNTIFS('Base de Datos 2024'!E:E,"Enviada / Seguimiento",'Base de Datos 2024'!#REF!,"Propuesta",'Base de Datos 2024'!F:F,"Brasil",'Base de Datos 2024'!#REF!,"2024") -> #REF! | O16: Propuestas | P16: =+SUMIFS('Base de Datos 2024'!K:K,'Base de Datos 2024'!#REF!,"Propuesta",'Base de Datos 2024'!#REF!,">0,1",'Base de Datos 2024'!F:F,"EEUU",'Base de Datos 2024'!#REF!,"2024")/1000000 -> #REF! | S16: Propuestas | T16: =+SUMIFS('Base de Datos 2024'!#REF!,'Base de Datos 2024'!#REF!,"Propuesta",'Base de Datos 2024'!#REF!,">0,1",'Base de Datos 2024'!F:F,"EEUU",'Base de Datos 2024'!#REF!,"2024")/1000000 -> #REF!
B17: N° Adjudicada | C17: =+COUNTIFS('Base de Datos 2024'!E:E,"Adjudicada",'Base de Datos 2024'!#REF!,"Propuesta",'Base de Datos 2024'!F:F,"Perú",'Base de Datos 2024'!#REF!,"2024") -> #REF! | E17: N° Adjudicada | F17: =+COUNTIFS('Base de Datos 2024'!E:E,"Adjudicada",'Base de Datos 2024'!#REF!,"Propuesta",'Base de Datos 2024'!F:F,"EEUU",'Base de Datos 2024'!#REF!,"2024") -> #REF! | H17: N° Adjudicada | I17: =+COUNTIFS('Base de Datos 2024'!E:E,"Adjudicada",'Base de Datos 2024'!#REF!,"Propuesta",'Base de Datos 2024'!F:F,"Brasil",'Base de Datos 2024'!#REF!,"2024") -> #REF! | N17: Brasil | O17: Iniciativas | P17: =+SUMIFS('Base de Datos 2024'!K:K,'Base de Datos 2024'!#REF!,"Iniciativa",'Base de Datos 2024'!#REF!,">0,1",'Base de Datos 2024'!F:F,"Brasil",'Base de Datos 2024'!#REF!,"2024")/1000000 -> #REF! | R17: Brasil | S17: Iniciativas | T17: =+SUMIFS('Base de Datos 2024'!#REF!,'Base de Datos 2024'!#REF!,"Iniciativa",'Base de Datos 2024'!#REF!,">0,1",'Base de Datos 2024'!F:F,"Brasil",'Base de Datos 2024'!#REF!,"2024")/1000000 -> #REF!
B18: N° No Adjudicada | C18: =+COUNTIFS('Base de Datos 2024'!E:E,"No Adjudicada",'Base de Datos 2024'!#REF!,"Propuesta",'Base de Datos 2024'!F:F,"Perú",'Base de Datos 2024'!#REF!,"2024") -> #REF! | E18: N° No Adjudicada | F18: =+COUNTIFS('Base de Datos 2024'!E:E,"No Adjudicada",'Base de Datos 2024'!#REF!,"Propuesta",'Base de Datos 2024'!F:F,"EEUU",'Base de Datos 2024'!#REF!,"2024") -> #REF! | H18: N° No Adjudicada | I18: =+COUNTIFS('Base de Datos 2024'!E:E,"No Adjudicada",'Base de Datos 2024'!#REF!,"Propuesta",'Base de Datos 2024'!F:F,"Brasil",'Base de Datos 2024'!#REF!,"2024") -> #REF! | O18: Propuestas | P18: =+SUMIFS('Base de Datos 2024'!K:K,'Base de Datos 2024'!#REF!,"Propuesta",'Base de Datos 2024'!#REF!,">0,1",'Base de Datos 2024'!F:F,"Brasil",'Base de Datos 2024'!#REF!,"2024")/1000000 -> #REF! | S18: Propuestas | T18: =+SUMIFS('Base de Datos 2024'!#REF!,'Base de Datos 2024'!#REF!,"Propuesta",'Base de Datos 2024'!#REF!,">0,1",'Base de Datos 2024'!F:F,"Brasil",'Base de Datos 2024'!#REF!,"2024")/1000000 -> #REF!
C19: =+C13-(SUM(C14:C18)) -> #REF! | F19: =+F13-(SUM(F14:F18)) -> #REF! | I19: =+I13-(SUM(I14:I18)) -> #REF! | N19: Perú | O19: Iniciativas | P19: =+SUMIFS('Base de Datos 2024'!K:K,'Base de Datos 2024'!#REF!,"Iniciativa",'Base de Datos 2024'!#REF!,">0,1",'Base de Datos 2024'!F:F,"Perú",'Base de Datos 2024'!#REF!,"2024")/1000000 -> #REF! | R19: Perú | S19: Iniciativas | T19: =+SUMIFS('Base de Datos 2024'!#REF!,'Base de Datos 2024'!#REF!,"Iniciativa",'Base de Datos 2024'!#REF!,">0,1",'Base de Datos 2024'!F:F,"Perú",'Base de Datos 2024'!#REF!,"2024")/1000000 -> #REF!
B20: Validación | O20: Propuestas | P20: =+SUMIFS('Base de Datos 2024'!K:K,'Base de Datos 2024'!#REF!,"Propuesta",'Base de Datos 2024'!#REF!,">0,1",'Base de Datos 2024'!F:F,"Perú",'Base de Datos 2024'!#REF!,"2024")/1000000 -> #REF! | S20: Propuestas | T20: =+SUMIFS('Base de Datos 2024'!#REF!,'Base de Datos 2024'!#REF!,"Propuesta",'Base de Datos 2024'!#REF!,">0,1",'Base de Datos 2024'!F:F,"Perú",'Base de Datos 2024'!#REF!,"2024")/1000000 -> #REF!
B21: N° Iniciativas | C21: =+C3-(F3+I3+I12+F12+C12) -> #REF! | N21: Rusia | O21: Iniciativas | P21: =+SUMIFS('Base de Datos 2024'!K:K,'Base de Datos 2024'!#REF!,"Iniciativa",'Base de Datos 2024'!#REF!,">0,1",'Base de Datos 2024'!F:F,"Rusia",'Base de Datos 2024'!#REF!,"2024")/1000000 -> #REF! | R21: Rusia | S21: Iniciativas | T21: =+SUMIFS('Base de Datos 2024'!#REF!,'Base de Datos 2024'!#REF!,"Iniciativa",'Base de Datos 2024'!#REF!,">0,1",'Base de Datos 2024'!F:F,"Rusia",'Base de Datos 2024'!#REF!,"2024")/1000000 -> #REF!
B22: N° Propuestas | C22: =+C4-(F4+I4+I13+F13+C13) -> #REF! | O22: Propuestas | P22: =+SUMIFS('Base de Datos 2024'!K:K,'Base de Datos 2024'!#REF!,"Propuesta",'Base de Datos 2024'!#REF!,">0,1",'Base de Datos 2024'!F:F,"Rusia",'Base de Datos 2024'!#REF!,"2024")/1000000 -> #REF! | S22: Propuestas | T22: =+SUMIFS('Base de Datos 2024'!#REF!,'Base de Datos 2024'!#REF!,"Propuesta",'Base de Datos 2024'!#REF!,">0,1",'Base de Datos 2024'!F:F,"Rusia",'Base de Datos 2024'!#REF!,"2024")/1000000 -> #REF!
B23: N° En Construcción | C23: =+C6-(F5+I5+I14+F14+C14) -> #REF! | N23: Total | O23: Iniciativas | P23: =+P21+P19+P17+P15+P13 -> #REF! | R23: Total | S23: Iniciativas | T23: =+T21+T19+T17+T15+T13 -> #REF!
B24: N° Enviada / Seguimiento | C24: =+C7-(F7+I7+I16+F16+C16) -> #REF! | O24: Propuestas | P24: =+P22+P20+P18+P16+P14 -> #REF! | S24: Propuestas | T24: =+T22+T20+T18+T16+T14 -> #REF!
B25: N° Adjudicada | C25: =+C8-(F8+I8+I17+F17+C17) -> #REF! | N25: Total | P25: =+P24+P23 -> #REF! | R25: Total | T25: =+T24+T23 -> #REF!
B26: N° No Adjudicada | C26: =+C9-(F9+I9+I18+F18+C18) -> #REF!
N27: Venta REDCO (>10%) por País | R27: Ingresos por País
N28: Chile | O28: =+P13+P14 -> #REF! | R28: Chile | S28: =+T14 -> #REF!
N29: EEUU | O29: =+P15+P16 -> #REF! | R29: EEUU | S29: =+T16 -> #REF!
N30: Brasil | O30: =+P17+P18 -> #REF! | R30: Brasil | S30: =+T18 -> #REF!
N31: Perú | O31: =+P19+P20 -> #REF! | R31: Perú | S31: =+T20 -> #REF!
N32: Rusia | O32: =+P21+P22 -> #REF! | R32: Rusia | S32: =+T22 -> #REF!
R33: Total | S33: =+SUM(S28:S32) -> #REF!

Sheet Resumen Gen N°
A3: Cuenta de Descripcion Oportunidad | B3: Etiquetas de columna | I3: País | J3: Adjudicadas | K3: Seguimiento | L3: =+E4 -> No Adjudicada | M3: =+G4 -> Total general | N3: Tasa Adjudicación [%por cantidad] | O3: Propuestas Construidas [%] | R3: País | S3: Total Construidas | T3: Adjudicadas | U3: Seguimiento | V3: No adjudicas | X3: Tasa Adjudicación [%] | Y3: Propuestas Construidas [%]
A4: Etiquetas de fila | B4: Adjudicada | C4: En Construcción | D4: Enviada / Seguimiento | E4: No Adjudicada | F4: (en blanco) | G4: Total general | I4: =+A5 -> Brasil | J4: =+B5 -> 9 | K4: 2 | L4: =+E5 -> 1 | M4: =+G5 -> 12 | N4: =+J4/M4 -> 0.75 | O4: =+M4/$M$9 -> 0.081632653 | R4: =+I4 -> Brasil | S4: =+M4 -> 12 | T4: =+J4 -> 9 | U4: =+K4 -> 2 | V4: =+L4 -> 1 | X4: =+T4/(V4+T4) -> 0.9 | Y4: =+S4/$S$8 -> 0.095238095
A5: Brasil | B5: 9 | D5: 2 | E5: 1 | G5: 12 | I5: =+A6 -> Chile | J5: =+B6 -> 32 | K5: 8 | L5: =+E6 -> 20 | M5: =+G6 -> 60 | N5: =+J5/M5 -> 0.53333333 | O5: =+M5/$M$9 -> 0.40816327 | R5: =+I5 -> Chile | S5: =+M5 -> 60 | T5: =+J5 -> 32 | U5: =+K5 -> 8 | V5: =+L5 -> 20 | X5: =+T5/(V5+T5) -> 0.61538462 | Y5: =+S5/$S$8 -> 0.47619048
A6: Chile | B6: 32 | C6: 2 | D6: 6 | E6: 20 | G6: 60 | I6: =+A7 -> EEUU | J6: =+B7 -> 6 | K6: 2 | L6: =+E7 -> 11 | M6: =+G7 -> 19 | N6: =+J6/M6 -> 0.31578947 | O6: =+M6/$M$9 -> 0.1292517 | R6: =+I6 -> EEUU | S6: =+M6 -> 19 | T6: =+J6 -> 6 | U6: =+K6 -> 2 | V6: =+L6 -> 11 | X6: =+T6/(V6+T6) -> 0.35294118 | Y6: =+S6/$S$8 -> 0.15079365
A7: EEUU | B7: 6 | D7: 2 | E7: 11 | G7: 19 | I7: =+A8 -> Perú | J7: =+B8 -> 13 | K7: 4 | L7: =+E8 -> 18 | M7: =+G8 -> 35 | N7: =+J7/M7 -> 0.37142857 | O7: =+M7/$M$9 -> 0.23809524 | R7: =+I7 -> Perú | S7: =+M7 -> 35 | T7: =+J7 -> 13 | U7: =+K7 -> 4 | V7: =+L7 -> 18 | X7: =+T7/(V7+T7) -> 0.41935484 | Y7: =+S7/$S$8 -> 0.27777778
A8: Perú | B8: 13 | D8: 4 | E8: 18 | G8: 35 | I8: =+A9 -> Rusia | J8: =+B9 -> 3 | K8: 2 | L8: =+E9 -> 16 | M8: =+G9 -> 21 | N8: =+J8/M8 -> 0.14285714 | O8: =+M8/$M$9 -> 0.14285714 | R8: Total | S8: =+SUM(S4:S7) -> 126 | T8: =+SUM(T4:T7) -> 60 | U8: =+SUM(U4:U7) -> 16 | V8: =+SUM(V4:V7) -> 50 | X8: =+T8/(V8+T8) -> 0.54545455 | Y8: =+S8/$S$8 -> 1
A9: Rusia | B9: 3 | D9: 2 | E9: 16 | G9: 21 | I9: Total | J9: =+SUM(J4:J8) -> 63 | K9: 18 | L9: =+SUM(L4:L8) -> 66 | M9: =+SUM(M4:M8) -> 147 | N9: =+J9/M9 -> 0.42857143 | O9: =+M9/$M$9 -> 1
A10: (en blanco) | R10: =+I8 -> Rusia | S10: =+SUM(T10:V10) -> 21 | T10: =+J8 -> 3 | U10: =+K8 -> 2 | V10: =+L8 -> 16 | X10: =+T10/(V10+T10) -> 0.15789474 | Y10: =+S10/$S$11 -> 0.14285714
A11: Total general | B11: 63 | C11: 2 | D11: 16 | E11: 66 | G11: 147 | R11: Total | S11: =+S10+S8 -> 147 | T11: =+T10+T8 -> 63 | U11: =+U10+U8 -> 18 | V11: =+V10+V8 -> 66 | X11: =+T11/(V11+T11) -> 0.48837209 | Y11: =+S11/$S$11 -> 1
I12: Promedio Mes | J12: =+SUM(M4:M7)/12 -> 10.5 | K12: =+SUM(J4:J7)/12 -> 5
I13: Promedio Semanal | J13: =+J12/4 -> 2.625
J19: =+J12*150000 -> 1575000

Sheet Resumen Gen Monto
A4: Suma de Monto (USD) | B4: Etiquetas de columna
A5: Etiquetas de fila | B5: Adjudicada | C5: En Construcción | D5: Enviada / Seguimiento | E5: No Adjudicada | F5: (en blanco) | G5: Total general | I5: País | J5: =+G5 -> Total general | K5: Adjudicadas | L5: Seguimiento | M5: =+E5 -> No Adjudicada | O5: Tasa Adjudicación [%] | P5: Propuestas Construidas [%]
A6: Brasil | B6: 1248085 | D6: 1750000 | E6: 101000 | G6: 3099085 | I6: =+A6 -> Brasil | J6: =+SUM(K6:M6) -> 3099085 | K6: =+GETPIVOTDATA("Monto (USD)",$A$4,"Estado Propuesta","Adjudicada","País (Oficina REDCO)","Brasil") -> 1248085 | L6: =+GETPIVOTDATA("Monto (USD)",$A$4,"Estado Propuesta","En Construcción","País (Oficina REDCO)","Brasil")+GETPIVOTDATA("Monto (USD)",$A$4,"Estado Propuesta","Enviada / Seguimiento","País (Oficina REDCO)","Brasil") -> 1750000 | M6: =+GETPIVOTDATA("Monto (USD)",$A$4,"Estado Propuesta","No Adjudicada","País (Oficina REDCO)","Brasil") -> 101000 | O6: =+K6/(M6+K6) -> 0.92513444 | P6: =+J6/$J$10 -> 0.10894067
A7: Chile | B7: 4761416 | C7: 1350000 | D7: 755000 | E7: 3706500 | G7: 10572916 | I7: =+A7 -> Chile | J7: =+SUM(K7:M7) -> 10572916 | K7: =+B7 -> 4761416 | L7: =+GETPIVOTDATA("Monto (USD)",$A$4,"Estado Propuesta","En Construcción","País (Oficina REDCO)","Chile")+GETPIVOTDATA("Monto (USD)",$A$4,"Estado Propuesta","Enviada / Seguimiento","País (Oficina REDCO)","Chile") -> 2105000 | M7: =+GETPIVOTDATA("Monto (USD)",$A$4,"Estado Propuesta","No Adjudicada","País (Oficina REDCO)","Chile") -> 3706500 | O7: =+K7/(M7+K7) -> 0.562289 | P7: =+J7/$J$10 -> 0.37166473
A8: EEUU | B8: 1661000 | D8: 906000 | E8: 6111900 | G8: 8678900 | I8: =+A8 -> EEUU | J8: =+SUM(K8:M8) -> 8678900 | K8: =+B8 -> 1661000 | L8: =+GETPIVOTDATA("Monto (USD)",$A$4,"Estado Propuesta","Enviada / Seguimiento","País (Oficina REDCO)","EEUU") -> 906000 | M8: =+GETPIVOTDATA("Monto (USD)",$A$4,"Estado Propuesta","No Adjudicada","País (Oficina REDCO)","EEUU") -> 6111900 | O8: =+K8/(M8+K8) -> 0.21369116 | P8: =+J8/$J$10 -> 0.30508528
A9: Perú | B9: 1245600 | D9: 1740000 | E9: 3110955 | G9: 6096555 | I9: =+A9 -> Perú | J9: =+SUM(K9:M9) -> 6096555 | K9: =+B9 -> 1245600 | L9: =+GETPIVOTDATA("Monto (USD)",$A$4,"Estado Propuesta","Enviada / Seguimiento","País (Oficina REDCO)","Perú") -> 1740000 | M9: =+GETPIVOTDATA("Monto (USD)",$A$4,"Estado Propuesta","No Adjudicada","País (Oficina REDCO)","Perú") -> 3110955 | O9: =+K9/(M9+K9) -> 0.28591398 | P9: =+J9/$J$10 -> 0.21430932
A10: Rusia | B10: 4709980 | D10: 759000 | E10: 8080206 | G10: 13549186 | I10: Total | J10: =+SUM(K10:M10) -> 28447456 | K10: =+SUM(K6:K9) -> 8916101 | L10: =+SUM(L6:L9) -> 6501000 | M10: =+SUM(M6:M9) -> 13030355 | O10: =+K10/(M10+K10) -> 0.4062661 | P10: =+J10/$J$10 -> 1
A11: (en blanco)
A12: Total general | B12: 13626081 | C12: 1350000 | D12: 5910000 | E12: 21110561 | G12: 41996642 | I12: =+A10 -> Rusia | J12: =+SUM(K12:M12) -> 13549186 | K12: =+B10 -> 4709980 | L12: =+GETPIVOTDATA("Monto (USD)",$A$4,"Estado Propuesta","Enviada / Seguimiento","País (Oficina REDCO)","Rusia") -> 759000 | M12: =+GETPIVOTDATA("Monto (USD)",$A$4,"Estado Propuesta","No Adjudicada","País (Oficina REDCO)","Rusia") -> 8080206 | O12: =+K12/J12 -> 0.34762088 | P12: =+J12/$J$12 -> 1
I13: Total | J13: =+J12+J10 -> 41996642 | K13: =+K12+K10 -> 13626081 | L13: =+L12+L10 -> 7260000 | M13: =+M12+M10 -> 21110561 | O13: =+K13/J13 -> 0.32445644 | P13: =+J13/$J$12 -> 3.0995694
I16: País | J16: Total | K16: Adjudicadas | L16: Seguimiento | M16: No Adjudicadas
I17: =+I6 -> Brasil | J17: =+J6/1000000 -> 3.099085 | K17: =+K6/1000000 -> 1.248085 | L17: =+L6/1000000 -> 1.75 | M17: =+M6/1000000 -> 0.101 | O17: Mensual | P17: =+J10/12 -> 2370621.3
I18: =+I7 -> Chile | J18: =+J7/1000000 -> 10.572916 | K18: =+K7/1000000 -> 4.761416 | L18: =+L7/1000000 -> 2.105 | M18: =+M7/1000000 -> 3.7065
I19: =+I8 -> EEUU | J19: =+J8/1000000 -> 8.6789 | K19: =+K8/1000000 -> 1.661 | L19: =+L8/1000000 -> 0.906 | M19: =+M8/1000000 -> 6.1119 | O19: Semanal | P19: =+P17/4 -> 592655.33
I20: =+I9 -> Perú | J20: =+J9/1000000 -> 6.096555 | K20: =+K9/1000000 -> 1.2456 | L20: =+L9/1000000 -> 1.74 | M20: =+M9/1000000 -> 3.110955
I21: =+I10 -> Total | J21: =+J10/1000000 -> 28.447456 | K21: =+K10/1000000 -> 8.916101 | L21: =+L10/1000000 -> 6.501 | M21: =+M10/1000000 -> 13.030355 | O21: Adjudicado Mensual | P21: =+K21/12 -> 0.74300842
I23: =+I12 -> Rusia | J23: =+J12/1000000 -> 13.549186 | K23: =+K12/1000000 -> 4.70998 | L23: =+L12/1000000 -> 0.759 | M23: =+M12/1000000 -> 8.080206
I24: Total | J24: =+J13/1000000 -> 41.996642 | K24: =+K13/1000000 -> 13.626081 | L24: =+L13/1000000 -> 7.26 | M24: =+M13/1000000 -> 21.110561

Sheet KPIs
U1: Perú | Z1: Chile | AE1: USA | AJ1: Brasil
M2: Promedio | N2: Pendientes | O2: Promedio | P2: Promedio | R2: Promedio | S2: Promedio | U2: Promedio | V2: Pendientes | W2: Promedio | X2: Promedio | Z2: Promedio | AA2: Pendientes | AB2: Promedio | AC2: Promedio | AE2: Promedio | AF2: Pendientes | AG2: Promedio | AH2: Promedio | AJ2: Promedio | AK2: Pendientes | AL2: Promedio | AM2: Promedio | AP2: Promedio de propuestas | AQ2: Adjudicadas | AR2: Pendientes | AS2: No Adjudicadas | AT2: Total
C3: País (Oficina REDCO) | D3: (Todas) | M3: =+AVERAGE(M5:M130) -> 138676.11 | N3: =+AVERAGE(N5:N130) -> 875000 | O3: =+AVERAGE(O5:O130) -> 101000 | P3: =+AVERAGE(P5:P130) -> 258257.08 | R3: =+AVERAGE(R5:R130) -> 675000 | S3: =+AVERAGE(S5:S130) -> 125833.33 | U3: 95815.385 | V3: 435000 | W3: 172830.83 | X3: 174187.29 | Z3: 148794.25 | AA3: 263125 | AB3: 185325 | AC3: 176215.27 | AE3: =+AVERAGE(AE5:AE130) -> 276833.33 | AF3: =+AVERAGE(AF5:AF130) -> 453000 | AG3: =+AVERAGE(AG5:AG130) -> 555627.27 | AH3: =+AVERAGE(AH5:AH130) -> 456784.21 | AJ3: =+AVERAGE(AJ5:AJ130) -> 138676.11 | AK3: =+AVERAGE(AK5:AK130) -> 875000 | AL3: =+AVERAGE(AL5:AL130) -> 101000 | AM3: =+AVERAGE(AM5:AM130) -> 258257.08 | AP3: Brasil | AQ3: 138676.11 | AR3: 875000 | AS3: 101000 | AT3: 258257.08
L4: Etiquetas de fila | M4: Adjudicada | N4: Pendientes | O4: No Adjudicada | P4: Total general | R4: En Construcción | S4: Enviada / Seguimiento | U4: Adjudicada | V4: Pendientes | W4: No Adjudicada | X4: Total general | Z4: Adjudicada | AA4: Pendientes | AB4: No Adjudicada | AC4: Total general | AE4: Adjudicada | AF4: Pendientes | AG4: No Adjudicada | AH4: Total general | AJ4: Adjudicada | AK4: Pendientes | AL4: No Adjudicada | AM4: Total general | AP4: Chile | AQ4: 148794.25 | AR4: 263125 | AS4: 185325 | AT4: 176215.27
C5: Etiquetas de fila | D5: Suma de Monto (USD) | E5: OP | F5: =60/147 -> 0.40816327 | H5: =27/62 -> 0.43548387 | L5: 1 | M5: 78846.6 | P5: 78846.6 | U5: 196600 | V5: - | X5: 196600 | Z5: 200000 | AA5: - | AC5: 200000 | AE5: 612000 | AH5: 612000 | AJ5: 78846.6 | AM5: 78846.6 | AP5: EEUU | AQ5: 276833.33 | AR5: 453000 | AS5: 555627.27 | AT5: 456784.21
C6: 1 | D6: 78846.6 | E6: UG | F6: =87/147 -> 0.59183673 | H6: =35/62 -> 0.56451613 | L6: 2 | M6: 263238.4 | P6: 263238.4 | V6: - | W6: 492580 | X6: 492580 | Z6: 225000 | AA6: - | AC6: 225000 | AG6: 800000 | AH6: 800000 | AJ6: 263238.4 | AM6: 263238.4 | AP6: Perú | AQ6: 95815.385 | AR6: 435000 | AS6: 172830.83 | AT6: 174187.29
C7: 2 | D7: 263238.4 | L7: 3 | M7: 90000 | P7: 90000 | V7: - | W7: 236000 | X7: 236000 | Z7: 200000 | AA7: - | AC7: 200000 | AG7: 1650000 | AH7: 1650000 | AJ7: 90000 | AM7: 90000 | AP7: Total | AQ7: 148602 | AR7: 406313 | AS7: 260607 | AT7: 225773
C8: 3 | D8: 200000 | F8: 3 | G8: 16 | L8: 4 | O8: 101000 | P8: 101000 | U8: 105000 | V8: - | X8: 105000 | Z8: 54000 | AA8: - | AC8: 54000 | AG8: 173900 | AH8: 173900 | AL8: 101000 | AM8: 101000
C9: 4 | D9: 0 | F9: =+F8/G8 -> 0.1875 | L9: 5 | M9: 67000 | P9: 67000 | V9: - | W9: 200000 | X9: 200000 | Z9: 239000 | AA9: - | AC9: 239000 | AG9: 651000 | AH9: 651000 | AJ9: 67000 | AM9: 67000 | AP9: País | AQ9: Diferencia [%]
C10: 5 | D10: 0 | L10: 6 | M10: 60000 | P10: 60000 | V10: - | W10: 285000 | X10: 285000 | Z10: 840000 | AA10: - | AC10: 840000 | AG10: 200000 | AH10: 200000 | AJ10: 60000 | AM10: 60000 | AP10: Brasil | AQ10: =+(AQ3-$AQ$4)/$AQ$4 -> -0.068000873 | AS10: =+(AR7-AQ7)/AQ7 -> 1.7342364
C11: 6 | D11: 0 | L11: 8 | M11: 70000 | P11: 70000 | V11: - | W11: 102545 | X11: 102545 | AA11: - | AB11: 0 | AC11: 0 | AG11: 300000 | AH11: 300000 | AJ11: 70000 | AM11: 70000 | AP11: EEUU | AQ11: =+(AQ5-$AQ$4)/$AQ$4 -> 0.86051096
C12: 7 | D12: 0 | L12: 9 | M12: 40000 | P12: 40000 | V12: - | W12: 149657 | X12: 149657 | AA12: - | AB12: 130000 | AC12: 130000 | AG12: 97000 | AH12: 97000 | AJ12: 40000 | AM12: 40000 | AP12: Perú | AQ12: =+(AQ6-$AQ$4)/$AQ$4 -> -0.35605452
C13: 8 | D13: 0 | L13: 10 | N13: 150000 | P13: 150000 | V13: - | W13: 90120 | X13: 90120 | AA13: - | AB13: 250000 | AC13: 250000 | AG13: 370000 | AH13: 370000 | AK13: 150000 | AM13: 150000
C14: 9 | D14: 0 | L14: 11 | M14: 355000 | P14: 355000 | U14: 119000 | V14: - | X14: 119000 | AA14: - | AB14: 317000 | AC14: 317000 | AE14: 15000 | AH14: 15000 | AJ14: 355000 | AM14: 355000
C15: 10 | D15: 0 | L15: 12 | N15: 1600000 | P15: 1600000 | U15: 74000 | V15: - | X15: 74000 | AA15: - | AB15: 60000 | AC15: 60000 | AE15: 196000 | AH15: 196000 | AK15: 1600000 | AM15: 1600000
C16: 11 | D16: 0 | L16: 14 | M16: 224000 | P16: 224000 | V16: - | W16: 200000 | X16: 200000 | Z16: 300000 | AA16: - | AC16: 300000 | AE16: 98000 | AH16: 98000 | AJ16: 224000 | AM16: 224000
C17: 12 | D17: 0 | L17: 15 | V17: - | W17: 100000 | X17: 100000 | AA17: - | AB17: 145000 | AC17: 145000 | AG17: 70000 | AH17: 70000
C18: 13 | D18: 0 | L18: 16 | V18: - | W18: 40053 | X18: 40053 | Z18: 91650 | AA18: - | AC18: 91650 | AG18: 500000 | AH18: 500000
C19: 14 | D19: 0 | L19: 17 | V19: - | W19: 85000 | X19: 85000 | AA19: - | AB19: 78000 | AC19: 78000 | AE19: 480000 | AH19: 480000
C20: 15 | D20: 0 | L20: 19 | U20: 8000 | V20: - | X20: 8000 | AA20: - | AB20: 1100000 | AC20: 1100000 | AG20: 1300000 | AH20: 1300000
C21: 16 | D21: 0 | L21: 20 | V21: - | W21: 197000 | X21: 197000 | Z21: 88166 | AA21: - | AC21: 88166 | AF21: 566000 | AH21: 566000
C22: 17 | D22: 0 | L22: 21 | U22: 27000 | V22: - | X22: 27000 | AA22: - | AB22: 162000 | AC22: 162000 | AF22: 340000 | AH22: 340000
C23: 18 | D23: 0 | L23: 22 | V23: - | W23: 38000 | X23: 38000 | AA23: - | AB23: 200000 | AC23: 200000 | AE23: 260000 | AH23: 260000
C24: 19 | D24: 0 | L24: 23 | U24: 83000 | V24: - | X24: 83000 | AA24: - | AB24: 520000 | AC24: 520000
C25: 20 | D25: 0 | L25: 24 | U25: 90000 | V25: - | X25: 90000 | AA25: - | AB25: 40000 | AC25: 40000
C26: 21 | D26: 0 | L26: 25 | U26: 70000 | V26: - | X26: 70000 | Z26: 35600 | AA26: - | AC26: 35600
C27: 22 | D27: 0 | L27: 26 | V27: - | W27: 125000 | X27: 125000 | Z27: 30000 | AA27: - | AC27: 30000
C28: 23 | D28: 0 | L28: 27 | V28: - | W28: 80000 | X28: 80000 | AA28: - | AB28: 12500 | AC28: 12500
C29: 24 | D29: 0 | L29: 31 | U29: 133000 | V29: - | X29: 133000 | Z29: 12000 | AA29: - | AC29: 12000
C30: 25 | D30: 0 | L30: 32 | V30: 180000 | X30: 180000 | Z30: 50000 | AA30: - | AC30: 50000
C31: 26 | D31: 0 | L31: 33 | V31: 1100000 | X31: 1100000 | Z31: 43000 | AA31: - | AC31: 43000
C32: 27 | D32: 0 | L32: 34 | V32: - | W32: 250000 | X32: 250000 | Z32: 95000 | AA32: - | AC32: 95000
C33: 28 | D33: 0 | L33: 37 | U33: 270000 | V33: - | X33: 270000 | AA33: - | AB33: 81000 | AC33: 81000
C34: 29 | D34: 0 | L34: 38 | V34: - | W34: 190000 | X34: 190000 | Z34: 190000 | AA34: - | AC34: 190000
C35: 30 | D35: 0 | L35: 39 | U35: 20000 | V35: - | X35: 20000 | AA35: - | AB35: 100000 | AC35: 100000
C36: 31 | D36: 0 | L36: 40 | V36: - | W36: 250000 | X36: 250000 | AA36: - | AB36: 45000 | AC36: 45000
C37: 32 | D37: 0 | L37: 41 | V37: 240000 | X37: 240000 | Z37: 85000 | AA37: - | AC37: 85000
C38: 33 | D38: 0 | L38: 42 | V38: 220000 | X38: 220000 | Z38: 45000 | AA38: - | AC38: 45000
C39: 34 | D39: 0 | L39: 43 | U39: 50000 | V39: - | X39: 50000 | Z39: 70000 | AA39: - | AC39: 70000
C40: 35 | D40: 0 | L40: 44 | Z40: 100000 | AA40: - | AC40: 100000
...

Sheet Hoja7
A3: Suma de Monto (USD) | B3: Etiquetas de columna
A4: Etiquetas de fila | B4: Adjudicada | C4: No Adjudicada | D4: Total general | G4: Adjudicada | H4: No Adjudicada | I4: Total general
A5: 7 | B5: 4339980 | D5: 4339980 | F5: 1 | G5: 4339980 | I5: 4339980
A6: 19 | C6: 1650000 | D6: 1650000 | F6: 2 | H6: 1650000 | I6: 1650000
A7: 79 | C7: 1500000 | D7: 1500000 | F7: 3 | H7: 1500000 | I7: 1500000
A8: 118 | C8: 1300000 | D8: 1300000 | F8: 4 | H8: 1300000 | I8: 1300000
A9: 26 | C9: 1100000 | D9: 1100000 | F9: 5 | H9: 1100000 | I9: 1100000
A10: 92 | C10: 1000000 | D10: 1000000 | F10: 6 | H10: 1000000 | I10: 1000000
A11: 59 | C11: 1000000 | D11: 1000000 | F11: 7 | H11: 1000000 | I11: 1000000 | K11: =20/30 -> 0.66666667
A12: 10 | B12: 840000 | D12: 840000 | F12: 8 | G12: 840000 | I12: 840000
A13: 16 | C13: 800000 | D13: 800000 | F13: 9 | H13: 800000 | I13: 800000
A14: 18 | C14: 725000 | D14: 725000 | F14: 10 | H14: 725000 | I14: 725000
A15: 93 | C15: 720000 | D15: 720000 | F15: 11 | H15: 720000 | I15: 720000
A16: 47 | C16: 651000 | D16: 651000 | F16: 12 | H16: 651000 | I16: 651000
A17: 15 | B17: 612000 | D17: 612000 | F17: 13 | G17: 612000 | I17: 612000
A18: 29 | C18: 600000 | D18: 600000 | F18: 14 | H18: 600000 | I18: 600000
A19: 41 | C19: 520000 | D19: 520000 | F19: 15 | H19: 520000 | I19: 520000
A20: 107 | B20: 500000 | D20: 500000 | F20: 16 | G20: 500000 | I20: 500000
A21: 98 | C21: 500000 | D21: 500000 | F21: 17 | H21: 500000 | I21: 500000
A22: 113 | C22: 500000 | D22: 500000 | F22: 18 | H22: 500000 | I22: 500000
A23: 32 | C23: 492580 | D23: 492580 | F23: 19 | H23: 492580 | I23: 492580
A24: 103 | B24: 480000 | D24: 480000 | F24: 20 | G24: 480000 | I24: 480000
A25: 138 | B25: 450000 | D25: 450000 | F25: 21 | G25: 450000 | I25: 450000
A26: 35 | C26: 395205 | D26: 395205 | F26: 22 | H26: 395205 | I26: 395205
A27: 36 | C27: 375000 | D27: 375000 | F27: 23 | H27: 375000 | I27: 375000
A28: 67 | C28: 370000 | D28: 370000 | F28: 24 | H28: 370000 | I28: 370000
A29: 115 | B29: 355000 | D29: 355000 | F29: 25 | G29: 355000 | I29: 355000
A30: 30 | C30: 324700 | D30: 324700 | F30: 26 | H30: 324700 | I30: 324700
A31: 20 | C31: 317000 | D31: 317000 | F31: 27 | H31: 317000 | I31: 317000
A32: 49 | C32: 300000 | D32: 300000 | F32: 28 | H32: 300000 | I32: 300000
A33: 22 | B33: 300000 | D33: 300000 | F33: 29 | G33: 300000 | I33: 300000 | K33: =29/50 -> 0.58
A34: 42 | C34: 285000 | D34: 285000 | F34: 30 | H34: 285000 | I34: 285000
A35: 116 | B35: 270000 | D35: 270000 | F35: 31 | G35: 270000 | I35: 270000
A36: 2 | B36: 263238.4 | D36: 263238.4 | F36: 32 | G36: 263238.4 | I36: 263238.4
A37: 140 | B37: 260000 | D37: 260000 | F37: 33 | G37: 260000 | I37: 260000
A38: 17 | C38: 250000 | D38: 250000 | F38: 34 | H38: 250000 | I38: 250000
A39: 108 | B39: 250000 | D39: 250000 | F39: 35 | G39: 250000 | I39: 250000
A40: 111 | C40: 250000 | D40: 250000 | F40: 36 | H40: 250000 | I40: 250000
A41: 132 | C41: 250000 | D41: 250000 | F41: 37 | H41: 250000 | I41: 250000
A42: 112 | C42: 240000 | D42: 240000 | F42: 38 | H42: 240000 | I42: 240000
...

Sheet Hoja8
A1: 2500
A2: 4666.6667
A3: 6000
A4: 6250
A5: 7500
A6: 8000
A7: 10000
A8: 10000
A9: 10000
A10: 12666.667
A11: 13333.333
A12: 13500
... A145: 309998.57

Sheet Hoja4
A1: Estado Propuesta | B1: Adjudicada
A3: Etiquetas de fila | B3: Promedio de Monto (USD)
A4: ene | B4: 279423.3
A5: feb | B5: 139500
A6: mar | B6: 118308.33
A7: abr | B7: 177333.33
A8: may | B8: 585931.6
A9: jun | B9: 88142.857
A10: jul | B10: 389666.67
A11: ago | B11: 94777.778
A12: sept | B12: 63000
A13: oct | B13: 217500
A14: nov | B14: 75000
A15: dic | B15: 312500
A16: Total general | B16: 230567.57

Sheet Base de Datos 2024
A1: ID | B1: Área | C1: Gestor Comercial (Responsable) | D1: Desarrollador | E1: Estado Propuesta | F1: País (Oficina REDCO) | G1: Empresa | H1: Mina | I1: Descripcion Oportunidad | J1: Tipo de Mineria | K1: Monto (USD) | L1: Tipo de Contrato | M1: Duracion (meses) | N1: Fecha potencial inicio | O1: Core del negocio | P1: Motivo no Adjudicación
A2: 103 | B2: ING | C2: PV | D2: PA | E2: Adjudicada | F2: EEUU | G2: Twin Metals | H2: Birch Lake - Maturi | I2: Prefactibilidad para el conjunto Birch Lake - Maturi | J2: UG | K2: 480000 | L2: Solicitud Directa | M2: 6 | N2: 45658 | O2: Si | Q2: =+K2/M2 -> 80000
A3: 118 | B3: ING | C3: PV | E3: No Adjudicada | F3: EEUU | G3: Highland Copper | H3: Copperword | I3: FS STUDY | J3: UG | K3: 1300000 | L3: Licitación | M3: 12 | N3: 45627 | O3: No | Q3: =+K3/M3 -> 108333.33
A4: 113 | B4: ING | C4: OD | D4: FR | E4: No Adjudicada | F4: Rusia | G4: Highland Gold | H4: Valunisty mine | I4: PFS OP | J4: OP | K4: 500000 | L4: Solicitud Directa | M4: 6 | N4: 45627 | O4: Si | Q4: =+K4/M4 -> 83333.333
A5: 115 | B5: ING | C5: AS | D5: FR | E5: Adjudicada | F5: Brasil | G5: Mosaic | H5: CTV | I5: Proyecto integral CTV Fase 2 | J5: UG | K5: 355000 | L5: Solicitud Directa | M5: 6 | N5: 45627 | O5: Si | Q5: =+K5/M5 -> 59166.667
A6: 116 | B6: ING | C6: FR | D6: PA | E6: Adjudicada | F6: Perú | G6: Minera Hampton | H6: Los Calatos | I6: Los Calatos Pre-FP Study (V3) | J6: UG | K6: 270000 | L6: Solicitud Directa | M6: 6 | N6: 45627 | O6: Si | Q6: =+K6/M6 -> 45000
A7: 112 | B7: ING | C7: OD | D7: FR | E7: No Adjudicada | F7: Rusia | G7: Highland Gold | H7: Taleveem mine | I7: Scoping Study | J7: OP | K7: 240000 | L7: Solicitud Directa | M7: 3 | N7: 45627 | O7: Si | Q7: =+K7/M7 -> 80000
A8: 117 | B8: ING | C8: AZ | D8: AS | E8: No Adjudicada | F8: Perú | G8: Hudbay Perú S.A.C | H8: Constancia | I8: Estudio de Factibilidad del WRF y Tajo Constancia para la 4ta MEIA | J8: OP | K8: 190000 | L8: Licitación | M8: 3 | N8: 45627 | O8: Si | Q8: =+K8/M8 -> 63333.333
A9: 114 | B9: ING | C9: AS | D9: FR | E9: Enviada / Seguimiento | F9: Brasil | G9: Vale | H9: Gongo Soco | I9: Estudio Conceptual | J9: OP | K9: 150000 | L9: Solicitud Directa | M9: 3 | N9: 45627 | O9: Si | Q9: =+K9/M9 -> 50000
A10: 97 | B10: ING | C10: MM | D10: PA | E10: No Adjudicada | F10: Chile | G10: Codelco | H10: DET | I10: ESTUDIO SISTEMA DE GESTIÓN PREMIN DET | J10: UG | K10: 90000 | L10: Licitación | M10: 6 | N10: 45627 | O10: Si | Q10: =+K10/M10 -> 15000
A11: 110 | B11: ING | C11: MM | D11: PA | E11: Adjudicada | F11: Chile | G11: Codelco | H11: DMH | I11: INGENIERÍA EXPLORATORIA DEL PROYECTO DMH NORTE | J11: UG | K11: 75000 | L11: Licitación | M11: 3 | N11: 45597 | O11: Si | Q11: =+K11/M11 -> 25000
A12: 106 | B12: ING | C12: AZ | D12: PA | E12: Enviada / Seguimiento | F12: Perú | G12: Las Bambas | H12: Ferrobamba | I12: PFS Ferrobamba Deep | J12: UG | K12: 1100000 | L12: Licitación | M12: 13 | N12: 45566 | O12: Si | Q12: =+K12/M12 -> 84615.385
A13: 107 | B13: ING | C13: ER | D13: PA | E13: Adjudicada | F13: Chile | G13: AMSA | H13: Centinela | I13: Trade Off Tecnologias de manejo de materiales | J13: q | K13: 500000 | L13: Licitación | M13: 24 | N13: 45566 | O13: Si | Q13: =+K13/M13 -> 20833.333
A14: 108 | B14: ING | C14: ER | D14: PA | E14: Adjudicada | F14: Chile | G14: Capstone Copper | H14: =AVERAGE(M13:M75) -> 4.8730159 | I14: Ing Conceptual: Estudio Extensión Sierra Norte | J14: OP | K14: 250000 | L14: Solicitud Directa | M14: 5 | N14: 45566 | O14: Si | Q14: =+K14/M14 -> 50000
A15: 111 | B15: ING | C15: CH | D15: PA | E15: No Adjudicada | F15: Perú | G15: Sierra Metals | H15: Yauricocha | I15: ESTUDIO DE VENTILACIÓN UNIDAD MINERA YAURICOCHA | J15: UG | K15: 250000 | L15: Licitación | M15: 6 | N15: 45566 | O15: No | Q15: =+K15/M15 -> 41666.667
A16: 101 | B16: ING | C16: AZ | D16: PA | E16: Enviada / Seguimiento | F16: Perú | G16: OCP | H16: Cobriza | I16: Diagnostico operaciónal y construcción de planes alternativos (Blue Sky y potencial) | J16: UG | K16: 180000 | L16: Licitación | M16: 3 | N16: 45566 | O16: Si | Q16: =+K16/M16 -> 60000
A17: 105 | B17: ING | C17: OD | D17: PA | E17: No Adjudicada | F17: Rusia | G17: Seligdar | H17: Seligdar | I17: Construccion de wireframes de cuerpo mineral y modelos de bloque de 2 yacimientos: Nerundinskoye y Mukodek | J17: UG | K17: 150000 | L17: Solicitud Directa | M17: 3 | N17: 45566 | O17: Si | Q17: =+K17/M17 -> 50000
A18: 102 | B18: ING | C18: FR | D18: PA | E18: Adjudicada | F18: Chile | G18: CMP | H18: CNN | I18: Mejoras Operacionales CNN FEL3 (upgrade de la evaluación del proyecto de ampliación) | J18: OP | K18: 100000 | L18: Licitación | M18: 3 | N18: 45566 | O18: Si | Q18: =+K18/M18 -> 33333.333
A19: 109 | B19: ING | C19: PA | D19: PA | E19: No Adjudicada | F19: Chile | G19: Carola | H19: Carola | I19: Apoyo en la planificación de Corto Plazo (SIMPREP) | J19: UG | K19: 66000 | L19: Solicitud Directa | M19: 4 | N19: 45566 | O19: Si | Q19: =+K19/M19 -> 16500
A20: 119 | B20: ING | C20: FR | E20: Adjudicada | F20: Perú | G20: Buenaventura | H20: Tantahuatay | I20: servicio de capacitación en DBS y SIMPLAN | J20: OP | K20: 20000 | L20: Solicitud Directa | M20: 2 | N20: 45566 | O20: Si | Q20: =+K20/M20 -> 10000
A21: 59 | B21: ING | C21: OD | D21: RM | E21: No Adjudicada | F21: Rusia | G21: ERG | H21: - | I21: Desarrollo plan LOM y plan de cierre | J21: OP | K21: 1000000 | L21: Licitación | M21: 12 | N21: 45536 | O21: Si | P21: Anulación de licitación | Q21: =+K21/M21 -> 83333.333
A22: 92 | B22: ING | C22: OD | D22: RM | E22: No Adjudicada | F22: Rusia | G22: Atlas Mining | I22: Ing PFS Mina | J22: OP | K22: 1000000 | L22: Licitación | M22: 6 | N22: 45536 | O22: Si | Q22: =+K22/M22 -> 166666.67
A23: 93 | B23: GEOT | C23: OD | D23: RM | E23: No Adjudicada | F23: Rusia | G23: Kuzbass | H23: Ugol | I23: Modelo 3d geologica de 2 yacimientos | J23: OP | K23: 720000 | L23: Licitación | M23: 12 | N23: 45536 | O23: Si | Q23: =+K23/M23 -> 60000
A24: 38 | B24: ING | C24: AZ | E24: No Adjudicada | F24: Perú | G24: Minera Chinalco Perú S.A | H24: Chinalco | I24: Estimación de Reservas Minerales y Plan de Vida de Mina | J24: OP | K24: 200000 | L24: Licitación | M24: 4 | N24: 45536 | O24: Si | P24: Anulación de licitación | Q24: =+K24/M24 -> 50000
A25: 99 | B25: ING | C25: FR | D25: PA | E25: Adjudicada | F25: Chile | G25: Lundin | H25: Candelaria | I25: Diagnóstico de gaps de planificación y operaciones (Foco en riesgos geomecánicos) | J25: UG | K25: 66000 | L25: Solicitud Directa | M25: 2 | N25: 45536 | O25: Si | Q25: =+K25/M25 -> 33000
A26: 83 | B26: ING | C26: AS | D26: PA | E26: Adjudicada | F26: Brasil | G26: Mosaic | H26: Cajati | I26: Metodologia para evaluar cumplimiento del plan con KPIs reales | J26: UG | K26: 60000 | L26: Solicitud Directa | M26: 2 | N26: 45536 | O26: Si | Q26: =+K26/M26 -> 30000
A27: 11 | B27: ING | C27: MM | E27: No Adjudicada | F27: Chile | G27: Lundin | H27: Candelaria | I27: Mejoras operacionales (Simprep y optimización P&T subterranea) | J27: UG | K27: - | L27: Solicitud Directa | M27: 3 | N27: 45505 | O27: Si
A28: 79 | B28: ING | C28: OD | D28: RM | E28: No Adjudicada | F28: Rusia | G28: EVRAZ | I28: Propuesta sistema de simulación | J28: UG | K28: 1500000 | L28: Licitación | M28: 14 | N28: 45505 | O28: No | Q28: =+K28/M28 -> 107142.86
A29: 98 | B29: ING | C29: PV | E29: No Adjudicada | F29: EEUU | G29: Cementation | I29: Estimación de reservas, mine plan | J29: OP | K29: 500000 | L29: Solicitud Directa | M29: 6 | N29: 45505 | O29: No | Q29: =+K29/M29 -> 83333.333
A30: 85 | B30: ING | D30: PA | E30: Adjudicada | F30: Chile | G30: BHP | H30: Escondida | I30: Modelo predictivo para Definir ubicación óptima de pozos de drenaje | J30: UG | K30: 190000 | L30: Solicitud Directa | M30: 2 | N30: 45505 | O30: No | Q30: =+K30/M30 -> 95000
A31: 31 | B31: ING | C31: PV | E31: No Adjudicada | F31: EEUU | G31: Rockhaven | H31: - | I31: Mining Trade Off Study | J31: UG | K31: 173900 | L31: Solicitud Directa | M31: 3 | N31: 45505 | O31: Si | Q31: =+K31/M31 -> 57966.667
A32: 89 | B32: ING | C32: AZ | D32: PA | E32: Adjudicada | F32: Perú | G32: Minsur | H32: Mina Justa | I32: Estudio técnico – económico para fase de perfil proyecto achupallas | J32: OP | K32: 133000 | L32: Licitación | M32: 2 | N32: 45505 | O32: Si | Q32: =+K32/M32 -> 66500
A33: 87 | B33: ING | C33: MM | D33: PA | E33: No Adjudicada | F33: Perú | G33: Minsur | H33: - | I33: Estandarización, control y seguimiento de KPIs/resultados de corto/mediano plazo para Minsur | J33: UG | K33: 125000 | L33: Solicitud Directa | M33: 4 | N33: 45505 | O33: Si | Q33: =+K33/M33 -> 31250
A34: 100 | B34: ING | C34: FR | D34: PA | E34: Adjudicada | F34: Chile | G34: Lundin | H34: Caserones | I34: Evaluación opciones de mejora a través de nuevos criterios para definir los destinos óptimos y la estrategia de leyes de corte | J34: UG | K34: 120000 | L34: Solicitud Directa | M34: 3 | N34: 45505 | O34: Si | Q34: =+K34/M34 -> 40000
A35: 86 | B35: ING | C35: MM | D35: PV | E35: No Adjudicada | F35: Chile | G35: Codelco | H35: DRT | I35: Análisis y cuantificación de cobre en riesgo por expansión del OP | J35: OP | K35: 100000 | L35: Solicitud Directa | M35: 2 | N35: 45505 | O35: Si | Q35: =+K35/M35 -> 50000
A36: 96 | B36: ING | C36: FR | D36: CH | E36: Adjudicada | F36: Chile | G36: CMP | H36: Algarrobo | I36: Nuevos alcances: Proyecto Algarrobo Finos | J36: OP | K36: 100000 | L36: Solicitud Directa | M36: 10 | N36: 45505 | O36: Si | Q36: =+K36/M36 -> 10000
A37: 91 | B37: ING | C37: MM | D37: PA | E37: Adjudicada | F37: Chile | G37: Codelco | H37: DMH | I37: Estudio Análisis Opciones de Vaciado Mineral Subterránea Vía Rajo Horizonte Corto-Mediano Plazo | J37: OP | K37: 85000 | L37: Licitación | M37: 3 | N37: 45505 | O37: Si | Q37: =+K37/M37 -> 28333.333
A38: 88 | B38: ING | C38: AZ | D38: PA | E38: No Adjudicada | F38: Perú | G38: Buenaventura | H38: El Brocal | I38: Estudio de ingeniería de factibilidad para la Ampliación del Tajo Norte | J38: OP | K38: 80000 | L38: Licitación | M38: 3 | N38: 45505 | O38: Si | P38: Costos muy altos | Q38: =+K38/M38 -> 26666.667
A39: 81 | B39: ING | C39: MF | D39: PA | E39: Adjudicada | F39: Perú | G39: Minsur | H39: San Rafael | I39: Evaluación de recursos marginales | J39: UG | K39: 70000 | L39: Solicitud Directa | M39: 2 | N39: 45505 | O39: Si | Q39: =+K39/M39 -> 35000
A40: 95 | B40: ING | C40: FR | D40: PA | E40: Adjudicada | F40: Chile | G40: BHP | H40: Spence | I40: Análisis de confiabilidad del plan LoA 2025-26 | J40: OP | K40: 70000 | L40: Solicitud Directa | M40: 2 | N40: 45505 | O40: Si | Q40: =+K40/M40 -> 35000
...

Sheet Hoja5
M13: 480000 | N13: =AVERAGE(M13:M75) -> 216287
M14: 355000
M15: 270000
M16: 75000
M17: 500000
M18: 250000
M19: 100000
M20: 20000
M21: 66000
M22: 60000
M23: 190000
M24: 133000
M25: 120000
... M75: 14000

Sheet POM_Agosto
J1: =+SUM(F2:J2) -> 45 | O1: =+SUM(K2:O2) -> 60.5 | T1: =+SUM(P2:T2) -> 46.8 | Y1: =+SUM(U2:Y2) -> 9 | AD1: =+SUM(Z2:AD2) -> 13 | AI1: =+SUM(AE2:AI2) -> 9 | AN1: =+SUM(AJ2:AN2) -> 9 | AS1: =+SUM(AO2:AS2) -> 9
F2: =+F14+F20+F27+F33+F41+F51+F59+F64+F74+F79+F84+F89+F94+F106+F113+F118+F124+F137+F5+F142+F99+F147 -> 5 | G2: =+G14+G20+G27+G33+G41+G51+G59+G64+G74+G79+G84+G89+G94+G106+G113+G118+G124+G137+G5+G142+G99+G147 -> 7 | H2: =+H14+H20+H27+H33+H41+H51+H59+H64+H74+H79+H84+H89+H94+H106+H113+H118+H124+H137+H5+H142+H99+H147 -> 10.5 | I2: =+I14+I20+I27+I33+I41+I51+I59+I64+I74+I79+I84+I89+I94+I106+I113+I118+I124+I137+I5+I142+I99+I147 -> 14.5 | J2: =+J14+J20+J27+J33+J41+J51+J59+J64+J74+J79+J84+J89+J94+J106+J113+J118+J124+J137+J5+J142+J99+J147 -> 8 | K2: =+K14+K20+K27+K33+K41+K51+K59+K64+K74+K79+K84+K89+K94+K106+K113+K118+K124+K137+K5+K142+K99+K147 -> 7 | L2: =+L14+L20+L27+L33+L41+L51+L59+L64+L74+L79+L84+L89+L94+L106+L113+L118+L124+L137+L5+L142+L99+L147 -> 30 | M2: =+M14+M20+M27+M33+M41+M51+M59+M64+M74+M79+M84+M89+M94+M106+M113+M118+M124+M137+M5+M142+M99+M147 -> 9.5 | ... AS2: =+AS14+AS20+AS27+AS33+AS41+AS51+AS59+AS64+AS74+AS79+AS84+AS89+AS94+AS106+AS113+AS118+AS124+AS137+AS5+AS142+AS99+AS147 -> 0
F3: Semana 05/08 | K3: Semana 12/08 | P3: Semana 19/08 | U3: Semana 26/08 | Z3: Semana 02/09 | AE3: Semana 09/09 | AJ3: Semana 16/09 | AO3: Semana 23/09
A4: ID | B4: País | C4: Tema | D4: Objetivo | E4: Requerimiento | F4: Lunes | G4: Martes | H4: Miércoles | I4: Jueves | J4: Viernes | K4: Lunes | L4: Martes | M4: Miércoles | N4: Jueves | O4: Viernes | P4: Lunes | Q4: Martes | R4: Miércoles | S4: Jueves | T4: Viernes | U4: Lunes | V4: Martes | W4: Miércoles | X4: Jueves | Y4: Viernes | Z4: Lunes | AA4: Martes | AB4: Miércoles | AC4: Jueves | AD4: Viernes | AE4: Lunes | AF4: Martes | AG4: Miércoles | AH4: Jueves | AI4: Viernes | AJ4: Lunes | AK4: Martes | AL4: Miércoles | AM4: Jueves | AN4: Viernes | AO4: Lunes | AP4: Martes | AQ4: Miércoles | AR4: Jueves | AS4: Viernes
A5: 0 | B5: Chile | C5: Reuniones | D5: Reuniones administrativas | F5: =+SUM(F6:F13) -> 2 | G5: =+SUM(G6:G13) -> 0 | H5: =+SUM(H6:H13) -> 2 | I5: =+SUM(I6:I13) -> 2 | J5: =+SUM(J6:J13) -> 0 | K5: =+SUM(K6:K13) -> 2 | L5: =+SUM(L6:L13) -> 4 | M5: =+SUM(M6:M13) -> 2 | ... AS5: =+SUM(AS6:AS13) -> 0
C6: A1 | D6: Reunión ejectuviva (12:00) | F6: 1 | K6: 1 | P6: 1 | U6: 1 | Z6: 1 | AE6: 1 | AJ6: 1 | AO6: 1
C7: A2 | D7: Reunión ejecutiva (13:00) | F7: 1 | K7: 1 | P7: 1 | U7: 1 | Z7: 1 | AE7: 1 | AJ7: 1 | AO7: 1
C8: A3 | D8: Reunión comercial (9:30) | H8: 1 | M8: 1 | R8: 1 | W8: 1 | AB8: 1 | AG8: 1 | AL8: 1 | AQ8: 1
C9: A4 | D9: Reunión de gestión de cobranza (12:30) | H9: 1 | M9: 1 | R9: 1 | W9: 1 | AB9: 1 | AG9: 1 | AL9: 1 | AQ9: 1
C10: A5
C11: A6
C12: A7 | D12: Preparación reunión de gestión | I12: 2 | L12: 4 | AA12: 4
C13: A8 | D13: Reunión de gestión
A14: 1 | B14: USA | C14: KSM | D14: Preparar Statement of Qualifications (SOQ) (20 agosto) | F14: =+SUM(F15:F19) -> 1 | G14: =+SUM(G15:G19) -> 0 | H14: =+SUM(H15:H19) -> 1 | I14: =+SUM(I15:I19) -> 0 | J14: =+SUM(J15:J19) -> 0 | K14: =+SUM(K15:K19) -> 3 | L14: =+SUM(L15:L19) -> 1 | M14: =+SUM(M15:M19) -> 0 | ... AS14: =+SUM(AS15:AS19) -> 0
C15: A1 | D15: Hacer ppta con entendimiento. | F15: 1
C16: A2 | D16: Coordinar con equipo que material vamos a presentar (que y como) | E16: Reunión con ER | H16: 0.5
C17: A3 | D17: Preparar material | H17: 0.5 | I17: 0 | K17: 3
C18: A4 | D18: Validación con PV y equipo de Ing | I18: 0 | L18: 0.5 | P18: 3
C19: A5 | D19: Envio de documento (material) | J19: 0 | K19: 0 | L19: 0.5
A20: 2 | B20: USA | C20: Twin Metals | D20: Prepararación de propuestas Birch Lake - Maturi (05/09) | F20: =+SUM(F21:F25) -> 0 | G20: =+SUM(G21:G25) -> 0 | H20: =+SUM(H21:H25) -> 0 | I20: =+SUM(I21:I25) -> 0 | J20: =+SUM(J21:J25) -> 0 | K20: =+SUM(K21:K25) -> 0 | L20: =+SUM(L21:L25) -> 3 | M20: =+SUM(M21:M25) -> 0.5 | ... AS20: =+SUM(AS21:AS25) -> 0
C21: A1 | D21: Preparación de lamina de entendimiento, alcances y temas principales | G21: 0
C22: A2 | D22: Construcción de excel (HH, gantt, equipo, tareas) y PPT propuesta | K22: 0 | L22: 3
C23: A3 | D23: Validación con PV y equipo de Ing | M23: 0.5
C24: A4 | D24: Construcción documento (word) | N24: 0 | O24: 6 | P24: 6
C25: A5 | D25: Validación con PV y equipo de Ing | Q25: 0.5
C26: A6 | D26: Envio de propuesta | R26: 0.5
A27: 3 | B27: Chile | C27: MassMin | D27: Coordinación participación MassMin | F27: =+SUM(F28:F32) -> 0 | G27: =+SUM(G28:G32) -> 0 | H27: =+SUM(H28:H32) -> 0 | I27: =+SUM(I28:I32) -> 0 | J27: =+SUM(J28:J32) -> 3 | K27: =+SUM(K28:K32) -> 1 | L27: =+SUM(L28:L32) -> 3 | M27: =+SUM(M28:M32) -> 0 | N27: =+SUM(N28:N32) -> 3 | O27: =+SUM(O29:O32) -> 1 | P27: =+SUM(P28:P32) -> 0 | Q27: =+SUM(Q28:Q32) -> 0 | R27: =+SUM(R28:R32) -> 0 | S27: =+SUM(S28:S32) -> 0 | T27: =+SUM(T29:T32) -> 0 | U27: =+SUM(U28:U32) -> 0 | V27: =+SUM(V28:V32) -> 0 | W27: =+SUM(W28:W32) -> 0 | X27: =+SUM(X28:X32) -> 0 | Y27: =+SUM(Y29:Y32) -> 0 | Z27: =+SUM(Z28:Z32) -> 0 | AA27: =+SUM(AA28:AA32) -> 0 | AB27: =+SUM(AB28:AB32) -> 0 | AC27: =+SUM(AC28:AC32) -> 0 | AD27: =+SUM(AD29:AD32) -> 0 | AE27: =+SUM(AE28:AE32) -> 0 | AF27: =+SUM(AF28:AF32) -> 0 | AG27: =+SUM(AG28:AG32) -> 0 | AH27: =+SUM(AH28:AH32) -> 0 | AI27: =+SUM(AI29:AI32) -> 0 | AJ27: =+SUM(AJ28:AJ32) -> 0 | AK27: =+SUM(AK28:AK32) -> 0 | AL27: =+SUM(AL28:AL32) -> 0 | AM27: =+SUM(AM28:AM32) -> 0 | AN27: =+SUM(AN29:AN32) -> 0 | AO27: =+SUM(AO28:AO32) -> 0 | AP27: =+SUM(AP28:AP32) -> 0 | AQ27: =+SUM(AQ28:AQ32) -> 0 | AR27: =+SUM(AR28:AR32) -> 0 | AS27: =+SUM(AS29:AS32) -> 0
C28: A1 | D28: Reunión de coordinación sobre fechas, temas a presentar, etc | E28: Reunión con PV, MF, ER | K28: 1
C29: A2 | D29: Preparar diseño stand | E29: Validación ER | J29: 3
C30: A3 | D30: Preparar presentaciones (ppt) | K30: 0 | L30: 2
C31: A4 | D31: Presentar presentaciones | N31: 3
C32: A5 | D32: Revisión de presentaciones | L32: 1 | O32: 1
A33: 4 | B33: Rusia | C33: Viaje Rusia | D33: Coordinación viaje a Rusia | F33: =+SUM(F34:F35) -> 1 | G33: =+SUM(G34:G35) -> 0 | H33: =+SUM(H34:H35) -> 0 | I33: =+SUM(I34:I35) -> 4 | J33: =+SUM(J34:J35) -> 0 | K33: =+SUM(K34:K35) -> 0 | L33: =+SUM(L34:L35) -> 0 | M33: =+SUM(M34:M35) -> 0 | ... AS33: =+SUM(AS34:AS35) -> 0
C34: A1 | D34: Reunión de coordinación sobre fechas, material para presentar, etc | E34: Reunión con OD y FR | F34: 1
C35: A2 | D35: Preparar presentación actualizada con casos de éxito UG | I35: 4
C36: A3 | D36: Revisión de plan de visita a empresas | K36: 1
C37: A4 | D37: Asiganación de recursos a las solicitudes | O37: 1 | P37: 1 | Q37: 1 | R37: 1
C38: A5
C39: A6
C40: A7
...

Sheet Lista de proyectos
