Workbook

Sheet 00_Portada_Metodologia
B1: REDCO · Rentabilidad, Ventas y Flujo de Caja — Análisis histórico
B2: Libro único de trazabilidad. Fecha de generación: 2026-07-05. Todos los montos en USD.
B4: Qué es este archivo
B5: Cuatro análisis históricos de REDCO, cada uno en su hoja (01-04), más el puente de identidad (91), las hojas de datos de origen (90_*) y las fuentes (99).
B6: Las hojas 01-04 NO contienen valores pegados: se calculan con fórmulas (SUMIFS/VLOOKUP) que leen de las hojas 90_* y 91. La trazabilidad es recalculable dentro del mismo libro (Datos → Actualizar / recalcular).
B7: Regla de color: texto VERDE = fórmula que enlaza a otra hoja del libro (staging); texto NEGRO = cálculo dentro de la hoja.
B9: Definición de 'VENTA' usada (Entregable 2)
B10: VENTA = 'Emitido USD' del ledger CicloEdP_2023_v1 (devengo real del servicio ejecutado / EDP emitido).
B11: Motivo: el campo 'Proyectado USD' está en 0 para todo 2025 en el ledger (la proyección de ese año se llevó en el POM, no en el ledger), por lo que NO sirve como proxy de venta comparable entre años.
B12: 'Proyectado USD', 'Facturado USD' e 'Ingresado USD' se muestran como columnas de contraste (hoja 02, bloque C).
B14: Definición de 'TIPO DE PRODUCTO' (derivado — no es campo nativo)
B15: No existe columna de tipo de producto/línea de servicio en ninguna fuente. Se deriva del segmento FASE del campo 'Código' del ledger (formato PAÍS-CLIENTE-UNIDAD-FASE-corr-rev, p.ej. CH-CMP-OU-FEL00-001-A).
... B46: 00_Portada_Metodologia · 01_Rentabilidad_2024_2025 · 02_Ventas_2023_2025 · 03_FlujoCaja_2024_2025 · 04_Rentab_Dotacion_Dic2025 (FOTO dic-2025) · 91_Puente_Identidad · 90_Origen_* (datos de origen) · 99_Fuentes.

Sheet 01_Rentabilidad_2024_2025
A1: ENTREGABLE 1 · Rentabilidad histórica por país y tipo de producto
A2: 2025: País×Mes (resultado operacional real). 2024: solo ingreso devengado (EDP emitido) — el costo/margen 2024 por país NO existe en las fuentes.
A4: A) 2025 — Resultado operacional por País × Mes (USD) · fuente: Tabla datos unidades_Dic
A5: País | B5: Mes | C5: Ingreso Op. USD | D5: Gasto Op. USD (incl. adm.) | E5: Beneficio USD | F5: Margen %
A6: Chile | B6: ene | C6: =SUMIFS('90_Origen_Rentab_2025'!$F$3:$F$122,'90_Origen_Rentab_2025'!$A$3:$A$122,$A6,'90_Origen_Rentab_2025'!$C$3:$C$122,1,'90_Origen_Rentab_2025'!$E$3:$E$122,"INGRESOS OP") -> 362362.73 | D6: =SUMIFS('90_Origen_Rentab_2025'!$F$3:$F$122,'90_Origen_Rentab_2025'!$A$3:$A$122,$A6,'90_Origen_Rentab_2025'!$C$3:$C$122,1,'90_Origen_Rentab_2025'!$E$3:$E$122,"COSTOS OP") -> 397276.65 | E6: =C6-D6 -> -34913.92 | F6: =IF(C6=0,"-",E6/C6) -> -0.096350748
A7: Chile | B7: feb | C7: =SUMIFS('90_Origen_Rentab_2025'!$F$3:$F$122,'90_Origen_Rentab_2025'!$A$3:$A$122,$A7,'90_Origen_Rentab_2025'!$C$3:$C$122,2,'90_Origen_Rentab_2025'!$E$3:$E$122,"INGRESOS OP") -> 547310.62 | D7: =SUMIFS('90_Origen_Rentab_2025'!$F$3:$F$122,'90_Origen_Rentab_2025'!$A$3:$A$122,$A7,'90_Origen_Rentab_2025'!$C$3:$C$122,2,'90_Origen_Rentab_2025'!$E$3:$E$122,"COSTOS OP") -> 422126.64 | E7: =C7-D7 -> 125183.98 | F7: =IF(C7=0,"-",E7/C7) -> 0.22872565
A8: Chile | B8: mar | C8: =SUMIFS('90_Origen_Rentab_2025'!$F$3:$F$122,'90_Origen_Rentab_2025'!$A$3:$A$122,$A8,'90_Origen_Rentab_2025'!$C$3:$C$122,3,'90_Origen_Rentab_2025'!$E$3:$E$122,"INGRESOS OP") -> 389727.46 | D8: =SUMIFS('90_Origen_Rentab_2025'!$F$3:$F$122,'90_Origen_Rentab_2025'!$A$3:$A$122,$A8,'90_Origen_Rentab_2025'!$C$3:$C$122,3,'90_Origen_Rentab_2025'!$E$3:$E$122,"COSTOS OP") -> 439899.18 | E8: =C8-D8 -> -50171.72 | F8: =IF(C8=0,"-",E8/C8) -> -0.1287354
A9: Chile | B9: abr | C9: =SUMIFS('90_Origen_Rentab_2025'!$F$3:$F$122,'90_Origen_Rentab_2025'!$A$3:$A$122,$A9,'90_Origen_Rentab_2025'!$C$3:$C$122,4,'90_Origen_Rentab_2025'!$E$3:$E$122,"INGRESOS OP") -> 237434.48 | D9: =SUMIFS('90_Origen_Rentab_2025'!$F$3:$F$122,'90_Origen_Rentab_2025'!$A$3:$A$122,$A9,'90_Origen_Rentab_2025'!$C$3:$C$122,4,'90_Origen_Rentab_2025'!$E$3:$E$122,"COSTOS OP") -> 341507.35 | E9: =C9-D9 -> -104072.87 | F9: =IF(C9=0,"-",E9/C9) -> -0.43832248
A10: Chile | B10: may | C10: =SUMIFS('90_Origen_Rentab_2025'!$F$3:$F$122,'90_Origen_Rentab_2025'!$A$3:$A$122,$A10,'90_Origen_Rentab_2025'!$C$3:$C$122,5,'90_Origen_Rentab_2025'!$E$3:$E$122,"INGRESOS OP") -> 272631.08 | D10: =SUMIFS('90_Origen_Rentab_2025'!$F$3:$F$122,'90_Origen_Rentab_2025'!$A$3:$A$122,$A10,'90_Origen_Rentab_2025'!$C$3:$C$122,5,'90_Origen_Rentab_2025'!$E$3:$E$122,"COSTOS OP") -> 340134.8 | E10: =C10-D10 -> -67503.72 | F10: =IF(C10=0,"-",E10/C10) -> -0.24760097
A11: Chile | B11: jun | C11: =SUMIFS('90_Origen_Rentab_2025'!$F$3:$F$122,'90_Origen_Rentab_2025'!$A$3:$A$122,$A11,'90_Origen_Rentab_2025'!$C$3:$C$122,6,'90_Origen_Rentab_2025'!$E$3:$E$122,"INGRESOS OP") -> 277419.07 | D11: =SUMIFS('90_Origen_Rentab_2025'!$F$3:$F$122,'90_Origen_Rentab_2025'!$A$3:$A$122,$A11,'90_Origen_Rentab_2025'!$C$3:$C$122,6,'90_Origen_Rentab_2025'!$E$3:$E$122,"COSTOS OP") -> 380566.17 | E11: =C11-D11 -> -103147.1 | F11: =IF(C11=0,"-",E11/C11) -> -0.3718097
A12: Chile | B12: jul | C12: =SUMIFS('90_Origen_Rentab_2025'!$F$3:$F$122,'90_Origen_Rentab_2025'!$A$3:$A$122,$A12,'90_Origen_Rentab_2025'!$C$3:$C$122,7,'90_Origen_Rentab_2025'!$E$3:$E$122,"INGRESOS OP") -> 475570.75 | D12: =SUMIFS('90_Origen_Rentab_2025'!$F$3:$F$122,'90_Origen_Rentab_2025'!$A$3:$A$122,$A12,'90_Origen_Rentab_2025'!$C$3:$C$122,7,'90_Origen_Rentab_2025'!$E$3:$E$122,"COSTOS OP") -> 395727.19 | E12: =C12-D12 -> 79843.56 | F12: =IF(C12=0,"-",E12/C12) -> 0.16788997
A13: Chile | B13: ago | C13: =SUMIFS('90_Origen_Rentab_2025'!$F$3:$F$122,'90_Origen_Rentab_2025'!$A$3:$A$122,$A13,'90_Origen_Rentab_2025'!$C$3:$C$122,8,'90_Origen_Rentab_2025'!$E$3:$E$122,"INGRESOS OP") -> 151482.74 | D13: =SUMIFS('90_Origen_Rentab_2025'!$F$3:$F$122,'90_Origen_Rentab_2025'!$A$3:$A$122,$A13,'90_Origen_Rentab_2025'!$C$3:$C$122,8,'90_Origen_Rentab_2025'!$E$3:$E$122,"COSTOS OP") -> 425248.91 | E13: =C13-D13 -> -273766.17 | F13: =IF(C13=0,"-",E13/C13) -> -1.8072433
A14: Chile | B14: sep | C14: =SUMIFS('90_Origen_Rentab_2025'!$F$3:$F$122,'90_Origen_Rentab_2025'!$A$3:$A$122,$A14,'90_Origen_Rentab_2025'!$C$3:$C$122,9,'90_Origen_Rentab_2025'!$E$3:$E$122,"INGRESOS OP") -> 297925.05 | D14: =SUMIFS('90_Origen_Rentab_2025'!$F$3:$F$122,'90_Origen_Rentab_2025'!$A$3:$A$122,$A14,'90_Origen_Rentab_2025'!$C$3:$C$122,9,'90_Origen_Rentab_2025'!$E$3:$E$122,"COSTOS OP") -> 455871.33 | E14: =C14-D14 -> -157946.28 | F14: =IF(C14=0,"-",E14/C14) -> -0.53015441
A15: Chile | B15: oct | C15: =SUMIFS('90_Origen_Rentab_2025'!$F$3:$F$122,'90_Origen_Rentab_2025'!$A$3:$A$122,$A15,'90_Origen_Rentab_2025'!$C$3:$C$122,10,'90_Origen_Rentab_2025'!$E$3:$E$122,"INGRESOS OP") -> 158266.46 | D15: =SUMIFS('90_Origen_Rentab_2025'!$F$3:$F$122,'90_Origen_Rentab_2025'!$A$3:$A$122,$A15,'90_Origen_Rentab_2025'!$C$3:$C$122,10,'90_Origen_Rentab_2025'!$E$3:$E$122,"COSTOS OP") -> 513185.66 | E15: =C15-D15 -> -354919.2 | F15: =IF(C15=0,"-",E15/C15) -> -2.2425421
A16: Chile | B16: nov | C16: =SUMIFS('90_Origen_Rentab_2025'!$F$3:$F$122,'90_Origen_Rentab_2025'!$A$3:$A$122,$A16,'90_Origen_Rentab_2025'!$C$3:$C$122,11,'90_Origen_Rentab_2025'!$E$3:$E$122,"INGRESOS OP") -> 248788.93 | D16: =SUMIFS('90_Origen_Rentab_2025'!$F$3:$F$122,'90_Origen_Rentab_2025'!$A$3:$A$122,$A16,'90_Origen_Rentab_2025'!$C$3:$C$122,11,'90_Origen_Rentab_2025'!$E$3:$E$122,"COSTOS OP") -> 392218.11 | E16: =C16-D16 -> -143429.18 | F16: =IF(C16=0,"-",E16/C16) -> -0.57650949
A17: Chile | B17: dic | C17: =SUMIFS('90_Origen_Rentab_2025'!$F$3:$F$122,'90_Origen_Rentab_2025'!$A$3:$A$122,$A17,'90_Origen_Rentab_2025'!$C$3:$C$122,12,'90_Origen_Rentab_2025'!$E$3:$E$122,"INGRESOS OP") -> 173207.55 | D17: =SUMIFS('90_Origen_Rentab_2025'!$F$3:$F$122,'90_Origen_Rentab_2025'!$A$3:$A$122,$A17,'90_Origen_Rentab_2025'!$C$3:$C$122,12,'90_Origen_Rentab_2025'!$E$3:$E$122,"COSTOS OP") -> 495505.54 | E17: =C17-D17 -> -322297.99 | F17: =IF(C17=0,"-",E17/C17) -> -1.8607618
A18: Perú | B18: ene | C18: =SUMIFS('90_Origen_Rentab_2025'!$F$3:$F$122,'90_Origen_Rentab_2025'!$A$3:$A$122,$A18,'90_Origen_Rentab_2025'!$C$3:$C$122,1,'90_Origen_Rentab_2025'!$E$3:$E$122,"INGRESOS OP") -> 123848 | D18: =SUMIFS('90_Origen_Rentab_2025'!$F$3:$F$122,'90_Origen_Rentab_2025'!$A$3:$A$122,$A18,'90_Origen_Rentab_2025'!$C$3:$C$122,1,'90_Origen_Rentab_2025'!$E$3:$E$122,"COSTOS OP") -> 89462.85 | E18: =C18-D18 -> 34385.15 | F18: =IF(C18=0,"-",E18/C18) -> 0.27763993
A19: Perú | B19: feb | C19: =SUMIFS('90_Origen_Rentab_2025'!$F$3:$F$122,'90_Origen_Rentab_2025'!$A$3:$A$122,$A19,'90_Origen_Rentab_2025'!$C$3:$C$122,2,'90_Origen_Rentab_2025'!$E$3:$E$122,"INGRESOS OP") -> 62454 | D19: =SUMIFS('90_Origen_Rentab_2025'!$F$3:$F$122,'90_Origen_Rentab_2025'!$A$3:$A$122,$A19,'90_Origen_Rentab_2025'!$C$3:$C$122,2,'90_Origen_Rentab_2025'!$E$3:$E$122,"COSTOS OP") -> 81597 | E19: =C19-D19 -> -19143 | F19: =IF(C19=0,"-",E19/C19) -> -0.30651359
A20: Perú | B20: mar | C20: =SUMIFS('90_Origen_Rentab_2025'!$F$3:$F$122,'90_Origen_Rentab_2025'!$A$3:$A$122,$A20,'90_Origen_Rentab_2025'!$C$3:$C$122,3,'90_Origen_Rentab_2025'!$E$3:$E$122,"INGRESOS OP") -> 105377 | D20: =SUMIFS('90_Origen_Rentab_2025'!$F$3:$F$122,'90_Origen_Rentab_2025'!$A$3:$A$122,$A20,'90_Origen_Rentab_2025'!$C$3:$C$122,3,'90_Origen_Rentab_2025'!$E$3:$E$122,"COSTOS OP") -> 92755 | E20: =C20-D20 -> 12622 | F20: =IF(C20=0,"-",E20/C20) -> 0.11977946
A21: Perú | B21: abr | C21: =SUMIFS('90_Origen_Rentab_2025'!$F$3:$F$122,'90_Origen_Rentab_2025'!$A$3:$A$122,$A21,'90_Origen_Rentab_2025'!$C$3:$C$122,4,'90_Origen_Rentab_2025'!$E$3:$E$122,"INGRESOS OP") -> 110077 | D21: =SUMIFS('90_Origen_Rentab_2025'!$F$3:$F$122,'90_Origen_Rentab_2025'!$A$3:$A$122,$A21,'90_Origen_Rentab_2025'!$C$3:$C$122,4,'90_Origen_Rentab_2025'!$E$3:$E$122,"COSTOS OP") -> 137672.3 | E21: =C21-D21 -> -27595.3 | F21: =IF(C21=0,"-",E21/C21) -> -0.25069088
A22: Perú | B22: may | C22: =SUMIFS('90_Origen_Rentab_2025'!$F$3:$F$122,'90_Origen_Rentab_2025'!$A$3:$A$122,$A22,'90_Origen_Rentab_2025'!$C$3:$C$122,5,'90_Origen_Rentab_2025'!$E$3:$E$122,"INGRESOS OP") -> 142610 | D22: =SUMIFS('90_Origen_Rentab_2025'!$F$3:$F$122,'90_Origen_Rentab_2025'!$A$3:$A$122,$A22,'90_Origen_Rentab_2025'!$C$3:$C$122,5,'90_Origen_Rentab_2025'!$E$3:$E$122,"COSTOS OP") -> 128924 | E22: =C22-D22 -> 13686 | F22: =IF(C22=0,"-",E22/C22) -> 0.095968025
A23: Perú | B23: jun | C23: =SUMIFS('90_Origen_Rentab_2025'!$F$3:$F$122,'90_Origen_Rentab_2025'!$A$3:$A$122,$A23,'90_Origen_Rentab_2025'!$C$3:$C$122,6,'90_Origen_Rentab_2025'!$E$3:$E$122,"INGRESOS OP") -> 229588 | D23: =SUMIFS('90_Origen_Rentab_2025'!$F$3:$F$122,'90_Origen_Rentab_2025'!$A$3:$A$122,$A23,'90_Origen_Rentab_2025'!$C$3:$C$122,6,'90_Origen_Rentab_2025'!$E$3:$E$122,"COSTOS OP") -> 167995 | E23: =C23-D23 -> 61593 | F23: =IF(C23=0,"-",E23/C23) -> 0.26827622
A24: Perú | B24: jul | C24: =SUMIFS('90_Origen_Rentab_2025'!$F$3:$F$122,'90_Origen_Rentab_2025'!$A$3:$A$122,$A24,'90_Origen_Rentab_2025'!$C$3:$C$122,7,'90_Origen_Rentab_2025'!$E$3:$E$122,"INGRESOS OP") -> 251702 | D24: =SUMIFS('90_Origen_Rentab_2025'!$F$3:$F$122,'90_Origen_Rentab_2025'!$A$3:$A$122,$A24,'90_Origen_Rentab_2025'!$C$3:$C$122,7,'90_Origen_Rentab_2025'!$E$3:$E$122,"COSTOS OP") -> 199355 | E24: =C24-D24 -> 52347 | F24: =IF(C24=0,"-",E24/C24) -> 0.20797213
A25: Perú | B25: ago | C25: =SUMIFS('90_Origen_Rentab_2025'!$F$3:$F$122,'90_Origen_Rentab_2025'!$A$3:$A$122,$A25,'90_Origen_Rentab_2025'!$C$3:$C$122,8,'90_Origen_Rentab_2025'!$E$3:$E$122,"INGRESOS OP") -> 641573 | D25: =SUMIFS('90_Origen_Rentab_2025'!$F$3:$F$122,'90_Origen_Rentab_2025'!$A$3:$A$122,$A25,'90_Origen_Rentab_2025'!$C$3:$C$122,8,'90_Origen_Rentab_2025'!$E$3:$E$122,"COSTOS OP") -> 225572 | E25: =C25-D25 -> 416001 | F25: =IF(C25=0,"-",E25/C25) -> 0.6484079
A26: Perú | B26: sep | C26: =SUMIFS('90_Origen_Rentab_2025'!$F$3:$F$122,'90_Origen_Rentab_2025'!$A$3:$A$122,$A26,'90_Origen_Rentab_2025'!$C$3:$C$122,9,'90_Origen_Rentab_2025'!$E$3:$E$122,"INGRESOS OP") -> 119133 | D26: =SUMIFS('90_Origen_Rentab_2025'!$F$3:$F$122,'90_Origen_Rentab_2025'!$A$3:$A$122,$A26,'90_Origen_Rentab_2025'!$C$3:$C$122,9,'90_Origen_Rentab_2025'!$E$3:$E$122,"COSTOS OP") -> 127097 | E26: =C26-D26 -> -7964 | F26: =IF(C26=0,"-",E26/C26) -> -0.066849655
A27: Perú | B27: oct | C27: =SUMIFS('90_Origen_Rentab_2025'!$F$3:$F$122,'90_Origen_Rentab_2025'!$A$3:$A$122,$A27,'90_Origen_Rentab_2025'!$C$3:$C$122,10,'90_Origen_Rentab_2025'!$E$3:$E$122,"INGRESOS OP") -> 265449 | D27: =SUMIFS('90_Origen_Rentab_2025'!$F$3:$F$122,'90_Origen_Rentab_2025'!$A$3:$A$122,$A27,'90_Origen_Rentab_2025'!$C$3:$C$122,10,'90_Origen_Rentab_2025'!$E$3:$E$122,"COSTOS OP") -> 108174 | E27: =C27-D27 -> 157275 | F27: =IF(C27=0,"-",E27/C27) -> 0.59248669
A28: Perú | B28: nov | C28: =SUMIFS('90_Origen_Rentab_2025'!$F$3:$F$122,'90_Origen_Rentab_2025'!$A$3:$A$122,$A28,'90_Origen_Rentab_2025'!$C$3:$C$122,11,'90_Origen_Rentab_2025'!$E$3:$E$122,"INGRESOS OP") -> 96110 | D28: =SUMIFS('90_Origen_Rentab_2025'!$F$3:$F$122,'90_Origen_Rentab_2025'!$A$3:$A$122,$A28,'90_Origen_Rentab_2025'!$C$3:$C$122,11,'90_Origen_Rentab_2025'!$E$3:$E$122,"COSTOS OP") -> 139137.64 | E28: =C28-D28 -> -43027.64 | F28: =IF(C28=0,"-",E28/C28) -> -0.4476916
A29: Perú | B29: dic | C29: =SUMIFS('90_Origen_Rentab_2025'!$F$3:$F$122,'90_Origen_Rentab_2025'!$A$3:$A$122,$A29,'90_Origen_Rentab_2025'!$C$3:$C$122,12,'90_Origen_Rentab_2025'!$E$3:$E$122,"INGRESOS OP") -> 269432 | D29: =SUMIFS('90_Origen_Rentab_2025'!$F$3:$F$122,'90_Origen_Rentab_2025'!$A$3:$A$122,$A29,'90_Origen_Rentab_2025'!$C$3:$C$122,12,'90_Origen_Rentab_2025'!$E$3:$E$122,"COSTOS OP") -> 234121 | E29: =C29-D29 -> 35311 | F29: =IF(C29=0,"-",E29/C29) -> 0.13105719
A30: Brasil | B30: ene | C30: =SUMIFS('90_Origen_Rentab_2025'!$F$3:$F$122,'90_Origen_Rentab_2025'!$A$3:$A$122,$A30,'90_Origen_Rentab_2025'!$C$3:$C$122,1,'90_Origen_Rentab_2025'!$E$3:$E$122,"INGRESOS OP") -> 80502 | D30: =SUMIFS('90_Origen_Rentab_2025'!$F$3:$F$122,'90_Origen_Rentab_2025'!$A$3:$A$122,$A30,'90_Origen_Rentab_2025'!$C$3:$C$122,1,'90_Origen_Rentab_2025'!$E$3:$E$122,"COSTOS OP") -> 21023 | E30: =C30-D30 -> 59479 | F30: =IF(C30=0,"-",E30/C30) -> 0.73885121
A31: Brasil | B31: feb | C31: =SUMIFS('90_Origen_Rentab_2025'!$F$3:$F$122,'90_Origen_Rentab_2025'!$A$3:$A$122,$A31,'90_Origen_Rentab_2025'!$C$3:$C$122,2,'90_Origen_Rentab_2025'!$E$3:$E$122,"INGRESOS OP") -> 59683 | D31: =SUMIFS('90_Origen_Rentab_2025'!$F$3:$F$122,'90_Origen_Rentab_2025'!$A$3:$A$122,$A31,'90_Origen_Rentab_2025'!$C$3:$C$122,2,'90_Origen_Rentab_2025'!$E$3:$E$122,"COSTOS OP") -> 27812 | E31: =C31-D31 -> 31871 | F31: =IF(C31=0,"-",E31/C31) -> 0.53400466
A32: Brasil | B32: mar | C32: =SUMIFS('90_Origen_Rentab_2025'!$F$3:$F$122,'90_Origen_Rentab_2025'!$A$3:$A$122,$A32,'90_Origen_Rentab_2025'!$C$3:$C$122,3,'90_Origen_Rentab_2025'!$E$3:$E$122,"INGRESOS OP") -> 96322 | D32: =SUMIFS('90_Origen_Rentab_2025'!$F$3:$F$122,'90_Origen_Rentab_2025'!$A$3:$A$122,$A32,'90_Origen_Rentab_2025'!$C$3:$C$122,3,'90_Origen_Rentab_2025'!$E$3:$E$122,"COSTOS OP") -> 26425 | E32: =C32-D32 -> 69897 | F32: =IF(C32=0,"-",E32/C32) -> 0.72565977
A33: Brasil | B33: abr | C33: =SUMIFS('90_Origen_Rentab_2025'!$F$3:$F$122,'90_Origen_Rentab_2025'!$A$3:$A$122,$A33,'90_Origen_Rentab_2025'!$C$3:$C$122,4,'90_Origen_Rentab_2025'!$E$3:$E$122,"INGRESOS OP") -> 97209.7 | D33: =SUMIFS('90_Origen_Rentab_2025'!$F$3:$F$122,'90_Origen_Rentab_2025'!$A$3:$A$122,$A33,'90_Origen_Rentab_2025'!$C$3:$C$122,4,'90_Origen_Rentab_2025'!$E$3:$E$122,"COSTOS OP") -> 52004.4 | E33: =C33-D33 -> 45205.3 | F33: =IF(C33=0,"-",E33/C33) -> 0.4650287
A34: Brasil | B34: may | C34: =SUMIFS('90_Origen_Rentab_2025'!$F$3:$F$122,'90_Origen_Rentab_2025'!$A$3:$A$122,$A34,'90_Origen_Rentab_2025'!$C$3:$C$122,5,'90_Origen_Rentab_2025'!$E$3:$E$122,"INGRESOS OP") -> 37074 | D34: =SUMIFS('90_Origen_Rentab_2025'!$F$3:$F$122,'90_Origen_Rentab_2025'!$A$3:$A$122,$A34,'90_Origen_Rentab_2025'!$C$3:$C$122,5,'90_Origen_Rentab_2025'!$E$3:$E$122,"COSTOS OP") -> 33329 | E34: =C34-D34 -> 3745 | F34: =IF(C34=0,"-",E34/C34) -> 0.10101419
A35: Brasil | B35: jun | C35: =SUMIFS('90_Origen_Rentab_2025'!$F$3:$F$122,'90_Origen_Rentab_2025'!$A$3:$A$122,$A35,'90_Origen_Rentab_2025'!$C$3:$C$122,6,'90_Origen_Rentab_2025'!$E$3:$E$122,"INGRESOS OP") -> 66563 | D35: =SUMIFS('90_Origen_Rentab_2025'!$F$3:$F$122,'90_Origen_Rentab_2025'!$A$3:$A$122,$A35,'90_Origen_Rentab_2025'!$C$3:$C$122,6,'90_Origen_Rentab_2025'!$E$3:$E$122,"COSTOS OP") -> 76286 | E35: =C35-D35 -> -9723 | F35: =IF(C35=0,"-",E35/C35) -> -0.14607214
A36: Brasil | B36: jul | C36: =SUMIFS('90_Origen_Rentab_2025'!$F$3:$F$122,'90_Origen_Rentab_2025'!$A$3:$A$122,$A36,'90_Origen_Rentab_2025'!$C$3:$C$122,7,'90_Origen_Rentab_2025'!$E$3:$E$122,"INGRESOS OP") -> 47717 | D36: =SUMIFS('90_Origen_Rentab_2025'!$F$3:$F$122,'90_Origen_Rentab_2025'!$A$3:$A$122,$A36,'90_Origen_Rentab_2025'!$C$3:$C$122,7,'90_Origen_Rentab_2025'!$E$3:$E$122,"COSTOS OP") -> 31019 | E36: =C36-D36 -> 16698 | F36: =IF(C36=0,"-",E36/C36) -> 0.34993818
A37: Brasil | B37: ago | C37: =SUMIFS('90_Origen_Rentab_2025'!$F$3:$F$122,'90_Origen_Rentab_2025'!$A$3:$A$122,$A37,'90_Origen_Rentab_2025'!$C$3:$C$122,8,'90_Origen_Rentab_2025'!$E$3:$E$122,"INGRESOS OP") -> 119652 | D37: =SUMIFS('90_Origen_Rentab_2025'!$F$3:$F$122,'90_Origen_Rentab_2025'!$A$3:$A$122,$A37,'90_Origen_Rentab_2025'!$C$3:$C$122,8,'90_Origen_Rentab_2025'!$E$3:$E$122,"COSTOS OP") -> 21475 | E37: =C37-D37 -> 98177 | F37: =IF(C37=0,"-",E37/C37) -> 0.82052118
A38: Brasil | B38: sep | C38: =SUMIFS('90_Origen_Rentab_2025'!$F$3:$F$122,'90_Origen_Rentab_2025'!$A$3:$A$122,$A38,'90_Origen_Rentab_2025'!$C$3:$C$122,9,'90_Origen_Rentab_2025'!$E$3:$E$122,"INGRESOS OP") -> 203588 | D38: =SUMIFS('90_Origen_Rentab_2025'!$F$3:$F$122,'90_Origen_Rentab_2025'!$A$3:$A$122,$A38,'90_Origen_Rentab_2025'!$C$3:$C$122,9,'90_Origen_Rentab_2025'!$E$3:$E$122,"COSTOS OP") -> 77323 | E38: =C38-D38 -> 126265 | F38: =IF(C38=0,"-",E38/C38) -> 0.62019864
A39: Brasil | B39: oct | C39: =SUMIFS('90_Origen_Rentab_2025'!$F$3:$F$122,'90_Origen_Rentab_2025'!$A$3:$A$122,$A39,'90_Origen_Rentab_2025'!$C$3:$C$122,10,'90_Origen_Rentab_2025'!$E$3:$E$122,"INGRESOS OP") -> 325062 | D39: =SUMIFS('90_Origen_Rentab_2025'!$F$3:$F$122,'90_Origen_Rentab_2025'!$A$3:$A$122,$A39,'90_Origen_Rentab_2025'!$C$3:$C$122,10,'90_Origen_Rentab_2025'!$E$3:$E$122,"COSTOS OP") -> 14049 | E39: =C39-D39 -> 311013 | F39: =IF(C39=0,"-",E39/C39) -> 0.95678055
A40: Brasil | B40: nov | C40: =SUMIFS('90_Origen_Rentab_2025'!$F$3:$F$122,'90_Origen_Rentab_2025'!$A$3:$A$122,$A40,'90_Origen_Rentab_2025'!$C$3:$C$122,11,'90_Origen_Rentab_2025'!$E$3:$E$122,"INGRESOS OP") -> 239603 | D40: =SUMIFS('90_Origen_Rentab_2025'!$F$3:$F$122,'90_Origen_Rentab_2025'!$A$3:$A$122,$A40,'90_Origen_Rentab_2025'!$C$3:$C$122,11,'90_Origen_Rentab_2025'!$E$3:$E$122,"COSTOS OP") -> 47971 | E40: =C40-D40 -> 191632 | F40: =IF(C40=0,"-",E40/C40) -> 0.79978965
A41: Brasil | B41: dic | C41: =SUMIFS('90_Origen_Rentab_2025'!$F$3:$F$122,'90_Origen_Rentab_2025'!$A$3:$A$122,$A41,'90_Origen_Rentab_2025'!$C$3:$C$122,12,'90_Origen_Rentab_2025'!$E$3:$E$122,"INGRESOS OP") -> 224116.51 | D41: =SUMIFS('90_Origen_Rentab_2025'!$F$3:$F$122,'90_Origen_Rentab_2025'!$A$3:$A$122,$A41,'90_Origen_Rentab_2025'!$C$3:$C$122,12,'90_Origen_Rentab_2025'!$E$3:$E$122,"COSTOS OP") -> 23001 | E41: =C41-D41 -> 201115.51 | F41: =IF(C41=0,"-",E41/C41) -> 0.89737035
...

Sheet 02_Ventas_2023_2025
A1: ENTREGABLE 2 · Ventas por país y cliente (2023→2026 parcial)
A2: Definición de VENTA = 'Emitido USD' (devengo real del EDP). 'Proyectado USD' se descarta como principal (=0 en 2025). Contraste: Proyectado / Ingresado.
A4: A) Venta (Emitido USD) por País × Cliente × Año — top 10 clientes por país + resto
A5: País | B5: Cliente | C5: 2023 | D5: 2024 | E5: 2025 | F5: 2026 (parc.) | G5: Total 23-26 | H5: % país
A6: Chile | B6: CMP | C6: =SUMIFS('90_Origen_Ledger_EdP'!$K$3:$K$702,'90_Origen_Ledger_EdP'!$F$3:$F$702,$A6,'90_Origen_Ledger_EdP'!$E$3:$E$702,$B6,'90_Origen_Ledger_EdP'!$G$3:$G$702,2023) -> 2283982.6 | D6: =SUMIFS('90_Origen_Ledger_EdP'!$K$3:$K$702,'90_Origen_Ledger_EdP'!$F$3:$F$702,$A6,'90_Origen_Ledger_EdP'!$E$3:$E$702,$B6,'90_Origen_Ledger_EdP'!$G$3:$G$702,2024) -> 1652260.5 | E6: =SUMIFS('90_Origen_Ledger_EdP'!$K$3:$K$702,'90_Origen_Ledger_EdP'!$F$3:$F$702,$A6,'90_Origen_Ledger_EdP'!$E$3:$E$702,$B6,'90_Origen_Ledger_EdP'!$G$3:$G$702,2025) -> 423425 | F6: =SUMIFS('90_Origen_Ledger_EdP'!$K$3:$K$702,'90_Origen_Ledger_EdP'!$F$3:$F$702,$A6,'90_Origen_Ledger_EdP'!$E$3:$E$702,$B6,'90_Origen_Ledger_EdP'!$G$3:$G$702,2026) -> 0 | G6: =SUM(C6:F6) -> 4359668.1 | H6: =IF($G$17=0,"-",G6/$G$17) -> 0.36297503
A7: Chile | B7: AMSA | C7: =SUMIFS('90_Origen_Ledger_EdP'!$K$3:$K$702,'90_Origen_Ledger_EdP'!$F$3:$F$702,$A7,'90_Origen_Ledger_EdP'!$E$3:$E$702,$B7,'90_Origen_Ledger_EdP'!$G$3:$G$702,2023) -> 765922.76 | D7: =SUMIFS('90_Origen_Ledger_EdP'!$K$3:$K$702,'90_Origen_Ledger_EdP'!$F$3:$F$702,$A7,'90_Origen_Ledger_EdP'!$E$3:$E$702,$B7,'90_Origen_Ledger_EdP'!$G$3:$G$702,2024) -> 390618 | E7: =SUMIFS('90_Origen_Ledger_EdP'!$K$3:$K$702,'90_Origen_Ledger_EdP'!$F$3:$F$702,$A7,'90_Origen_Ledger_EdP'!$E$3:$E$702,$B7,'90_Origen_Ledger_EdP'!$G$3:$G$702,2025) -> 375534.67 | F7: =SUMIFS('90_Origen_Ledger_EdP'!$K$3:$K$702,'90_Origen_Ledger_EdP'!$F$3:$F$702,$A7,'90_Origen_Ledger_EdP'!$E$3:$E$702,$B7,'90_Origen_Ledger_EdP'!$G$3:$G$702,2026) -> 23913 | G7: =SUM(C7:F7) -> 1555988.4 | H7: =IF($G$17=0,"-",G7/$G$17) -> 0.12954769
A8: Chile | B8: BHP | C8: =SUMIFS('90_Origen_Ledger_EdP'!$K$3:$K$702,'90_Origen_Ledger_EdP'!$F$3:$F$702,$A8,'90_Origen_Ledger_EdP'!$E$3:$E$702,$B8,'90_Origen_Ledger_EdP'!$G$3:$G$702,2023) -> 50688.323 | D8: =SUMIFS('90_Origen_Ledger_EdP'!$K$3:$K$702,'90_Origen_Ledger_EdP'!$F$3:$F$702,$A8,'90_Origen_Ledger_EdP'!$E$3:$E$702,$B8,'90_Origen_Ledger_EdP'!$G$3:$G$702,2024) -> 116314 | E8: =SUMIFS('90_Origen_Ledger_EdP'!$K$3:$K$702,'90_Origen_Ledger_EdP'!$F$3:$F$702,$A8,'90_Origen_Ledger_EdP'!$E$3:$E$702,$B8,'90_Origen_Ledger_EdP'!$G$3:$G$702,2025) -> 1153726.4 | F8: =SUMIFS('90_Origen_Ledger_EdP'!$K$3:$K$702,'90_Origen_Ledger_EdP'!$F$3:$F$702,$A8,'90_Origen_Ledger_EdP'!$E$3:$E$702,$B8,'90_Origen_Ledger_EdP'!$G$3:$G$702,2026) -> 0 | G8: =SUM(C8:F8) -> 1320728.8 | H8: =IF($G$17=0,"-",G8/$G$17) -> 0.10996056
A9: Chile | B9: Codelco | C9: =SUMIFS('90_Origen_Ledger_EdP'!$K$3:$K$702,'90_Origen_Ledger_EdP'!$F$3:$F$702,$A9,'90_Origen_Ledger_EdP'!$E$3:$E$702,$B9,'90_Origen_Ledger_EdP'!$G$3:$G$702,2023) -> 349598 | D9: =SUMIFS('90_Origen_Ledger_EdP'!$K$3:$K$702,'90_Origen_Ledger_EdP'!$F$3:$F$702,$A9,'90_Origen_Ledger_EdP'!$E$3:$E$702,$B9,'90_Origen_Ledger_EdP'!$G$3:$G$702,2024) -> 289901 | E9: =SUMIFS('90_Origen_Ledger_EdP'!$K$3:$K$702,'90_Origen_Ledger_EdP'!$F$3:$F$702,$A9,'90_Origen_Ledger_EdP'!$E$3:$E$702,$B9,'90_Origen_Ledger_EdP'!$G$3:$G$702,2025) -> 125926.75 | F9: =SUMIFS('90_Origen_Ledger_EdP'!$K$3:$K$702,'90_Origen_Ledger_EdP'!$F$3:$F$702,$A9,'90_Origen_Ledger_EdP'!$E$3:$E$702,$B9,'90_Origen_Ledger_EdP'!$G$3:$G$702,2026) -> 292487 | G9: =SUM(C9:F9) -> 1057912.8 | H9: =IF($G$17=0,"-",G9/$G$17) -> 0.088079162
A10: Chile | B10: Lundin | C10: =SUMIFS('90_Origen_Ledger_EdP'!$K$3:$K$702,'90_Origen_Ledger_EdP'!$F$3:$F$702,$A10,'90_Origen_Ledger_EdP'!$E$3:$E$702,$B10,'90_Origen_Ledger_EdP'!$G$3:$G$702,2023) -> 390540.16 | D10: =SUMIFS('90_Origen_Ledger_EdP'!$K$3:$K$702,'90_Origen_Ledger_EdP'!$F$3:$F$702,$A10,'90_Origen_Ledger_EdP'!$E$3:$E$702,$B10,'90_Origen_Ledger_EdP'!$G$3:$G$702,2024) -> 313105.94 | E10: =SUMIFS('90_Origen_Ledger_EdP'!$K$3:$K$702,'90_Origen_Ledger_EdP'!$F$3:$F$702,$A10,'90_Origen_Ledger_EdP'!$E$3:$E$702,$B10,'90_Origen_Ledger_EdP'!$G$3:$G$702,2025) -> 299270 | F10: =SUMIFS('90_Origen_Ledger_EdP'!$K$3:$K$702,'90_Origen_Ledger_EdP'!$F$3:$F$702,$A10,'90_Origen_Ledger_EdP'!$E$3:$E$702,$B10,'90_Origen_Ledger_EdP'!$G$3:$G$702,2026) -> 0 | G10: =SUM(C10:F10) -> 1002916.1 | H10: =IF($G$17=0,"-",G10/$G$17) -> 0.083500278
A11: Chile | B11: Glencore | C11: =SUMIFS('90_Origen_Ledger_EdP'!$K$3:$K$702,'90_Origen_Ledger_EdP'!$F$3:$F$702,$A11,'90_Origen_Ledger_EdP'!$E$3:$E$702,$B11,'90_Origen_Ledger_EdP'!$G$3:$G$702,2023) -> 258540.53 | D11: =SUMIFS('90_Origen_Ledger_EdP'!$K$3:$K$702,'90_Origen_Ledger_EdP'!$F$3:$F$702,$A11,'90_Origen_Ledger_EdP'!$E$3:$E$702,$B11,'90_Origen_Ledger_EdP'!$G$3:$G$702,2024) -> 0 | E11: =SUMIFS('90_Origen_Ledger_EdP'!$K$3:$K$702,'90_Origen_Ledger_EdP'!$F$3:$F$702,$A11,'90_Origen_Ledger_EdP'!$E$3:$E$702,$B11,'90_Origen_Ledger_EdP'!$G$3:$G$702,2025) -> 198640 | F11: =SUMIFS('90_Origen_Ledger_EdP'!$K$3:$K$702,'90_Origen_Ledger_EdP'!$F$3:$F$702,$A11,'90_Origen_Ledger_EdP'!$E$3:$E$702,$B11,'90_Origen_Ledger_EdP'!$G$3:$G$702,2026) -> 186828 | G11: =SUM(C11:F11) -> 644008.53 | H11: =IF($G$17=0,"-",G11/$G$17) -> 0.053618535
A12: Chile | B12: Capstone Copper | C12: =SUMIFS('90_Origen_Ledger_EdP'!$K$3:$K$702,'90_Origen_Ledger_EdP'!$F$3:$F$702,$A12,'90_Origen_Ledger_EdP'!$E$3:$E$702,$B12,'90_Origen_Ledger_EdP'!$G$3:$G$702,2023) -> 0 | D12: =SUMIFS('90_Origen_Ledger_EdP'!$K$3:$K$702,'90_Origen_Ledger_EdP'!$F$3:$F$702,$A12,'90_Origen_Ledger_EdP'!$E$3:$E$702,$B12,'90_Origen_Ledger_EdP'!$G$3:$G$702,2024) -> 354849 | E12: =SUMIFS('90_Origen_Ledger_EdP'!$K$3:$K$702,'90_Origen_Ledger_EdP'!$F$3:$F$702,$A12,'90_Origen_Ledger_EdP'!$E$3:$E$702,$B12,'90_Origen_Ledger_EdP'!$G$3:$G$702,2025) -> 184058 | F12: =SUMIFS('90_Origen_Ledger_EdP'!$K$3:$K$702,'90_Origen_Ledger_EdP'!$F$3:$F$702,$A12,'90_Origen_Ledger_EdP'!$E$3:$E$702,$B12,'90_Origen_Ledger_EdP'!$G$3:$G$702,2026) -> 0 | G12: =SUM(C12:F12) -> 538907 | H12: =IF($G$17=0,"-",G12/$G$17) -> 0.044868045
A13: Chile | B13: AngloAmerican | C13: =SUMIFS('90_Origen_Ledger_EdP'!$K$3:$K$702,'90_Origen_Ledger_EdP'!$F$3:$F$702,$A13,'90_Origen_Ledger_EdP'!$E$3:$E$702,$B13,'90_Origen_Ledger_EdP'!$G$3:$G$702,2023) -> 0 | D13: =SUMIFS('90_Origen_Ledger_EdP'!$K$3:$K$702,'90_Origen_Ledger_EdP'!$F$3:$F$702,$A13,'90_Origen_Ledger_EdP'!$E$3:$E$702,$B13,'90_Origen_Ledger_EdP'!$G$3:$G$702,2024) -> 0 | E13: =SUMIFS('90_Origen_Ledger_EdP'!$K$3:$K$702,'90_Origen_Ledger_EdP'!$F$3:$F$702,$A13,'90_Origen_Ledger_EdP'!$E$3:$E$702,$B13,'90_Origen_Ledger_EdP'!$G$3:$G$702,2025) -> 340671.33 | F13: =SUMIFS('90_Origen_Ledger_EdP'!$K$3:$K$702,'90_Origen_Ledger_EdP'!$F$3:$F$702,$A13,'90_Origen_Ledger_EdP'!$E$3:$E$702,$B13,'90_Origen_Ledger_EdP'!$G$3:$G$702,2026) -> 0 | G13: =SUM(C13:F13) -> 340671.33 | H13: =IF($G$17=0,"-",G13/$G$17) -> 0.02836344
A14: Chile | B14: Mitsubichi | C14: =SUMIFS('90_Origen_Ledger_EdP'!$K$3:$K$702,'90_Origen_Ledger_EdP'!$F$3:$F$702,$A14,'90_Origen_Ledger_EdP'!$E$3:$E$702,$B14,'90_Origen_Ledger_EdP'!$G$3:$G$702,2023) -> 0 | D14: =SUMIFS('90_Origen_Ledger_EdP'!$K$3:$K$702,'90_Origen_Ledger_EdP'!$F$3:$F$702,$A14,'90_Origen_Ledger_EdP'!$E$3:$E$702,$B14,'90_Origen_Ledger_EdP'!$G$3:$G$702,2024) -> 215280 | E14: =SUMIFS('90_Origen_Ledger_EdP'!$K$3:$K$702,'90_Origen_Ledger_EdP'!$F$3:$F$702,$A14,'90_Origen_Ledger_EdP'!$E$3:$E$702,$B14,'90_Origen_Ledger_EdP'!$G$3:$G$702,2025) -> 23720 | F14: =SUMIFS('90_Origen_Ledger_EdP'!$K$3:$K$702,'90_Origen_Ledger_EdP'!$F$3:$F$702,$A14,'90_Origen_Ledger_EdP'!$E$3:$E$702,$B14,'90_Origen_Ledger_EdP'!$G$3:$G$702,2026) -> 0 | G14: =SUM(C14:F14) -> 239000 | H14: =IF($G$17=0,"-",G14/$G$17) -> 0.01989854
A15: Chile | B15: MEL | C15: =SUMIFS('90_Origen_Ledger_EdP'!$K$3:$K$702,'90_Origen_Ledger_EdP'!$F$3:$F$702,$A15,'90_Origen_Ledger_EdP'!$E$3:$E$702,$B15,'90_Origen_Ledger_EdP'!$G$3:$G$702,2023) -> 150618.18 | D15: =SUMIFS('90_Origen_Ledger_EdP'!$K$3:$K$702,'90_Origen_Ledger_EdP'!$F$3:$F$702,$A15,'90_Origen_Ledger_EdP'!$E$3:$E$702,$B15,'90_Origen_Ledger_EdP'!$G$3:$G$702,2024) -> 0 | E15: =SUMIFS('90_Origen_Ledger_EdP'!$K$3:$K$702,'90_Origen_Ledger_EdP'!$F$3:$F$702,$A15,'90_Origen_Ledger_EdP'!$E$3:$E$702,$B15,'90_Origen_Ledger_EdP'!$G$3:$G$702,2025) -> 0 | F15: =SUMIFS('90_Origen_Ledger_EdP'!$K$3:$K$702,'90_Origen_Ledger_EdP'!$F$3:$F$702,$A15,'90_Origen_Ledger_EdP'!$E$3:$E$702,$B15,'90_Origen_Ledger_EdP'!$G$3:$G$702,2026) -> 0 | G15: =SUM(C15:F15) -> 150618.18 | H15: =IF($G$17=0,"-",G15/$G$17) -> 0.012540092
A16: Chile | B16: Otros clientes (resto) | C16: =SUMIFS('90_Origen_Ledger_EdP'!$K$3:$K$702,'90_Origen_Ledger_EdP'!$F$3:$F$702,$A16,'90_Origen_Ledger_EdP'!$G$3:$G$702,2023)-SUM(C6:C15) -> 42285 | D16: =SUMIFS('90_Origen_Ledger_EdP'!$K$3:$K$702,'90_Origen_Ledger_EdP'!$F$3:$F$702,$A16,'90_Origen_Ledger_EdP'!$G$3:$G$702,2024)-SUM(D6:D15) -> 190031 | E16: =SUMIFS('90_Origen_Ledger_EdP'!$K$3:$K$702,'90_Origen_Ledger_EdP'!$F$3:$F$702,$A16,'90_Origen_Ledger_EdP'!$G$3:$G$702,2025)-SUM(E6:E15) -> 128461 | F16: =SUMIFS('90_Origen_Ledger_EdP'!$K$3:$K$702,'90_Origen_Ledger_EdP'!$F$3:$F$702,$A16,'90_Origen_Ledger_EdP'!$G$3:$G$702,2026)-SUM(F6:F15) -> 439735 | G16: =SUM(C16:F16) -> 800512 | H16: =IF($G$17=0,"-",G16/$G$17) -> 0.066648621
A17: Chile | B17: TOTAL Chile | C17: =SUM(C6:C16) -> 4292175.5 | D17: =SUM(D6:D16) -> 3522359.5 | E17: =SUM(E6:E16) -> 3253433.2 | F17: =SUM(F6:F16) -> 942963 | G17: =SUM(C17:F17) -> 12010931 | H17: 1
A18: Perú | B18: Minsur | C18: =SUMIFS('90_Origen_Ledger_EdP'!$K$3:$K$702,'90_Origen_Ledger_EdP'!$F$3:$F$702,$A18,'90_Origen_Ledger_EdP'!$E$3:$E$702,$B18,'90_Origen_Ledger_EdP'!$G$3:$G$702,2023) -> 933597.6 | D18: =SUMIFS('90_Origen_Ledger_EdP'!$K$3:$K$702,'90_Origen_Ledger_EdP'!$F$3:$F$702,$A18,'90_Origen_Ledger_EdP'!$E$3:$E$702,$B18,'90_Origen_Ledger_EdP'!$G$3:$G$702,2024) -> 405659.87 | E18: =SUMIFS('90_Origen_Ledger_EdP'!$K$3:$K$702,'90_Origen_Ledger_EdP'!$F$3:$F$702,$A18,'90_Origen_Ledger_EdP'!$E$3:$E$702,$B18,'90_Origen_Ledger_EdP'!$G$3:$G$702,2025) -> 356402 | F18: =SUMIFS('90_Origen_Ledger_EdP'!$K$3:$K$702,'90_Origen_Ledger_EdP'!$F$3:$F$702,$A18,'90_Origen_Ledger_EdP'!$E$3:$E$702,$B18,'90_Origen_Ledger_EdP'!$G$3:$G$702,2026) -> 50798 | G18: =SUM(C18:F18) -> 1746457.5 | H18: =IF($G$29=0,"-",G18/$G$29) -> 0.24832541
A19: Perú | B19: CD Capitals | C19: =SUMIFS('90_Origen_Ledger_EdP'!$K$3:$K$702,'90_Origen_Ledger_EdP'!$F$3:$F$702,$A19,'90_Origen_Ledger_EdP'!$E$3:$E$702,$B19,'90_Origen_Ledger_EdP'!$G$3:$G$702,2023) -> 221948.28 | D19: =SUMIFS('90_Origen_Ledger_EdP'!$K$3:$K$702,'90_Origen_Ledger_EdP'!$F$3:$F$702,$A19,'90_Origen_Ledger_EdP'!$E$3:$E$702,$B19,'90_Origen_Ledger_EdP'!$G$3:$G$702,2024) -> 817713 | E19: =SUMIFS('90_Origen_Ledger_EdP'!$K$3:$K$702,'90_Origen_Ledger_EdP'!$F$3:$F$702,$A19,'90_Origen_Ledger_EdP'!$E$3:$E$702,$B19,'90_Origen_Ledger_EdP'!$G$3:$G$702,2025) -> 336554 | F19: =SUMIFS('90_Origen_Ledger_EdP'!$K$3:$K$702,'90_Origen_Ledger_EdP'!$F$3:$F$702,$A19,'90_Origen_Ledger_EdP'!$E$3:$E$702,$B19,'90_Origen_Ledger_EdP'!$G$3:$G$702,2026) -> 86140 | G19: =SUM(C19:F19) -> 1462355.3 | H19: =IF($G$29=0,"-",G19/$G$29) -> 0.20792947
A20: Perú | B20: Las Bambas | C20: =SUMIFS('90_Origen_Ledger_EdP'!$K$3:$K$702,'90_Origen_Ledger_EdP'!$F$3:$F$702,$A20,'90_Origen_Ledger_EdP'!$E$3:$E$702,$B20,'90_Origen_Ledger_EdP'!$G$3:$G$702,2023) -> 40394 | D20: =SUMIFS('90_Origen_Ledger_EdP'!$K$3:$K$702,'90_Origen_Ledger_EdP'!$F$3:$F$702,$A20,'90_Origen_Ledger_EdP'!$E$3:$E$702,$B20,'90_Origen_Ledger_EdP'!$G$3:$G$702,2024) -> 189557 | E20: =SUMIFS('90_Origen_Ledger_EdP'!$K$3:$K$702,'90_Origen_Ledger_EdP'!$F$3:$F$702,$A20,'90_Origen_Ledger_EdP'!$E$3:$E$702,$B20,'90_Origen_Ledger_EdP'!$G$3:$G$702,2025) -> 1085729.6 | F20: =SUMIFS('90_Origen_Ledger_EdP'!$K$3:$K$702,'90_Origen_Ledger_EdP'!$F$3:$F$702,$A20,'90_Origen_Ledger_EdP'!$E$3:$E$702,$B20,'90_Origen_Ledger_EdP'!$G$3:$G$702,2026) -> 0 | G20: =SUM(C20:F20) -> 1315680.6 | H20: =IF($G$29=0,"-",G20/$G$29) -> 0.18707408
A21: Perú | B21: Marcobre | C21: =SUMIFS('90_Origen_Ledger_EdP'!$K$3:$K$702,'90_Origen_Ledger_EdP'!$F$3:$F$702,$A21,'90_Origen_Ledger_EdP'!$E$3:$E$702,$B21,'90_Origen_Ledger_EdP'!$G$3:$G$702,2023) -> 137832 | D21: =SUMIFS('90_Origen_Ledger_EdP'!$K$3:$K$702,'90_Origen_Ledger_EdP'!$F$3:$F$702,$A21,'90_Origen_Ledger_EdP'!$E$3:$E$702,$B21,'90_Origen_Ledger_EdP'!$G$3:$G$702,2024) -> 73833 | E21: =SUMIFS('90_Origen_Ledger_EdP'!$K$3:$K$702,'90_Origen_Ledger_EdP'!$F$3:$F$702,$A21,'90_Origen_Ledger_EdP'!$E$3:$E$702,$B21,'90_Origen_Ledger_EdP'!$G$3:$G$702,2025) -> 87945 | F21: =SUMIFS('90_Origen_Ledger_EdP'!$K$3:$K$702,'90_Origen_Ledger_EdP'!$F$3:$F$702,$A21,'90_Origen_Ledger_EdP'!$E$3:$E$702,$B21,'90_Origen_Ledger_EdP'!$G$3:$G$702,2026) -> 0 | G21: =SUM(C21:F21) -> 299610 | H21: =IF($G$29=0,"-",G21/$G$29) -> 0.042600967
A22: Perú | B22: Sierra metals | C22: =SUMIFS('90_Origen_Ledger_EdP'!$K$3:$K$702,'90_Origen_Ledger_EdP'!$F$3:$F$702,$A22,'90_Origen_Ledger_EdP'!$E$3:$E$702,$B22,'90_Origen_Ledger_EdP'!$G$3:$G$702,2023) -> 95353.875 | D22: =SUMIFS('90_Origen_Ledger_EdP'!$K$3:$K$702,'90_Origen_Ledger_EdP'!$F$3:$F$702,$A22,'90_Origen_Ledger_EdP'!$E$3:$E$702,$B22,'90_Origen_Ledger_EdP'!$G$3:$G$702,2024) -> 186049 | E22: =SUMIFS('90_Origen_Ledger_EdP'!$K$3:$K$702,'90_Origen_Ledger_EdP'!$F$3:$F$702,$A22,'90_Origen_Ledger_EdP'!$E$3:$E$702,$B22,'90_Origen_Ledger_EdP'!$G$3:$G$702,2025) -> 0 | F22: =SUMIFS('90_Origen_Ledger_EdP'!$K$3:$K$702,'90_Origen_Ledger_EdP'!$F$3:$F$702,$A22,'90_Origen_Ledger_EdP'!$E$3:$E$702,$B22,'90_Origen_Ledger_EdP'!$G$3:$G$702,2026) -> 0 | G22: =SUM(C22:F22) -> 281402.88 | H22: =IF($G$29=0,"-",G22/$G$29) -> 0.040012131
A23: Perú | B23: MiskiMayo | C23: =SUMIFS('90_Origen_Ledger_EdP'!$K$3:$K$702,'90_Origen_Ledger_EdP'!$F$3:$F$702,$A23,'90_Origen_Ledger_EdP'!$E$3:$E$702,$B23,'90_Origen_Ledger_EdP'!$G$3:$G$702,2023) -> 50472.9 | D23: =SUMIFS('90_Origen_Ledger_EdP'!$K$3:$K$702,'90_Origen_Ledger_EdP'!$F$3:$F$702,$A23,'90_Origen_Ledger_EdP'!$E$3:$E$702,$B23,'90_Origen_Ledger_EdP'!$G$3:$G$702,2024) -> 64663.2 | E23: =SUMIFS('90_Origen_Ledger_EdP'!$K$3:$K$702,'90_Origen_Ledger_EdP'!$F$3:$F$702,$A23,'90_Origen_Ledger_EdP'!$E$3:$E$702,$B23,'90_Origen_Ledger_EdP'!$G$3:$G$702,2025) -> 44033 | F23: =SUMIFS('90_Origen_Ledger_EdP'!$K$3:$K$702,'90_Origen_Ledger_EdP'!$F$3:$F$702,$A23,'90_Origen_Ledger_EdP'!$E$3:$E$702,$B23,'90_Origen_Ledger_EdP'!$G$3:$G$702,2026) -> 126618 | G23: =SUM(C23:F23) -> 285787.1 | H23: =IF($G$29=0,"-",G23/$G$29) -> 0.040635515
A24: Perú | B24: Glencore | C24: =SUMIFS('90_Origen_Ledger_EdP'!$K$3:$K$702,'90_Origen_Ledger_EdP'!$F$3:$F$702,$A24,'90_Origen_Ledger_EdP'!$E$3:$E$702,$B24,'90_Origen_Ledger_EdP'!$G$3:$G$702,2023) -> 0 | D24: =SUMIFS('90_Origen_Ledger_EdP'!$K$3:$K$702,'90_Origen_Ledger_EdP'!$F$3:$F$702,$A24,'90_Origen_Ledger_EdP'!$E$3:$E$702,$B24,'90_Origen_Ledger_EdP'!$G$3:$G$702,2024) -> 198000 | E24: =SUMIFS('90_Origen_Ledger_EdP'!$K$3:$K$702,'90_Origen_Ledger_EdP'!$F$3:$F$702,$A24,'90_Origen_Ledger_EdP'!$E$3:$E$702,$B24,'90_Origen_Ledger_EdP'!$G$3:$G$702,2025) -> 0 | F24: =SUMIFS('90_Origen_Ledger_EdP'!$K$3:$K$702,'90_Origen_Ledger_EdP'!$F$3:$F$702,$A24,'90_Origen_Ledger_EdP'!$E$3:$E$702,$B24,'90_Origen_Ledger_EdP'!$G$3:$G$702,2026) -> 0 | G24: =SUM(C24:F24) -> 198000 | H24: =IF($G$29=0,"-",G24/$G$29) -> 0.028153237
A25: Perú | B25: Alpayana | C25: =SUMIFS('90_Origen_Ledger_EdP'!$K$3:$K$702,'90_Origen_Ledger_EdP'!$F$3:$F$702,$A25,'90_Origen_Ledger_EdP'!$E$3:$E$702,$B25,'90_Origen_Ledger_EdP'!$G$3:$G$702,2023) -> 0 | D25: =SUMIFS('90_Origen_Ledger_EdP'!$K$3:$K$702,'90_Origen_Ledger_EdP'!$F$3:$F$702,$A25,'90_Origen_Ledger_EdP'!$E$3:$E$702,$B25,'90_Origen_Ledger_EdP'!$G$3:$G$702,2024) -> 0 | E25: =SUMIFS('90_Origen_Ledger_EdP'!$K$3:$K$702,'90_Origen_Ledger_EdP'!$F$3:$F$702,$A25,'90_Origen_Ledger_EdP'!$E$3:$E$702,$B25,'90_Origen_Ledger_EdP'!$G$3:$G$702,2025) -> 131313 | F25: =SUMIFS('90_Origen_Ledger_EdP'!$K$3:$K$702,'90_Origen_Ledger_EdP'!$F$3:$F$702,$A25,'90_Origen_Ledger_EdP'!$E$3:$E$702,$B25,'90_Origen_Ledger_EdP'!$G$3:$G$702,2026) -> 56306 | G25: =SUM(C25:F25) -> 187619 | H25: =IF($G$29=0,"-",G25/$G$29) -> 0.026677183
A26: Perú | B26: Emincar | C26: =SUMIFS('90_Origen_Ledger_EdP'!$K$3:$K$702,'90_Origen_Ledger_EdP'!$F$3:$F$702,$A26,'90_Origen_Ledger_EdP'!$E$3:$E$702,$B26,'90_Origen_Ledger_EdP'!$G$3:$G$702,2023) -> 0 | D26: =SUMIFS('90_Origen_Ledger_EdP'!$K$3:$K$702,'90_Origen_Ledger_EdP'!$F$3:$F$702,$A26,'90_Origen_Ledger_EdP'!$E$3:$E$702,$B26,'90_Origen_Ledger_EdP'!$G$3:$G$702,2024) -> 0 | E26: =SUMIFS('90_Origen_Ledger_EdP'!$K$3:$K$702,'90_Origen_Ledger_EdP'!$F$3:$F$702,$A26,'90_Origen_Ledger_EdP'!$E$3:$E$702,$B26,'90_Origen_Ledger_EdP'!$G$3:$G$702,2025) -> 0 | F26: =SUMIFS('90_Origen_Ledger_EdP'!$K$3:$K$702,'90_Origen_Ledger_EdP'!$F$3:$F$702,$A26,'90_Origen_Ledger_EdP'!$E$3:$E$702,$B26,'90_Origen_Ledger_EdP'!$G$3:$G$702,2026) -> 183496 | G26: =SUM(C26:F26) -> 183496 | H26: =IF($G$29=0,"-",G26/$G$29) -> 0.026090941
A27: Perú | B27: Raura | C27: =SUMIFS('90_Origen_Ledger_EdP'!$K$3:$K$702,'90_Origen_Ledger_EdP'!$F$3:$F$702,$A27,'90_Origen_Ledger_EdP'!$E$3:$E$702,$B27,'90_Origen_Ledger_EdP'!$G$3:$G$702,2023) -> 96638.4 | D27: =SUMIFS('90_Origen_Ledger_EdP'!$K$3:$K$702,'90_Origen_Ledger_EdP'!$F$3:$F$702,$A27,'90_Origen_Ledger_EdP'!$E$3:$E$702,$B27,'90_Origen_Ledger_EdP'!$G$3:$G$702,2024) -> 0 | E27: =SUMIFS('90_Origen_Ledger_EdP'!$K$3:$K$702,'90_Origen_Ledger_EdP'!$F$3:$F$702,$A27,'90_Origen_Ledger_EdP'!$E$3:$E$702,$B27,'90_Origen_Ledger_EdP'!$G$3:$G$702,2025) -> 0 | F27: =SUMIFS('90_Origen_Ledger_EdP'!$K$3:$K$702,'90_Origen_Ledger_EdP'!$F$3:$F$702,$A27,'90_Origen_Ledger_EdP'!$E$3:$E$702,$B27,'90_Origen_Ledger_EdP'!$G$3:$G$702,2026) -> 0 | G27: =SUM(C27:F27) -> 96638.4 | H27: =IF($G$29=0,"-",G27/$G$29) -> 0.013740827
A28: Perú | B28: Otros clientes (resto) | C28: =SUMIFS('90_Origen_Ledger_EdP'!$K$3:$K$702,'90_Origen_Ledger_EdP'!$F$3:$F$702,$A28,'90_Origen_Ledger_EdP'!$G$3:$G$702,2023)-SUM(C18:C27) -> 50760 | D28: =SUMIFS('90_Origen_Ledger_EdP'!$K$3:$K$702,'90_Origen_Ledger_EdP'!$F$3:$F$702,$A28,'90_Origen_Ledger_EdP'!$G$3:$G$702,2024)-SUM(D18:D27) -> 170262 | E28: =SUMIFS('90_Origen_Ledger_EdP'!$K$3:$K$702,'90_Origen_Ledger_EdP'!$F$3:$F$702,$A28,'90_Origen_Ledger_EdP'!$G$3:$G$702,2025)-SUM(E18:E27) -> 423077 | F28: =SUMIFS('90_Origen_Ledger_EdP'!$K$3:$K$702,'90_Origen_Ledger_EdP'!$F$3:$F$702,$A28,'90_Origen_Ledger_EdP'!$G$3:$G$702,2026)-SUM(F18:F27) -> 331793.29 | G28: =SUM(C28:F28) -> 975892.29 | H28: =IF($G$29=0,"-",G28/$G$29) -> 0.13876024
A29: Perú | B29: TOTAL Perú | C29: =SUM(C18:C28) -> 1626997.1 | D29: =SUM(D18:D28) -> 2105737.1 | E29: =SUM(E18:E28) -> 2465053.6 | F29: =SUM(F18:F28) -> 835151.29 | G29: =SUM(C29:F29) -> 7032939 | H29: 1
A30: Brasil | B30: Mosaic | C30: =SUMIFS('90_Origen_Ledger_EdP'!$K$3:$K$702,'90_Origen_Ledger_EdP'!$F$3:$F$702,$A30,'90_Origen_Ledger_EdP'!$E$3:$E$702,$B30,'90_Origen_Ledger_EdP'!$G$3:$G$702,2023) -> 600368.46 | D30: =SUMIFS('90_Origen_Ledger_EdP'!$K$3:$K$702,'90_Origen_Ledger_EdP'!$F$3:$F$702,$A30,'90_Origen_Ledger_EdP'!$E$3:$E$702,$B30,'90_Origen_Ledger_EdP'!$G$3:$G$702,2024) -> 612782 | E30: =SUMIFS('90_Origen_Ledger_EdP'!$K$3:$K$702,'90_Origen_Ledger_EdP'!$F$3:$F$702,$A30,'90_Origen_Ledger_EdP'!$E$3:$E$702,$B30,'90_Origen_Ledger_EdP'!$G$3:$G$702,2025) -> 404204 | F30: =SUMIFS('90_Origen_Ledger_EdP'!$K$3:$K$702,'90_Origen_Ledger_EdP'!$F$3:$F$702,$A30,'90_Origen_Ledger_EdP'!$E$3:$E$702,$B30,'90_Origen_Ledger_EdP'!$G$3:$G$702,2026) -> 101210 | G30: =SUM(C30:F30) -> 1718564.5 | H30: =IF($G$40=0,"-",G30/$G$40) -> 0.42563915
A31: Brasil | B31: EroCopper | C31: =SUMIFS('90_Origen_Ledger_EdP'!$K$3:$K$702,'90_Origen_Ledger_EdP'!$F$3:$F$702,$A31,'90_Origen_Ledger_EdP'!$E$3:$E$702,$B31,'90_Origen_Ledger_EdP'!$G$3:$G$702,2023) -> 0 | D31: =SUMIFS('90_Origen_Ledger_EdP'!$K$3:$K$702,'90_Origen_Ledger_EdP'!$F$3:$F$702,$A31,'90_Origen_Ledger_EdP'!$E$3:$E$702,$B31,'90_Origen_Ledger_EdP'!$G$3:$G$702,2024) -> 0 | E31: =SUMIFS('90_Origen_Ledger_EdP'!$K$3:$K$702,'90_Origen_Ledger_EdP'!$F$3:$F$702,$A31,'90_Origen_Ledger_EdP'!$E$3:$E$702,$B31,'90_Origen_Ledger_EdP'!$G$3:$G$702,2025) -> 406493.6 | F31: =SUMIFS('90_Origen_Ledger_EdP'!$K$3:$K$702,'90_Origen_Ledger_EdP'!$F$3:$F$702,$A31,'90_Origen_Ledger_EdP'!$E$3:$E$702,$B31,'90_Origen_Ledger_EdP'!$G$3:$G$702,2026) -> 151478.5 | G31: =SUM(C31:F31) -> 557972.1 | H31: =IF($G$40=0,"-",G31/$G$40) -> 0.13819369
A32: Brasil | B32: AuraMinerals | C32: =SUMIFS('90_Origen_Ledger_EdP'!$K$3:$K$702,'90_Origen_Ledger_EdP'!$F$3:$F$702,$A32,'90_Origen_Ledger_EdP'!$E$3:$E$702,$B32,'90_Origen_Ledger_EdP'!$G$3:$G$702,2023) -> 0 | D32: =SUMIFS('90_Origen_Ledger_EdP'!$K$3:$K$702,'90_Origen_Ledger_EdP'!$F$3:$F$702,$A32,'90_Origen_Ledger_EdP'!$E$3:$E$702,$B32,'90_Origen_Ledger_EdP'!$G$3:$G$702,2024) -> 0 | E32: =SUMIFS('90_Origen_Ledger_EdP'!$K$3:$K$702,'90_Origen_Ledger_EdP'!$F$3:$F$702,$A32,'90_Origen_Ledger_EdP'!$E$3:$E$702,$B32,'90_Origen_Ledger_EdP'!$G$3:$G$702,2025) -> 342523.62 | F32: =SUMIFS('90_Origen_Ledger_EdP'!$K$3:$K$702,'90_Origen_Ledger_EdP'!$F$3:$F$702,$A32,'90_Origen_Ledger_EdP'!$E$3:$E$702,$B32,'90_Origen_Ledger_EdP'!$G$3:$G$702,2026) -> 159558.2 | G32: =SUM(C32:F32) -> 502081.82 | H32: =IF($G$40=0,"-",G32/$G$40) -> 0.12435127
A33: Brasil | B33: EQUINOX | C33: =SUMIFS('90_Origen_Ledger_EdP'!$K$3:$K$702,'90_Origen_Ledger_EdP'!$F$3:$F$702,$A33,'90_Origen_Ledger_EdP'!$E$3:$E$702,$B33,'90_Origen_Ledger_EdP'!$G$3:$G$702,2023) -> 0 | D33: =SUMIFS('90_Origen_Ledger_EdP'!$K$3:$K$702,'90_Origen_Ledger_EdP'!$F$3:$F$702,$A33,'90_Origen_Ledger_EdP'!$E$3:$E$702,$B33,'90_Origen_Ledger_EdP'!$G$3:$G$702,2024) -> 0 | E33: =SUMIFS('90_Origen_Ledger_EdP'!$K$3:$K$702,'90_Origen_Ledger_EdP'!$F$3:$F$702,$A33,'90_Origen_Ledger_EdP'!$E$3:$E$702,$B33,'90_Origen_Ledger_EdP'!$G$3:$G$702,2025) -> 306848 | F33: =SUMIFS('90_Origen_Ledger_EdP'!$K$3:$K$702,'90_Origen_Ledger_EdP'!$F$3:$F$702,$A33,'90_Origen_Ledger_EdP'!$E$3:$E$702,$B33,'90_Origen_Ledger_EdP'!$G$3:$G$702,2026) -> 47145 | G33: =SUM(C33:F33) -> 353993 | H33: =IF($G$40=0,"-",G33/$G$40) -> 0.087673919
A34: Brasil | B34: J&F | C34: =SUMIFS('90_Origen_Ledger_EdP'!$K$3:$K$702,'90_Origen_Ledger_EdP'!$F$3:$F$702,$A34,'90_Origen_Ledger_EdP'!$E$3:$E$702,$B34,'90_Origen_Ledger_EdP'!$G$3:$G$702,2023) -> 0 | D34: =SUMIFS('90_Origen_Ledger_EdP'!$K$3:$K$702,'90_Origen_Ledger_EdP'!$F$3:$F$702,$A34,'90_Origen_Ledger_EdP'!$E$3:$E$702,$B34,'90_Origen_Ledger_EdP'!$G$3:$G$702,2024) -> 319132 | E34: =SUMIFS('90_Origen_Ledger_EdP'!$K$3:$K$702,'90_Origen_Ledger_EdP'!$F$3:$F$702,$A34,'90_Origen_Ledger_EdP'!$E$3:$E$702,$B34,'90_Origen_Ledger_EdP'!$G$3:$G$702,2025) -> 8092 | F34: =SUMIFS('90_Origen_Ledger_EdP'!$K$3:$K$702,'90_Origen_Ledger_EdP'!$F$3:$F$702,$A34,'90_Origen_Ledger_EdP'!$E$3:$E$702,$B34,'90_Origen_Ledger_EdP'!$G$3:$G$702,2026) -> 0 | G34: =SUM(C34:F34) -> 327224 | H34: =IF($G$40=0,"-",G34/$G$40) -> 0.081044005
A35: Brasil | B35: NEXA | C35: =SUMIFS('90_Origen_Ledger_EdP'!$K$3:$K$702,'90_Origen_Ledger_EdP'!$F$3:$F$702,$A35,'90_Origen_Ledger_EdP'!$E$3:$E$702,$B35,'90_Origen_Ledger_EdP'!$G$3:$G$702,2023) -> 128549.59 | D35: =SUMIFS('90_Origen_Ledger_EdP'!$K$3:$K$702,'90_Origen_Ledger_EdP'!$F$3:$F$702,$A35,'90_Origen_Ledger_EdP'!$E$3:$E$702,$B35,'90_Origen_Ledger_EdP'!$G$3:$G$702,2024) -> 75794 | E35: =SUMIFS('90_Origen_Ledger_EdP'!$K$3:$K$702,'90_Origen_Ledger_EdP'!$F$3:$F$702,$A35,'90_Origen_Ledger_EdP'!$E$3:$E$702,$B35,'90_Origen_Ledger_EdP'!$G$3:$G$702,2025) -> 0 | F35: =SUMIFS('90_Origen_Ledger_EdP'!$K$3:$K$702,'90_Origen_Ledger_EdP'!$F$3:$F$702,$A35,'90_Origen_Ledger_EdP'!$E$3:$E$702,$B35,'90_Origen_Ledger_EdP'!$G$3:$G$702,2026) -> 0 | G35: =SUM(C35:F35) -> 204343.59 | H35: =IF($G$40=0,"-",G35/$G$40) -> 0.05061005
A36: Brasil | B36: Taboca | C36: =SUMIFS('90_Origen_Ledger_EdP'!$K$3:$K$702,'90_Origen_Ledger_EdP'!$F$3:$F$702,$A36,'90_Origen_Ledger_EdP'!$E$3:$E$702,$B36,'90_Origen_Ledger_EdP'!$G$3:$G$702,2023) -> 0 | D36: =SUMIFS('90_Origen_Ledger_EdP'!$K$3:$K$702,'90_Origen_Ledger_EdP'!$F$3:$F$702,$A36,'90_Origen_Ledger_EdP'!$E$3:$E$702,$B36,'90_Origen_Ledger_EdP'!$G$3:$G$702,2024) -> 0 | E36: =SUMIFS('90_Origen_Ledger_EdP'!$K$3:$K$702,'90_Origen_Ledger_EdP'!$F$3:$F$702,$A36,'90_Origen_Ledger_EdP'!$E$3:$E$702,$B36,'90_Origen_Ledger_EdP'!$G$3:$G$702,2025) -> 180000 | F36: =SUMIFS('90_Origen_Ledger_EdP'!$K$3:$K$702,'90_Origen_Ledger_EdP'!$F$3:$F$702,$A36,'90_Origen_Ledger_EdP'!$E$3:$E$702,$B36,'90_Origen_Ledger_EdP'!$G$3:$G$702,2026) -> 0 | G36: =SUM(C36:F36) -> 180000 | H36: =IF($G$40=0,"-",G36/$G$40) -> 0.04458084
A37: Brasil | B37: LHG | C37: =SUMIFS('90_Origen_Ledger_EdP'!$K$3:$K$702,'90_Origen_Ledger_EdP'!$F$3:$F$702,$A37,'90_Origen_Ledger_EdP'!$E$3:$E$702,$B37,'90_Origen_Ledger_EdP'!$G$3:$G$702,2023) -> 0 | D37: =SUMIFS('90_Origen_Ledger_EdP'!$K$3:$K$702,'90_Origen_Ledger_EdP'!$F$3:$F$702,$A37,'90_Origen_Ledger_EdP'!$E$3:$E$702,$B37,'90_Origen_Ledger_EdP'!$G$3:$G$702,2024) -> 0 | E37: =SUMIFS('90_Origen_Ledger_EdP'!$K$3:$K$702,'90_Origen_Ledger_EdP'!$F$3:$F$702,$A37,'90_Origen_Ledger_EdP'!$E$3:$E$702,$B37,'90_Origen_Ledger_EdP'!$G$3:$G$702,2025) -> 113137 | F37: =SUMIFS('90_Origen_Ledger_EdP'!$K$3:$K$702,'90_Origen_Ledger_EdP'!$F$3:$F$702,$A37,'90_Origen_Ledger_EdP'!$E$3:$E$702,$B37,'90_Origen_Ledger_EdP'!$G$3:$G$702,2026) -> 0 | G37: =SUM(C37:F37) -> 113137 | H37: =IF($G$40=0,"-",G37/$G$40) -> 0.028020792
A38: Brasil | B38: CBMM | C38: =SUMIFS('90_Origen_Ledger_EdP'!$K$3:$K$702,'90_Origen_Ledger_EdP'!$F$3:$F$702,$A38,'90_Origen_Ledger_EdP'!$E$3:$E$702,$B38,'90_Origen_Ledger_EdP'!$G$3:$G$702,2023) -> 0 | D38: =SUMIFS('90_Origen_Ledger_EdP'!$K$3:$K$702,'90_Origen_Ledger_EdP'!$F$3:$F$702,$A38,'90_Origen_Ledger_EdP'!$E$3:$E$702,$B38,'90_Origen_Ledger_EdP'!$G$3:$G$702,2024) -> 0 | E38: =SUMIFS('90_Origen_Ledger_EdP'!$K$3:$K$702,'90_Origen_Ledger_EdP'!$F$3:$F$702,$A38,'90_Origen_Ledger_EdP'!$E$3:$E$702,$B38,'90_Origen_Ledger_EdP'!$G$3:$G$702,2025) -> 72515 | F38: =SUMIFS('90_Origen_Ledger_EdP'!$K$3:$K$702,'90_Origen_Ledger_EdP'!$F$3:$F$702,$A38,'90_Origen_Ledger_EdP'!$E$3:$E$702,$B38,'90_Origen_Ledger_EdP'!$G$3:$G$702,2026) -> 7778 | G38: =SUM(C38:F38) -> 80293 | H38: =IF($G$40=0,"-",G38/$G$40) -> 0.019886274
A39: Brasil | B39: Otros clientes (resto) | C39: =SUMIFS('90_Origen_Ledger_EdP'!$K$3:$K$702,'90_Origen_Ledger_EdP'!$F$3:$F$702,$A39,'90_Origen_Ledger_EdP'!$G$3:$G$702,2023)-SUM(C30:C38) -> 0 | D39: =SUMIFS('90_Origen_Ledger_EdP'!$K$3:$K$702,'90_Origen_Ledger_EdP'!$F$3:$F$702,$A39,'90_Origen_Ledger_EdP'!$G$3:$G$702,2024)-SUM(D30:D38) -> 0 | E39: =SUMIFS('90_Origen_Ledger_EdP'!$K$3:$K$702,'90_Origen_Ledger_EdP'!$F$3:$F$702,$A39,'90_Origen_Ledger_EdP'!$G$3:$G$702,2025)-SUM(E30:E38) -> 0 | F39: =SUMIFS('90_Origen_Ledger_EdP'!$K$3:$K$702,'90_Origen_Ledger_EdP'!$F$3:$F$702,$A39,'90_Origen_Ledger_EdP'!$G$3:$G$702,2026)-SUM(F30:F38) -> 0 | G39: =SUM(C39:F39) -> 0 | H39: =IF($G$40=0,"-",G39/$G$40) -> 0
A40: Brasil | B40: TOTAL Brasil | C40: =SUM(C30:C39) -> 728918.05 | D40: =SUM(D30:D39) -> 1007708 | E40: =SUM(E30:E39) -> 1833813.2 | F40: =SUM(F30:F39) -> 467169.7 | G40: =SUM(C40:F40) -> 4037609 | H40: 1
A41: USA | B41: Ivanhoe | C41: =SUMIFS('90_Origen_Ledger_EdP'!$K$3:$K$702,'90_Origen_Ledger_EdP'!$F$3:$F$702,$A41,'90_Origen_Ledger_EdP'!$E$3:$E$702,$B41,'90_Origen_Ledger_EdP'!$G$3:$G$702,2023) -> 102384 | D41: =SUMIFS('90_Origen_Ledger_EdP'!$K$3:$K$702,'90_Origen_Ledger_EdP'!$F$3:$F$702,$A41,'90_Origen_Ledger_EdP'!$E$3:$E$702,$B41,'90_Origen_Ledger_EdP'!$G$3:$G$702,2024) -> 601598 | E41: =SUMIFS('90_Origen_Ledger_EdP'!$K$3:$K$702,'90_Origen_Ledger_EdP'!$F$3:$F$702,$A41,'90_Origen_Ledger_EdP'!$E$3:$E$702,$B41,'90_Origen_Ledger_EdP'!$G$3:$G$702,2025) -> 0 | F41: =SUMIFS('90_Origen_Ledger_EdP'!$K$3:$K$702,'90_Origen_Ledger_EdP'!$F$3:$F$702,$A41,'90_Origen_Ledger_EdP'!$E$3:$E$702,$B41,'90_Origen_Ledger_EdP'!$G$3:$G$702,2026) -> 0 | G41: =SUM(C41:F41) -> 703982 | H41: =IF($G$52=0,"-",G41/$G$52) -> 0.18368753
...

Sheet 03_FlujoCaja_2024_2025
A1: ENTREGABLE 3 · Flujo de caja histórico mensual
A2: Se separa DEVENGO (gestión: EDP/Factura/Ingreso) de CAJA REAL (movimientos). 2025 completo por entidad; 2024 solo cobros a caja (egresos/saldos 2024 no disponibles mensualmente).
A4: A) CAJA REAL 2025 — por entidad × mes (USD). Caja Inicial · Ingresos · Egresos · Caja Final. Fuente: 'Flujo Redco <país>'.
A5: Entidad | B5: Mes | C5: Caja Inicial | D5: Ingresos (op+otros) | E5: Egresos (costos+admin+no op+cta cte) | F5: Caja Final | G5: Flujo Neto Mes
A6: Chile | B6: ene | C6: =SUMIFS('90_Origen_Caja_2025'!$F$3:$F$542,'90_Origen_Caja_2025'!$A$3:$A$542,"Chile",'90_Origen_Caja_2025'!$C$3:$C$542,1,'90_Origen_Caja_2025'!$E$3:$E$542,"Caja Inicial") -> 52257.14 | D6: =SUMIFS('90_Origen_Caja_2025'!$F$3:$F$542,'90_Origen_Caja_2025'!$A$3:$A$542,"Chile",'90_Origen_Caja_2025'!$C$3:$C$542,1,'90_Origen_Caja_2025'!$E$3:$E$542,"Ingresos Op.")+SUMIFS('90_Origen_Caja_2025'!$F$3:$F$542,'90_Origen_Caja_2025'!$A$3:$A$542,"Chile",'90_Origen_Caja_2025'!$C$3:$C$542,1,'90_Origen_Caja_2025'!$E$3:$E$542,"Otros Ingresos") -> 623639.54 | E6: =SUMIFS('90_Origen_Caja_2025'!$F$3:$F$542,'90_Origen_Caja_2025'!$A$3:$A$542,"Chile",'90_Origen_Caja_2025'!$C$3:$C$542,1,'90_Origen_Caja_2025'!$E$3:$E$542,"Costos Op.")+SUMIFS('90_Origen_Caja_2025'!$F$3:$F$542,'90_Origen_Caja_2025'!$A$3:$A$542,"Chile",'90_Origen_Caja_2025'!$C$3:$C$542,1,'90_Origen_Caja_2025'!$E$3:$E$542,"Costos Admin.")+SUMIFS('90_Origen_Caja_2025'!$F$3:$F$542,'90_Origen_Caja_2025'!$A$3:$A$542,"Chile",'90_Origen_Caja_2025'!$C$3:$C$542,1,'90_Origen_Caja_2025'!$E$3:$E$542,"Activo")+SUMIFS('90_Origen_Caja_2025'!$F$3:$F$542,'90_Origen_Caja_2025'!$A$3:$A$542,"Chile",'90_Origen_Caja_2025'!$C$3:$C$542,1,'90_Origen_Caja_2025'!$E$3:$E$542,"Egresos No Op.")+SUMIFS('90_Origen_Caja_2025'!$F$3:$F$542,'90_Origen_Caja_2025'!$A$3:$A$542,"Chile",'90_Origen_Caja_2025'!$C$3:$C$542,1,'90_Origen_Caja_2025'!$E$3:$E$542,"Pagos Cta.Cte.") -> 505243.99 | F6: =C6+D6-E6 -> 170652.69 | G6: =D6-E6 -> 118395.55
A7: Chile | B7: feb | C7: =SUMIFS('90_Origen_Caja_2025'!$F$3:$F$542,'90_Origen_Caja_2025'!$A$3:$A$542,"Chile",'90_Origen_Caja_2025'!$C$3:$C$542,2,'90_Origen_Caja_2025'!$E$3:$E$542,"Caja Inicial") -> 170652.7 | D7: =SUMIFS('90_Origen_Caja_2025'!$F$3:$F$542,'90_Origen_Caja_2025'!$A$3:$A$542,"Chile",'90_Origen_Caja_2025'!$C$3:$C$542,2,'90_Origen_Caja_2025'!$E$3:$E$542,"Ingresos Op.")+SUMIFS('90_Origen_Caja_2025'!$F$3:$F$542,'90_Origen_Caja_2025'!$A$3:$A$542,"Chile",'90_Origen_Caja_2025'!$C$3:$C$542,2,'90_Origen_Caja_2025'!$E$3:$E$542,"Otros Ingresos") -> 776046.03 | E7: =SUMIFS('90_Origen_Caja_2025'!$F$3:$F$542,'90_Origen_Caja_2025'!$A$3:$A$542,"Chile",'90_Origen_Caja_2025'!$C$3:$C$542,2,'90_Origen_Caja_2025'!$E$3:$E$542,"Costos Op.")+SUMIFS('90_Origen_Caja_2025'!$F$3:$F$542,'90_Origen_Caja_2025'!$A$3:$A$542,"Chile",'90_Origen_Caja_2025'!$C$3:$C$542,2,'90_Origen_Caja_2025'!$E$3:$E$542,"Costos Admin.")+SUMIFS('90_Origen_Caja_2025'!$F$3:$F$542,'90_Origen_Caja_2025'!$A$3:$A$542,"Chile",'90_Origen_Caja_2025'!$C$3:$C$542,2,'90_Origen_Caja_2025'!$E$3:$E$542,"Activo")+SUMIFS('90_Origen_Caja_2025'!$F$3:$F$542,'90_Origen_Caja_2025'!$A$3:$A$542,"Chile",'90_Origen_Caja_2025'!$C$3:$C$542,2,'90_Origen_Caja_2025'!$E$3:$E$542,"Egresos No Op.")+SUMIFS('90_Origen_Caja_2025'!$F$3:$F$542,'90_Origen_Caja_2025'!$A$3:$A$542,"Chile",'90_Origen_Caja_2025'!$C$3:$C$542,2,'90_Origen_Caja_2025'!$E$3:$E$542,"Pagos Cta.Cte.") -> 642883.86 | F7: =C7+D7-E7 -> 303814.87 | G7: =D7-E7 -> 133162.17
A8: Chile | B8: mar | C8: =SUMIFS('90_Origen_Caja_2025'!$F$3:$F$542,'90_Origen_Caja_2025'!$A$3:$A$542,"Chile",'90_Origen_Caja_2025'!$C$3:$C$542,3,'90_Origen_Caja_2025'!$E$3:$E$542,"Caja Inicial") -> 303814.87 | D8: =SUMIFS('90_Origen_Caja_2025'!$F$3:$F$542,'90_Origen_Caja_2025'!$A$3:$A$542,"Chile",'90_Origen_Caja_2025'!$C$3:$C$542,3,'90_Origen_Caja_2025'!$E$3:$E$542,"Ingresos Op.")+SUMIFS('90_Origen_Caja_2025'!$F$3:$F$542,'90_Origen_Caja_2025'!$A$3:$A$542,"Chile",'90_Origen_Caja_2025'!$C$3:$C$542,3,'90_Origen_Caja_2025'!$E$3:$E$542,"Otros Ingresos") -> 490017.58 | E8: =SUMIFS('90_Origen_Caja_2025'!$F$3:$F$542,'90_Origen_Caja_2025'!$A$3:$A$542,"Chile",'90_Origen_Caja_2025'!$C$3:$C$542,3,'90_Origen_Caja_2025'!$E$3:$E$542,"Costos Op.")+SUMIFS('90_Origen_Caja_2025'!$F$3:$F$542,'90_Origen_Caja_2025'!$A$3:$A$542,"Chile",'90_Origen_Caja_2025'!$C$3:$C$542,3,'90_Origen_Caja_2025'!$E$3:$E$542,"Costos Admin.")+SUMIFS('90_Origen_Caja_2025'!$F$3:$F$542,'90_Origen_Caja_2025'!$A$3:$A$542,"Chile",'90_Origen_Caja_2025'!$C$3:$C$542,3,'90_Origen_Caja_2025'!$E$3:$E$542,"Activo")+SUMIFS('90_Origen_Caja_2025'!$F$3:$F$542,'90_Origen_Caja_2025'!$A$3:$A$542,"Chile",'90_Origen_Caja_2025'!$C$3:$C$542,3,'90_Origen_Caja_2025'!$E$3:$E$542,"Egresos No Op.")+SUMIFS('90_Origen_Caja_2025'!$F$3:$F$542,'90_Origen_Caja_2025'!$A$3:$A$542,"Chile",'90_Origen_Caja_2025'!$C$3:$C$542,3,'90_Origen_Caja_2025'!$E$3:$E$542,"Pagos Cta.Cte.") -> 559907.99 | F8: =C8+D8-E8 -> 233924.46 | G8: =D8-E8 -> -69890.41
A9: Chile | B9: abr | C9: =SUMIFS('90_Origen_Caja_2025'!$F$3:$F$542,'90_Origen_Caja_2025'!$A$3:$A$542,"Chile",'90_Origen_Caja_2025'!$C$3:$C$542,4,'90_Origen_Caja_2025'!$E$3:$E$542,"Caja Inicial") -> 233924.45 | D9: =SUMIFS('90_Origen_Caja_2025'!$F$3:$F$542,'90_Origen_Caja_2025'!$A$3:$A$542,"Chile",'90_Origen_Caja_2025'!$C$3:$C$542,4,'90_Origen_Caja_2025'!$E$3:$E$542,"Ingresos Op.")+SUMIFS('90_Origen_Caja_2025'!$F$3:$F$542,'90_Origen_Caja_2025'!$A$3:$A$542,"Chile",'90_Origen_Caja_2025'!$C$3:$C$542,4,'90_Origen_Caja_2025'!$E$3:$E$542,"Otros Ingresos") -> 501115.29 | E9: =SUMIFS('90_Origen_Caja_2025'!$F$3:$F$542,'90_Origen_Caja_2025'!$A$3:$A$542,"Chile",'90_Origen_Caja_2025'!$C$3:$C$542,4,'90_Origen_Caja_2025'!$E$3:$E$542,"Costos Op.")+SUMIFS('90_Origen_Caja_2025'!$F$3:$F$542,'90_Origen_Caja_2025'!$A$3:$A$542,"Chile",'90_Origen_Caja_2025'!$C$3:$C$542,4,'90_Origen_Caja_2025'!$E$3:$E$542,"Costos Admin.")+SUMIFS('90_Origen_Caja_2025'!$F$3:$F$542,'90_Origen_Caja_2025'!$A$3:$A$542,"Chile",'90_Origen_Caja_2025'!$C$3:$C$542,4,'90_Origen_Caja_2025'!$E$3:$E$542,"Activo")+SUMIFS('90_Origen_Caja_2025'!$F$3:$F$542,'90_Origen_Caja_2025'!$A$3:$A$542,"Chile",'90_Origen_Caja_2025'!$C$3:$C$542,4,'90_Origen_Caja_2025'!$E$3:$E$542,"Egresos No Op.")+SUMIFS('90_Origen_Caja_2025'!$F$3:$F$542,'90_Origen_Caja_2025'!$A$3:$A$542,"Chile",'90_Origen_Caja_2025'!$C$3:$C$542,4,'90_Origen_Caja_2025'!$E$3:$E$542,"Pagos Cta.Cte.") -> 614316.02 | F9: =C9+D9-E9 -> 120723.72 | G9: =D9-E9 -> -113200.73
A10: Chile | B10: may | C10: =SUMIFS('90_Origen_Caja_2025'!$F$3:$F$542,'90_Origen_Caja_2025'!$A$3:$A$542,"Chile",'90_Origen_Caja_2025'!$C$3:$C$542,5,'90_Origen_Caja_2025'!$E$3:$E$542,"Caja Inicial") -> 120723.72 | D10: =SUMIFS('90_Origen_Caja_2025'!$F$3:$F$542,'90_Origen_Caja_2025'!$A$3:$A$542,"Chile",'90_Origen_Caja_2025'!$C$3:$C$542,5,'90_Origen_Caja_2025'!$E$3:$E$542,"Ingresos Op.")+SUMIFS('90_Origen_Caja_2025'!$F$3:$F$542,'90_Origen_Caja_2025'!$A$3:$A$542,"Chile",'90_Origen_Caja_2025'!$C$3:$C$542,5,'90_Origen_Caja_2025'!$E$3:$E$542,"Otros Ingresos") -> 432617.57 | E10: =SUMIFS('90_Origen_Caja_2025'!$F$3:$F$542,'90_Origen_Caja_2025'!$A$3:$A$542,"Chile",'90_Origen_Caja_2025'!$C$3:$C$542,5,'90_Origen_Caja_2025'!$E$3:$E$542,"Costos Op.")+SUMIFS('90_Origen_Caja_2025'!$F$3:$F$542,'90_Origen_Caja_2025'!$A$3:$A$542,"Chile",'90_Origen_Caja_2025'!$C$3:$C$542,5,'90_Origen_Caja_2025'!$E$3:$E$542,"Costos Admin.")+SUMIFS('90_Origen_Caja_2025'!$F$3:$F$542,'90_Origen_Caja_2025'!$A$3:$A$542,"Chile",'90_Origen_Caja_2025'!$C$3:$C$542,5,'90_Origen_Caja_2025'!$E$3:$E$542,"Activo")+SUMIFS('90_Origen_Caja_2025'!$F$3:$F$542,'90_Origen_Caja_2025'!$A$3:$A$542,"Chile",'90_Origen_Caja_2025'!$C$3:$C$542,5,'90_Origen_Caja_2025'!$E$3:$E$542,"Egresos No Op.")+SUMIFS('90_Origen_Caja_2025'!$F$3:$F$542,'90_Origen_Caja_2025'!$A$3:$A$542,"Chile",'90_Origen_Caja_2025'!$C$3:$C$542,5,'90_Origen_Caja_2025'!$E$3:$E$542,"Pagos Cta.Cte.") -> 473383.13 | F10: =C10+D10-E10 -> 79958.16 | G10: =D10-E10 -> -40765.56
A11: Chile | B11: jun | C11: =SUMIFS('90_Origen_Caja_2025'!$F$3:$F$542,'90_Origen_Caja_2025'!$A$3:$A$542,"Chile",'90_Origen_Caja_2025'!$C$3:$C$542,6,'90_Origen_Caja_2025'!$E$3:$E$542,"Caja Inicial") -> 79958.16 | D11: =SUMIFS('90_Origen_Caja_2025'!$F$3:$F$542,'90_Origen_Caja_2025'!$A$3:$A$542,"Chile",'90_Origen_Caja_2025'!$C$3:$C$542,6,'90_Origen_Caja_2025'!$E$3:$E$542,"Ingresos Op.")+SUMIFS('90_Origen_Caja_2025'!$F$3:$F$542,'90_Origen_Caja_2025'!$A$3:$A$542,"Chile",'90_Origen_Caja_2025'!$C$3:$C$542,6,'90_Origen_Caja_2025'!$E$3:$E$542,"Otros Ingresos") -> 420992.32 | E11: =SUMIFS('90_Origen_Caja_2025'!$F$3:$F$542,'90_Origen_Caja_2025'!$A$3:$A$542,"Chile",'90_Origen_Caja_2025'!$C$3:$C$542,6,'90_Origen_Caja_2025'!$E$3:$E$542,"Costos Op.")+SUMIFS('90_Origen_Caja_2025'!$F$3:$F$542,'90_Origen_Caja_2025'!$A$3:$A$542,"Chile",'90_Origen_Caja_2025'!$C$3:$C$542,6,'90_Origen_Caja_2025'!$E$3:$E$542,"Costos Admin.")+SUMIFS('90_Origen_Caja_2025'!$F$3:$F$542,'90_Origen_Caja_2025'!$A$3:$A$542,"Chile",'90_Origen_Caja_2025'!$C$3:$C$542,6,'90_Origen_Caja_2025'!$E$3:$E$542,"Activo")+SUMIFS('90_Origen_Caja_2025'!$F$3:$F$542,'90_Origen_Caja_2025'!$A$3:$A$542,"Chile",'90_Origen_Caja_2025'!$C$3:$C$542,6,'90_Origen_Caja_2025'!$E$3:$E$542,"Egresos No Op.")+SUMIFS('90_Origen_Caja_2025'!$F$3:$F$542,'90_Origen_Caja_2025'!$A$3:$A$542,"Chile",'90_Origen_Caja_2025'!$C$3:$C$542,6,'90_Origen_Caja_2025'!$E$3:$E$542,"Pagos Cta.Cte.") -> 469053.99 | F11: =C11+D11-E11 -> 31896.49 | G11: =D11-E11 -> -48061.67
A12: Chile | B12: jul | C12: =SUMIFS('90_Origen_Caja_2025'!$F$3:$F$542,'90_Origen_Caja_2025'!$A$3:$A$542,"Chile",'90_Origen_Caja_2025'!$C$3:$C$542,7,'90_Origen_Caja_2025'!$E$3:$E$542,"Caja Inicial") -> 31896.49 | D12: =SUMIFS('90_Origen_Caja_2025'!$F$3:$F$542,'90_Origen_Caja_2025'!$A$3:$A$542,"Chile",'90_Origen_Caja_2025'!$C$3:$C$542,7,'90_Origen_Caja_2025'!$E$3:$E$542,"Ingresos Op.")+SUMIFS('90_Origen_Caja_2025'!$F$3:$F$542,'90_Origen_Caja_2025'!$A$3:$A$542,"Chile",'90_Origen_Caja_2025'!$C$3:$C$542,7,'90_Origen_Caja_2025'!$E$3:$E$542,"Otros Ingresos") -> 694589.56 | E12: =SUMIFS('90_Origen_Caja_2025'!$F$3:$F$542,'90_Origen_Caja_2025'!$A$3:$A$542,"Chile",'90_Origen_Caja_2025'!$C$3:$C$542,7,'90_Origen_Caja_2025'!$E$3:$E$542,"Costos Op.")+SUMIFS('90_Origen_Caja_2025'!$F$3:$F$542,'90_Origen_Caja_2025'!$A$3:$A$542,"Chile",'90_Origen_Caja_2025'!$C$3:$C$542,7,'90_Origen_Caja_2025'!$E$3:$E$542,"Costos Admin.")+SUMIFS('90_Origen_Caja_2025'!$F$3:$F$542,'90_Origen_Caja_2025'!$A$3:$A$542,"Chile",'90_Origen_Caja_2025'!$C$3:$C$542,7,'90_Origen_Caja_2025'!$E$3:$E$542,"Activo")+SUMIFS('90_Origen_Caja_2025'!$F$3:$F$542,'90_Origen_Caja_2025'!$A$3:$A$542,"Chile",'90_Origen_Caja_2025'!$C$3:$C$542,7,'90_Origen_Caja_2025'!$E$3:$E$542,"Egresos No Op.")+SUMIFS('90_Origen_Caja_2025'!$F$3:$F$542,'90_Origen_Caja_2025'!$A$3:$A$542,"Chile",'90_Origen_Caja_2025'!$C$3:$C$542,7,'90_Origen_Caja_2025'!$E$3:$E$542,"Pagos Cta.Cte.") -> 502823.19 | F12: =C12+D12-E12 -> 223662.86 | G12: =D12-E12 -> 191766.37
A13: Chile | B13: ago | C13: =SUMIFS('90_Origen_Caja_2025'!$F$3:$F$542,'90_Origen_Caja_2025'!$A$3:$A$542,"Chile",'90_Origen_Caja_2025'!$C$3:$C$542,8,'90_Origen_Caja_2025'!$E$3:$E$542,"Caja Inicial") -> 223662.84 | D13: =SUMIFS('90_Origen_Caja_2025'!$F$3:$F$542,'90_Origen_Caja_2025'!$A$3:$A$542,"Chile",'90_Origen_Caja_2025'!$C$3:$C$542,8,'90_Origen_Caja_2025'!$E$3:$E$542,"Ingresos Op.")+SUMIFS('90_Origen_Caja_2025'!$F$3:$F$542,'90_Origen_Caja_2025'!$A$3:$A$542,"Chile",'90_Origen_Caja_2025'!$C$3:$C$542,8,'90_Origen_Caja_2025'!$E$3:$E$542,"Otros Ingresos") -> 684254.25 | E13: =SUMIFS('90_Origen_Caja_2025'!$F$3:$F$542,'90_Origen_Caja_2025'!$A$3:$A$542,"Chile",'90_Origen_Caja_2025'!$C$3:$C$542,8,'90_Origen_Caja_2025'!$E$3:$E$542,"Costos Op.")+SUMIFS('90_Origen_Caja_2025'!$F$3:$F$542,'90_Origen_Caja_2025'!$A$3:$A$542,"Chile",'90_Origen_Caja_2025'!$C$3:$C$542,8,'90_Origen_Caja_2025'!$E$3:$E$542,"Costos Admin.")+SUMIFS('90_Origen_Caja_2025'!$F$3:$F$542,'90_Origen_Caja_2025'!$A$3:$A$542,"Chile",'90_Origen_Caja_2025'!$C$3:$C$542,8,'90_Origen_Caja_2025'!$E$3:$E$542,"Activo")+SUMIFS('90_Origen_Caja_2025'!$F$3:$F$542,'90_Origen_Caja_2025'!$A$3:$A$542,"Chile",'90_Origen_Caja_2025'!$C$3:$C$542,8,'90_Origen_Caja_2025'!$E$3:$E$542,"Egresos No Op.")+SUMIFS('90_Origen_Caja_2025'!$F$3:$F$542,'90_Origen_Caja_2025'!$A$3:$A$542,"Chile",'90_Origen_Caja_2025'!$C$3:$C$542,8,'90_Origen_Caja_2025'!$E$3:$E$542,"Pagos Cta.Cte.") -> 549999.74 | F13: =C13+D13-E13 -> 357917.35 | G13: =D13-E13 -> 134254.51
