Workbook
Name RutaCarpeta: #REF!
Name RutaCarpeta: #REF!
Name RutaCarpeta: #REF!
Name RutaCarpeta: #REF!
Name RutaCarpeta: #REF!
Name RutaCarpeta: #REF!
Name RutaCarpeta: #REF!
Name RutaCarpeta: #REF!
Name RutaCarpeta: #REF!
Name RutaCarpeta: #REF!
Name RutaCarpeta: #REF!
Name RutaCarpeta: #REF!
Name RutaCarpeta: #REF!
Name RutaCarpeta: #REF!
Name RutaCarpeta: #REF!

Sheet Gasto Diciembre (4)
A2: Clasificación 1 | B2: (Todas)
A3: País | B3: Chile
A5: Suma de Valor USD | E5: Meses (Atributo)
A6: Clasificación 0 | B6: Clasificación 2 | C6: Clasificación 3 | D6: Detalle | E6: ene | F6: feb | G6: mar | H6: abr | I6: may | J6: jun | K6: jul | L6: ago | M6: sept | N6: oct | O6: nov | P6: dic
A7: Fijo | B7: Sueldos | E7: 198081.87 | F7: 192564.08 | G7: 201303.57 | H7: 191949.92 | I7: 203926.54 | J7: 158834.49 | K7: 206742.44 | L7: 213676.32 | M7: 209758.6 | N7: 218099.34 | O7: 180235.68 | P7: 210281.54
A8: Fijo | B8: Oficina | C8: Arriendo | D8: Arriendo oficina 1502 + estac-Edif. Kennedy 85 UF | E8: 0 | F8: 0 | G8: 0 | H8: 0 | I8: 0 | J8: 0 | K8: 0 | L8: 0 | M8: 0 | N8: 0 | O8: 0 | P8: 3325.6019
A9: Fijo | B9: Oficina | C9: Caja Chica | E9: 727.30977 | F9: 840.72594 | G9: 0 | H9: 533.34618 | I9: 431.11082 | J9: 399.46981 | K9: 0 | L9: 0 | M9: 0 | N9: 0 | O9: 0 | P9: 0
A10: Fijo | B10: Oficina | C10: Credito | E10: 5434.0037 | F10: 5121.254 | G10: 5097.4926 | H10: 0 | I10: 0 | J10: 0 | K10: 20056.597 | L10: 20219.14 | M10: 20292.392 | N10: 20123.773 | O10: 19323.355 | P10: 19118.322 | Q10: =+SUM(E10:P10) -> 134786.33
A11: Fijo | B11: Oficina | C11: Dividendo | E11: 7385.6937 | F11: 6926.5943 | G11: 6940.7147 | H11: 7041.2961 | I11: 7394.7891 | J11: 7365.1434 | K11: 7257.5718 | L11: 7309.8688 | M11: 7390.6943 | N11: 7351.6261 | O11: 7071.903 | P11: 7068.4154
A12: Fijo | B12: Oficina | C12: Estacionamiento | E12: 563.77934 | F12: 833.38661 | G12: 186.48559 | H12: 231.62247 | I12: 881.57384 | J12: 438.28935 | K12: 336.76885 | L12: 437.55242 | M12: 440.47138 | N12: 437.2624 | O12: 236.03849 | P12: 0
A13: Fijo | B13: Oficina | C13: GGCC | E13: 1631.7195 | F13: 3153.2529 | G13: 1703.742 | H13: 0 | I13: 3464.7961 | J13: 1594.0513 | K13: 1829.9533 | L13: 1829.6451 | M13: 1943.7061 | N13: 1931.123 | O13: 1730.6196 | P13: 1692.5466
A14: Fijo | B14: Oficina | C14: Pago servicio | D14: Prisa S.A. arts. Aseso y cocina | E14: 0 | F14: 0 | G14: 0 | H14: 0 | I14: 0 | J14: 0 | K14: 270.24937 | L14: 354.15959 | M14: 248.09169 | N14: 319.03385 | O14: 283.28016 | P14: 320.23548
A15: Fijo | B15: Oficina | C15: Patente | E15: 234.19751 | F15: 0 | G15: 0 | H15: 0 | I15: 0 | J15: 0 | K15: 444.74274 | L15: 0 | M15: 0 | N15: 0 | O15: 0 | P15: 0
A16: Fijo | B16: Oficina | C16: Registro Proveedores | E16: 786.88532 | F16: 0 | G16: 0 | H16: 1369.4388 | I16: 0 | J16: 141.96506 | K16: 0 | L16: 0 | M16: 0 | N16: 0 | O16: 0 | P16: 186.31142
A17: Fijo | B17: Oficina | C17: Software | E17: 1408.3305 | F17: 0 | G17: 0 | H17: 2485.0699 | I17: 0 | J17: 0 | K17: 1459.0864 | L17: 492.34649 | M17: 496.1499 | N17: 1892.4888 | O17: 475.44463 | P17: 6475.7578
A18: Fijo | B18: Oficina | C18: Tarjeta | E18: 11332.386 | F18: 0 | G18: 0 | H18: 5740.8586 | I18: 10765.363 | J18: 6994.2921 | K18: 4987.7725 | L18: 4749.3128 | M18: 3756.4883 | N18: 10809.471 | O18: 3941.0292 | P18: 13615.383
A19: Fijo | B19: Oficina | C19: Telefonia | E19: 716.93961 | F19: 947.894 | G19: 558.75528 | H19: 0 | I19: 2075.049 | J19: 0 | K19: 1546.173 | L19: 1020.6216 | M19: 333.36824 | N19: 668.79451 | O19: 919.83326 | P19: 1577.9017
A20: Fijo | B20: Oficina | C20: Prestamo | D20: Préstamo Bco. Chile - Redco Perú | E20: 0 | F20: 0 | G20: 0 | H20: 0 | I20: 0 | J20: 5658.2315 | K20: 5585.8718 | L20: 5630.5689 | M20: 5649.6021 | N20: 5601.5838 | O20: 5381.6622 | P20: 0
A21: Fijo | B21: Extras personas | E21: 4574.0405 | F21: 4427.5118 | G21: 5067.7415 | H21: 2404.6587 | I21: 5844.4873 | J21: 3856.6463 | K21: 4005.1474 | L21: 4380.3484 | M21: 4268.1498 | N21: 4189.2387 | O21: 745.20585 | P21: 1865.8346
A22: Fijo | B22: Externo | C22: Pago servicio | D22: Salcedo & Cia. Limitada (Asesoria Tributaria) | E22: 805.48795 | F22: 762.41593 | G22: 761.73587 | H22: 0 | I22: 812.02227 | J22: 808.67636 | K22: 801.5615 | L22: 808.21056 | M22: 815.42955 | N22: 812.03243 | O22: 781.65191 | P22: 779.36527
A23: Fijo | B23: Externo | C23: Pago servicio | D23: Transp. Nueva Apoquindo Ltda. Mayo | E23: 562.26721 | F23: 326.20298 | G23: 606.07689 | H23: 0 | I23: 962.64 | J23: 396.47871 | K23: 581.36119 | L23: 429.1483 | M23: 449.21346 | N23: 872.42694 | O23: 201.39358 | P23: 399.30844
A24: Fijo | B24: Externo | C24: Pago servicio | D24: Transp. Nueva Apoquindo Ltda. Abril | E24: 0 | F24: 607.48983 | G24: 0 | H24: 0 | I24: 549.58164 | J24: 0 | K24: 0 | L24: 0 | M24: 0 | N24: 0 | O24: 0 | P24: 0
A25: Fijo | B25: Externo | C25: Pago servicio | D25: Salcedo & Cia. Limitada (Asesoria Tributaria) marzo y abril | E25: 0 | F25: 763.88047 | G25: 0 | H25: 0 | I25: 1593.8336 | J25: 0 | K25: 0 | L25: 0 | M25: 0 | N25: 0 | O25: 0 | P25: 0
A26: Fijo | B26: Externo | C26: Pago servicio | D26: Par Cuatro aromatizacion oficina mayo | E26: 135.91229 | F26: 129.00751 | G26: 128.10637 | H26: 0 | I26: 138.55188 | J26: 136.38563 | K26: 0 | L26: 0 | M26: 0 | N26: 0 | O26: 0 | P26: 0
A27: Fijo | B27: Externo | C27: Pago servicio | D27: Par Cuatro aromatizacion oficina factura abril | E27: 0 | F27: 129.08432 | G27: 0 | H27: 0 | I27: 134.70824 | J27: 0 | K27: 0 | L27: 0 | M27: 0 | N27: 0 | O27: 0 | P27: 0
A28: Fijo | B28: Externo | C28: Pago servicio | D28: Nespresso Chile S.A. mayo | E28: 566.17364 | F28: 533.58798 | G28: 1120.0087 | H28: 0 | I28: 292.02946 | J28: 292.65614 | K28: 283.99569 | L28: 574.58974 | M28: 291.652 | N28: 289.27833 | O28: 277.10786 | P28: 274.2178
A29: Fijo | B29: Externo | C29: Pago servicio | D29: Nespresso Chile S.A. abril | E29: 0 | F29: 0 | G29: 0 | H29: 0 | I29: 590.54125 | J29: 0 | K29: 0 | L29: 0 | M29: 0 | N29: 0 | O29: 0 | P29: 0
A30: Fijo | B30: Dueño | C30: Credito | E30: 0 | F30: 2174.0077 | G30: 1084.7913 | H30: 1093.5926 | I30: 1140.9585 | J30: 1130.8559 | K30: 2234.0181 | L30: 1126.2103 | M30: 1130.6971 | N30: 0 | O30: 1077.8746 | P30: 1066.6331
A31: Fijo | B31: Dueño | C31: Seguro | E31: 298.83699 | F31: 230.32675 | G31: 171.39669 | H31: 173.79341 | I31: 41.82246 | J31: 41.637871 | K31: 318.70707 | L31: 41.809872 | M31: 325.10662 | N31: 41.84363 | O31: 176.79498 | P31: 40.017722
A32: Fijo | B32: Comercial | C32: Publicidad | E32: 917.41098 | F32: 864.61015 | G32: 1721.1988 | H32: 0 | I32: 1815.0521 | J32: 899.49032 | K32: 888.47647 | L32: 895.79525 | M32: 1130.6291 | N32: 892.04442 | O32: 2363.8329 | P32: 1026.5726
A33: Fijo | B33: Bancarios | E33: 702.15641 | F33: 185.02346 | G33: 224.98218 | H33: 139.82023 | I33: 553.76956 | J33: 343.9746 | K33: 456.20014 | L33: 203.9144 | M33: 420.02786 | N33: 280.12444 | O33: 1209.8837 | P33: 408.12454
A34: Fijo | B34: Compañía | E34: 1186.458 | F34: 2675.0934 | G34: 2662.6843 | H34: 2684.2877 | I34: 2807.8747 | J34: 0 | K34: 2748.9355 | L34: 5543.1595 | M34: 2782.6217 | N34: 5519.9495 | O34: 2652.6266 | P34: 2624.9613
A35: Total Fijo | E35: 238051.86 | F35: 224195.43 | G35: 229339.48 | H35: 215847.71 | I35: 246217.1 | J35: 189332.73 | K35: 262835.63 | L35: 269722.72 | M35: 261923.09 | N35: 280131.44 | O35: 229085.21 | P35: 272147.06
A36: Variable | B36: Impuestos | C36: Impuesto | D36: PPM 6,8% | E36: 0 | F36: 0 | G36: 0 | H36: 0 | I36: 0 | J36: 0 | K36: 0 | L36: 0 | M36: 0 | N36: 0 | O36: 0 | P36: 0
A37: Variable | B37: Impuestos | C37: Impuesto | D37: IVA DEBITO FISCAL | E37: 87861.647 | F37: 75662.112 | G37: 16948.437 | H37: 41207.305 | I37: 18324.099 | J37: 25946.446 | K37: 25109.218 | L37: 0 | M37: 100217.1 | N37: 82725.581 | O37: 69233.677 | P37: 11568.045
A38: Variable | B38: Impuestos | C38: Impuesto | D38: IMPTO.ADICIONAL 20% | E38: 2122.541 | F38: 380.23644 | G38: 718.38769 | H38: 416.78089 | I38: 398.3244 | J38: 438.25587 | K38: 472.24604 | L38: 0 | M38: 447.51082 | N38: 0 | O38: 714.69226 | P38: 140.52697
A39: Variable | B39: Impuestos | C39: Impuesto | D39: IMPTO.TIMBRE Y ESTAMPILLA | E39: 0 | F39: 0 | G39: 0 | H39: 0 | I39: 0 | J39: 126.32494 | K39: 0 | L39: 0 | M39: 0 | N39: 0 | O39: 0 | P39: 0
A40: Variable | B40: Impuestos | C40: REDTEC | E40: 0 | F40: 0 | G40: 0 | H40: 0 | I40: 0 | J40: 0 | K40: 0 | L40: 0 | M40: 0 | N40: 8002.0732 | O40: 0 | P40: 0
A41: Variable | B41: Externo | C41: Pago servicio | D41: Cintamatrix Ltda. | E41: 72.737585 | F41: 168.21598 | G41: 0 | H41: 0 | I41: 58.34096 | J41: 0 | K41: 0 | L41: 0 | M41: 0 | N41: 0 | O41: 71.037464 | P41: 0
A42: Variable | B42: Externo | C42: Pago servicio | D42: CONSTRUCCION SERVI TRES SPA | E42: 0 | F42: 0 | G42: 0 | H42: 0 | I42: 129.64658 | J42: 0 | K42: 0 | L42: 0 | M42: 0 | N42: 0 | O42: 0 | P42: 0
...

Sheet Gasto total_Análisis (2)
C3: Gasto Proyectado REDCO sin EEUU
O4: =+O8-N8 -> 28.076021
C5: Item | D5: ene | E5: feb | F5: mar | G5: abr | H5: may | I5: jun | J5: jul | K5: ago | L5: sept | M5: oct | N5: nov | O5: dic | P5: Total | Q5: Promedio
C6: ='Gasto Septiembre'!A9 -> Sueldos | D6: =('Gasto Diciembre (2)'!B8)/1000 -> 302.50526 | E6: =('Gasto Diciembre (2)'!C8)/1000 -> 278.5006 | F6: =('Gasto Diciembre (2)'!D8)/1000 -> 288.865 | G6: =('Gasto Diciembre (2)'!E8)/1000 -> 271.76518 | H6: =('Gasto Diciembre (2)'!F8)/1000 -> 312.95631 | I6: =('Gasto Diciembre (2)'!G8)/1000 -> 233.21148 | J6: =('Gasto Diciembre (2)'!H8)/1000 -> 335.85132 | K6: =('Gasto Diciembre (2)'!I8)/1000 -> 306.40784 | ... O6: =('Gasto Diciembre (2)'!M8)/1000 -> 316.82887 | P6: =+SUM(D6:O6) -> 3489.543 | Q6: =+AVERAGE(D6:O6) -> 290.79525
C7: ='Gasto Septiembre'!A10 -> Externo | D7: =('Gasto Diciembre (2)'!B9)/1000 -> 123.39341 | E7: =('Gasto Diciembre (2)'!C9)/1000 -> 95.218967 | F7: =('Gasto Diciembre (2)'!D9)/1000 -> 63.271157 | G7: =('Gasto Diciembre (2)'!E9)/1000 -> 9.5349993 | H7: =('Gasto Diciembre (2)'!F9)/1000 -> 90.110012 | I7: =('Gasto Diciembre (2)'!G9)/1000 -> 101.18794 | J7: =('Gasto Diciembre (2)'!H9)/1000 -> 53.135335 | K7: =('Gasto Diciembre (2)'!I9)/1000 -> 107.30165 | ... O7: =('Gasto Diciembre (2)'!M9)/1000 -> 97.664797 | P7: =+SUM(D7:O7) -> 948.81357 | Q7: =+AVERAGE(D7:O7) -> 79.067798
C8: ='Gasto Septiembre'!A11 -> Oficina | D8: =('Gasto Diciembre (2)'!B10)/1000 -> 46.73479 | E8: =('Gasto Diciembre (2)'!C10)/1000 -> 35.698197 | F8: =('Gasto Diciembre (2)'!D10)/1000 -> 25.091045 | G8: =('Gasto Diciembre (2)'!E10)/1000 -> 34.665023 | H8: =('Gasto Diciembre (2)'!F10)/1000 -> 46.509808 | I8: =('Gasto Diciembre (2)'!G10)/1000 -> 36.712331 | J8: =('Gasto Diciembre (2)'!H10)/1000 -> 41.59982 | K8: =('Gasto Diciembre (2)'!I10)/1000 -> 37.109385 | ... O8: =('Gasto Diciembre (2)'!M10)/1000 -> 70.662434 | P8: =+SUM(D8:O8) -> 508.93863 | Q8: =+AVERAGE(D8:O8) -> 42.411552
C9: ='Gasto Septiembre'!A12 -> Extras personas | D9: =('Gasto Diciembre (2)'!B11)/1000 -> 129.39817 | E9: =('Gasto Diciembre (2)'!C11)/1000 -> 40.431764 | F9: =('Gasto Diciembre (2)'!D11)/1000 -> 19.643364 | G9: =('Gasto Diciembre (2)'!E11)/1000 -> 12.341404 | H9: =('Gasto Diciembre (2)'!F11)/1000 -> 18.451806 | I9: =('Gasto Diciembre (2)'!G11)/1000 -> 6.0272542 | J9: =('Gasto Diciembre (2)'!H11)/1000 -> 5.0827933 | K9: =('Gasto Diciembre (2)'!I11)/1000 -> 4.9271873 | ... O9: =('Gasto Diciembre (2)'!M11)/1000 -> 13.829525 | P9: =+SUM(D9:O9) -> 313.73029 | Q9: =+AVERAGE(D9:O9) -> 26.144191
C10: ='Gasto Septiembre'!A13 -> Viajes | D10: =('Gasto Diciembre (2)'!B12)/1000 -> 70.94038 | E10: =('Gasto Diciembre (2)'!C12)/1000 -> 15.541723 | F10: =('Gasto Diciembre (2)'!D12)/1000 -> 6.4251697 | G10: =('Gasto Diciembre (2)'!E12)/1000 -> 19.654064 | H10: =('Gasto Diciembre (2)'!F12)/1000 -> 11.217311 | I10: =('Gasto Diciembre (2)'!G12)/1000 -> 6.643918 | J10: =('Gasto Diciembre (2)'!H12)/1000 -> 10.766462 | K10: =('Gasto Diciembre (2)'!I12)/1000 -> 12.765451 | ... O10: =('Gasto Diciembre (2)'!M12)/1000 -> 16.0338 | P10: =+SUM(D10:O10) -> 192.24619 | Q10: =+AVERAGE(D10:O10) -> 16.020516
C11: ='Gasto Septiembre'!A14 -> Compañía | D11: =('Gasto Diciembre (2)'!B13)/1000 -> 12.901351 | E11: =('Gasto Diciembre (2)'!C13)/1000 -> 5.280059 | F11: =('Gasto Diciembre (2)'!D13)/1000 -> 2.6626843 | G11: =('Gasto Diciembre (2)'!E13)/1000 -> 2.6842877 | H11: =('Gasto Diciembre (2)'!F13)/1000 -> 6.9208513 | I11: =('Gasto Diciembre (2)'!G13)/1000 -> 0 | J11: =('Gasto Diciembre (2)'!H13)/1000 -> 5.6590789 | K11: =('Gasto Diciembre (2)'!I13)/1000 -> 5.7457512 | ... O11: =('Gasto Diciembre (2)'!M13)/1000 -> 12.612711 | P11: =+SUM(D11:O11) -> 76.115717 | Q11: =+AVERAGE(D11:O11) -> 6.3429764
C12: ='Gasto Septiembre'!A15 -> Comercial | D12: =('Gasto Diciembre (2)'!B14)/1000 -> 1.146288 | E12: =('Gasto Diciembre (2)'!C14)/1000 -> 0.86461015 | F12: =('Gasto Diciembre (2)'!D14)/1000 -> 1.7211988 | G12: =('Gasto Diciembre (2)'!E14)/1000 -> 0 | H12: =('Gasto Diciembre (2)'!F14)/1000 -> 2.3744771 | I12: =('Gasto Diciembre (2)'!G14)/1000 -> 0.89949032 | J12: =('Gasto Diciembre (2)'!H14)/1000 -> 0.88847647 | K12: =('Gasto Diciembre (2)'!I14)/1000 -> 0.89579525 | ... O12: =('Gasto Diciembre (2)'!M14)/1000 -> 1.1941192 | P12: =+SUM(D12:O12) -> 14.370962 | Q12: =+AVERAGE(D12:O12) -> 1.1975801
C13: ='Gasto Septiembre'!A16 -> Bancarios | D13: =('Gasto Diciembre (2)'!B15)/1000 -> 1.010502 | E13: =('Gasto Diciembre (2)'!C15)/1000 -> 0.71911981 | F13: =('Gasto Diciembre (2)'!D15)/1000 -> 0.47228157 | G13: =('Gasto Diciembre (2)'!E15)/1000 -> 0.36444023 | H13: =('Gasto Diciembre (2)'!F15)/1000 -> 0.81385956 | I13: =('Gasto Diciembre (2)'!G15)/1000 -> 1.6420746 | J13: =('Gasto Diciembre (2)'!H15)/1000 -> 2.1692001 | K13: =('Gasto Diciembre (2)'!I15)/1000 -> 1.1940144 | ... O13: =('Gasto Diciembre (2)'!M15)/1000 -> 1.5701245 | P13: =+SUM(D13:O13) -> 13.501653 | Q13: =+AVERAGE(D13:O13) -> 1.1251377
C14: Total | D14: =+SUM(D6:D13) -> 688.03016 | E14: =+SUM(E6:E13) -> 472.25504 | F14: =+SUM(F6:F13) -> 408.1519 | G14: =+SUM(G6:G13) -> 351.0094 | H14: =+SUM(H6:H13) -> 489.35443 | I14: =+SUM(I6:I13) -> 386.32449 | J14: =+SUM(J6:J13) -> 455.15249 | K14: =+SUM(K6:K13) -> 476.34708 | ... Q14: =+SUM(Q6:Q13) -> 463.105
C15: Acumulado | D15: =+SUM($D$14:D14) -> 688.03016 | E15: =+SUM($D$14:E14) -> 1160.2852 | F15: =+SUM($D$14:F14) -> 1568.4371 | G15: =+SUM($D$14:G14) -> 1919.4465 | H15: =+SUM($D$14:H14) -> 2408.8009 | I15: =+SUM($D$14:I14) -> 2795.1254 | J15: =+SUM($D$14:J14) -> 3250.2779 | K15: =+SUM($D$14:K14) -> 3726.625 | ... O15: =+SUM($D$14:O14) -> 5557.26
D16: =+D15/$O$15 -> 0.12380744 | E16: =+E15/$O$15 -> 0.20878728 | F16: =+F15/$O$15 -> 0.28223209 | G16: =+G15/$O$15 -> 0.3453944 | H16: =+H15/$O$15 -> 0.43345118 | I16: =+I15/$O$15 -> 0.50296826 | J16: =+J15/$O$15 -> 0.58487058 | K16: =+K15/$O$15 -> 0.67058676 | ... O16: =+O15/$O$15 -> 1
C18: Sueldo/total | D18: =+D6/D14 -> 0.43966861 | E18: =+E6/E14 -> 0.58972499 | F18: =+F6/F14 -> 0.70773896 | G18: =+G6/G14 -> 0.77423904 | H18: =+H6/H14 -> 0.63952892 | I18: =+I6/I14 -> 0.60366736 | J18: =+J6/J14 -> 0.73788748 | K18: =+K6/K14 -> 0.64324494 | ... M18: =+M6/M14 -> 0.60569456
C19: Externo/total | D19: =+D7/D14 -> 0.17934303 | E19: =+E7/E14 -> 0.20162615 | F19: =+F7/F14 -> 0.15501865 | G19: =+G7/G14 -> 0.027164513 | H19: =+H7/H14 -> 0.18414058 | I19: =+I7/I14 -> 0.26192473 | J19: =+J7/J14 -> 0.11674183 | K19: =+K7/K14 -> 0.22525938 | ... M19: =+M7/M14 -> 0.20205971
C20: Oficina/total | D20: =+D8/D14 -> 0.067925497 | E20: =+E8/E14 -> 0.075590928 | F20: =+F8/F14 -> 0.061474772 | G20: =+G8/G14 -> 0.098758104 | H20: =+H8/H14 -> 0.095043192 | I20: =+I8/I14 -> 0.095029779 | J20: =+J8/J14 -> 0.091397546 | K20: =+K8/K14 -> 0.07790409 | ... M20: =+M8/M14 -> 0.097829435
C23: Item | D23: ene | E23: feb | F23: mar | G23: abr | H23: may | I23: jun | J23: jul | K23: ago | L23: sept | M23: oct | N23: nov | O23: dic | P23: Total | Q23: Promedio
C24: ='Gasto Septiembre'!A30 -> Chile | D24: =('Gasto Diciembre (2)'!B28)/1000 -> 476.29051 | E24: =('Gasto Diciembre (2)'!C28)/1000 -> 313.31492 | F24: =('Gasto Diciembre (2)'!D28)/1000 -> 275.86855 | G24: =('Gasto Diciembre (2)'!E28)/1000 -> 231.52127 | H24: =('Gasto Diciembre (2)'!F28)/1000 -> 317.17005 | I24: =('Gasto Diciembre (2)'!G28)/1000 -> 288.14494 | J24: =('Gasto Diciembre (2)'!H28)/1000 -> 292.12749 | K24: =('Gasto Diciembre (2)'!I28)/1000 -> 299.21779 | ... O24: =('Gasto Diciembre (2)'!M28)/1000 -> 334.87696 | P24: =+SUM(D24:O24) -> 3770.4617 | Q24: =+AVERAGE(D24:O24) -> 314.20514
C25: ='Gasto Septiembre'!A31 -> Perú | D25: =('Gasto Diciembre (2)'!B29)/1000 -> 167.14016 | E25: =('Gasto Diciembre (2)'!C29)/1000 -> 109.66978 | F25: =('Gasto Diciembre (2)'!D29)/1000 -> 119.90377 | G25: =('Gasto Diciembre (2)'!E29)/1000 -> 98.13241 | H25: =('Gasto Diciembre (2)'!F29)/1000 -> 125.25863 | I25: =('Gasto Diciembre (2)'!G29)/1000 -> 82.824806 | J25: =('Gasto Diciembre (2)'!H29)/1000 -> 139.674 | K25: =('Gasto Diciembre (2)'!I29)/1000 -> 152.09422 | ... O25: =('Gasto Diciembre (2)'!M29)/1000 -> 159.18262 | P25: =+SUM(D25:O25) -> 1428.4109 | Q25: =+AVERAGE(D25:O25) -> 119.03424
C26: ='Gasto Septiembre'!A32 -> Brasil | D26: =('Gasto Diciembre (2)'!B30)/1000 -> 44.59949 | E26: =('Gasto Diciembre (2)'!C30)/1000 -> 49.27034 | F26: =('Gasto Diciembre (2)'!D30)/1000 -> 12.37958 | G26: =('Gasto Diciembre (2)'!E30)/1000 -> 21.355715 | H26: =('Gasto Diciembre (2)'!F30)/1000 -> 46.92575 | I26: =('Gasto Diciembre (2)'!G30)/1000 -> 15.35474 | J26: =('Gasto Diciembre (2)'!H30)/1000 -> 23.351 | K26: =('Gasto Diciembre (2)'!I30)/1000 -> 25.03507 | ... O26: =('Gasto Diciembre (2)'!M30)/1000 -> 36.3368 | P26: =+SUM(D26:O26) -> 358.38748 | Q26: =+AVERAGE(D26:O26) -> 29.865624
C27: Total | D27: =+SUM(D24:D26) -> 688.03016 | E27: =+SUM(E24:E26) -> 472.25504 | F27: =+SUM(F24:F26) -> 408.1519 | G27: =+SUM(G24:G26) -> 351.0094 | H27: =+SUM(H24:H26) -> 489.35443 | I27: =+SUM(I24:I26) -> 386.32449 | J27: =+SUM(J24:J26) -> 455.15249 | K27: =+SUM(K24:K26) -> 476.34708 | ... Q27: =+SUM(Q24:Q26) -> 463.105
C28: Acumulado | D28: =+SUM($D$27:D27) -> 688.03016 | E28: =+SUM($D$27:E27) -> 1160.2852 | F28: =+SUM($D$27:F27) -> 1568.4371 | G28: =+SUM($D$27:G27) -> 1919.4465 | H28: =+SUM($D$27:H27) -> 2408.8009 | I28: =+SUM($D$27:I27) -> 2795.1254 | J28: =+SUM($D$27:J27) -> 3250.2779 | K28: =+SUM($D$27:K27) -> 3726.625 | ... O28: =+SUM($D$27:O27) -> 5557.26
D29: =+D28/$O$28 -> 0.12380744 | E29: =+E28/$O$28 -> 0.20878728 | F29: =+F28/$O$28 -> 0.28223209 | G29: =+G28/$O$28 -> 0.3453944 | H29: =+H28/$O$28 -> 0.43345118 | I29: =+I28/$O$28 -> 0.50296826 | J29: =+J28/$O$28 -> 0.58487058 | K29: =+K28/$O$28 -> 0.67058676 | ... O29: =+O28/$O$28 -> 1
E31: =+(E27-D27)/D27 -> -0.31361288 | F31: =+(F27-E27)/E27 -> -0.13573839 | G31: =+(G27-F27)/F27 -> -0.14000304 | H31: =+(H27-G27)/G27 -> 0.39413486 | I31: =+(I27-H27)/H27 -> -0.21054258 | J31: =+(J27-I27)/I27 -> 0.17816111 | K31: =+(K27-J27)/J27 -> 0.0465659 | L31: =+(L27-K27)/K27 -> -0.22561245 | ... O31: =+(O27-N27)/N27 -> 0.19269656
C37: Gasto Proyectado REDCO con EEUU
C39: Item | D39: ene | E39: feb | F39: mar | G39: abr | H39: may | I39: jun | J39: jul | K39: ago | L39: sept | M39: oct | N39: nov | O39: dic | P39: Total | Q39: Promedio
C40: Chile | D40: 476.29051 | E40: 313.31492 | F40: 275.86855 | G40: 231.52127 | H40: 317.17005 | I40: 288.14494 | J40: 292.12749 | K40: 299.21779 | L40: 267.60024 | M40: 356.05444 | N40: 318.27454 | O40: 334.87696 | P40: =+SUM(D40:O40) -> 3770.4617 | Q40: =+AVERAGE(D40:O40) -> 314.20514
C41: Perú | D41: 167.14016 | E41: 109.66978 | F41: 119.90377 | G41: 98.13241 | H41: 125.25863 | I41: 82.824806 | J41: 139.674 | K41: 152.09422 | L41: 73.594 | M41: 88.14845 | N41: 112.788 | O41: 159.18262 | P41: =+SUM(D41:O41) -> 1428.4109 | Q41: =+AVERAGE(D41:O41) -> 119.03424
C42: Brasil | D42: 44.59949 | E42: 49.27034 | F42: 12.37958 | G42: 21.355715 | H42: 46.92575 | I42: 15.35474 | J42: 23.351 | K42: 25.03507 | L42: 27.683 | M42: 42.455 | N42: 13.641 | O42: 36.3368 | P42: =+SUM(D42:O42) -> 358.38748 | Q42: =+AVERAGE(D42:O42) -> 29.865624
C43: EEUU | D43: 0 | E43: 0 | F43: 29.806 | G43: 0 | H43: 33.409 | I43: 8.512 | J43: 71.468 | K43: 61.963 | L43: 14.9 | M43: 32.355 | N43: 7.5 | O43: 150.67 | P43: =+SUM(D43:O43) -> 410.583 | Q43: =+AVERAGE(D43:O43) -> 34.21525
C44: Total | D44: =+SUM(D40:D43) -> 688.03016 | E44: =+SUM(E40:E43) -> 472.25504 | F44: =+SUM(F40:F43) -> 437.9579 | G44: =+SUM(G40:G43) -> 351.0094 | H44: =+SUM(H40:H43) -> 522.76343 | I44: =+SUM(I40:I43) -> 394.83649 | J44: =+SUM(J40:J43) -> 526.62049 | K44: =+SUM(K40:K43) -> 538.31008 | ... Q44: =+SUM(Q40:Q43) -> 497.32025
C47: Item | D47: ene | E47: feb | F47: mar | G47: abr | H47: may | I47: jun | J47: jul | K47: ago | L47: sept | M47: oct | N47: nov | O47: dic | P47: Total | Q47: Promedio | R47: P2025
C48: Sueldos | D48: 344.70391 | E48: 313.86733 | F48: 332.5578 | G48: 271.76518 | H48: 381.94289 | I48: 266.57109 | J48: 407.31932 | K48: 375.94014 | L48: 286.92174 | M48: 356.79323 | N48: 318.18725 | O48: 488.7877 | P48: =+SUM(D48:O48) -> 4145.3576 | Q48: =+AVERAGE(D48:O48) -> 345.44647 | R48: =+P48+300+120 -> 4565.3576 | S48: =+(R48-P48)/P48 -> 0.10131816
C49: Oficina | D49: 67.486891 | E49: 43.518066 | F49: 36.558028 | G49: 37.661349 | H49: 56.954104 | I49: 42.344468 | J49: 56.94287 | K49: 42.07897 | L49: 48.093315 | M49: 56.748175 | N49: 51.180095 | O49: 80.809693 | P49: =+SUM(D49:O49) -> 620.37602 | Q49: =+AVERAGE(D49:O49) -> 51.698002 | R49: =+P49 -> 620.37602 | S49: =+(R49-P49)/P49 -> 0
C50: Otros gastos | D50: 215.39669 | E50: 62.837275 | F50: 30.924698 | G50: 35.044196 | H50: 39.778305 | I50: 15.212737 | J50: 24.566011 | K50: 25.528199 | L50: 21.856405 | M50: 45.948439 | N50: 47.631579 | O50: 45.24028 | P50: =+SUM(D50:O50) -> 609.96482 | Q50: =+AVERAGE(D50:O50) -> 50.830401 | R50: =+P50/P48*R48 -> 671.76533 | S50: =+(R50-P50)/P50 -> 0.10131816
C51: Externo | D51: 60.442668 | E51: 52.032368 | F51: 37.917372 | G51: 6.5386728 | H51: 44.088135 | I51: 70.708193 | J51: 37.792285 | K51: 94.762768 | L51: 26.905788 | M51: 59.523048 | N51: 35.204613 | O51: 66.228705 | P51: =+SUM(D51:O51) -> 592.14461 | Q51: =+AVERAGE(D51:O51) -> 49.345384 | R51: =+P51/P48*R48 -> 652.13962 | S51: =+(R51-P51)/P51 -> 0.10131816
C52: Total | D52: =+SUM(D48:D51) -> 688.03016 | E52: =+SUM(E48:E51) -> 472.25504 | F52: =+SUM(F48:F51) -> 437.9579 | G52: =+SUM(G48:G51) -> 351.0094 | H52: =+SUM(H48:H51) -> 522.76343 | I52: =+SUM(I48:I51) -> 394.83649 | J52: =+SUM(J48:J51) -> 526.62049 | K52: =+SUM(K48:K51) -> 538.31008 | ... R52: =+SUM(R48:R51) -> 6509.6386
C53: Acumulado | D53: =+SUM($D$52:D52) -> 688.03016 | E53: =+SUM($D$52:E52) -> 1160.2852 | F53: =+SUM($D$52:F52) -> 1598.2431 | G53: =+SUM($D$52:G52) -> 1949.2525 | H53: =+SUM($D$52:H52) -> 2472.0159 | I53: =+SUM($D$52:I52) -> 2866.8524 | J53: =+SUM($D$52:J52) -> 3393.4729 | K53: =+SUM($D$52:K52) -> 3931.783 | ... O53: =+SUM($D$52:O52) -> 5967.843 | R53: 9660
P55: 8275 | R55: =+R53-R52 -> 3150.3614
...

Sheet Ingresos para PPT_Dic
B3: Pais | C3: 45292 | D3: 45323 | E3: 45352 | F3: 45383 | G3: 45413 | H3: 45444 | I3: 45474 | J3: 45505 | K3: 45536 | L3: 45566 | M3: 45597 | N3: 45627
B4: Gran Total | C4: 782.47265 | D4: 579.08373 | E4: 663.71177 | F4: 492.6642 | G4: 817.072 | H4: 398.011 | I4: 464.29877 | J4: 672.28596 | K4: 1311.681 | L4: 1003.5651 | M4: 614.74 | N4: 475.262 | O4: =+SUM(C4:N4) -> 8274.8482 | R4: =+AVERAGE(C4:I4) -> 599.6163 | S4: =+MEDIAN(C4:I4) -> 579.08373
B5: Finalizado | C5: 667.3589 | D5: 532.92403 | E5: 468.64003 | F5: 461.52255 | G5: 641.341 | H5: 189.42 | I5: 229.80636 | J5: 456.18696 | K5: 887.187 | L5: 334.20609 | M5: 161.027 | N5: 9.928 | O5: =+SUM(C5:N5) -> 5039.5479 | P5: =+O5/$O$4 -> 0.60901999 | R5: =+(K4-R4)/R4 -> 1.1875339
B6: Ejecución | C6: 115.11375 | D6: 46.1597 | E6: 195.07174 | F6: 31.14165 | G6: 175.731 | H6: 208.591 | I6: 234.49241 | J6: 216.099 | K6: 424.494 | L6: 669.359 | M6: 453.713 | N6: 465.334 | O6: =+SUM(C6:N6) -> 3235.3003 | P6: =+O6/$O$4 -> 0.39098001
B7: Pipeline | C7: 0 | D7: 0 | E7: 0 | F7: 0 | G7: 0 | H7: 0 | I7: 0 | J7: 0 | K7: 0 | L7: 0 | M7: 0 | N7: 0 | O7: =+SUM(C7:N7) -> 0 | P7: =+O7/$O$4 -> 0 | R7: =+AVERAGE(C4:N4) -> 689.57068 | U7: País | V7: kUSD
B8: Chile | C8: 427.78565 | D8: 203.47573 | E8: 294.69749 | F8: 239.0302 | G8: 253.288 | H8: 181.519 | I8: 199.83051 | J8: 191.73696 | K8: 305.343 | L8: 505.285 | M8: 354.326 | N8: 214.111 | O8: =+SUM(C8:N8) -> 3370.4285 | P8: =+O8/$O$4 -> 0.40731002 | R8: =+_xlfn.STDEV.P(C4:N4) -> 249.95506 | U8: Chile | V8: =+_xlfn.XLOOKUP(U8,B:B,O:O,"!",0,1) -> 3370.4285 | W8: =+V8/$V$13 -> 0.40731002
B9: Perú | C9: 165.529 | D9: 97.072 | E9: 127.385 | F9: 76.133 | G9: 107.922 | H9: 172.201 | I9: 189.28926 | J9: 185.957 | K9: 387.972 | L9: 293.429 | M9: 155.905 | N9: 119.107 | O9: =+SUM(C9:N9) -> 2077.9013 | P9: =+O9/$O$4 -> 0.2511105 | R9: =+R8/R7 -> 0.36247925 | U9: Perú | V9: =+_xlfn.XLOOKUP(U9,B:B,O:O,"!",0,1) -> 2077.9013 | W9: =+V9/$V$13 -> 0.2511105
B10: Brasil | C10: 189.158 | D10: 225.732 | E10: 78.64628 | F10: 74.596 | G10: 267.262 | H10: 0 | I10: 23.44 | J10: 144.771 | K10: 0 | L10: 128.80109 | M10: 58.584 | N10: 19.954 | O10: =+SUM(C10:N10) -> 1210.9444 | P10: =+O10/$O$4 -> 0.14634037 | U10: EEUU | V10: =+_xlfn.XLOOKUP(U10,B:B,O:O,"!",0,1) -> 1463.474 | W10: =+V10/$V$13 -> 0.17685811
B11: Rusia | C11: 0 | D11: 0 | E11: 0 | F11: 0 | G11: 0 | H11: 0 | I11: 0 | J11: 0 | K11: 0 | L11: 76.05 | M11: 0 | N11: 76.05 | O11: =+SUM(C11:N11) -> 152.1 | P11: =+O11/$O$4 -> 0.018381002 | U11: Brasil | V11: =+_xlfn.XLOOKUP(U11,B:B,O:O,"!",0,1) -> 1210.9444 | W11: =+V11/$V$13 -> 0.14634037
B12: EEUU | C12: 0 | D12: 52.804 | E12: 162.983 | F12: 102.905 | G12: 188.6 | H12: 44.291 | I12: 51.739 | J12: 149.821 | K12: 618.366 | L12: 0 | M12: 45.925 | N12: 46.04 | O12: =+SUM(C12:N12) -> 1463.474 | P12: =+O12/$O$4 -> 0.17685811 | U12: Rusia | V12: =+_xlfn.XLOOKUP(U12,B:B,O:O,"!",0,1) -> 152.1 | W12: =+V12/$V$13 -> 0.018381002
B13: Nro. de Proyectos | C13: 10 | D13: 14 | E13: 14 | F13: 13 | G13: 14 | H13: 8 | I13: 13 | J13: 14 | K13: 13 | L13: 22 | M13: 15 | N13: 14 | O13: =+AVERAGE(C13:N13) -> 13.666667 | V13: =+SUM(V8:V12) -> 8274.8482
B14: Acumulado | C14: 782.47265 | D14: 1361.5564 | E14: 2025.2682 | F14: 2517.9324 | G14: 3335.0044 | H14: 3733.0154 | I14: 4197.3141 | J14: 4869.6001 | K14: 6181.2811 | L14: 7184.8462 | M14: 7799.5862 | N14: 8274.8482
C15: =+C14/$N$14 -> 0.094560363 | D15: =+D14/$N$14 -> 0.16454155 | E15: =+E14/$N$14 -> 0.24474989 | F15: =+F14/$N$14 -> 0.30428744 | G15: =+G14/$N$14 -> 0.40302907 | H15: =+H14/$N$14 -> 0.45112796 | I15: =+I14/$N$14 -> 0.5072376 | J15: =+J14/$N$14 -> 0.58848211 | ... N15: =+N14/$N$14 -> 1
D16: =+(D14-C14)/C14 -> 0.74006897 | E16: =+(E14-D14)/D14 -> 0.48746551 | F16: =+(F14-E14)/E14 -> 0.24325875 | G16: =+(G14-F14)/F14 -> 0.32450117 | H16: =+(H14-G14)/G14 -> 0.11934347 | I16: =+(I14-H14)/H14 -> 0.12437633 | J16: =+(J14-I14)/I14 -> 0.16017051 | K16: =+(K14-J14)/J14 -> 0.26936113 | ... N16: =+(N14-M14)/M14 -> 0.060934259

Sheet Gasto Noviembre_Pruebas
A2: Clasificación 1 | B2: (Varios elementos)
A3: País | B3: (Todas)
A5: Suma de Valor USD | E5: Meses (Atributo)
A6: Clasificación 0 | B6: Clasificación 2 | C6: Clasificación 3 | D6: Detalle | E6: ene | F6: feb | G6: mar | H6: abr | I6: may | J6: jun | K6: jul | L6: ago | M6: sept | N6: oct | O6: nov | P6: dic
A7: Fijo | B7: Sueldos | E7: 302229.93 | F7: 278427.94 | G7: 288746.19 | H7: 271765.18 | I7: 312956.31 | J7: 232896.54 | K7: 335584.67 | L7: 306031.46 | M7: 271556.13 | N7: 268591.11 | O7: 274838.8 | P7: 312370.57
A8: Fijo | B8: Oficina | E8: 35918.38 | F8: 22497.787 | G8: 23276.092 | H8: 28010.34 | I8: 36031.921 | J8: 31987.272 | K8: 32369.19 | L8: 31539.816 | M8: 29697.572 | N8: 39183.383 | O8: 28484.811 | P8: 31457.659
A9: Fijo | B9: Externo | E9: 4375.7069 | F9: 3900.039 | G9: 7037.4952 | H9: 2996.3265 | I9: 7545.7184 | J9: 4977.1768 | K9: 15134.918 | L9: 4103.9086 | M9: 3849.295 | N9: 4361.7377 | O9: 3517.1534 | P9: 3746.6714
A10: Fijo | B10: Extras personas | E10: 4574.0405 | F10: 4427.5118 | G10: 5067.7415 | H10: 2404.6587 | I10: 5844.4873 | J10: 3856.6463 | K10: 4005.1474 | L10: 4380.3484 | M10: 4268.1498 | N10: 3748.5195 | O10: 1681.9514 | P10: 3497.8842
A11: Fijo | B11: Bancarios | E11: 1010.502 | F11: 719.11981 | G11: 472.28157 | H11: 364.44023 | I11: 813.85956 | J11: 1642.0746 | K11: 2169.2001 | L11: 1194.0144 | M11: 1128.0279 | N11: 864.12444 | O11: 1479.8837 | P11: 779.89359
A12: Fijo | B12: Comercial | E12: 917.41098 | F12: 864.61015 | G12: 1721.1988 | H12: 0 | I12: 1815.0521 | J12: 899.49032 | K12: 888.47647 | L12: 895.79525 | M12: 1130.6291 | N12: 892.04442 | O12: 2363.8329 | P12: 882.53679
A13: Fijo | B13: Compañía | C13: EERR | E13: 1186.458 | F13: 2675.0934 | G13: 2662.6843 | H13: 2684.2877 | I13: 2807.8747 | J13: 0 | K13: 2748.9355 | L13: 5543.1595 | M13: 2782.6217 | N13: 2759.9747 | O13: 2652.6266 | P13: 2730.5582
A14: Total Fijo | E14: 350212.43 | F14: 313512.11 | G14: 328983.69 | H14: 308225.23 | I14: 367815.22 | J14: 276259.2 | K14: 392900.54 | L14: 353688.5 | M14: 314412.42 | N14: 320400.89 | O14: 315019.06 | P14: 355465.77
A15: Variable | B15: Externo | E15: 58575.039 | F15: 39286.56 | G15: 18316.29 | H15: 0 | I15: 38476.159 | J15: 25502.568 | K15: 208.13136 | L15: 8434.9704 | M15: 284.10677 | N15: 34449.165 | O15: 39900.403 | P15: 1442
A16: Variable | B16: Viajes | E16: 70940.38 | F16: 15541.723 | G16: 6425.1697 | H16: 19654.064 | I16: 11217.311 | J16: 6643.918 | K16: 10766.462 | L16: 12765.451 | M16: 12095.977 | N16: 8598.2621 | O16: 1440.6731 | P16: 8082
A17: Variable | B17: Oficina | E17: 10816.411 | F17: 13200.409 | G17: 1814.9526 | H17: 6654.6824 | I17: 10477.886 | J17: 4725.0585 | K17: 9230.6307 | L17: 5569.5698 | M17: 14262.341 | N17: 8426.0828 | O17: 14101.602 | P17: 4858.734
A18: Variable | B18: Extras personas | E18: 124824.13 | F18: 36004.252 | G18: 14575.623 | H18: 9936.7454 | I18: 12607.319 | J18: 2170.6079 | K18: 1077.6459 | L18: 546.83891 | M18: 451 | N18: 25761.82 | O18: 27886.439 | P18: 452
A19: Variable | B19: Sueldos | E19: 275.33343 | F19: 72.656315 | G19: 118.81024 | H19: 0 | I19: 0 | J19: 314.94795 | K19: 266.6496 | L19: 376.38456 | M19: 465.60715 | N19: 461.81771 | O19: 1024.5723 | P19: 456.89555
A20: Variable | B20: Compañía | C20: Boleta | D20: Boletas de garantía CMP Comisión+i | E20: 1040.5875 | F20: 519.3245 | G20: 0 | H20: 0 | I20: 4112.9766 | J20: 0 | K20: 2910.1434 | L20: 202.59168 | M20: 0 | N20: 0 | O20: 10693.744 | P20: 530.09207
A21: Variable | B21: Compañía | C21: Boleta | D21: Boletas de garantía CMP intereses | E21: 10674.306 | F21: 0 | G21: 0 | H21: 0 | I21: 0 | J21: 0 | K21: 0 | L21: 0 | M21: 0 | N21: 0 | O21: 0 | P21: 0
A22: Variable | B22: Compañía | C22: EERR | E22: 0 | F22: 2085.641 | G22: 0 | H22: 0 | I22: 0 | J22: 0 | K22: 0 | L22: 0 | M22: 0 | N22: 0 | O22: 0 | P22: 0
A23: Variable | B23: Comercial | E23: 228.87697 | F23: 0 | G23: 0 | H23: 0 | I23: 559.42498 | J23: 0 | K23: 0 | L23: 0 | M23: 0 | N23: 0 | O23: 0 | P23: 0
A24: Total Variable | E24: 277375.06 | F24: 106710.57 | G24: 41250.845 | H24: 36245.492 | I24: 77451.076 | J24: 39357.101 | K24: 24459.663 | L24: 27895.807 | M24: 27559.032 | N24: 77697.147 | O24: 95047.435 | P24: 15821.722
A25: Adicionales | B25: Externo | E25: 60442.668 | F25: 52032.368 | G25: 37917.372 | H25: 6538.6728 | I25: 44088.135 | J25: 70708.193 | K25: 37792.285 | L25: 94762.768 | M25: 26905.788 | N25: 59523.048 | O25: 35204.613 | P25: 0
A26: Total Adicionales | E26: 60442.668 | F26: 52032.368 | G26: 37917.372 | H26: 6538.6728 | I26: 44088.135 | J26: 70708.193 | K26: 37792.285 | L26: 94762.768 | M26: 26905.788 | N26: 59523.048 | O26: 35204.613 | P26: 0
A27: Total general | E27: 688030.16 | F27: 472255.04 | G27: 408151.9 | H27: 351009.4 | I27: 489354.43 | J27: 386324.49 | K27: 455152.49 | L27: 476347.08 | M27: 368877.24 | N27: 457621.08 | O27: 445271.11 | P27: 371287.49
D29: Costo Directo | E29: 300430.87 | F29: 321466.3 | G29: 291430.23 | H29: 301846.1 | I29: 343761.08 | J29: 307715.81 | K29: 412320.75 | L29: 318179.89 | M29: 274659.87 | N29: 311374.2 | U29: Costo Directo | V29: 150215.44 | W29: 160733.15 | X29: 145715.11 | Y29: 150923.05 | Z29: 171880.54 | AA29: 153857.9 | AB29: 206160.38 | AC29: 159089.95 | AD29: 137329.94 | AE29: 155687.1
D30: Gasto Sueldos | E30: =[1]Sueldos!G107 -> 3345.9327 | F30: =[1]Sueldos!H107 -> 2746.0803 | G30: =[1]Sueldos!I107 -> 2790.9983 | H30: =[1]Sueldos!J107 -> 2849.6109 | I30: =[1]Sueldos!K107 -> 3928.1958 | J30: =[1]Sueldos!L107 -> 2691.4163 | K30: =[1]Sueldos!M107 -> 0 | L30: =[1]Sueldos!N107 -> 0 | ... P30: =[1]Sueldos!R107 -> 0
D31: Delta | E31: =+E30-E29 -> -297084.94 | F31: =+F30-F29 -> -318720.22 | G31: =+G30-G29 -> -288639.23 | H31: =+H30-H29 -> -298996.49 | I31: =+I30-I29 -> -339832.89 | J31: =+J30-J29 -> -305024.39 | K31: =+K30-K29 -> -412320.75 | L31: =+L30-L29 -> -318179.89 | ... N31: =+N30-N29 -> -311374.2
E32: =+E31/E30 -> -88.789875 | F32: =+F31/F30 -> -116.06369 | G32: =+G31/G30 -> -103.41791 | H32: =+H31/H30 -> -104.92537 | I32: =+I31/I30 -> -86.511188 | J32: =+J31/J30 -> -113.3323 | K32: =+K31/K30 -> #DIV/0! | L32: =+L31/L30 -> #DIV/0! | ... N32: =+N31/N30 -> #DIV/0!
T33: 48000
D35: % Sueldo | E35: =+E30/E25 -> 0.055357131 | F35: =+F30/F25 -> 0.052776385 | G35: =+G30/G25 -> 0.073607379 | H35: =+H30/H25 -> 0.43580876 | I35: =+I30/I25 -> 0.089098708 | J35: =+J30/J25 -> 0.038063711 | K35: =+K30/K25 -> 0 | L35: =+L30/L25 -> 0 | ... P35: =+P30/P25 -> #DIV/0!
D38: Gasto Otros | E38: =+E25-E30 -> 57096.735 | F38: =+F25-F30 -> 49286.288 | G38: =+G25-G30 -> 35126.373 | H38: =+H25-H30 -> 3689.0619 | I38: =+I25-I30 -> 40159.939 | J38: =+J25-J30 -> 68016.777 | K38: =+K25-K30 -> 37792.285 | L38: =+L25-L30 -> 94762.768 | ... P38: =+P25-P30 -> 0
E39: =+E38/E25 -> 0.94464287 | F39: =+F38/F25 -> 0.94722361 | G39: =+G38/G25 -> 0.92639262 | H39: =+H38/H25 -> 0.56419124 | I39: =+I38/I25 -> 0.91090129 | J39: =+J38/J25 -> 0.96193629 | K39: =+K38/K25 -> 1 | L39: =+L38/L25 -> 1 | ... P39: =+P38/P25 -> #DIV/0!

Sheet Hoja3
B1: 45292 | C1: 45323 | D1: 45352 | E1: 45383 | F1: 45413 | G1: 45444 | H1: 45474 | I1: 45505 | J1: 45536 | K1: 45566 | L1: 45597 | M1: 45627
A2: Gastos del dueño | B2: 298.83699 | C2: 1268.2741 | D2: 171.39669 | E2: 18069.475 | F2: 537.09853 | G2: 1587.9773 | H2: 373.9238 | I2: 22887.263 | J2: 410.05603 | K2: 113.05512 | L2: 52579.889 | M2: 20707.212
A3: REDTEC | B3: 1060.3246 | C3: 70628.998 | D3: 8560.529 | E3: 6450 | F3: 12531 | G3: 8690.9461 | H3: 10711.144 | I3: 10163.703 | J3: 9855.4696 | K3: 18252.545 | L3: 115687.99 | M3: 6886
A8: Ingresos
A9: Chile | B9: 491038355 | C9: 328098423 | D9: 344330410 | E9: 238698876 | F9: 348792953 | G9: 141091125 | H9: 326660345 | I9: 3.1477254e+08 | J9: 585454974 | K9: 516832647 | L9: 411995131 | M9: 358257483
A10: Perú | B10: 205682.23 | C10: 117395.19 | D10: 147879.94 | E10: 90961 | F10: 120651 | G10: 184899 | H10: 235161 | I10: 222913 | J10: 455729 | K10: 356456 | L10: 202065 | M10: 139885
A11: Brasil
A12: EEUU

Sheet Gasto Diciembre (3)
A2: Clasificación 1 | B2: (Varios elementos)
A3: País | B3: (Todas)
A5: Suma de Valor USD | E5: Meses (Atributo)
A6: Clasificación 0 | B6: Clasificación 2 | C6: Clasificación 3 | D6: Detalle | E6: ene | F6: feb | G6: mar | H6: abr | I6: may | J6: jun | K6: jul | L6: ago | M6: sept | N6: oct | O6: nov | P6: dic
A7: Fijo | B7: Sueldos | C7: Asociado a sueldo | D7: Ricardo Miranda | E7: 0 | F7: 1467.7533 | G7: 0 | H7: 0 | I7: 260.87986 | J7: 0 | K7: 0 | L7: 0 | M7: 0 | N7: 0 | O7: 0 | P7: 0 | R7: =+IF(P7>0,1,0) -> 0
A8: Fijo | B8: Sueldos | C8: Sueldo | D8: Alejandro Espinosa | E8: 8612.8752 | F8: 8256.7911 | G8: 8277.5328 | H8: 8177.8985 | I8: 8346.2575 | J8: 8561.1387 | K8: 8384.322 | L8: 0 | M8: 12470.381 | N8: 0 | O8: 0 | P8: 0 | R8: =+IF(P8>0,1,0) -> 0
A9: Fijo | B9: Sueldos | C9: Sueldo | D9: Alex Figueroa | E9: 8425.1203 | F9: 8065.6523 | G9: 8084.2266 | H9: 9000.5222 | I9: 9188.1821 | J9: 9427.2681 | K9: 9215.5727 | L9: 9646.0851 | M9: 9698.6681 | N9: 8989.0109 | O9: 8785.0906 | P9: 8896.3497 | R9: =+IF(P9>0,1,0) -> 1
A10: Fijo | B10: Sueldos | C10: Sueldo | D10: Alex Pacheco C. | E10: 2947.9802 | F10: 2825.3146 | G10: 2831.856 | H10: 2796.9641 | I10: 2854.5881 | J10: 2927.2905 | K10: 2944.313 | L10: 3029.1555 | M10: 3023.0005 | N10: 2797.3888 | O10: 2733.6622 | P10: 3505.8177 | Q10: =+SUM(E10:P10) -> 35217.331 | R10: =+IF(P10>0,1,0) -> 1
A11: Fijo | B11: Sueldos | C11: Sueldo | D11: Americo Zuzunaga | E11: 15627.149 | F11: 12771.726 | G11: 12720.817 | H11: 13033.347 | I11: 18057.936 | J11: 12583.422 | K11: 24597.319 | L11: 21641.216 | M11: 12712.144 | N11: 0 | O11: 0 | P11: 0 | R11: =+IF(P11>0,1,0) -> 0
A12: Fijo | B12: Sueldos | C12: Sueldo | D12: Andree del Castillo | E12: 3378.5173 | F12: 2772.8232 | G12: 2818.1787 | H12: 2877.3642 | I12: 3966.4574 | J12: 3082.1981 | K12: 13291.234 | L12: 0 | M12: 0 | N12: 0 | O12: 0 | P12: 0 | R12: =+IF(P12>0,1,0) -> 0
A13: Fijo | B13: Sueldos | C13: Sueldo | D13: Andrés Budini M. | E13: 3630.5471 | F13: 3477.3079 | G13: 1991.6571 | H13: 3438.5715 | I13: 3509.267 | J13: 3598.4542 | K13: 3608.7223 | L13: 3694.1883 | M13: 3770.5848 | N13: 6794.0432 | O13: 0 | P13: 0 | R13: =+IF(P13>0,1,0) -> 0
A14: Fijo | B14: Sueldos | C14: Sueldo | D14: Angelo Patri Carbajal | E14: 655.65172 | F14: 658.4 | G14: 671.8624 | H14: 334.76 | I14: 0 | J14: 0 | K14: 0 | L14: 0 | M14: 0 | N14: 0 | O14: 0 | P14: 0 | R14: =+IF(P14>0,1,0) -> 0
A15: Fijo | B15: Sueldos | C15: Sueldo | D15: Arnold Tadeo | E15: 3002.0235 | F15: 1495.2351 | G15: 1519.6929 | H15: 1551.6122 | I15: 2138.8881 | J15: 1465.4653 | K15: 2922.7402 | L15: 2520.336 | M15: 1497.0419 | N15: 2305.4657 | O15: 2706.7812 | P15: 2868.3641 | R15: =+IF(P15>0,1,0) -> 1
A16: Fijo | B16: Sueldos | C16: Sueldo | D16: CARLOS CARMELO HIDALGO | E16: 4101.7571 | F16: 0 | G16: 0 | H16: 0 | I16: 0 | J16: 0 | K16: 0 | L16: 0 | M16: 0 | N16: 0 | O16: 0 | P16: 0 | R16: =+IF(P16>0,1,0) -> 0
A17: Fijo | B17: Sueldos | C17: Sueldo | D17: Carlos Catalán | E17: 3582.3951 | F17: 2930.091 | G17: 2960.0891 | H17: 3022.2491 | I17: 4166.1994 | J17: 2854.4678 | K17: 6129.0731 | L17: 5367.0215 | M17: 2946.2263 | N17: 5676.5791 | O17: 6661.5991 | P17: 7066.0392 | R17: =+IF(P17>0,1,0) -> 1
A18: Fijo | B18: Sueldos | C18: Sueldo | D18: Carlos Morante | E18: 3867.8791 | F18: 3174.4532 | G18: 3226.3782 | H18: 3294.14 | I18: 4540.9759 | J18: 3111.2584 | K18: 0 | L18: 0 | M18: 0 | N18: 0 | O18: 0 | P18: 0 | R18: =+IF(P18>0,1,0) -> 0
A19: Fijo | B19: Sueldos | C19: Sueldo | D19: Claudio Hernandez | E19: 10340.278 | F19: 9912.7777 | G19: 9941.9923 | H19: 9825.5356 | I19: 10030.851 | J19: 10291.81 | K19: 10050.912 | L19: 10530.224 | M19: 10562.402 | N19: 9818.5739 | O19: 9597.5381 | P19: 9600.55 | R19: =+IF(P19>0,1,0) -> 1
A20: Fijo | B20: Sueldos | C20: Sueldo | D20: Clinton Yahuira | E20: 655.65172 | F20: 658.4 | G20: 671.8624 | H20: 669.52 | I20: 666.13 | J20: 654.96 | K20: 668 | L20: 654.96 | M20: 0 | N20: 0 | O20: 0 | P20: 0 | R20: =+IF(P20>0,1,0) -> 0
A21: Fijo | B21: Sueldos | C21: Sueldo | D21: Cristián Alarcón | E21: 2214.8278 | F21: 2123.0161 | G21: 2524.1096 | H21: 2492.4647 | I21: 2543.443 | J21: 2451.1332 | K21: 2490.2273 | L21: 2842.5992 | M21: 2682.7516 | N21: 2497.4535 | O21: 2442.0531 | P21: 2706.5608 | R21: =+IF(P21>0,1,0) -> 1
A22: Fijo | B22: Sueldos | C22: Sueldo | D22: Cristián García | E22: 7950.2818 | F22: 8123.8317 | G22: 0 | H22: 0 | I22: 0 | J22: 0 | K22: 0 | L22: 0 | M22: 0 | N22: 0 | O22: 0 | P22: 0 | R22: =+IF(P22>0,1,0) -> 0
... A70: Fijo | B70: Sueldos | C70: Sueldo | D70: Nelson Rumino | E70: 8571.5704 | F70: 8217.194 | G70: 8208.0735 | H70: 5202.6789 | I70: 9345.9367 | J70: 0 | K70: 0 | L70: 0 | M70: 0 | N70: 0 | O70: 0 | P70: 0 | R70: =+IF(P70>0,1,0) -> 0
A71: Fijo | B71: Sueldos | C71: Sueldo | D71: Nicolás Ayarza D. | E71: 2947.789 | F71: 2825.1313 | G71: 4206.8493 | H71: 4151.3789 | I71: 4233.1904 | J71: 4337.9801 | K71: 4333.4784 | L71: 4449.8019 | M71: 4531.7376 | N71: 4126.6661 | O71: 4030.0378 | P71: 4312.2767
A72: Fijo | B72: Sueldos | C72: Sueldo | D72: Nicolás Sanzana | E72: 1938.2542 | F72: 1857.877 | G72: 2243.653 | H72: 2215.5565 | I72: 2260.8933 | J72: 2318.0773 | K72: 2360.6434 | L72: 2386.5227 | M72: 2388.0888 | N72: 2221.8622 | O72: 2172.5817 | P72: 2448.8362 | R72: =+IF(P72>0,1,0) -> 1
A73: Fijo | B73: Sueldos | C73: Sueldo | D73: Nilcélio José Dos Santos | E73: 2829.304 | F73: 2609.6521 | G73: 3831.9996 | H73: 2879.8682 | I73: 1881.46 | J73: 3098.1 | K73: 4489.222 | L73: 2622.9914 | M73: 2724.3547 | N73: 2292.3891 | O73: 4295.2801 | P73: 3585.5581
A74: Fijo | B74: Sueldos | C74: Sueldo | D74: Olesya Dashavskaya | E74: 3341.2793 | F74: 3225.9169 | G74: 3130.9925 | H74: 3092.3157 | I74: 3155.957 | J74: 3447.4363 | K74: 3341.4649 | L74: 3754.8482 | M74: 3457.0857 | N74: 3177.1164 | O74: 3104.7693 | P74: 3458.5523 | R74: =+IF(P74>0,1,0) -> 1
A75: Fijo | B75: Sueldos | C75: Sueldo | D75: Omar Meléndez Huamán | E75: 1966.9552 | F75: 1975.2 | G75: 2015.5872 | H75: 0 | I75: 0 | J75: 0 | K75: 0 | L75: 0 | M75: 0 | N75: 0 | O75: 0 | P75: 0
A76: Fijo | B76: Sueldos | C76: Sueldo | D76: Oscar Cáceres servicios | E76: 0 | F76: 0 | G76: 6729.0529 | H76: 0 | I76: 0 | J76: 0 | K76: 0 | L76: 0 | M76: 0 | N76: 0 | O76: 0 | P76: 0 | R76: =+IF(P76>0,1,0) -> 0
A77: Fijo | B77: Sueldos | C77: Sueldo | D77: Osvaldo Ulloa | E77: 1462.6464 | F77: 720.92549 | G77: 0 | H77: 561.93443 | I77: 0 | J77: 0 | K77: 0 | L77: 0 | M77: 0 | N77: 0 | O77: 0 | P77: 0 | R77: =+IF(P77>0,1,0) -> 0
A78: Fijo | B78: Sueldos | C78: Sueldo | D78: Pablo Quiero | E78: 6116.6473 | F78: 5859.2992 | G78: 5868.7329 | H78: 5770.9611 | I78: 5886.5524 | J78: 6034.1019 | K78: 5965.323 | L78: 6181.7069 | M78: 6249.5378 | N78: 5733.3651 | O78: 5600.9214 | P78: 5820.3729 | R78: =+IF(P78>0,1,0) -> 1
A79: Fijo | B79: Sueldos | C79: Sueldo | D79: Paolo Tito | E79: 1994.709 | F79: 1637.1014 | G79: 1663.8797 | H79: 1698.8277 | I79: 6991.7565 | J79: 0 | K79: 0 | L79: 0 | M79: 0 | N79: 0 | O79: 274 | P79: 0 | Q79: =+SUM(E79:P79) -> 14260.274 | R79: =+IF(P79>0,1,0) -> 0
A80: Fijo | B80: Sueldos | C80: Sueldo | D80: Pedro Aguiluz P. | E80: 2955.3281 | F80: 2832.3588 | G80: 4206.8493 | H80: 4151.3955 | I80: 4233.2229 | J80: 4338.0264 | K80: 4333.526 | L80: 4449.8699 | M80: 4531.8154 | N80: 4135.1181 | O80: 4038.3857 | P80: 4441.1686
A81: Fijo | B81: Sueldos | C81: Sueldo | D81: Pedro Ccanto | E81: 655.65172 | F81: 658.4 | G81: 671.8624 | H81: 669.52 | I81: 666.13 | J81: 654.96 | K81: 0 | L81: 0 | M81: 0 | N81: 0 | O81: 0 | P81: 0
A82: Fijo | B82: Sueldos | C82: Sueldo | D82: Ricardo Miranda | E82: 9705.5518 | F82: 9689.2921 | G82: 9152.7915 | H82: 9549.1047 | I82: 10598.236 | J82: 0 | K82: 16952.004 | L82: 10605.981 | M82: 9094.1616 | N82: 15822.168 | O82: 13212.968 | P82: 13223.502 | R82: =+IF(P82>0,1,0) -> 1
A83: Fijo | B83: Sueldos | C83: Sueldo | D83: Rodrigo Cori Córdova | E83: 9029.0693 | F83: 6945.5798 | G83: 7059.1897 | H83: 7206.1373 | I83: 9933.6704 | J83: 6806.0767 | K83: 13571.932 | L83: 11704.079 | M83: 6955.7861 | N83: 13704.458 | O83: 13633.857 | P83: 14460.863 | R83: =+IF(P83>0,1,0) -> 1
A84: Fijo | B84: Sueldos | C84: Sueldo | D84: Rodrigo Pinto H. | E84: 0 | F84: 3372.6944 | G84: 0 | H84: 0 | I84: 0 | J84: 0 | K84: 0 | L84: 0 | M84: 0 | N84: 0 | O84: 0 | P84: 0 | R84: =+IF(P84>0,1,0) -> 0
A85: Fijo | B85: Sueldos | C85: Sueldo | D85: Roxana Avilés | E85: 1882.588 | F85: 1803.9649 | G85: 1806.7268 | H85: 1783.4191 | I85: 1819.1622 | J85: 1864.6137 | K85: 1921.339 | L85: 1910.8177 | M85: 1931.1291 | N85: 2260.7647 | O85: 2210.6205 | P85: 2045.9159 | R85: =+IF(P85>0,1,0) -> 1
A86: Fijo | B86: Sueldos | C86: Sueldo | D86: Sebastián González | E86: 1607.8029 | F86: 1541.0876 | G86: 1544.3975 | H86: 513.72151 | I86: 0 | J86: 0 | K86: 0 | L86: 0 | M86: 0 | N86: 0 | O86: 0 | P86: 0 | R86: =+IF(P86>0,1,0) -> 0
A87: Fijo | B87: Sueldos | C87: Sueldo | D87: Thalia Rimac | E87: 675.02842 | F87: 554.01063 | G87: 563.06825 | H87: 574.89325 | I87: 2217.0896 | J87: 0 | K87: 0 | L87: 0 | M87: 0 | N87: 0 | O87: 0 | P87: 0 | R87: =+IF(P87>0,1,0) -> 0
A88: Fijo | B88: Sueldos | C88: Sueldo | D88: Victor Arias | E88: 3478.5661 | F88: 2854.9355 | G88: 2901.6341 | H88: 2962.5717 | I88: 4083.919 | J88: 2798.1089 | K88: 5587.9321 | L88: 4820.2371 | M88: 2863.9713 | N88: 4406.9688 | O88: 5173.1396 | P88: 5490.1396 | R88: =+IF(P88>0,1,0) -> 1
A89: Fijo | B89: Sueldos | C89: Sueldo | D89: Victor Mohana Tapia | E89: 2200.2998 | F89: 1799.0398 | G89: 2524.1096 | H89: 2467.2148 | I89: 2517.6787 | J89: 2581.33 | K89: 2614.7413 | L89: 2655.4243 | M89: 2625.4619 | N89: 2467.1972 | O89: 2410.9698 | P89: 2683.0602 | R89: =+IF(P89>0,1,0) -> 1
...

Sheet Gasto Diciembre
A2: Clasificación 1 | B2: (Varios elementos)
A3: País | B3: (Todas)
A5: Suma de Valor USD | E5: Meses (Atributo) | U5: REDCO | V5: REDCROSS | W5: R+
A6: Clasificación 0 | B6: Clasificación 2 | C6: Clasificación 3 | D6: Detalle | E6: ene | F6: feb | G6: mar | H6: abr | I6: may | J6: jun | K6: jul | L6: ago | M6: sept | N6: oct | O6: nov | P6: dic
A7: Fijo | B7: Sueldos | C7: Asociado a sueldo | D7: Ricardo Miranda | E7: 0 | F7: 1467.7533 | G7: 0 | H7: 0 | I7: 260.87986 | J7: 0 | K7: 0 | L7: 0 | M7: 0 | N7: 0 | O7: 0 | P7: 0 | Q7: =+SUM(E7:P7) -> 1728.6331 | R7: 1 | S7: =+Q7*R7 -> 1728.6331 | U7: =+IF(P7>0,1,0) -> 0 | W7: =+IF(P7>0,1,0) -> 0
A8: Fijo | B8: Sueldos | C8: Sueldo | D8: Alejandro Espinosa | E8: 8612.8752 | F8: 8256.7911 | G8: 8277.5328 | H8: 8177.8985 | I8: 8346.2575 | J8: 8561.1387 | K8: 8384.322 | L8: 0 | M8: 12470.381 | N8: 0 | O8: 0 | P8: 0 | Q8: =+SUM(E8:P8) -> 71087.197 | R8: 1 | S8: =+Q8*R8 -> 71087.197 | U8: =+IF(P8>0,1,0) -> 0 | W8: =+IF(P8>0,1,0) -> 0
A9: Fijo | B9: Sueldos | C9: Sueldo | D9: Alex Figueroa | E9: 8425.1203 | F9: 8065.6523 | G9: 8084.2266 | H9: 9000.5222 | I9: 9188.1821 | J9: 9427.2681 | K9: 9215.5727 | L9: 9646.0851 | M9: 9698.6681 | N9: 8989.0109 | O9: 8785.0906 | P9: 8896.3497 | Q9: =+SUM(E9:P9) -> 107421.75 | R9: 1 | S9: =+Q9*R9 -> 107421.75 | U9: =+IF(P9>0,1,0) -> 1
A10: Fijo | B10: Sueldos | C10: Sueldo | D10: Alex Pacheco C. | E10: 2947.9802 | F10: 2825.3146 | G10: 2831.856 | H10: 2796.9641 | I10: 2854.5881 | J10: 2927.2905 | K10: 2944.313 | L10: 3029.1555 | M10: 3023.0005 | N10: 2797.3888 | O10: 2733.6622 | P10: 3505.8177 | Q10: =+SUM(E10:P10) -> 35217.331 | R10: 1 | S10: =+Q10*R10 -> 35217.331 | U10: =+IF(P10>0,1,0) -> 1
A11: Fijo | B11: Sueldos | C11: Sueldo | D11: Americo Zuzunaga | E11: 15627.149 | F11: 12771.726 | G11: 12720.817 | H11: 13033.347 | I11: 18057.936 | J11: 12583.422 | K11: 24597.319 | L11: 21641.216 | M11: 12712.144 | N11: 0 | O11: 0 | P11: 0 | Q11: =+SUM(E11:P11) -> 143745.07 | R11: 0 | S11: =+Q11*R11 -> 0 | U11: =+IF(P11>0,1,0) -> 0 | W11: =+IF(P11>0,1,0) -> 0
A12: Fijo | B12: Sueldos | C12: Sueldo | D12: Andree del Castillo | E12: 3378.5173 | F12: 2772.8232 | G12: 2818.1787 | H12: 2877.3642 | I12: 3966.4574 | J12: 3082.1981 | K12: 13291.234 | L12: 0 | M12: 0 | N12: 0 | O12: 0 | P12: 0 | Q12: =+SUM(E12:P12) -> 32186.772 | R12: 1 | S12: =+Q12*R12 -> 32186.772 | U12: =+IF(P12>0,1,0) -> 0 | W12: =+IF(P12>0,1,0) -> 0
A13: Fijo | B13: Sueldos | C13: Sueldo | D13: Andrés Budini M. | E13: 3630.5471 | F13: 3477.3079 | G13: 1991.6571 | H13: 3438.5715 | I13: 3509.267 | J13: 3598.4542 | K13: 3608.7223 | L13: 3694.1883 | M13: 3770.5848 | N13: 6794.0432 | O13: 0 | P13: 0 | Q13: =+SUM(E13:P13) -> 37513.343 | R13: 1 | S13: =+Q13*R13 -> 37513.343 | U13: =+IF(P13>0,1,0) -> 0 | W13: =+IF(P13>0,1,0) -> 0
A14: Fijo | B14: Sueldos | C14: Sueldo | D14: Angelo Patri Carbajal | E14: 655.65172 | F14: 658.4 | G14: 671.8624 | H14: 334.76 | I14: 0 | J14: 0 | K14: 0 | L14: 0 | M14: 0 | N14: 0 | O14: 0 | P14: 0 | Q14: =+SUM(E14:P14) -> 2320.6741 | R14: 1 | S14: =+Q14*R14 -> 2320.6741 | U14: =+IF(P14>0,1,0) -> 0 | W14: =+IF(P14>0,1,0) -> 0
A15: Fijo | B15: Sueldos | C15: Sueldo | D15: Arnold Tadeo | E15: 3002.0235 | F15: 1495.2351 | G15: 1519.6929 | H15: 1551.6122 | I15: 2138.8881 | J15: 1465.4653 | K15: 2922.7402 | L15: 2520.336 | M15: 1497.0419 | N15: 2305.4657 | O15: 2706.7812 | P15: 2868.3641 | Q15: =+SUM(E15:P15) -> 25993.646 | R15: 1 | S15: =+Q15*R15 -> 25993.646 | U15: =+IF(P15>0,1,0) -> 1
A16: Fijo | B16: Sueldos | C16: Sueldo | D16: CARLOS CARMELO HIDALGO | E16: 4101.7571 | F16: 0 | G16: 0 | H16: 0 | I16: 0 | J16: 0 | K16: 0 | L16: 0 | M16: 0 | N16: 0 | O16: 0 | P16: 0 | Q16: =+SUM(E16:P16) -> 4101.7571 | R16: 0 | S16: =+Q16*R16 -> 0 | U16: =+IF(P16>0,1,0) -> 0 | W16: =+IF(P16>0,1,0) -> 0
A17: Fijo | B17: Sueldos | C17: Sueldo | D17: Carlos Catalán | E17: 3582.3951 | F17: 2930.091 | G17: 2960.0891 | H17: 3022.2491 | I17: 4166.1994 | J17: 2854.4678 | K17: 6129.0731 | L17: 5367.0215 | M17: 2946.2263 | N17: 5676.5791 | O17: 6661.5991 | P17: 7066.0392 | Q17: =+SUM(E17:P17) -> 53362.03 | R17: 1 | S17: =+Q17*R17 -> 53362.03 | U17: =+IF(P17>0,1,0) -> 1
A18: Fijo | B18: Sueldos | C18: Sueldo | D18: Carlos Morante | E18: 3867.8791 | F18: 3174.4532 | G18: 3226.3782 | H18: 3294.14 | I18: 4540.9759 | J18: 3111.2584 | K18: 0 | L18: 0 | M18: 0 | N18: 0 | O18: 0 | P18: 0 | Q18: =+SUM(E18:P18) -> 21215.085 | R18: 1 | S18: =+Q18*R18 -> 21215.085 | U18: =+IF(P18>0,1,0) -> 0 | W18: =+IF(P18>0,1,0) -> 0
A19: Fijo | B19: Sueldos | C19: Sueldo | D19: Claudio Hernandez | E19: 10340.278 | F19: 9912.7777 | G19: 9941.9923 | H19: 9825.5356 | I19: 10030.851 | J19: 10291.81 | K19: 10050.912 | L19: 10530.224 | M19: 10562.402 | N19: 9818.5739 | O19: 9597.5381 | P19: 9600.55 | Q19: =+SUM(E19:P19) -> 120503.45 | R19: 1 | S19: =+Q19*R19 -> 120503.45 | U19: =+IF(P19>0,1,0) -> 1
A20: Fijo | B20: Sueldos | C20: Sueldo | D20: Clinton Yahuira | E20: 655.65172 | F20: 658.4 | G20: 671.8624 | H20: 669.52 | I20: 666.13 | J20: 654.96 | K20: 668 | L20: 654.96 | M20: 0 | N20: 0 | O20: 0 | P20: 0 | Q20: =+SUM(E20:P20) -> 5299.4841 | R20: 1 | S20: =+Q20*R20 -> 5299.4841 | U20: =+IF(P20>0,1,0) -> 0 | W20: =+IF(P20>0,1,0) -> 0
A21: Fijo | B21: Sueldos | C21: Sueldo | D21: Cristián Alarcón | E21: 2214.8278 | F21: 2123.0161 | G21: 2524.1096 | H21: 2492.4647 | I21: 2543.443 | J21: 2451.1332 | K21: 2490.2273 | L21: 2842.5992 | M21: 2682.7516 | N21: 2497.4535 | O21: 2442.0531 | P21: 2706.5608 | Q21: =+SUM(E21:P21) -> 30010.64 | R21: 1 | S21: =+Q21*R21 -> 30010.64 | U21: =+IF(P21>0,1,0) -> 1
A22: Fijo | B22: Sueldos | C22: Sueldo | D22: Cristián García | E22: 7950.2818 | F22: 8123.8317 | G22: 0 | H22: 0 | I22: 0 | J22: 0 | K22: 0 | L22: 0 | M22: 0 | N22: 0 | O22: 0 | P22: 0 | Q22: =+SUM(E22:P22) -> 16074.114 | R22: 0 | S22: =+Q22*R22 -> 0 | U22: =+IF(P22>0,1,0) -> 0 | W22: =+IF(P22>0,1,0) -> 0
A23: Fijo | B23: Sueldos | C23: Sueldo | D23: Cristian Quezada | E23: 0 | F23: 0 | G23: 8988.0921 | H23: 9037.1248 | I23: 9562.8774 | J23: 9618.1163 | K23: 9327.9782 | L23: 9841.642 | M23: 9929.0624 | N23: 6512.2778 | O23: 0 | P23: 0 | Q23: =+SUM(E23:P23) -> 72817.171 | R23: 1 | S23: =+Q23*R23 -> 72817.171 | U23: =+IF(P23>0,1,0) -> 0 | W23: =+IF(P23>0,1,0) -> 0
A24: Fijo | B24: Sueldos | C24: Sueldo | D24: Cristóbal García Wallis practicante | E24: 157.80001 | F24: 296.7861 | G24: 204.3325 | H24: 0 | I24: 0 | J24: 0 | K24: 0 | L24: 0 | M24: 0 | N24: 0 | O24: 0 | P24: 0 | Q24: =+SUM(E24:P24) -> 658.9186 | R24: 1 | S24: =+Q24*R24 -> 658.9186 | U24: =+IF(P24>0,1,0) -> 0 | W24: =+IF(P24>0,1,0) -> 0
A25: Fijo | B25: Sueldos | C25: Sueldo | D25: Daniela Oyarzo E. | E25: 1900.1613 | F25: 1821.3576 | G25: 2524.1096 | H25: 2492.4647 | I25: 2543.443 | J25: 2607.743 | K25: 2641.543 | L25: 2682.6035 | M25: 2682.7516 | N25: 2497.4535 | O25: 2442.0531 | P25: 2770.9919 | Q25: =+SUM(E25:P25) -> 29606.676 | R25: 1 | S25: =+Q25*R25 -> 29606.676 | U25: =+IF(P25>0,1,0) -> 1
A26: Fijo | B26: Sueldos | C26: Sueldo | D26: Diego Muñoz | E26: 1940.7741 | F26: 1860.2927 | G26: 1511.9865 | H26: 2215.5565 | I26: 2260.8933 | J26: 2318.0773 | K26: 3719.6206 | L26: 2386.5479 | M26: 2388.6901 | N26: 2221.8856 | O26: 2172.6046 | P26: 2448.8362 | Q26: =+SUM(E26:P26) -> 27445.765 | R26: 1 | S26: =+Q26*R26 -> 27445.765 | U26: =+IF(P26>0,1,0) -> 1
A27: Fijo | B27: Sueldos | C27: Sueldo | D27: Diego Troncoso | E27: 1616.1771 | F27: 1549.1156 | G27: 1552.441 | H27: 1533.0899 | I27: 1564.5228 | J27: 1078.9067 | K27: 0 | L27: 0 | M27: 0 | N27: 0 | O27: 0 | P27: 0 | Q27: =+SUM(E27:P27) -> 8894.2531 | R27: 1 | S27: =+Q27*R27 -> 8894.2531 | U27: =+IF(P27>0,1,0) -> 0 | W27: =+IF(P27>0,1,0) -> 0
A28: Fijo | B28: Sueldos | C28: Sueldo | D28: Eduardo Cuevas | E28: 2585.6758 | F28: 2478.5321 | G28: 3505.7078 | H28: 3458.9533 | I28: 3526.4912 | J28: 3613.3574 | K28: 3633.3522 | L28: 3709.3411 | M28: 3796.5793 | N28: 3453.7916 | O28: 3377.268 | P28: 3667.6687 | Q28: =+SUM(E28:P28) -> 40806.719 | R28: 0 | S28: =+Q28*R28 -> 0 | U28: =+IF(P28>0,1,0) -> 1
A29: Fijo | B29: Sueldos | C29: Sueldo | D29: Eduardo Lama | E29: 2045.6334 | F29: 2054.3 | G29: 2096.2107 | H29: 2088.91 | I29: 2078.34 | J29: 2043.49 | K29: 2084 | L29: 2043.49 | M29: 2518 | N29: 5798.04 | O29: 6807.4736 | P29: 7221.9285 | Q29: =+SUM(E29:P29) -> 38879.816 | R29: 0 | S29: =+Q29*R29 -> 0 | U29: =+IF(P29>0,1,0) -> 1
A30: Fijo | B30: Sueldos | C30: Sueldo | D30: Edward Torres | E30: 1683.1014 | F30: 1381.3582 | G30: 1403.9533 | H30: 1433.4381 | I30: 1976.0055 | J30: 1353.8577 | K30: 2699.9175 | L30: 2328.3911 | M30: 1383.3804 | N30: 2129.0036 | O30: 2498.775 | P30: 2650.119 | Q30: =+SUM(E30:P30) -> 22921.301 | R30: 1 | S30: =+Q30*R30 -> 22921.301 | U30: =+IF(P30>0,1,0) -> 1
A31: Fijo | B31: Sueldos | C31: Sueldo | D31: Emilio Sánchez | E31: 6440.2135 | F31: 6173.9543 | G31: 6184.0531 | H31: 5690.3406 | I31: 6233.7735 | J31: 5411.6844 | K31: 8398.601 | L31: 6548.0607 | M31: 6594.0449 | N31: 6079.7914 | O31: 12675.226 | P31: 6201.5179 | Q31: =+SUM(E31:P31) -> 82631.262 | R31: 1 | S31: =+Q31*R31 -> 82631.262 | U31: 0 | W31: =+IF(P31>0,1,0) -> 1
A32: Fijo | B32: Sueldos | C32: Sueldo | D32: Fabián González Recabarren | E32: 1606.9736 | F32: 1541.8742 | G32: 1545.1856 | H32: 1525.9263 | I32: 1557.2132 | J32: 2542.2702 | K32: 0 | L32: 0 | M32: 0 | N32: 0 | O32: 0 | P32: 0 | Q32: =+SUM(E32:P32) -> 10319.443 | R32: 1 | S32: =+Q32*R32 -> 10319.443 | U32: =+IF(P32>0,1,0) -> 0 | W32: =+IF(P32>0,1,0) -> 0
A33: Fijo | B33: Sueldos | C33: Sueldo | D33: Felipe Espinosa Practica en informática nov.23 | E33: 0 | F33: 0 | G33: 0 | H33: 308.17135 | I33: 0 | J33: 0 | K33: 0 | L33: 0 | M33: 0 | N33: 0 | O33: 0 | P33: 0 | Q33: =+SUM(E33:P33) -> 308.17135 | R33: 1 | S33: =+Q33*R33 -> 308.17135 | U33: =+IF(P33>0,1,0) -> 0 | W33: =+IF(P33>0,1,0) -> 0
A34: Fijo | B34: Sueldos | C34: Sueldo | D34: Felipe Lira A. | E34: 4374.5966 | F34: 4190.4798 | G34: 4627.5343 | H34: 4568.267 | I34: 4659.6313 | J34: 4776.4984 | K34: 4749.4501 | L34: 4897.0997 | M34: 3767.3152 | N34: 3300.8313 | O34: 4584.0874 | P34: 4701.2501 | Q34: =+SUM(E34:P34) -> 53197.041 | R34: 1 | S34: =+Q34*R34 -> 53197.041 | U34: =+IF(P34>0,1,0) -> 1
A35: Fijo | B35: Sueldos | C35: Sueldo | D35: Felipe Matamoros C. | E35: 4537.6827 | F35: 4348.7199 | G35: 4423.2777 | H35: 4366.3829 | I35: 4453.4068 | J35: 4564.9059 | K35: 5700.3997 | L35: 0 | M35: 0 | N35: 0 | O35: 0 | P35: 0 | Q35: =+SUM(E35:P35) -> 32394.776 | R35: 1 | S35: =+Q35*R35 -> 32394.776 | U35: =+IF(P35>0,1,0) -> 0 | W35: =+IF(P35>0,1,0) -> 0
A36: Fijo | B36: Sueldos | C36: Sueldo | D36: Felipe Rojas Z. | E36: 8782.9384 | F36: 8366.8112 | G36: 8373.8724 | H36: 8271.4672 | I36: 8440.0669 | J36: 8656.0283 | K36: 8389.7375 | L36: 8842.8204 | M36: 8926.0301 | N36: 8213.102 | O36: 8022.4436 | P36: 8278.3956 | Q36: =+SUM(E36:P36) -> 101563.71 | R36: 1 | S36: =+Q36*R36 -> 101563.71 | U36: =+IF(P36>0,1,0) -> 1
A37: Fijo | B37: Sueldos | C37: Sueldo | D37: Fernando Caballero | E37: 3560.658 | F37: 1415.3235 | G37: 0 | H37: 0 | I37: 0 | J37: 0 | K37: 0 | L37: 0 | M37: 0 | N37: 0 | O37: 0 | P37: 0 | Q37: =+SUM(E37:P37) -> 4975.9816 | R37: 1 | S37: =+Q37*R37 -> 4975.9816 | U37: =+IF(P37>0,1,0) -> 0 | W37: =+IF(P37>0,1,0) -> 0
A38: Fijo | B38: Sueldos | C38: Sueldo | D38: Francisco Bello Moreno | E38: 2360.8092 | F38: 2262.9608 | G38: 3085.0228 | H38: 3046.9277 | I38: 1593.0391 | J38: 3188.769 | K38: 3198.1772 | L38: 3275.6527 | M38: 6341.147 | N38: 0 | O38: 0 | P38: 0 | Q38: =+SUM(E38:P38) -> 28352.505 | R38: 1 | S38: =+Q38*R38 -> 28352.505 | U38: =+IF(P38>0,1,0) -> 0 | W38: =+IF(P38>0,1,0) -> 0
A39: Fijo | B39: Sueldos | C39: Sueldo | D39: Freddy Díaz | E39: 5083.8147 | F39: 4873.6334 | G39: 4887.8345 | H39: 4825.3029 | I39: 4915.4108 | J39: 6517.6964 | K39: 6426.1494 | L39: 6689.0507 | M39: 6729.9375 | N39: 6206.2222 | O39: 6064.6647 | P39: 6270.6616 | Q39: =+SUM(E39:P39) -> 69490.379 | R39: 1 | S39: =+Q39*R39 -> 69490.379 | U39: =+IF(P39>0,1,0) -> 1
A40: Fijo | B40: Sueldos | C40: Sueldo | D40: Gerson Alfaro | E40: 2947.5685 | F40: 2824.92 | G40: 4206.8493 | H40: 4151.3789 | I40: 4233.1904 | J40: 4337.9801 | K40: 4333.4784 | L40: 4449.8019 | M40: 4531.7376 | N40: 4139.3751 | O40: 4042.5536 | P40: 4312.2767 | Q40: =+SUM(E40:P40) -> 48511.11 | R40: 1 | S40: =+Q40*R40 -> 48511.11 | U40: =+IF(P40>0,1,0) -> 1
A41: Fijo | B41: Sueldos | C41: Sueldo | D41: Gino Espinoza | E41: 2466.5056 | F41: 2024.3153 | G41: 2057.4273 | H41: 2100.6381 | I41: 2895.7281 | J41: 1984.0207 | K41: 3955.8276 | L41: 3411.674 | M41: 2027.9609 | N41: 3121.3164 | O41: 3663.0691 | P41: 4359.2332 | Q41: =+SUM(E41:P41) -> 34067.716 | R41: 1 | S41: =+Q41*R41 -> 34067.716 | U41: =+IF(P41>0,1,0) -> 1
A42: Fijo | B42: Sueldos | C42: Sueldo | D42: Gladys Myriam Muñoz | E42: 799.46255 | F42: 753.45014 | G42: 727.39971 | H42: 733.30139 | I42: 3490.7308 | J42: 807.42053 | K42: 774.24805 | L42: 851.05925 | M42: 1238.6737 | N42: 699.62091 | O42: 747.12227 | P42: 1528.6645 | Q42: =+SUM(E42:P42) -> 13151.154 | R42: 0 | S42: =+Q42*R42 -> 0 | U42: =+IF(P42>0,1,0) -> 1
...

Sheet Hoja2
A1: Nombre | B1: 45292 | C1: 45323 | D1: 45352 | E1: 45383 | F1: 45413 | G1: 45444 | H1: 45474 | I1: 45505 | J1: 45536 | K1: 45566 | L1: 45597 | M1: 45627
A2: Patricio Vegara (EEUU) | B2: 42.198646 | C2: 0 | D2: 13.886803 | E2: 0 | F2: 0 | G2: 22.741378 | H2: 0 | I2: 7.5692946 | J2: 0 | K2: 1.1561931 | L2: 34.823875 | M2: 15.173832
A3: SERVICIO ASESORIA MINERA - Comissão Antonio | B3: 0 | C3: 35.36673 | D3: 0 | E3: 0 | F3: 35.57758 | G3: 2.10623 | H3: 0 | I3: 0 | J3: 0 | K3: 28.516 | L3: 0 | M3: 6.115
B4: =+B2+B3 -> 42.198646 | C4: =+C2+C3 -> 35.36673 | D4: =+D2+D3 -> 13.886803 | E4: =+E2+E3 -> 0 | F4: =+F2+F3 -> 35.57758 | G4: =+G2+G3 -> 24.847608 | H4: =+H2+H3 -> 0 | I4: =+I2+I3 -> 7.5692946 | ... M4: =+M2+M3 -> 21.288832 | O4: 1000
A6: Total valores | B6: 42.198646 | C6: 35.36673 | D6: 13.886803 | E6: 0 | F6: 35.57758 | G6: 24.847608 | H6: 0 | I6: 7.5692946 | J6: 0 | K6: 29.672193 | L6: 34.823875 | M6: 21.288832
A9: Externo Fijo | B9: 4375.7069 | C9: 3900.039 | D9: 7037.4952 | E9: 2996.3265 | F9: 7545.7184 | G9: 4977.1768 | H9: 15134.918 | I9: 4103.9086 | J9: 3849.295 | K9: 4361.7377 | L9: 3517.1534 | M9: 4471.8915
A10: Externo Variable | B10: 16376.394 | C10: 3919.8297 | D10: 4429.4877 | E10: 0 | F10: 2898.5785 | G10: 654.96 | H10: 208.13136 | I10: 865.67588 | J10: 284.10677 | K10: 4776.9715 | L10: 5076.5286 | M10: 5675.3676
A11: Total | B11: =+B9+B10 -> 20752.101 | C11: =+C9+C10 -> 7819.8687 | D11: =+D9+D10 -> 11466.983 | E11: =+E9+E10 -> 2996.3265 | F11: =+F9+F10 -> 10444.297 | G11: =+G9+G10 -> 5632.1368 | H11: =+H9+H10 -> 15343.05 | I11: =+I9+I10 -> 4969.5845 | ... M11: =+M9+M10 -> 10147.259
A13: Total valores | B13: 20.752101 | C13: 7.8198687 | D13: 11.466983 | E13: 2.9963265 | F13: 10.444297 | G13: 5.6321368 | H13: 15.34305 | I13: 4.9695845 | J13: 4.1334018 | K13: 9.1387092 | L13: 8.593682 | M13: 10.147259
A15: Extras personas | B15: 129.39817 | C15: 40.431764 | D15: 19.643364 | E15: 12.341404 | F15: 18.451806 | G15: 6.0272542 | H15: 5.0827933 | I15: 4.9271873 | J15: 4.7191498 | K15: 29.951058 | L15: 28.926818 | M15: 13.829525
A16: Viajes | B16: 70.94038 | C16: 15.541723 | D16: 6.4251697 | E16: 19.654064 | F16: 11.217311 | G16: 6.643918 | H16: 10.766462 | I16: 12.765451 | J16: 12.095977 | K16: 8.7212621 | L16: 1.4406731 | M16: 16.0338
